{
  "version": 8,
  "blockIdVersion": 11,
  "anchorX": 0,
  "anchorY": 0,
  "anchorZ": 0,
  "blocks": [
    {
      "x": -6,
      "y": 0,
      "z": -6,
      "name": "Rock_Basalt_Cobble"
    },
    {
      "x": -6,
      "y": 1,
      "z": -6,
      "name": "Empty"
    },
    {
      "x": -6,
      "y": 2,
      "z": -6,
      "name": "Empty"
    },
    {
      "x": -6,
      "y": 3,
      "z": -6,
      "name": "Empty"
    },
    {
      "x": -6,
      "y": 0,
      "z": -5,
      "name": "Rock_Basalt"
    },
    {
      "x": -6,
      "y": 1,
      "z": -5,
      "name": "Empty"
    },
    {
      "x": -6,
      "y": 2,
      "z": -5,
      "name": "Empty"
    },
    {
      "x": -6,
      "y": 3,
      "z": -5,
      "name": "Empty"
    },
    {
      "x": -6,
      "y": 0,
      "z": -4,
      "name": "Rock_Basalt"
    },
    {
      "x": -6,
      "y": 1,
      "z": -4,
      "name": "Empty"
    },
    {
      "x": -6,
      "y": 2,
      "z": -4,
      "name": "Empty"
    },
    {
      "x": -6,
      "y": 3,
      "z": -4,
      "name": "Empty"
    },
    {
      "x": -6,
      "y": 0,
      "z": -3,
      "name": "Rock_Basalt"
    },
    {
      "x": -6,
      "y": 1,
      "z": -3,
      "name": "Empty"
    },
    {
      "x": -6,
      "y": 2,
      "z": -3,
      "name": "Empty"
    },
    {
      "x": -6,
      "y": 3,
      "z": -3,
      "name": "Empty"
    },
    {
      "x": -6,
      "y": 0,
      "z": -2,
      "name": "Rock_Basalt"
    },
    {
      "x": -6,
      "y": 1,
      "z": -2,
      "name": "Empty"
    },
    {
      "x": -6,
      "y": 2,
      "z": -2,
      "name": "Empty"
    },
    {
      "x": -6,
      "y": 3,
      "z": -2,
      "name": "Empty"
    },
    {
      "x": -6,
      "y": 0,
      "z": -1,
      "name": "Ore_Iron_Basalt_Cracked"
    },
    {
      "x": -6,
      "y": 1,
      "z": -1,
      "name": "Empty"
    },
    {
      "x": -6,
      "y": 2,
      "z": -1,
      "name": "Empty"
    },
    {
      "x": -6,
      "y": 3,
      "z": -1,
      "name": "Empty"
    },
    {
      "x": -6,
      "y": 0,
      "z": 0,
      "name": "Rock_Basalt"
    },
    {
      "x": -6,
      "y": 1,
      "z": 0,
      "name": "Empty"
    },
    {
      "x": -6,
      "y": 2,
      "z": 0,
      "name": "Empty"
    },
    {
      "x": -6,
      "y": 3,
      "z": 0,
      "name": "Empty"
    },
    {
      "x": -6,
      "y": 0,
      "z": 1,
      "name": "Rock_Basalt"
    },
    {
      "x": -6,
      "y": 1,
      "z": 1,
      "name": "Empty"
    },
    {
      "x": -6,
      "y": 2,
      "z": 1,
      "name": "Empty"
    },
    {
      "x": -6,
      "y": 3,
      "z": 1,
      "name": "Empty"
    },
    {
      "x": -6,
      "y": 0,
      "z": 2,
      "name": "Rock_Basalt"
    },
    {
      "x": -6,
      "y": 1,
      "z": 2,
      "name": "Empty"
    },
    {
      "x": -6,
      "y": 2,
      "z": 2,
      "name": "Empty"
    },
    {
      "x": -6,
      "y": 3,
      "z": 2,
      "name": "Empty"
    },
    {
      "x": -6,
      "y": 0,
      "z": 3,
      "name": "Plant_Crop_Mushroom_Block_Green"
    },
    {
      "x": -6,
      "y": 1,
      "z": 3,
      "name": "Empty"
    },
    {
      "x": -6,
      "y": 2,
      "z": 3,
      "name": "Empty"
    },
    {
      "x": -6,
      "y": 3,
      "z": 3,
      "name": "Empty"
    },
    {
      "x": -6,
      "y": 0,
      "z": 4,
      "name": "Rock_Basalt"
    },
    {
      "x": -6,
      "y": 1,
      "z": 4,
      "name": "Plant_Seaweed_Grass"
    },
    {
      "x": -6,
      "y": 2,
      "z": 4,
      "name": "Empty"
    },
    {
      "x": -6,
      "y": 3,
      "z": 4,
      "name": "Empty"
    },
    {
      "x": -6,
      "y": 0,
      "z": 5,
      "name": "Rock_Basalt"
    },
    {
      "x": -6,
      "y": 1,
      "z": 5,
      "name": "Empty"
    },
    {
      "x": -6,
      "y": 2,
      "z": 5,
      "name": "Empty"
    },
    {
      "x": -6,
      "y": 3,
      "z": 5,
      "name": "Empty"
    },
    {
      "x": -6,
      "y": 0,
      "z": 6,
      "name": "Rock_Basalt"
    },
    {
      "x": -6,
      "y": 1,
      "z": 6,
      "name": "Empty"
    },
    {
      "x": -6,
      "y": 2,
      "z": 6,
      "name": "Empty"
    },
    {
      "x": -6,
      "y": 3,
      "z": 6,
      "name": "Empty"
    },
    {
      "x": -6,
      "y": 0,
      "z": 7,
      "name": "Ore_Iron_Basalt_Cracked"
    },
    {
      "x": -6,
      "y": 1,
      "z": 7,
      "name": "Empty"
    },
    {
      "x": -6,
      "y": 2,
      "z": 7,
      "name": "Empty"
    },
    {
      "x": -6,
      "y": 3,
      "z": 7,
      "name": "Empty"
    },
    {
      "x": -5,
      "y": 0,
      "z": -6,
      "name": "Rock_Basalt"
    },
    {
      "x": -5,
      "y": 1,
      "z": -6,
      "name": "Empty"
    },
    {
      "x": -5,
      "y": 2,
      "z": -6,
      "name": "Empty"
    },
    {
      "x": -5,
      "y": 3,
      "z": -6,
      "name": "Empty"
    },
    {
      "x": -5,
      "y": 0,
      "z": -5,
      "name": "Rock_Basalt_Cobble"
    },
    {
      "x": -5,
      "y": 1,
      "z": -5,
      "name": "Empty"
    },
    {
      "x": -5,
      "y": 2,
      "z": -5,
      "name": "Empty"
    },
    {
      "x": -5,
      "y": 3,
      "z": -5,
      "name": "Empty",
      "rotation": 3
    },
    {
      "x": -5,
      "y": 0,
      "z": -4,
      "name": "Ore_Iron_Basalt_Cracked"
    },
    {
      "x": -5,
      "y": 1,
      "z": -4,
      "name": "Empty"
    },
    {
      "x": -5,
      "y": 2,
      "z": -4,
      "name": "Empty"
    },
    {
      "x": -5,
      "y": 3,
      "z": -4,
      "name": "Empty",
      "rotation": 3
    },
    {
      "x": -5,
      "y": 0,
      "z": -3,
      "name": "Ore_Iron_Basalt_Cracked"
    },
    {
      "x": -5,
      "y": 1,
      "z": -3,
      "name": "Empty"
    },
    {
      "x": -5,
      "y": 2,
      "z": -3,
      "name": "Empty"
    },
    {
      "x": -5,
      "y": 3,
      "z": -3,
      "name": "Empty",
      "rotation": 3
    },
    {
      "x": -5,
      "y": 0,
      "z": -2,
      "name": "Plant_Crop_Mushroom_Block_Green"
    },
    {
      "x": -5,
      "y": 1,
      "z": -2,
      "name": "Empty"
    },
    {
      "x": -5,
      "y": 2,
      "z": -2,
      "name": "Empty"
    },
    {
      "x": -5,
      "y": 3,
      "z": -2,
      "name": "Empty",
      "rotation": 3
    },
    {
      "x": -5,
      "y": 0,
      "z": -1,
      "name": "Ore_Iron_Basalt_Cracked"
    },
    {
      "x": -5,
      "y": 1,
      "z": -1,
      "name": "Empty"
    },
    {
      "x": -5,
      "y": 2,
      "z": -1,
      "name": "Empty"
    },
    {
      "x": -5,
      "y": 3,
      "z": -1,
      "name": "Empty"
    },
    {
      "x": -5,
      "y": 0,
      "z": 0,
      "name": "Rock_Basalt"
    },
    {
      "x": -5,
      "y": 1,
      "z": 0,
      "name": "Empty"
    },
    {
      "x": -5,
      "y": 2,
      "z": 0,
      "name": "Empty"
    },
    {
      "x": -5,
      "y": 3,
      "z": 0,
      "name": "Empty"
    },
    {
      "x": -5,
      "y": 0,
      "z": 1,
      "name": "Rock_Basalt"
    },
    {
      "x": -5,
      "y": 1,
      "z": 1,
      "name": "Empty"
    },
    {
      "x": -5,
      "y": 2,
      "z": 1,
      "name": "Empty"
    },
    {
      "x": -5,
      "y": 3,
      "z": 1,
      "name": "Empty"
    },
    {
      "x": -5,
      "y": 0,
      "z": 2,
      "name": "Plant_Crop_Mushroom_Block_Green"
    },
    {
      "x": -5,
      "y": 1,
      "z": 2,
      "name": "Empty"
    },
    {
      "x": -5,
      "y": 2,
      "z": 2,
      "name": "Empty"
    },
    {
      "x": -5,
      "y": 3,
      "z": 2,
      "name": "Empty"
    },
    {
      "x": -5,
      "y": 0,
      "z": 3,
      "name": "Rock_Basalt"
    },
    {
      "x": -5,
      "y": 1,
      "z": 3,
      "name": "Empty"
    },
    {
      "x": -5,
      "y": 2,
      "z": 3,
      "name": "Empty"
    },
    {
      "x": -5,
      "y": 3,
      "z": 3,
      "name": "Empty"
    },
    {
      "x": -5,
      "y": 0,
      "z": 4,
      "name": "Rock_Basalt_Cobble"
    },
    {
      "x": -5,
      "y": 1,
      "z": 4,
      "name": "Empty"
    },
    {
      "x": -5,
      "y": 2,
      "z": 4,
      "name": "Empty"
    },
    {
      "x": -5,
      "y": 3,
      "z": 4,
      "name": "Empty"
    },
    {
      "x": -5,
      "y": 0,
      "z": 5,
      "name": "Rock_Basalt_Cobble"
    },
    {
      "x": -5,
      "y": 1,
      "z": 5,
      "name": "Plant_Coral_Model_Grey"
    },
    {
      "x": -5,
      "y": 2,
      "z": 5,
      "name": "Empty"
    },
    {
      "x": -5,
      "y": 3,
      "z": 5,
      "name": "Empty"
    },
    {
      "x": -5,
      "y": 0,
      "z": 6,
      "name": "Ore_Iron_Basalt_Cracked"
    },
    {
      "x": -5,
      "y": 1,
      "z": 6,
      "name": "Empty"
    },
    {
      "x": -5,
      "y": 2,
      "z": 6,
      "name": "Empty"
    },
    {
      "x": -5,
      "y": 3,
      "z": 6,
      "name": "Empty"
    },
    {
      "x": -5,
      "y": 0,
      "z": 7,
      "name": "Rock_Basalt"
    },
    {
      "x": -5,
      "y": 1,
      "z": 7,
      "name": "Empty"
    },
    {
      "x": -5,
      "y": 2,
      "z": 7,
      "name": "Empty"
    },
    {
      "x": -5,
      "y": 3,
      "z": 7,
      "name": "Empty"
    },
    {
      "x": -4,
      "y": 0,
      "z": -6,
      "name": "Ore_Iron_Basalt_Cracked"
    },
    {
      "x": -4,
      "y": 1,
      "z": -6,
      "name": "Plant_Seaweed_Grass_Short"
    },
    {
      "x": -4,
      "y": 2,
      "z": -6,
      "name": "Empty"
    },
    {
      "x": -4,
      "y": 3,
      "z": -6,
      "name": "Empty"
    },
    {
      "x": -4,
      "y": 0,
      "z": -5,
      "name": "Rock_Basalt"
    },
    {
      "x": -4,
      "y": 1,
      "z": -5,
      "name": "Plant_Coral_Model_Green"
    },
    {
      "x": -4,
      "y": 2,
      "z": -5,
      "name": "Empty"
    },
    {
      "x": -4,
      "y": 3,
      "z": -5,
      "name": "Empty",
      "rotation": 3
    },
    {
      "x": -4,
      "y": 0,
      "z": -4,
      "name": "Plant_Crop_Mushroom_Block_Green"
    },
    {
      "x": -4,
      "y": 1,
      "z": -4,
      "name": "Empty"
    },
    {
      "x": -4,
      "y": 2,
      "z": -4,
      "name": "Empty"
    },
    {
      "x": -4,
      "y": 3,
      "z": -4,
      "name": "Empty",
      "rotation": 3
    },
    {
      "x": -4,
      "y": 0,
      "z": -3,
      "name": "Rock_Basalt"
    },
    {
      "x": -4,
      "y": 1,
      "z": -3,
      "name": "Empty"
    },
    {
      "x": -4,
      "y": 2,
      "z": -3,
      "name": "Empty"
    },
    {
      "x": -4,
      "y": 3,
      "z": -3,
      "name": "Empty",
      "rotation": 3
    },
    {
      "x": -4,
      "y": 0,
      "z": -2,
      "name": "Rock_Basalt"
    },
    {
      "x": -4,
      "y": 1,
      "z": -2,
      "name": "Empty"
    },
    {
      "x": -4,
      "y": 2,
      "z": -2,
      "name": "Empty"
    },
    {
      "x": -4,
      "y": 3,
      "z": -2,
      "name": "Empty",
      "rotation": 3
    },
    {
      "x": -4,
      "y": 0,
      "z": -1,
      "name": "Rock_Basalt"
    },
    {
      "x": -4,
      "y": 1,
      "z": -1,
      "name": "Empty"
    },
    {
      "x": -4,
      "y": 2,
      "z": -1,
      "name": "Empty"
    },
    {
      "x": -4,
      "y": 3,
      "z": -1,
      "name": "Empty"
    },
    {
      "x": -4,
      "y": 0,
      "z": 0,
      "name": "Plant_Crop_Mushroom_Block_Green"
    },
    {
      "x": -4,
      "y": 1,
      "z": 0,
      "name": "Empty"
    },
    {
      "x": -4,
      "y": 2,
      "z": 0,
      "name": "Empty"
    },
    {
      "x": -4,
      "y": 3,
      "z": 0,
      "name": "Empty"
    },
    {
      "x": -4,
      "y": 0,
      "z": 1,
      "name": "Rock_Basalt"
    },
    {
      "x": -4,
      "y": 1,
      "z": 1,
      "name": "Plant_Coral_Model_Grey"
    },
    {
      "x": -4,
      "y": 2,
      "z": 1,
      "name": "Empty"
    },
    {
      "x": -4,
      "y": 3,
      "z": 1,
      "name": "Empty"
    },
    {
      "x": -4,
      "y": 0,
      "z": 2,
      "name": "Plant_Crop_Mushroom_Block_Green"
    },
    {
      "x": -4,
      "y": 1,
      "z": 2,
      "name": "Empty"
    },
    {
      "x": -4,
      "y": 2,
      "z": 2,
      "name": "Empty"
    },
    {
      "x": -4,
      "y": 3,
      "z": 2,
      "name": "Empty"
    },
    {
      "x": -4,
      "y": 0,
      "z": 3,
      "name": "Plant_Crop_Mushroom_Block_Green"
    },
    {
      "x": -4,
      "y": 1,
      "z": 3,
      "name": "Empty"
    },
    {
      "x": -4,
      "y": 2,
      "z": 3,
      "name": "Empty"
    },
    {
      "x": -4,
      "y": 3,
      "z": 3,
      "name": "Empty"
    },
    {
      "x": -4,
      "y": 0,
      "z": 4,
      "name": "Ore_Iron_Basalt_Cracked"
    },
    {
      "x": -4,
      "y": 1,
      "z": 4,
      "name": "Empty"
    },
    {
      "x": -4,
      "y": 2,
      "z": 4,
      "name": "Empty"
    },
    {
      "x": -4,
      "y": 3,
      "z": 4,
      "name": "Empty"
    },
    {
      "x": -4,
      "y": 0,
      "z": 5,
      "name": "Plant_Crop_Mushroom_Block_Green"
    },
    {
      "x": -4,
      "y": 1,
      "z": 5,
      "name": "Plant_Seaweed_Grass"
    },
    {
      "x": -4,
      "y": 2,
      "z": 5,
      "name": "Empty"
    },
    {
      "x": -4,
      "y": 3,
      "z": 5,
      "name": "Empty"
    },
    {
      "x": -4,
      "y": 0,
      "z": 6,
      "name": "Rock_Basalt"
    },
    {
      "x": -4,
      "y": 1,
      "z": 6,
      "name": "Plant_Coral_Model_Grey"
    },
    {
      "x": -4,
      "y": 2,
      "z": 6,
      "name": "Empty"
    },
    {
      "x": -4,
      "y": 3,
      "z": 6,
      "name": "Empty"
    },
    {
      "x": -4,
      "y": 0,
      "z": 7,
      "name": "Plant_Crop_Mushroom_Block_Green"
    },
    {
      "x": -4,
      "y": 1,
      "z": 7,
      "name": "Empty"
    },
    {
      "x": -4,
      "y": 2,
      "z": 7,
      "name": "Empty"
    },
    {
      "x": -4,
      "y": 3,
      "z": 7,
      "name": "Empty"
    },
    {
      "x": -3,
      "y": 0,
      "z": -6,
      "name": "Rock_Basalt"
    },
    {
      "x": -3,
      "y": 1,
      "z": -6,
      "name": "Plant_Coral_Model_Grey"
    },
    {
      "x": -3,
      "y": 2,
      "z": -6,
      "name": "Empty"
    },
    {
      "x": -3,
      "y": 3,
      "z": -6,
      "name": "Empty"
    },
    {
      "x": -3,
      "y": 0,
      "z": -5,
      "name": "Plant_Crop_Mushroom_Block_Green"
    },
    {
      "x": -3,
      "y": 1,
      "z": -5,
      "name": "Empty"
    },
    {
      "x": -3,
      "y": 2,
      "z": -5,
      "name": "Empty"
    },
    {
      "x": -3,
      "y": 3,
      "z": -5,
      "name": "Empty",
      "rotation": 3
    },
    {
      "x": -3,
      "y": 0,
      "z": -4,
      "name": "Ore_Iron_Basalt_Cracked"
    },
    {
      "x": -3,
      "y": 1,
      "z": -4,
      "name": "Empty"
    },
    {
      "x": -3,
      "y": 2,
      "z": -4,
      "name": "Empty"
    },
    {
      "x": -3,
      "y": 3,
      "z": -4,
      "name": "Empty",
      "rotation": 3
    },
    {
      "x": -3,
      "y": 0,
      "z": -3,
      "name": "Plant_Crop_Mushroom_Block_Green"
    },
    {
      "x": -3,
      "y": 1,
      "z": -3,
      "name": "Empty"
    },
    {
      "x": -3,
      "y": 2,
      "z": -3,
      "name": "Empty"
    },
    {
      "x": -3,
      "y": 3,
      "z": -3,
      "name": "Empty",
      "rotation": 3
    },
    {
      "x": -3,
      "y": 0,
      "z": -2,
      "name": "Rock_Basalt_Cobble"
    },
    {
      "x": -3,
      "y": 1,
      "z": -2,
      "name": "Empty"
    },
    {
      "x": -3,
      "y": 2,
      "z": -2,
      "name": "Empty"
    },
    {
      "x": -3,
      "y": 3,
      "z": -2,
      "name": "Empty"
    },
    {
      "x": -3,
      "y": 0,
      "z": -1,
      "name": "Ore_Iron_Basalt_Cracked"
    },
    {
      "x": -3,
      "y": 1,
      "z": -1,
      "name": "Plant_Seaweed_Grass_Tall"
    },
    {
      "x": -3,
      "y": 2,
      "z": -1,
      "name": "Empty"
    },
    {
      "x": -3,
      "y": 3,
      "z": -1,
      "name": "Empty"
    },
    {
      "x": -3,
      "y": 0,
      "z": 0,
      "name": "Rock_Basalt"
    },
    {
      "x": -3,
      "y": 1,
      "z": 0,
      "name": "Empty"
    },
    {
      "x": -3,
      "y": 2,
      "z": 0,
      "name": "Empty"
    },
    {
      "x": -3,
      "y": 3,
      "z": 0,
      "name": "Empty"
    },
    {
      "x": -3,
      "y": 0,
      "z": 1,
      "name": "Plant_Crop_Mushroom_Block_Green"
    },
    {
      "x": -3,
      "y": 1,
      "z": 1,
      "name": "Empty"
    },
    {
      "x": -3,
      "y": 2,
      "z": 1,
      "name": "Empty"
    },
    {
      "x": -3,
      "y": 3,
      "z": 1,
      "name": "Empty"
    },
    {
      "x": -3,
      "y": 0,
      "z": 2,
      "name": "Rock_Basalt"
    },
    {
      "x": -3,
      "y": 1,
      "z": 2,
      "name": "Rock_Basalt_Cobble"
    },
    {
      "x": -3,
      "y": 2,
      "z": 2,
      "name": "Empty"
    },
    {
      "x": -3,
      "y": 3,
      "z": 2,
      "name": "Empty"
    },
    {
      "x": -3,
      "y": 0,
      "z": 3,
      "name": "Ore_Iron_Basalt_Cracked"
    },
    {
      "x": -3,
      "y": 1,
      "z": 3,
      "name": "Empty"
    },
    {
      "x": -3,
      "y": 2,
      "z": 3,
      "name": "Empty"
    },
    {
      "x": -3,
      "y": 3,
      "z": 3,
      "name": "Empty"
    },
    {
      "x": -3,
      "y": 0,
      "z": 4,
      "name": "Rock_Basalt"
    },
    {
      "x": -3,
      "y": 1,
      "z": 4,
      "name": "Plant_Crop_Mushroom_Block_Green"
    },
    {
      "x": -3,
      "y": 2,
      "z": 4,
      "name": "Empty"
    },
    {
      "x": -3,
      "y": 3,
      "z": 4,
      "name": "Empty"
    },
    {
      "x": -3,
      "y": 0,
      "z": 5,
      "name": "Rock_Basalt"
    },
    {
      "x": -3,
      "y": 1,
      "z": 5,
      "name": "Rock_Basalt"
    },
    {
      "x": -3,
      "y": 2,
      "z": 5,
      "name": "Empty"
    },
    {
      "x": -3,
      "y": 3,
      "z": 5,
      "name": "Empty"
    },
    {
      "x": -3,
      "y": 0,
      "z": 6,
      "name": "Plant_Crop_Mushroom_Block_Green"
    },
    {
      "x": -3,
      "y": 1,
      "z": 6,
      "name": "Rock_Basalt"
    },
    {
      "x": -3,
      "y": 2,
      "z": 6,
      "name": "Empty"
    },
    {
      "x": -3,
      "y": 3,
      "z": 6,
      "name": "Empty"
    },
    {
      "x": -3,
      "y": 0,
      "z": 7,
      "name": "Plant_Crop_Mushroom_Block_Green"
    },
    {
      "x": -3,
      "y": 1,
      "z": 7,
      "name": "Plant_Seaweed_Grass"
    },
    {
      "x": -3,
      "y": 2,
      "z": 7,
      "name": "Empty"
    },
    {
      "x": -3,
      "y": 3,
      "z": 7,
      "name": "Empty"
    },
    {
      "x": -2,
      "y": 0,
      "z": -6,
      "name": "Rock_Basalt"
    },
    {
      "x": -2,
      "y": 1,
      "z": -6,
      "name": "Empty"
    },
    {
      "x": -2,
      "y": 2,
      "z": -6,
      "name": "Empty"
    },
    {
      "x": -2,
      "y": 3,
      "z": -6,
      "name": "Empty"
    },
    {
      "x": -2,
      "y": 0,
      "z": -5,
      "name": "Plant_Crop_Mushroom_Block_Green"
    },
    {
      "x": -2,
      "y": 1,
      "z": -5,
      "name": "Empty"
    },
    {
      "x": -2,
      "y": 2,
      "z": -5,
      "name": "Empty"
    },
    {
      "x": -2,
      "y": 3,
      "z": -5,
      "name": "Empty",
      "rotation": 3
    },
    {
      "x": -2,
      "y": 0,
      "z": -4,
      "name": "Plant_Crop_Mushroom_Block_Green"
    },
    {
      "x": -2,
      "y": 1,
      "z": -4,
      "name": "Empty"
    },
    {
      "x": -2,
      "y": 2,
      "z": -4,
      "name": "Empty"
    },
    {
      "x": -2,
      "y": 3,
      "z": -4,
      "name": "Empty",
      "rotation": 3
    },
    {
      "x": -2,
      "y": 0,
      "z": -3,
      "name": "Ore_Iron_Basalt_Cracked"
    },
    {
      "x": -2,
      "y": 1,
      "z": -3,
      "name": "Empty"
    },
    {
      "x": -2,
      "y": 2,
      "z": -3,
      "name": "Empty"
    },
    {
      "x": -2,
      "y": 3,
      "z": -3,
      "name": "Empty"
    },
    {
      "x": -2,
      "y": 0,
      "z": -2,
      "name": "Rock_Basalt"
    },
    {
      "x": -2,
      "y": 1,
      "z": -2,
      "name": "Plant_Seaweed_Grass"
    },
    {
      "x": -2,
      "y": 2,
      "z": -2,
      "name": "Empty"
    },
    {
      "x": -2,
      "y": 3,
      "z": -2,
      "name": "Empty"
    },
    {
      "x": -2,
      "y": 0,
      "z": -1,
      "name": "Rock_Basalt"
    },
    {
      "x": -2,
      "y": 1,
      "z": -1,
      "name": "Empty"
    },
    {
      "x": -2,
      "y": 2,
      "z": -1,
      "name": "Empty"
    },
    {
      "x": -2,
      "y": 3,
      "z": -1,
      "name": "Empty"
    },
    {
      "x": -2,
      "y": 0,
      "z": 0,
      "name": "Rock_Basalt"
    },
    {
      "x": -2,
      "y": 1,
      "z": 0,
      "name": "Rock_Basalt"
    },
    {
      "x": -2,
      "y": 2,
      "z": 0,
      "name": "Empty"
    },
    {
      "x": -2,
      "y": 3,
      "z": 0,
      "name": "Empty"
    },
    {
      "x": -2,
      "y": 0,
      "z": 1,
      "name": "Rock_Basalt"
    },
    {
      "x": -2,
      "y": 1,
      "z": 1,
      "name": "Rock_Basalt"
    },
    {
      "x": -2,
      "y": 2,
      "z": 1,
      "name": "Rock_Basalt"
    },
    {
      "x": -2,
      "y": 3,
      "z": 1,
      "name": "Empty"
    },
    {
      "x": -2,
      "y": 0,
      "z": 2,
      "name": "Ore_Iron_Basalt_Cracked"
    },
    {
      "x": -2,
      "y": 1,
      "z": 2,
      "name": "Rock_Basalt"
    },
    {
      "x": -2,
      "y": 2,
      "z": 2,
      "name": "Rock_Basalt"
    },
    {
      "x": -2,
      "y": 3,
      "z": 2,
      "name": "Rock_Stone"
    },
    {
      "x": -2,
      "y": 4,
      "z": 2,
      "name": "Rock_Stone_Stairs",
      "rotation": 3
    },
    {
      "x": -2,
      "y": 0,
      "z": 3,
      "name": "Rock_Basalt"
    },
    {
      "x": -2,
      "y": 1,
      "z": 3,
      "name": "Rock_Basalt"
    },
    {
      "x": -2,
      "y": 2,
      "z": 3,
      "name": "Rock_Basalt"
    },
    {
      "x": -2,
      "y": 3,
      "z": 3,
      "name": "Empty"
    },
    {
      "x": -2,
      "y": 0,
      "z": 4,
      "name": "Ore_Iron_Basalt_Cracked"
    },
    {
      "x": -2,
      "y": 1,
      "z": 4,
      "name": "Rock_Basalt"
    },
    {
      "x": -2,
      "y": 2,
      "z": 4,
      "name": "Rock_Basalt"
    },
    {
      "x": -2,
      "y": 3,
      "z": 4,
      "name": "Rock_Basalt"
    },
    {
      "x": -2,
      "y": 4,
      "z": 4,
      "name": "Rock_Stone_Mossy"
    },
    {
      "x": -2,
      "y": 5,
      "z": 4,
      "name": "Rock_Stone_Mossy"
    },
    {
      "x": -2,
      "y": 6,
      "z": 4,
      "name": "Plant_Moss_Rug_Green"
    },
    {
      "x": -2,
      "y": 0,
      "z": 5,
      "name": "Plant_Crop_Mushroom_Block_Green"
    },
    {
      "x": -2,
      "y": 1,
      "z": 5,
      "name": "Rock_Basalt"
    },
    {
      "x": -2,
      "y": 2,
      "z": 5,
      "name": "Rock_Basalt"
    },
    {
      "x": -2,
      "y": 3,
      "z": 5,
      "name": "Rock_Basalt"
    },
    {
      "x": -2,
      "y": 4,
      "z": 5,
      "name": "Rock_Stone"
    },
    {
      "x": -2,
      "y": 0,
      "z": 6,
      "name": "Rock_Basalt"
    },
    {
      "x": -2,
      "y": 1,
      "z": 6,
      "name": "Rock_Basalt"
    },
    {
      "x": -2,
      "y": 2,
      "z": 6,
      "name": "Rock_Basalt"
    },
    {
      "x": -2,
      "y": 3,
      "z": 6,
      "name": "Empty"
    },
    {
      "x": -2,
      "y": 0,
      "z": 7,
      "name": "Rock_Basalt"
    },
    {
      "x": -2,
      "y": 1,
      "z": 7,
      "name": "Rock_Basalt"
    },
    {
      "x": -2,
      "y": 2,
      "z": 7,
      "name": "Plant_Coral_Model_Lime"
    },
    {
      "x": -2,
      "y": 3,
      "z": 7,
      "name": "Empty"
    },
    {
      "x": -1,
      "y": 0,
      "z": -6,
      "name": "Plant_Crop_Mushroom_Block_Green"
    },
    {
      "x": -1,
      "y": 1,
      "z": -6,
      "name": "Empty"
    },
    {
      "x": -1,
      "y": 2,
      "z": -6,
      "name": "Empty"
    },
    {
      "x": -1,
      "y": 3,
      "z": -6,
      "name": "Empty"
    },
    {
      "x": -1,
      "y": 0,
      "z": -5,
      "name": "Rock_Basalt_Cobble"
    },
    {
      "x": -1,
      "y": 1,
      "z": -5,
      "name": "Empty"
    },
    {
      "x": -1,
      "y": 2,
      "z": -5,
      "name": "Empty"
    },
    {
      "x": -1,
      "y": 3,
      "z": -5,
      "name": "Empty",
      "rotation": 3
    },
    {
      "x": -1,
      "y": 0,
      "z": -4,
      "name": "Rock_Basalt"
    },
    {
      "x": -1,
      "y": 1,
      "z": -4,
      "name": "Plant_Seaweed_Grass_Stack"
    },
    {
      "x": -1,
      "y": 2,
      "z": -4,
      "name": "Empty"
    },
    {
      "x": -1,
      "y": 3,
      "z": -4,
      "name": "Empty",
      "rotation": 3
    },
    {
      "x": -1,
      "y": 0,
      "z": -3,
      "name": "Ore_Iron_Basalt_Cracked"
    },
    {
      "x": -1,
      "y": 1,
      "z": -3,
      "name": "Empty"
    },
    {
      "x": -1,
      "y": 2,
      "z": -3,
      "name": "Empty"
    },
    {
      "x": -1,
      "y": 3,
      "z": -3,
      "name": "Empty"
    },
    {
      "x": -1,
      "y": 0,
      "z": -2,
      "name": "Rock_Basalt"
    },
    {
      "x": -1,
      "y": 1,
      "z": -2,
      "name": "Empty"
    },
    {
      "x": -1,
      "y": 2,
      "z": -2,
      "name": "Empty"
    },
    {
      "x": -1,
      "y": 3,
      "z": -2,
      "name": "Empty"
    },
    {
      "x": -1,
      "y": 0,
      "z": -1,
      "name": "Rock_Basalt"
    },
    {
      "x": -1,
      "y": 1,
      "z": -1,
      "name": "Rock_Basalt"
    },
    {
      "x": -1,
      "y": 2,
      "z": -1,
      "name": "Empty"
    },
    {
      "x": -1,
      "y": 3,
      "z": -1,
      "name": "Empty"
    },
    {
      "x": -1,
      "y": 0,
      "z": 0,
      "name": "Rock_Basalt"
    },
    {
      "x": -1,
      "y": 1,
      "z": 0,
      "name": "Rock_Basalt",
      "rotation": 3
    },
    {
      "x": -1,
      "y": 2,
      "z": 0,
      "name": "Rock_Basalt"
    },
    {
      "x": -1,
      "y": 3,
      "z": 0,
      "name": "Empty"
    },
    {
      "x": -1,
      "y": 0,
      "z": 1,
      "name": "Rock_Basalt"
    },
    {
      "x": -1,
      "y": 1,
      "z": 1,
      "name": "Rock_Basalt"
    },
    {
      "x": -1,
      "y": 2,
      "z": 1,
      "name": "Rock_Basalt"
    },
    {
      "x": -1,
      "y": 3,
      "z": 1,
      "name": "Rock_Stone"
    },
    {
      "x": -1,
      "y": 4,
      "z": 1,
      "name": "Rubble_Stone"
    },
    {
      "x": -1,
      "y": 0,
      "z": 2,
      "name": "Rock_Basalt"
    },
    {
      "x": -1,
      "y": 1,
      "z": 2,
      "name": "Rock_Basalt"
    },
    {
      "x": -1,
      "y": 2,
      "z": 2,
      "name": "Rock_Basalt"
    },
    {
      "x": -1,
      "y": 3,
      "z": 2,
      "name": "Rock_Basalt"
    },
    {
      "x": -1,
      "y": 4,
      "z": 2,
      "name": "Rock_Stone"
    },
    {
      "x": -1,
      "y": 5,
      "z": 2,
      "name": "Rock_Stone"
    },
    {
      "x": -1,
      "y": 6,
      "z": 2,
      "name": "Rock_Stone_Mossy"
    },
    {
      "x": -1,
      "y": 0,
      "z": 3,
      "name": "Rock_Basalt"
    },
    {
      "x": -1,
      "y": 1,
      "z": 3,
      "name": "Rock_Basalt"
    },
    {
      "x": -1,
      "y": 2,
      "z": 3,
      "name": "Rock_Basalt"
    },
    {
      "x": -1,
      "y": 3,
      "z": 3,
      "name": "Rock_Basalt"
    },
    {
      "x": -1,
      "y": 4,
      "z": 3,
      "name": "Rock_Stone_Mossy"
    },
    {
      "x": -1,
      "y": 5,
      "z": 3,
      "name": "Rock_Stone_Mossy"
    },
    {
      "x": -1,
      "y": 6,
      "z": 3,
      "name": "Rock_Stone"
    },
    {
      "x": -1,
      "y": 7,
      "z": 3,
      "name": "Rock_Stone"
    },
    {
      "x": -1,
      "y": 0,
      "z": 4,
      "name": "Rock_Basalt"
    },
    {
      "x": -1,
      "y": 1,
      "z": 4,
      "name": "Rock_Basalt"
    },
    {
      "x": -1,
      "y": 2,
      "z": 4,
      "name": "Rock_Basalt"
    },
    {
      "x": -1,
      "y": 3,
      "z": 4,
      "name": "Rock_Basalt"
    },
    {
      "x": -1,
      "y": 4,
      "z": 4,
      "name": "Rock_Stone"
    },
    {
      "x": -1,
      "y": 5,
      "z": 4,
      "name": "Rock_Stone_Mossy"
    },
    {
      "x": -1,
      "y": 6,
      "z": 4,
      "name": "Rock_Stone_Mossy"
    },
    {
      "x": -1,
      "y": 7,
      "z": 4,
      "name": "Rock_Stone_Mossy"
    },
    {
      "x": -1,
      "y": 8,
      "z": 4,
      "name": "Plant_Moss_Rug_Green"
    },
    {
      "x": -1,
      "y": 0,
      "z": 5,
      "name": "Rock_Basalt"
    },
    {
      "x": -1,
      "y": 1,
      "z": 5,
      "name": "Rock_Basalt"
    },
    {
      "x": -1,
      "y": 2,
      "z": 5,
      "name": "Rock_Basalt"
    },
    {
      "x": -1,
      "y": 3,
      "z": 5,
      "name": "Rock_Basalt"
    },
    {
      "x": -1,
      "y": 4,
      "z": 5,
      "name": "Rock_Stone"
    },
    {
      "x": -1,
      "y": 5,
      "z": 5,
      "name": "Rock_Stone"
    },
    {
      "x": -1,
      "y": 6,
      "z": 5,
      "name": "Rock_Stone_Stairs",
      "rotation": 3
    },
    {
      "x": -1,
      "y": 0,
      "z": 6,
      "name": "Rock_Basalt"
    },
    {
      "x": -1,
      "y": 1,
      "z": 6,
      "name": "Rock_Basalt"
    },
    {
      "x": -1,
      "y": 2,
      "z": 6,
      "name": "Rock_Basalt"
    },
    {
      "x": -1,
      "y": 3,
      "z": 6,
      "name": "Rock_Basalt"
    },
    {
      "x": -1,
      "y": 4,
      "z": 6,
      "name": "Rock_Stone"
    },
    {
      "x": -1,
      "y": 5,
      "z": 6,
      "name": "Rock_Stone_Mossy"
    },
    {
      "x": -1,
      "y": 6,
      "z": 6,
      "name": "Rock_Stone_Mossy"
    },
    {
      "x": -1,
      "y": 0,
      "z": 7,
      "name": "Rock_Basalt_Cobble"
    },
    {
      "x": -1,
      "y": 1,
      "z": 7,
      "name": "Plant_Crop_Mushroom_Block_Green"
    },
    {
      "x": -1,
      "y": 2,
      "z": 7,
      "name": "Rock_Basalt"
    },
    {
      "x": -1,
      "y": 3,
      "z": 7,
      "name": "Rock_Basalt"
    },
    {
      "x": -1,
      "y": 4,
      "z": 7,
      "name": "Rock_Stone"
    },
    {
      "x": -1,
      "y": 5,
      "z": 7,
      "name": "Rock_Stone"
    },
    {
      "x": -1,
      "y": 6,
      "z": 7,
      "name": "Rock_Stone_Mossy"
    },
    {
      "x": -1,
      "y": 7,
      "z": 7,
      "name": "Rock_Stone_Mossy"
    },
    {
      "x": -1,
      "y": 8,
      "z": 7,
      "name": "Plant_Moss_Rug_Green"
    },
    {
      "x": 0,
      "y": 0,
      "z": -6,
      "name": "Rock_Basalt"
    },
    {
      "x": 0,
      "y": 1,
      "z": -6,
      "name": "Plant_Seaweed_Grass_Short"
    },
    {
      "x": 0,
      "y": 2,
      "z": -6,
      "name": "Empty"
    },
    {
      "x": 0,
      "y": 3,
      "z": -6,
      "name": "Empty"
    },
    {
      "x": 0,
      "y": 0,
      "z": -5,
      "name": "Rock_Basalt"
    },
    {
      "x": 0,
      "y": 1,
      "z": -5,
      "name": "Plant_Coral_Model_Green"
    },
    {
      "x": 0,
      "y": 2,
      "z": -5,
      "name": "Empty"
    },
    {
      "x": 0,
      "y": 3,
      "z": -5,
      "name": "Empty",
      "rotation": 3
    },
    {
      "x": 0,
      "y": 0,
      "z": -4,
      "name": "Rock_Basalt"
    },
    {
      "x": 0,
      "y": 1,
      "z": -4,
      "name": "Plant_Seaweed_Grass_Stack"
    },
    {
      "x": 0,
      "y": 2,
      "z": -4,
      "name": "Empty"
    },
    {
      "x": 0,
      "y": 3,
      "z": -4,
      "name": "Empty",
      "rotation": 3
    },
    {
      "x": 0,
      "y": 0,
      "z": -3,
      "name": "Plant_Crop_Mushroom_Block_Green"
    },
    {
      "x": 0,
      "y": 1,
      "z": -3,
      "name": "Plant_Seaweed_Grass_Stack"
    },
    {
      "x": 0,
      "y": 2,
      "z": -3,
      "name": "Empty"
    },
    {
      "x": 0,
      "y": 3,
      "z": -3,
      "name": "Empty"
    },
    {
      "x": 0,
      "y": 0,
      "z": -2,
      "name": "Plant_Crop_Mushroom_Block_Green"
    },
    {
      "x": 0,
      "y": 1,
      "z": -2,
      "name": "Empty"
    },
    {
      "x": 0,
      "y": 2,
      "z": -2,
      "name": "Empty"
    },
    {
      "x": 0,
      "y": 3,
      "z": -2,
      "name": "Empty"
    },
    {
      "x": 0,
      "y": 0,
      "z": -1,
      "name": "Rock_Basalt"
    },
    {
      "x": 0,
      "y": 1,
      "z": -1,
      "name": "Rock_Basalt",
      "rotation": 3
    },
    {
      "x": 0,
      "y": 2,
      "z": -1,
      "name": "Rock_Basalt"
    },
    {
      "x": 0,
      "y": 3,
      "z": -1,
      "name": "Empty"
    },
    {
      "x": 0,
      "y": 0,
      "z": 0,
      "name": "Rock_Basalt"
    },
    {
      "x": 0,
      "y": 1,
      "z": 0,
      "name": "Rock_Basalt",
      "rotation": 3
    },
    {
      "x": 0,
      "y": 2,
      "z": 0,
      "name": "Rock_Basalt",
      "rotation": 3
    },
    {
      "x": 0,
      "y": 3,
      "z": 0,
      "name": "Rock_Basalt",
      "rotation": 3
    },
    {
      "x": 0,
      "y": 4,
      "z": 0,
      "name": "Rock_Stone",
      "rotation": 3
    },
    {
      "x": 0,
      "y": 5,
      "z": 0,
      "name": "Rock_Stone"
    },
    {
      "x": 0,
      "y": 6,
      "z": 0,
      "name": "Rock_Stone_Stairs",
      "rotation": 2
    },
    {
      "x": 0,
      "y": 0,
      "z": 1,
      "name": "Rock_Basalt"
    },
    {
      "x": 0,
      "y": 1,
      "z": 1,
      "name": "Rock_Basalt"
    },
    {
      "x": 0,
      "y": 2,
      "z": 1,
      "name": "Rock_Basalt"
    },
    {
      "x": 0,
      "y": 3,
      "z": 1,
      "name": "Rock_Basalt"
    },
    {
      "x": 0,
      "y": 4,
      "z": 1,
      "name": "Rock_Stone"
    },
    {
      "x": 0,
      "y": 5,
      "z": 1,
      "name": "Rock_Stone"
    },
    {
      "x": 0,
      "y": 6,
      "z": 1,
      "name": "Rock_Stone"
    },
    {
      "x": 0,
      "y": 7,
      "z": 1,
      "name": "Rock_Stone"
    },
    {
      "x": 0,
      "y": 8,
      "z": 1,
      "name": "Rock_Stone_Stairs",
      "rotation": 3
    },
    {
      "x": 0,
      "y": 0,
      "z": 2,
      "name": "Rock_Basalt"
    },
    {
      "x": 0,
      "y": 1,
      "z": 2,
      "name": "Rock_Basalt"
    },
    {
      "x": 0,
      "y": 2,
      "z": 2,
      "name": "Rock_Basalt"
    },
    {
      "x": 0,
      "y": 3,
      "z": 2,
      "name": "Rock_Basalt"
    },
    {
      "x": 0,
      "y": 4,
      "z": 2,
      "name": "Rock_Stone"
    },
    {
      "x": 0,
      "y": 5,
      "z": 2,
      "name": "Rock_Stone"
    },
    {
      "x": 0,
      "y": 6,
      "z": 2,
      "name": "Rock_Stone"
    },
    {
      "x": 0,
      "y": 7,
      "z": 2,
      "name": "Rock_Stone"
    },
    {
      "x": 0,
      "y": 8,
      "z": 2,
      "name": "Rock_Stone"
    },
    {
      "x": 0,
      "y": 0,
      "z": 3,
      "name": "Rock_Basalt"
    },
    {
      "x": 0,
      "y": 1,
      "z": 3,
      "name": "Rock_Basalt"
    },
    {
      "x": 0,
      "y": 2,
      "z": 3,
      "name": "Rock_Basalt"
    },
    {
      "x": 0,
      "y": 3,
      "z": 3,
      "name": "Rock_Basalt"
    },
    {
      "x": 0,
      "y": 4,
      "z": 3,
      "name": "Rock_Stone"
    },
    {
      "x": 0,
      "y": 5,
      "z": 3,
      "name": "Rock_Stone"
    },
    {
      "x": 0,
      "y": 6,
      "z": 3,
      "name": "Rock_Stone"
    },
    {
      "x": 0,
      "y": 7,
      "z": 3,
      "name": "Rock_Stone"
    },
    {
      "x": 0,
      "y": 8,
      "z": 3,
      "name": "Rock_Stone"
    },
    {
      "x": 0,
      "y": 0,
      "z": 4,
      "name": "Rock_Basalt"
    },
    {
      "x": 0,
      "y": 1,
      "z": 4,
      "name": "Rock_Basalt"
    },
    {
      "x": 0,
      "y": 2,
      "z": 4,
      "name": "Rock_Basalt"
    },
    {
      "x": 0,
      "y": 3,
      "z": 4,
      "name": "Rock_Basalt"
    },
    {
      "x": 0,
      "y": 4,
      "z": 4,
      "name": "Rock_Stone"
    },
    {
      "x": 0,
      "y": 5,
      "z": 4,
      "name": "Rock_Stone"
    },
    {
      "x": 0,
      "y": 6,
      "z": 4,
      "name": "Rock_Stone"
    },
    {
      "x": 0,
      "y": 7,
      "z": 4,
      "name": "Rock_Stone"
    },
    {
      "x": 0,
      "y": 8,
      "z": 4,
      "name": "Rock_Stone_Stairs",
      "rotation": 3
    },
    {
      "x": 0,
      "y": 0,
      "z": 5,
      "name": "Rock_Basalt"
    },
    {
      "x": 0,
      "y": 1,
      "z": 5,
      "name": "Rock_Basalt"
    },
    {
      "x": 0,
      "y": 2,
      "z": 5,
      "name": "Rock_Basalt"
    },
    {
      "x": 0,
      "y": 3,
      "z": 5,
      "name": "Rock_Basalt"
    },
    {
      "x": 0,
      "y": 4,
      "z": 5,
      "name": "Rock_Stone"
    },
    {
      "x": 0,
      "y": 5,
      "z": 5,
      "name": "Rock_Stone"
    },
    {
      "x": 0,
      "y": 6,
      "z": 5,
      "name": "Rock_Stone"
    },
    {
      "x": 0,
      "y": 7,
      "z": 5,
      "name": "Rock_Stone"
    },
    {
      "x": 0,
      "y": 8,
      "z": 5,
      "name": "Rock_Stone"
    },
    {
      "x": 0,
      "y": 0,
      "z": 6,
      "name": "Rock_Basalt"
    },
    {
      "x": 0,
      "y": 1,
      "z": 6,
      "name": "Rock_Basalt"
    },
    {
      "x": 0,
      "y": 2,
      "z": 6,
      "name": "Rock_Basalt"
    },
    {
      "x": 0,
      "y": 3,
      "z": 6,
      "name": "Rock_Basalt"
    },
    {
      "x": 0,
      "y": 4,
      "z": 6,
      "name": "Rock_Stone"
    },
    {
      "x": 0,
      "y": 5,
      "z": 6,
      "name": "Rock_Stone"
    },
    {
      "x": 0,
      "y": 6,
      "z": 6,
      "name": "Rock_Stone"
    },
    {
      "x": 0,
      "y": 7,
      "z": 6,
      "name": "Rock_Stone"
    },
    {
      "x": 0,
      "y": 8,
      "z": 6,
      "name": "Rock_Stone"
    },
    {
      "x": 0,
      "y": 0,
      "z": 7,
      "name": "Rock_Basalt"
    },
    {
      "x": 0,
      "y": 1,
      "z": 7,
      "name": "Rock_Basalt"
    },
    {
      "x": 0,
      "y": 2,
      "z": 7,
      "name": "Rock_Basalt"
    },
    {
      "x": 0,
      "y": 3,
      "z": 7,
      "name": "Rock_Basalt"
    },
    {
      "x": 0,
      "y": 4,
      "z": 7,
      "name": "Rock_Stone"
    },
    {
      "x": 0,
      "y": 5,
      "z": 7,
      "name": "Rock_Stone"
    },
    {
      "x": 0,
      "y": 6,
      "z": 7,
      "name": "Rock_Stone"
    },
    {
      "x": 0,
      "y": 7,
      "z": 7,
      "name": "Rock_Stone"
    },
    {
      "x": 0,
      "y": 8,
      "z": 7,
      "name": "Rock_Stone_Half"
    },
    {
      "x": 1,
      "y": 0,
      "z": -6,
      "name": "Rock_Basalt_Cobble"
    },
    {
      "x": 1,
      "y": 1,
      "z": -6,
      "name": "Empty"
    },
    {
      "x": 1,
      "y": 2,
      "z": -6,
      "name": "Empty"
    },
    {
      "x": 1,
      "y": 3,
      "z": -6,
      "name": "Empty",
      "rotation": 3
    },
    {
      "x": 1,
      "y": 0,
      "z": -5,
      "name": "Plant_Crop_Mushroom_Block_Green"
    },
    {
      "x": 1,
      "y": 1,
      "z": -5,
      "name": "Plant_Coral_Model_Grey"
    },
    {
      "x": 1,
      "y": 2,
      "z": -5,
      "name": "Empty"
    },
    {
      "x": 1,
      "y": 3,
      "z": -5,
      "name": "Empty",
      "rotation": 3
    },
    {
      "x": 1,
      "y": 0,
      "z": -4,
      "name": "Rock_Basalt_Cobble"
    },
    {
      "x": 1,
      "y": 1,
      "z": -4,
      "name": "Empty"
    },
    {
      "x": 1,
      "y": 2,
      "z": -4,
      "name": "Empty"
    },
    {
      "x": 1,
      "y": 3,
      "z": -4,
      "name": "Empty",
      "rotation": 3
    },
    {
      "x": 1,
      "y": 0,
      "z": -3,
      "name": "Rock_Basalt"
    },
    {
      "x": 1,
      "y": 1,
      "z": -3,
      "name": "Plant_Seaweed_Grass_Tall"
    },
    {
      "x": 1,
      "y": 2,
      "z": -3,
      "name": "Empty"
    },
    {
      "x": 1,
      "y": 3,
      "z": -3,
      "name": "Empty",
      "rotation": 3
    },
    {
      "x": 1,
      "y": 0,
      "z": -2,
      "name": "Plant_Crop_Mushroom_Block_Green"
    },
    {
      "x": 1,
      "y": 1,
      "z": -2,
      "name": "Rock_Basalt",
      "rotation": 3
    },
    {
      "x": 1,
      "y": 2,
      "z": -2,
      "name": "Empty"
    },
    {
      "x": 1,
      "y": 3,
      "z": -2,
      "name": "Empty",
      "rotation": 3
    },
    {
      "x": 1,
      "y": 0,
      "z": -1,
      "name": "Rock_Basalt"
    },
    {
      "x": 1,
      "y": 1,
      "z": -1,
      "name": "Rock_Basalt",
      "rotation": 3
    },
    {
      "x": 1,
      "y": 2,
      "z": -1,
      "name": "Rock_Basalt",
      "rotation": 3
    },
    {
      "x": 1,
      "y": 3,
      "z": -1,
      "name": "Rock_Basalt",
      "rotation": 3
    },
    {
      "x": 1,
      "y": 4,
      "z": -1,
      "name": "Rock_Stone",
      "rotation": 3
    },
    {
      "x": 1,
      "y": 0,
      "z": 0,
      "name": "Rock_Basalt"
    },
    {
      "x": 1,
      "y": 1,
      "z": 0,
      "name": "Rock_Basalt",
      "rotation": 3
    },
    {
      "x": 1,
      "y": 2,
      "z": 0,
      "name": "Rock_Basalt",
      "rotation": 3
    },
    {
      "x": 1,
      "y": 3,
      "z": 0,
      "name": "Rock_Basalt",
      "rotation": 3
    },
    {
      "x": 1,
      "y": 4,
      "z": 0,
      "name": "Rock_Stone",
      "rotation": 3
    },
    {
      "x": 1,
      "y": 5,
      "z": 0,
      "name": "Rock_Stone",
      "rotation": 3
    },
    {
      "x": 1,
      "y": 6,
      "z": 0,
      "name": "Rock_Stone",
      "rotation": 3
    },
    {
      "x": 1,
      "y": 7,
      "z": 0,
      "name": "Rock_Stone",
      "rotation": 3
    },
    {
      "x": 1,
      "y": 0,
      "z": 1,
      "name": "Rock_Basalt"
    },
    {
      "x": 1,
      "y": 1,
      "z": 1,
      "name": "Rock_Basalt",
      "rotation": 2
    },
    {
      "x": 1,
      "y": 2,
      "z": 1,
      "name": "Rock_Basalt",
      "rotation": 2
    },
    {
      "x": 1,
      "y": 3,
      "z": 1,
      "name": "Rock_Basalt",
      "rotation": 2
    },
    {
      "x": 1,
      "y": 4,
      "z": 1,
      "name": "Rock_Stone",
      "rotation": 2
    },
    {
      "x": 1,
      "y": 5,
      "z": 1,
      "name": "Rock_Stone",
      "rotation": 2
    },
    {
      "x": 1,
      "y": 6,
      "z": 1,
      "name": "Rock_Stone",
      "rotation": 2
    },
    {
      "x": 1,
      "y": 7,
      "z": 1,
      "name": "Rock_Stone",
      "rotation": 2
    },
    {
      "x": 1,
      "y": 8,
      "z": 1,
      "name": "Rock_Stone",
      "rotation": 2
    },
    {
      "x": 1,
      "y": 0,
      "z": 2,
      "name": "Rock_Basalt"
    },
    {
      "x": 1,
      "y": 1,
      "z": 2,
      "name": "Rock_Basalt",
      "rotation": 2
    },
    {
      "x": 1,
      "y": 2,
      "z": 2,
      "name": "Rock_Basalt",
      "rotation": 2
    },
    {
      "x": 1,
      "y": 3,
      "z": 2,
      "name": "Rock_Basalt",
      "rotation": 2
    },
    {
      "x": 1,
      "y": 4,
      "z": 2,
      "name": "Rock_Stone",
      "rotation": 2
    },
    {
      "x": 1,
      "y": 5,
      "z": 2,
      "name": "Rock_Stone",
      "rotation": 2
    },
    {
      "x": 1,
      "y": 6,
      "z": 2,
      "name": "Rock_Stone",
      "rotation": 2
    },
    {
      "x": 1,
      "y": 7,
      "z": 2,
      "name": "Rock_Stone",
      "rotation": 2
    },
    {
      "x": 1,
      "y": 8,
      "z": 2,
      "name": "Rock_Stone",
      "rotation": 2
    },
    {
      "x": 1,
      "y": 0,
      "z": 3,
      "name": "Rock_Basalt"
    },
    {
      "x": 1,
      "y": 1,
      "z": 3,
      "name": "Rock_Basalt",
      "rotation": 2
    },
    {
      "x": 1,
      "y": 2,
      "z": 3,
      "name": "Rock_Basalt",
      "rotation": 2
    },
    {
      "x": 1,
      "y": 3,
      "z": 3,
      "name": "Rock_Basalt",
      "rotation": 2
    },
    {
      "x": 1,
      "y": 4,
      "z": 3,
      "name": "Rock_Stone",
      "rotation": 2
    },
    {
      "x": 1,
      "y": 5,
      "z": 3,
      "name": "Rock_Stone",
      "rotation": 2
    },
    {
      "x": 1,
      "y": 6,
      "z": 3,
      "name": "Rock_Stone",
      "rotation": 2
    },
    {
      "x": 1,
      "y": 7,
      "z": 3,
      "name": "Rock_Stone",
      "rotation": 2
    },
    {
      "x": 1,
      "y": 8,
      "z": 3,
      "name": "Rock_Stone",
      "rotation": 2
    },
    {
      "x": 1,
      "y": 9,
      "z": 3,
      "name": "Soil_Clay_Grey",
      "rotation": 2
    },
    {
      "x": 1,
      "y": 10,
      "z": 3,
      "name": "Soil_Clay_Grey",
      "rotation": 2
    },
    {
      "x": 1,
      "y": 11,
      "z": 3,
      "name": "Soil_Clay_Grey",
      "rotation": 2
    },
    {
      "x": 1,
      "y": 12,
      "z": 3,
      "name": "Soil_Clay_Grey",
      "rotation": 2
    },
    {
      "x": 1,
      "y": 13,
      "z": 3,
      "name": "Soil_Clay_White",
      "rotation": 2
    },
    {
      "x": 1,
      "y": 14,
      "z": 3,
      "name": "Soil_Clay_White",
      "rotation": 2
    },
    {
      "x": 1,
      "y": 15,
      "z": 3,
      "name": "Soil_Clay_Smooth_Red",
      "rotation": 2
    },
    {
      "x": 1,
      "y": 16,
      "z": 3,
      "name": "Soil_Clay_Smooth_Red",
      "rotation": 2
    },
    {
      "x": 1,
      "y": 17,
      "z": 3,
      "name": "Soil_Clay_Smooth_Red",
      "rotation": 2
    },
    {
      "x": 1,
      "y": 18,
      "z": 3,
      "name": "Soil_Clay_Smooth_Red",
      "rotation": 2
    },
    {
      "x": 1,
      "y": 19,
      "z": 3,
      "name": "Soil_Clay_White",
      "rotation": 2
    },
    {
      "x": 1,
      "y": 20,
      "z": 3,
      "name": "Soil_Clay_White",
      "rotation": 2
    },
    {
      "x": 1,
      "y": 21,
      "z": 3,
      "name": "Soil_Clay_White",
      "rotation": 2
    },
    {
      "x": 1,
      "y": 22,
      "z": 3,
      "name": "Soil_Clay_White",
      "rotation": 2
    },
    {
      "x": 1,
      "y": 23,
      "z": 3,
      "name": "Soil_Clay_Smooth_Red",
      "rotation": 2
    },
    {
      "x": 1,
      "y": 24,
      "z": 3,
      "name": "Soil_Clay_Smooth_Red",
      "rotation": 2
    },
    {
      "x": 1,
      "y": 25,
      "z": 3,
      "name": "Soil_Clay_Smooth_Red",
      "rotation": 2
    },
    {
      "x": 1,
      "y": 26,
      "z": 3,
      "name": "Soil_Clay_Smooth_Red",
      "rotation": 2
    },
    {
      "x": 1,
      "y": 27,
      "z": 3,
      "name": "Soil_Clay_White",
      "rotation": 2
    },
    {
      "x": 1,
      "y": 28,
      "z": 3,
      "name": "Soil_Clay_White",
      "rotation": 2
    },
    {
      "x": 1,
      "y": 29,
      "z": 3,
      "name": "Soil_Clay_White",
      "rotation": 2
    },
    {
      "x": 1,
      "y": 30,
      "z": 3,
      "name": "Soil_Clay_White",
      "rotation": 2
    },
    {
      "x": 1,
      "y": 31,
      "z": 3,
      "name": "Soil_Clay_Grey",
      "rotation": 2
    },
    {
      "x": 1,
      "y": 32,
      "z": 3,
      "name": "Soil_Clay_Grey",
      "rotation": 2
    },
    {
      "x": 1,
      "y": 35,
      "z": 3,
      "name": "Soil_Clay_Grey",
      "rotation": 2
    },
    {
      "x": 1,
      "y": 0,
      "z": 4,
      "name": "Rock_Basalt"
    },
    {
      "x": 1,
      "y": 1,
      "z": 4,
      "name": "Rock_Basalt",
      "rotation": 2
    },
    {
      "x": 1,
      "y": 2,
      "z": 4,
      "name": "Rock_Basalt",
      "rotation": 2
    },
    {
      "x": 1,
      "y": 3,
      "z": 4,
      "name": "Rock_Basalt",
      "rotation": 2
    },
    {
      "x": 1,
      "y": 4,
      "z": 4,
      "name": "Rock_Stone",
      "rotation": 2
    },
    {
      "x": 1,
      "y": 5,
      "z": 4,
      "name": "Rock_Stone",
      "rotation": 2
    },
    {
      "x": 1,
      "y": 6,
      "z": 4,
      "name": "Rock_Stone",
      "rotation": 2
    },
    {
      "x": 1,
      "y": 7,
      "z": 4,
      "name": "Rock_Stone",
      "rotation": 2
    },
    {
      "x": 1,
      "y": 8,
      "z": 4,
      "name": "Rock_Stone",
      "rotation": 2
    },
    {
      "x": 1,
      "y": 9,
      "z": 4,
      "name": "Soil_Clay_Smooth_Grey_Stairs",
      "rotation": 3
    },
    {
      "x": 1,
      "y": 10,
      "z": 4,
      "name": "Soil_Clay_Smooth_Grey_Half",
      "rotation": 7
    },
    {
      "x": 1,
      "y": 11,
      "z": 4,
      "name": "Soil_Clay_Smooth_Grey_Half",
      "rotation": 7
    },
    {
      "x": 1,
      "y": 12,
      "z": 4,
      "name": "Soil_Clay_Smooth_Grey_Stairs",
      "rotation": 9
    },
    {
      "x": 1,
      "y": 13,
      "z": 4,
      "name": "Soil_Clay_White",
      "rotation": 2
    },
    {
      "x": 1,
      "y": 14,
      "z": 4,
      "name": "Soil_Clay_White",
      "rotation": 2
    },
    {
      "x": 1,
      "y": 15,
      "z": 4,
      "name": "Soil_Clay_Smooth_Red",
      "rotation": 2
    },
    {
      "x": 1,
      "y": 16,
      "z": 4,
      "name": "Soil_Clay_Smooth_Red",
      "rotation": 2
    },
    {
      "x": 1,
      "y": 17,
      "z": 4,
      "name": "Soil_Clay_Smooth_Grey_Stairs",
      "rotation": 3
    },
    {
      "x": 1,
      "y": 20,
      "z": 4,
      "name": "Soil_Clay_Smooth_Grey_Stairs",
      "rotation": 9
    },
    {
      "x": 1,
      "y": 21,
      "z": 4,
      "name": "Soil_Clay_White",
      "rotation": 2
    },
    {
      "x": 1,
      "y": 22,
      "z": 4,
      "name": "Soil_Clay_White",
      "rotation": 2
    },
    {
      "x": 1,
      "y": 23,
      "z": 4,
      "name": "Soil_Clay_Smooth_Red",
      "rotation": 2
    },
    {
      "x": 1,
      "y": 24,
      "z": 4,
      "name": "Soil_Clay_Smooth_Red",
      "rotation": 2
    },
    {
      "x": 1,
      "y": 25,
      "z": 4,
      "name": "Soil_Clay_Smooth_Grey_Stairs",
      "rotation": 3
    },
    {
      "x": 1,
      "y": 28,
      "z": 4,
      "name": "Soil_Clay_Smooth_Grey_Stairs",
      "rotation": 9
    },
    {
      "x": 1,
      "y": 29,
      "z": 4,
      "name": "Soil_Clay_White",
      "rotation": 2
    },
    {
      "x": 1,
      "y": 30,
      "z": 4,
      "name": "Soil_Clay_White",
      "rotation": 2
    },
    {
      "x": 1,
      "y": 31,
      "z": 4,
      "name": "Soil_Clay_Grey",
      "rotation": 2
    },
    {
      "x": 1,
      "y": 32,
      "z": 4,
      "name": "Soil_Clay_Grey",
      "rotation": 2
    },
    {
      "x": 1,
      "y": 35,
      "z": 4,
      "name": "Soil_Clay_Grey",
      "rotation": 2
    },
    {
      "x": 1,
      "y": 0,
      "z": 5,
      "name": "Rock_Basalt"
    },
    {
      "x": 1,
      "y": 1,
      "z": 5,
      "name": "Rock_Basalt",
      "rotation": 2
    },
    {
      "x": 1,
      "y": 2,
      "z": 5,
      "name": "Rock_Basalt",
      "rotation": 2
    },
    {
      "x": 1,
      "y": 3,
      "z": 5,
      "name": "Rock_Basalt",
      "rotation": 2
    },
    {
      "x": 1,
      "y": 4,
      "z": 5,
      "name": "Rock_Stone",
      "rotation": 2
    },
    {
      "x": 1,
      "y": 5,
      "z": 5,
      "name": "Rock_Stone",
      "rotation": 2
    },
    {
      "x": 1,
      "y": 6,
      "z": 5,
      "name": "Rock_Stone",
      "rotation": 2
    },
    {
      "x": 1,
      "y": 7,
      "z": 5,
      "name": "Rock_Stone",
      "rotation": 2
    },
    {
      "x": 1,
      "y": 8,
      "z": 5,
      "name": "Rock_Stone",
      "rotation": 2
    },
    {
      "x": 1,
      "y": 9,
      "z": 5,
      "name": "Soil_Clay_Grey",
      "rotation": 2
    },
    {
      "x": 1,
      "y": 10,
      "z": 5,
      "name": "Soil_Clay_Grey",
      "rotation": 2
    },
    {
      "x": 1,
      "y": 11,
      "z": 5,
      "name": "Soil_Clay_Grey",
      "rotation": 2
    },
    {
      "x": 1,
      "y": 12,
      "z": 5,
      "name": "Soil_Clay_Grey",
      "rotation": 2
    },
    {
      "x": 1,
      "y": 13,
      "z": 5,
      "name": "Soil_Clay_White",
      "rotation": 2
    },
    {
      "x": 1,
      "y": 14,
      "z": 5,
      "name": "Soil_Clay_White",
      "rotation": 2
    },
    {
      "x": 1,
      "y": 15,
      "z": 5,
      "name": "Soil_Clay_Smooth_Red",
      "rotation": 2
    },
    {
      "x": 1,
      "y": 16,
      "z": 5,
      "name": "Soil_Clay_Smooth_Red",
      "rotation": 2
    },
    {
      "x": 1,
      "y": 17,
      "z": 5,
      "name": "Soil_Clay_Smooth_Red",
      "rotation": 2
    },
    {
      "x": 1,
      "y": 18,
      "z": 5,
      "name": "Soil_Clay_Smooth_Red",
      "rotation": 2
    },
    {
      "x": 1,
      "y": 19,
      "z": 5,
      "name": "Soil_Clay_White",
      "rotation": 2
    },
    {
      "x": 1,
      "y": 20,
      "z": 5,
      "name": "Soil_Clay_White",
      "rotation": 2
    },
    {
      "x": 1,
      "y": 21,
      "z": 5,
      "name": "Soil_Clay_White",
      "rotation": 2
    },
    {
      "x": 1,
      "y": 22,
      "z": 5,
      "name": "Soil_Clay_White",
      "rotation": 2
    },
    {
      "x": 1,
      "y": 23,
      "z": 5,
      "name": "Soil_Clay_Smooth_Red",
      "rotation": 2
    },
    {
      "x": 1,
      "y": 24,
      "z": 5,
      "name": "Soil_Clay_Smooth_Red",
      "rotation": 2
    },
    {
      "x": 1,
      "y": 25,
      "z": 5,
      "name": "Soil_Clay_Smooth_Red",
      "rotation": 2
    },
    {
      "x": 1,
      "y": 26,
      "z": 5,
      "name": "Soil_Clay_Smooth_Red",
      "rotation": 2
    },
    {
      "x": 1,
      "y": 27,
      "z": 5,
      "name": "Soil_Clay_White",
      "rotation": 2
    },
    {
      "x": 1,
      "y": 28,
      "z": 5,
      "name": "Soil_Clay_White",
      "rotation": 2
    },
    {
      "x": 1,
      "y": 29,
      "z": 5,
      "name": "Soil_Clay_White",
      "rotation": 2
    },
    {
      "x": 1,
      "y": 30,
      "z": 5,
      "name": "Soil_Clay_White",
      "rotation": 2
    },
    {
      "x": 1,
      "y": 31,
      "z": 5,
      "name": "Soil_Clay_Grey",
      "rotation": 2
    },
    {
      "x": 1,
      "y": 32,
      "z": 5,
      "name": "Soil_Clay_Grey",
      "rotation": 2
    },
    {
      "x": 1,
      "y": 35,
      "z": 5,
      "name": "Soil_Clay_Grey",
      "rotation": 2
    },
    {
      "x": 1,
      "y": 0,
      "z": 6,
      "name": "Rock_Basalt"
    },
    {
      "x": 1,
      "y": 1,
      "z": 6,
      "name": "Rock_Basalt",
      "rotation": 2
    },
    {
      "x": 1,
      "y": 2,
      "z": 6,
      "name": "Rock_Basalt",
      "rotation": 2
    },
    {
      "x": 1,
      "y": 3,
      "z": 6,
      "name": "Rock_Basalt",
      "rotation": 2
    },
    {
      "x": 1,
      "y": 4,
      "z": 6,
      "name": "Rock_Stone",
      "rotation": 2
    },
    {
      "x": 1,
      "y": 5,
      "z": 6,
      "name": "Rock_Stone",
      "rotation": 2
    },
    {
      "x": 1,
      "y": 6,
      "z": 6,
      "name": "Rock_Stone",
      "rotation": 2
    },
    {
      "x": 1,
      "y": 7,
      "z": 6,
      "name": "Rock_Stone",
      "rotation": 2
    },
    {
      "x": 1,
      "y": 8,
      "z": 6,
      "name": "Rock_Stone",
      "rotation": 2
    },
    {
      "x": 1,
      "y": 0,
      "z": 7,
      "name": "Rock_Basalt"
    },
    {
      "x": 1,
      "y": 1,
      "z": 7,
      "name": "Rock_Basalt",
      "rotation": 2
    },
    {
      "x": 1,
      "y": 2,
      "z": 7,
      "name": "Rock_Basalt",
      "rotation": 2
    },
    {
      "x": 1,
      "y": 3,
      "z": 7,
      "name": "Rock_Basalt",
      "rotation": 2
    },
    {
      "x": 1,
      "y": 4,
      "z": 7,
      "name": "Rock_Stone",
      "rotation": 2
    },
    {
      "x": 1,
      "y": 5,
      "z": 7,
      "name": "Rock_Stone",
      "rotation": 2
    },
    {
      "x": 1,
      "y": 6,
      "z": 7,
      "name": "Rock_Stone",
      "rotation": 2
    },
    {
      "x": 1,
      "y": 7,
      "z": 7,
      "name": "Rock_Stone",
      "rotation": 2
    },
    {
      "x": 1,
      "y": 8,
      "z": 7,
      "name": "Rock_Stone",
      "rotation": 2
    },
    {
      "x": 2,
      "y": 0,
      "z": -6,
      "name": "Ore_Iron_Basalt_Cracked"
    },
    {
      "x": 2,
      "y": 1,
      "z": -6,
      "name": "Empty"
    },
    {
      "x": 2,
      "y": 2,
      "z": -6,
      "name": "Empty"
    },
    {
      "x": 2,
      "y": 3,
      "z": -6,
      "name": "Empty",
      "rotation": 3
    },
    {
      "x": 2,
      "y": 0,
      "z": -5,
      "name": "Ore_Iron_Basalt_Cracked"
    },
    {
      "x": 2,
      "y": 1,
      "z": -5,
      "name": "Empty"
    },
    {
      "x": 2,
      "y": 2,
      "z": -5,
      "name": "Empty"
    },
    {
      "x": 2,
      "y": 3,
      "z": -5,
      "name": "Empty",
      "rotation": 3
    },
    {
      "x": 2,
      "y": 0,
      "z": -4,
      "name": "Rock_Basalt_Cobble"
    },
    {
      "x": 2,
      "y": 1,
      "z": -4,
      "name": "Empty"
    },
    {
      "x": 2,
      "y": 2,
      "z": -4,
      "name": "Empty"
    },
    {
      "x": 2,
      "y": 3,
      "z": -4,
      "name": "Empty",
      "rotation": 3
    },
    {
      "x": 2,
      "y": 0,
      "z": -3,
      "name": "Rock_Basalt"
    },
    {
      "x": 2,
      "y": 1,
      "z": -3,
      "name": "Rock_Basalt",
      "rotation": 3
    },
    {
      "x": 2,
      "y": 2,
      "z": -3,
      "name": "Empty"
    },
    {
      "x": 2,
      "y": 3,
      "z": -3,
      "name": "Empty",
      "rotation": 3
    },
    {
      "x": 2,
      "y": 0,
      "z": -2,
      "name": "Rock_Basalt"
    },
    {
      "x": 2,
      "y": 1,
      "z": -2,
      "name": "Rock_Basalt",
      "rotation": 3
    },
    {
      "x": 2,
      "y": 2,
      "z": -2,
      "name": "Rock_Basalt",
      "rotation": 3
    },
    {
      "x": 2,
      "y": 3,
      "z": -2,
      "name": "Empty",
      "rotation": 3
    },
    {
      "x": 2,
      "y": 0,
      "z": -1,
      "name": "Rock_Basalt"
    },
    {
      "x": 2,
      "y": 1,
      "z": -1,
      "name": "Rock_Basalt",
      "rotation": 3
    },
    {
      "x": 2,
      "y": 2,
      "z": -1,
      "name": "Rock_Basalt",
      "rotation": 3
    },
    {
      "x": 2,
      "y": 3,
      "z": -1,
      "name": "Rock_Basalt",
      "rotation": 3
    },
    {
      "x": 2,
      "y": 4,
      "z": -1,
      "name": "Rock_Stone",
      "rotation": 3
    },
    {
      "x": 2,
      "y": 5,
      "z": -1,
      "name": "Rock_Stone_Mossy",
      "rotation": 3
    },
    {
      "x": 2,
      "y": 6,
      "z": -1,
      "name": "Rock_Stone_Mossy",
      "rotation": 3
    },
    {
      "x": 2,
      "y": 0,
      "z": 0,
      "name": "Rock_Basalt"
    },
    {
      "x": 2,
      "y": 1,
      "z": 0,
      "name": "Rock_Basalt",
      "rotation": 3
    },
    {
      "x": 2,
      "y": 2,
      "z": 0,
      "name": "Rock_Basalt",
      "rotation": 3
    },
    {
      "x": 2,
      "y": 3,
      "z": 0,
      "name": "Rock_Basalt",
      "rotation": 3
    },
    {
      "x": 2,
      "y": 4,
      "z": 0,
      "name": "Rock_Stone",
      "rotation": 3
    },
    {
      "x": 2,
      "y": 5,
      "z": 0,
      "name": "Rock_Stone",
      "rotation": 3
    },
    {
      "x": 2,
      "y": 6,
      "z": 0,
      "name": "Rock_Stone",
      "rotation": 3
    },
    {
      "x": 2,
      "y": 7,
      "z": 0,
      "name": "Rock_Stone",
      "rotation": 3
    },
    {
      "x": 2,
      "y": 8,
      "z": 0,
      "name": "Rock_Stone",
      "rotation": 3
    },
    {
      "x": 2,
      "y": 0,
      "z": 1,
      "name": "Rock_Basalt"
    },
    {
      "x": 2,
      "y": 1,
      "z": 1,
      "name": "Rock_Basalt",
      "rotation": 2
    },
    {
      "x": 2,
      "y": 2,
      "z": 1,
      "name": "Rock_Basalt",
      "rotation": 2
    },
    {
      "x": 2,
      "y": 3,
      "z": 1,
      "name": "Rock_Basalt",
      "rotation": 2
    },
    {
      "x": 2,
      "y": 4,
      "z": 1,
      "name": "Rock_Stone",
      "rotation": 2
    },
    {
      "x": 2,
      "y": 5,
      "z": 1,
      "name": "Rock_Stone",
      "rotation": 2
    },
    {
      "x": 2,
      "y": 6,
      "z": 1,
      "name": "Rock_Stone",
      "rotation": 2
    },
    {
      "x": 2,
      "y": 7,
      "z": 1,
      "name": "Rock_Stone",
      "rotation": 2
    },
    {
      "x": 2,
      "y": 8,
      "z": 1,
      "name": "Rock_Stone",
      "rotation": 2
    },
    {
      "x": 2,
      "y": 0,
      "z": 2,
      "name": "Rock_Basalt"
    },
    {
      "x": 2,
      "y": 1,
      "z": 2,
      "name": "Rock_Basalt",
      "rotation": 2
    },
    {
      "x": 2,
      "y": 2,
      "z": 2,
      "name": "Rock_Basalt",
      "rotation": 2
    },
    {
      "x": 2,
      "y": 3,
      "z": 2,
      "name": "Rock_Basalt",
      "rotation": 2
    },
    {
      "x": 2,
      "y": 4,
      "z": 2,
      "name": "Rock_Stone",
      "rotation": 2
    },
    {
      "x": 2,
      "y": 5,
      "z": 2,
      "name": "Rock_Stone",
      "rotation": 2
    },
    {
      "x": 2,
      "y": 6,
      "z": 2,
      "name": "Rock_Stone",
      "rotation": 2
    },
    {
      "x": 2,
      "y": 7,
      "z": 2,
      "name": "Rock_Stone",
      "rotation": 2
    },
    {
      "x": 2,
      "y": 8,
      "z": 2,
      "name": "Rock_Stone",
      "rotation": 2
    },
    {
      "x": 2,
      "y": 9,
      "z": 2,
      "name": "Soil_Clay_Grey",
      "rotation": 2
    },
    {
      "x": 2,
      "y": 10,
      "z": 2,
      "name": "Soil_Clay_Grey",
      "rotation": 2
    },
    {
      "x": 2,
      "y": 11,
      "z": 2,
      "name": "Soil_Clay_Grey",
      "rotation": 2
    },
    {
      "x": 2,
      "y": 12,
      "z": 2,
      "name": "Soil_Clay_Grey",
      "rotation": 2
    },
    {
      "x": 2,
      "y": 13,
      "z": 2,
      "name": "Soil_Clay_White",
      "rotation": 2
    },
    {
      "x": 2,
      "y": 14,
      "z": 2,
      "name": "Soil_Clay_White",
      "rotation": 2
    },
    {
      "x": 2,
      "y": 15,
      "z": 2,
      "name": "Soil_Clay_Smooth_Red",
      "rotation": 2
    },
    {
      "x": 2,
      "y": 16,
      "z": 2,
      "name": "Soil_Clay_Smooth_Red",
      "rotation": 2
    },
    {
      "x": 2,
      "y": 17,
      "z": 2,
      "name": "Soil_Clay_Smooth_Red",
      "rotation": 2
    },
    {
      "x": 2,
      "y": 18,
      "z": 2,
      "name": "Soil_Clay_Smooth_Red",
      "rotation": 2
    },
    {
      "x": 2,
      "y": 19,
      "z": 2,
      "name": "Soil_Clay_White",
      "rotation": 2
    },
    {
      "x": 2,
      "y": 20,
      "z": 2,
      "name": "Soil_Clay_White",
      "rotation": 2
    },
    {
      "x": 2,
      "y": 21,
      "z": 2,
      "name": "Soil_Clay_White",
      "rotation": 2
    },
    {
      "x": 2,
      "y": 22,
      "z": 2,
      "name": "Soil_Clay_White",
      "rotation": 2
    },
    {
      "x": 2,
      "y": 23,
      "z": 2,
      "name": "Soil_Clay_Smooth_Red",
      "rotation": 2
    },
    {
      "x": 2,
      "y": 24,
      "z": 2,
      "name": "Soil_Clay_Smooth_Red",
      "rotation": 2
    },
    {
      "x": 2,
      "y": 25,
      "z": 2,
      "name": "Soil_Clay_Smooth_Red",
      "rotation": 2
    },
    {
      "x": 2,
      "y": 26,
      "z": 2,
      "name": "Soil_Clay_Smooth_Red",
      "rotation": 2
    },
    {
      "x": 2,
      "y": 27,
      "z": 2,
      "name": "Soil_Clay_White",
      "rotation": 2
    },
    {
      "x": 2,
      "y": 28,
      "z": 2,
      "name": "Soil_Clay_White",
      "rotation": 2
    },
    {
      "x": 2,
      "y": 29,
      "z": 2,
      "name": "Soil_Clay_White",
      "rotation": 2
    },
    {
      "x": 2,
      "y": 30,
      "z": 2,
      "name": "Soil_Clay_White",
      "rotation": 2
    },
    {
      "x": 2,
      "y": 31,
      "z": 2,
      "name": "Soil_Clay_Grey",
      "rotation": 2
    },
    {
      "x": 2,
      "y": 32,
      "z": 2,
      "name": "Soil_Clay_Grey",
      "rotation": 2
    },
    {
      "x": 2,
      "y": 35,
      "z": 2,
      "name": "Soil_Clay_Grey",
      "rotation": 2
    },
    {
      "x": 2,
      "y": 0,
      "z": 3,
      "name": "Rock_Basalt"
    },
    {
      "x": 2,
      "y": 1,
      "z": 3,
      "name": "Rock_Basalt",
      "rotation": 2
    },
    {
      "x": 2,
      "y": 2,
      "z": 3,
      "name": "Rock_Basalt",
      "rotation": 2
    },
    {
      "x": 2,
      "y": 3,
      "z": 3,
      "name": "Rock_Basalt",
      "rotation": 2
    },
    {
      "x": 2,
      "y": 4,
      "z": 3,
      "name": "Rock_Stone",
      "rotation": 2
    },
    {
      "x": 2,
      "y": 5,
      "z": 3,
      "name": "Rock_Stone",
      "rotation": 2
    },
    {
      "x": 2,
      "y": 6,
      "z": 3,
      "name": "Rock_Stone",
      "rotation": 2
    },
    {
      "x": 2,
      "y": 7,
      "z": 3,
      "name": "Rock_Stone",
      "rotation": 2
    },
    {
      "x": 2,
      "y": 8,
      "z": 3,
      "name": "Rock_Stone",
      "rotation": 2
    },
    {
      "x": 2,
      "y": 31,
      "z": 3,
      "name": "Soil_Clay_Grey",
      "rotation": 2
    },
    {
      "x": 2,
      "y": 32,
      "z": 3,
      "name": "Soil_Clay_Grey",
      "rotation": 2
    },
    {
      "x": 2,
      "y": 33,
      "z": 3,
      "name": "Soil_Clay_Grey",
      "rotation": 2
    },
    {
      "x": 2,
      "y": 34,
      "z": 3,
      "name": "Soil_Clay_Grey",
      "rotation": 2
    },
    {
      "x": 2,
      "y": 35,
      "z": 3,
      "name": "Soil_Clay_Grey",
      "rotation": 2
    },
    {
      "x": 2,
      "y": 36,
      "z": 3,
      "name": "Soil_Clay_Grey",
      "rotation": 2
    },
    {
      "x": 2,
      "y": 0,
      "z": 4,
      "name": "Rock_Basalt"
    },
    {
      "x": 2,
      "y": 1,
      "z": 4,
      "name": "Rock_Basalt",
      "rotation": 2
    },
    {
      "x": 2,
      "y": 2,
      "z": 4,
      "name": "Rock_Basalt",
      "rotation": 2
    },
    {
      "x": 2,
      "y": 3,
      "z": 4,
      "name": "Rock_Basalt",
      "rotation": 2
    },
    {
      "x": 2,
      "y": 4,
      "z": 4,
      "name": "Rock_Stone",
      "rotation": 2
    },
    {
      "x": 2,
      "y": 5,
      "z": 4,
      "name": "Rock_Stone",
      "rotation": 2
    },
    {
      "x": 2,
      "y": 6,
      "z": 4,
      "name": "Rock_Stone",
      "rotation": 2
    },
    {
      "x": 2,
      "y": 7,
      "z": 4,
      "name": "Rock_Stone",
      "rotation": 2
    },
    {
      "x": 2,
      "y": 8,
      "z": 4,
      "name": "Rock_Stone",
      "rotation": 2
    },
    {
      "x": 2,
      "y": 17,
      "z": 4,
      "name": "Soil_Clay_Smooth_Black",
      "rotation": 2
    },
    {
      "x": 2,
      "y": 18,
      "z": 4,
      "name": "Soil_Clay_Smooth_Black",
      "rotation": 2
    },
    {
      "x": 2,
      "y": 19,
      "z": 4,
      "name": "Soil_Clay_Smooth_Black",
      "rotation": 2
    },
    {
      "x": 2,
      "y": 25,
      "z": 4,
      "name": "Soil_Clay_Smooth_Black",
      "rotation": 2
    },
    {
      "x": 2,
      "y": 26,
      "z": 4,
      "name": "Soil_Clay_Smooth_Black",
      "rotation": 2
    },
    {
      "x": 2,
      "y": 27,
      "z": 4,
      "name": "Soil_Clay_Smooth_Black",
      "rotation": 2
    },
    {
      "x": 2,
      "y": 31,
      "z": 4,
      "name": "Soil_Clay_Grey",
      "rotation": 2
    },
    {
      "x": 2,
      "y": 36,
      "z": 4,
      "name": "Soil_Clay_Grey",
      "rotation": 2
    },
    {
      "x": 2,
      "y": 0,
      "z": 5,
      "name": "Rock_Basalt"
    },
    {
      "x": 2,
      "y": 1,
      "z": 5,
      "name": "Rock_Basalt",
      "rotation": 2
    },
    {
      "x": 2,
      "y": 2,
      "z": 5,
      "name": "Rock_Basalt",
      "rotation": 2
    },
    {
      "x": 2,
      "y": 3,
      "z": 5,
      "name": "Rock_Basalt",
      "rotation": 2
    },
    {
      "x": 2,
      "y": 4,
      "z": 5,
      "name": "Rock_Stone",
      "rotation": 2
    },
    {
      "x": 2,
      "y": 5,
      "z": 5,
      "name": "Rock_Stone",
      "rotation": 2
    },
    {
      "x": 2,
      "y": 6,
      "z": 5,
      "name": "Rock_Stone",
      "rotation": 2
    },
    {
      "x": 2,
      "y": 7,
      "z": 5,
      "name": "Rock_Stone",
      "rotation": 2
    },
    {
      "x": 2,
      "y": 8,
      "z": 5,
      "name": "Rock_Stone",
      "rotation": 2
    },
    {
      "x": 2,
      "y": 31,
      "z": 5,
      "name": "Soil_Clay_Grey",
      "rotation": 2
    },
    {
      "x": 2,
      "y": 32,
      "z": 5,
      "name": "Soil_Clay_Grey",
      "rotation": 2
    },
    {
      "x": 2,
      "y": 33,
      "z": 5,
      "name": "Soil_Clay_Grey",
      "rotation": 2
    },
    {
      "x": 2,
      "y": 34,
      "z": 5,
      "name": "Soil_Clay_Grey",
      "rotation": 2
    },
    {
      "x": 2,
      "y": 35,
      "z": 5,
      "name": "Soil_Clay_Grey",
      "rotation": 2
    },
    {
      "x": 2,
      "y": 36,
      "z": 5,
      "name": "Soil_Clay_Grey",
      "rotation": 2
    },
    {
      "x": 2,
      "y": 0,
      "z": 6,
      "name": "Rock_Basalt"
    },
    {
      "x": 2,
      "y": 1,
      "z": 6,
      "name": "Rock_Basalt",
      "rotation": 2
    },
    {
      "x": 2,
      "y": 2,
      "z": 6,
      "name": "Rock_Basalt",
      "rotation": 2
    },
    {
      "x": 2,
      "y": 3,
      "z": 6,
      "name": "Rock_Basalt",
      "rotation": 2
    },
    {
      "x": 2,
      "y": 4,
      "z": 6,
      "name": "Rock_Stone",
      "rotation": 2
    },
    {
      "x": 2,
      "y": 5,
      "z": 6,
      "name": "Rock_Stone",
      "rotation": 2
    },
    {
      "x": 2,
      "y": 6,
      "z": 6,
      "name": "Rock_Stone",
      "rotation": 2
    },
    {
      "x": 2,
      "y": 7,
      "z": 6,
      "name": "Rock_Stone",
      "rotation": 2
    },
    {
      "x": 2,
      "y": 8,
      "z": 6,
      "name": "Rock_Stone",
      "rotation": 2
    },
    {
      "x": 2,
      "y": 9,
      "z": 6,
      "name": "Soil_Clay_Grey",
      "rotation": 2
    },
    {
      "x": 2,
      "y": 10,
      "z": 6,
      "name": "Soil_Clay_Grey",
      "rotation": 2
    },
    {
      "x": 2,
      "y": 11,
      "z": 6,
      "name": "Soil_Clay_Grey",
      "rotation": 2
    },
    {
      "x": 2,
      "y": 12,
      "z": 6,
      "name": "Soil_Clay_Grey",
      "rotation": 2
    },
    {
      "x": 2,
      "y": 13,
      "z": 6,
      "name": "Soil_Clay_White",
      "rotation": 2
    },
    {
      "x": 2,
      "y": 14,
      "z": 6,
      "name": "Soil_Clay_White",
      "rotation": 2
    },
    {
      "x": 2,
      "y": 15,
      "z": 6,
      "name": "Soil_Clay_Smooth_Red",
      "rotation": 2
    },
    {
      "x": 2,
      "y": 16,
      "z": 6,
      "name": "Soil_Clay_Smooth_Red",
      "rotation": 2
    },
    {
      "x": 2,
      "y": 17,
      "z": 6,
      "name": "Soil_Clay_Smooth_Red",
      "rotation": 2
    },
    {
      "x": 2,
      "y": 18,
      "z": 6,
      "name": "Soil_Clay_Smooth_Red",
      "rotation": 2
    },
    {
      "x": 2,
      "y": 19,
      "z": 6,
      "name": "Soil_Clay_White",
      "rotation": 2
    },
    {
      "x": 2,
      "y": 20,
      "z": 6,
      "name": "Soil_Clay_White",
      "rotation": 2
    },
    {
      "x": 2,
      "y": 21,
      "z": 6,
      "name": "Soil_Clay_White",
      "rotation": 2
    },
    {
      "x": 2,
      "y": 22,
      "z": 6,
      "name": "Soil_Clay_White",
      "rotation": 2
    },
    {
      "x": 2,
      "y": 23,
      "z": 6,
      "name": "Soil_Clay_Smooth_Red",
      "rotation": 2
    },
    {
      "x": 2,
      "y": 24,
      "z": 6,
      "name": "Soil_Clay_Smooth_Red",
      "rotation": 2
    },
    {
      "x": 2,
      "y": 25,
      "z": 6,
      "name": "Soil_Clay_Smooth_Red",
      "rotation": 2
    },
    {
      "x": 2,
      "y": 26,
      "z": 6,
      "name": "Soil_Clay_Smooth_Red",
      "rotation": 2
    },
    {
      "x": 2,
      "y": 27,
      "z": 6,
      "name": "Soil_Clay_White",
      "rotation": 2
    },
    {
      "x": 2,
      "y": 28,
      "z": 6,
      "name": "Soil_Clay_White",
      "rotation": 2
    },
    {
      "x": 2,
      "y": 29,
      "z": 6,
      "name": "Soil_Clay_White",
      "rotation": 2
    },
    {
      "x": 2,
      "y": 30,
      "z": 6,
      "name": "Soil_Clay_White",
      "rotation": 2
    },
    {
      "x": 2,
      "y": 31,
      "z": 6,
      "name": "Soil_Clay_Grey",
      "rotation": 2
    },
    {
      "x": 2,
      "y": 32,
      "z": 6,
      "name": "Soil_Clay_Grey",
      "rotation": 2
    },
    {
      "x": 2,
      "y": 35,
      "z": 6,
      "name": "Soil_Clay_Grey",
      "rotation": 2
    },
    {
      "x": 2,
      "y": 0,
      "z": 7,
      "name": "Rock_Basalt"
    },
    {
      "x": 2,
      "y": 1,
      "z": 7,
      "name": "Rock_Basalt",
      "rotation": 2
    },
    {
      "x": 2,
      "y": 2,
      "z": 7,
      "name": "Rock_Basalt",
      "rotation": 2
    },
    {
      "x": 2,
      "y": 3,
      "z": 7,
      "name": "Rock_Basalt",
      "rotation": 2
    },
    {
      "x": 2,
      "y": 4,
      "z": 7,
      "name": "Rock_Stone",
      "rotation": 2
    },
    {
      "x": 2,
      "y": 5,
      "z": 7,
      "name": "Rock_Stone",
      "rotation": 2
    },
    {
      "x": 2,
      "y": 6,
      "z": 7,
      "name": "Rock_Stone",
      "rotation": 2
    },
    {
      "x": 2,
      "y": 7,
      "z": 7,
      "name": "Rock_Stone",
      "rotation": 2
    },
    {
      "x": 2,
      "y": 8,
      "z": 7,
      "name": "Rock_Stone",
      "rotation": 2
    },
    {
      "x": 3,
      "y": 0,
      "z": -6,
      "name": "Rock_Basalt"
    },
    {
      "x": 3,
      "y": 1,
      "z": -6,
      "name": "Empty"
    },
    {
      "x": 3,
      "y": 2,
      "z": -6,
      "name": "Empty"
    },
    {
      "x": 3,
      "y": 3,
      "z": -6,
      "name": "Empty",
      "rotation": 3
    },
    {
      "x": 3,
      "y": 0,
      "z": -5,
      "name": "Rock_Basalt"
    },
    {
      "x": 3,
      "y": 1,
      "z": -5,
      "name": "Empty"
    },
    {
      "x": 3,
      "y": 2,
      "z": -5,
      "name": "Empty"
    },
    {
      "x": 3,
      "y": 3,
      "z": -5,
      "name": "Empty",
      "rotation": 3
    },
    {
      "x": 3,
      "y": 0,
      "z": -4,
      "name": "Rock_Basalt_Cobble"
    },
    {
      "x": 3,
      "y": 1,
      "z": -4,
      "name": "Empty"
    },
    {
      "x": 3,
      "y": 2,
      "z": -4,
      "name": "Empty"
    },
    {
      "x": 3,
      "y": 3,
      "z": -4,
      "name": "Empty",
      "rotation": 3
    },
    {
      "x": 3,
      "y": 0,
      "z": -3,
      "name": "Rock_Basalt"
    },
    {
      "x": 3,
      "y": 1,
      "z": -3,
      "name": "Rock_Basalt",
      "rotation": 3
    },
    {
      "x": 3,
      "y": 2,
      "z": -3,
      "name": "Empty"
    },
    {
      "x": 3,
      "y": 3,
      "z": -3,
      "name": "Empty",
      "rotation": 3
    },
    {
      "x": 3,
      "y": 0,
      "z": -2,
      "name": "Rock_Basalt"
    },
    {
      "x": 3,
      "y": 1,
      "z": -2,
      "name": "Rock_Basalt",
      "rotation": 3
    },
    {
      "x": 3,
      "y": 2,
      "z": -2,
      "name": "Rock_Basalt",
      "rotation": 3
    },
    {
      "x": 3,
      "y": 3,
      "z": -2,
      "name": "Rock_Basalt",
      "rotation": 3
    },
    {
      "x": 3,
      "y": 4,
      "z": -2,
      "name": "Rock_Stone_Mossy",
      "rotation": 3
    },
    {
      "x": 3,
      "y": 5,
      "z": -2,
      "name": "Plant_Moss_Rug_Green",
      "rotation": 3
    },
    {
      "x": 3,
      "y": 0,
      "z": -1,
      "name": "Rock_Basalt"
    },
    {
      "x": 3,
      "y": 1,
      "z": -1,
      "name": "Rock_Basalt",
      "rotation": 3
    },
    {
      "x": 3,
      "y": 2,
      "z": -1,
      "name": "Rock_Basalt",
      "rotation": 3
    },
    {
      "x": 3,
      "y": 3,
      "z": -1,
      "name": "Rock_Basalt",
      "rotation": 3
    },
    {
      "x": 3,
      "y": 4,
      "z": -1,
      "name": "Rock_Stone",
      "rotation": 3
    },
    {
      "x": 3,
      "y": 5,
      "z": -1,
      "name": "Rock_Stone",
      "rotation": 3
    },
    {
      "x": 3,
      "y": 6,
      "z": -1,
      "name": "Rock_Stone",
      "rotation": 3
    },
    {
      "x": 3,
      "y": 0,
      "z": 0,
      "name": "Rock_Basalt"
    },
    {
      "x": 3,
      "y": 1,
      "z": 0,
      "name": "Rock_Basalt",
      "rotation": 3
    },
    {
      "x": 3,
      "y": 2,
      "z": 0,
      "name": "Rock_Basalt",
      "rotation": 3
    },
    {
      "x": 3,
      "y": 3,
      "z": 0,
      "name": "Rock_Basalt",
      "rotation": 3
    },
    {
      "x": 3,
      "y": 4,
      "z": 0,
      "name": "Rock_Stone",
      "rotation": 3
    },
    {
      "x": 3,
      "y": 5,
      "z": 0,
      "name": "Rock_Stone",
      "rotation": 3
    },
    {
      "x": 3,
      "y": 6,
      "z": 0,
      "name": "Rock_Stone",
      "rotation": 3
    },
    {
      "x": 3,
      "y": 7,
      "z": 0,
      "name": "Rock_Stone",
      "rotation": 3
    },
    {
      "x": 3,
      "y": 8,
      "z": 0,
      "name": "Rock_Stone"
    },
    {
      "x": 3,
      "y": 0,
      "z": 1,
      "name": "Rock_Basalt"
    },
    {
      "x": 3,
      "y": 1,
      "z": 1,
      "name": "Rock_Basalt",
      "rotation": 2
    },
    {
      "x": 3,
      "y": 2,
      "z": 1,
      "name": "Rock_Basalt",
      "rotation": 2
    },
    {
      "x": 3,
      "y": 3,
      "z": 1,
      "name": "Rock_Basalt",
      "rotation": 2
    },
    {
      "x": 3,
      "y": 4,
      "z": 1,
      "name": "Rock_Stone",
      "rotation": 2
    },
    {
      "x": 3,
      "y": 5,
      "z": 1,
      "name": "Rock_Stone",
      "rotation": 2
    },
    {
      "x": 3,
      "y": 6,
      "z": 1,
      "name": "Rock_Stone",
      "rotation": 2
    },
    {
      "x": 3,
      "y": 7,
      "z": 1,
      "name": "Rock_Stone",
      "rotation": 2
    },
    {
      "x": 3,
      "y": 8,
      "z": 1,
      "name": "Rock_Stone",
      "rotation": 2
    },
    {
      "x": 3,
      "y": 9,
      "z": 1,
      "name": "Soil_Clay_Grey",
      "rotation": 2
    },
    {
      "x": 3,
      "y": 10,
      "z": 1,
      "name": "Soil_Clay_Grey",
      "rotation": 2
    },
    {
      "x": 3,
      "y": 11,
      "z": 1,
      "name": "Soil_Clay_Grey",
      "rotation": 2
    },
    {
      "x": 3,
      "y": 12,
      "z": 1,
      "name": "Soil_Clay_Grey",
      "rotation": 2
    },
    {
      "x": 3,
      "y": 13,
      "z": 1,
      "name": "Soil_Clay_White",
      "rotation": 2
    },
    {
      "x": 3,
      "y": 14,
      "z": 1,
      "name": "Soil_Clay_White",
      "rotation": 2
    },
    {
      "x": 3,
      "y": 15,
      "z": 1,
      "name": "Soil_Clay_Smooth_Red",
      "rotation": 2
    },
    {
      "x": 3,
      "y": 16,
      "z": 1,
      "name": "Soil_Clay_Smooth_Red",
      "rotation": 2
    },
    {
      "x": 3,
      "y": 17,
      "z": 1,
      "name": "Soil_Clay_Smooth_Red",
      "rotation": 2
    },
    {
      "x": 3,
      "y": 18,
      "z": 1,
      "name": "Soil_Clay_Smooth_Red",
      "rotation": 2
    },
    {
      "x": 3,
      "y": 19,
      "z": 1,
      "name": "Soil_Clay_White",
      "rotation": 2
    },
    {
      "x": 3,
      "y": 20,
      "z": 1,
      "name": "Soil_Clay_White",
      "rotation": 2
    },
    {
      "x": 3,
      "y": 21,
      "z": 1,
      "name": "Soil_Clay_White",
      "rotation": 2
    },
    {
      "x": 3,
      "y": 22,
      "z": 1,
      "name": "Soil_Clay_White",
      "rotation": 2
    },
    {
      "x": 3,
      "y": 23,
      "z": 1,
      "name": "Soil_Clay_Smooth_Red",
      "rotation": 2
    },
    {
      "x": 3,
      "y": 24,
      "z": 1,
      "name": "Soil_Clay_Smooth_Red",
      "rotation": 2
    },
    {
      "x": 3,
      "y": 25,
      "z": 1,
      "name": "Soil_Clay_Smooth_Red",
      "rotation": 2
    },
    {
      "x": 3,
      "y": 26,
      "z": 1,
      "name": "Soil_Clay_Smooth_Red",
      "rotation": 2
    },
    {
      "x": 3,
      "y": 27,
      "z": 1,
      "name": "Soil_Clay_White",
      "rotation": 2
    },
    {
      "x": 3,
      "y": 28,
      "z": 1,
      "name": "Soil_Clay_White",
      "rotation": 2
    },
    {
      "x": 3,
      "y": 29,
      "z": 1,
      "name": "Soil_Clay_White",
      "rotation": 2
    },
    {
      "x": 3,
      "y": 30,
      "z": 1,
      "name": "Soil_Clay_White",
      "rotation": 2
    },
    {
      "x": 3,
      "y": 31,
      "z": 1,
      "name": "Soil_Clay_Grey",
      "rotation": 2
    },
    {
      "x": 3,
      "y": 32,
      "z": 1,
      "name": "Soil_Clay_Grey",
      "rotation": 2
    },
    {
      "x": 3,
      "y": 35,
      "z": 1,
      "name": "Soil_Clay_Grey",
      "rotation": 2
    },
    {
      "x": 3,
      "y": 0,
      "z": 2,
      "name": "Rock_Basalt"
    },
    {
      "x": 3,
      "y": 1,
      "z": 2,
      "name": "Rock_Basalt",
      "rotation": 2
    },
    {
      "x": 3,
      "y": 2,
      "z": 2,
      "name": "Rock_Basalt",
      "rotation": 2
    },
    {
      "x": 3,
      "y": 3,
      "z": 2,
      "name": "Rock_Basalt",
      "rotation": 2
    },
    {
      "x": 3,
      "y": 4,
      "z": 2,
      "name": "Rock_Stone",
      "rotation": 2
    },
    {
      "x": 3,
      "y": 5,
      "z": 2,
      "name": "Rock_Stone",
      "rotation": 2
    },
    {
      "x": 3,
      "y": 6,
      "z": 2,
      "name": "Rock_Stone",
      "rotation": 2
    },
    {
      "x": 3,
      "y": 7,
      "z": 2,
      "name": "Rock_Stone",
      "rotation": 2
    },
    {
      "x": 3,
      "y": 8,
      "z": 2,
      "name": "Rock_Stone",
      "rotation": 2
    },
    {
      "x": 3,
      "y": 31,
      "z": 2,
      "name": "Soil_Clay_Grey",
      "rotation": 2
    },
    {
      "x": 3,
      "y": 32,
      "z": 2,
      "name": "Soil_Clay_Grey",
      "rotation": 2
    },
    {
      "x": 3,
      "y": 33,
      "z": 2,
      "name": "Soil_Clay_Grey",
      "rotation": 2
    },
    {
      "x": 3,
      "y": 34,
      "z": 2,
      "name": "Soil_Clay_Grey",
      "rotation": 2
    },
    {
      "x": 3,
      "y": 35,
      "z": 2,
      "name": "Soil_Clay_Grey",
      "rotation": 2
    },
    {
      "x": 3,
      "y": 36,
      "z": 2,
      "name": "Soil_Clay_Grey",
      "rotation": 2
    },
    {
      "x": 3,
      "y": 0,
      "z": 3,
      "name": "Rock_Basalt"
    },
    {
      "x": 3,
      "y": 1,
      "z": 3,
      "name": "Rock_Basalt",
      "rotation": 2
    },
    {
      "x": 3,
      "y": 2,
      "z": 3,
      "name": "Rock_Basalt",
      "rotation": 2
    },
    {
      "x": 3,
      "y": 3,
      "z": 3,
      "name": "Rock_Basalt",
      "rotation": 2
    },
    {
      "x": 3,
      "y": 4,
      "z": 3,
      "name": "Rock_Stone",
      "rotation": 2
    },
    {
      "x": 3,
      "y": 5,
      "z": 3,
      "name": "Rock_Stone",
      "rotation": 2
    },
    {
      "x": 3,
      "y": 6,
      "z": 3,
      "name": "Rock_Stone",
      "rotation": 2
    },
    {
      "x": 3,
      "y": 7,
      "z": 3,
      "name": "Rock_Stone",
      "rotation": 2
    },
    {
      "x": 3,
      "y": 8,
      "z": 3,
      "name": "Rock_Stone",
      "rotation": 2
    },
    {
      "x": 3,
      "y": 31,
      "z": 3,
      "name": "Soil_Clay_Grey",
      "rotation": 2
    },
    {
      "x": 3,
      "y": 32,
      "z": 3,
      "name": "Soil_Clay_Grey",
      "rotation": 2
    },
    {
      "x": 3,
      "y": 33,
      "z": 3,
      "name": "Soil_Clay_Grey",
      "rotation": 2
    },
    {
      "x": 3,
      "y": 34,
      "z": 3,
      "name": "Soil_Clay_Grey",
      "rotation": 2
    },
    {
      "x": 3,
      "y": 35,
      "z": 3,
      "name": "Soil_Clay_Grey",
      "rotation": 2
    },
    {
      "x": 3,
      "y": 36,
      "z": 3,
      "name": "Soil_Clay_Grey",
      "rotation": 2
    },
    {
      "x": 3,
      "y": 37,
      "z": 3,
      "name": "Soil_Clay_Grey",
      "rotation": 2
    },
    {
      "x": 3,
      "y": 0,
      "z": 4,
      "name": "Rock_Basalt"
    },
    {
      "x": 3,
      "y": 1,
      "z": 4,
      "name": "Rock_Basalt",
      "rotation": 2
    },
    {
      "x": 3,
      "y": 2,
      "z": 4,
      "name": "Rock_Basalt",
      "rotation": 2
    },
    {
      "x": 3,
      "y": 3,
      "z": 4,
      "name": "Rock_Basalt",
      "rotation": 2
    },
    {
      "x": 3,
      "y": 4,
      "z": 4,
      "name": "Rock_Stone",
      "rotation": 2
    },
    {
      "x": 3,
      "y": 5,
      "z": 4,
      "name": "Rock_Stone",
      "rotation": 2
    },
    {
      "x": 3,
      "y": 6,
      "z": 4,
      "name": "Rock_Stone",
      "rotation": 2
    },
    {
      "x": 3,
      "y": 7,
      "z": 4,
      "name": "Rock_Stone",
      "rotation": 2
    },
    {
      "x": 3,
      "y": 8,
      "z": 4,
      "name": "Rock_Stone",
      "rotation": 2
    },
    {
      "x": 3,
      "y": 31,
      "z": 4,
      "name": "Soil_Clay_Grey",
      "rotation": 2
    },
    {
      "x": 3,
      "y": 32,
      "z": 4,
      "name": "Soil_Clay_Grey",
      "rotation": 2
    },
    {
      "x": 3,
      "y": 35,
      "z": 4,
      "name": "Soil_Clay_Grey",
      "rotation": 2
    },
    {
      "x": 3,
      "y": 36,
      "z": 4,
      "name": "Soil_Clay_Grey",
      "rotation": 2
    },
    {
      "x": 3,
      "y": 37,
      "z": 4,
      "name": "Soil_Clay_Grey",
      "rotation": 2
    },
    {
      "x": 3,
      "y": 0,
      "z": 5,
      "name": "Rock_Basalt"
    },
    {
      "x": 3,
      "y": 1,
      "z": 5,
      "name": "Rock_Basalt",
      "rotation": 2
    },
    {
      "x": 3,
      "y": 2,
      "z": 5,
      "name": "Rock_Basalt",
      "rotation": 2
    },
    {
      "x": 3,
      "y": 3,
      "z": 5,
      "name": "Rock_Basalt",
      "rotation": 2
    },
    {
      "x": 3,
      "y": 4,
      "z": 5,
      "name": "Rock_Stone",
      "rotation": 2
    },
    {
      "x": 3,
      "y": 5,
      "z": 5,
      "name": "Rock_Stone",
      "rotation": 2
    },
    {
      "x": 3,
      "y": 6,
      "z": 5,
      "name": "Rock_Stone",
      "rotation": 2
    },
    {
      "x": 3,
      "y": 7,
      "z": 5,
      "name": "Rock_Stone",
      "rotation": 2
    },
    {
      "x": 3,
      "y": 8,
      "z": 5,
      "name": "Rock_Stone",
      "rotation": 2
    },
    {
      "x": 3,
      "y": 31,
      "z": 5,
      "name": "Soil_Clay_Grey",
      "rotation": 2
    },
    {
      "x": 3,
      "y": 32,
      "z": 5,
      "name": "Soil_Clay_Grey",
      "rotation": 2
    },
    {
      "x": 3,
      "y": 33,
      "z": 5,
      "name": "Soil_Clay_Grey",
      "rotation": 2
    },
    {
      "x": 3,
      "y": 34,
      "z": 5,
      "name": "Soil_Clay_Grey",
      "rotation": 2
    },
    {
      "x": 3,
      "y": 35,
      "z": 5,
      "name": "Soil_Clay_Grey",
      "rotation": 2
    },
    {
      "x": 3,
      "y": 36,
      "z": 5,
      "name": "Soil_Clay_Grey",
      "rotation": 2
    },
    {
      "x": 3,
      "y": 37,
      "z": 5,
      "name": "Soil_Clay_Grey",
      "rotation": 2
    },
    {
      "x": 3,
      "y": 0,
      "z": 6,
      "name": "Rock_Basalt"
    },
    {
      "x": 3,
      "y": 1,
      "z": 6,
      "name": "Rock_Basalt",
      "rotation": 2
    },
    {
      "x": 3,
      "y": 2,
      "z": 6,
      "name": "Rock_Basalt",
      "rotation": 2
    },
    {
      "x": 3,
      "y": 3,
      "z": 6,
      "name": "Rock_Basalt",
      "rotation": 2
    },
    {
      "x": 3,
      "y": 4,
      "z": 6,
      "name": "Rock_Stone",
      "rotation": 2
    },
    {
      "x": 3,
      "y": 5,
      "z": 6,
      "name": "Rock_Stone",
      "rotation": 2
    },
    {
      "x": 3,
      "y": 6,
      "z": 6,
      "name": "Rock_Stone",
      "rotation": 2
    },
    {
      "x": 3,
      "y": 7,
      "z": 6,
      "name": "Rock_Stone",
      "rotation": 2
    },
    {
      "x": 3,
      "y": 8,
      "z": 6,
      "name": "Rock_Stone",
      "rotation": 2
    },
    {
      "x": 3,
      "y": 31,
      "z": 6,
      "name": "Soil_Clay_Grey",
      "rotation": 2
    },
    {
      "x": 3,
      "y": 32,
      "z": 6,
      "name": "Soil_Clay_Grey",
      "rotation": 2
    },
    {
      "x": 3,
      "y": 33,
      "z": 6,
      "name": "Soil_Clay_Grey",
      "rotation": 2
    },
    {
      "x": 3,
      "y": 34,
      "z": 6,
      "name": "Soil_Clay_Grey",
      "rotation": 2
    },
    {
      "x": 3,
      "y": 35,
      "z": 6,
      "name": "Soil_Clay_Grey",
      "rotation": 2
    },
    {
      "x": 3,
      "y": 36,
      "z": 6,
      "name": "Soil_Clay_Grey",
      "rotation": 2
    },
    {
      "x": 3,
      "y": 0,
      "z": 7,
      "name": "Rock_Basalt"
    },
    {
      "x": 3,
      "y": 1,
      "z": 7,
      "name": "Rock_Basalt",
      "rotation": 2
    },
    {
      "x": 3,
      "y": 2,
      "z": 7,
      "name": "Rock_Basalt",
      "rotation": 2
    },
    {
      "x": 3,
      "y": 3,
      "z": 7,
      "name": "Rock_Basalt",
      "rotation": 2
    },
    {
      "x": 3,
      "y": 4,
      "z": 7,
      "name": "Rock_Stone",
      "rotation": 2
    },
    {
      "x": 3,
      "y": 5,
      "z": 7,
      "name": "Rock_Stone",
      "rotation": 2
    },
    {
      "x": 3,
      "y": 6,
      "z": 7,
      "name": "Rock_Stone",
      "rotation": 2
    },
    {
      "x": 3,
      "y": 7,
      "z": 7,
      "name": "Rock_Stone",
      "rotation": 2
    },
    {
      "x": 3,
      "y": 8,
      "z": 7,
      "name": "Rock_Stone",
      "rotation": 2
    },
    {
      "x": 3,
      "y": 9,
      "z": 7,
      "name": "Soil_Clay_Grey",
      "rotation": 2
    },
    {
      "x": 3,
      "y": 10,
      "z": 7,
      "name": "Soil_Clay_Grey",
      "rotation": 2
    },
    {
      "x": 3,
      "y": 11,
      "z": 7,
      "name": "Soil_Clay_Grey",
      "rotation": 2
    },
    {
      "x": 3,
      "y": 12,
      "z": 7,
      "name": "Soil_Clay_Grey",
      "rotation": 2
    },
    {
      "x": 3,
      "y": 13,
      "z": 7,
      "name": "Soil_Clay_White",
      "rotation": 2
    },
    {
      "x": 3,
      "y": 14,
      "z": 7,
      "name": "Soil_Clay_White",
      "rotation": 2
    },
    {
      "x": 3,
      "y": 15,
      "z": 7,
      "name": "Soil_Clay_Smooth_Red",
      "rotation": 2
    },
    {
      "x": 3,
      "y": 16,
      "z": 7,
      "name": "Soil_Clay_Smooth_Red",
      "rotation": 2
    },
    {
      "x": 3,
      "y": 17,
      "z": 7,
      "name": "Soil_Clay_Smooth_Red",
      "rotation": 2
    },
    {
      "x": 3,
      "y": 18,
      "z": 7,
      "name": "Soil_Clay_Smooth_Red",
      "rotation": 2
    },
    {
      "x": 3,
      "y": 19,
      "z": 7,
      "name": "Soil_Clay_White",
      "rotation": 2
    },
    {
      "x": 3,
      "y": 20,
      "z": 7,
      "name": "Soil_Clay_White",
      "rotation": 2
    },
    {
      "x": 3,
      "y": 21,
      "z": 7,
      "name": "Soil_Clay_White",
      "rotation": 2
    },
    {
      "x": 3,
      "y": 22,
      "z": 7,
      "name": "Soil_Clay_White",
      "rotation": 2
    },
    {
      "x": 3,
      "y": 23,
      "z": 7,
      "name": "Soil_Clay_Smooth_Red",
      "rotation": 2
    },
    {
      "x": 3,
      "y": 24,
      "z": 7,
      "name": "Soil_Clay_Smooth_Red",
      "rotation": 2
    },
    {
      "x": 3,
      "y": 25,
      "z": 7,
      "name": "Soil_Clay_Smooth_Red",
      "rotation": 2
    },
    {
      "x": 3,
      "y": 26,
      "z": 7,
      "name": "Soil_Clay_Smooth_Red",
      "rotation": 2
    },
    {
      "x": 3,
      "y": 27,
      "z": 7,
      "name": "Soil_Clay_White",
      "rotation": 2
    },
    {
      "x": 3,
      "y": 28,
      "z": 7,
      "name": "Soil_Clay_White",
      "rotation": 2
    },
    {
      "x": 3,
      "y": 29,
      "z": 7,
      "name": "Soil_Clay_White",
      "rotation": 2
    },
    {
      "x": 3,
      "y": 30,
      "z": 7,
      "name": "Soil_Clay_White",
      "rotation": 2
    },
    {
      "x": 3,
      "y": 31,
      "z": 7,
      "name": "Soil_Clay_Grey",
      "rotation": 2
    },
    {
      "x": 3,
      "y": 32,
      "z": 7,
      "name": "Soil_Clay_Grey",
      "rotation": 2
    },
    {
      "x": 3,
      "y": 35,
      "z": 7,
      "name": "Soil_Clay_Grey",
      "rotation": 2
    },
    {
      "x": 4,
      "y": 0,
      "z": -6,
      "name": "Rock_Basalt"
    },
    {
      "x": 4,
      "y": 1,
      "z": -6,
      "name": "Empty"
    },
    {
      "x": 4,
      "y": 2,
      "z": -6,
      "name": "Empty"
    },
    {
      "x": 4,
      "y": 3,
      "z": -6,
      "name": "Empty",
      "rotation": 3
    },
    {
      "x": 4,
      "y": 0,
      "z": -5,
      "name": "Plant_Crop_Mushroom_Block_Green"
    },
    {
      "x": 4,
      "y": 1,
      "z": -5,
      "name": "Plant_Seaweed_Grass_Tall"
    },
    {
      "x": 4,
      "y": 2,
      "z": -5,
      "name": "Empty"
    },
    {
      "x": 4,
      "y": 3,
      "z": -5,
      "name": "Empty",
      "rotation": 3
    },
    {
      "x": 4,
      "y": 0,
      "z": -4,
      "name": "Ore_Iron_Basalt_Cracked"
    },
    {
      "x": 4,
      "y": 1,
      "z": -4,
      "name": "Empty"
    },
    {
      "x": 4,
      "y": 2,
      "z": -4,
      "name": "Empty"
    },
    {
      "x": 4,
      "y": 3,
      "z": -4,
      "name": "Empty",
      "rotation": 3
    },
    {
      "x": 4,
      "y": 0,
      "z": -3,
      "name": "Rock_Basalt"
    },
    {
      "x": 4,
      "y": 1,
      "z": -3,
      "name": "Rock_Basalt",
      "rotation": 3
    },
    {
      "x": 4,
      "y": 2,
      "z": -3,
      "name": "Empty"
    },
    {
      "x": 4,
      "y": 3,
      "z": -3,
      "name": "Empty",
      "rotation": 3
    },
    {
      "x": 4,
      "y": 0,
      "z": -2,
      "name": "Rock_Basalt"
    },
    {
      "x": 4,
      "y": 1,
      "z": -2,
      "name": "Rock_Basalt",
      "rotation": 3
    },
    {
      "x": 4,
      "y": 2,
      "z": -2,
      "name": "Rock_Basalt",
      "rotation": 3
    },
    {
      "x": 4,
      "y": 3,
      "z": -2,
      "name": "Empty",
      "rotation": 3
    },
    {
      "x": 4,
      "y": 0,
      "z": -1,
      "name": "Rock_Basalt"
    },
    {
      "x": 4,
      "y": 1,
      "z": -1,
      "name": "Rock_Basalt",
      "rotation": 3
    },
    {
      "x": 4,
      "y": 2,
      "z": -1,
      "name": "Rock_Basalt",
      "rotation": 3
    },
    {
      "x": 4,
      "y": 3,
      "z": -1,
      "name": "Rock_Basalt",
      "rotation": 3
    },
    {
      "x": 4,
      "y": 4,
      "z": -1,
      "name": "Rock_Stone",
      "rotation": 3
    },
    {
      "x": 4,
      "y": 5,
      "z": -1,
      "name": "Rock_Stone_Mossy",
      "rotation": 3
    },
    {
      "x": 4,
      "y": 6,
      "z": -1,
      "name": "Rock_Stone_Mossy",
      "rotation": 3
    },
    {
      "x": 4,
      "y": 7,
      "z": -1,
      "name": "Rock_Stone_Mossy",
      "rotation": 3
    },
    {
      "x": 4,
      "y": 0,
      "z": 0,
      "name": "Rock_Basalt"
    },
    {
      "x": 4,
      "y": 1,
      "z": 0,
      "name": "Rock_Basalt",
      "rotation": 3
    },
    {
      "x": 4,
      "y": 2,
      "z": 0,
      "name": "Rock_Basalt",
      "rotation": 3
    },
    {
      "x": 4,
      "y": 3,
      "z": 0,
      "name": "Rock_Basalt",
      "rotation": 3
    },
    {
      "x": 4,
      "y": 4,
      "z": 0,
      "name": "Rock_Stone",
      "rotation": 3
    },
    {
      "x": 4,
      "y": 5,
      "z": 0,
      "name": "Rock_Stone",
      "rotation": 3
    },
    {
      "x": 4,
      "y": 6,
      "z": 0,
      "name": "Rock_Stone",
      "rotation": 3
    },
    {
      "x": 4,
      "y": 7,
      "z": 0,
      "name": "Rock_Stone",
      "rotation": 3
    },
    {
      "x": 4,
      "y": 8,
      "z": 0,
      "name": "Rock_Stone"
    },
    {
      "x": 4,
      "y": 0,
      "z": 1,
      "name": "Rock_Basalt"
    },
    {
      "x": 4,
      "y": 1,
      "z": 1,
      "name": "Rock_Basalt",
      "rotation": 2
    },
    {
      "x": 4,
      "y": 2,
      "z": 1,
      "name": "Rock_Basalt",
      "rotation": 2
    },
    {
      "x": 4,
      "y": 3,
      "z": 1,
      "name": "Rock_Basalt",
      "rotation": 2
    },
    {
      "x": 4,
      "y": 4,
      "z": 1,
      "name": "Rock_Stone",
      "rotation": 2
    },
    {
      "x": 4,
      "y": 5,
      "z": 1,
      "name": "Rock_Stone",
      "rotation": 2
    },
    {
      "x": 4,
      "y": 6,
      "z": 1,
      "name": "Rock_Stone",
      "rotation": 2
    },
    {
      "x": 4,
      "y": 7,
      "z": 1,
      "name": "Rock_Stone",
      "rotation": 2
    },
    {
      "x": 4,
      "y": 8,
      "z": 1,
      "name": "Rock_Stone",
      "rotation": 2
    },
    {
      "x": 4,
      "y": 9,
      "z": 1,
      "name": "Soil_Clay_Smooth_Grey_Stairs",
      "rotation": 2
    },
    {
      "x": 4,
      "y": 10,
      "z": 1,
      "name": "Soil_Clay_Smooth_Grey_Half",
      "rotation": 6
    },
    {
      "x": 4,
      "y": 11,
      "z": 1,
      "name": "Soil_Clay_Smooth_Grey_Half",
      "rotation": 6
    },
    {
      "x": 4,
      "y": 12,
      "z": 1,
      "name": "Soil_Clay_Smooth_Grey_Stairs",
      "rotation": 8
    },
    {
      "x": 4,
      "y": 13,
      "z": 1,
      "name": "Soil_Clay_White",
      "rotation": 2
    },
    {
      "x": 4,
      "y": 14,
      "z": 1,
      "name": "Soil_Clay_White",
      "rotation": 2
    },
    {
      "x": 4,
      "y": 15,
      "z": 1,
      "name": "Soil_Clay_Smooth_Red",
      "rotation": 2
    },
    {
      "x": 4,
      "y": 16,
      "z": 1,
      "name": "Soil_Clay_Smooth_Red",
      "rotation": 2
    },
    {
      "x": 4,
      "y": 17,
      "z": 1,
      "name": "Soil_Clay_Smooth_Grey_Stairs",
      "rotation": 2
    },
    {
      "x": 4,
      "y": 20,
      "z": 1,
      "name": "Soil_Clay_Smooth_Grey_Stairs",
      "rotation": 8
    },
    {
      "x": 4,
      "y": 21,
      "z": 1,
      "name": "Soil_Clay_White",
      "rotation": 2
    },
    {
      "x": 4,
      "y": 22,
      "z": 1,
      "name": "Soil_Clay_White",
      "rotation": 2
    },
    {
      "x": 4,
      "y": 23,
      "z": 1,
      "name": "Soil_Clay_Smooth_Red",
      "rotation": 2
    },
    {
      "x": 4,
      "y": 24,
      "z": 1,
      "name": "Soil_Clay_Smooth_Red",
      "rotation": 2
    },
    {
      "x": 4,
      "y": 25,
      "z": 1,
      "name": "Soil_Clay_Smooth_Grey_Stairs",
      "rotation": 2
    },
    {
      "x": 4,
      "y": 28,
      "z": 1,
      "name": "Soil_Clay_Smooth_Grey_Stairs",
      "rotation": 8
    },
    {
      "x": 4,
      "y": 29,
      "z": 1,
      "name": "Soil_Clay_White",
      "rotation": 2
    },
    {
      "x": 4,
      "y": 30,
      "z": 1,
      "name": "Soil_Clay_White",
      "rotation": 2
    },
    {
      "x": 4,
      "y": 31,
      "z": 1,
      "name": "Soil_Clay_Grey",
      "rotation": 2
    },
    {
      "x": 4,
      "y": 32,
      "z": 1,
      "name": "Soil_Clay_Grey",
      "rotation": 2
    },
    {
      "x": 4,
      "y": 35,
      "z": 1,
      "name": "Soil_Clay_Grey",
      "rotation": 2
    },
    {
      "x": 4,
      "y": 0,
      "z": 2,
      "name": "Rock_Basalt"
    },
    {
      "x": 4,
      "y": 1,
      "z": 2,
      "name": "Rock_Basalt",
      "rotation": 2
    },
    {
      "x": 4,
      "y": 2,
      "z": 2,
      "name": "Rock_Basalt",
      "rotation": 2
    },
    {
      "x": 4,
