{
  "version": 8,
  "blockIdVersion": 11,
  "anchorX": 0,
  "anchorY": 0,
  "anchorZ": 0,
  "blocks": [
    {
      "x": -10,
      "y": 0,
      "z": -6,
      "name": "Rock_Basalt"
    },
    {
      "x": -10,
      "y": 1,
      "z": -6,
      "name": "Rock_Basalt",
      "rotation": 1
    },
    {
      "x": -10,
      "y": 2,
      "z": -6,
      "name": "Rock_Basalt",
      "rotation": 1
    },
    {
      "x": -10,
      "y": 3,
      "z": -6,
      "name": "Rock_Basalt",
      "rotation": 1
    },
    {
      "x": -10,
      "y": 4,
      "z": -6,
      "name": "Rock_Stone",
      "rotation": 1
    },
    {
      "x": -10,
      "y": 5,
      "z": -6,
      "name": "Rock_Stone",
      "rotation": 1
    },
    {
      "x": -10,
      "y": 6,
      "z": -6,
      "name": "Rock_Stone",
      "rotation": 1
    },
    {
      "x": -10,
      "y": 7,
      "z": -6,
      "name": "Rock_Stone",
      "rotation": 1
    },
    {
      "x": -10,
      "y": 8,
      "z": -6,
      "name": "Rock_Stone",
      "rotation": 1
    },
    {
      "x": -10,
      "y": 0,
      "z": -5,
      "name": "Rock_Basalt"
    },
    {
      "x": -10,
      "y": 1,
      "z": -5,
      "name": "Rock_Basalt",
      "rotation": 1
    },
    {
      "x": -10,
      "y": 2,
      "z": -5,
      "name": "Rock_Basalt",
      "rotation": 1
    },
    {
      "x": -10,
      "y": 3,
      "z": -5,
      "name": "Rock_Basalt",
      "rotation": 1
    },
    {
      "x": -10,
      "y": 4,
      "z": -5,
      "name": "Rock_Stone",
      "rotation": 1
    },
    {
      "x": -10,
      "y": 5,
      "z": -5,
      "name": "Rock_Stone",
      "rotation": 1
    },
    {
      "x": -10,
      "y": 6,
      "z": -5,
      "name": "Rock_Stone",
      "rotation": 1
    },
    {
      "x": -10,
      "y": 7,
      "z": -5,
      "name": "Rock_Stone",
      "rotation": 1
    },
    {
      "x": -10,
      "y": 8,
      "z": -5,
      "name": "Rock_Stone",
      "rotation": 1
    },
    {
      "x": -10,
      "y": 0,
      "z": -4,
      "name": "Rock_Basalt"
    },
    {
      "x": -10,
      "y": 1,
      "z": -4,
      "name": "Rock_Basalt",
      "rotation": 1
    },
    {
      "x": -10,
      "y": 2,
      "z": -4,
      "name": "Rock_Basalt",
      "rotation": 1
    },
    {
      "x": -10,
      "y": 3,
      "z": -4,
      "name": "Rock_Basalt",
      "rotation": 1
    },
    {
      "x": -10,
      "y": 4,
      "z": -4,
      "name": "Rock_Stone",
      "rotation": 1
    },
    {
      "x": -10,
      "y": 5,
      "z": -4,
      "name": "Rock_Stone",
      "rotation": 1
    },
    {
      "x": -10,
      "y": 6,
      "z": -4,
      "name": "Rock_Stone",
      "rotation": 1
    },
    {
      "x": -10,
      "y": 7,
      "z": -4,
      "name": "Rock_Stone",
      "rotation": 1
    },
    {
      "x": -10,
      "y": 8,
      "z": -4,
      "name": "Rock_Stone",
      "rotation": 1
    },
    {
      "x": -10,
      "y": 0,
      "z": -3,
      "name": "Rock_Basalt"
    },
    {
      "x": -10,
      "y": 1,
      "z": -3,
      "name": "Rock_Basalt",
      "rotation": 1
    },
    {
      "x": -10,
      "y": 2,
      "z": -3,
      "name": "Rock_Basalt",
      "rotation": 1
    },
    {
      "x": -10,
      "y": 3,
      "z": -3,
      "name": "Rock_Basalt",
      "rotation": 1
    },
    {
      "x": -10,
      "y": 4,
      "z": -3,
      "name": "Rock_Stone",
      "rotation": 1
    },
    {
      "x": -10,
      "y": 5,
      "z": -3,
      "name": "Rock_Stone",
      "rotation": 1
    },
    {
      "x": -10,
      "y": 6,
      "z": -3,
      "name": "Rock_Stone",
      "rotation": 1
    },
    {
      "x": -10,
      "y": 7,
      "z": -3,
      "name": "Rock_Stone",
      "rotation": 1
    },
    {
      "x": -10,
      "y": 8,
      "z": -3,
      "name": "Rock_Stone_Mossy"
    },
    {
      "x": -10,
      "y": 0,
      "z": -2,
      "name": "Rock_Basalt"
    },
    {
      "x": -10,
      "y": 1,
      "z": -2,
      "name": "Rock_Basalt",
      "rotation": 1
    },
    {
      "x": -10,
      "y": 2,
      "z": -2,
      "name": "Rock_Basalt",
      "rotation": 1
    },
    {
      "x": -10,
      "y": 3,
      "z": -2,
      "name": "Rock_Basalt",
      "rotation": 1
    },
    {
      "x": -10,
      "y": 4,
      "z": -2,
      "name": "Rock_Stone",
      "rotation": 1
    },
    {
      "x": -10,
      "y": 5,
      "z": -2,
      "name": "Rock_Stone",
      "rotation": 1
    },
    {
      "x": -10,
      "y": 6,
      "z": -2,
      "name": "Rock_Stone",
      "rotation": 1
    },
    {
      "x": -10,
      "y": 7,
      "z": -2,
      "name": "Rock_Stone",
      "rotation": 1
    },
    {
      "x": -10,
      "y": 8,
      "z": -2,
      "name": "Rock_Stone",
      "rotation": 1
    },
    {
      "x": -10,
      "y": 0,
      "z": -1,
      "name": "Rock_Basalt"
    },
    {
      "x": -10,
      "y": 1,
      "z": -1,
      "name": "Rock_Basalt",
      "rotation": 1
    },
    {
      "x": -10,
      "y": 2,
      "z": -1,
      "name": "Rock_Basalt",
      "rotation": 1
    },
    {
      "x": -10,
      "y": 3,
      "z": -1,
      "name": "Rock_Basalt",
      "rotation": 1
    },
    {
      "x": -10,
      "y": 4,
      "z": -1,
      "name": "Rock_Stone",
      "rotation": 1
    },
    {
      "x": -10,
      "y": 5,
      "z": -1,
      "name": "Rock_Stone",
      "rotation": 1
    },
    {
      "x": -10,
      "y": 6,
      "z": -1,
      "name": "Rock_Stone",
      "rotation": 1
    },
    {
      "x": -10,
      "y": 7,
      "z": -1,
      "name": "Rock_Stone",
      "rotation": 1
    },
    {
      "x": -10,
      "y": 8,
      "z": -1,
      "name": "Rock_Stone"
    },
    {
      "x": -10,
      "y": 0,
      "z": 0,
      "name": "Rock_Basalt"
    },
    {
      "x": -10,
      "y": 1,
      "z": 0,
      "name": "Rock_Basalt",
      "rotation": 1
    },
    {
      "x": -10,
      "y": 2,
      "z": 0,
      "name": "Rock_Basalt",
      "rotation": 1
    },
    {
      "x": -10,
      "y": 3,
      "z": 0,
      "name": "Rock_Basalt",
      "rotation": 1
    },
    {
      "x": -10,
      "y": 4,
      "z": 0,
      "name": "Rock_Stone",
      "rotation": 1
    },
    {
      "x": -10,
      "y": 5,
      "z": 0,
      "name": "Rock_Stone",
      "rotation": 1
    },
    {
      "x": -10,
      "y": 6,
      "z": 0,
      "name": "Rock_Stone",
      "rotation": 1
    },
    {
      "x": -10,
      "y": 7,
      "z": 0,
      "name": "Rock_Stone",
      "rotation": 1
    },
    {
      "x": -10,
      "y": 8,
      "z": 0,
      "name": "Rock_Stone"
    },
    {
      "x": -10,
      "y": 0,
      "z": 1,
      "name": "Rock_Basalt"
    },
    {
      "x": -10,
      "y": 1,
      "z": 1,
      "name": "Rock_Basalt",
      "rotation": 1
    },
    {
      "x": -10,
      "y": 2,
      "z": 1,
      "name": "Rock_Basalt",
      "rotation": 1
    },
    {
      "x": -10,
      "y": 3,
      "z": 1,
      "name": "Rock_Basalt",
      "rotation": 1
    },
    {
      "x": -10,
      "y": 4,
      "z": 1,
      "name": "Rock_Stone",
      "rotation": 1
    },
    {
      "x": -10,
      "y": 5,
      "z": 1,
      "name": "Rock_Stone",
      "rotation": 1
    },
    {
      "x": -10,
      "y": 6,
      "z": 1,
      "name": "Rock_Stone",
      "rotation": 1
    },
    {
      "x": -10,
      "y": 7,
      "z": 1,
      "name": "Rock_Stone",
      "rotation": 1
    },
    {
      "x": -10,
      "y": 8,
      "z": 1,
      "name": "Rock_Stone",
      "rotation": 1
    },
    {
      "x": -10,
      "y": 0,
      "z": 2,
      "name": "Rock_Basalt"
    },
    {
      "x": -10,
      "y": 1,
      "z": 2,
      "name": "Rock_Basalt",
      "rotation": 1
    },
    {
      "x": -10,
      "y": 2,
      "z": 2,
      "name": "Rock_Basalt",
      "rotation": 1
    },
    {
      "x": -10,
      "y": 3,
      "z": 2,
      "name": "Rock_Basalt",
      "rotation": 1
    },
    {
      "x": -10,
      "y": 4,
      "z": 2,
      "name": "Rock_Stone",
      "rotation": 1
    },
    {
      "x": -10,
      "y": 5,
      "z": 2,
      "name": "Rock_Stone",
      "rotation": 1
    },
    {
      "x": -10,
      "y": 6,
      "z": 2,
      "name": "Rock_Stone",
      "rotation": 1
    },
    {
      "x": -10,
      "y": 7,
      "z": 2,
      "name": "Rock_Stone",
      "rotation": 1
    },
    {
      "x": -10,
      "y": 8,
      "z": 2,
      "name": "Rock_Stone"
    },
    {
      "x": -10,
      "y": 0,
      "z": 3,
      "name": "Rock_Basalt"
    },
    {
      "x": -10,
      "y": 1,
      "z": 3,
      "name": "Rock_Basalt",
      "rotation": 1
    },
    {
      "x": -10,
      "y": 2,
      "z": 3,
      "name": "Rock_Basalt",
      "rotation": 1
    },
    {
      "x": -10,
      "y": 3,
      "z": 3,
      "name": "Rock_Basalt",
      "rotation": 1
    },
    {
      "x": -10,
      "y": 4,
      "z": 3,
      "name": "Rock_Stone",
      "rotation": 1
    },
    {
      "x": -10,
      "y": 5,
      "z": 3,
      "name": "Rock_Stone",
      "rotation": 1
    },
    {
      "x": -10,
      "y": 6,
      "z": 3,
      "name": "Rock_Stone",
      "rotation": 1
    },
    {
      "x": -10,
      "y": 7,
      "z": 3,
      "name": "Rock_Stone",
      "rotation": 1
    },
    {
      "x": -10,
      "y": 8,
      "z": 3,
      "name": "Rock_Stone",
      "rotation": 1
    },
    {
      "x": -10,
      "y": 0,
      "z": 4,
      "name": "Rock_Basalt"
    },
    {
      "x": -10,
      "y": 1,
      "z": 4,
      "name": "Rock_Basalt",
      "rotation": 1
    },
    {
      "x": -10,
      "y": 2,
      "z": 4,
      "name": "Rock_Basalt",
      "rotation": 1
    },
    {
      "x": -10,
      "y": 3,
      "z": 4,
      "name": "Rock_Basalt",
      "rotation": 1
    },
    {
      "x": -10,
      "y": 4,
      "z": 4,
      "name": "Rock_Stone",
      "rotation": 1
    },
    {
      "x": -10,
      "y": 5,
      "z": 4,
      "name": "Rock_Stone",
      "rotation": 1
    },
    {
      "x": -10,
      "y": 6,
      "z": 4,
      "name": "Rock_Stone",
      "rotation": 1
    },
    {
      "x": -10,
      "y": 7,
      "z": 4,
      "name": "Rock_Stone",
      "rotation": 1
    },
    {
      "x": -10,
      "y": 8,
      "z": 4,
      "name": "Rock_Stone_Mossy"
    },
    {
      "x": -10,
      "y": 0,
      "z": 5,
      "name": "Rock_Basalt"
    },
    {
      "x": -10,
      "y": 1,
      "z": 5,
      "name": "Rock_Basalt",
      "rotation": 1
    },
    {
      "x": -10,
      "y": 2,
      "z": 5,
      "name": "Rock_Basalt",
      "rotation": 1
    },
    {
      "x": -10,
      "y": 3,
      "z": 5,
      "name": "Rock_Basalt",
      "rotation": 1
    },
    {
      "x": -10,
      "y": 4,
      "z": 5,
      "name": "Rock_Stone",
      "rotation": 1
    },
    {
      "x": -10,
      "y": 5,
      "z": 5,
      "name": "Rock_Stone",
      "rotation": 1
    },
    {
      "x": -10,
      "y": 6,
      "z": 5,
      "name": "Rock_Stone",
      "rotation": 1
    },
    {
      "x": -10,
      "y": 7,
      "z": 5,
      "name": "Rock_Stone",
      "rotation": 1
    },
    {
      "x": -10,
      "y": 8,
      "z": 5,
      "name": "Rock_Stone",
      "rotation": 1
    },
    {
      "x": -10,
      "y": 9,
      "z": 5,
      "name": "Plant_Moss_Rug_Green",
      "support": 15
    },
    {
      "x": -10,
      "y": 0,
      "z": 6,
      "name": "Rock_Basalt"
    },
    {
      "x": -10,
      "y": 1,
      "z": 6,
      "name": "Rock_Basalt",
      "rotation": 1
    },
    {
      "x": -10,
      "y": 2,
      "z": 6,
      "name": "Rock_Basalt",
      "rotation": 1
    },
    {
      "x": -10,
      "y": 3,
      "z": 6,
      "name": "Rock_Basalt",
      "rotation": 1
    },
    {
      "x": -10,
      "y": 4,
      "z": 6,
      "name": "Rock_Stone",
      "rotation": 1
    },
    {
      "x": -10,
      "y": 5,
      "z": 6,
      "name": "Rock_Stone",
      "rotation": 1
    },
    {
      "x": -10,
      "y": 6,
      "z": 6,
      "name": "Rock_Stone",
      "rotation": 1
    },
    {
      "x": -10,
      "y": 7,
      "z": 6,
      "name": "Rock_Stone",
      "rotation": 1
    },
    {
      "x": -10,
      "y": 8,
      "z": 6,
      "name": "Rock_Stone",
      "rotation": 1
    },
    {
      "x": -10,
      "y": 0,
      "z": 7,
      "name": "Rock_Basalt"
    },
    {
      "x": -10,
      "y": 1,
      "z": 7,
      "name": "Rock_Basalt",
      "rotation": 1
    },
    {
      "x": -10,
      "y": 2,
      "z": 7,
      "name": "Rock_Basalt",
      "rotation": 1
    },
    {
      "x": -10,
      "y": 3,
      "z": 7,
      "name": "Rock_Basalt",
      "rotation": 1
    },
    {
      "x": -10,
      "y": 4,
      "z": 7,
      "name": "Rock_Stone",
      "rotation": 1
    },
    {
      "x": -10,
      "y": 5,
      "z": 7,
      "name": "Rock_Stone",
      "rotation": 1
    },
    {
      "x": -10,
      "y": 6,
      "z": 7,
      "name": "Rock_Stone",
      "rotation": 1
    },
    {
      "x": -10,
      "y": 7,
      "z": 7,
      "name": "Rock_Stone",
      "rotation": 1
    },
    {
      "x": -10,
      "y": 8,
      "z": 7,
      "name": "Rock_Stone"
    },
    {
      "x": -9,
      "y": 0,
      "z": -6,
      "name": "Rock_Basalt"
    },
    {
      "x": -9,
      "y": 1,
      "z": -6,
      "name": "Rock_Basalt",
      "rotation": 1
    },
    {
      "x": -9,
      "y": 2,
      "z": -6,
      "name": "Rock_Basalt",
      "rotation": 1
    },
    {
      "x": -9,
      "y": 3,
      "z": -6,
      "name": "Rock_Basalt",
      "rotation": 1
    },
    {
      "x": -9,
      "y": 4,
      "z": -6,
      "name": "Rock_Stone",
      "rotation": 1
    },
    {
      "x": -9,
      "y": 5,
      "z": -6,
      "name": "Rock_Stone",
      "rotation": 1
    },
    {
      "x": -9,
      "y": 6,
      "z": -6,
      "name": "Rock_Stone",
      "rotation": 1
    },
    {
      "x": -9,
      "y": 7,
      "z": -6,
      "name": "Rock_Stone",
      "rotation": 1
    },
    {
      "x": -9,
      "y": 8,
      "z": -6,
      "name": "Soil_Ash",
      "rotation": 1
    },
    {
      "x": -9,
      "y": 0,
      "z": -5,
      "name": "Rock_Basalt"
    },
    {
      "x": -9,
      "y": 1,
      "z": -5,
      "name": "Rock_Basalt",
      "rotation": 1
    },
    {
      "x": -9,
      "y": 2,
      "z": -5,
      "name": "Rock_Basalt",
      "rotation": 1
    },
    {
      "x": -9,
      "y": 3,
      "z": -5,
      "name": "Rock_Basalt",
      "rotation": 1
    },
    {
      "x": -9,
      "y": 4,
      "z": -5,
      "name": "Rock_Stone",
      "rotation": 1
    },
    {
      "x": -9,
      "y": 5,
      "z": -5,
      "name": "Rock_Stone",
      "rotation": 1
    },
    {
      "x": -9,
      "y": 6,
      "z": -5,
      "name": "Rock_Stone",
      "rotation": 1
    },
    {
      "x": -9,
      "y": 7,
      "z": -5,
      "name": "Rock_Stone",
      "rotation": 1
    },
    {
      "x": -9,
      "y": 8,
      "z": -5,
      "name": "Soil_Ash",
      "rotation": 1
    },
    {
      "x": -9,
      "y": 0,
      "z": -4,
      "name": "Rock_Basalt"
    },
    {
      "x": -9,
      "y": 1,
      "z": -4,
      "name": "Rock_Basalt",
      "rotation": 1
    },
    {
      "x": -9,
      "y": 2,
      "z": -4,
      "name": "Rock_Basalt",
      "rotation": 1
    },
    {
      "x": -9,
      "y": 3,
      "z": -4,
      "name": "Rock_Basalt",
      "rotation": 1
    },
    {
      "x": -9,
      "y": 4,
      "z": -4,
      "name": "Rock_Stone",
      "rotation": 1
    },
    {
      "x": -9,
      "y": 5,
      "z": -4,
      "name": "Rock_Stone",
      "rotation": 1
    },
    {
      "x": -9,
      "y": 6,
      "z": -4,
      "name": "Rock_Stone",
      "rotation": 1
    },
    {
      "x": -9,
      "y": 7,
      "z": -4,
      "name": "Rock_Stone",
      "rotation": 1
    },
    {
      "x": -9,
      "y": 8,
      "z": -4,
      "name": "Soil_Ash",
      "rotation": 1
    },
    {
      "x": -9,
      "y": 0,
      "z": -3,
      "name": "Rock_Basalt"
    },
    {
      "x": -9,
      "y": 1,
      "z": -3,
      "name": "Rock_Basalt",
      "rotation": 1
    },
    {
      "x": -9,
      "y": 2,
      "z": -3,
      "name": "Rock_Basalt",
      "rotation": 1
    },
    {
      "x": -9,
      "y": 3,
      "z": -3,
      "name": "Rock_Basalt",
      "rotation": 1
    },
    {
      "x": -9,
      "y": 4,
      "z": -3,
      "name": "Rock_Stone",
      "rotation": 1
    },
    {
      "x": -9,
      "y": 5,
      "z": -3,
      "name": "Rock_Stone",
      "rotation": 1
    },
    {
      "x": -9,
      "y": 6,
      "z": -3,
      "name": "Rock_Stone",
      "rotation": 1
    },
    {
      "x": -9,
      "y": 7,
      "z": -3,
      "name": "Rock_Stone",
      "rotation": 1
    },
    {
      "x": -9,
      "y": 8,
      "z": -3,
      "name": "Soil_Ash",
      "rotation": 1
    },
    {
      "x": -9,
      "y": 0,
      "z": -2,
      "name": "Rock_Basalt"
    },
    {
      "x": -9,
      "y": 1,
      "z": -2,
      "name": "Rock_Basalt",
      "rotation": 1
    },
    {
      "x": -9,
      "y": 2,
      "z": -2,
      "name": "Rock_Basalt",
      "rotation": 1
    },
    {
      "x": -9,
      "y": 3,
      "z": -2,
      "name": "Rock_Basalt",
      "rotation": 1
    },
    {
      "x": -9,
      "y": 4,
      "z": -2,
      "name": "Rock_Stone",
      "rotation": 1
    },
    {
      "x": -9,
      "y": 5,
      "z": -2,
      "name": "Rock_Stone",
      "rotation": 1
    },
    {
      "x": -9,
      "y": 6,
      "z": -2,
      "name": "Rock_Stone",
      "rotation": 1
    },
    {
      "x": -9,
      "y": 7,
      "z": -2,
      "name": "Rock_Stone",
      "rotation": 1
    },
    {
      "x": -9,
      "y": 8,
      "z": -2,
      "name": "Soil_Ash",
      "rotation": 1
    },
    {
      "x": -9,
      "y": 0,
      "z": -1,
      "name": "Rock_Basalt"
    },
    {
      "x": -9,
      "y": 1,
      "z": -1,
      "name": "Rock_Basalt",
      "rotation": 1
    },
    {
      "x": -9,
      "y": 2,
      "z": -1,
      "name": "Rock_Basalt",
      "rotation": 1
    },
    {
      "x": -9,
      "y": 3,
      "z": -1,
      "name": "Rock_Basalt",
      "rotation": 1
    },
    {
      "x": -9,
      "y": 4,
      "z": -1,
      "name": "Rock_Stone",
      "rotation": 1
    },
    {
      "x": -9,
      "y": 5,
      "z": -1,
      "name": "Rock_Stone",
      "rotation": 1
    },
    {
      "x": -9,
      "y": 6,
      "z": -1,
      "name": "Rock_Stone",
      "rotation": 1
    },
    {
      "x": -9,
      "y": 7,
      "z": -1,
      "name": "Rock_Stone",
      "rotation": 1
    },
    {
      "x": -9,
      "y": 8,
      "z": -1,
      "name": "Soil_Ash",
      "rotation": 1
    },
    {
      "x": -9,
      "y": 0,
      "z": 0,
      "name": "Rock_Basalt"
    },
    {
      "x": -9,
      "y": 1,
      "z": 0,
      "name": "Rock_Basalt",
      "rotation": 1
    },
    {
      "x": -9,
      "y": 2,
      "z": 0,
      "name": "Rock_Basalt",
      "rotation": 1
    },
    {
      "x": -9,
      "y": 3,
      "z": 0,
      "name": "Rock_Basalt",
      "rotation": 1
    },
    {
      "x": -9,
      "y": 4,
      "z": 0,
      "name": "Rock_Stone",
      "rotation": 1
    },
    {
      "x": -9,
      "y": 5,
      "z": 0,
      "name": "Rock_Stone",
      "rotation": 1
    },
    {
      "x": -9,
      "y": 6,
      "z": 0,
      "name": "Rock_Stone",
      "rotation": 1
    },
    {
      "x": -9,
      "y": 7,
      "z": 0,
      "name": "Rock_Stone",
      "rotation": 1
    },
    {
      "x": -9,
      "y": 8,
      "z": 0,
      "name": "Soil_Ash",
      "rotation": 1
    },
    {
      "x": -9,
      "y": 0,
      "z": 1,
      "name": "Rock_Basalt"
    },
    {
      "x": -9,
      "y": 1,
      "z": 1,
      "name": "Rock_Basalt",
      "rotation": 1
    },
    {
      "x": -9,
      "y": 2,
      "z": 1,
      "name": "Rock_Basalt",
      "rotation": 1
    },
    {
      "x": -9,
      "y": 3,
      "z": 1,
      "name": "Rock_Basalt",
      "rotation": 1
    },
    {
      "x": -9,
      "y": 4,
      "z": 1,
      "name": "Rock_Stone",
      "rotation": 1
    },
    {
      "x": -9,
      "y": 5,
      "z": 1,
      "name": "Rock_Stone",
      "rotation": 1
    },
    {
      "x": -9,
      "y": 6,
      "z": 1,
      "name": "Rock_Stone",
      "rotation": 1
    },
    {
      "x": -9,
      "y": 7,
      "z": 1,
      "name": "Rock_Stone",
      "rotation": 1
    },
    {
      "x": -9,
      "y": 8,
      "z": 1,
      "name": "Soil_Ash",
      "rotation": 1
    },
    {
      "x": -9,
      "y": 0,
      "z": 2,
      "name": "Rock_Basalt"
    },
    {
      "x": -9,
      "y": 1,
      "z": 2,
      "name": "Rock_Basalt",
      "rotation": 1
    },
    {
      "x": -9,
      "y": 2,
      "z": 2,
      "name": "Rock_Basalt",
      "rotation": 1
    },
    {
      "x": -9,
      "y": 3,
      "z": 2,
      "name": "Rock_Basalt",
      "rotation": 1
    },
    {
      "x": -9,
      "y": 4,
      "z": 2,
      "name": "Rock_Stone",
      "rotation": 1
    },
    {
      "x": -9,
      "y": 5,
      "z": 2,
      "name": "Rock_Stone",
      "rotation": 1
    },
    {
      "x": -9,
      "y": 6,
      "z": 2,
      "name": "Rock_Stone",
      "rotation": 1
    },
    {
      "x": -9,
      "y": 7,
      "z": 2,
      "name": "Rock_Stone",
      "rotation": 1
    },
    {
      "x": -9,
      "y": 8,
      "z": 2,
      "name": "Soil_Ash",
      "rotation": 1
    },
    {
      "x": -9,
      "y": 0,
      "z": 3,
      "name": "Rock_Basalt"
    },
    {
      "x": -9,
      "y": 1,
      "z": 3,
      "name": "Rock_Basalt",
      "rotation": 1
    },
    {
      "x": -9,
      "y": 2,
      "z": 3,
      "name": "Rock_Basalt",
      "rotation": 1
    },
    {
      "x": -9,
      "y": 3,
      "z": 3,
      "name": "Rock_Basalt",
      "rotation": 1
    },
    {
      "x": -9,
      "y": 4,
      "z": 3,
      "name": "Rock_Stone",
      "rotation": 1
    },
    {
      "x": -9,
      "y": 5,
      "z": 3,
      "name": "Rock_Stone",
      "rotation": 1
    },
    {
      "x": -9,
      "y": 6,
      "z": 3,
      "name": "Rock_Stone",
      "rotation": 1
    },
    {
      "x": -9,
      "y": 7,
      "z": 3,
      "name": "Rock_Stone",
      "rotation": 1
    },
    {
      "x": -9,
      "y": 8,
      "z": 3,
      "name": "Soil_Ash",
      "rotation": 1
    },
    {
      "x": -9,
      "y": 0,
      "z": 4,
      "name": "Rock_Basalt"
    },
    {
      "x": -9,
      "y": 1,
      "z": 4,
      "name": "Rock_Basalt",
      "rotation": 1
    },
    {
      "x": -9,
      "y": 2,
      "z": 4,
      "name": "Rock_Basalt",
      "rotation": 1
    },
    {
      "x": -9,
      "y": 3,
      "z": 4,
      "name": "Rock_Basalt",
      "rotation": 1
    },
    {
      "x": -9,
      "y": 4,
      "z": 4,
      "name": "Rock_Stone",
      "rotation": 1
    },
    {
      "x": -9,
      "y": 5,
      "z": 4,
      "name": "Rock_Stone",
      "rotation": 1
    },
    {
      "x": -9,
      "y": 6,
      "z": 4,
      "name": "Rock_Stone",
      "rotation": 1
    },
    {
      "x": -9,
      "y": 7,
      "z": 4,
      "name": "Rock_Stone",
      "rotation": 1
    },
    {
      "x": -9,
      "y": 8,
      "z": 4,
      "name": "Soil_Ash",
      "rotation": 1
    },
    {
      "x": -9,
      "y": 0,
      "z": 5,
      "name": "Rock_Basalt"
    },
    {
      "x": -9,
      "y": 1,
      "z": 5,
      "name": "Rock_Basalt",
      "rotation": 1
    },
    {
      "x": -9,
      "y": 2,
      "z": 5,
      "name": "Rock_Basalt",
      "rotation": 1
    },
    {
      "x": -9,
      "y": 3,
      "z": 5,
      "name": "Rock_Basalt",
      "rotation": 1
    },
    {
      "x": -9,
      "y": 4,
      "z": 5,
      "name": "Rock_Stone",
      "rotation": 1
    },
    {
      "x": -9,
      "y": 5,
      "z": 5,
      "name": "Rock_Stone",
      "rotation": 1
    },
    {
      "x": -9,
      "y": 6,
      "z": 5,
      "name": "Rock_Stone",
      "rotation": 1
    },
    {
      "x": -9,
      "y": 7,
      "z": 5,
      "name": "Rock_Stone",
      "rotation": 1
    },
    {
      "x": -9,
      "y": 8,
      "z": 5,
      "name": "Soil_Ash",
      "rotation": 1
    },
    {
      "x": -9,
      "y": 0,
      "z": 6,
      "name": "Rock_Basalt"
    },
    {
      "x": -9,
      "y": 1,
      "z": 6,
      "name": "Rock_Basalt",
      "rotation": 1
    },
    {
      "x": -9,
      "y": 2,
      "z": 6,
      "name": "Rock_Basalt",
      "rotation": 1
    },
    {
      "x": -9,
      "y": 3,
      "z": 6,
      "name": "Rock_Basalt",
      "rotation": 1
    },
    {
      "x": -9,
      "y": 4,
      "z": 6,
      "name": "Rock_Stone",
      "rotation": 1
    },
    {
      "x": -9,
      "y": 5,
      "z": 6,
      "name": "Rock_Stone",
      "rotation": 1
    },
    {
      "x": -9,
      "y": 6,
      "z": 6,
      "name": "Rock_Stone",
      "rotation": 1
    },
    {
      "x": -9,
      "y": 7,
      "z": 6,
      "name": "Rock_Stone",
      "rotation": 1
    },
    {
      "x": -9,
      "y": 8,
      "z": 6,
      "name": "Soil_Ash",
      "rotation": 1
    },
    {
      "x": -9,
      "y": 0,
      "z": 7,
      "name": "Rock_Basalt"
    },
    {
      "x": -9,
      "y": 1,
      "z": 7,
      "name": "Rock_Basalt",
      "rotation": 1
    },
    {
      "x": -9,
      "y": 2,
      "z": 7,
      "name": "Rock_Basalt",
      "rotation": 1
    },
    {
      "x": -9,
      "y": 3,
      "z": 7,
      "name": "Rock_Basalt",
      "rotation": 1
    },
    {
      "x": -9,
      "y": 4,
      "z": 7,
      "name": "Rock_Stone",
      "rotation": 1
    },
    {
      "x": -9,
      "y": 5,
      "z": 7,
      "name": "Rock_Stone",
      "rotation": 1
    },
    {
      "x": -9,
      "y": 6,
      "z": 7,
      "name": "Rock_Stone",
      "rotation": 1
    },
    {
      "x": -9,
      "y": 7,
      "z": 7,
      "name": "Rock_Stone",
      "rotation": 1
    },
    {
      "x": -9,
      "y": 8,
      "z": 7,
      "name": "Soil_Ash",
      "rotation": 1
    },
    {
      "x": -8,
      "y": 0,
      "z": -6,
      "name": "Rock_Basalt"
    },
    {
      "x": -8,
      "y": 1,
      "z": -6,
      "name": "Rock_Basalt",
      "rotation": 1
    },
    {
      "x": -8,
      "y": 2,
      "z": -6,
      "name": "Rock_Basalt",
      "rotation": 1
    },
    {
      "x": -8,
      "y": 3,
      "z": -6,
      "name": "Rock_Basalt",
      "rotation": 1
    },
    {
      "x": -8,
      "y": 4,
      "z": -6,
      "name": "Rock_Stone",
      "rotation": 1
    },
    {
      "x": -8,
      "y": 5,
      "z": -6,
      "name": "Rock_Stone",
      "rotation": 1
    },
    {
      "x": -8,
      "y": 6,
      "z": -6,
      "name": "Rock_Stone",
      "rotation": 1
    },
    {
      "x": -8,
      "y": 7,
      "z": -6,
      "name": "Rock_Stone",
      "rotation": 1
    },
    {
      "x": -8,
      "y": 8,
      "z": -6,
      "name": "Soil_Ash",
      "rotation": 1
    },
    {
      "x": -8,
      "y": 0,
      "z": -5,
      "name": "Rock_Basalt"
    },
    {
      "x": -8,
      "y": 1,
      "z": -5,
      "name": "Rock_Basalt",
      "rotation": 1
    },
    {
      "x": -8,
      "y": 2,
      "z": -5,
      "name": "Rock_Basalt",
      "rotation": 1
    },
    {
      "x": -8,
      "y": 3,
      "z": -5,
      "name": "Rock_Basalt",
      "rotation": 1
    },
    {
      "x": -8,
      "y": 4,
      "z": -5,
      "name": "Rock_Stone",
      "rotation": 1
    },
    {
      "x": -8,
      "y": 5,
      "z": -5,
      "name": "Rock_Stone",
      "rotation": 1
    },
    {
      "x": -8,
      "y": 6,
      "z": -5,
      "name": "Rock_Stone",
      "rotation": 1
    },
    {
      "x": -8,
      "y": 7,
      "z": -5,
      "name": "Rock_Stone",
      "rotation": 1
    },
    {
      "x": -8,
      "y": 8,
      "z": -5,
      "name": "Soil_Ash",
      "rotation": 1
    },
    {
      "x": -8,
      "y": 0,
      "z": -4,
      "name": "Rock_Basalt"
    },
    {
      "x": -8,
      "y": 1,
      "z": -4,
      "name": "Rock_Basalt",
      "rotation": 1
    },
    {
      "x": -8,
      "y": 2,
      "z": -4,
      "name": "Rock_Basalt",
      "rotation": 1
    },
    {
      "x": -8,
      "y": 3,
      "z": -4,
      "name": "Rock_Basalt",
      "rotation": 1
    },
    {
      "x": -8,
      "y": 4,
      "z": -4,
      "name": "Rock_Stone",
      "rotation": 1
    },
    {
      "x": -8,
      "y": 5,
      "z": -4,
      "name": "Rock_Stone",
      "rotation": 1
    },
    {
      "x": -8,
      "y": 6,
      "z": -4,
      "name": "Rock_Stone",
      "rotation": 1
    },
    {
      "x": -8,
      "y": 7,
      "z": -4,
      "name": "Rock_Stone",
      "rotation": 1
    },
    {
      "x": -8,
      "y": 8,
      "z": -4,
      "name": "Soil_Ash",
      "rotation": 1
    },
    {
      "x": -8,
      "y": 0,
      "z": -3,
      "name": "Rock_Basalt"
    },
    {
      "x": -8,
      "y": 1,
      "z": -3,
      "name": "Rock_Basalt",
      "rotation": 1
    },
    {
      "x": -8,
      "y": 2,
      "z": -3,
      "name": "Rock_Basalt",
      "rotation": 1
    },
    {
      "x": -8,
      "y": 3,
      "z": -3,
      "name": "Rock_Basalt",
      "rotation": 1
    },
    {
      "x": -8,
      "y": 4,
      "z": -3,
      "name": "Rock_Stone",
      "rotation": 1
    },
    {
      "x": -8,
      "y": 5,
      "z": -3,
      "name": "Rock_Stone",
      "rotation": 1
    },
    {
      "x": -8,
      "y": 6,
      "z": -3,
      "name": "Rock_Stone",
      "rotation": 1
    },
    {
      "x": -8,
      "y": 7,
      "z": -3,
      "name": "Rock_Stone",
      "rotation": 1
    },
    {
      "x": -8,
      "y": 8,
      "z": -3,
      "name": "Soil_Ash",
      "rotation": 1
    },
    {
      "x": -8,
      "y": 0,
      "z": -2,
      "name": "Rock_Basalt"
    },
    {
      "x": -8,
      "y": 1,
      "z": -2,
      "name": "Rock_Basalt",
      "rotation": 1
    },
    {
      "x": -8,
      "y": 2,
      "z": -2,
      "name": "Rock_Basalt",
      "rotation": 1
    },
    {
      "x": -8,
      "y": 3,
      "z": -2,
      "name": "Rock_Basalt",
      "rotation": 1
    },
    {
      "x": -8,
      "y": 4,
      "z": -2,
      "name": "Rock_Stone",
      "rotation": 1
    },
    {
      "x": -8,
      "y": 5,
      "z": -2,
      "name": "Rock_Stone",
      "rotation": 1
    },
    {
      "x": -8,
      "y": 6,
      "z": -2,
      "name": "Rock_Stone",
      "rotation": 1
    },
    {
      "x": -8,
      "y": 7,
      "z": -2,
      "name": "Rock_Stone",
      "rotation": 1
    },
    {
      "x": -8,
      "y": 8,
      "z": -2,
      "name": "Soil_Ash",
      "rotation": 1
    },
    {
      "x": -8,
      "y": 0,
      "z": -1,
      "name": "Rock_Basalt"
    },
    {
      "x": -8,
      "y": 1,
      "z": -1,
      "name": "Rock_Basalt",
      "rotation": 1
    },
    {
      "x": -8,
      "y": 2,
      "z": -1,
      "name": "Rock_Basalt",
      "rotation": 1
    },
    {
      "x": -8,
      "y": 3,
      "z": -1,
      "name": "Rock_Basalt",
      "rotation": 1
    },
    {
      "x": -8,
      "y": 4,
      "z": -1,
      "name": "Rock_Stone",
      "rotation": 1
    },
    {
      "x": -8,
      "y": 5,
      "z": -1,
      "name": "Rock_Stone",
      "rotation": 1
    },
    {
      "x": -8,
      "y": 6,
      "z": -1,
      "name": "Rock_Stone",
      "rotation": 1
    },
    {
      "x": -8,
      "y": 7,
      "z": -1,
      "name": "Rock_Stone",
      "rotation": 1
    },
    {
      "x": -8,
      "y": 8,
      "z": -1,
      "name": "Soil_Ash",
      "rotation": 1
    },
    {
      "x": -8,
      "y": 0,
      "z": 0,
      "name": "Rock_Basalt"
    },
    {
      "x": -8,
      "y": 1,
      "z": 0,
      "name": "Rock_Basalt",
      "rotation": 1
    },
    {
      "x": -8,
      "y": 2,
      "z": 0,
      "name": "Rock_Basalt",
      "rotation": 1
    },
    {
      "x": -8,
      "y": 3,
      "z": 0,
      "name": "Rock_Basalt",
      "rotation": 1
    },
    {
      "x": -8,
      "y": 4,
      "z": 0,
      "name": "Rock_Stone",
      "rotation": 1
    },
    {
      "x": -8,
      "y": 5,
      "z": 0,
      "name": "Rock_Stone",
      "rotation": 1
    },
    {
      "x": -8,
      "y": 6,
      "z": 0,
      "name": "Rock_Stone",
      "rotation": 1
    },
    {
      "x": -8,
      "y": 7,
      "z": 0,
      "name": "Rock_Stone",
      "rotation": 1
    },
    {
      "x": -8,
      "y": 8,
      "z": 0,
      "name": "Soil_Ash",
      "rotation": 1
    },
    {
      "x": -8,
      "y": 0,
      "z": 1,
      "name": "Rock_Basalt"
    },
    {
      "x": -8,
      "y": 1,
      "z": 1,
      "name": "Rock_Basalt",
      "rotation": 1
    },
    {
      "x": -8,
      "y": 2,
      "z": 1,
      "name": "Rock_Basalt",
      "rotation": 1
    },
    {
      "x": -8,
      "y": 3,
      "z": 1,
      "name": "Rock_Basalt",
      "rotation": 1
    },
    {
      "x": -8,
      "y": 4,
      "z": 1,
      "name": "Rock_Stone",
      "rotation": 1
    },
    {
      "x": -8,
      "y": 5,
      "z": 1,
      "name": "Rock_Stone",
      "rotation": 1
    },
    {
      "x": -8,
      "y": 6,
      "z": 1,
      "name": "Rock_Stone",
      "rotation": 1
    },
    {
      "x": -8,
      "y": 7,
      "z": 1,
      "name": "Rock_Stone",
      "rotation": 1
    },
    {
      "x": -8,
      "y": 8,
      "z": 1,
      "name": "Soil_Ash",
      "rotation": 1
    },
    {
      "x": -8,
      "y": 0,
      "z": 2,
      "name": "Rock_Basalt"
    },
    {
      "x": -8,
      "y": 1,
      "z": 2,
      "name": "Rock_Basalt",
      "rotation": 1
    },
    {
      "x": -8,
      "y": 2,
      "z": 2,
      "name": "Rock_Basalt",
      "rotation": 1
    },
    {
      "x": -8,
      "y": 3,
      "z": 2,
      "name": "Rock_Basalt",
      "rotation": 1
    },
    {
      "x": -8,
      "y": 4,
      "z": 2,
      "name": "Rock_Stone",
      "rotation": 1
    },
    {
      "x": -8,
      "y": 5,
      "z": 2,
      "name": "Rock_Stone",
      "rotation": 1
    },
    {
      "x": -8,
      "y": 6,
      "z": 2,
      "name": "Rock_Stone",
      "rotation": 1
    },
    {
      "x": -8,
      "y": 7,
      "z": 2,
      "name": "Rock_Stone",
      "rotation": 1
    },
    {
      "x": -8,
      "y": 8,
      "z": 2,
      "name": "Soil_Ash",
      "rotation": 1
    },
    {
      "x": -8,
      "y": 0,
      "z": 3,
      "name": "Rock_Basalt"
    },
    {
      "x": -8,
      "y": 1,
      "z": 3,
      "name": "Rock_Basalt",
      "rotation": 1
    },
    {
      "x": -8,
      "y": 2,
      "z": 3,
      "name": "Rock_Basalt",
      "rotation": 1
    },
    {
      "x": -8,
      "y": 3,
      "z": 3,
      "name": "Rock_Basalt",
      "rotation": 1
    },
    {
      "x": -8,
      "y": 4,
      "z": 3,
      "name": "Rock_Stone",
      "rotation": 1
    },
    {
      "x": -8,
      "y": 5,
      "z": 3,
      "name": "Rock_Stone",
      "rotation": 1
    },
    {
      "x": -8,
      "y": 6,
      "z": 3,
      "name": "Rock_Stone",
      "rotation": 1
    },
    {
      "x": -8,
      "y": 7,
      "z": 3,
      "name": "Rock_Stone",
      "rotation": 1
    },
    {
      "x": -8,
      "y": 8,
      "z": 3,
      "name": "Soil_Ash",
      "rotation": 1
    },
    {
      "x": -8,
      "y": 0,
      "z": 4,
      "name": "Rock_Basalt"
    },
    {
      "x": -8,
      "y": 1,
      "z": 4,
      "name": "Rock_Basalt",
      "rotation": 1
    },
    {
      "x": -8,
      "y": 2,
      "z": 4,
      "name": "Rock_Basalt",
      "rotation": 1
    },
    {
      "x": -8,
      "y": 3,
      "z": 4,
      "name": "Rock_Basalt",
      "rotation": 1
    },
    {
      "x": -8,
      "y": 4,
      "z": 4,
      "name": "Rock_Stone",
      "rotation": 1
    },
    {
      "x": -8,
      "y": 5,
      "z": 4,
      "name": "Rock_Stone",
      "rotation": 1
    },
    {
      "x": -8,
      "y": 6,
      "z": 4,
      "name": "Rock_Stone",
      "rotation": 1
    },
    {
      "x": -8,
      "y": 7,
      "z": 4,
      "name": "Rock_Stone",
      "rotation": 1
    },
    {
      "x": -8,
      "y": 8,
      "z": 4,
      "name": "Soil_Ash",
      "rotation": 1
    },
    {
      "x": -8,
      "y": 0,
      "z": 5,
      "name": "Rock_Basalt"
    },
    {
      "x": -8,
      "y": 1,
      "z": 5,
      "name": "Rock_Basalt",
      "rotation": 1
    },
    {
      "x": -8,
      "y": 2,
      "z": 5,
      "name": "Rock_Basalt",
      "rotation": 1
    },
    {
      "x": -8,
      "y": 3,
      "z": 5,
      "name": "Rock_Basalt",
      "rotation": 1
    },
    {
      "x": -8,
      "y": 4,
      "z": 5,
      "name": "Rock_Stone",
      "rotation": 1
    },
    {
      "x": -8,
      "y": 5,
      "z": 5,
      "name": "Rock_Stone",
      "rotation": 1
    },
    {
      "x": -8,
      "y": 6,
      "z": 5,
      "name": "Rock_Stone",
      "rotation": 1
    },
    {
      "x": -8,
      "y": 7,
      "z": 5,
      "name": "Rock_Stone",
      "rotation": 1
    },
    {
      "x": -8,
      "y": 8,
      "z": 5,
      "name": "Soil_Ash",
      "rotation": 1
    },
    {
      "x": -8,
      "y": 0,
      "z": 6,
      "name": "Rock_Basalt"
    },
    {
      "x": -8,
      "y": 1,
      "z": 6,
      "name": "Rock_Basalt",
      "rotation": 1
    },
    {
      "x": -8,
      "y": 2,
      "z": 6,
      "name": "Rock_Basalt",
      "rotation": 1
    },
    {
      "x": -8,
      "y": 3,
      "z": 6,
      "name": "Rock_Basalt",
      "rotation": 1
    },
    {
      "x": -8,
      "y": 4,
      "z": 6,
      "name": "Rock_Stone",
      "rotation": 1
    },
    {
      "x": -8,
      "y": 5,
      "z": 6,
      "name": "Rock_Stone",
      "rotation": 1
    },
    {
      "x": -8,
      "y": 6,
      "z": 6,
      "name": "Rock_Stone",
      "rotation": 1
    },
    {
      "x": -8,
      "y": 7,
      "z": 6,
      "name": "Rock_Stone",
      "rotation": 1
    },
    {
      "x": -8,
      "y": 8,
      "z": 6,
      "name": "Soil_Ash",
      "rotation": 1
    },
    {
      "x": -8,
      "y": 0,
      "z": 7,
      "name": "Rock_Basalt"
    },
    {
      "x": -8,
      "y": 1,
      "z": 7,
      "name": "Rock_Basalt",
      "rotation": 1
    },
    {
      "x": -8,
      "y": 2,
      "z": 7,
      "name": "Rock_Basalt",
      "rotation": 1
    },
    {
      "x": -8,
      "y": 3,
      "z": 7,
      "name": "Rock_Basalt",
      "rotation": 1
    },
    {
      "x": -8,
      "y": 4,
      "z": 7,
      "name": "Rock_Stone",
      "rotation": 1
    },
    {
      "x": -8,
      "y": 5,
      "z": 7,
      "name": "Rock_Stone",
      "rotation": 1
    },
    {
      "x": -8,
      "y": 6,
      "z": 7,
      "name": "Rock_Stone",
      "rotation": 1
    },
    {
      "x": -8,
      "y": 7,
      "z": 7,
      "name": "Rock_Stone",
      "rotation": 1
    },
    {
      "x": -8,
      "y": 8,
      "z": 7,
      "name": "Soil_Ash",
      "rotation": 1
    },
    {
      "x": -7,
      "y": 0,
      "z": -6,
      "name": "Rock_Basalt"
    },
    {
      "x": -7,
      "y": 1,
      "z": -6,
      "name": "Rock_Basalt",
      "rotation": 1
    },
    {
      "x": -7,
      "y": 2,
      "z": -6,
      "name": "Rock_Basalt",
      "rotation": 1
    },
    {
      "x": -7,
      "y": 3,
      "z": -6,
      "name": "Rock_Basalt",
      "rotation": 1
    },
    {
      "x": -7,
      "y": 4,
      "z": -6,
      "name": "Rock_Stone",
      "rotation": 1
    },
    {
      "x": -7,
      "y": 5,
      "z": -6,
      "name": "Rock_Stone",
      "rotation": 1
    },
    {
      "x": -7,
      "y": 6,
      "z": -6,
      "name": "Rock_Stone",
      "rotation": 1
    },
    {
      "x": -7,
      "y": 7,
      "z": -6,
      "name": "Rock_Stone",
      "rotation": 1
    },
    {
      "x": -7,
      "y": 8,
      "z": -6,
      "name": "Soil_Ash",
      "rotation": 1
    },
    {
      "x": -7,
      "y": 0,
      "z": -5,
      "name": "Rock_Basalt"
    },
    {
      "x": -7,
      "y": 1,
      "z": -5,
      "name": "Rock_Basalt",
      "rotation": 1
    },
    {
      "x": -7,
      "y": 2,
      "z": -5,
      "name": "Rock_Basalt",
      "rotation": 1
    },
    {
      "x": -7,
      "y": 3,
      "z": -5,
      "name": "Rock_Basalt",
      "rotation": 1
    },
    {
      "x": -7,
      "y": 4,
      "z": -5,
      "name": "Rock_Stone",
      "rotation": 1
    },
    {
      "x": -7,
      "y": 5,
      "z": -5,
      "name": "Rock_Stone",
      "rotation": 1
    },
    {
      "x": -7,
      "y": 6,
      "z": -5,
      "name": "Rock_Stone",
      "rotation": 1
    },
    {
      "x": -7,
      "y": 7,
      "z": -5,
      "name": "Rock_Stone",
      "rotation": 1
    },
    {
      "x": -7,
      "y": 8,
      "z": -5,
      "name": "Cloth_Block_Wool_Gray_Half",
      "rotation": 1
    },
    {
      "x": -7,
      "y": 0,
      "z": -4,
      "name": "Rock_Basalt"
    },
    {
      "x": -7,
      "y": 1,
      "z": -4,
      "name": "Rock_Basalt",
      "rotation": 1
    },
    {
      "x": -7,
      "y": 2,
      "z": -4,
      "name": "Rock_Basalt",
      "rotation": 1
    },
    {
      "x": -7,
      "y": 3,
      "z": -4,
      "name": "Rock_Basalt",
      "rotation": 1
    },
    {
      "x": -7,
      "y": 4,
      "z": -4,
      "name": "Rock_Stone",
      "rotation": 1
    },
    {
      "x": -7,
      "y": 5,
      "z": -4,
      "name": "Rock_Stone",
      "rotation": 1
    },
    {
      "x": -7,
      "y": 6,
      "z": -4,
      "name": "Rock_Stone",
      "rotation": 1
    },
    {
      "x": -7,
      "y": 7,
      "z": -4,
      "name": "Rock_Stone",
      "rotation": 1
    },
    {
      "x": -7,
      "y": 8,
      "z": -4,
      "name": "Cloth_Block_Wool_Gray_Stairs",
      "rotation": 2
    },
    {
      "x": -7,
      "y": 0,
      "z": -3,
      "name": "Rock_Basalt"
    },
    {
      "x": -7,
      "y": 1,
      "z": -3,
      "name": "Rock_Basalt",
      "rotation": 1
    },
    {
      "x": -7,
      "y": 2,
      "z": -3,
      "name": "Rock_Basalt",
      "rotation": 1
    },
    {
      "x": -7,
      "y": 3,
      "z": -3,
      "name": "Rock_Basalt",
      "rotation": 1
    },
    {
      "x": -7,
      "y": 4,
      "z": -3,
      "name": "Rock_Stone",
      "rotation": 1
    },
    {
      "x": -7,
      "y": 5,
      "z": -3,
      "name": "Rock_Stone",
      "rotation": 1
    },
    {
      "x": -7,
      "y": 6,
      "z": -3,
      "name": "Rock_Stone",
      "rotation": 1
    },
    {
      "x": -7,
      "y": 7,
      "z": -3,
      "name": "Rock_Stone",
      "rotation": 1
    },
    {
      "x": -7,
      "y": 8,
      "z": -3,
      "name": "Soil_Ash",
      "rotation": 1
    },
    {
      "x": -7,
      "y": 0,
      "z": -2,
      "name": "Rock_Basalt"
    },
    {
      "x": -7,
      "y": 1,
      "z": -2,
      "name": "Rock_Basalt",
      "rotation": 1
    },
    {
      "x": -7,
      "y": 2,
      "z": -2,
      "name": "Rock_Basalt",
      "rotation": 1
    },
    {
      "x": -7,
      "y": 3,
      "z": -2,
      "name": "Rock_Basalt",
      "rotation": 1
    },
    {
      "x": -7,
      "y": 4,
      "z": -2,
      "name": "Rock_Stone",
      "rotation": 1
    },
    {
      "x": -7,
      "y": 5,
      "z": -2,
      "name": "Rock_Stone",
      "rotation": 1
    },
    {
      "x": -7,
      "y": 6,
      "z": -2,
      "name": "Rock_Stone",
      "rotation": 1
    },
    {
      "x": -7,
      "y": 7,
      "z": -2,
      "name": "Rock_Stone",
      "rotation": 1
    },
    {
      "x": -7,
      "y": 8,
      "z": -2,
      "name": "Cloth_Block_Wool_Gray_Stairs"
    },
    {
      "x": -7,
      "y": 0,
      "z": -1,
      "name": "Rock_Basalt"
    },
    {
      "x": -7,
      "y": 1,
      "z": -1,
      "name": "Rock_Basalt",
      "rotation": 1
    },
    {
      "x": -7,
      "y": 2,
      "z": -1,
      "name": "Rock_Basalt",
      "rotation": 1
    },
    {
      "x": -7,
      "y": 3,
      "z": -1,
      "name": "Rock_Basalt",
      "rotation": 1
    },
    {
      "x": -7,
      "y": 4,
      "z": -1,
      "name": "Rock_Stone",
      "rotation": 1
    },
    {
      "x": -7,
      "y": 5,
      "z": -1,
      "name": "Rock_Stone",
      "rotation": 1
    },
    {
      "x": -7,
      "y": 6,
      "z": -1,
      "name": "Rock_Stone",
      "rotation": 1
    },
    {
      "x": -7,
      "y": 7,
      "z": -1,
      "name": "Rock_Stone",
      "rotation": 1
    },
    {
      "x": -7,
      "y": 8,
      "z": -1,
      "name": "Cloth_Block_Wool_Gray_Half",
      "rotation": 1
    },
    {
      "x": -7,
      "y": 0,
      "z": 0,
      "name": "Rock_Basalt"
    },
    {
      "x": -7,
      "y": 1,
      "z": 0,
      "name": "Rock_Basalt",
      "rotation": 1
    },
    {
      "x": -7,
      "y": 2,
      "z": 0,
      "name": "Rock_Basalt",
      "rotation": 1
    },
    {
      "x": -7,
      "y": 3,
      "z": 0,
      "name": "Rock_Basalt",
      "rotation": 1
    },
    {
      "x": -7,
      "y": 4,
      "z": 0,
      "name": "Rock_Stone",
      "rotation": 1
    },
    {
      "x": -7,
      "y": 5,
      "z": 0,
      "name": "Rock_Stone",
      "rotation": 1
    },
    {
      "x": -7,
      "y": 6,
      "z": 0,
      "name": "Rock_Stone",
      "rotation": 1
    },
    {
      "x": -7,
      "y": 7,
      "z": 0,
      "name": "Rock_Stone",
      "rotation": 1
    },
    {
      "x": -7,
      "y": 8,
      "z": 0,
      "name": "Soil_Ash",
      "rotation": 1
    },
    {
      "x": -7,
      "y": 0,
      "z": 1,
      "name": "Rock_Basalt"
    },
    {
      "x": -7,
      "y": 1,
      "z": 1,
      "name": "Rock_Basalt",
      "rotation": 1
    },
    {
      "x": -7,
      "y": 2,
      "z": 1,
      "name": "Rock_Basalt",
      "rotation": 1
    },
    {
      "x": -7,
      "y": 3,
      "z": 1,
      "name": "Rock_Basalt",
      "rotation": 1
    },
    {
      "x": -7,
      "y": 4,
      "z": 1,
      "name": "Rock_Stone",
      "rotation": 1
    },
    {
      "x": -7,
      "y": 5,
      "z": 1,
      "name": "Rock_Stone",
      "rotation": 1
    },
    {
      "x": -7,
      "y": 6,
      "z": 1,
      "name": "Rock_Stone",
      "rotation": 1
    },
    {
      "x": -7,
      "y": 7,
      "z": 1,
      "name": "Rock_Stone",
      "rotation": 1
    },
    {
      "x": -7,
      "y": 8,
      "z": 1,
      "name": "Soil_Ash",
      "rotation": 1
    },
    {
      "x": -7,
      "y": 0,
      "z": 2,
      "name": "Rock_Basalt"
    },
    {
      "x": -7,
      "y": 1,
      "z": 2,
      "name": "Rock_Basalt",
      "rotation": 1
    },
    {
      "x": -7,
      "y": 2,
      "z": 2,
      "name": "Rock_Basalt",
      "rotation": 1
    },
    {
      "x": -7,
      "y": 3,
      "z": 2,
      "name": "Rock_Basalt",
      "rotation": 1
    },
    {
      "x": -7,
      "y": 4,
      "z": 2,
      "name": "Rock_Stone",
      "rotation": 1
    },
    {
      "x": -7,
      "y": 5,
      "z": 2,
      "name": "Rock_Stone",
      "rotation": 1
    },
    {
      "x": -7,
      "y": 6,
      "z": 2,
      "name": "Rock_Stone",
      "rotation": 1
    },
    {
      "x": -7,
      "y": 7,
      "z": 2,
      "name": "Rock_Stone",
      "rotation": 1
    },
    {
      "x": -7,
      "y": 8,
      "z": 2,
      "name": "Cloth_Block_Wool_Gray_Half",
      "rotation": 1
    },
    {
      "x": -7,
      "y": 0,
      "z": 3,
      "name": "Rock_Basalt"
    },
    {
      "x": -7,
      "y": 1,
      "z": 3,
      "name": "Rock_Basalt",
      "rotation": 1
    },
    {
      "x": -7,
      "y": 2,
      "z": 3,
      "name": "Rock_Basalt",
      "rotation": 1
    },
    {
      "x": -7,
      "y": 3,
      "z": 3,
      "name": "Rock_Basalt",
      "rotation": 1
    },
    {
      "x": -7,
      "y": 4,
      "z": 3,
      "name": "Rock_Stone",
      "rotation": 1
    },
    {
      "x": -7,
      "y": 5,
      "z": 3,
      "name": "Rock_Stone",
      "rotation": 1
    },
    {
      "x": -7,
      "y": 6,
      "z": 3,
      "name": "Rock_Stone",
      "rotation": 1
    },
    {
      "x": -7,
      "y": 7,
      "z": 3,
      "name": "Rock_Stone",
      "rotation": 1
    },
    {
      "x": -7,
      "y": 8,
      "z": 3,
      "name": "Cloth_Block_Wool_Gray_Stairs",
      "rotation": 2
    },
    {
      "x": -7,
      "y": 0,
      "z": 4,
      "name": "Rock_Basalt"
    },
    {
      "x": -7,
      "y": 1,
      "z": 4,
      "name": "Rock_Basalt",
      "rotation": 1
    },
    {
      "x": -7,
      "y": 2,
      "z": 4,
      "name": "Rock_Basalt",
      "rotation": 1
    },
    {
      "x": -7,
      "y": 3,
      "z": 4,
      "name": "Rock_Basalt",
      "rotation": 1
    },
    {
      "x": -7,
      "y": 4,
      "z": 4,
      "name": "Rock_Stone",
      "rotation": 1
    },
    {
      "x": -7,
      "y": 5,
      "z": 4,
      "name": "Rock_Stone",
      "rotation": 1
    },
    {
      "x": -7,
      "y": 6,
      "z": 4,
      "name": "Rock_Stone",
      "rotation": 1
    },
    {
      "x": -7,
      "y": 7,
      "z": 4,
      "name": "Rock_Stone",
      "rotation": 1
    },
    {
      "x": -7,
      "y": 8,
      "z": 4,
      "name": "Soil_Ash",
      "rotation": 1
    },
    {
      "x": -7,
      "y": 0,
      "z": 5,
      "name": "Rock_Basalt"
    },
    {
      "x": -7,
      "y": 1,
      "z": 5,
      "name": "Rock_Basalt",
      "rotation": 1
    },
    {
      "x": -7,
      "y": 2,
      "z": 5,
      "name": "Rock_Basalt",
      "rotation": 1
    },
    {
      "x": -7,
      "y": 3,
      "z": 5,
      "name": "Rock_Basalt",
      "rotation": 1
    },
    {
      "x": -7,
      "y": 4,
      "z": 5,
      "name": "Rock_Stone",
      "rotation": 1
    },
    {
      "x": -7,
      "y": 5,
      "z": 5,
      "name": "Rock_Stone",
      "rotation": 1
    },
    {
      "x": -7,
      "y": 6,
      "z": 5,
      "name": "Rock_Stone",
      "rotation": 1
    },
    {
      "x": -7,
      "y": 7,
      "z": 5,
      "name": "Rock_Stone",
      "rotation": 1
    },
    {
      "x": -7,
      "y": 8,
      "z": 5,
      "name": "Cloth_Block_Wool_Gray_Stairs"
    },
    {
      "x": -7,
      "y": 0,
      "z": 6,
      "name": "Rock_Basalt"
    },
    {
      "x": -7,
      "y": 1,
      "z": 6,
      "name": "Rock_Basalt",
      "rotation": 1
    },
    {
      "x": -7,
      "y": 2,
      "z": 6,
      "name": "Rock_Basalt",
      "rotation": 1
    },
    {
      "x": -7,
      "y": 3,
      "z": 6,
      "name": "Rock_Basalt",
      "rotation": 1
    },
    {
      "x": -7,
      "y": 4,
      "z": 6,
      "name": "Rock_Stone",
      "rotation": 1
    },
    {
      "x": -7,
      "y": 5,
      "z": 6,
      "name": "Rock_Stone",
      "rotation": 1
    },
    {
      "x": -7,
      "y": 6,
      "z": 6,
      "name": "Rock_Stone",
      "rotation": 1
    },
    {
      "x": -7,
      "y": 7,
      "z": 6,
      "name": "Rock_Stone",
      "rotation": 1
    },
    {
      "x": -7,
      "y": 8,
      "z": 6,
      "name": "Cloth_Block_Wool_Gray_Half",
      "rotation": 1
    },
    {
      "x": -7,
      "y": 0,
      "z": 7,
      "name": "Rock_Basalt"
    },
    {
      "x": -7,
      "y": 1,
      "z": 7,
      "name": "Rock_Basalt",
      "rotation": 1
    },
    {
      "x": -7,
      "y": 2,
      "z": 7,
      "name": "Rock_Basalt",
      "rotation": 1
    },
    {
      "x": -7,
      "y": 3,
      "z": 7,
      "name": "Rock_Basalt",
      "rotation": 1
    },
    {
      "x": -7,
      "y": 4,
      "z": 7,
      "name": "Rock_Stone",
      "rotation": 1
    },
    {
      "x": -7,
      "y": 5,
      "z": 7,
      "name": "Rock_Stone",
      "rotation": 1
    },
    {
      "x": -7,
      "y": 6,
      "z": 7,
      "name": "Rock_Stone",
      "rotation": 1
    },
    {
      "x": -7,
      "y": 7,
      "z": 7,
      "name": "Rock_Stone",
      "rotation": 1
    },
    {
      "x": -7,
      "y": 8,
      "z": 7,
      "name": "Soil_Ash",
      "rotation": 1
    },
    {
      "x": -6,
      "y": 0,
      "z": -6,
      "name": "Rock_Basalt"
    },
    {
      "x": -6,
      "y": 1,
      "z": -6,
      "name": "Rock_Basalt",
      "rotation": 1
    },
    {
      "x": -6,
      "y": 2,
      "z": -6,
      "name": "Rock_Basalt",
      "rotation": 1
    },
    {
      "x": -6,
      "y": 3,
      "z": -6,
      "name": "Rock_Basalt",
      "rotation": 1
    },
    {
      "x": -6,
      "y": 4,
      "z": -6,
      "name": "Rock_Stone",
      "rotation": 1
    },
    {
      "x": -6,
      "y": 5,
      "z": -6,
      "name": "Rock_Stone",
      "rotation": 1
    },
    {
      "x": -6,
      "y": 6,
      "z": -6,
      "name": "Rock_Stone",
      "rotation": 1
    },
    {
      "x": -6,
      "y": 7,
      "z": -6,
      "name": "Rock_Stone",
      "rotation": 1
    },
    {
      "x": -6,
      "y": 8,
      "z": -6,
      "name": "Soil_Ash",
      "rotation": 1
    },
    {
      "x": -6,
      "y": 0,
      "z": -5,
      "name": "Rock_Basalt"
    },
    {
      "x": -6,
      "y": 1,
      "z": -5,
      "name": "Rock_Basalt",
      "rotation": 1
    },
    {
      "x": -6,
      "y": 2,
      "z": -5,
      "name": "Rock_Basalt",
      "rotation": 1
    },
    {
      "x": -6,
      "y": 3,
      "z": -5,
      "name": "Rock_Basalt",
      "rotation": 1
    },
    {
      "x": -6,
      "y": 4,
      "z": -5,
      "name": "Rock_Stone",
      "rotation": 1
    },
    {
      "x": -6,
      "y": 5,
      "z": -5,
      "name": "Rock_Stone",
      "rotation": 1
    },
    {
      "x": -6,
      "y": 6,
      "z": -5,
      "name": "Rock_Stone",
      "rotation": 1
    },
    {
      "x": -6,
      "y": 7,
      "z": -5,
      "name": "Rock_Stone",
      "rotation": 1
    },
    {
      "x": -6,
      "y": 8,
      "z": -5,
      "name": "Soil_Ash",
      "rotation": 1
    },
    {
      "x": -6,
      "y": 0,
      "z": -4,
      "name": "Rock_Basalt"
    },
    {
      "x": -6,
      "y": 1,
      "z": -4,
      "name": "Rock_Basalt",
      "rotation": 1
    },
    {
      "x": -6,
      "y": 2,
      "z": -4,
      "name": "Rock_Basalt",
      "rotation": 1
    },
    {
      "x": -6,
      "y": 3,
      "z": -4,
      "name": "Rock_Basalt",
      "rotation": 1
    },
    {
      "x": -6,
      "y": 4,
      "z": -4,
      "name": "Rock_Stone",
      "rotation": 1
    },
    {
      "x": -6,
      "y": 5,
      "z": -4,
      "name": "Rock_Stone",
      "rotation": 1
    },
    {
      "x": -6,
      "y": 6,
      "z": -4,
      "name": "Rock_Stone",
      "rotation": 1
    },
    {
      "x": -6,
      "y": 7,
      "z": -4,
      "name": "Rock_Stone",
      "rotation": 1
    },
    {
      "x": -6,
      "y": 8,
      "z": -4,
      "name": "Soil_Ash",
      "rotation": 1
    },
    {
      "x": -6,
      "y": 0,
      "z": -3,
      "name": "Rock_Basalt"
    },
    {
      "x": -6,
      "y": 1,
      "z": -3,
      "name": "Rock_Basalt",
      "rotation": 1
    },
    {
      "x": -6,
      "y": 2,
      "z": -3,
      "name": "Rock_Basalt",
      "rotation": 1
    },
    {
      "x": -6,
      "y": 3,
      "z": -3,
      "name": "Rock_Basalt",
      "rotation": 1
    },
    {
      "x": -6,
      "y": 4,
      "z": -3,
      "name": "Rock_Stone",
      "rotation": 1
    },
    {
      "x": -6,
      "y": 5,
      "z": -3,
      "name": "Rock_Stone",
      "rotation": 1
    },
    {
      "x": -6,
      "y": 6,
      "z": -3,
      "name": "Rock_Stone",
      "rotation": 1
    },
    {
      "x": -6,
      "y": 7,
      "z": -3,
      "name": "Rock_Stone",
      "rotation": 1
    },
    {
      "x": -6,
      "y": 8,
      "z": -3,
      "name": "Soil_Ash",
      "rotation": 1
    },
    {
      "x": -6,
      "y": 0,
      "z": -2,
      "name": "Rock_Basalt"
    },
    {
      "x": -6,
      "y": 1,
      "z": -2,
      "name": "Rock_Basalt",
      "rotation": 1
    },
    {
      "x": -6,
      "y": 2,
      "z": -2,
      "name": "Rock_Basalt",
      "rotation": 1
    },
    {
      "x": -6,
      "y": 3,
      "z": -2,
      "name": "Rock_Basalt",
      "rotation": 1
    },
    {
      "x": -6,
      "y": 4,
      "z": -2,
      "name": "Rock_Stone",
      "rotation": 1
    },
    {
      "x": -6,
      "y": 5,
      "z": -2,
      "name": "Rock_Stone",
      "rotation": 1
    },
    {
      "x": -6,
      "y": 6,
      "z": -2,
      "name": "Rock_Stone",
      "rotation": 1
    },
    {
      "x": -6,
      "y": 7,
      "z": -2,
      "name": "Rock_Stone",
      "rotation": 1
    },
    {
      "x": -6,
      "y": 8,
      "z": -2,
      "name": "Soil_Ash",
      "rotation": 1
    },
    {
      "x": -6,
      "y": 0,
      "z": -1,
      "name": "Rock_Basalt"
    },
    {
      "x": -6,
      "y": 1,
      "z": -1,
      "name": "Rock_Basalt",
      "rotation": 1
    },
    {
      "x": -6,
      "y": 2,
      "z": -1,
      "name": "Rock_Basalt",
      "rotation": 1
    },
    {
      "x": -6,
      "y": 3,
      "z": -1,
      "name": "Rock_Basalt",
      "rotation": 1
    },
    {
      "x": -6,
      "y": 4,
      "z": -1,
      "name": "Rock_Stone",
      "rotation": 1
    },
    {
      "x": -6,
      "y": 5,
      "z": -1,
      "name": "Rock_Stone",
      "rotation": 1
    },
    {
      "x": -6,
      "y": 6,
      "z": -1,
      "name": "Rock_Stone",
      "rotation": 1
    },
    {
      "x": -6,
      "y": 7,
      "z": -1,
      "name": "Rock_Stone",
      "rotation": 1
    },
    {
      "x": -6,
      "y": 8,
      "z": -1,
      "name": "Soil_Ash",
      "rotation": 1
    },
    {
      "x": -6,
      "y": 0,
      "z": 0,
      "name": "Rock_Basalt"
    },
    {
      "x": -6,
      "y": 1,
      "z": 0,
      "name": "Rock_Basalt",
      "rotation": 1
    },
    {
      "x": -6,
      "y": 2,
      "z": 0,
      "name": "Rock_Basalt",
      "rotation": 1
    },
    {
      "x": -6,
      "y": 3,
      "z": 0,
      "name": "Rock_Basalt",
      "rotation": 1
    },
    {
      "x": -6,
      "y": 4,
      "z": 0,
      "name": "Rock_Stone",
      "rotation": 1
    },
    {
      "x": -6,
      "y": 5,
      "z": 0,
      "name": "Rock_Stone",
      "rotation": 1
    },
    {
      "x": -6,
      "y": 6,
      "z": 0,
      "name": "Rock_Stone",
      "rotation": 1
    },
    {
      "x": -6,
      "y": 7,
      "z": 0,
      "name": "Rock_Stone",
      "rotation": 1
    },
    {
      "x": -6,
      "y": 8,
      "z": 0,
      "name": "Soil_Ash",
      "rotation": 1
    },
    {
      "x": -6,
      "y": 0,
      "z": 1,
      "name": "Rock_Basalt"
    },
    {
      "x": -6,
      "y": 1,
      "z": 1,
      "name": "Rock_Basalt",
      "rotation": 1
    },
    {
      "x": -6,
      "y": 2,
      "z": 1,
      "name": "Rock_Basalt",
      "rotation": 1
    },
    {
      "x": -6,
      "y": 3,
      "z": 1,
      "name": "Rock_Basalt",
      "rotation": 1
    },
    {
      "x": -6,
      "y": 4,
      "z": 1,
      "name": "Rock_Stone",
      "rotation": 1
    },
    {
      "x": -6,
      "y": 5,
      "z": 1,
      "name": "Rock_Stone",
      "rotation": 1
    },
    {
      "x": -6,
      "y": 6,
      "z": 1,
      "name": "Rock_Stone",
      "rotation": 1
    },
    {
      "x": -6,
      "y": 7,
      "z": 1,
      "name": "Rock_Stone",
      "rotation": 1
    },
    {
      "x": -6,
      "y": 8,
      "z": 1,
      "name": "Soil_Ash",
      "rotation": 1
    },
    {
      "x": -6,
      "y": 0,
      "z": 2,
      "name": "Rock_Basalt"
    },
    {
      "x": -6,
      "y": 1,
      "z": 2,
      "name": "Rock_Basalt",
      "rotation": 1
    },
    {
      "x": -6,
      "y": 2,
      "z": 2,
      "name": "Rock_Basalt",
      "rotation": 1
    },
    {
      "x": -6,
      "y": 3,
      "z": 2,
      "name": "Rock_Basalt",
      "rotation": 1
    },
    {
      "x": -6,
      "y": 4,
      "z": 2,
      "name": "Rock_Stone",
      "rotation": 1
    },
    {
      "x": -6,
      "y": 5,
      "z": 2,
      "name": "Rock_Stone",
      "rotation": 1
    },
    {
      "x": -6,
      "y": 6,
      "z": 2,
      "name": "Rock_Stone",
      "rotation": 1
    },
    {
      "x": -6,
      "y": 7,
      "z": 2,
      "name": "Rock_Stone",
      "rotation": 1
    },
    {
      "x": -6,
      "y": 8,
      "z": 2,
      "name": "Soil_Ash",
      "rotation": 1
    },
    {
      "x": -6,
      "y": 0,
      "z": 3,
      "name": "Rock_Basalt"
    },
    {
      "x": -6,
      "y": 1,
      "z": 3,
      "name": "Rock_Basalt",
      "rotation": 1
    },
    {
      "x": -6,
      "y": 2,
      "z": 3,
      "name": "Rock_Basalt",
      "rotation": 1
    },
    {
      "x": -6,
      "y": 3,
      "z": 3,
      "name": "Rock_Basalt",
      "rotation": 1
    },
    {
      "x": -6,
      "y": 4,
      "z": 3,
      "name": "Rock_Stone",
      "rotation": 1
    },
    {
      "x": -6,
      "y": 5,
      "z": 3,
      "name": "Rock_Stone",
      "rotation": 1
    },
    {
      "x": -6,
      "y": 6,
      "z": 3,
      "name": "Rock_Stone",
      "rotation": 1
    },
    {
      "x": -6,
      "y": 7,
      "z": 3,
      "name": "Rock_Stone",
      "rotation": 1
    },
    {
      "x": -6,
      "y": 8,
      "z": 3,
      "name": "Soil_Ash",
      "rotation": 1
    },
    {
      "x": -6,
      "y": 0,
      "z": 4,
      "name": "Rock_Basalt"
    },
    {
      "x": -6,
      "y": 1,
      "z": 4,
      "name": "Rock_Basalt",
      "rotation": 1
    },
    {
      "x": -6,
      "y": 2,
      "z": 4,
      "name": "Rock_Basalt",
      "rotation": 1
    },
    {
      "x": -6,
      "y": 3,
      "z": 4,
      "name": "Rock_Basalt",
      "rotation": 1
    },
    {
      "x": -6,
      "y": 4,
      "z": 4,
      "name": "Rock_Stone",
      "rotation": 1
    },
    {
      "x": -6,
      "y": 5,
      "z": 4,
      "name": "Rock_Stone",
      "rotation": 1
    },
    {
      "x": -6,
      "y": 6,
      "z": 4,
      "name": "Rock_Stone",
      "rotation": 1
    },
    {
      "x": -6,
      "y": 7,
      "z": 4,
      "name": "Rock_Stone",
      "rotation": 1
    },
    {
      "x": -6,
      "y": 8,
      "z": 4,
      "name": "Soil_Ash",
      "rotation": 1
    },
    {
      "x": -6,
      "y": 0,
      "z": 5,
      "name": "Rock_Basalt"
    },
    {
      "x": -6,
      "y": 1,
      "z": 5,
      "name": "Rock_Basalt",
      "rotation": 1
    },
    {
      "x": -6,
      "y": 2,
      "z": 5,
      "name": "Rock_Basalt",
      "rotation": 1
    },
    {
      "x": -6,
      "y": 3,
      "z": 5,
      "name": "Rock_Basalt",
      "rotation": 1
    },
    {
      "x": -6,
      "y": 4,
      "z": 5,
      "name": "Rock_Stone",
      "rotation": 1
    },
    {
      "x": -6,
      "y": 5,
      "z": 5,
      "name": "Rock_Stone",
      "rotation": 1
    },
    {
      "x": -6,
      "y": 6,
      "z": 5,
      "name": "Rock_Stone",
      "rotation": 1
    },
    {
      "x": -6,
      "y": 7,
      "z": 5,
      "name": "Rock_Stone",
      "rotation": 1
    },
    {
      "x": -6,
      "y": 8,
      "z": 5,
      "name": "Soil_Ash",
      "rotation": 1
    },
    {
      "x": -6,
      "y": 0,
      "z": 6,
      "name": "Rock_Basalt"
    },
    {
      "x": -6,
      "y": 1,
      "z": 6,
      "name": "Rock_Basalt",
      "rotation": 1
    },
    {
      "x": -6,
      "y": 2,
      "z": 6,
      "name": "Rock_Basalt",
      "rotation": 1
    },
    {
      "x": -6,
      "y": 3,
      "z": 6,
      "name": "Rock_Basalt",
      "rotation": 1
    },
    {
      "x": -6,
      "y": 4,
      "z": 6,
      "name": "Rock_Stone",
      "rotation": 1
    },
    {
      "x": -6,
      "y": 5,
      "z": 6,
      "name": "Rock_Stone",
      "rotation": 1
    },
    {
      "x": -6,
      "y": 6,
      "z": 6,
      "name": "Rock_Stone",
      "rotation": 1
    },
    {
      "x": -6,
      "y": 7,
      "z": 6,
      "name": "Rock_Stone",
      "rotation": 1
    },
    {
      "x": -6,
      "y": 8,
      "z": 6,
      "name": "Soil_Ash",
      "rotation": 1
    },
    {
      "x": -6,
      "y": 0,
      "z": 7,
      "name": "Rock_Basalt"
    },
    {
      "x": -6,
      "y": 1,
      "z": 7,
      "name": "Rock_Basalt",
      "rotation": 1
    },
    {
      "x": -6,
      "y": 2,
      "z": 7,
      "name": "Rock_Basalt",
      "rotation": 1
    },
    {
      "x": -6,
      "y": 3,
      "z": 7,
      "name": "Rock_Basalt",
      "rotation": 1
    },
    {
      "x": -6,
      "y": 4,
      "z": 7,
      "name": "Rock_Stone",
      "rotation": 1
    },
    {
      "x": -6,
      "y": 5,
      "z": 7,
      "name": "Rock_Stone",
      "rotation": 1
    },
    {
      "x": -6,
      "y": 6,
      "z": 7,
      "name": "Rock_Stone",
      "rotation": 1
    },
    {
      "x": -6,
      "y": 7,
      "z": 7,
      "name": "Rock_Stone",
      "rotation": 1
    },
    {
      "x": -6,
      "y": 8,
      "z": 7,
      "name": "Soil_Ash",
      "rotation": 1
    },
    {
      "x": -5,
      "y": 0,
      "z": -6,
      "name": "Rock_Basalt"
    },
    {
      "x": -5,
      "y": 1,
      "z": -6,
      "name": "Rock_Basalt",
      "rotation": 1
    },
    {
      "x": -5,
      "y": 2,
      "z": -6,
      "name": "Rock_Basalt",
      "rotation": 1
    },
    {
      "x": -5,
      "y": 3,
      "z": -6,
      "name": "Rock_Basalt",
      "rotation": 1
    },
    {
      "x": -5,
      "y": 4,
      "z": -6,
      "name": "Rock_Stone",
      "rotation": 1
    },
    {
      "x": -5,
      "y": 5,
      "z": -6,
      "name": "Rock_Stone",
      "rotation": 1
    },
    {
      "x": -5,
      "y": 6,
      "z": -6,
      "name": "Rock_Stone",
      "rotation": 1
    },
    {
      "x": -5,
      "y": 7,
      "z": -6,
      "name": "Rock_Stone",
      "rotation": 1
    },
    {
      "x": -5,
      "y": 8,
      "z": -6,
      "name": "Soil_Ash",
      "rotation": 1
    },
    {
      "x": -5,
      "y": 0,
      "z": -5,
      "name": "Rock_Basalt"
    },
    {
      "x": -5,
      "y": 1,
      "z": -5,
      "name": "Rock_Basalt",
      "rotation": 1
    },
    {
      "x": -5,
      "y": 2,
      "z": -5,
      "name": "Rock_Basalt",
      "rotation": 1
    },
    {
      "x": -5,
      "y": 3,
      "z": -5,
      "name": "Rock_Basalt",
      "rotation": 1
    },
    {
      "x": -5,
      "y": 4,
      "z": -5,
      "name": "Rock_Stone",
      "rotation": 1
    },
    {
      "x": -5,
      "y": 5,
      "z": -5,
      "name": "Rock_Stone",
      "rotation": 1
    },
    {
      "x": -5,
      "y": 6,
      "z": -5,
      "name": "Rock_Stone",
      "rotation": 1
    },
    {
      "x": -5,
      "y": 7,
      "z": -5,
      "name": "Rock_Stone",
      "rotation": 1
    },
    {
      "x": -5,
      "y": 8,
      "z": -5,
      "name": "Soil_Ash",
      "rotation": 1
    },
    {
      "x": -5,
      "y": 0,
      "z": -4,
      "name": "Rock_Basalt"
    },
    {
      "x": -5,
      "y": 1,
      "z": -4,
      "name": "Rock_Basalt",
      "rotation": 1
    },
    {
      "x": -5,
      "y": 2,
      "z": -4,
      "name": "Rock_Basalt",
      "rotation": 1
    },
    {
      "x": -5,
      "y": 3,
      "z": -4,
      "name": "Rock_Basalt",
      "rotation": 1
    },
    {
      "x": -5,
      "y": 4,
      "z": -4,
      "name": "Rock_Stone",
      "rotation": 1
    },
    {
      "x": -5,
      "y": 5,
      "z": -4,
      "name": "Rock_Stone",
      "rotation": 1
    },
    {
      "x": -5,
      "y": 6,
      "z": -4,
      "name": "Rock_Stone",
      "rotation": 1
    },
    {
      "x": -5,
      "y": 7,
      "z": -4,
      "name": "Rock_Stone",
      "rotation": 1
    },
    {
      "x": -5,
      "y": 8,
      "z": -4,
      "name": "Soil_Ash",
      "rotation": 1
    },
    {
      "x": -5,
      "y": 0,
      "z": -3,
      "name": "Rock_Basalt"
    },
    {
      "x": -5,
      "y": 1,
      "z": -3,
      "name": "Rock_Basalt",
      "rotation": 1
    },
    {
      "x": -5,
      "y": 2,
      "z": -3,
      "name": "Rock_Basalt",
      "rotation": 1
    },
    {
      "x": -5,
      "y": 3,
      "z": -3,
      "name": "Rock_Basalt",
      "rotation": 1
    },
    {
      "x": -5,
      "y": 4,
      "z": -3,
      "name": "Rock_Stone",
      "rotation": 1
    },
    {
      "x": -5,
      "y": 5,
      "z": -3,
      "name": "Rock_Stone",
      "rotation": 1
    },
    {
      "x": -5,
      "y": 6,
      "z": -3,
      "name": "Rock_Stone",
      "rotation": 1
    },
    {
      "x": -5,
      "y": 7,
      "z": -3,
      "name": "Rock_Stone",
      "rotation": 1
    },
    {
      "x": -5,
      "y": 8,
      "z": -3,
      "name": "Soil_Ash",
      "rotation": 1
    },
    {
      "x": -5,
      "y": 0,
      "z": -2,
      "name": "Rock_Basalt"
    },
    {
      "x": -5,
      "y": 1,
      "z": -2,
      "name": "Rock_Basalt",
      "rotation": 1
    },
    {
      "x": -5,
      "y": 2,
      "z": -2,
      "name": "Rock_Basalt",
      "rotation": 1
    },
    {
      "x": -5,
      "y": 3,
      "z": -2,
      "name": "Rock_Basalt",
      "rotation": 1
    },
    {
      "x": -5,
      "y": 4,
      "z": -2,
      "name": "Rock_Stone",
      "rotation": 1
    },
    {
      "x": -5,
      "y": 5,
      "z": -2,
      "name": "Rock_Stone",
      "rotation": 1
    },
    {
      "x": -5,
      "y": 6,
      "z": -2,
      "name": "Rock_Stone",
      "rotation": 1
    },
    {
      "x": -5,
      "y": 7,
      "z": -2,
      "name": "Rock_Stone",
      "rotation": 1
    },
    {
      "x": -5,
      "y": 8,
      "z": -2,
      "name": "Soil_Ash",
      "rotation": 1
    },
    {
      "x": -5,
      "y": 0,
      "z": -1,
      "name": "Rock_Basalt"
    },
    {
      "x": -5,
      "y": 1,
      "z": -1,
      "name": "Rock_Basalt",
      "rotation": 1
    },
    {
      "x": -5,
      "y": 2,
      "z": -1,
      "name": "Rock_Basalt",
      "rotation": 1
    },
    {
      "x": -5,
      "y": 3,
      "z": -1,
      "name": "Rock_Basalt",
      "rotation": 1
    },
    {
      "x": -5,
      "y": 4,
      "z": -1,
      "name": "Rock_Stone",
      "rotation": 1
    },
    {
      "x": -5,
      "y": 5,
      "z": -1,
      "name": "Rock_Stone",
      "rotation": 1
    },
    {
      "x": -5,
      "y": 6,
      "z": -1,
      "name": "Rock_Stone",
      "rotation": 1
    },
    {
      "x": -5,
      "y": 7,
      "z": -1,
      "name": "Rock_Stone",
      "rotation": 1
    },
    {
      "x": -5,
      "y": 8,
      "z": -1,
      "name": "Soil_Ash",
      "rotation": 1
    },
    {
      "x": -5,
      "y": 0,
      "z": 0,
      "name": "Rock_Basalt"
    },
    {
      "x": -5,
      "y": 1,
      "z": 0,
      "name": "Rock_Basalt",
      "rotation": 1
    },
    {
      "x": -5,
      "y": 2,
      "z": 0,
      "name": "Rock_Basalt",
      "rotation": 1
    },
    {
      "x": -5,
      "y": 3,
      "z": 0,
      "name": "Rock_Basalt",
      "rotation": 1
    },
    {
      "x": -5,
      "y": 4,
      "z": 0,
      "name": "Rock_Stone",
      "rotation": 1
    },
    {
      "x": -5,
      "y": 5,
      "z": 0,
      "name": "Rock_Stone",
      "rotation": 1
    },
    {
      "x": -5,
      "y": 6,
      "z": 0,
      "name": "Rock_Stone",
      "rotation": 1
    },
    {
      "x": -5,
      "y": 7,
      "z": 0,
      "name": "Rock_Stone",
      "rotation": 1
    },
    {
      "x": -5,
      "y": 8,
      "z": 0,
      "name": "Soil_Ash",
      "rotation": 1
    },
    {
      "x": -5,
      "y": 0,
      "z": 1,
      "name": "Rock_Basalt"
    },
    {
      "x": -5,
      "y": 1,
      "z": 1,
      "name": "Rock_Basalt",
      "rotation": 1
    },
    {
      "x": -5,
      "y": 2,
      "z": 1,
      "name": "Rock_Basalt",
      "rotation": 1
    },
    {
      "x": -5,
      "y": 3,
      "z": 1,
      "name": "Rock_Basalt",
      "rotation": 1
    },
    {
      "x": -5,
      "y": 4,
      "z": 1,
      "name": "Rock_Stone",
      "rotation": 1
    },
    {
      "x": -5,
      "y": 5,
      "z": 1,
      "name": "Rock_Stone",
      "rotation": 1
    },
    {
      "x": -5,
      "y": 6,
      "z": 1,
      "name": "Rock_Stone",
      "rotation": 1
    },
    {
      "x": -5,
      "y": 7,
      "z": 1,
      "name": "Rock_Stone",
      "rotation": 1
    },
    {
      "x": -5,
      "y": 8,
      "z": 1,
      "name": "Soil_Ash",
      "rotation": 1
    },
    {
      "x": -5,
      "y": 0,
      "z": 2,
      "name": "Rock_Basalt"
    },
    {
      "x": -5,
      "y": 1,
      "z": 2,
      "name": "Rock_Basalt",
      "rotation": 1
    },
    {
      "x": -5,
      "y": 2,
      "z": 2,
      "name": "Rock_Basalt",
      "rotation": 1
    },
    {
      "x": -5,
      "y": 3,
      "z": 2,
      "name": "Rock_Basalt",
      "rotation": 1
    },
    {
      "x": -5,
      "y": 4,
      "z": 2,
      "name": "Rock_Stone",
      "rotation": 1
    },
    {
      "x": -5,
      "y": 5,
      "z": 2,
      "name": "Rock_Stone",
      "rotation": 1
    },
    {
      "x": -5,
      "y": 6,
      "z": 2,
      "name": "Rock_Stone",
      "rotation": 1
    },
    {
      "x": -5,
      "y": 7,
      "z": 2,
      "name": "Rock_Stone",
      "rotation": 1
    },
    {
      "x": -5,
      "y": 8,
      "z": 2,
      "name": "Soil_Ash",
      "rotation": 1
    },
    {
      "x": -5,
      "y": 0,
      "z": 3,
      "name": "Rock_Basalt"
    },
    {
      "x": -5,
      "y": 1,
      "z": 3,
      "name": "Rock_Basalt",
      "rotation": 1
    },
    {
      "x": -5,
      "y": 2,
      "z": 3,
      "name": "Rock_Basalt",
      "rotation": 1
    },
    {
      "x": -5,
      "y": 3,
      "z": 3,
      "name": "Rock_Basalt",
      "rotation": 1
    },
    {
      "x": -5,
      "y": 4,
      "z": 3,
      "name": "Rock_Stone",
      "rotation": 1
    },
    {
      "x": -5,
      "y": 5,
      "z": 3,
      "name": "Rock_Stone",
      "rotation": 1
    },
    {
      "x": -5,
      "y": 6,
      "z": 3,
      "name": "Rock_Stone",
      "rotation": 1
    },
    {
      "x": -5,
      "y": 7,
      "z": 3,
      "name": "Rock_Stone",
      "rotation": 1
    },
    {
      "x": -5,
      "y": 8,
      "z": 3,
      "name": "Soil_Ash",
      "rotation": 1
    },
    {
      "x": -5,
      "y": 0,
      "z": 4,
      "name": "Rock_Basalt"
    },
    {
      "x": -5,
      "y": 1,
      "z": 4,
      "name": "Rock_Basalt",
      "rotation": 1
    },
    {
      "x": -5,
      "y": 2,
      "z": 4,
      "name": "Rock_Basalt",
      "rotation": 1
    },
    {
      "x": -5,
      "y": 3,
      "z": 4,
      "name": "Rock_Basalt",
      "rotation": 1
    },
    {
      "x": -5,
      "y": 4,
      "z": 4,
      "name": "Rock_Stone",
      "rotation": 1
    },
    {
      "x": -5,
      "y": 5,
      "z": 4,
      "name": "Rock_Stone",
      "rotation": 1
    },
    {
      "x": -5,
      "y": 6,
      "z": 4,
      "name": "Rock_Stone",
      "rotation": 1
    },
    {
      "x": -5,
      "y": 7,
      "z": 4,
      "name": "Rock_Stone",
      "rotation": 1
    },
    {
      "x": -5,
      "y": 8,
      "z": 4,
      "name": "Soil_Ash",
      "rotation": 1
    },
    {
      "x": -5,
      "y": 0,
      "z": 5,
      "name": "Rock_Basalt"
    },
    {
      "x": -5,
      "y": 1,
      "z": 5,
      "name": "Rock_Basalt",
      "rotation": 1
    },
    {
      "x": -5,
      "y": 2,
      "z": 5,
      "name": "Rock_Basalt",
      "rotation": 1
    },
    {
      "x": -5,
      "y": 3,
      "z": 5,
      "name": "Rock_Basalt",
      "rotation": 1
    },
    {
      "x": -5,
      "y": 4,
      "z": 5,
      "name": "Rock_Stone",
      "rotation": 1
    },
    {
      "x": -5,
      "y": 5,
      "z": 5,
      "name": "Rock_Stone",
      "rotation": 1
    },
    {
      "x": -5,
      "y": 6,
      "z": 5,
      "name": "Rock_Stone",
      "rotation": 1
    },
    {
      "x": -5,
      "y": 7,
      "z": 5,
      "name": "Rock_Stone",
      "rotation": 1
    },
    {
      "x": -5,
      "y": 8,
      "z": 5,
      "name": "Soil_Ash",
      "rotation": 1
    },
    {
      "x": -5,
      "y": 0,
      "z": 6,
      "name": "Rock_Basalt"
    },
    {
      "x": -5,
      "y": 1,
      "z": 6,
      "name": "Rock_Basalt",
      "rotation": 1
    },
    {
      "x": -5,
      "y": 2,
      "z": 6,
      "name": "Rock_Basalt",
      "rotation": 1
    },
    {
      "x": -5,
      "y": 3,
      "z": 6,
      "name": "Rock_Basalt",
      "rotation": 1
    },
    {
      "x": -5,
      "y": 4,
      "z": 6,
      "name": "Rock_Stone",
      "rotation": 1
    },
    {
      "x": -5,
      "y": 5,
      "z": 6,
      "name": "Rock_Stone",
      "rotation": 1
    },
    {
      "x": -5,
      "y": 6,
      "z": 6,
      "name": "Rock_Stone",
      "rotation": 1
    },
    {
      "x": -5,
      "y": 7,
      "z": 6,
      "name": "Rock_Stone",
      "rotation": 1
    },
    {
      "x": -5,
      "y": 8,
      "z": 6,
      "name": "Soil_Ash",
      "rotation": 1
    },
    {
      "x": -5,
      "y": 0,
      "z": 7,
      "name": "Rock_Basalt"
    },
    {
      "x": -5,
      "y": 1,
      "z": 7,
      "name": "Rock_Basalt",
      "rotation": 1
    },
    {
      "x": -5,
      "y": 2,
      "z": 7,
      "name": "Rock_Basalt",
      "rotation": 1
    },
    {
      "x": -5,
      "y": 3,
      "z": 7,
      "name": "Rock_Basalt",
      "rotation": 1
    },
    {
      "x": -5,
      "y": 4,
      "z": 7,
      "name": "Rock_Stone",
      "rotation": 1
    },
    {
      "x": -5,
      "y": 5,
      "z": 7,
      "name": "Rock_Stone",
      "rotation": 1
    },
    {
      "x": -5,
      "y": 6,
      "z": 7,
      "name": "Rock_Stone",
      "rotation": 1
    },
    {
      "x": -5,
      "y": 7,
      "z": 7,
      "name": "Rock_Stone",
      "rotation": 1
    },
    {
      "x": -5,
      "y": 8,
      "z": 7,
      "name": "Soil_Ash",
      "rotation": 1
    },
    {
      "x": -4,
      "y": 0,
      "z": -6,
      "name": "Rock_Basalt"
    },
    {
      "x": -4,
      "y": 1,
      "z": -6,
      "name": "Rock_Basalt",
      "rotation": 1
    },
    {
      "x": -4,
      "y": 2,
      "z": -6,
      "name": "Rock_Basalt",
      "rotation": 1
    },
    {
      "x": -4,
      "y": 3,
      "z": -6,
      "name": "Rock_Basalt",
      "rotation": 1
    },
    {
      "x": -4,
      "y": 4,
      "z": -6,
      "name": "Rock_Stone",
      "rotation": 1
    },
    {
      "x": -4,
      "y": 5,
      "z": -6,
      "name": "Rock_Stone",
      "rotation": 1
    },
    {
      "x": -4,
      "y": 6,
      "z": -6,
      "name": "Rock_Stone",
      "rotation": 1
    },
    {
      "x": -4,
      "y": 7,
      "z": -6,
      "name": "Rock_Stone",
      "rotation": 1
    },
    {
      "x": -4,
      "y": 8,
      "z": -6,
      "name": "Rock_Stone",
      "rotation": 1
    },
    {
      "x": -4,
      "y": 0,
      "z": -5,
      "name": "Rock_Basalt"
    },
    {
      "x": -4,
      "y": 1,
      "z": -5,
      "name": "Rock_Basalt",
      "rotation": 1
    },
    {
      "x": -4,
      "y": 2,
      "z": -5,
      "name": "Rock_Basalt",
      "rotation": 1
    },
    {
      "x": -4,
      "y": 3,
      "z": -5,
      "name": "Rock_Basalt",
      "rotation": 1
    },
    {
      "x": -4,
      "y": 4,
      "z": -5,
      "name": "Rock_Stone",
      "rotation": 1
    },
    {
      "x": -4,
      "y": 5,
      "z": -5,
      "name": "Rock_Stone",
      "rotation": 1
    },
    {
      "x": -4,
      "y": 6,
      "z": -5,
      "name": "Rock_Stone",
      "rotation": 1
    },
    {
      "x": -4,
      "y": 7,
      "z": -5,
      "name": "Rock_Stone",
      "rotation": 1
    },
    {
      "x": -4,
      "y": 8,
      "z": -5,
      "name": "Rock_Stone_Mossy",
      "rotation": 1
    },
    {
      "x": -4,
      "y": 0,
      "z": -4,
      "name": "Rock_Basalt"
    },
    {
      "x": -4,
      "y": 1,
      "z": -4,
      "name": "Rock_Basalt",
      "rotation": 1
    },
    {
      "x": -4,
      "y": 2,
      "z": -4,
      "name": "Rock_Basalt",
      "rotation": 1
    },
    {
      "x": -4,
      "y": 3,
      "z": -4,
      "name": "Rock_Basalt",
      "rotation": 1
    },
    {
      "x": -4,
      "y": 4,
      "z": -4,
      "name": "Rock_Stone",
      "rotation": 1
    },
    {
      "x": -4,
      "y": 5,
      "z": -4,
      "name": "Rock_Stone",
      "rotation": 1
    },
    {
      "x": -4,
      "y": 6,
      "z": -4,
      "name": "Rock_Stone",
      "rotation": 1
    },
    {
      "x": -4,
      "y": 7,
      "z": -4,
      "name": "Rock_Stone",
      "rotation": 1
    },
    {
      "x": -4,
      "y": 8,
      "z": -4,
      "name": "Rock_Stone",
      "rotation": 1
    },
    {
      "x": -4,
      "y": 0,
      "z": -3,
      "name": "Rock_Basalt"
    },
    {
      "x": -4,
      "y": 1,
      "z": -3,
      "name": "Rock_Basalt",
      "rotation": 1
    },
    {
      "x": -4,
      "y": 2,
      "z": -3,
      "name": "Rock_Basalt",
      "rotation": 1
    },
    {
      "x": -4,
      "y": 3,
      "z": -3,
      "name": "Rock_Basalt",
      "rotation": 1
    },
    {
      "x": -4,
      "y": 4,
      "z": -3,
      "name": "Rock_Stone",
      "rotation": 1
    },
    {
      "x": -4,
      "y": 5,
      "z": -3,
      "name": "Rock_Stone",
      "rotation": 1
    },
    {
      "x": -4,
      "y": 6,
      "z": -3,
      "name": "Rock_Stone",
      "rotation": 1
    },
    {
      "x": -4,
      "y": 7,
      "z": -3,
      "name": "Rock_Stone",
      "rotation": 1
    },
    {
      "x": -4,
      "y": 8,
      "z": -3,
      "name": "Soil_Ash"
    },
    {
      "x": -4,
      "y": 0,
      "z": -2,
      "name": "Rock_Basalt"
    },
    {
      "x": -4,
      "y": 1,
      "z": -2,
      "name": "Rock_Basalt",
      "rotation": 1
    },
    {
      "x": -4,
      "y": 2,
      "z": -2,
      "name": "Rock_Basalt",
      "rotation": 1
    },
    {
      "x": -4,
      "y": 3,
      "z": -2,
      "name": "Rock_Basalt",
      "rotation": 1
    },
    {
      "x": -4,
      "y": 4,
      "z": -2,
      "name": "Rock_Stone",
      "rotation": 1
    },
    {
      "x": -4,
      "y": 5,
      "z": -2,
      "name": "Rock_Stone",
      "rotation": 1
    },
    {
      "x": -4,
      "y": 6,
      "z": -2,
      "name": "Rock_Stone",
      "rotation": 1
    },
    {
      "x": -4,
      "y": 7,
      "z": -2,
      "name": "Rock_Stone",
      "rotation": 1
    },
    {
      "x": -4,
      "y": 8,
      "z": -2,
      "name": "*Cloth_Block_Wool_Gray_Stairs_State_Definitions_Inverted_Corner_Right"
    },
    {
      "x": -4,
      "y": 0,
      "z": -1,
      "name": "Rock_Basalt"
    },
    {
      "x": -4,
      "y": 1,
      "z": -1,
      "name": "Rock_Basalt",
      "rotation": 1
    },
    {
      "x": -4,
      "y": 2,
      "z": -1,
      "name": "Rock_Basalt",
      "rotation": 1
    },
    {
      "x": -4,
      "y": 3,
      "z": -1,
      "name": "Rock_Basalt",
      "rotation": 1
    },
    {
      "x": -4,
      "y": 4,
      "z": -1,
      "name": "Rock_Stone",
      "rotation": 1
    },
    {
      "x": -4,
      "y": 5,
      "z": -1,
      "name": "Rock_Stone",
      "rotation": 1
    },
    {
      "x": -4,
      "y": 6,
      "z": -1,
      "name": "Rock_Stone",
      "rotation": 1
    },
    {
      "x": -4,
      "y": 7,
      "z": -1,
      "name": "Rock_Stone",
      "rotation": 1
    },
    {
      "x": -4,
      "y": 8,
      "z": -1,
      "name": "Cloth_Block_Wool_Gray_Stairs",
      "rotation": 3
    },
    {
      "x": -4,
      "y": 0,
      "z": 0,
      "name": "Rock_Basalt"
    },
    {
      "x": -4,
      "y": 1,
      "z": 0,
      "name": "Rock_Basalt",
      "rotation": 1
    },
    {
      "x": -4,
      "y": 2,
      "z": 0,
      "name": "Rock_Basalt",
      "rotation": 1
    },
    {
      "x": -4,
      "y": 3,
      "z": 0,
      "name": "Rock_Basalt",
      "rotation": 1
    },
    {
      "x": -4,
      "y": 4,
      "z": 0,
      "name": "Rock_Stone",
      "rotation": 1
    },
    {
      "x": -4,
      "y": 5,
      "z": 0,
      "name": "Rock_Stone",
      "rotation": 1
    },
    {
      "x": -4,
      "y": 6,
      "z": 0,
      "name": "Rock_Stone",
      "rotation": 1
    },
    {
      "x": -4,
      "y": 7,
      "z": 0,
      "name": "Rock_Stone",
      "rotation": 1
    },
    {
      "x": -4,
      "y": 8,
      "z": 0,
      "name": "Cloth_Block_Wool_Gray_Stairs",
      "rotation": 3
    },
    {
      "x": -4,
      "y": 0,
      "z": 1,
      "name": "Rock_Basalt"
    },
    {
      "x": -4,
      "y": 1,
      "z": 1,
      "name": "Rock_Basalt",
      "rotation": 1
    },
    {
      "x": -4,
      "y": 2,
      "z": 1,
      "name": "Rock_Basalt",
      "rotation": 1
    },
    {
      "x": -4,
      "y": 3,
      "z": 1,
      "name": "Rock_Basalt",
      "rotation": 1
    },
    {
      "x": -4,
      "y": 4,
      "z": 1,
      "name": "Rock_Stone",
      "rotation": 1
    },
    {
      "x": -4,
      "y": 5,
      "z": 1,
      "name": "Rock_Stone",
      "rotation": 1
    },
    {
      "x": -4,
      "y": 6,
      "z": 1,
      "name": "Rock_Stone",
      "rotation": 1
    },
    {
      "x": -4,
      "y": 7,
      "z": 1,
      "name": "Rock_Stone",
      "rotation": 1
    },
    {
      "x": -4,
      "y": 8,
      "z": 1,
      "name": "Cloth_Block_Wool_Gray_Stairs",
      "rotation": 3
    },
    {
      "x": -4,
      "y": 0,
      "z": 2,
      "name": "Rock_Basalt"
    },
    {
      "x": -4,
      "y": 1,
      "z": 2,
      "name": "Rock_Basalt",
      "rotation": 1
    },
    {
      "x": -4,
      "y": 2,
      "z": 2,
      "name": "Rock_Basalt",
      "rotation": 1
    },
    {
      "x": -4,
      "y": 3,
      "z": 2,
      "name": "Rock_Basalt",
      "rotation": 1
    },
    {
      "x": -4,
      "y": 4,
      "z": 2,
      "name": "Rock_Stone",
      "rotation": 1
    },
    {
      "x": -4,
      "y": 5,
      "z": 2,
      "name": "Rock_Stone",
      "rotation": 1
    },
    {
      "x": -4,
      "y": 6,
      "z": 2,
      "name": "Rock_Stone",
      "rotation": 1
    },
    {
      "x": -4,
      "y": 7,
      "z": 2,
      "name": "Rock_Stone",
      "rotation": 1
    },
    {
      "x": -4,
      "y": 8,
      "z": 2,
      "name": "Cloth_Block_Wool_Gray_Stairs",
      "rotation": 3
    },
    {
      "x": -4,
      "y": 0,
      "z": 3,
      "name": "Rock_Basalt"
    },
    {
      "x": -4,
      "y": 1,
      "z": 3,
      "name": "Rock_Basalt",
      "rotation": 1
    },
    {
      "x": -4,
      "y": 2,
      "z": 3,
      "name": "Rock_Basalt",
      "rotation": 1
    },
    {
      "x": -4,
      "y": 3,
      "z": 3,
      "name": "Rock_Basalt",
      "rotation": 1
    },
    {
      "x": -4,
      "y": 4,
      "z": 3,
      "name": "Rock_Stone",
      "rotation": 1
    },
    {
      "x": -4,
      "y": 5,
      "z": 3,
      "name": "Rock_Stone",
      "rotation": 1
    },
    {
      "x": -4,
      "y": 6,
      "z": 3,
      "name": "Rock_Stone",
      "rotation": 1
    },
    {
      "x": -4,
      "y": 7,
      "z": 3,
      "name": "Rock_Stone",
      "rotation": 1
    },
    {
      "x": -4,
      "y": 8,
      "z": 3,
      "name": "*Cloth_Block_Wool_Gray_Stairs_State_Definitions_Inverted_Corner_Left",
      "rotation": 2
    },
    {
      "x": -4,
      "y": 0,
      "z": 4,
      "name": "Rock_Basalt"
    },
    {
      "x": -4,
      "y": 1,
      "z": 4,
      "name": "Rock_Basalt",
      "rotation": 1
    },
    {
      "x": -4,
      "y": 2,
      "z": 4,
      "name": "Rock_Basalt",
      "rotation": 1
    },
    {
      "x": -4,
      "y": 3,
      "z": 4,
      "name": "Rock_Basalt",
      "rotation": 1
    },
    {
      "x": -4,
      "y": 4,
      "z": 4,
      "name": "Rock_Stone",
      "rotation": 1
    },
    {
      "x": -4,
      "y": 5,
      "z": 4,
      "name": "Rock_Stone",
      "rotation": 1
    },
    {
      "x": -4,
      "y": 6,
      "z": 4,
      "name": "Rock_Stone",
      "rotation": 1
    },
    {
      "x": -4,
      "y": 7,
      "z": 4,
      "name": "Rock_Stone",
      "rotation": 1
    },
    {
      "x": -4,
      "y": 8,
      "z": 4,
      "name": "Soil_Ash"
    },
    {
      "x": -4,
      "y": 0,
      "z": 5,
      "name": "Rock_Basalt"
    },
    {
      "x": -4,
      "y": 1,
      "z": 5,
      "name": "Rock_Basalt",
      "rotation": 1
    },
    {
      "x": -4,
      "y": 2,
      "z": 5,
      "name": "Rock_Basalt",
      "rotation": 1
    },
    {
      "x": -4,
      "y": 3,
      "z": 5,
      "name": "Rock_Basalt",
      "rotation": 1
    },
    {
      "x": -4,
      "y": 4,
      "z": 5,
      "name": "Rock_Stone",
      "rotation": 1
    },
    {
      "x": -4,
      "y": 5,
      "z": 5,
      "name": "Rock_Stone",
      "rotation": 1
    },
    {
      "x": -4,
      "y": 6,
      "z": 5,
      "name": "Rock_Stone",
      "rotation": 1
    },
    {
      "x": -4,
      "y": 7,
      "z": 5,
      "name": "Rock_Stone",
      "rotation": 1
    },
    {
      "x": -4,
      "y": 8,
      "z": 5,
      "name": "Rock_Stone",
      "rotation": 1
    },
    {
      "x": -4,
      "y": 0,
      "z": 6,
      "name": "Rock_Basalt"
    },
    {
      "x": -4,
      "y": 1,
      "z": 6,
      "name": "Rock_Basalt",
      "rotation": 1
    },
    {
      "x": -4,
      "y": 2,
      "z": 6,
      "name": "Rock_Basalt",
      "rotation": 1
    },
    {
      "x": -4,
      "y": 3,
      "z": 6,
      "name": "Rock_Basalt",
      "rotation": 1
    },
    {
      "x": -4,
      "y": 4,
      "z": 6,
      "name": "Rock_Stone",
      "rotation": 1
    },
    {
      "x": -4,
      "y": 5,
      "z": 6,
      "name": "Rock_Stone",
      "rotation": 1
    },
    {
      "x": -4,
      "y": 6,
      "z": 6,
      "name": "Rock_Stone",
      "rotation": 1
    },
    {
      "x": -4,
      "y": 7,
      "z": 6,
      "name": "Rock_Stone",
      "rotation": 1
    },
    {
      "x": -4,
      "y": 8,
      "z": 6,
      "name": "Rock_Stone_Mossy"
    },
    {
      "x": -4,
      "y": 0,
      "z": 7,
      "name": "Rock_Basalt"
    },
    {
      "x": -4,
      "y": 1,
      "z": 7,
      "name": "Rock_Basalt",
      "rotation": 1
    },
    {
      "x": -4,
      "y": 2,
      "z": 7,
      "name": "Rock_Basalt",
      "rotation": 1
    },
    {
      "x": -4,
      "y": 3,
      "z": 7,
      "name": "Rock_Basalt",
      "rotation": 1
    },
    {
      "x": -4,
      "y": 4,
      "z": 7,
      "name": "Rock_Stone",
      "rotation": 1
    },
    {
      "x": -4,
      "y": 5,
      "z": 7,
      "name": "Rock_Stone",
      "rotation": 1
    },
    {
      "x": -4,
      "y": 6,
      "z": 7,
      "name": "Rock_Stone",
      "rotation": 1
    },
    {
      "x": -4,
      "y": 7,
      "z": 7,
      "name": "Rock_Stone",
      "rotation": 1
    },
    {
      "x": -4,
      "y": 8,
      "z": 7,
      "name": "Rock_Stone",
      "rotation": 1
    },
    {
      "x": -3,
      "y": 0,
      "z": -6,
      "name": "Rock_Basalt"
    },
    {
      "x": -3,
      "y": 1,
      "z": -6,
      "name": "Rock_Basalt"
    },
    {
      "x": -3,
      "y": 2,
      "z": -6,
      "name": "Rock_Basalt"
    },
    {
      "x": -3,
      "y": 3,
      "z": -6,
      "name": "Rock_Basalt"
    },
    {
      "x": -3,
      "y": 4,
      "z": -6,
      "name": "Rock_Stone"
    },
    {
      "x": -3,
      "y": 5,
      "z": -6,
      "name": "Rock_Stone"
    },
    {
      "x": -3,
      "y": 6,
      "z": -6,
      "name": "Rock_Stone"
    },
    {
      "x": -3,
      "y": 7,
      "z": -6,
      "name": "Rock_Stone"
    },
    {
      "x": -3,
      "y": 8,
      "z": -6,
      "name": "Rock_Stone"
    },
    {
      "x": -3,
      "y": 0,
      "z": -5,
      "name": "Rock_Basalt"
    },
    {
      "x": -3,
      "y": 1,
      "z": -5,
      "name": "Rock_Basalt"
    },
    {
      "x": -3,
      "y": 2,
      "z": -5,
      "name": "Rock_Basalt"
    },
    {
      "x": -3,
      "y": 3,
      "z": -5,
      "name": "Rock_Basalt"
    },
    {
      "x": -3,
      "y": 4,
      "z": -5,
      "name": "Rock_Stone"
    },
    {
      "x": -3,
      "y": 5,
      "z": -5,
      "name": "Rock_Stone"
    },
    {
      "x": -3,
      "y": 6,
      "z": -5,
      "name": "Rock_Stone"
    },
    {
      "x": -3,
      "y": 7,
      "z": -5,
      "name": "Rock_Stone"
    },
    {
      "x": -3,
      "y": 8,
      "z": -5,
      "name": "Rock_Stone"
    },
    {
      "x": -3,
      "y": 0,
      "z": -4,
      "name": "Rock_Basalt"
    },
    {
      "x": -3,
      "y": 1,
      "z": -4,
      "name": "Rock_Basalt"
    },
    {
      "x": -3,
      "y": 2,
      "z": -4,
      "name": "Rock_Basalt"
    },
    {
      "x": -3,
      "y": 3,
      "z": -4,
      "name": "Rock_Basalt"
    },
    {
      "x": -3,
      "y": 4,
      "z": -4,
      "name": "Rock_Stone"
    },
    {
      "x": -3,
      "y": 5,
      "z": -4,
      "name": "Rock_Stone"
    },
    {
      "x": -3,
      "y": 6,
      "z": -4,
      "name": "Rock_Stone"
    },
    {
      "x": -3,
      "y": 7,
      "z": -4,
      "name": "Rock_Stone"
    },
    {
      "x": -3,
      "y": 8,
      "z": -4,
      "name": "Rock_Stone"
    },
    {
      "x": -3,
      "y": 0,
      "z": -3,
      "name": "Rock_Basalt"
    },
    {
      "x": -3,
      "y": 1,
      "z": -3,
      "name": "Rock_Basalt"
    },
    {
      "x": -3,
      "y": 2,
      "z": -3,
      "name": "Rock_Basalt"
    },
    {
      "x": -3,
      "y": 3,
      "z": -3,
      "name": "Rock_Basalt"
    },
    {
      "x": -3,
      "y": 4,
      "z": -3,
      "name": "Rock_Stone"
    },
    {
      "x": -3,
      "y": 5,
      "z": -3,
      "name": "Rock_Stone"
    },
    {
      "x": -3,
      "y": 6,
      "z": -3,
      "name": "Rock_Stone"
    },
    {
      "x": -3,
      "y": 7,
      "z": -3,
      "name": "Rock_Stone"
    },
    {
      "x": -3,
      "y": 8,
      "z": -3,
      "name": "Rock_Stone"
    },
    {
      "x": -3,
      "y": 0,
      "z": -2,
      "name": "Rock_Basalt"
    },
    {
      "x": -3,
      "y": 1,
      "z": -2,
      "name": "Rock_Basalt"
    },
    {
      "x": -3,
      "y": 2,
      "z": -2,
      "name": "Rock_Basalt"
    },
    {
      "x": -3,
      "y": 3,
      "z": -2,
      "name": "Rock_Basalt"
    },
    {
      "x": -3,
      "y": 4,
      "z": -2,
      "name": "Rock_Stone"
    },
    {
      "x": -3,
      "y": 5,
      "z": -2,
      "name": "Rock_Stone"
    },
    {
      "x": -3,
      "y": 6,
      "z": -2,
      "name": "Rock_Stone"
    },
    {
      "x": -3,
      "y": 7,
      "z": -2,
      "name": "Rock_Stone"
    },
    {
      "x": -3,
      "y": 8,
      "z": -2,
      "name": "Soil_Ash"
    },
    {
      "x": -3,
      "y": 0,
      "z": -1,
      "name": "Rock_Basalt"
    },
    {
      "x": -3,
      "y": 1,
      "z": -1,
      "name": "Rock_Basalt"
    },
    {
      "x": -3,
      "y": 2,
      "z": -1,
      "name": "Rock_Basalt"
    },
    {
      "x": -3,
      "y": 3,
      "z": -1,
      "name": "Rock_Basalt"
    },
    {
      "x": -3,
      "y": 4,
      "z": -1,
      "name": "Rock_Stone"
    },
    {
      "x": -3,
      "y": 5,
      "z": -1,
      "name": "Rock_Stone"
    },
    {
      "x": -3,
      "y": 6,
      "z": -1,
      "name": "Rock_Stone"
    },
    {
      "x": -3,
      "y": 7,
      "z": -1,
      "name": "Rock_Stone"
    },
    {
      "x": -3,
      "y": 8,
      "z": -1,
      "name": "Soil_Ash"
    },
    {
      "x": -3,
      "y": 0,
      "z": 0,
      "name": "Rock_Basalt"
    },
    {
      "x": -3,
      "y": 1,
      "z": 0,
      "name": "Rock_Basalt"
    },
    {
      "x": -3,
      "y": 2,
      "z": 0,
      "name": "Rock_Basalt"
    },
    {
      "x": -3,
      "y": 3,
      "z": 0,
      "name": "Rock_Basalt"
    },
    {
      "x": -3,
      "y": 4,
      "z": 0,
      "name": "Rock_Stone"
    },
    {
      "x": -3,
      "y": 5,
      "z": 0,
      "name": "Rock_Stone"
    },
    {
      "x": -3,
      "y": 6,
      "z": 0,
      "name": "Rock_Stone"
    },
    {
      "x": -3,
      "y": 7,
      "z": 0,
      "name": "Rock_Stone"
    },
    {
      "x": -3,
      "y": 8,
      "z": 0,
      "name": "Soil_Ash"
    },
    {
      "x": -3,
      "y": 0,
      "z": 1,
      "name": "Rock_Basalt"
    },
    {
      "x": -3,
      "y": 1,
      "z": 1,
      "name": "Rock_Basalt"
    },
    {
      "x": -3,
      "y": 2,
      "z": 1,
      "name": "Rock_Basalt"
    },
    {
      "x": -3,
      "y": 3,
      "z": 1,
      "name": "Rock_Basalt"
    },
    {
      "x": -3,
      "y": 4,
      "z": 1,
      "name": "Rock_Stone"
    },
    {
      "x": -3,
      "y": 5,
      "z": 1,
      "name": "Rock_Stone"
    },
    {
      "x": -3,
      "y": 6,
      "z": 1,
      "name": "Rock_Stone"
    },
    {
      "x": -3,
      "y": 7,
      "z": 1,
      "name": "Rock_Stone"
    },
    {
      "x": -3,
      "y": 8,
      "z": 1,
      "name": "Soil_Ash"
    },
    {
      "x": -3,
      "y": 0,
      "z": 2,
      "name": "Rock_Basalt"
    },
    {
      "x": -3,
      "y": 1,
      "z": 2,
      "name": "Rock_Basalt"
    },
    {
      "x": -3,
      "y": 2,
      "z": 2,
      "name": "Rock_Basalt"
    },
    {
      "x": -3,
      "y": 3,
      "z": 2,
      "name": "Rock_Basalt"
    },
    {
      "x": -3,
      "y": 4,
      "z": 2,
      "name": "Rock_Stone"
    },
    {
      "x": -3,
      "y": 5,
      "z": 2,
      "name": "Rock_Stone"
    },
    {
      "x": -3,
      "y": 6,
      "z": 2,
      "name": "Rock_Stone"
    },
    {
      "x": -3,
      "y": 7,
      "z": 2,
      "name": "Rock_Stone"
    },
    {
      "x": -3,
      "y": 8,
      "z": 2,
      "name": "Soil_Ash"
    },
    {
      "x": -3,
      "y": 0,
      "z": 3,
      "name": "Rock_Basalt"
    },
    {
      "x": -3,
      "y": 1,
      "z": 3,
      "name": "Rock_Basalt"
    },
    {
      "x": -3,
      "y": 2,
      "z": 3,
      "name": "Rock_Basalt"
    },
    {
      "x": -3,
      "y": 3,
      "z": 3,
      "name": "Rock_Basalt"
    },
    {
      "x": -3,
      "y": 4,
      "z": 3,
      "name": "Rock_Stone"
    },
    {
      "x": -3,
      "y": 5,
      "z": 3,
      "name": "Rock_Stone"
    },
    {
      "x": -3,
      "y": 6,
      "z": 3,
      "name": "Rock_Stone"
    },
    {
      "x": -3,
      "y": 7,
      "z": 3,
      "name": "Rock_Stone"
    },
    {
      "x": -3,
      "y": 8,
      "z": 3,
      "name": "Soil_Ash"
    },
    {
      "x": -3,
      "y": 0,
      "z": 4,
      "name": "Rock_Basalt"
    },
    {
      "x": -3,
      "y": 1,
      "z": 4,
      "name": "Rock_Basalt"
    },
    {
      "x": -3,
      "y": 2,
      "z": 4,
      "name": "Rock_Basalt"
    },
    {
      "x": -3,
      "y": 3,
      "z": 4,
      "name": "Rock_Basalt"
    },
    {
      "x": -3,
      "y": 4,
      "z": 4,
      "name": "Rock_Stone"
    },
    {
      "x": -3,
      "y": 5,
      "z": 4,
      "name": "Rock_Stone"
    },
    {
      "x": -3,
      "y": 6,
      "z": 4,
      "name": "Rock_Stone"
    },
    {
      "x": -3,
      "y": 7,
      "z": 4,
      "name": "Rock_Stone"
    },
    {
      "x": -3,
      "y": 8,
      "z": 4,
      "name": "Rock_Stone"
    },
    {
      "x": -3,
      "y": 0,
      "z": 5,
      "name": "Rock_Basalt"
    },
    {
      "x": -3,
      "y": 1,
      "z": 5,
      "name": "Rock_Basalt"
    },
    {
      "x": -3,
      "y": 2,
      "z": 5,
      "name": "Rock_Basalt"
    },
    {
      "x": -3,
      "y": 3,
      "z": 5,
      "name": "Rock_Basalt"
    },
    {
      "x": -3,
      "y": 4,
      "z": 5,
      "name": "Rock_Stone"
    },
    {
      "x": -3,
      "y": 5,
      "z": 5,
      "name": "Rock_Stone"
    },
    {
      "x": -3,
      "y": 6,
      "z": 5,
      "name": "Rock_Stone"
    },
    {
      "x": -3,
      "y": 7,
      "z": 5,
      "name": "Rock_Stone"
    },
    {
      "x": -3,
      "y": 8,
      "z": 5,
      "name": "Rock_Stone"
    },
    {
      "x": -3,
      "y": 0,
      "z": 6,
      "name": "Rock_Basalt"
    },
    {
      "x": -3,
      "y": 1,
      "z": 6,
      "name": "Rock_Basalt"
    },
    {
      "x": -3,
