{
  "version": 8,
  "blockIdVersion": 11,
  "anchorX": 0,
  "anchorY": 0,
  "anchorZ": 0,
  "blocks": [
    {
      "x": -17,
      "y": 0,
      "z": -3,
      "name": "Rock_Basalt"
    },
    {
      "x": -17,
      "y": 1,
      "z": -3,
      "name": "Empty"
    },
    {
      "x": -17,
      "y": 2,
      "z": -3,
      "name": "Empty"
    },
    {
      "x": -17,
      "y": 3,
      "z": -3,
      "name": "Empty"
    },
    {
      "x": -17,
      "y": 8,
      "z": -3,
      "name": "Soil_Clay_Smooth_Red_Half",
      "rotation": 6
    },
    {
      "x": -17,
      "y": 9,
      "z": -3,
      "name": "Soil_Clay_Smooth_Red_Half",
      "rotation": 6
    },
    {
      "x": -17,
      "y": 0,
      "z": -2,
      "name": "Plant_Crop_Mushroom_Block_Green"
    },
    {
      "x": -17,
      "y": 1,
      "z": -2,
      "name": "Empty"
    },
    {
      "x": -17,
      "y": 2,
      "z": -2,
      "name": "Empty"
    },
    {
      "x": -17,
      "y": 3,
      "z": -2,
      "name": "Empty"
    },
    {
      "x": -17,
      "y": 7,
      "z": -2,
      "name": "Soil_Clay_Smooth_Red_Half",
      "rotation": 8
    },
    {
      "x": -17,
      "y": 8,
      "z": -2,
      "name": "Soil_Ash"
    },
    {
      "x": -17,
      "y": 0,
      "z": -1,
      "name": "Rock_Basalt_Cobble"
    },
    {
      "x": -17,
      "y": 1,
      "z": -1,
      "name": "Empty"
    },
    {
      "x": -17,
      "y": 2,
      "z": -1,
      "name": "Empty"
    },
    {
      "x": -17,
      "y": 3,
      "z": -1,
      "name": "Empty"
    },
    {
      "x": -17,
      "y": 7,
      "z": -1,
      "name": "Soil_Clay_Smooth_Red"
    },
    {
      "x": -17,
      "y": 8,
      "z": -1,
      "name": "Soil_Ash"
    },
    {
      "x": -17,
      "y": 0,
      "z": 0,
      "name": "Plant_Crop_Mushroom_Block_Green"
    },
    {
      "x": -17,
      "y": 1,
      "z": 0,
      "name": "Empty"
    },
    {
      "x": -17,
      "y": 2,
      "z": 0,
      "name": "Empty"
    },
    {
      "x": -17,
      "y": 3,
      "z": 0,
      "name": "Empty"
    },
    {
      "x": -17,
      "y": 7,
      "z": 0,
      "name": "Soil_Clay_Smooth_Red"
    },
    {
      "x": -17,
      "y": 8,
      "z": 0,
      "name": "Soil_Ash"
    },
    {
      "x": -17,
      "y": 0,
      "z": 1,
      "name": "Plant_Crop_Mushroom_Block_Green"
    },
    {
      "x": -17,
      "y": 1,
      "z": 1,
      "name": "Empty"
    },
    {
      "x": -17,
      "y": 2,
      "z": 1,
      "name": "Empty"
    },
    {
      "x": -17,
      "y": 3,
      "z": 1,
      "name": "Empty"
    },
    {
      "x": -17,
      "y": 7,
      "z": 1,
      "name": "Soil_Clay_Smooth_Red"
    },
    {
      "x": -17,
      "y": 8,
      "z": 1,
      "name": "Soil_Ash"
    },
    {
      "x": -17,
      "y": 0,
      "z": 2,
      "name": "Plant_Crop_Mushroom_Block_Green"
    },
    {
      "x": -17,
      "y": 1,
      "z": 2,
      "name": "Empty"
    },
    {
      "x": -17,
      "y": 2,
      "z": 2,
      "name": "Empty"
    },
    {
      "x": -17,
      "y": 3,
      "z": 2,
      "name": "Empty"
    },
    {
      "x": -17,
      "y": 7,
      "z": 2,
      "name": "Soil_Clay_Smooth_Red_Half",
      "rotation": 8
    },
    {
      "x": -17,
      "y": 8,
      "z": 2,
      "name": "Soil_Ash"
    },
    {
      "x": -17,
      "y": 0,
      "z": 3,
      "name": "Plant_Crop_Mushroom_Block_Green"
    },
    {
      "x": -17,
      "y": 1,
      "z": 3,
      "name": "Empty"
    },
    {
      "x": -17,
      "y": 2,
      "z": 3,
      "name": "Empty"
    },
    {
      "x": -17,
      "y": 3,
      "z": 3,
      "name": "Empty"
    },
    {
      "x": -17,
      "y": 8,
      "z": 3,
      "name": "Soil_Clay_Smooth_Red_Half",
      "rotation": 4
    },
    {
      "x": -17,
      "y": 9,
      "z": 3,
      "name": "Soil_Clay_Smooth_Red_Half",
      "rotation": 4
    },
    {
      "x": -16,
      "y": 0,
      "z": -3,
      "name": "Rock_Basalt"
    },
    {
      "x": -16,
      "y": 1,
      "z": -3,
      "name": "Empty"
    },
    {
      "x": -16,
      "y": 2,
      "z": -3,
      "name": "Empty"
    },
    {
      "x": -16,
      "y": 3,
      "z": -3,
      "name": "Empty"
    },
    {
      "x": -16,
      "y": 7,
      "z": -3,
      "name": "Soil_Clay_Smooth_Red_Stairs",
      "rotation": 8
    },
    {
      "x": -16,
      "y": 8,
      "z": -3,
      "name": "Soil_Clay_Smooth_Red"
    },
    {
      "x": -16,
      "y": 9,
      "z": -3,
      "name": "Soil_Clay_Smooth_Red"
    },
    {
      "x": -16,
      "y": 0,
      "z": -2,
      "name": "Rock_Basalt_Cobble"
    },
    {
      "x": -16,
      "y": 1,
      "z": -2,
      "name": "Empty"
    },
    {
      "x": -16,
      "y": 2,
      "z": -2,
      "name": "Empty"
    },
    {
      "x": -16,
      "y": 3,
      "z": -2,
      "name": "Empty"
    },
    {
      "x": -16,
      "y": 7,
      "z": -2,
      "name": "Soil_Clay_Smooth_Red"
    },
    {
      "x": -16,
      "y": 8,
      "z": -2,
      "name": "Soil_Ash"
    },
    {
      "x": -16,
      "y": 0,
      "z": -1,
      "name": "Ore_Iron_Basalt_Cracked"
    },
    {
      "x": -16,
      "y": 1,
      "z": -1,
      "name": "Empty"
    },
    {
      "x": -16,
      "y": 2,
      "z": -1,
      "name": "Empty"
    },
    {
      "x": -16,
      "y": 3,
      "z": -1,
      "name": "Empty"
    },
    {
      "x": -16,
      "y": 7,
      "z": -1,
      "name": "Soil_Clay_Smooth_Red"
    },
    {
      "x": -16,
      "y": 8,
      "z": -1,
      "name": "Soil_Ash"
    },
    {
      "x": -16,
      "y": 0,
      "z": 0,
      "name": "Rock_Basalt"
    },
    {
      "x": -16,
      "y": 1,
      "z": 0,
      "name": "Empty"
    },
    {
      "x": -16,
      "y": 2,
      "z": 0,
      "name": "Empty"
    },
    {
      "x": -16,
      "y": 3,
      "z": 0,
      "name": "Empty"
    },
    {
      "x": -16,
      "y": 7,
      "z": 0,
      "name": "Soil_Clay_Smooth_Red"
    },
    {
      "x": -16,
      "y": 8,
      "z": 0,
      "name": "Cloth_Block_Wool_Gray_Half"
    },
    {
      "x": -16,
      "y": 0,
      "z": 1,
      "name": "Rock_Basalt"
    },
    {
      "x": -16,
      "y": 1,
      "z": 1,
      "name": "Empty"
    },
    {
      "x": -16,
      "y": 2,
      "z": 1,
      "name": "Empty"
    },
    {
      "x": -16,
      "y": 3,
      "z": 1,
      "name": "Empty"
    },
    {
      "x": -16,
      "y": 7,
      "z": 1,
      "name": "Soil_Clay_Smooth_Red"
    },
    {
      "x": -16,
      "y": 8,
      "z": 1,
      "name": "Soil_Ash"
    },
    {
      "x": -16,
      "y": 0,
      "z": 2,
      "name": "Rock_Basalt"
    },
    {
      "x": -16,
      "y": 1,
      "z": 2,
      "name": "Empty"
    },
    {
      "x": -16,
      "y": 2,
      "z": 2,
      "name": "Empty"
    },
    {
      "x": -16,
      "y": 3,
      "z": 2,
      "name": "Empty"
    },
    {
      "x": -16,
      "y": 7,
      "z": 2,
      "name": "Soil_Clay_Smooth_Red"
    },
    {
      "x": -16,
      "y": 8,
      "z": 2,
      "name": "Soil_Ash"
    },
    {
      "x": -16,
      "y": 0,
      "z": 3,
      "name": "Rock_Basalt_Cobble"
    },
    {
      "x": -16,
      "y": 1,
      "z": 3,
      "name": "Empty"
    },
    {
      "x": -16,
      "y": 2,
      "z": 3,
      "name": "Empty"
    },
    {
      "x": -16,
      "y": 3,
      "z": 3,
      "name": "Empty"
    },
    {
      "x": -16,
      "y": 7,
      "z": 3,
      "name": "Soil_Clay_Smooth_Red_Stairs",
      "rotation": 10
    },
    {
      "x": -16,
      "y": 8,
      "z": 3,
      "name": "Soil_Clay_Smooth_Red"
    },
    {
      "x": -16,
      "y": 9,
      "z": 3,
      "name": "Soil_Clay_Smooth_Red"
    },
    {
      "x": -15,
      "y": 0,
      "z": -3,
      "name": "Rock_Basalt_Cobble"
    },
    {
      "x": -15,
      "y": 1,
      "z": -3,
      "name": "Plant_Seaweed_Grass"
    },
    {
      "x": -15,
      "y": 2,
      "z": -3,
      "name": "Empty"
    },
    {
      "x": -15,
      "y": 3,
      "z": -3,
      "name": "Empty"
    },
    {
      "x": -15,
      "y": 8,
      "z": -3,
      "name": "Soil_Clay_Smooth_Red_Half",
      "rotation": 6
    },
    {
      "x": -15,
      "y": 9,
      "z": -3,
      "name": "Soil_Clay_Smooth_Red_Half",
      "rotation": 6
    },
    {
      "x": -15,
      "y": 0,
      "z": -2,
      "name": "Rock_Basalt_Cobble"
    },
    {
      "x": -15,
      "y": 1,
      "z": -2,
      "name": "Empty"
    },
    {
      "x": -15,
      "y": 2,
      "z": -2,
      "name": "Empty"
    },
    {
      "x": -15,
      "y": 3,
      "z": -2,
      "name": "Empty"
    },
    {
      "x": -15,
      "y": 7,
      "z": -2,
      "name": "Soil_Clay_Smooth_Red_Half",
      "rotation": 8
    },
    {
      "x": -15,
      "y": 8,
      "z": -2,
      "name": "Soil_Ash"
    },
    {
      "x": -15,
      "y": 0,
      "z": -1,
      "name": "Ore_Iron_Basalt_Cracked"
    },
    {
      "x": -15,
      "y": 1,
      "z": -1,
      "name": "Empty"
    },
    {
      "x": -15,
      "y": 2,
      "z": -1,
      "name": "Empty"
    },
    {
      "x": -15,
      "y": 3,
      "z": -1,
      "name": "Empty"
    },
    {
      "x": -15,
      "y": 7,
      "z": -1,
      "name": "Soil_Clay_Smooth_Red"
    },
    {
      "x": -15,
      "y": 8,
      "z": -1,
      "name": "Soil_Ash"
    },
    {
      "x": -15,
      "y": 0,
      "z": 0,
      "name": "Rock_Basalt_Cobble"
    },
    {
      "x": -15,
      "y": 1,
      "z": 0,
      "name": "Empty"
    },
    {
      "x": -15,
      "y": 2,
      "z": 0,
      "name": "Empty"
    },
    {
      "x": -15,
      "y": 3,
      "z": 0,
      "name": "Empty"
    },
    {
      "x": -15,
      "y": 7,
      "z": 0,
      "name": "Soil_Clay_Smooth_Red"
    },
    {
      "x": -15,
      "y": 8,
      "z": 0,
      "name": "Cloth_Block_Wool_Gray_Stairs",
      "rotation": 3
    },
    {
      "x": -15,
      "y": 0,
      "z": 1,
      "name": "Plant_Crop_Mushroom_Block_Green"
    },
    {
      "x": -15,
      "y": 1,
      "z": 1,
      "name": "Empty"
    },
    {
      "x": -15,
      "y": 2,
      "z": 1,
      "name": "Empty"
    },
    {
      "x": -15,
      "y": 3,
      "z": 1,
      "name": "Empty"
    },
    {
      "x": -15,
      "y": 7,
      "z": 1,
      "name": "Soil_Clay_Smooth_Red"
    },
    {
      "x": -15,
      "y": 8,
      "z": 1,
      "name": "Soil_Ash"
    },
    {
      "x": -15,
      "y": 0,
      "z": 2,
      "name": "Rock_Basalt"
    },
    {
      "x": -15,
      "y": 1,
      "z": 2,
      "name": "Empty"
    },
    {
      "x": -15,
      "y": 2,
      "z": 2,
      "name": "Empty"
    },
    {
      "x": -15,
      "y": 3,
      "z": 2,
      "name": "Empty"
    },
    {
      "x": -15,
      "y": 7,
      "z": 2,
      "name": "Soil_Clay_Smooth_Red_Half",
      "rotation": 8
    },
    {
      "x": -15,
      "y": 8,
      "z": 2,
      "name": "Soil_Ash"
    },
    {
      "x": -15,
      "y": 0,
      "z": 3,
      "name": "Rock_Basalt"
    },
    {
      "x": -15,
      "y": 1,
      "z": 3,
      "name": "Empty"
    },
    {
      "x": -15,
      "y": 2,
      "z": 3,
      "name": "Empty"
    },
    {
      "x": -15,
      "y": 3,
      "z": 3,
      "name": "Empty"
    },
    {
      "x": -15,
      "y": 8,
      "z": 3,
      "name": "Soil_Clay_Smooth_Red_Half",
      "rotation": 4
    },
    {
      "x": -15,
      "y": 9,
      "z": 3,
      "name": "Soil_Clay_Smooth_Red_Half",
      "rotation": 4
    },
    {
      "x": -14,
      "y": 0,
      "z": -3,
      "name": "Plant_Crop_Mushroom_Block_Green"
    },
    {
      "x": -14,
      "y": 1,
      "z": -3,
      "name": "Empty"
    },
    {
      "x": -14,
      "y": 2,
      "z": -3,
      "name": "Empty"
    },
    {
      "x": -14,
      "y": 3,
      "z": -3,
      "name": "Empty"
    },
    {
      "x": -14,
      "y": 7,
      "z": -3,
      "name": "Soil_Clay_Smooth_Red_Stairs",
      "rotation": 8
    },
    {
      "x": -14,
      "y": 8,
      "z": -3,
      "name": "Soil_Clay_Smooth_Red"
    },
    {
      "x": -14,
      "y": 9,
      "z": -3,
      "name": "Soil_Clay_Smooth_Red"
    },
    {
      "x": -14,
      "y": 0,
      "z": -2,
      "name": "Rock_Basalt_Cobble"
    },
    {
      "x": -14,
      "y": 1,
      "z": -2,
      "name": "Empty"
    },
    {
      "x": -14,
      "y": 2,
      "z": -2,
      "name": "Empty"
    },
    {
      "x": -14,
      "y": 3,
      "z": -2,
      "name": "Empty"
    },
    {
      "x": -14,
      "y": 7,
      "z": -2,
      "name": "Soil_Clay_Smooth_Red"
    },
    {
      "x": -14,
      "y": 8,
      "z": -2,
      "name": "Soil_Ash"
    },
    {
      "x": -14,
      "y": 0,
      "z": -1,
      "name": "Plant_Crop_Mushroom_Block_Green"
    },
    {
      "x": -14,
      "y": 1,
      "z": -1,
      "name": "Empty"
    },
    {
      "x": -14,
      "y": 2,
      "z": -1,
      "name": "Empty"
    },
    {
      "x": -14,
      "y": 3,
      "z": -1,
      "name": "Empty"
    },
    {
      "x": -14,
      "y": 7,
      "z": -1,
      "name": "Soil_Clay_Smooth_Red"
    },
    {
      "x": -14,
      "y": 8,
      "z": -1,
      "name": "Soil_Ash"
    },
    {
      "x": -14,
      "y": 0,
      "z": 0,
      "name": "Ore_Iron_Basalt_Cracked"
    },
    {
      "x": -14,
      "y": 1,
      "z": 0,
      "name": "Empty"
    },
    {
      "x": -14,
      "y": 2,
      "z": 0,
      "name": "Empty"
    },
    {
      "x": -14,
      "y": 3,
      "z": 0,
      "name": "Empty"
    },
    {
      "x": -14,
      "y": 7,
      "z": 0,
      "name": "Soil_Clay_Smooth_Red"
    },
    {
      "x": -14,
      "y": 8,
      "z": 0,
      "name": "Soil_Ash"
    },
    {
      "x": -14,
      "y": 0,
      "z": 1,
      "name": "Rock_Basalt"
    },
    {
      "x": -14,
      "y": 1,
      "z": 1,
      "name": "Empty"
    },
    {
      "x": -14,
      "y": 2,
      "z": 1,
      "name": "Empty"
    },
    {
      "x": -14,
      "y": 3,
      "z": 1,
      "name": "Empty"
    },
    {
      "x": -14,
      "y": 7,
      "z": 1,
      "name": "Soil_Clay_Smooth_Red"
    },
    {
      "x": -14,
      "y": 8,
      "z": 1,
      "name": "Soil_Ash"
    },
    {
      "x": -14,
      "y": 0,
      "z": 2,
      "name": "Rock_Basalt"
    },
    {
      "x": -14,
      "y": 1,
      "z": 2,
      "name": "Empty"
    },
    {
      "x": -14,
      "y": 2,
      "z": 2,
      "name": "Empty"
    },
    {
      "x": -14,
      "y": 3,
      "z": 2,
      "name": "Empty"
    },
    {
      "x": -14,
      "y": 7,
      "z": 2,
      "name": "Soil_Clay_Smooth_Red"
    },
    {
      "x": -14,
      "y": 8,
      "z": 2,
      "name": "Soil_Ash"
    },
    {
      "x": -14,
      "y": 0,
      "z": 3,
      "name": "Rock_Basalt"
    },
    {
      "x": -14,
      "y": 1,
      "z": 3,
      "name": "Empty"
    },
    {
      "x": -14,
      "y": 2,
      "z": 3,
      "name": "Empty"
    },
    {
      "x": -14,
      "y": 3,
      "z": 3,
      "name": "Empty"
    },
    {
      "x": -14,
      "y": 7,
      "z": 3,
      "name": "Soil_Clay_Smooth_Red_Stairs",
      "rotation": 10
    },
    {
      "x": -14,
      "y": 8,
      "z": 3,
      "name": "Soil_Clay_Smooth_Red"
    },
    {
      "x": -14,
      "y": 9,
      "z": 3,
      "name": "Soil_Clay_Smooth_Red"
    },
    {
      "x": -13,
      "y": 0,
      "z": -3,
      "name": "Rock_Basalt"
    },
    {
      "x": -13,
      "y": 1,
      "z": -3,
      "name": "Empty"
    },
    {
      "x": -13,
      "y": 2,
      "z": -3,
      "name": "Empty"
    },
    {
      "x": -13,
      "y": 3,
      "z": -3,
      "name": "Empty"
    },
    {
      "x": -13,
      "y": 8,
      "z": -3,
      "name": "Soil_Clay_Smooth_Red_Half",
      "rotation": 6
    },
    {
      "x": -13,
      "y": 9,
      "z": -3,
      "name": "Soil_Clay_Smooth_Red_Half",
      "rotation": 6
    },
    {
      "x": -13,
      "y": 0,
      "z": -2,
      "name": "Rock_Basalt"
    },
    {
      "x": -13,
      "y": 1,
      "z": -2,
      "name": "Empty"
    },
    {
      "x": -13,
      "y": 2,
      "z": -2,
      "name": "Empty"
    },
    {
      "x": -13,
      "y": 3,
      "z": -2,
      "name": "Empty"
    },
    {
      "x": -13,
      "y": 7,
      "z": -2,
      "name": "Soil_Clay_Smooth_Red_Half",
      "rotation": 8
    },
    {
      "x": -13,
      "y": 8,
      "z": -2,
      "name": "Soil_Ash"
    },
    {
      "x": -13,
      "y": 0,
      "z": -1,
      "name": "Rock_Basalt"
    },
    {
      "x": -13,
      "y": 1,
      "z": -1,
      "name": "Empty"
    },
    {
      "x": -13,
      "y": 2,
      "z": -1,
      "name": "Empty"
    },
    {
      "x": -13,
      "y": 3,
      "z": -1,
      "name": "Empty"
    },
    {
      "x": -13,
      "y": 7,
      "z": -1,
      "name": "Soil_Clay_Smooth_Red"
    },
    {
      "x": -13,
      "y": 8,
      "z": -1,
      "name": "Soil_Ash"
    },
    {
      "x": -13,
      "y": 0,
      "z": 0,
      "name": "Ore_Iron_Basalt_Cracked"
    },
    {
      "x": -13,
      "y": 1,
      "z": 0,
      "name": "Empty"
    },
    {
      "x": -13,
      "y": 2,
      "z": 0,
      "name": "Empty"
    },
    {
      "x": -13,
      "y": 3,
      "z": 0,
      "name": "Empty"
    },
    {
      "x": -13,
      "y": 7,
      "z": 0,
      "name": "Soil_Clay_Smooth_Red"
    },
    {
      "x": -13,
      "y": 8,
      "z": 0,
      "name": "Cloth_Block_Wool_Gray_Stairs",
      "rotation": 1
    },
    {
      "x": -13,
      "y": 0,
      "z": 1,
      "name": "Rock_Basalt"
    },
    {
      "x": -13,
      "y": 1,
      "z": 1,
      "name": "Empty"
    },
    {
      "x": -13,
      "y": 2,
      "z": 1,
      "name": "Empty"
    },
    {
      "x": -13,
      "y": 3,
      "z": 1,
      "name": "Empty"
    },
    {
      "x": -13,
      "y": 7,
      "z": 1,
      "name": "Soil_Clay_Smooth_Red"
    },
    {
      "x": -13,
      "y": 8,
      "z": 1,
      "name": "Soil_Ash"
    },
    {
      "x": -13,
      "y": 0,
      "z": 2,
      "name": "Ore_Iron_Basalt_Cracked"
    },
    {
      "x": -13,
      "y": 1,
      "z": 2,
      "name": "Plant_Seaweed_Grass_Stack"
    },
    {
      "x": -13,
      "y": 2,
      "z": 2,
      "name": "Empty"
    },
    {
      "x": -13,
      "y": 3,
      "z": 2,
      "name": "Empty"
    },
    {
      "x": -13,
      "y": 7,
      "z": 2,
      "name": "Soil_Clay_Smooth_Red_Half",
      "rotation": 8
    },
    {
      "x": -13,
      "y": 8,
      "z": 2,
      "name": "Soil_Ash"
    },
    {
      "x": -13,
      "y": 0,
      "z": 3,
      "name": "Rock_Basalt"
    },
    {
      "x": -13,
      "y": 1,
      "z": 3,
      "name": "Empty"
    },
    {
      "x": -13,
      "y": 2,
      "z": 3,
      "name": "Empty"
    },
    {
      "x": -13,
      "y": 3,
      "z": 3,
      "name": "Empty"
    },
    {
      "x": -13,
      "y": 8,
      "z": 3,
      "name": "Soil_Clay_Smooth_Red_Half",
      "rotation": 4
    },
    {
      "x": -13,
      "y": 9,
      "z": 3,
      "name": "Soil_Clay_Smooth_Red_Half",
      "rotation": 4
    },
    {
      "x": -12,
      "y": 0,
      "z": -3,
      "name": "Rock_Basalt"
    },
    {
      "x": -12,
      "y": 1,
      "z": -3,
      "name": "Plant_Seaweed_Grass_Tall"
    },
    {
      "x": -12,
      "y": 2,
      "z": -3,
      "name": "Empty"
    },
    {
      "x": -12,
      "y": 3,
      "z": -3,
      "name": "Empty"
    },
    {
      "x": -12,
      "y": 7,
      "z": -3,
      "name": "Soil_Clay_Smooth_Red_Stairs",
      "rotation": 8
    },
    {
      "x": -12,
      "y": 8,
      "z": -3,
      "name": "Soil_Clay_Smooth_Red"
    },
    {
      "x": -12,
      "y": 9,
      "z": -3,
      "name": "Soil_Clay_Smooth_Red"
    },
    {
      "x": -12,
      "y": 0,
      "z": -2,
      "name": "Rock_Basalt"
    },
    {
      "x": -12,
      "y": 1,
      "z": -2,
      "name": "Empty"
    },
    {
      "x": -12,
      "y": 2,
      "z": -2,
      "name": "Empty"
    },
    {
      "x": -12,
      "y": 3,
      "z": -2,
      "name": "Empty"
    },
    {
      "x": -12,
      "y": 7,
      "z": -2,
      "name": "Soil_Clay_Smooth_Red"
    },
    {
      "x": -12,
      "y": 8,
      "z": -2,
      "name": "Soil_Ash"
    },
    {
      "x": -12,
      "y": 0,
      "z": -1,
      "name": "Rock_Basalt"
    },
    {
      "x": -12,
      "y": 1,
      "z": -1,
      "name": "Empty"
    },
    {
      "x": -12,
      "y": 2,
      "z": -1,
      "name": "Empty"
    },
    {
      "x": -12,
      "y": 3,
      "z": -1,
      "name": "Empty"
    },
    {
      "x": -12,
      "y": 7,
      "z": -1,
      "name": "Soil_Clay_Smooth_Red"
    },
    {
      "x": -12,
      "y": 8,
      "z": -1,
      "name": "Soil_Ash"
    },
    {
      "x": -12,
      "y": 0,
      "z": 0,
      "name": "Rock_Basalt"
    },
    {
      "x": -12,
      "y": 1,
      "z": 0,
      "name": "Empty"
    },
    {
      "x": -12,
      "y": 2,
      "z": 0,
      "name": "Empty"
    },
    {
      "x": -12,
      "y": 3,
      "z": 0,
      "name": "Empty"
    },
    {
      "x": -12,
      "y": 7,
      "z": 0,
      "name": "Soil_Clay_Smooth_Red"
    },
    {
      "x": -12,
      "y": 8,
      "z": 0,
      "name": "Cloth_Block_Wool_Gray_Half"
    },
    {
      "x": -12,
      "y": 0,
      "z": 1,
      "name": "Plant_Crop_Mushroom_Block_Green"
    },
    {
      "x": -12,
      "y": 1,
      "z": 1,
      "name": "Plant_Coral_Model_Green"
    },
    {
      "x": -12,
      "y": 2,
      "z": 1,
      "name": "Empty"
    },
    {
      "x": -12,
      "y": 3,
      "z": 1,
      "name": "Empty"
    },
    {
      "x": -12,
      "y": 7,
      "z": 1,
      "name": "Soil_Clay_Smooth_Red"
    },
    {
      "x": -12,
      "y": 8,
      "z": 1,
      "name": "Soil_Ash"
    },
    {
      "x": -12,
      "y": 0,
      "z": 2,
      "name": "Plant_Crop_Mushroom_Block_Green"
    },
    {
      "x": -12,
      "y": 1,
      "z": 2,
      "name": "Empty"
    },
    {
      "x": -12,
      "y": 2,
      "z": 2,
      "name": "Empty"
    },
    {
      "x": -12,
      "y": 3,
      "z": 2,
      "name": "Empty"
    },
    {
      "x": -12,
      "y": 7,
      "z": 2,
      "name": "Soil_Clay_Smooth_Red"
    },
    {
      "x": -12,
      "y": 8,
      "z": 2,
      "name": "Soil_Ash"
    },
    {
      "x": -12,
      "y": 0,
      "z": 3,
      "name": "Plant_Crop_Mushroom_Block_Green"
    },
    {
      "x": -12,
      "y": 1,
      "z": 3,
      "name": "Empty"
    },
    {
      "x": -12,
      "y": 2,
      "z": 3,
      "name": "Empty"
    },
    {
      "x": -12,
      "y": 3,
      "z": 3,
      "name": "Empty"
    },
    {
      "x": -12,
      "y": 7,
      "z": 3,
      "name": "Soil_Clay_Smooth_Red_Stairs",
      "rotation": 10
    },
    {
      "x": -12,
      "y": 8,
      "z": 3,
      "name": "Soil_Clay_Smooth_Red"
    },
    {
      "x": -12,
      "y": 9,
      "z": 3,
      "name": "Soil_Clay_Smooth_Red"
    },
    {
      "x": -11,
      "y": 0,
      "z": -3,
      "name": "Plant_Crop_Mushroom_Block_Green"
    },
    {
      "x": -11,
      "y": 1,
      "z": -3,
      "name": "Empty"
    },
    {
      "x": -11,
      "y": 2,
      "z": -3,
      "name": "Empty"
    },
    {
      "x": -11,
      "y": 3,
      "z": -3,
      "name": "Empty"
    },
    {
      "x": -11,
      "y": 8,
      "z": -3,
      "name": "Soil_Clay_Smooth_Red_Half",
      "rotation": 6
    },
    {
      "x": -11,
      "y": 9,
      "z": -3,
      "name": "Soil_Clay_Smooth_Red_Half",
      "rotation": 6
    },
    {
      "x": -11,
      "y": 0,
      "z": -2,
      "name": "Plant_Crop_Mushroom_Block_Green"
    },
    {
      "x": -11,
      "y": 1,
      "z": -2,
      "name": "Empty"
    },
    {
      "x": -11,
      "y": 2,
      "z": -2,
      "name": "Empty"
    },
    {
      "x": -11,
      "y": 3,
      "z": -2,
      "name": "Empty"
    },
    {
      "x": -11,
      "y": 7,
      "z": -2,
      "name": "Soil_Clay_Smooth_Red_Half",
      "rotation": 8
    },
    {
      "x": -11,
      "y": 8,
      "z": -2,
      "name": "Soil_Ash"
    },
    {
      "x": -11,
      "y": 0,
      "z": -1,
      "name": "Plant_Crop_Mushroom_Block_Green"
    },
    {
      "x": -11,
      "y": 1,
      "z": -1,
      "name": "Empty"
    },
    {
      "x": -11,
      "y": 2,
      "z": -1,
      "name": "Empty"
    },
    {
      "x": -11,
      "y": 3,
      "z": -1,
      "name": "Empty"
    },
    {
      "x": -11,
      "y": 7,
      "z": -1,
      "name": "Soil_Clay_Smooth_Red"
    },
    {
      "x": -11,
      "y": 8,
      "z": -1,
      "name": "Soil_Ash"
    },
    {
      "x": -11,
      "y": 0,
      "z": 0,
      "name": "Rock_Basalt_Cobble"
    },
    {
      "x": -11,
      "y": 1,
      "z": 0,
      "name": "Empty"
    },
    {
      "x": -11,
      "y": 2,
      "z": 0,
      "name": "Empty"
    },
    {
      "x": -11,
      "y": 3,
      "z": 0,
      "name": "Empty"
    },
    {
      "x": -11,
      "y": 7,
      "z": 0,
      "name": "Soil_Clay_Smooth_Red"
    },
    {
      "x": -11,
      "y": 8,
      "z": 0,
      "name": "Soil_Ash"
    },
    {
      "x": -11,
      "y": 0,
      "z": 1,
      "name": "Rock_Basalt"
    },
    {
      "x": -11,
      "y": 1,
      "z": 1,
      "name": "Empty"
    },
    {
      "x": -11,
      "y": 2,
      "z": 1,
      "name": "Empty"
    },
    {
      "x": -11,
      "y": 3,
      "z": 1,
      "name": "Empty"
    },
    {
      "x": -11,
      "y": 7,
      "z": 1,
      "name": "Soil_Clay_Smooth_Red"
    },
    {
      "x": -11,
      "y": 8,
      "z": 1,
      "name": "Soil_Ash"
    },
    {
      "x": -11,
      "y": 0,
      "z": 2,
      "name": "Plant_Crop_Mushroom_Block_Green"
    },
    {
      "x": -11,
      "y": 1,
      "z": 2,
      "name": "Plant_Seaweed_Grass_Stack"
    },
    {
      "x": -11,
      "y": 2,
      "z": 2,
      "name": "Empty"
    },
    {
      "x": -11,
      "y": 3,
      "z": 2,
      "name": "Empty"
    },
    {
      "x": -11,
      "y": 7,
      "z": 2,
      "name": "Soil_Clay_Smooth_Red_Half",
      "rotation": 8
    },
    {
      "x": -11,
      "y": 8,
      "z": 2,
      "name": "Soil_Ash"
    },
    {
      "x": -11,
      "y": 0,
      "z": 3,
      "name": "Rock_Basalt"
    },
    {
      "x": -11,
      "y": 1,
      "z": 3,
      "name": "Plant_Seaweed_Grass"
    },
    {
      "x": -11,
      "y": 2,
      "z": 3,
      "name": "Empty"
    },
    {
      "x": -11,
      "y": 3,
      "z": 3,
      "name": "Empty"
    },
    {
      "x": -11,
      "y": 8,
      "z": 3,
      "name": "Soil_Clay_Smooth_Red_Half",
      "rotation": 4
    },
    {
      "x": -11,
      "y": 9,
      "z": 3,
      "name": "Soil_Clay_Smooth_Red_Half",
      "rotation": 4
    },
    {
      "x": -10,
      "y": 0,
      "z": -3,
      "name": "Rock_Basalt"
    },
    {
      "x": -10,
      "y": 1,
      "z": -3,
      "name": "Plant_Seaweed_Grass_Short"
    },
    {
      "x": -10,
      "y": 2,
      "z": -3,
      "name": "Empty"
    },
    {
      "x": -10,
      "y": 3,
      "z": -3,
      "name": "Empty"
    },
    {
      "x": -10,
      "y": 8,
      "z": -3,
      "name": "Soil_Clay_Smooth_Red_Half",
      "rotation": 6
    },
    {
      "x": -10,
      "y": 9,
      "z": -3,
      "name": "Soil_Clay_Smooth_Red_Half",
      "rotation": 6
    },
    {
      "x": -10,
      "y": 0,
      "z": -2,
      "name": "Rock_Basalt_Cobble"
    },
    {
      "x": -10,
      "y": 1,
      "z": -2,
      "name": "Empty"
    },
    {
      "x": -10,
      "y": 2,
      "z": -2,
      "name": "Empty"
    },
    {
      "x": -10,
      "y": 3,
      "z": -2,
      "name": "Empty"
    },
    {
      "x": -10,
      "y": 7,
      "z": -2,
      "name": "Soil_Clay_Smooth_Red_Half",
      "rotation": 8
    },
    {
      "x": -10,
      "y": 8,
      "z": -2,
      "name": "Soil_Ash"
    },
    {
      "x": -10,
      "y": 0,
      "z": -1,
      "name": "Rock_Basalt"
    },
    {
      "x": -10,
      "y": 1,
      "z": -1,
      "name": "Empty"
    },
    {
      "x": -10,
      "y": 2,
      "z": -1,
      "name": "Empty"
    },
    {
      "x": -10,
      "y": 3,
      "z": -1,
      "name": "Empty"
    },
    {
      "x": -10,
      "y": 7,
      "z": -1,
      "name": "Soil_Clay_Smooth_Red"
    },
    {
      "x": -10,
      "y": 8,
      "z": -1,
      "name": "Soil_Ash"
    },
    {
      "x": -10,
      "y": 0,
      "z": 0,
      "name": "Rock_Basalt_Cobble"
    },
    {
      "x": -10,
      "y": 1,
      "z": 0,
      "name": "Empty"
    },
    {
      "x": -10,
      "y": 2,
      "z": 0,
      "name": "Empty"
    },
    {
      "x": -10,
      "y": 3,
      "z": 0,
      "name": "Empty"
    },
    {
      "x": -10,
      "y": 7,
      "z": 0,
      "name": "Soil_Clay_Smooth_Red"
    },
    {
      "x": -10,
      "y": 8,
      "z": 0,
      "name": "Soil_Ash"
    },
    {
      "x": -10,
      "y": 0,
      "z": 1,
      "name": "Rock_Basalt_Cobble"
    },
    {
      "x": -10,
      "y": 1,
      "z": 1,
      "name": "Plant_Seaweed_Grass_Stack"
    },
    {
      "x": -10,
      "y": 2,
      "z": 1,
      "name": "Empty"
    },
    {
      "x": -10,
      "y": 3,
      "z": 1,
      "name": "Empty"
    },
    {
      "x": -10,
      "y": 7,
      "z": 1,
      "name": "Soil_Clay_Smooth_Red"
    },
    {
      "x": -10,
      "y": 8,
      "z": 1,
      "name": "Soil_Ash"
    },
    {
      "x": -10,
      "y": 0,
      "z": 2,
      "name": "Rock_Basalt"
    },
    {
      "x": -10,
      "y": 1,
      "z": 2,
      "name": "Plant_Seaweed_Grass_Stack"
    },
    {
      "x": -10,
      "y": 2,
      "z": 2,
      "name": "Empty"
    },
    {
      "x": -10,
      "y": 3,
      "z": 2,
      "name": "Empty"
    },
    {
      "x": -10,
      "y": 7,
      "z": 2,
      "name": "Soil_Clay_Smooth_Red_Half",
      "rotation": 8
    },
    {
      "x": -10,
      "y": 8,
      "z": 2,
      "name": "Soil_Ash"
    },
    {
      "x": -10,
      "y": 0,
      "z": 3,
      "name": "Rock_Basalt"
    },
    {
      "x": -10,
      "y": 1,
      "z": 3,
      "name": "Empty"
    },
    {
      "x": -10,
      "y": 2,
      "z": 3,
      "name": "Empty"
    },
    {
      "x": -10,
      "y": 3,
      "z": 3,
      "name": "Empty"
    },
    {
      "x": -10,
      "y": 8,
      "z": 3,
      "name": "Soil_Clay_Smooth_Red_Half",
      "rotation": 4
    },
    {
      "x": -10,
      "y": 9,
      "z": 3,
      "name": "Soil_Clay_Smooth_Red_Half",
      "rotation": 4
    },
    {
      "x": -9,
      "y": 0,
      "z": -3,
      "name": "Rock_Basalt"
    },
    {
      "x": -9,
      "y": 1,
      "z": -3,
      "name": "Empty"
    },
    {
      "x": -9,
      "y": 2,
      "z": -3,
      "name": "Empty"
    },
    {
      "x": -9,
      "y": 3,
      "z": -3,
      "name": "Empty"
    },
    {
      "x": -9,
      "y": 7,
      "z": -3,
      "name": "Soil_Clay_Smooth_Red_Stairs",
      "rotation": 8
    },
    {
      "x": -9,
      "y": 8,
      "z": -3,
      "name": "Soil_Clay_Smooth_Red"
    },
    {
      "x": -9,
      "y": 9,
      "z": -3,
      "name": "Soil_Clay_Smooth_Red"
    },
    {
      "x": -9,
      "y": 0,
      "z": -2,
      "name": "Rock_Basalt"
    },
    {
      "x": -9,
      "y": 1,
      "z": -2,
      "name": "Empty"
    },
    {
      "x": -9,
      "y": 2,
      "z": -2,
      "name": "Empty"
    },
    {
      "x": -9,
      "y": 3,
      "z": -2,
      "name": "Empty"
    },
    {
      "x": -9,
      "y": 7,
      "z": -2,
      "name": "Soil_Clay_Smooth_Red"
    },
    {
      "x": -9,
      "y": 8,
      "z": -2,
      "name": "Soil_Ash"
    },
    {
      "x": -9,
      "y": 0,
      "z": -1,
      "name": "Rock_Basalt"
    },
    {
      "x": -9,
      "y": 1,
      "z": -1,
      "name": "Empty"
    },
    {
      "x": -9,
      "y": 2,
      "z": -1,
      "name": "Empty"
    },
    {
      "x": -9,
      "y": 3,
      "z": -1,
      "name": "Empty"
    },
    {
      "x": -9,
      "y": 7,
      "z": -1,
      "name": "Soil_Clay_Smooth_Red"
    },
    {
      "x": -9,
      "y": 8,
      "z": -1,
      "name": "Soil_Ash"
    },
    {
      "x": -9,
      "y": 0,
      "z": 0,
      "name": "Rock_Basalt"
    },
    {
      "x": -9,
      "y": 1,
      "z": 0,
      "name": "Empty"
    },
    {
      "x": -9,
      "y": 2,
      "z": 0,
      "name": "Empty"
    },
    {
      "x": -9,
      "y": 3,
      "z": 0,
      "name": "Empty"
    },
    {
      "x": -9,
      "y": 6,
      "z": 0,
      "name": "Soil_Clay_Smooth_Grey_Stairs",
      "rotation": 9
    },
    {
      "x": -9,
      "y": 7,
      "z": 0,
      "name": "Soil_Clay_Smooth_Red"
    },
    {
      "x": -9,
      "y": 8,
      "z": 0,
      "name": "Cloth_Block_Wool_Gray_Half"
    },
    {
      "x": -9,
      "y": 0,
      "z": 1,
      "name": "Rock_Basalt"
    },
    {
      "x": -9,
      "y": 1,
      "z": 1,
      "name": "Empty"
    },
    {
      "x": -9,
      "y": 2,
      "z": 1,
      "name": "Empty"
    },
    {
      "x": -9,
      "y": 3,
      "z": 1,
      "name": "Empty"
    },
    {
      "x": -9,
      "y": 7,
      "z": 1,
      "name": "Soil_Clay_Smooth_Red"
    },
    {
      "x": -9,
      "y": 8,
      "z": 1,
      "name": "Soil_Ash"
    },
    {
      "x": -9,
      "y": 0,
      "z": 2,
      "name": "Ore_Iron_Basalt_Cracked"
    },
    {
      "x": -9,
      "y": 1,
      "z": 2,
      "name": "Empty"
    },
    {
      "x": -9,
      "y": 2,
      "z": 2,
      "name": "Empty"
    },
    {
      "x": -9,
      "y": 3,
      "z": 2,
      "name": "Empty"
    },
    {
      "x": -9,
      "y": 7,
      "z": 2,
      "name": "Soil_Clay_Smooth_Red"
    },
    {
      "x": -9,
      "y": 8,
      "z": 2,
      "name": "Soil_Ash"
    },
    {
      "x": -9,
      "y": 0,
      "z": 3,
      "name": "Rock_Basalt_Cobble"
    },
    {
      "x": -9,
      "y": 1,
      "z": 3,
      "name": "Empty"
    },
    {
      "x": -9,
      "y": 2,
      "z": 3,
      "name": "Empty"
    },
    {
      "x": -9,
      "y": 3,
      "z": 3,
      "name": "Empty"
    },
    {
      "x": -9,
      "y": 7,
      "z": 3,
      "name": "Soil_Clay_Smooth_Red_Stairs",
      "rotation": 10
    },
    {
      "x": -9,
      "y": 8,
      "z": 3,
      "name": "Soil_Clay_Smooth_Red"
    },
    {
      "x": -9,
      "y": 9,
      "z": 3,
      "name": "Soil_Clay_Smooth_Red"
    },
    {
      "x": -8,
      "y": 0,
      "z": -3,
      "name": "Plant_Crop_Mushroom_Block_Green"
    },
    {
      "x": -8,
      "y": 1,
      "z": -3,
      "name": "Empty"
    },
    {
      "x": -8,
      "y": 2,
      "z": -3,
      "name": "Empty"
    },
    {
      "x": -8,
      "y": 3,
      "z": -3,
      "name": "Empty"
    },
    {
      "x": -8,
      "y": 8,
      "z": -3,
      "name": "Soil_Clay_Smooth_Red_Half",
      "rotation": 6
    },
    {
      "x": -8,
      "y": 9,
      "z": -3,
      "name": "Soil_Clay_Smooth_Red_Half",
      "rotation": 6
    },
    {
      "x": -8,
      "y": 0,
      "z": -2,
      "name": "Rock_Basalt"
    },
    {
      "x": -8,
      "y": 1,
      "z": -2,
      "name": "Empty"
    },
    {
      "x": -8,
      "y": 2,
      "z": -2,
      "name": "Empty"
    },
    {
      "x": -8,
      "y": 3,
      "z": -2,
      "name": "Empty"
    },
    {
      "x": -8,
      "y": 7,
      "z": -2,
      "name": "Soil_Clay_Smooth_Red_Half",
      "rotation": 8
    },
    {
      "x": -8,
      "y": 8,
      "z": -2,
      "name": "Soil_Ash"
    },
    {
      "x": -8,
      "y": 0,
      "z": -1,
      "name": "Rock_Basalt"
    },
    {
      "x": -8,
      "y": 1,
      "z": -1,
      "name": "Soil_Clay_Smooth_Grey_Stairs",
      "rotation": 50
    },
    {
      "x": -8,
      "y": 2,
      "z": -1,
      "name": "Soil_Clay_Smooth_Grey_Stairs",
      "rotation": 50
    },
    {
      "x": -8,
      "y": 3,
      "z": -1,
      "name": "Soil_Clay_Smooth_Grey_Stairs",
      "rotation": 24
    },
    {
      "x": -8,
      "y": 4,
      "z": -1,
      "name": "Soil_Clay_Smooth_Grey_Stairs",
      "rotation": 50
    },
    {
      "x": -8,
      "y": 5,
      "z": -1,
      "name": "Soil_Clay_Smooth_Grey_Stairs",
      "rotation": 50
    },
    {
      "x": -8,
      "y": 6,
      "z": -1,
      "name": "Soil_Clay_Smooth_Grey_Stairs",
      "rotation": 50
    },
    {
      "x": -8,
      "y": 7,
      "z": -1,
      "name": "Soil_Clay_Smooth_Red"
    },
    {
      "x": -8,
      "y": 8,
      "z": -1,
      "name": "Soil_Ash"
    },
    {
      "x": -8,
      "y": 0,
      "z": 0,
      "name": "Rock_Basalt"
    },
    {
      "x": -8,
      "y": 1,
      "z": 0,
      "name": "Soil_Clay_Grey"
    },
    {
      "x": -8,
      "y": 2,
      "z": 0,
      "name": "Soil_Clay_Grey"
    },
    {
      "x": -8,
      "y": 3,
      "z": 0,
      "name": "Soil_Clay_Grey"
    },
    {
      "x": -8,
      "y": 4,
      "z": 0,
      "name": "Soil_Clay_Grey"
    },
    {
      "x": -8,
      "y": 5,
      "z": 0,
      "name": "Soil_Clay_Grey"
    },
    {
      "x": -8,
      "y": 6,
      "z": 0,
      "name": "Soil_Clay_Grey"
    },
    {
      "x": -8,
      "y": 7,
      "z": 0,
      "name": "Soil_Clay_Smooth_Red"
    },
    {
      "x": -8,
      "y": 8,
      "z": 0,
      "name": "Cloth_Block_Wool_Gray_Stairs",
      "rotation": 3
    },
    {
      "x": -8,
      "y": 0,
      "z": 1,
      "name": "Rock_Basalt"
    },
    {
      "x": -8,
      "y": 1,
      "z": 1,
      "name": "Soil_Clay_Smooth_Grey_Stairs",
      "rotation": 51
    },
    {
      "x": -8,
      "y": 2,
      "z": 1,
      "name": "Soil_Clay_Smooth_Grey_Stairs",
      "rotation": 51
    },
    {
      "x": -8,
      "y": 3,
      "z": 1,
      "name": "Soil_Clay_Smooth_Grey_Stairs",
      "rotation": 25
    },
    {
      "x": -8,
      "y": 4,
      "z": 1,
      "name": "Soil_Clay_Smooth_Grey_Stairs",
      "rotation": 51
    },
    {
      "x": -8,
      "y": 5,
      "z": 1,
      "name": "Soil_Clay_Smooth_Grey_Stairs",
      "rotation": 51
    },
    {
      "x": -8,
      "y": 6,
      "z": 1,
      "name": "Soil_Clay_Smooth_Grey_Stairs",
      "rotation": 51
    },
    {
      "x": -8,
      "y": 7,
      "z": 1,
      "name": "Soil_Clay_Smooth_Red"
    },
    {
      "x": -8,
      "y": 8,
      "z": 1,
      "name": "Soil_Ash"
    },
    {
      "x": -8,
      "y": 0,
      "z": 2,
      "name": "Rock_Basalt_Cobble"
    },
    {
      "x": -8,
      "y": 1,
      "z": 2,
      "name": "Empty"
    },
    {
      "x": -8,
      "y": 2,
      "z": 2,
      "name": "Empty"
    },
    {
      "x": -8,
      "y": 3,
      "z": 2,
      "name": "Empty"
    },
    {
      "x": -8,
      "y": 7,
      "z": 2,
      "name": "Soil_Clay_Smooth_Red_Half",
      "rotation": 8
    },
    {
      "x": -8,
      "y": 8,
      "z": 2,
      "name": "Soil_Ash"
    },
    {
      "x": -8,
      "y": 0,
      "z": 3,
      "name": "Rock_Basalt"
    },
    {
      "x": -8,
      "y": 1,
      "z": 3,
      "name": "Empty"
    },
    {
      "x": -8,
      "y": 2,
      "z": 3,
      "name": "Empty"
    },
    {
      "x": -8,
      "y": 3,
      "z": 3,
      "name": "Empty"
    },
    {
      "x": -8,
      "y": 8,
      "z": 3,
      "name": "Soil_Clay_Smooth_Red_Half",
      "rotation": 4
    },
    {
      "x": -8,
      "y": 9,
      "z": 3,
      "name": "Soil_Clay_Smooth_Red_Half",
      "rotation": 4
    },
    {
      "x": -7,
      "y": 0,
      "z": -3,
      "name": "Rock_Basalt"
    },
    {
      "x": -7,
      "y": 1,
      "z": -3,
      "name": "Empty"
    },
    {
      "x": -7,
      "y": 2,
      "z": -3,
      "name": "Empty"
    },
    {
      "x": -7,
      "y": 3,
      "z": -3,
      "name": "Empty"
    },
    {
      "x": -7,
      "y": 7,
      "z": -3,
      "name": "Soil_Clay_Smooth_Red_Stairs",
      "rotation": 8
    },
    {
      "x": -7,
      "y": 8,
      "z": -3,
      "name": "Soil_Clay_Smooth_Red"
    },
    {
      "x": -7,
      "y": 9,
      "z": -3,
      "name": "Soil_Clay_Smooth_Red"
    },
    {
      "x": -7,
      "y": 0,
      "z": -2,
      "name": "Rock_Basalt"
    },
    {
      "x": -7,
      "y": 1,
      "z": -2,
      "name": "Empty"
    },
    {
      "x": -7,
      "y": 2,
      "z": -2,
      "name": "Empty"
    },
    {
      "x": -7,
      "y": 3,
      "z": -2,
      "name": "Empty"
    },
    {
      "x": -7,
      "y": 6,
      "z": -2,
      "name": "Soil_Clay_Smooth_Grey_Stairs",
      "rotation": 8
    },
    {
      "x": -7,
      "y": 7,
      "z": -2,
      "name": "Soil_Clay_Smooth_Red"
    },
    {
      "x": -7,
      "y": 8,
      "z": -2,
      "name": "Soil_Ash"
    },
    {
      "x": -7,
      "y": 0,
      "z": -1,
      "name": "Rock_Basalt"
    },
    {
      "x": -7,
      "y": 1,
      "z": -1,
      "name": "Soil_Clay_Grey"
    },
    {
      "x": -7,
      "y": 2,
      "z": -1,
      "name": "Soil_Clay_Grey"
    },
    {
      "x": -7,
      "y": 3,
      "z": -1,
      "name": "Soil_Clay_Grey"
    },
    {
      "x": -7,
      "y": 4,
      "z": -1,
      "name": "Soil_Clay_Grey"
    },
    {
      "x": -7,
      "y": 5,
      "z": -1,
      "name": "Soil_Clay_Grey"
    },
    {
      "x": -7,
      "y": 6,
      "z": -1,
      "name": "Soil_Clay_Grey"
    },
    {
      "x": -7,
      "y": 7,
      "z": -1,
      "name": "Soil_Clay_Smooth_Red"
    },
    {
      "x": -7,
      "y": 8,
      "z": -1,
      "name": "Soil_Ash"
    },
    {
      "x": -7,
      "y": 0,
      "z": 0,
      "name": "Rock_Basalt"
    },
    {
      "x": -7,
      "y": 1,
      "z": 0,
      "name": "Soil_Clay_Grey"
    },
    {
      "x": -7,
      "y": 2,
      "z": 0,
      "name": "Soil_Clay_Grey"
    },
    {
      "x": -7,
      "y": 3,
      "z": 0,
      "name": "Soil_Clay_Grey"
    },
    {
      "x": -7,
      "y": 4,
      "z": 0,
      "name": "Soil_Clay_Grey"
    },
    {
      "x": -7,
      "y": 5,
      "z": 0,
      "name": "Soil_Clay_Grey"
    },
    {
      "x": -7,
      "y": 6,
      "z": 0,
      "name": "Soil_Clay_Grey"
    },
    {
      "x": -7,
      "y": 7,
      "z": 0,
      "name": "Soil_Clay_Smooth_Red"
    },
    {
      "x": -7,
      "y": 8,
      "z": 0,
      "name": "Soil_Ash"
    },
    {
      "x": -7,
      "y": 0,
      "z": 1,
      "name": "Rock_Basalt"
    },
    {
      "x": -7,
      "y": 1,
      "z": 1,
      "name": "Soil_Clay_Grey"
    },
    {
      "x": -7,
      "y": 2,
      "z": 1,
      "name": "Soil_Clay_Grey"
    },
    {
      "x": -7,
      "y": 3,
      "z": 1,
      "name": "Soil_Clay_Grey"
    },
    {
      "x": -7,
      "y": 4,
      "z": 1,
      "name": "Soil_Clay_Grey"
    },
    {
      "x": -7,
      "y": 5,
      "z": 1,
      "name": "Soil_Clay_Grey"
    },
    {
      "x": -7,
      "y": 6,
      "z": 1,
      "name": "Soil_Clay_Grey"
    },
    {
      "x": -7,
      "y": 7,
      "z": 1,
      "name": "Soil_Clay_Smooth_Red"
    },
    {
      "x": -7,
      "y": 8,
      "z": 1,
      "name": "Soil_Ash"
    },
    {
      "x": -7,
      "y": 0,
      "z": 2,
      "name": "Rock_Basalt"
    },
    {
      "x": -7,
      "y": 1,
      "z": 2,
      "name": "Empty"
    },
    {
      "x": -7,
      "y": 2,
      "z": 2,
      "name": "Empty"
    },
    {
      "x": -7,
      "y": 3,
      "z": 2,
      "name": "Empty"
    },
    {
      "x": -7,
      "y": 6,
      "z": 2,
      "name": "Soil_Clay_Smooth_Grey_Stairs",
      "rotation": 10
    },
    {
      "x": -7,
      "y": 7,
      "z": 2,
      "name": "Soil_Clay_Smooth_Red"
    },
    {
      "x": -7,
      "y": 8,
      "z": 2,
      "name": "Soil_Ash"
    },
    {
      "x": -7,
      "y": 0,
      "z": 3,
      "name": "Plant_Crop_Mushroom_Block_Green"
    },
    {
      "x": -7,
      "y": 1,
      "z": 3,
      "name": "Empty"
    },
    {
      "x": -7,
      "y": 2,
      "z": 3,
      "name": "Empty"
    },
    {
      "x": -7,
      "y": 3,
      "z": 3,
      "name": "Empty"
    },
    {
      "x": -7,
      "y": 7,
      "z": 3,
      "name": "Soil_Clay_Smooth_Red_Stairs",
      "rotation": 10
    },
    {
      "x": -7,
      "y": 8,
      "z": 3,
      "name": "Soil_Clay_Smooth_Red"
    },
    {
      "x": -7,
      "y": 9,
      "z": 3,
      "name": "Soil_Clay_Smooth_Red"
    },
    {
      "x": -6,
      "y": 0,
      "z": -3,
      "name": "Rock_Basalt"
    },
    {
      "x": -6,
      "y": 1,
      "z": -3,
      "name": "Empty"
    },
    {
      "x": -6,
      "y": 2,
      "z": -3,
      "name": "Empty"
    },
    {
      "x": -6,
      "y": 3,
      "z": -3,
      "name": "Empty"
    },
    {
      "x": -6,
      "y": 8,
      "z": -3,
      "name": "Soil_Clay_Smooth_Red_Half",
      "rotation": 6
    },
    {
      "x": -6,
      "y": 9,
      "z": -3,
      "name": "Soil_Clay_Smooth_Red_Half",
      "rotation": 6
    },
    {
      "x": -6,
      "y": 0,
      "z": -2,
      "name": "Rock_Basalt"
    },
    {
      "x": -6,
      "y": 1,
      "z": -2,
      "name": "Empty"
    },
    {
      "x": -6,
      "y": 2,
      "z": -2,
      "name": "Empty"
    },
    {
      "x": -6,
      "y": 3,
      "z": -2,
      "name": "Empty"
    },
    {
      "x": -6,
      "y": 7,
      "z": -2,
      "name": "Soil_Clay_Smooth_Red_Half",
      "rotation": 8
    },
    {
      "x": -6,
      "y": 8,
      "z": -2,
      "name": "Soil_Ash"
    },
    {
      "x": -6,
      "y": 0,
      "z": -1,
      "name": "Rock_Basalt"
    },
    {
      "x": -6,
      "y": 1,
      "z": -1,
      "name": "Soil_Clay_Smooth_Grey_Stairs",
      "rotation": 49
    },
    {
      "x": -6,
      "y": 2,
      "z": -1,
      "name": "Soil_Clay_Smooth_Grey_Stairs",
      "rotation": 49
    },
    {
      "x": -6,
      "y": 3,
      "z": -1,
      "name": "Soil_Clay_Smooth_Grey_Stairs",
      "rotation": 27
    },
    {
      "x": -6,
      "y": 4,
      "z": -1,
      "name": "Soil_Clay_Smooth_Grey_Stairs",
      "rotation": 49
    },
    {
      "x": -6,
      "y": 5,
      "z": -1,
      "name": "Soil_Clay_Smooth_Grey_Stairs",
      "rotation": 49
    },
    {
      "x": -6,
      "y": 6,
      "z": -1,
      "name": "Soil_Clay_Smooth_Grey_Stairs",
      "rotation": 49
    },
    {
      "x": -6,
      "y": 7,
      "z": -1,
      "name": "Soil_Clay_Smooth_Red"
    },
    {
      "x": -6,
      "y": 8,
      "z": -1,
      "name": "Soil_Ash"
    },
    {
      "x": -6,
      "y": 0,
      "z": 0,
      "name": "Rock_Basalt"
    },
    {
      "x": -6,
      "y": 1,
      "z": 0,
      "name": "Soil_Clay_Grey"
    },
    {
      "x": -6,
      "y": 2,
      "z": 0,
      "name": "Soil_Clay_Grey"
    },
    {
      "x": -6,
      "y": 3,
      "z": 0,
      "name": "Soil_Clay_Grey"
    },
    {
      "x": -6,
      "y": 4,
      "z": 0,
      "name": "Soil_Clay_Grey"
    },
    {
      "x": -6,
      "y": 5,
      "z": 0,
      "name": "Soil_Clay_Grey"
    },
    {
      "x": -6,
      "y": 6,
      "z": 0,
      "name": "Soil_Clay_Grey"
    },
    {
      "x": -6,
      "y": 7,
      "z": 0,
      "name": "Soil_Clay_Smooth_Red"
    },
    {
      "x": -6,
      "y": 8,
      "z": 0,
      "name": "Cloth_Block_Wool_Gray_Stairs",
      "rotation": 1
    },
    {
      "x": -6,
      "y": 0,
      "z": 1,
      "name": "Rock_Basalt"
    },
    {
      "x": -6,
      "y": 1,
      "z": 1,
      "name": "Soil_Clay_Smooth_Grey_Stairs",
      "rotation": 26
    },
    {
      "x": -6,
      "y": 2,
      "z": 1,
      "name": "Soil_Clay_Smooth_Grey_Stairs",
      "rotation": 26
    },
    {
      "x": -6,
      "y": 3,
      "z": 1,
      "name": "Soil_Clay_Smooth_Grey_Stairs",
      "rotation": 26
    },
    {
      "x": -6,
      "y": 4,
      "z": 1,
      "name": "Soil_Clay_Smooth_Grey_Stairs",
      "rotation": 26
    },
    {
      "x": -6,
      "y": 5,
      "z": 1,
      "name": "Soil_Clay_Smooth_Grey_Stairs",
      "rotation": 26
    },
    {
      "x": -6,
      "y": 6,
      "z": 1,
      "name": "Soil_Clay_Smooth_Grey_Stairs",
      "rotation": 26
    },
    {
      "x": -6,
      "y": 7,
      "z": 1,
      "name": "Soil_Clay_Smooth_Red"
    },
    {
      "x": -6,
      "y": 8,
      "z": 1,
      "name": "Soil_Ash"
    },
    {
      "x": -6,
      "y": 0,
      "z": 2,
      "name": "Rock_Basalt"
    },
    {
      "x": -6,
      "y": 1,
      "z": 2,
      "name": "Empty"
    },
    {
      "x": -6,
      "y": 2,
      "z": 2,
      "name": "Empty"
    },
    {
      "x": -6,
      "y": 3,
      "z": 2,
      "name": "Empty"
    },
    {
      "x": -6,
      "y": 7,
      "z": 2,
      "name": "Soil_Clay_Smooth_Red_Half",
      "rotation": 8
    },
    {
      "x": -6,
      "y": 8,
      "z": 2,
      "name": "Soil_Ash"
    },
    {
      "x": -6,
      "y": 0,
      "z": 3,
      "name": "Rock_Basalt"
    },
    {
      "x": -6,
      "y": 1,
      "z": 3,
      "name": "Plant_Coral_Model_Grey"
    },
    {
      "x": -6,
      "y": 2,
      "z": 3,
      "name": "Empty"
    },
    {
      "x": -6,
      "y": 3,
      "z": 3,
      "name": "Empty"
    },
    {
      "x": -6,
      "y": 8,
      "z": 3,
      "name": "Soil_Clay_Smooth_Red_Half",
      "rotation": 4
    },
    {
      "x": -6,
      "y": 9,
      "z": 3,
      "name": "Soil_Clay_Smooth_Red_Half",
      "rotation": 4
    },
    {
      "x": -5,
      "y": 0,
      "z": -3,
      "name": "Rock_Basalt_Cobble"
    },
    {
      "x": -5,
      "y": 1,
      "z": -3,
      "name": "Empty"
    },
    {
      "x": -5,
      "y": 2,
      "z": -3,
      "name": "Empty"
    },
    {
      "x": -5,
      "y": 3,
      "z": -3,
      "name": "Empty"
    },
    {
      "x": -5,
      "y": 7,
      "z": -3,
      "name": "Soil_Clay_Smooth_Red_Stairs",
      "rotation": 8
    },
    {
      "x": -5,
      "y": 8,
      "z": -3,
      "name": "Soil_Clay_Smooth_Red"
    },
    {
      "x": -5,
      "y": 9,
      "z": -3,
      "name": "Soil_Clay_Smooth_Red"
    },
    {
      "x": -5,
      "y": 0,
      "z": -2,
      "name": "Rock_Basalt"
    },
    {
      "x": -5,
      "y": 1,
      "z": -2,
      "name": "Empty"
    },
    {
      "x": -5,
      "y": 2,
      "z": -2,
      "name": "Empty"
    },
    {
      "x": -5,
      "y": 3,
      "z": -2,
      "name": "Empty"
    },
    {
      "x": -5,
      "y": 7,
      "z": -2,
      "name": "Soil_Clay_Smooth_Red"
    },
    {
      "x": -5,
      "y": 8,
      "z": -2,
      "name": "Soil_Ash"
    },
    {
      "x": -5,
      "y": 0,
      "z": -1,
      "name": "Rock_Basalt"
    },
    {
      "x": -5,
      "y": 1,
      "z": -1,
      "name": "Empty"
    },
    {
      "x": -5,
      "y": 2,
      "z": -1,
      "name": "Empty"
    },
    {
      "x": -5,
      "y": 3,
      "z": -1,
      "name": "Empty"
    },
    {
      "x": -5,
      "y": 7,
      "z": -1,
      "name": "Soil_Clay_Smooth_Red"
    },
    {
      "x": -5,
      "y": 8,
      "z": -1,
      "name": "Soil_Ash"
    },
    {
      "x": -5,
      "y": 0,
      "z": 0,
      "name": "Rock_Basalt"
    },
    {
      "x": -5,
      "y": 1,
      "z": 0,
      "name": "Empty"
    },
    {
      "x": -5,
      "y": 2,
      "z": 0,
      "name": "Empty"
    },
    {
      "x": -5,
      "y": 3,
      "z": 0,
      "name": "Empty"
    },
    {
      "x": -5,
      "y": 6,
      "z": 0,
      "name": "Soil_Clay_Smooth_Grey_Stairs",
      "rotation": 11
    },
    {
      "x": -5,
      "y": 7,
      "z": 0,
      "name": "Soil_Clay_Smooth_Red"
    },
    {
      "x": -5,
      "y": 8,
      "z": 0,
      "name": "Cloth_Block_Wool_Gray_Half"
    },
    {
      "x": -5,
      "y": 0,
      "z": 1,
      "name": "Rock_Basalt"
    },
    {
      "x": -5,
      "y": 1,
      "z": 1,
      "name": "Empty"
    },
    {
      "x": -5,
      "y": 2,
      "z": 1,
      "name": "Empty"
    },
    {
      "x": -5,
      "y": 3,
      "z": 1,
      "name": "Empty"
    },
    {
      "x": -5,
      "y": 7,
      "z": 1,
      "name": "Soil_Clay_Smooth_Red"
    },
    {
      "x": -5,
      "y": 8,
      "z": 1,
      "name": "Soil_Ash"
    },
    {
      "x": -5,
      "y": 0,
      "z": 2,
      "name": "Rock_Basalt"
    },
    {
      "x": -5,
      "y": 1,
      "z": 2,
      "name": "Empty"
    },
    {
      "x": -5,
      "y": 2,
      "z": 2,
      "name": "Empty"
    },
    {
      "x": -5,
      "y": 3,
      "z": 2,
      "name": "Empty"
    },
    {
      "x": -5,
      "y": 7,
      "z": 2,
      "name": "Soil_Clay_Smooth_Red"
    },
    {
      "x": -5,
      "y": 8,
      "z": 2,
      "name": "Soil_Ash"
    },
    {
      "x": -5,
      "y": 0,
      "z": 3,
      "name": "Plant_Crop_Mushroom_Block_Green"
    },
    {
      "x": -5,
      "y": 1,
      "z": 3,
      "name": "Empty"
    },
    {
      "x": -5,
      "y": 2,
      "z": 3,
      "name": "Empty"
    },
    {
      "x": -5,
      "y": 3,
      "z": 3,
      "name": "Empty"
    },
    {
      "x": -5,
      "y": 7,
      "z": 3,
      "name": "Soil_Clay_Smooth_Red_Stairs",
      "rotation": 10
    },
    {
      "x": -5,
      "y": 8,
      "z": 3,
      "name": "Soil_Clay_Smooth_Red"
    },
    {
      "x": -5,
      "y": 9,
      "z": 3,
      "name": "Soil_Clay_Smooth_Red"
    },
    {
      "x": -4,
      "y": 0,
      "z": -3,
      "name": "Rock_Basalt"
    },
    {
      "x": -4,
      "y": 1,
      "z": -3,
      "name": "Empty"
    },
    {
      "x": -4,
      "y": 2,
      "z": -3,
      "name": "Empty"
    },
    {
      "x": -4,
      "y": 3,
      "z": -3,
      "name": "Empty"
    },
    {
      "x": -4,
      "y": 8,
      "z": -3,
      "name": "Soil_Clay_Smooth_Red_Half",
      "rotation": 6
    },
    {
      "x": -4,
      "y": 9,
      "z": -3,
      "name": "Soil_Clay_Smooth_Red_Half",
      "rotation": 6
    },
    {
      "x": -4,
      "y": 0,
      "z": -2,
      "name": "Rock_Basalt"
    },
    {
      "x": -4,
      "y": 1,
      "z": -2,
      "name": "Empty"
    },
    {
      "x": -4,
      "y": 2,
      "z": -2,
      "name": "Empty"
    },
    {
      "x": -4,
      "y": 3,
      "z": -2,
      "name": "Empty"
    },
    {
      "x": -4,
      "y": 7,
      "z": -2,
      "name": "Soil_Clay_Smooth_Red_Half",
      "rotation": 8
    },
    {
      "x": -4,
      "y": 8,
      "z": -2,
      "name": "Soil_Ash"
    },
    {
      "x": -4,
      "y": 0,
      "z": -1,
      "name": "Rock_Basalt"
    },
    {
      "x": -4,
      "y": 1,
      "z": -1,
      "name": "Empty"
    },
    {
      "x": -4,
      "y": 2,
      "z": -1,
      "name": "Empty"
    },
    {
      "x": -4,
      "y": 3,
      "z": -1,
      "name": "Empty"
    },
    {
      "x": -4,
      "y": 7,
      "z": -1,
      "name": "Soil_Clay_Smooth_Red"
    },
    {
      "x": -4,
      "y": 8,
      "z": -1,
      "name": "Soil_Ash"
    },
    {
      "x": -4,
      "y": 0,
      "z": 0,
      "name": "Rock_Basalt"
    },
    {
      "x": -4,
      "y": 1,
      "z": 0,
      "name": "Empty"
    },
    {
      "x": -4,
      "y": 2,
      "z": 0,
      "name": "Empty"
    },
    {
      "x": -4,
      "y": 3,
      "z": 0,
      "name": "Empty"
    },
    {
      "x": -4,
      "y": 7,
      "z": 0,
      "name": "Soil_Clay_Smooth_Red"
    },
    {
      "x": -4,
      "y": 8,
      "z": 0,
      "name": "Soil_Ash"
    },
    {
      "x": -4,
      "y": 0,
      "z": 1,
      "name": "Plant_Crop_Mushroom_Block_Green"
    },
    {
      "x": -4,
      "y": 1,
      "z": 1,
      "name": "Empty"
    },
    {
      "x": -4,
      "y": 2,
      "z": 1,
      "name": "Empty"
    },
    {
      "x": -4,
      "y": 3,
      "z": 1,
      "name": "Empty"
    },
    {
      "x": -4,
      "y": 7,
      "z": 1,
      "name": "Soil_Clay_Smooth_Red"
    },
    {
      "x": -4,
      "y": 8,
      "z": 1,
      "name": "Soil_Ash"
    },
    {
      "x": -4,
      "y": 0,
      "z": 2,
      "name": "Rock_Basalt_Cobble"
    },
    {
      "x": -4,
      "y": 1,
      "z": 2,
      "name": "Empty"
    },
    {
      "x": -4,
      "y": 2,
      "z": 2,
      "name": "Empty"
    },
    {
      "x": -4,
      "y": 3,
      "z": 2,
      "name": "Empty"
    },
    {
      "x": -4,
      "y": 7,
      "z": 2,
      "name": "Soil_Clay_Smooth_Red_Half",
      "rotation": 8
    },
    {
      "x": -4,
      "y": 8,
      "z": 2,
      "name": "Soil_Ash"
    },
    {
      "x": -4,
      "y": 0,
      "z": 3,
      "name": "Plant_Crop_Mushroom_Block_Green"
    },
    {
      "x": -4,
      "y": 1,
      "z": 3,
      "name": "Plant_Seaweed_Grass"
    },
    {
      "x": -4,
      "y": 2,
      "z": 3,
      "name": "Empty"
    },
    {
      "x": -4,
      "y": 3,
      "z": 3,
      "name": "Empty"
    },
    {
      "x": -4,
      "y": 8,
      "z": 3,
      "name": "Soil_Clay_Smooth_Red_Half",
      "rotation": 4
    },
    {
      "x": -4,
      "y": 9,
      "z": 3,
      "name": "Soil_Clay_Smooth_Red_Half",
      "rotation": 4
    },
    {
      "x": -3,
      "y": 0,
      "z": -3,
      "name": "Plant_Crop_Mushroom_Block_Green"
    },
    {
      "x": -3,
      "y": 1,
      "z": -3,
      "name": "Empty"
    },
    {
      "x": -3,
      "y": 2,
      "z": -3,
      "name": "Empty"
    },
    {
      "x": -3,
      "y": 3,
      "z": -3,
      "name": "Empty"
    },
    {
      "x": -3,
      "y": 8,
      "z": -3,
      "name": "Soil_Clay_Smooth_Red_Half",
      "rotation": 6
    },
    {
      "x": -3,
      "y": 9,
      "z": -3,
      "name": "Soil_Clay_Smooth_Red_Half",
      "rotation": 6
    },
    {
      "x": -3,
      "y": 0,
      "z": -2,
      "name": "Plant_Crop_Mushroom_Block_Green"
    },
    {
      "x": -3,
      "y": 1,
      "z": -2,
      "name": "Empty"
    },
    {
      "x": -3,
      "y": 2,
      "z": -2,
      "name": "Empty"
    },
    {
      "x": -3,
      "y": 3,
      "z": -2,
      "name": "Empty"
    },
    {
      "x": -3,
      "y": 7,
      "z": -2,
      "name": "Soil_Clay_Smooth_Red_Half",
      "rotation": 8
    },
    {
      "x": -3,
      "y": 8,
      "z": -2,
      "name": "Soil_Ash"
    },
    {
      "x": -3,
      "y": 0,
      "z": -1,
      "name": "Plant_Crop_Mushroom_Block_Green"
    },
    {
      "x": -3,
      "y": 1,
      "z": -1,
      "name": "Empty"
    },
    {
      "x": -3,
      "y": 2,
      "z": -1,
      "name": "Empty"
    },
    {
      "x": -3,
      "y": 3,
      "z": -1,
      "name": "Empty"
    },
    {
      "x": -3,
      "y": 7,
      "z": -1,
      "name": "Soil_Clay_Smooth_Red"
    },
    {
      "x": -3,
      "y": 8,
      "z": -1,
      "name": "Soil_Ash"
    },
    {
      "x": -3,
      "y": 0,
      "z": 0,
      "name": "Plant_Crop_Mushroom_Block_Green"
    },
    {
      "x": -3,
      "y": 1,
      "z": 0,
      "name": "Empty"
    },
    {
      "x": -3,
      "y": 2,
      "z": 0,
      "name": "Empty"
    },
    {
      "x": -3,
      "y": 3,
      "z": 0,
      "name": "Empty"
    },
    {
      "x": -3,
      "y": 7,
      "z": 0,
      "name": "Soil_Clay_Smooth_Red"
    },
    {
      "x": -3,
      "y": 8,
      "z": 0,
      "name": "Soil_Ash"
    },
    {
      "x": -3,
      "y": 0,
      "z": 1,
      "name": "Ore_Iron_Basalt_Cracked"
    },
    {
      "x": -3,
      "y": 1,
      "z": 1,
      "name": "Empty"
    },
    {
      "x": -3,
      "y": 2,
      "z": 1,
      "name": "Empty"
    },
    {
      "x": -3,
      "y": 3,
      "z": 1,
      "name": "Empty"
    },
    {
      "x": -3,
      "y": 7,
      "z": 1,
      "name": "Soil_Clay_Smooth_Red"
    },
    {
      "x": -3,
      "y": 8,
      "z": 1,
      "name": "Soil_Ash"
    },
    {
      "x": -3,
      "y": 0,
      "z": 2,
      "name": "Rock_Basalt_Cobble"
    },
    {
      "x": -3,
      "y": 1,
      "z": 2,
      "name": "Plant_Coral_Model_Lime"
    },
    {
      "x": -3,
      "y": 2,
      "z": 2,
      "name": "Empty"
    },
    {
      "x": -3,
      "y": 3,
      "z": 2,
      "name": "Empty"
    },
    {
      "x": -3,
      "y": 7,
      "z": 2,
      "name": "Soil_Clay_Smooth_Red_Half",
      "rotation": 8
    },
    {
      "x": -3,
      "y": 8,
      "z": 2,
      "name": "Soil_Ash"
    },
    {
      "x": -3,
      "y": 0,
      "z": 3,
      "name": "Rock_Basalt"
    },
    {
      "x": -3,
      "y": 1,
      "z": 3,
      "name": "Empty"
    },
    {
      "x": -3,
      "y": 2,
      "z": 3,
      "name": "Empty"
    },
    {
      "x": -3,
      "y": 3,
      "z": 3,
      "name": "Empty"
    },
    {
      "x": -3,
      "y": 8,
      "z": 3,
      "name": "Soil_Clay_Smooth_Red_Half",
      "rotation": 4
    },
    {
      "x": -3,
      "y": 9,
      "z": 3,
      "name": "Soil_Clay_Smooth_Red_Half",
      "rotation": 4
    },
    {
      "x": -2,
      "y": 0,
      "z": -3,
      "name": "Ore_Iron_Basalt_Cracked"
    },
    {
      "x": -2,
      "y": 1,
      "z": -3,
      "name": "Empty"
    },
    {
      "x": -2,
      "y": 2,
      "z": -3,
      "name": "Empty"
    },
    {
      "x": -2,
      "y": 3,
      "z": -3,
      "name": "Empty"
    },
    {
      "x": -2,
      "y": 7,
      "z": -3,
      "name": "Soil_Clay_Smooth_Red_Stairs",
      "rotation": 8
    },
    {
      "x": -2,
      "y": 8,
      "z": -3,
      "name": "Soil_Clay_Smooth_Red"
    },
    {
      "x": -2,
      "y": 9,
      "z": -3,
      "name": "Soil_Clay_Smooth_Red"
    },
    {
      "x": -2,
      "y": 0,
      "z": -2,
      "name": "Ore_Iron_Basalt_Cracked"
    },
    {
      "x": -2,
      "y": 1,
      "z": -2,
      "name": "Empty"
    },
    {
      "x": -2,
      "y": 2,
      "z": -2,
      "name": "Empty"
    },
    {
      "x": -2,
      "y": 3,
      "z": -2,
      "name": "Empty"
    },
    {
      "x": -2,
      "y": 7,
      "z": -2,
      "name": "Soil_Clay_Smooth_Red"
    },
    {
      "x": -2,
      "y": 8,
      "z": -2,
      "name": "Soil_Ash"
    },
    {
      "x": -2,
      "y": 0,
      "z": -1,
      "name": "Plant_Crop_Mushroom_Block_Green"
    },
    {
      "x": -2,
      "y": 1,
      "z": -1,
      "name": "Empty"
    },
    {
      "x": -2,
      "y": 2,
      "z": -1,
      "name": "Empty"
    },
    {
      "x": -2,
      "y": 3,
      "z": -1,
      "name": "Empty"
    },
    {
      "x": -2,
      "y": 7,
      "z": -1,
      "name": "Soil_Clay_Smooth_Red"
    },
    {
      "x": -2,
      "y": 8,
      "z": -1,
      "name": "Soil_Ash"
    },
    {
      "x": -2,
      "y": 0,
      "z": 0,
      "name": "Rock_Basalt"
    },
    {
      "x": -2,
      "y": 1,
      "z": 0,
      "name": "Empty"
    },
    {
      "x": -2,
      "y": 2,
      "z": 0,
      "name": "Empty"
    },
    {
      "x": -2,
      "y": 3,
      "z": 0,
      "name": "Empty"
    },
    {
      "x": -2,
      "y": 7,
      "z": 0,
      "name": "Soil_Clay_Smooth_Red"
    },
    {
      "x": -2,
      "y": 8,
      "z": 0,
      "name": "Cloth_Block_Wool_Gray_Half"
    },
    {
      "x": -2,
      "y": 0,
      "z": 1,
      "name": "Ore_Iron_Basalt_Cracked"
    },
    {
      "x": -2,
      "y": 1,
      "z": 1,
      "name": "Empty"
    },
    {
      "x": -2,
      "y": 2,
      "z": 1,
      "name": "Empty"
    },
    {
      "x": -2,
      "y": 3,
      "z": 1,
      "name": "Empty"
    },
    {
      "x": -2,
      "y": 7,
      "z": 1,
      "name": "Soil_Clay_Smooth_Red"
    },
    {
      "x": -2,
      "y": 8,
      "z": 1,
      "name": "Soil_Ash"
    },
    {
      "x": -2,
      "y": 0,
      "z": 2,
      "name": "Plant_Crop_Mushroom_Block_Green"
    },
    {
      "x": -2,
      "y": 1,
      "z": 2,
      "name": "Plant_Coral_Model_Lime"
    },
    {
      "x": -2,
      "y": 2,
      "z": 2,
      "name": "Empty"
    },
    {
      "x": -2,
      "y": 3,
      "z": 2,
      "name": "Empty"
    },
    {
      "x": -2,
      "y": 7,
      "z": 2,
      "name": "Soil_Clay_Smooth_Red"
    },
    {
      "x": -2,
      "y": 8,
      "z": 2,
      "name": "Soil_Ash"
    },
    {
      "x": -2,
      "y": 0,
      "z": 3,
      "name": "Ore_Iron_Basalt_Cracked"
    },
    {
      "x": -2,
      "y": 1,
      "z": 3,
      "name": "Empty"
    },
    {
      "x": -2,
      "y": 2,
      "z": 3,
      "name": "Empty"
    },
    {
      "x": -2,
      "y": 3,
      "z": 3,
      "name": "Empty"
    },
    {
      "x": -2,
      "y": 7,
      "z": 3,
      "name": "Soil_Clay_Smooth_Red_Stairs",
      "rotation": 10
    },
    {
      "x": -2,
      "y": 8,
      "z": 3,
      "name": "Soil_Clay_Smooth_Red"
    },
    {
      "x": -2,
      "y": 9,
      "z": 3,
      "name": "Soil_Clay_Smooth_Red"
    },
    {
      "x": -1,
      "y": 0,
      "z": -3,
      "name": "Ore_Iron_Basalt_Cracked"
    },
    {
      "x": -1,
      "y": 1,
      "z": -3,
      "name": "Empty"
    },
    {
      "x": -1,
      "y": 2,
      "z": -3,
      "name": "Empty"
    },
    {
      "x": -1,
      "y": 3,
      "z": -3,
      "name": "Empty"
    },
    {
      "x": -1,
      "y": 8,
      "z": -3,
      "name": "Soil_Clay_Smooth_Red_Half",
      "rotation": 6
    },
    {
      "x": -1,
      "y": 9,
      "z": -3,
      "name": "Soil_Clay_Smooth_Red_Half",
      "rotation": 6
    },
    {
      "x": -1,
      "y": 0,
      "z": -2,
      "name": "Plant_Crop_Mushroom_Block_Green"
    },
    {
      "x": -1,
      "y": 1,
      "z": -2,
      "name": "Empty"
    },
    {
      "x": -1,
      "y": 2,
      "z": -2,
      "name": "Empty"
    },
    {
      "x": -1,
      "y": 3,
      "z": -2,
      "name": "Empty"
    },
    {
      "x": -1,
      "y": 7,
      "z": -2,
      "name": "Soil_Clay_Smooth_Red_Half",
      "rotation": 8
    },
    {
      "x": -1,
      "y": 8,
      "z": -2,
      "name": "Soil_Ash"
    },
    {
      "x": -1,
      "y": 0,
      "z": -1,
      "name": "Plant_Crop_Mushroom_Block_Green"
    },
    {
      "x": -1,
      "y": 1,
      "z": -1,
      "name": "Plant_Seaweed_Grass_Stack"
    },
    {
      "x": -1,
      "y": 2,
      "z": -1,
      "name": "Empty"
    },
    {
      "x": -1,
      "y": 3,
      "z": -1,
      "name": "Empty"
    },
    {
      "x": -1,
      "y": 7,
      "z": -1,
      "name": "Soil_Clay_Smooth_Red"
    },
    {
      "x": -1,
      "y": 8,
      "z": -1,
      "name": "Soil_Ash"
    },
    {
      "x": -1,
      "y": 0,
      "z": 0,
      "name": "Ore_Iron_Basalt_Cracked"
    },
    {
      "x": -1,
      "y": 1,
      "z": 0,
      "name": "Empty"
    },
    {
      "x": -1,
      "y": 2,
      "z": 0,
      "name": "Empty"
    },
    {
      "x": -1,
      "y": 3,
      "z": 0,
      "name": "Empty"
    },
    {
      "x": -1,
      "y": 7,
      "z": 0,
      "name": "Soil_Clay_Smooth_Red"
    },
    {
      "x": -1,
      "y": 8,
      "z": 0,
      "name": "Cloth_Block_Wool_Gray_Stairs",
      "rotation": 3
    },
    {
      "x": -1,
      "y": 0,
      "z": 1,
      "name": "Rock_Basalt_Cobble"
    },
    {
      "x": -1,
      "y": 1,
      "z": 1,
      "name": "Empty"
    },
    {
      "x": -1,
      "y": 2,
      "z": 1,
      "name": "Empty"
    },
    {
      "x": -1,
      "y": 3,
      "z": 1,
      "name": "Empty"
    },
    {
      "x": -1,
      "y": 7,
      "z": 1,
      "name": "Soil_Clay_Smooth_Red"
    },
    {
      "x": -1,
      "y": 8,
      "z": 1,
      "name": "Soil_Ash"
    },
    {
      "x": -1,
      "y": 0,
      "z": 2,
      "name": "Rock_Basalt_Cobble"
    },
    {
      "x": -1,
      "y": 1,
      "z": 2,
      "name": "Plant_Seaweed_Grass_Stack"
    },
    {
      "x": -1,
      "y": 2,
      "z": 2,
      "name": "Empty"
    },
    {
      "x": -1,
      "y": 3,
      "z": 2,
      "name": "Empty"
    },
    {
      "x": -1,
      "y": 7,
      "z": 2,
      "name": "Soil_Clay_Smooth_Red_Half",
      "rotation": 8
    },
    {
      "x": -1,
      "y": 8,
      "z": 2,
      "name": "Soil_Ash"
    },
    {
      "x": -1,
      "y": 0,
      "z": 3,
      "name": "Ore_Iron_Basalt_Cracked"
    },
    {
      "x": -1,
      "y": 1,
      "z": 3,
      "name": "Empty"
    },
    {
      "x": -1,
      "y": 2,
      "z": 3,
      "name": "Empty"
    },
    {
      "x": -1,
      "y": 3,
      "z": 3,
      "name": "Empty"
    },
    {
      "x": -1,
      "y": 8,
      "z": 3,
      "name": "Soil_Clay_Smooth_Red_Half",
      "rotation": 4
    },
    {
      "x": -1,
      "y": 9,
      "z": 3,
      "name": "Soil_Clay_Smooth_Red_Half",
      "rotation": 4
    },
    {
      "x": 0,
      "y": 0,
      "z": -3,
      "name": "Rock_Basalt"
    },
    {
      "x": 0,
      "y": 1,
      "z": -3,
      "name": "Empty"
    },
    {
      "x": 0,
      "y": 2,
      "z": -3,
      "name": "Empty"
    },
    {
      "x": 0,
      "y": 3,
      "z": -3,
      "name": "Empty"
    },
    {
      "x": 0,
      "y": 7,
      "z": -3,
      "name": "Soil_Clay_Smooth_Red_Stairs",
      "rotation": 8
    },
    {
      "x": 0,
      "y": 8,
      "z": -3,
      "name": "Soil_Clay_Smooth_Red"
    },
    {
      "x": 0,
      "y": 9,
      "z": -3,
      "name": "Soil_Clay_Smooth_Red"
    },
    {
      "x": 0,
      "y": 0,
      "z": -2,
      "name": "Plant_Crop_Mushroom_Block_Green"
    },
    {
      "x": 0,
      "y": 1,
      "z": -2,
      "name": "Empty"
    },
    {
      "x": 0,
      "y": 2,
      "z": -2,
      "name": "Empty"
    },
    {
      "x": 0,
      "y": 3,
      "z": -2,
      "name": "Empty"
    },
    {
      "x": 0,
      "y": 7,
      "z": -2,
      "name": "Soil_Clay_Smooth_Red"
    },
    {
      "x": 0,
      "y": 8,
      "z": -2,
      "name": "Soil_Ash"
    },
    {
      "x": 0,
      "y": 0,
      "z": -1,
      "name": "Ore_Iron_Basalt_Cracked"
    },
    {
      "x": 0,
      "y": 1,
      "z": -1,
      "name": "Empty"
    },
    {
      "x": 0,
      "y": 2,
      "z": -1,
      "name": "Empty"
    },
    {
      "x": 0,
      "y": 3,
      "z": -1,
      "name": "Empty"
    },
    {
      "x": 0,
      "y": 7,
      "z": -1,
      "name": "Soil_Clay_Smooth_Red"
    },
    {
      "x": 0,
      "y": 8,
      "z": -1,
      "name": "Soil_Ash"
    },
    {
      "x": 0,
      "y": 0,
      "z": 0,
      "name": "Rock_Basalt"
    },
    {
      "x": 0,
      "y": 1,
      "z": 0,
      "name": "Empty"
    },
    {
      "x": 0,
      "y": 2,
      "z": 0,
      "name": "Empty"
    },
    {
      "x": 0,
      "y": 3,
      "z": 0,
      "name": "Empty"
    },
    {
      "x": 0,
      "y": 7,
      "z": 0,
      "name": "Soil_Clay_Smooth_Red"
    },
    {
      "x": 0,
      "y": 8,
      "z": 0,
      "name": "Soil_Ash"
    },
    {
      "x": 0,
      "y": 0,
      "z": 1,
      "name": "Rock_Basalt"
    },
    {
      "x": 0,
      "y": 1,
      "z": 1,
      "name": "Plant_Coral_Model_Lime"
    },
    {
      "x": 0,
      "y": 2,
      "z": 1,
      "name": "Empty"
    },
    {
      "x": 0,
      "y": 3,
      "z": 1,
      "name": "Empty"
    },
    {
      "x": 0,
      "y": 7,
      "z": 1,
      "name": "Soil_Clay_Smooth_Red"
    },
    {
      "x": 0,
      "y": 8,
      "z": 1,
      "name": "Soil_Ash"
    },
    {
      "x": 0,
      "y": 0,
      "z": 2,
      "name": "Rock_Basalt"
    },
    {
      "x": 0,
      "y": 1,
      "z": 2,
      "name": "Empty"
    },
    {
      "x": 0,
      "y": 2,
      "z": 2,
      "name": "Empty"
    },
    {
      "x": 0,
      "y": 3,
      "z": 2,
      "name": "Empty"
    },
    {
      "x": 0,
      "y": 7,
      "z": 2,
      "name": "Soil_Clay_Smooth_Red"
    },
    {
      "x": 0,
      "y": 8,
      "z": 2,
      "name": "Soil_Ash"
    },
    {
      "x": 0,
      "y": 0,
      "z": 3,
      "name": "Plant_Crop_Mushroom_Block_Green"
    },
    {
      "x": 0,
      "y": 1,
      "z": 3,
      "name": "Empty"
    },
    {
      "x": 0,
      "y": 2,
      "z": 3,
      "name": "Empty"
    },
    {
      "x": 0,
      "y": 3,
      "z": 3,
      "name": "Empty"
    },
    {
      "x": 0,
      "y": 7,
      "z": 3,
      "name": "Soil_Clay_Smooth_Red_Stairs",
      "rotation": 10
    },
    {
      "x": 0,
      "y": 8,
      "z": 3,
      "name": "Soil_Clay_Smooth_Red"
    },
    {
      "x": 0,
      "y": 9,
      "z": 3,
      "name": "Soil_Clay_Smooth_Red"
    },
    {
      "x": 1,
      "y": 0,
      "z": -3,
      "name": "Plant_Crop_Mushroom_Block_Green"
    },
    {
      "x": 1,
      "y": 1,
      "z": -3,
      "name": "Plant_Coral_Model_Green"
    },
    {
      "x": 1,
      "y": 2,
      "z": -3,
      "name": "Empty"
    },
    {
      "x": 1,
      "y": 3,
      "z": -3,
      "name": "Empty"
    },
    {
      "x": 1,
      "y": 8,
      "z": -3,
      "name": "Soil_Clay_Smooth_Red_Half",
      "rotation": 6
    },
    {
      "x": 1,
      "y": 9,
      "z": -3,
      "name": "Soil_Clay_Smooth_Red_Half",
      "rotation": 6
    },
    {
      "x": 1,
      "y": 0,
      "z": -2,
      "name": "Plant_Crop_Mushroom_Block_Green"
    },
    {
      "x": 1,
      "y": 1,
      "z": -2,
      "name": "Plant_Coral_Model_Green"
    },
    {
      "x": 1,
      "y": 2,
      "z": -2,
      "name": "Empty"
    },
    {
      "x": 1,
      "y": 3,
      "z": -2,
      "name": "Empty"
    },
    {
      "x": 1,
      "y": 7,
      "z": -2,
      "name": "Soil_Clay_Smooth_Red_Half",
      "rotation": 8
    },
    {
      "x": 1,
      "y": 8,
      "z": -2,
      "name": "Soil_Ash"
    },
    {
      "x": 1,
      "y": 0,
      "z": -1,
      "name": "Ore_Iron_Basalt_Cracked"
    },
    {
      "x": 1,
      "y": 1,
      "z": -1,
      "name": "Empty"
    },
    {
      "x": 1,
      "y": 2,
      "z": -1,
      "name": "Empty"
    },
    {
      "x": 1,
      "y": 3,
      "z": -1,
      "name": "Empty"
    },
    {
      "x": 1,
      "y": 7,
      "z": -1,
      "name": "Soil_Clay_Smooth_Red"
    },
    {
      "x": 1,
      "y": 8,
      "z": -1,
      "name": "Soil_Ash"
    },
    {
      "x": 1,
      "y": 0,
      "z": 0,
      "name": "Plant_Crop_Mushroom_Block_Green"
    },
    {
      "x": 1,
      "y": 1,
      "z": 0,
      "name": "Empty"
    },
    {
      "x": 1,
      "y": 2,
      "z": 0,
      "name": "Empty"
    },
    {
      "x": 1,
      "y": 3,
      "z": 0,
      "name": "Empty"
    },
    {
      "x": 1,
      "y": 7,
      "z": 0,
      "name": "Soil_Clay_Smooth_Red"
    },
    {
      "x": 1,
      "y": 8,
      "z": 0,
      "name": "Cloth_Block_Wool_Gray_Stairs",
      "rotation": 1
    },
    {
      "x": 1,
      "y": 0,
      "z": 1,
      "name": "Rock_Basalt_Cobble"
    },
    {
      "x": 1,
      "y": 1,
      "z": 1,
      "name": "Plant_Coral_Model_Grey"
    },
    {
      "x": 1,
      "y": 2,
      "z": 1,
      "name": "Empty"
    },
    {
      "x": 1,
      "y": 3,
      "z": 1,
      "name": "Empty"
    },
    {
      "x": 1,
      "y": 7,
      "z": 1,
      "name": "Soil_Clay_Smooth_Red"
    },
    {
      "x": 1,
      "y": 8,
      "z": 1,
      "name": "Soil_Ash"
    },
    {
      "x": 1,
      "y": 0,
      "z": 2,
      "name": "Rock_Basalt_Cobble"
    },
    {
      "x": 1,
      "y": 1,
      "z": 2,
      "name": "Empty"
    },
    {
      "x": 1,
      "y": 2,
      "z": 2,
      "name": "Empty"
    },
    {
      "x": 1,
      "y": 3,
      "z": 2,
      "name": "Empty"
    },
    {
      "x": 1,
      "y": 7,
      "z": 2,
      "name": "Soil_Clay_Smooth_Red_Half",
      "rotation": 8
    },
    {
      "x": 1,
      "y": 8,
      "z": 2,
      "name": "Soil_Ash"
    },
    {
      "x": 1,
      "y": 0,
      "z": 3,
      "name": "Rock_Basalt"
    },
    {
      "x": 1,
      "y": 1,
      "z": 3,
      "name": "Empty"
    },
    {
      "x": 1,
      "y": 2,
      "z": 3,
      "name": "Empty"
    },
    {
      "x": 1,
      "y": 3,
      "z": 3,
      "name": "Empty"
    },
    {
      "x": 1,
      "y": 8,
      "z": 3,
      "name": "Soil_Clay_Smooth_Red_Half",
      "rotation": 4
    },
    {
      "x": 1,
      "y": 9,
      "z": 3,
      "name": "Soil_Clay_Smooth_Red_Half",
      "rotation": 4
    },
    {
      "x": 2,
      "y": 0,
      "z": -3,
      "name": "Rock_Basalt"
    },
    {
      "x": 2,
      "y": 1,
      "z": -3,
      "name": "Empty"
    },
    {
      "x": 2,
      "y": 2,
      "z": -3,
      "name": "Empty"
    },
    {
      "x": 2,
      "y": 3,
      "z": -3,
      "name": "Empty"
    },
    {
      "x": 2,
      "y": 7,
      "z": -3,
      "name": "Soil_Clay_Smooth_Red_Stairs",
      "rotation": 8
    },
    {
      "x": 2,
      "y": 8,
      "z": -3,
      "name": "Soil_Clay_Smooth_Red"
    },
    {
      "x": 2,
      "y": 9,
      "z": -3,
      "name": "Soil_Clay_Smooth_Red"
    },
    {
      "x": 2,
      "y": 0,
      "z": -2,
      "name": "Rock_Basalt"
    },
    {
      "x": 2,
      "y": 1,
      "z": -2,
      "name": "Empty"
    },
    {
      "x": 2,
      "y": 2,
      "z": -2,
      "name": "Empty"
    },
    {
      "x": 2,
      "y": 3,
      "z": -2,
      "name": "Empty"
    },
    {
      "x": 2,
      "y": 7,
      "z": -2,
      "name": "Soil_Clay_Smooth_Red"
    },
    {
      "x": 2,
      "y": 8,
      "z": -2,
      "name": "Soil_Ash"
    },
    {
      "x": 2,
      "y": 0,
      "z": -1,
      "name": "Rock_Basalt_Cobble"
    },
    {
      "x": 2,
      "y": 1,
      "z": -1,
      "name": "Empty"
    },
    {
      "x": 2,
      "y": 2,
      "z": -1,
      "name": "Empty"
    },
    {
      "x": 2,
      "y": 3,
      "z": -1,
      "name": "Empty"
    },
    {
      "x": 2,
      "y": 7,
      "z": -1,
      "name": "Soil_Clay_Smooth_Red"
    },
    {
      "x": 2,
      "y": 8,
      "z": -1,
      "name": "Soil_Ash"
    },
    {
      "x": 2,
      "y": 0,
      "z": 0,
      "name": "Rock_Basalt_Cobble"
    },
    {
      "x": 2,
      "y": 1,
      "z": 0,
      "name": "Empty"
    },
    {
      "x": 2,
      "y": 2,
      "z": 0,
      "name": "Empty"
    },
    {
      "x": 2,
      "y": 3,
      "z": 0,
      "name": "Empty"
    },
    {
      "x": 2,
      "y": 7,
      "z": 0,
      "name": "Soil_Clay_Smooth_Red"
    },
    {
      "x": 2,
      "y": 8,
      "z": 0,
      "name": "Cloth_Block_Wool_Gray_Half"
    },
    {
      "x": 2,
      "y": 0,
      "z": 1,
      "name": "Ore_Iron_Basalt_Cracked"
    },
    {
      "x": 2,
      "y": 1,
      "z": 1,
      "name": "Empty"
    },
    {
      "x": 2,
      "y": 2,
      "z": 1,
      "name": "Empty"
    },
    {
      "x": 2,
      "y": 3,
      "z": 1,
      "name": "Empty"
    },
    {
      "x": 2,
      "y": 7,
      "z": 1,
      "name": "Soil_Clay_Smooth_Red"
    },
    {
      "x": 2,
      "y": 8,
      "z": 1,
      "name": "Soil_Ash"
    },
    {
      "x": 2,
      "y": 0,
      "z": 2,
      "name": "Plant_Crop_Mushroom_Block_Green"
    },
    {
      "x": 2,
      "y": 1,
      "z": 2,
      "name": "Plant_Coral_Model_Green"
    },
    {
      "x": 2,
      "y": 2,
      "z": 2,
      "name": "Empty"
    },
    {
      "x": 2,
      "y": 3,
      "z": 2,
      "name": "Empty"
    },
    {
      "x": 2,
      "y": 7,
      "z": 2,
      "name": "Soil_Clay_Smooth_Red"
    },
    {
      "x": 2,
      "y": 8,
      "z": 2,
      "name": "Soil_Ash"
    },
    {
      "x": 2,
      "y": 0,
      "z": 3,
      "name": "Rock_Basalt"
    },
    {
      "x": 2,
      "y": 1,
      "z": 3,
      "name": "Empty"
    },
    {
      "x": 2,
      "y": 2,
      "z": 3,
      "name": "Empty"
    },
    {
      "x": 2,
      "y": 3,
      "z": 3,
      "name": "Empty"
    },
    {
      "x": 2,
      "y": 7,
      "z": 3,
      "name": "Soil_Clay_Smooth_Red_Stairs",
      "rotation": 10
    },
    {
      "x": 2,
      "y": 8,
      "z": 3,
      "name": "Soil_Clay_Smooth_Red"
    },
    {
      "x": 2,
      "y": 9,
      "z": 3,
      "name": "Soil_Clay_Smooth_Red"
    },
    {
      "x": 3,
      "y": 0,
      "z": -3,
      "name": "Rock_Basalt"
    },
    {
      "x": 3,
      "y": 1,
      "z": -3,
      "name": "Empty"
    },
    {
      "x": 3,
      "y": 2,
      "z": -3,
      "name": "Empty"
    },
    {
      "x": 3,
      "y": 3,
      "z": -3,
      "name": "Empty"
    },
    {
      "x": 3,
      "y": 8,
      "z": -3,
      "name": "Soil_Clay_Smooth_Red_Half",
      "rotation": 6
    },
    {
      "x": 3,
      "y": 9,
      "z": -3,
      "name": "Soil_Clay_Smooth_Red_Half",
      "rotation": 6
    },
    {
      "x": 3,
      "y": 0,
      "z": -2,
      "name": "Ore_Iron_Basalt_Cracked"
    },
    {
      "x": 3,
      "y": 1,
      "z": -2,
      "name": "Empty"
    },
    {
      "x": 3,
      "y": 2,
      "z": -2,
      "name": "Empty"
    },
    {
      "x": 3,
      "y": 3,
      "z": -2,
      "name": "Empty"
    },
    {
      "x": 3,
      "y": 7,
      "z": -2,
      "name": "Soil_Clay_Smooth_Red_Half",
      "rotation": 8
    },
    {
      "x": 3,
      "y": 8,
      "z": -2,
      "name": "Soil_Ash"
    },
    {
      "x": 3,
      "y": 0,
      "z": -1,
      "name": "Rock_Basalt"
    },
    {
      "x": 3,
      "y": 1,
      "z": -1,
      "name": "Empty"
    },
    {
      "x": 3,
      "y": 2,
      "z": -1,
      "name": "Empty"
    },
    {
      "x": 3,
      "y": 3,
      "z": -1,
      "name": "Empty"
    },
    {
      "x": 3,
      "y": 7,
      "z": -1,
      "name": "Soil_Clay_Smooth_Red"
    },
    {
      "x": 3,
      "y": 8,
      "z": -1,
      "name": "Soil_Ash"
    },
    {
      "x": 3,
      "y": 0,
      "z": 0,
      "name": "Plant_Crop_Mushroom_Block_Green"
    },
    {
      "x": 3,
      "y": 1,
      "z": 0,
      "name": "Empty"
    },
    {
      "x": 3,
      "y": 2,
      "z": 0,
      "name": "Empty"
    },
    {
      "x": 3,
      "y": 3,
      "z": 0,
      "name": "Empty"
    },
    {
      "x": 3,
      "y": 7,
      "z": 0,
      "name": "Soil_Clay_Smooth_Red"
    },
    {
      "x": 3,
      "y": 8,
      "z": 0,
      "name": "Soil_Ash"
    },
    {
      "x": 3,
      "y": 0,
      "z": 1,
      "name": "Plant_Crop_Mushroom_Block_Green"
    },
    {
      "x": 3,
      "y": 1,
      "z": 1,
      "name": "Empty"
    },
    {
      "x": 3,
      "y": 2,
      "z": 1,
      "name": "Empty"
    },
    {
      "x": 3,
      "y": 3,
      "z": 1,
      "name": "Empty"
    },
    {
      "x": 3,
      "y": 7,
      "z": 1,
      "name": "Soil_Clay_Smooth_Red"
    },
    {
      "x": 3,
      "y": 8,
      "z": 1,
      "name": "Soil_Ash"
    },
    {
      "x": 3,
      "y": 0,
      "z": 2,
      "name": "Rock_Basalt"
    },
    {
      "x": 3,
      "y": 1,
      "z": 2,
      "name": "Empty"
    },
    {
      "x": 3,
      "y": 2,
      "z": 2,
      "name": "Empty"
    },
    {
      "x": 3,
      "y": 3,
      "z": 2,
      "name": "Empty"
    },
    {
      "x": 3,
      "y": 7,
      "z": 2,
      "name": "Soil_Clay_Smooth_Red_Half",
      "rotation": 8
    },
    {
      "x": 3,
      "y": 8,
      "z": 2,
      "name": "Soil_Ash"
    },
    {
      "x": 3,
      "y": 0,
      "z": 3,
      "name": "Rock_Basalt"
    },
    {
      "x": 3,
      "y": 1,
      "z": 3,
      "name": "Empty"
    },
    {
      "x": 3,
      "y": 2,
      "z": 3,
      "name": "Empty"
    },
    {
      "x": 3,
      "y": 3,
      "z": 3,
      "name": "Empty"
    },
    {
      "x": 3,
      "y": 8,
      "z": 3,
      "name": "Soil_Clay_Smooth_Red_Half",
      "rotation": 4
    },
    {
      "x": 3,
      "y": 9,
      "z": 3,
      "name": "Soil_Clay_Smooth_Red_Half",
      "rotation": 4
    },
    {
      "x": 4,
      "y": 0,
      "z": -3,
      "name": "Rock_Basalt"
    },
    {
      "x": 4,
      "y": 1,
      "z": -3,
      "name": "Empty"
    },
    {
      "x": 4,
      "y": 2,
      "z": -3,
      "name": "Empty"
    },
    {
      "x": 4,
      "y": 3,
      "z": -3,
      "name": "Empty"
    },
    {
      "x": 4,
      "y": 8,
      "z": -3,
      "name": "Soil_Clay_Smooth_Red_Half",
      "rotation": 6
    },
    {
      "x": 4,
      "y": 9,
      "z": -3,
      "name": "Soil_Clay_Smooth_Red_Half",
      "rotation": 6
    },
    {
      "x": 4,
      "y": 0,
      "z": -2,
      "name": "Ore_Iron_Basalt_Cracked"
    },
    {
      "x": 4,
      "y": 1,
      "z": -2,
      "name": "Empty"
    },
    {
      "x": 4,
      "y": 2,
      "z": -2,
      "name": "Empty"
    },
    {
      "x": 4,
      "y": 3,
      "z": -2,
      "name": "Empty"
    },
    {
      "x": 4,
      "y": 7,
      "z": -2,
      "name": "Soil_Clay_Smooth_Red_Half",
      "rotation": 8
    },
    {
      "x": 4,
      "y": 8,
      "z": -2,
      "name": "Soil_Ash"
    },
    {
      "x": 4,
      "y": 0,
      "z": -1,
      "name": "Rock_Basalt"
    },
    {
      "x": 4,
      "y": 1,
      "z": -1,
      "name": "Empty"
    },
    {
      "x": 4,
      "y": 2,
      "z": -1,
      "name": "Empty"
    },
    {
      "x": 4,
      "y": 3,
      "z": -1,
      "name": "Empty"
    },
    {
      "x": 4,
      "y": 7,
      "z": -1,
      "name": "Soil_Clay_Smooth_Red"
    },
    {
      "x": 4,
      "y": 8,
      "z": -1,
      "name": "Soil_Ash"
    },
    {
      "x": 4,
      "y": 0,
      "z": 0,
      "name": "Rock_Basalt"
    },
    {
      "x": 4,
      "y": 1,
      "z": 0,
      "name": "Empty"
    },
    {
      "x": 4,
      "y": 2,
      "z": 0,
      "name": "Empty"
    },
    {
      "x": 4,
      "y": 3,
      "z": 0,
      "name": "Empty"
    },
    {
      "x": 4,
      "y": 7,
      "z": 0,
      "name": "Soil_Clay_Smooth_Red"
    },
    {
      "x": 4,
      "y": 8,
      "z": 0,
      "name": "Soil_Ash"
    },
    {
      "x": 4,
      "y": 0,
      "z": 1,
      "name": "Rock_Basalt_Cobble"
    },
    {
      "x": 4,
      "y": 1,
      "z": 1,
      "name": "Plant_Seaweed_Grass_Short"
    },
    {
      "x": 4,
      "y": 2,
      "z": 1,
      "name": "Empty"
    },
    {
      "x": 4,
      "y": 3,
      "z": 1,
      "name": "Empty"
    },
    {
      "x": 4,
      "y": 7,
      "z": 1,
      "name": "Soil_Clay_Smooth_Red"
    },
    {
      "x": 4,
      "y": 8,
      "z": 1,
      "name": "Soil_Ash"
    },
    {
      "x": 4,
      "y": 0,
      "z": 2,
      "name": "Plant_Crop_Mushroom_Block_Green"
    },
    {
      "x": 4,
      "y": 1,
      "z": 2,
      "name": "Empty"
    },
    {
      "x": 4,
      "y": 2,
      "z": 2,
      "name": "Empty"
    },
    {
      "x": 4,
      "y": 3,
      "z": 2,
      "name": "Empty"
    },
    {
      "x": 4,
      "y": 7,
      "z": 2,
      "name": "Soil_Clay_Smooth_Red_Half",
      "rotation": 8
    },
    {
      "x": 4,
      "y": 8,
      "z": 2,
      "name": "Soil_Ash"
    },
    {
      "x": 4,
      "y": 0,
      "z": 3,
      "name": "Rock_Basalt"
    },
    {
      "x": 4,
      "y": 1,
      "z": 3,
      "name": "Empty"
    },
    {
      "x": 4,
      "y": 2,
      "z": 3,
      "name": "Empty"
    },
    {
      "x": 4,
      "y": 3,
      "z": 3,
      "name": "Empty"
    },
    {
      "x": 4,
      "y": 8,
      "z": 3,
      "name": "Soil_Clay_Smooth_Red_Half",
      "rotation": 4
    },
    {
      "x": 4,
      "y": 9,
      "z": 3,
      "name": "Soil_Clay_Smooth_Red_Half",
      "rotation": 4
    },
    {
      "x": 5,
      "y": 0,
      "z": -3,
      "name": "Rock_Basalt"
    },
    {
      "x": 5,
      "y": 1,
      "z": -3,
      "name": "Empty"
    },
    {
      "x": 5,
      "y": 2,
      "z": -3,
      "name": "Empty"
    },
    {
      "x": 5,
      "y": 3,
      "z": -3,
      "name": "Empty"
    },
    {
      "x": 5,
      "y": 7,
      "z": -3,
      "name": "Soil_Clay_Smooth_Red_Stairs",
      "rotation": 8
    },
    {
      "x": 5,
      "y": 8,
      "z": -3,
      "name": "Soil_Clay_Smooth_Red"
    },
    {
      "x": 5,
      "y": 9,
      "z": -3,
      "name": "Soil_Clay_Smooth_Red"
    },
    {
      "x": 5,
      "y": 0,
      "z": -2,
      "name": "Rock_Basalt"
    },
    {
      "x": 5,
      "y": 1,
      "z": -2,
      "name": "Empty"
    },
    {
      "x": 5,
      "y": 2,
      "z": -2,
      "name": "Empty"
    },
    {
      "x": 5,
      "y": 3,
      "z": -2,
      "name": "Empty"
    },
    {
      "x": 5,
      "y": 7,
      "z": -2,
      "name": "Soil_Clay_Smooth_Red"
    },
    {
      "x": 5,
      "y": 8,
      "z": -2,
      "name": "Soil_Ash"
    },
    {
      "x": 5,
      "y": 0,
      "z": -1,
      "name": "Plant_Crop_Mushroom_Block_Green"
    },
    {
      "x": 5,
      "y": 1,
      "z": -1,
      "name": "Empty"
    },
    {
      "x": 5,
      "y": 2,
      "z": -1,
      "name": "Empty"
    },
    {
      "x": 5,
      "y": 3,
      "z": -1,
      "name": "Empty"
    },
    {
      "x": 5,
      "y": 6,
      "z": -1,
      "name": "Soil_Clay_Smooth_Grey_Stairs",
      "rotation": 9
    },
    {
      "x": 5,
      "y": 7,
      "z": -1,
      "name": "Soil_Clay_Smooth_Red"
    },
    {
      "x": 5,
      "y": 8,
      "z": -1,
      "name": "Soil_Ash"
    },
    {
      "x": 5,
      "y": 0,
      "z": 0,
      "name": "Rock_Basalt"
    },
    {
      "x": 5,
      "y": 1,
      "z": 0,
      "name": "Empty"
    },
    {
      "x": 5,
      "y": 2,
      "z": 0,
      "name": "Empty"
    },
    {
      "x": 5,
      "y": 3,
      "z": 0,
      "name": "Empty"
    },
    {
      "x": 5,
      "y": 7,
      "z": 0,
      "name": "Soil_Clay_Smooth_Red"
    },
    {
      "x": 5,
      "y": 8,
      "z": 0,
      "name": "Cloth_Block_Wool_Gray_Half"
    },
    {
      "x": 5,
      "y": 0,
      "z": 1,
      "name": "Plant_Crop_Mushroom_Block_Green"
    },
    {
      "x": 5,
      "y": 1,
      "z": 1,
      "name": "Plant_Seaweed_Grass_Stack"
    },
    {
      "x": 5,
      "y": 2,
      "z": 1,
      "name": "Empty"
    },
    {
      "x": 5,
      "y": 3,
      "z": 1,
      "name": "Empty"
    },
    {
      "x": 5,
      "y": 7,
      "z": 1,
      "name": "Soil_Clay_Smooth_Red"
    },
    {
      "x": 5,
      "y": 8,
      "z": 1,
      "name": "Soil_Ash"
    },
    {
      "x": 5,
      "y": 0,
      "z": 2,
      "name": "Rock_Basalt_Cobble"
    },
    {
      "x": 5,
      "y": 1,
      "z": 2,
      "name": "Empty"
    },
    {
      "x": 5,
      "y": 2,
      "z": 2,
      "name": "Empty"
    },
    {
      "x": 5,
      "y": 3,
      "z": 2,
      "name": "Empty"
    },
    {
      "x": 5,
      "y": 7,
      "z": 2,
      "name": "Soil_Clay_Smooth_Red"
    },
    {
      "x": 5,
      "y": 8,
      "z": 2,
      "name": "Soil_Ash"
    },
    {
      "x": 5,
      "y": 0,
      "z": 3,
      "name": "Rock_Basalt"
    },
    {
      "x": 5,
      "y": 1,
      "z": 3,
      "name": "Plant_Coral_Model_Grey"
    },
    {
      "x": 5,
      "y": 2,
      "z": 3,
      "name": "Empty"
    },
    {
      "x": 5,
      "y": 3,
      "z": 3,
      "name": "Empty"
    },
    {
      "x": 5,
      "y": 7,
      "z": 3,
      "name": "Soil_Clay_Smooth_Red_Stairs",
      "rotation": 10
    },
    {
      "x": 5,
      "y": 8,
      "z": 3,
      "name": "Soil_Clay_Smooth_Red"
    },
    {
      "x": 5,
      "y": 9,
      "z": 3,
      "name": "Soil_Clay_Smooth_Red"
    },
    {
      "x": 6,
      "y": 0,
      "z": -3,
      "name": "Rock_Basalt"
    },
    {
      "x": 6,
      "y": 1,
      "z": -3,
      "name": "Empty"
    },
    {
      "x": 6,
      "y": 2,
      "z": -3,
      "name": "Empty"
    },
    {
      "x": 6,
      "y": 3,
      "z": -3,
      "name": "Empty"
    },
    {
      "x": 6,
      "y": 8,
      "z": -3,
      "name": "Soil_Clay_Smooth_Red_Half",
      "rotation": 6
    },
    {
      "x": 6,
      "y": 9,
      "z": -3,
      "name": "Soil_Clay_Smooth_Red_Half",
      "rotation": 6
    },
    {
      "x": 6,
      "y": 0,
      "z": -2,
      "name": "Rock_Basalt"
    },
    {
      "x": 6,
      "y": 1,
      "z": -2,
      "name": "Soil_Clay_Smooth_Grey_Stairs",
      "rotation": 50
    },
    {
      "x": 6,
      "y": 2,
      "z": -2,
      "name": "Soil_Clay_Smooth_Grey_Stairs",
      "rotation": 50
    },
    {
      "x": 6,
      "y": 3,
      "z": -2,
      "name": "Soil_Clay_Smooth_Grey_Stairs",
      "rotation": 24
    },
    {
      "x": 6,
      "y": 4,
      "z": -2,
      "name": "Soil_Clay_Smooth_Grey_Stairs",
      "rotation": 50
    },
    {
      "x": 6,
      "y": 5,
      "z": -2,
      "name": "Soil_Clay_Smooth_Grey_Stairs",
      "rotation": 50
    },
    {
      "x": 6,
      "y": 6,
      "z": -2,
      "name": "Soil_Clay_Smooth_Grey_Stairs",
      "rotation": 50
    },
    {
      "x": 6,
      "y": 7,
      "z": -2,
      "name": "Soil_Clay_Smooth_Red_Half",
      "rotation": 8
    },
    {
      "x": 6,
      "y": 8,
      "z": -2,
      "name": "Soil_Ash"
    },
    {
      "x": 6,
      "y": 0,
      "z": -1,
      "name": "Rock_Basalt"
    },
    {
      "x": 6,
      "y": 1,
      "z": -1,
      "name": "Soil_Clay_Grey"
    },
    {
      "x": 6,
      "y": 2,
      "z": -1,
      "name": "Soil_Clay_Grey"
    },
    {
      "x": 6,
      "y": 3,
      "z": -1,
      "name": "Soil_Clay_Grey"
    },
    {
      "x": 6,
      "y": 4,
      "z": -1,
      "name": "Soil_Clay_Grey"
    },
    {
      "x": 6,
      "y": 5,
      "z": -1,
      "name": "Soil_Clay_Grey"
    },
    {
      "x": 6,
      "y": 6,
      "z": -1,
      "name": "Soil_Clay_Grey"
    },
    {
      "x": 6,
      "y": 7,
      "z": -1,
      "name": "Soil_Clay_Smooth_Red"
    },
    {
      "x": 6,
      "y": 8,
      "z": -1,
      "name": "Soil_Ash"
    },
    {
      "x": 6,
      "y": 0,
      "z": 0,
      "name": "Rock_Basalt"
    },
    {
      "x": 6,
      "y": 1,
      "z": 0,
      "name": "Soil_Clay_Smooth_Grey_Stairs",
      "rotation": 51
    },
    {
      "x": 6,
      "y": 2,
      "z": 0,
      "name": "Soil_Clay_Smooth_Grey_Stairs",
      "rotation": 51
    },
    {
      "x": 6,
      "y": 3,
      "z": 0,
      "name": "Soil_Clay_Smooth_Grey_Stairs",
      "rotation": 25
    },
    {
      "x": 6,
      "y": 4,
      "z": 0,
      "name": "Soil_Clay_Smooth_Grey_Stairs",
      "rotation": 51
    },
    {
      "x": 6,
      "y": 5,
      "z": 0,
      "name": "Soil_Clay_Smooth_Grey_Stairs",
      "rotation": 51
    },
    {
      "x": 6,
      "y": 6,
      "z": 0,
      "name": "Soil_Clay_Smooth_Grey_Stairs",
      "rotation": 51
    },
    {
      "x": 6,
      "y": 7,
      "z": 0,
      "name": "Soil_Clay_Smooth_Red"
    },
    {
      "x": 6,
      "y": 8,
      "z": 0,
      "name": "Cloth_Block_Wool_Gray_Stairs",
      "rotation": 3
    },
    {
      "x": 6,
      "y": 0,
      "z": 1,
      "name": "Rock_Basalt_Cobble"
    },
    {
      "x": 6,
      "y": 1,
      "z": 1,
      "name": "Empty"
    },
    {
      "x": 6,
      "y": 2,
      "z": 1,
      "name": "Empty"
    },
    {
      "x": 6,
      "y": 3,
      "z": 1,
      "name": "Empty"
    },
    {
      "x": 6,
      "y": 7,
      "z": 1,
      "name": "Soil_Clay_Smooth_Red"
    },
    {
      "x": 6,
      "y": 8,
      "z": 1,
      "name": "Soil_Ash"
    },
    {
      "x": 6,
      "y": 0,
      "z": 2,
      "name": "Plant_Crop_Mushroom_Block_Green"
    },
    {
      "x": 6,
      "y": 1,
      "z": 2,
      "name": "Empty"
    },
    {
      "x": 6,
      "y": 2,
      "z": 2,
      "name": "Empty"
    },
    {
      "x": 6,
      "y": 3,
      "z": 2,
      "name": "Empty"
    },
    {
      "x": 6,
      "y": 7,
      "z": 2,
      "name": "Soil_Clay_Smooth_Red_Half",
      "rotation": 8
    },
    {
      "x": 6,
      "y": 8,
      "z": 2,
      "name": "Soil_Ash"
    },
    {
      "x": 6,
      "y": 0,
      "z": 3,
      "name": "Rock_Basalt"
    },
    {
      "x": 6,
      "y": 1,
      "z": 3,
      "name": "Empty"
    },
    {
      "x": 6,
      "y": 2,
      "z": 3,
      "name": "Empty"
    },
    {
      "x": 6,
      "y": 3,
      "z": 3,
      "name": "Empty"
    },
    {
      "x": 6,
      "y": 8,
      "z": 3,
      "name": "Soil_Clay_Smooth_Red_Half",
      "rotation": 4
    },
    {
      "x": 6,
      "y": 9,
      "z": 3,
      "name": "Soil_Clay_Smooth_Red_Half",
      "rotation": 4
    },
    {
      "x": 7,
      "y": 0,
      "z": -3,
      "name": "Rock_Basalt"
    },
    {
      "x": 7,
      "y": 1,
      "z": -3,
      "name": "Empty"
    },
    {
      "x": 7,
      "y": 2,
      "z": -3,
      "name": "Empty"
    },
    {
      "x": 7,
      "y": 3,
      "z": -3,
      "name": "Empty"
    },
    {
      "x": 7,
      "y": 6,
      "z": -3,
      "name": "Soil_Clay_Smooth_Grey_Stairs",
      "rotation": 8
    },
    {
      "x": 7,
      "y": 7,
      "z": -3,
      "name": "Soil_Clay_Smooth_Red_Stairs",
      "rotation": 8
    },
    {
      "x": 7,
      "y": 8,
      "z": -3,
      "name": "Soil_Clay_Smooth_Red"
    },
    {
      "x": 7,
      "y": 9,
      "z": -3,
      "name": "Soil_Clay_Smooth_Red"
    },
    {
      "x": 7,
      "y": 0,
      "z": -2,
      "name": "Rock_Basalt"
    },
    {
      "x": 7,
      "y": 1,
      "z": -2,
      "name": "Soil_Clay_Grey"
    },
    {
      "x": 7,
      "y": 2,
      "z": -2,
      "name": "Soil_Clay_Grey"
    },
    {
      "x": 7,
      "y": 3,
      "z": -2,
      "name": "Soil_Clay_Grey"
    },
    {
      "x": 7,
      "y": 4,
      "z": -2,
      "name": "Soil_Clay_Grey"
    },
    {
      "x": 7,
      "y": 5,
      "z": -2,
      "name": "Soil_Clay_Grey"
    },
    {
      "x": 7,
      "y": 6,
      "z": -2,
      "name": "Soil_Clay_Grey"
    },
    {
      "x": 7,
      "y": 7,
      "z": -2,
      "name": "Soil_Clay_Smooth_Red"
    },
    {
      "x": 7,
      "y": 8,
      "z": -2,
      "name": "Soil_Ash"
    },
    {
      "x": 7,
      "y": 0,
      "z": -1,
      "name": "Rock_Basalt"
    },
    {
      "x": 7,
      "y": 1,
      "z": -1,
      "name": "Soil_Clay_Grey"
    },
    {
      "x": 7,
      "y": 2,
      "z": -1,
      "name": "Soil_Clay_Grey"
    },
    {
      "x": 7,
      "y": 3,
      "z": -1,
      "name": "Soil_Clay_Grey"
    },
    {
      "x": 7,
      "y": 4,
      "z": -1,
      "name": "Soil_Clay_Grey"
    },
    {
      "x": 7,
      "y": 5,
      "z": -1,
      "name": "Soil_Clay_Grey"
    },
    {
      "x": 7,
      "y": 6,
      "z": -1,
      "name": "Soil_Clay_Grey"
    },
    {
      "x": 7,
      "y": 7,
      "z": -1,
      "name": "Soil_Clay_Smooth_Red"
    },
    {
      "x": 7,
      "y": 8,
      "z": -1,
      "name": "Soil_Ash"
    },
    {
      "x": 7,
      "y": 0,
      "z": 0,
      "name": "Rock_Basalt"
    },
    {
      "x": 7,
      "y": 1,
      "z": 0,
      "name": "Soil_Clay_Grey"
    },
    {
      "x": 7,
      "y": 2,
      "z": 0,
      "name": "Soil_Clay_Grey"
    },
    {
      "x": 7,
      "y": 3,
      "z": 0,
      "name": "Soil_Clay_Grey"
    },
    {
      "x": 7,
      "y": 4,
      "z": 0,
      "name": "Soil_Clay_Grey"
    },
    {
      "x": 7,
      "y": 5,
      "z": 0,
      "name": "Soil_Clay_Grey"
    },
    {
      "x": 7,
      "y": 6,
      "z": 0,
      "name": "Soil_Clay_Grey"
    },
    {
      "x": 7,
      "y": 7,
      "z": 0,
      "name": "Soil_Clay_Smooth_Red"
    },
    {
      "x": 7,
      "y": 8,
      "z": 0,
      "name": "Soil_Ash"
    },
    {
      "x": 7,
      "y": 0,
      "z": 1,
      "name": "Rock_Basalt"
    },
    {
      "x": 7,
      "y": 1,
      "z": 1,
      "name": "Empty"
    },
    {
      "x": 7,
      "y": 2,
      "z": 1,
      "name": "Empty"
    },
    {
      "x": 7,
      "y": 3,
      "z": 1,
      "name": "Empty"
    },
    {
      "x": 7,
      "y": 6,
      "z": 1,
      "name": "Soil_Clay_Smooth_Grey_Stairs",
      "rotation": 10
    },
    {
      "x": 7,
      "y": 7,
      "z": 1,
      "name": "Soil_Clay_Smooth_Red"
    },
    {
      "x": 7,
      "y": 8,
      "z": 1,
      "name": "Soil_Ash"
    },
    {
      "x": 7,
      "y": 0,
      "z": 2,
      "name": "Plant_Crop_Mushroom_Block_Green"
    },
    {
      "x": 7,
      "y": 1,
      "z": 2,
      "name": "Empty"
    },
    {
      "x": 7,
      "y": 2,
      "z": 2,
      "name": "Empty"
    },
    {
      "x": 7,
      "y": 3,
      "z": 2,
      "name": "Empty"
    },
    {
      "x": 7,
      "y": 7,
      "z": 2,
      "name": "Soil_Clay_Smooth_Red"
    },
    {
      "x": 7,
      "y": 8,
      "z": 2,
