{
  "version": 8,
  "blockIdVersion": 11,
  "anchorX": 0,
  "anchorY": 0,
  "anchorZ": 0,
  "blocks": [
    {
      "x": -6,
      "y": 0,
      "z": -6,
      "name": "Rock_Basalt"
    },
    {
      "x": -6,
      "y": 1,
      "z": -6,
      "name": "Rock_Basalt"
    },
    {
      "x": -6,
      "y": 2,
      "z": -6,
      "name": "Rock_Basalt"
    },
    {
      "x": -6,
      "y": 3,
      "z": -6,
      "name": "Rock_Basalt"
    },
    {
      "x": -6,
      "y": 4,
      "z": -6,
      "name": "Rock_Stone"
    },
    {
      "x": -6,
      "y": 5,
      "z": -6,
      "name": "Rock_Stone"
    },
    {
      "x": -6,
      "y": 6,
      "z": -6,
      "name": "Rock_Stone"
    },
    {
      "x": -6,
      "y": 7,
      "z": -6,
      "name": "Rock_Stone"
    },
    {
      "x": -6,
      "y": 8,
      "z": -6,
      "name": "Rock_Stone"
    },
    {
      "x": -6,
      "y": 0,
      "z": -5,
      "name": "Rock_Basalt"
    },
    {
      "x": -6,
      "y": 1,
      "z": -5,
      "name": "Rock_Basalt"
    },
    {
      "x": -6,
      "y": 2,
      "z": -5,
      "name": "Rock_Basalt"
    },
    {
      "x": -6,
      "y": 3,
      "z": -5,
      "name": "Rock_Basalt"
    },
    {
      "x": -6,
      "y": 4,
      "z": -5,
      "name": "Rock_Stone"
    },
    {
      "x": -6,
      "y": 5,
      "z": -5,
      "name": "Rock_Stone"
    },
    {
      "x": -6,
      "y": 6,
      "z": -5,
      "name": "Rock_Stone"
    },
    {
      "x": -6,
      "y": 7,
      "z": -5,
      "name": "Rock_Stone"
    },
    {
      "x": -6,
      "y": 8,
      "z": -5,
      "name": "Rock_Stone"
    },
    {
      "x": -6,
      "y": 0,
      "z": -4,
      "name": "Rock_Basalt"
    },
    {
      "x": -6,
      "y": 1,
      "z": -4,
      "name": "Rock_Basalt"
    },
    {
      "x": -6,
      "y": 2,
      "z": -4,
      "name": "Rock_Basalt"
    },
    {
      "x": -6,
      "y": 3,
      "z": -4,
      "name": "Rock_Basalt"
    },
    {
      "x": -6,
      "y": 4,
      "z": -4,
      "name": "Rock_Stone"
    },
    {
      "x": -6,
      "y": 5,
      "z": -4,
      "name": "Rock_Stone"
    },
    {
      "x": -6,
      "y": 6,
      "z": -4,
      "name": "Rock_Stone"
    },
    {
      "x": -6,
      "y": 7,
      "z": -4,
      "name": "Rock_Stone"
    },
    {
      "x": -6,
      "y": 8,
      "z": -4,
      "name": "Rock_Stone"
    },
    {
      "x": -6,
      "y": 0,
      "z": -3,
      "name": "Rock_Basalt"
    },
    {
      "x": -6,
      "y": 1,
      "z": -3,
      "name": "Rock_Basalt"
    },
    {
      "x": -6,
      "y": 2,
      "z": -3,
      "name": "Rock_Basalt"
    },
    {
      "x": -6,
      "y": 3,
      "z": -3,
      "name": "Rock_Basalt"
    },
    {
      "x": -6,
      "y": 4,
      "z": -3,
      "name": "Rock_Stone"
    },
    {
      "x": -6,
      "y": 5,
      "z": -3,
      "name": "Rock_Stone"
    },
    {
      "x": -6,
      "y": 6,
      "z": -3,
      "name": "Rock_Stone"
    },
    {
      "x": -6,
      "y": 7,
      "z": -3,
      "name": "Rock_Stone"
    },
    {
      "x": -6,
      "y": 8,
      "z": -3,
      "name": "Rock_Stone"
    },
    {
      "x": -6,
      "y": 0,
      "z": -2,
      "name": "Rock_Basalt"
    },
    {
      "x": -6,
      "y": 1,
      "z": -2,
      "name": "Rock_Basalt"
    },
    {
      "x": -6,
      "y": 2,
      "z": -2,
      "name": "Rock_Basalt"
    },
    {
      "x": -6,
      "y": 3,
      "z": -2,
      "name": "Rock_Basalt"
    },
    {
      "x": -6,
      "y": 4,
      "z": -2,
      "name": "Rock_Stone"
    },
    {
      "x": -6,
      "y": 5,
      "z": -2,
      "name": "Rock_Stone"
    },
    {
      "x": -6,
      "y": 6,
      "z": -2,
      "name": "Rock_Stone"
    },
    {
      "x": -6,
      "y": 7,
      "z": -2,
      "name": "Rock_Stone"
    },
    {
      "x": -6,
      "y": 8,
      "z": -2,
      "name": "Rock_Stone"
    },
    {
      "x": -6,
      "y": 0,
      "z": -1,
      "name": "Rock_Basalt"
    },
    {
      "x": -6,
      "y": 1,
      "z": -1,
      "name": "Rock_Basalt"
    },
    {
      "x": -6,
      "y": 2,
      "z": -1,
      "name": "Rock_Basalt"
    },
    {
      "x": -6,
      "y": 3,
      "z": -1,
      "name": "Rock_Basalt"
    },
    {
      "x": -6,
      "y": 4,
      "z": -1,
      "name": "Rock_Stone"
    },
    {
      "x": -6,
      "y": 5,
      "z": -1,
      "name": "Rock_Stone"
    },
    {
      "x": -6,
      "y": 6,
      "z": -1,
      "name": "Rock_Stone"
    },
    {
      "x": -6,
      "y": 7,
      "z": -1,
      "name": "Rock_Stone"
    },
    {
      "x": -6,
      "y": 8,
      "z": -1,
      "name": "Rock_Stone"
    },
    {
      "x": -6,
      "y": 0,
      "z": 0,
      "name": "Rock_Basalt"
    },
    {
      "x": -6,
      "y": 1,
      "z": 0,
      "name": "Rock_Basalt"
    },
    {
      "x": -6,
      "y": 2,
      "z": 0,
      "name": "Rock_Basalt"
    },
    {
      "x": -6,
      "y": 3,
      "z": 0,
      "name": "Rock_Basalt"
    },
    {
      "x": -6,
      "y": 4,
      "z": 0,
      "name": "Rock_Stone"
    },
    {
      "x": -6,
      "y": 5,
      "z": 0,
      "name": "Rock_Stone"
    },
    {
      "x": -6,
      "y": 6,
      "z": 0,
      "name": "Rock_Stone"
    },
    {
      "x": -6,
      "y": 7,
      "z": 0,
      "name": "Rock_Stone"
    },
    {
      "x": -6,
      "y": 8,
      "z": 0,
      "name": "Rock_Stone"
    },
    {
      "x": -6,
      "y": 0,
      "z": 1,
      "name": "Rock_Basalt"
    },
    {
      "x": -6,
      "y": 1,
      "z": 1,
      "name": "Rock_Basalt"
    },
    {
      "x": -6,
      "y": 2,
      "z": 1,
      "name": "Rock_Basalt"
    },
    {
      "x": -6,
      "y": 3,
      "z": 1,
      "name": "Rock_Basalt"
    },
    {
      "x": -6,
      "y": 4,
      "z": 1,
      "name": "Rock_Stone"
    },
    {
      "x": -6,
      "y": 5,
      "z": 1,
      "name": "Rock_Stone"
    },
    {
      "x": -6,
      "y": 6,
      "z": 1,
      "name": "Rock_Stone"
    },
    {
      "x": -6,
      "y": 7,
      "z": 1,
      "name": "Rock_Stone"
    },
    {
      "x": -6,
      "y": 8,
      "z": 1,
      "name": "Rock_Stone"
    },
    {
      "x": -6,
      "y": 0,
      "z": 2,
      "name": "Rock_Basalt"
    },
    {
      "x": -6,
      "y": 1,
      "z": 2,
      "name": "Rock_Basalt"
    },
    {
      "x": -6,
      "y": 2,
      "z": 2,
      "name": "Rock_Basalt"
    },
    {
      "x": -6,
      "y": 3,
      "z": 2,
      "name": "Rock_Basalt"
    },
    {
      "x": -6,
      "y": 4,
      "z": 2,
      "name": "Rock_Stone"
    },
    {
      "x": -6,
      "y": 5,
      "z": 2,
      "name": "Rock_Stone"
    },
    {
      "x": -6,
      "y": 6,
      "z": 2,
      "name": "Rock_Stone"
    },
    {
      "x": -6,
      "y": 7,
      "z": 2,
      "name": "Rock_Stone"
    },
    {
      "x": -6,
      "y": 8,
      "z": 2,
      "name": "Rock_Stone"
    },
    {
      "x": -6,
      "y": 0,
      "z": 3,
      "name": "Rock_Basalt"
    },
    {
      "x": -6,
      "y": 1,
      "z": 3,
      "name": "Rock_Basalt"
    },
    {
      "x": -6,
      "y": 2,
      "z": 3,
      "name": "Rock_Basalt"
    },
    {
      "x": -6,
      "y": 3,
      "z": 3,
      "name": "Rock_Basalt"
    },
    {
      "x": -6,
      "y": 4,
      "z": 3,
      "name": "Rock_Stone"
    },
    {
      "x": -6,
      "y": 5,
      "z": 3,
      "name": "Rock_Stone"
    },
    {
      "x": -6,
      "y": 6,
      "z": 3,
      "name": "Rock_Stone"
    },
    {
      "x": -6,
      "y": 7,
      "z": 3,
      "name": "Rock_Stone"
    },
    {
      "x": -6,
      "y": 8,
      "z": 3,
      "name": "Rock_Stone"
    },
    {
      "x": -6,
      "y": 0,
      "z": 4,
      "name": "Rock_Basalt"
    },
    {
      "x": -6,
      "y": 1,
      "z": 4,
      "name": "Rock_Basalt"
    },
    {
      "x": -6,
      "y": 2,
      "z": 4,
      "name": "Rock_Basalt"
    },
    {
      "x": -6,
      "y": 3,
      "z": 4,
      "name": "Rock_Basalt"
    },
    {
      "x": -6,
      "y": 4,
      "z": 4,
      "name": "Rock_Stone"
    },
    {
      "x": -6,
      "y": 5,
      "z": 4,
      "name": "Rock_Stone"
    },
    {
      "x": -6,
      "y": 6,
      "z": 4,
      "name": "Rock_Stone"
    },
    {
      "x": -6,
      "y": 7,
      "z": 4,
      "name": "Rock_Stone"
    },
    {
      "x": -6,
      "y": 8,
      "z": 4,
      "name": "Rock_Stone"
    },
    {
      "x": -6,
      "y": 0,
      "z": 5,
      "name": "Rock_Basalt"
    },
    {
      "x": -6,
      "y": 1,
      "z": 5,
      "name": "Rock_Basalt"
    },
    {
      "x": -6,
      "y": 2,
      "z": 5,
      "name": "Rock_Basalt"
    },
    {
      "x": -6,
      "y": 3,
      "z": 5,
      "name": "Rock_Basalt"
    },
    {
      "x": -6,
      "y": 4,
      "z": 5,
      "name": "Rock_Stone"
    },
    {
      "x": -6,
      "y": 5,
      "z": 5,
      "name": "Rock_Stone"
    },
    {
      "x": -6,
      "y": 6,
      "z": 5,
      "name": "Rock_Stone"
    },
    {
      "x": -6,
      "y": 7,
      "z": 5,
      "name": "Rock_Stone"
    },
    {
      "x": -6,
      "y": 8,
      "z": 5,
      "name": "Rock_Stone_Mossy"
    },
    {
      "x": -6,
      "y": 0,
      "z": 6,
      "name": "Rock_Basalt"
    },
    {
      "x": -6,
      "y": 1,
      "z": 6,
      "name": "Rock_Basalt"
    },
    {
      "x": -6,
      "y": 2,
      "z": 6,
      "name": "Rock_Basalt"
    },
    {
      "x": -6,
      "y": 3,
      "z": 6,
      "name": "Rock_Basalt"
    },
    {
      "x": -6,
      "y": 4,
      "z": 6,
      "name": "Rock_Stone"
    },
    {
      "x": -6,
      "y": 5,
      "z": 6,
      "name": "Rock_Stone"
    },
    {
      "x": -6,
      "y": 6,
      "z": 6,
      "name": "Rock_Stone"
    },
    {
      "x": -6,
      "y": 7,
      "z": 6,
      "name": "Rock_Stone"
    },
    {
      "x": -6,
      "y": 8,
      "z": 6,
      "name": "Rock_Stone"
    },
    {
      "x": -6,
      "y": 0,
      "z": 7,
      "name": "Rock_Basalt"
    },
    {
      "x": -6,
      "y": 1,
      "z": 7,
      "name": "Rock_Basalt"
    },
    {
      "x": -6,
      "y": 2,
      "z": 7,
      "name": "Rock_Basalt"
    },
    {
      "x": -6,
      "y": 3,
      "z": 7,
      "name": "Rock_Basalt"
    },
    {
      "x": -6,
      "y": 4,
      "z": 7,
      "name": "Rock_Stone"
    },
    {
      "x": -6,
      "y": 5,
      "z": 7,
      "name": "Rock_Stone"
    },
    {
      "x": -6,
      "y": 6,
      "z": 7,
      "name": "Rock_Stone"
    },
    {
      "x": -6,
      "y": 7,
      "z": 7,
      "name": "Rock_Stone"
    },
    {
      "x": -6,
      "y": 8,
      "z": 7,
      "name": "Rock_Stone"
    },
    {
      "x": -5,
      "y": 0,
      "z": -6,
      "name": "Rock_Basalt"
    },
    {
      "x": -5,
      "y": 1,
      "z": -6,
      "name": "Rock_Basalt"
    },
    {
      "x": -5,
      "y": 2,
      "z": -6,
      "name": "Rock_Basalt"
    },
    {
      "x": -5,
      "y": 3,
      "z": -6,
      "name": "Rock_Basalt"
    },
    {
      "x": -5,
      "y": 4,
      "z": -6,
      "name": "Rock_Stone"
    },
    {
      "x": -5,
      "y": 5,
      "z": -6,
      "name": "Rock_Stone"
    },
    {
      "x": -5,
      "y": 6,
      "z": -6,
      "name": "Rock_Stone"
    },
    {
      "x": -5,
      "y": 7,
      "z": -6,
      "name": "Rock_Stone"
    },
    {
      "x": -5,
      "y": 8,
      "z": -6,
      "name": "Rock_Stone"
    },
    {
      "x": -5,
      "y": 0,
      "z": -5,
      "name": "Rock_Basalt"
    },
    {
      "x": -5,
      "y": 1,
      "z": -5,
      "name": "Rock_Basalt"
    },
    {
      "x": -5,
      "y": 2,
      "z": -5,
      "name": "Rock_Basalt"
    },
    {
      "x": -5,
      "y": 3,
      "z": -5,
      "name": "Rock_Basalt"
    },
    {
      "x": -5,
      "y": 4,
      "z": -5,
      "name": "Rock_Stone"
    },
    {
      "x": -5,
      "y": 5,
      "z": -5,
      "name": "Rock_Stone"
    },
    {
      "x": -5,
      "y": 6,
      "z": -5,
      "name": "Rock_Stone"
    },
    {
      "x": -5,
      "y": 7,
      "z": -5,
      "name": "Rock_Stone"
    },
    {
      "x": -5,
      "y": 8,
      "z": -5,
      "name": "Rock_Stone"
    },
    {
      "x": -5,
      "y": 0,
      "z": -4,
      "name": "Rock_Basalt"
    },
    {
      "x": -5,
      "y": 1,
      "z": -4,
      "name": "Rock_Basalt"
    },
    {
      "x": -5,
      "y": 2,
      "z": -4,
      "name": "Rock_Basalt"
    },
    {
      "x": -5,
      "y": 3,
      "z": -4,
      "name": "Rock_Basalt"
    },
    {
      "x": -5,
      "y": 4,
      "z": -4,
      "name": "Rock_Stone"
    },
    {
      "x": -5,
      "y": 5,
      "z": -4,
      "name": "Rock_Stone"
    },
    {
      "x": -5,
      "y": 6,
      "z": -4,
      "name": "Rock_Stone"
    },
    {
      "x": -5,
      "y": 7,
      "z": -4,
      "name": "Rock_Stone"
    },
    {
      "x": -5,
      "y": 8,
      "z": -4,
      "name": "Rock_Stone_Mossy"
    },
    {
      "x": -5,
      "y": 0,
      "z": -3,
      "name": "Rock_Basalt"
    },
    {
      "x": -5,
      "y": 1,
      "z": -3,
      "name": "Rock_Basalt"
    },
    {
      "x": -5,
      "y": 2,
      "z": -3,
      "name": "Rock_Basalt"
    },
    {
      "x": -5,
      "y": 3,
      "z": -3,
      "name": "Rock_Basalt"
    },
    {
      "x": -5,
      "y": 4,
      "z": -3,
      "name": "Rock_Stone"
    },
    {
      "x": -5,
      "y": 5,
      "z": -3,
      "name": "Rock_Stone"
    },
    {
      "x": -5,
      "y": 6,
      "z": -3,
      "name": "Rock_Stone"
    },
    {
      "x": -5,
      "y": 7,
      "z": -3,
      "name": "Rock_Stone"
    },
    {
      "x": -5,
      "y": 8,
      "z": -3,
      "name": "Rock_Stone"
    },
    {
      "x": -5,
      "y": 0,
      "z": -2,
      "name": "Rock_Basalt"
    },
    {
      "x": -5,
      "y": 1,
      "z": -2,
      "name": "Rock_Basalt"
    },
    {
      "x": -5,
      "y": 2,
      "z": -2,
      "name": "Rock_Basalt"
    },
    {
      "x": -5,
      "y": 3,
      "z": -2,
      "name": "Rock_Basalt"
    },
    {
      "x": -5,
      "y": 4,
      "z": -2,
      "name": "Rock_Stone"
    },
    {
      "x": -5,
      "y": 5,
      "z": -2,
      "name": "Rock_Stone"
    },
    {
      "x": -5,
      "y": 6,
      "z": -2,
      "name": "Rock_Stone"
    },
    {
      "x": -5,
      "y": 7,
      "z": -2,
      "name": "Rock_Stone"
    },
    {
      "x": -5,
      "y": 8,
      "z": -2,
      "name": "Rock_Stone"
    },
    {
      "x": -5,
      "y": 0,
      "z": -1,
      "name": "Rock_Basalt"
    },
    {
      "x": -5,
      "y": 1,
      "z": -1,
      "name": "Rock_Basalt"
    },
    {
      "x": -5,
      "y": 2,
      "z": -1,
      "name": "Rock_Basalt"
    },
    {
      "x": -5,
      "y": 3,
      "z": -1,
      "name": "Rock_Basalt"
    },
    {
      "x": -5,
      "y": 4,
      "z": -1,
      "name": "Rock_Stone"
    },
    {
      "x": -5,
      "y": 5,
      "z": -1,
      "name": "Rock_Stone"
    },
    {
      "x": -5,
      "y": 6,
      "z": -1,
      "name": "Rock_Stone"
    },
    {
      "x": -5,
      "y": 7,
      "z": -1,
      "name": "Rock_Stone"
    },
    {
      "x": -5,
      "y": 8,
      "z": -1,
      "name": "Rock_Stone"
    },
    {
      "x": -5,
      "y": 0,
      "z": 0,
      "name": "Rock_Basalt"
    },
    {
      "x": -5,
      "y": 1,
      "z": 0,
      "name": "Rock_Basalt"
    },
    {
      "x": -5,
      "y": 2,
      "z": 0,
      "name": "Rock_Basalt"
    },
    {
      "x": -5,
      "y": 3,
      "z": 0,
      "name": "Rock_Basalt"
    },
    {
      "x": -5,
      "y": 4,
      "z": 0,
      "name": "Rock_Stone"
    },
    {
      "x": -5,
      "y": 5,
      "z": 0,
      "name": "Rock_Stone"
    },
    {
      "x": -5,
      "y": 6,
      "z": 0,
      "name": "Rock_Stone"
    },
    {
      "x": -5,
      "y": 7,
      "z": 0,
      "name": "Rock_Stone"
    },
    {
      "x": -5,
      "y": 8,
      "z": 0,
      "name": "Soil_Ash"
    },
    {
      "x": -5,
      "y": 0,
      "z": 1,
      "name": "Rock_Basalt"
    },
    {
      "x": -5,
      "y": 1,
      "z": 1,
      "name": "Rock_Basalt"
    },
    {
      "x": -5,
      "y": 2,
      "z": 1,
      "name": "Rock_Basalt"
    },
    {
      "x": -5,
      "y": 3,
      "z": 1,
      "name": "Rock_Basalt"
    },
    {
      "x": -5,
      "y": 4,
      "z": 1,
      "name": "Rock_Stone"
    },
    {
      "x": -5,
      "y": 5,
      "z": 1,
      "name": "Rock_Stone"
    },
    {
      "x": -5,
      "y": 6,
      "z": 1,
      "name": "Rock_Stone"
    },
    {
      "x": -5,
      "y": 7,
      "z": 1,
      "name": "Rock_Stone"
    },
    {
      "x": -5,
      "y": 8,
      "z": 1,
      "name": "Soil_Ash"
    },
    {
      "x": -5,
      "y": 0,
      "z": 2,
      "name": "Rock_Basalt"
    },
    {
      "x": -5,
      "y": 1,
      "z": 2,
      "name": "Rock_Basalt"
    },
    {
      "x": -5,
      "y": 2,
      "z": 2,
      "name": "Rock_Basalt"
    },
    {
      "x": -5,
      "y": 3,
      "z": 2,
      "name": "Rock_Basalt"
    },
    {
      "x": -5,
      "y": 4,
      "z": 2,
      "name": "Rock_Stone"
    },
    {
      "x": -5,
      "y": 5,
      "z": 2,
      "name": "Rock_Stone"
    },
    {
      "x": -5,
      "y": 6,
      "z": 2,
      "name": "Rock_Stone"
    },
    {
      "x": -5,
      "y": 7,
      "z": 2,
      "name": "Rock_Stone"
    },
    {
      "x": -5,
      "y": 8,
      "z": 2,
      "name": "Rock_Stone"
    },
    {
      "x": -5,
      "y": 0,
      "z": 3,
      "name": "Rock_Basalt"
    },
    {
      "x": -5,
      "y": 1,
      "z": 3,
      "name": "Rock_Basalt"
    },
    {
      "x": -5,
      "y": 2,
      "z": 3,
      "name": "Rock_Basalt"
    },
    {
      "x": -5,
      "y": 3,
      "z": 3,
      "name": "Rock_Basalt"
    },
    {
      "x": -5,
      "y": 4,
      "z": 3,
      "name": "Rock_Stone"
    },
    {
      "x": -5,
      "y": 5,
      "z": 3,
      "name": "Rock_Stone"
    },
    {
      "x": -5,
      "y": 6,
      "z": 3,
      "name": "Rock_Stone"
    },
    {
      "x": -5,
      "y": 7,
      "z": 3,
      "name": "Rock_Stone"
    },
    {
      "x": -5,
      "y": 8,
      "z": 3,
      "name": "Rock_Stone"
    },
    {
      "x": -5,
      "y": 0,
      "z": 4,
      "name": "Rock_Basalt"
    },
    {
      "x": -5,
      "y": 1,
      "z": 4,
      "name": "Rock_Basalt"
    },
    {
      "x": -5,
      "y": 2,
      "z": 4,
      "name": "Rock_Basalt"
    },
    {
      "x": -5,
      "y": 3,
      "z": 4,
      "name": "Rock_Basalt"
    },
    {
      "x": -5,
      "y": 4,
      "z": 4,
      "name": "Rock_Stone"
    },
    {
      "x": -5,
      "y": 5,
      "z": 4,
      "name": "Rock_Stone"
    },
    {
      "x": -5,
      "y": 6,
      "z": 4,
      "name": "Rock_Stone"
    },
    {
      "x": -5,
      "y": 7,
      "z": 4,
      "name": "Rock_Stone"
    },
    {
      "x": -5,
      "y": 8,
      "z": 4,
      "name": "Rock_Stone"
    },
    {
      "x": -5,
      "y": 0,
      "z": 5,
      "name": "Rock_Basalt"
    },
    {
      "x": -5,
      "y": 1,
      "z": 5,
      "name": "Rock_Basalt"
    },
    {
      "x": -5,
      "y": 2,
      "z": 5,
      "name": "Rock_Basalt"
    },
    {
      "x": -5,
      "y": 3,
      "z": 5,
      "name": "Rock_Basalt"
    },
    {
      "x": -5,
      "y": 4,
      "z": 5,
      "name": "Rock_Stone"
    },
    {
      "x": -5,
      "y": 5,
      "z": 5,
      "name": "Rock_Stone"
    },
    {
      "x": -5,
      "y": 6,
      "z": 5,
      "name": "Rock_Stone"
    },
    {
      "x": -5,
      "y": 7,
      "z": 5,
      "name": "Rock_Stone"
    },
    {
      "x": -5,
      "y": 8,
      "z": 5,
      "name": "Rock_Stone"
    },
    {
      "x": -5,
      "y": 0,
      "z": 6,
      "name": "Rock_Basalt"
    },
    {
      "x": -5,
      "y": 1,
      "z": 6,
      "name": "Rock_Basalt"
    },
    {
      "x": -5,
      "y": 2,
      "z": 6,
      "name": "Rock_Basalt"
    },
    {
      "x": -5,
      "y": 3,
      "z": 6,
      "name": "Rock_Basalt"
    },
    {
      "x": -5,
      "y": 4,
      "z": 6,
      "name": "Rock_Stone"
    },
    {
      "x": -5,
      "y": 5,
      "z": 6,
      "name": "Rock_Stone"
    },
    {
      "x": -5,
      "y": 6,
      "z": 6,
      "name": "Rock_Stone"
    },
    {
      "x": -5,
      "y": 7,
      "z": 6,
      "name": "Rock_Stone"
    },
    {
      "x": -5,
      "y": 8,
      "z": 6,
      "name": "Rock_Stone"
    },
    {
      "x": -5,
      "y": 0,
      "z": 7,
      "name": "Rock_Basalt"
    },
    {
      "x": -5,
      "y": 1,
      "z": 7,
      "name": "Rock_Basalt"
    },
    {
      "x": -5,
      "y": 2,
      "z": 7,
      "name": "Rock_Basalt"
    },
    {
      "x": -5,
      "y": 3,
      "z": 7,
      "name": "Rock_Basalt"
    },
    {
      "x": -5,
      "y": 4,
      "z": 7,
      "name": "Rock_Stone"
    },
    {
      "x": -5,
      "y": 5,
      "z": 7,
      "name": "Rock_Stone"
    },
    {
      "x": -5,
      "y": 6,
      "z": 7,
      "name": "Rock_Stone"
    },
    {
      "x": -5,
      "y": 7,
      "z": 7,
      "name": "Rock_Stone"
    },
    {
      "x": -5,
      "y": 8,
      "z": 7,
      "name": "Rock_Stone"
    },
    {
      "x": -4,
      "y": 0,
      "z": -6,
      "name": "Rock_Basalt"
    },
    {
      "x": -4,
      "y": 1,
      "z": -6,
      "name": "Rock_Basalt"
    },
    {
      "x": -4,
      "y": 2,
      "z": -6,
      "name": "Rock_Basalt"
    },
    {
      "x": -4,
      "y": 3,
      "z": -6,
      "name": "Rock_Basalt"
    },
    {
      "x": -4,
      "y": 4,
      "z": -6,
      "name": "Rock_Stone"
    },
    {
      "x": -4,
      "y": 5,
      "z": -6,
      "name": "Rock_Stone"
    },
    {
      "x": -4,
      "y": 6,
      "z": -6,
      "name": "Rock_Stone"
    },
    {
      "x": -4,
      "y": 7,
      "z": -6,
      "name": "Rock_Stone"
    },
    {
      "x": -4,
      "y": 8,
      "z": -6,
      "name": "Rock_Stone"
    },
    {
      "x": -4,
      "y": 0,
      "z": -5,
      "name": "Rock_Basalt"
    },
    {
      "x": -4,
      "y": 1,
      "z": -5,
      "name": "Rock_Basalt"
    },
    {
      "x": -4,
      "y": 2,
      "z": -5,
      "name": "Rock_Basalt"
    },
    {
      "x": -4,
      "y": 3,
      "z": -5,
      "name": "Rock_Basalt"
    },
    {
      "x": -4,
      "y": 4,
      "z": -5,
      "name": "Rock_Stone"
    },
    {
      "x": -4,
      "y": 5,
      "z": -5,
      "name": "Rock_Stone"
    },
    {
      "x": -4,
      "y": 6,
      "z": -5,
      "name": "Rock_Stone"
    },
    {
      "x": -4,
      "y": 7,
      "z": -5,
      "name": "Rock_Stone"
    },
    {
      "x": -4,
      "y": 8,
      "z": -5,
      "name": "Rock_Stone"
    },
    {
      "x": -4,
      "y": 9,
      "z": -5,
      "name": "Soil_Clay_Red"
    },
    {
      "x": -4,
      "y": 10,
      "z": -5,
      "name": "Soil_Clay_Smooth_Red"
    },
    {
      "x": -4,
      "y": 11,
      "z": -5,
      "name": "Soil_Clay_Smooth_Red"
    },
    {
      "x": -4,
      "y": 12,
      "z": -5,
      "name": "Soil_Clay_Smooth_Red"
    },
    {
      "x": -4,
      "y": 0,
      "z": -4,
      "name": "Rock_Basalt"
    },
    {
      "x": -4,
      "y": 1,
      "z": -4,
      "name": "Rock_Basalt"
    },
    {
      "x": -4,
      "y": 2,
      "z": -4,
      "name": "Rock_Basalt"
    },
    {
      "x": -4,
      "y": 3,
      "z": -4,
      "name": "Rock_Basalt"
    },
    {
      "x": -4,
      "y": 4,
      "z": -4,
      "name": "Rock_Stone"
    },
    {
      "x": -4,
      "y": 5,
      "z": -4,
      "name": "Rock_Stone"
    },
    {
      "x": -4,
      "y": 6,
      "z": -4,
      "name": "Rock_Stone"
    },
    {
      "x": -4,
      "y": 7,
      "z": -4,
      "name": "Rock_Stone"
    },
    {
      "x": -4,
      "y": 8,
      "z": -4,
      "name": "Rock_Stone_Mossy"
    },
    {
      "x": -4,
      "y": 9,
      "z": -4,
      "name": "Plant_Moss_Rug_Green",
      "support": 15
    },
    {
      "x": -4,
      "y": 12,
      "z": -4,
      "name": "Soil_Clay_Smooth_Red"
    },
    {
      "x": -4,
      "y": 13,
      "z": -4,
      "name": "Soil_Clay_Smooth_Red"
    },
    {
      "x": -4,
      "y": 0,
      "z": -3,
      "name": "Rock_Basalt"
    },
    {
      "x": -4,
      "y": 1,
      "z": -3,
      "name": "Rock_Basalt"
    },
    {
      "x": -4,
      "y": 2,
      "z": -3,
      "name": "Rock_Basalt"
    },
    {
      "x": -4,
      "y": 3,
      "z": -3,
      "name": "Rock_Basalt"
    },
    {
      "x": -4,
      "y": 4,
      "z": -3,
      "name": "Rock_Stone"
    },
    {
      "x": -4,
      "y": 5,
      "z": -3,
      "name": "Rock_Stone"
    },
    {
      "x": -4,
      "y": 6,
      "z": -3,
      "name": "Rock_Stone"
    },
    {
      "x": -4,
      "y": 7,
      "z": -3,
      "name": "Rock_Stone"
    },
    {
      "x": -4,
      "y": 8,
      "z": -3,
      "name": "Rock_Stone_Mossy"
    },
    {
      "x": -4,
      "y": 13,
      "z": -3,
      "name": "Soil_Clay_Smooth_Red"
    },
    {
      "x": -4,
      "y": 14,
      "z": -3,
      "name": "Soil_Clay_Smooth_Red"
    },
    {
      "x": -4,
      "y": 0,
      "z": -2,
      "name": "Rock_Basalt"
    },
    {
      "x": -4,
      "y": 1,
      "z": -2,
      "name": "Rock_Basalt"
    },
    {
      "x": -4,
      "y": 2,
      "z": -2,
      "name": "Rock_Basalt"
    },
    {
      "x": -4,
      "y": 3,
      "z": -2,
      "name": "Rock_Basalt"
    },
    {
      "x": -4,
      "y": 4,
      "z": -2,
      "name": "Rock_Stone"
    },
    {
      "x": -4,
      "y": 5,
      "z": -2,
      "name": "Rock_Stone"
    },
    {
      "x": -4,
      "y": 6,
      "z": -2,
      "name": "Rock_Stone"
    },
    {
      "x": -4,
      "y": 7,
      "z": -2,
      "name": "Rock_Stone"
    },
    {
      "x": -4,
      "y": 8,
      "z": -2,
      "name": "Rock_Stone"
    },
    {
      "x": -4,
      "y": 14,
      "z": -2,
      "name": "Soil_Clay_Smooth_Red"
    },
    {
      "x": -4,
      "y": 0,
      "z": -1,
      "name": "Rock_Basalt"
    },
    {
      "x": -4,
      "y": 1,
      "z": -1,
      "name": "Rock_Basalt"
    },
    {
      "x": -4,
      "y": 2,
      "z": -1,
      "name": "Rock_Basalt"
    },
    {
      "x": -4,
      "y": 3,
      "z": -1,
      "name": "Rock_Basalt"
    },
    {
      "x": -4,
      "y": 4,
      "z": -1,
      "name": "Rock_Stone"
    },
    {
      "x": -4,
      "y": 5,
      "z": -1,
      "name": "Rock_Stone"
    },
    {
      "x": -4,
      "y": 6,
      "z": -1,
      "name": "Rock_Stone"
    },
    {
      "x": -4,
      "y": 7,
      "z": -1,
      "name": "Rock_Stone"
    },
    {
      "x": -4,
      "y": 8,
      "z": -1,
      "name": "Soil_Ash"
    },
    {
      "x": -4,
      "y": 14,
      "z": -1,
      "name": "Soil_Clay_White"
    },
    {
      "x": -4,
      "y": 0,
      "z": 0,
      "name": "Rock_Basalt"
    },
    {
      "x": -4,
      "y": 1,
      "z": 0,
      "name": "Rock_Basalt"
    },
    {
      "x": -4,
      "y": 2,
      "z": 0,
      "name": "Rock_Basalt"
    },
    {
      "x": -4,
      "y": 3,
      "z": 0,
      "name": "Rock_Basalt"
    },
    {
      "x": -4,
      "y": 4,
      "z": 0,
      "name": "Rock_Stone"
    },
    {
      "x": -4,
      "y": 5,
      "z": 0,
      "name": "Rock_Stone"
    },
    {
      "x": -4,
      "y": 6,
      "z": 0,
      "name": "Rock_Stone"
    },
    {
      "x": -4,
      "y": 7,
      "z": 0,
      "name": "Rock_Stone"
    },
    {
      "x": -4,
      "y": 8,
      "z": 0,
      "name": "Soil_Ash"
    },
    {
      "x": -4,
      "y": 14,
      "z": 0,
      "name": "Soil_Clay_White"
    },
    {
      "x": -4,
      "y": 0,
      "z": 1,
      "name": "Rock_Basalt"
    },
    {
      "x": -4,
      "y": 1,
      "z": 1,
      "name": "Rock_Basalt"
    },
    {
      "x": -4,
      "y": 2,
      "z": 1,
      "name": "Rock_Basalt"
    },
    {
      "x": -4,
      "y": 3,
      "z": 1,
      "name": "Rock_Basalt"
    },
    {
      "x": -4,
      "y": 4,
      "z": 1,
      "name": "Rock_Stone"
    },
    {
      "x": -4,
      "y": 5,
      "z": 1,
      "name": "Rock_Stone"
    },
    {
      "x": -4,
      "y": 6,
      "z": 1,
      "name": "Rock_Stone"
    },
    {
      "x": -4,
      "y": 7,
      "z": 1,
      "name": "Rock_Stone"
    },
    {
      "x": -4,
      "y": 8,
      "z": 1,
      "name": "Rock_Stone"
    },
    {
      "x": -4,
      "y": 14,
      "z": 1,
      "name": "Soil_Clay_White"
    },
    {
      "x": -4,
      "y": 0,
      "z": 2,
      "name": "Rock_Basalt"
    },
    {
      "x": -4,
      "y": 1,
      "z": 2,
      "name": "Rock_Basalt"
    },
    {
      "x": -4,
      "y": 2,
      "z": 2,
      "name": "Rock_Basalt"
    },
    {
      "x": -4,
      "y": 3,
      "z": 2,
      "name": "Rock_Basalt"
    },
    {
      "x": -4,
      "y": 4,
      "z": 2,
      "name": "Rock_Stone"
    },
    {
      "x": -4,
      "y": 5,
      "z": 2,
      "name": "Rock_Stone"
    },
    {
      "x": -4,
      "y": 6,
      "z": 2,
      "name": "Rock_Stone"
    },
    {
      "x": -4,
      "y": 7,
      "z": 2,
      "name": "Rock_Stone"
    },
    {
      "x": -4,
      "y": 8,
      "z": 2,
      "name": "Soil_Ash"
    },
    {
      "x": -4,
      "y": 14,
      "z": 2,
      "name": "Soil_Clay_White"
    },
    {
      "x": -4,
      "y": 0,
      "z": 3,
      "name": "Rock_Basalt"
    },
    {
      "x": -4,
      "y": 1,
      "z": 3,
      "name": "Rock_Basalt"
    },
    {
      "x": -4,
      "y": 2,
      "z": 3,
      "name": "Rock_Basalt"
    },
    {
      "x": -4,
      "y": 3,
      "z": 3,
      "name": "Rock_Basalt"
    },
    {
      "x": -4,
      "y": 4,
      "z": 3,
      "name": "Rock_Stone"
    },
    {
      "x": -4,
      "y": 5,
      "z": 3,
      "name": "Rock_Stone"
    },
    {
      "x": -4,
      "y": 6,
      "z": 3,
      "name": "Rock_Stone"
    },
    {
      "x": -4,
      "y": 7,
      "z": 3,
      "name": "Rock_Stone"
    },
    {
      "x": -4,
      "y": 8,
      "z": 3,
      "name": "Rock_Stone"
    },
    {
      "x": -4,
      "y": 14,
      "z": 3,
      "name": "Soil_Clay_Smooth_Red"
    },
    {
      "x": -4,
      "y": 0,
      "z": 4,
      "name": "Rock_Basalt"
    },
    {
      "x": -4,
      "y": 1,
      "z": 4,
      "name": "Rock_Basalt"
    },
    {
      "x": -4,
      "y": 2,
      "z": 4,
      "name": "Rock_Basalt"
    },
    {
      "x": -4,
      "y": 3,
      "z": 4,
      "name": "Rock_Basalt"
    },
    {
      "x": -4,
      "y": 4,
      "z": 4,
      "name": "Rock_Stone"
    },
    {
      "x": -4,
      "y": 5,
      "z": 4,
      "name": "Rock_Stone"
    },
    {
      "x": -4,
      "y": 6,
      "z": 4,
      "name": "Rock_Stone"
    },
    {
      "x": -4,
      "y": 7,
      "z": 4,
      "name": "Rock_Stone"
    },
    {
      "x": -4,
      "y": 8,
      "z": 4,
      "name": "Rock_Stone"
    },
    {
      "x": -4,
      "y": 13,
      "z": 4,
      "name": "Soil_Clay_Smooth_Red"
    },
    {
      "x": -4,
      "y": 14,
      "z": 4,
      "name": "Soil_Clay_Smooth_Red"
    },
    {
      "x": -4,
      "y": 0,
      "z": 5,
      "name": "Rock_Basalt"
    },
    {
      "x": -4,
      "y": 1,
      "z": 5,
      "name": "Rock_Basalt"
    },
    {
      "x": -4,
      "y": 2,
      "z": 5,
      "name": "Rock_Basalt"
    },
    {
      "x": -4,
      "y": 3,
      "z": 5,
      "name": "Rock_Basalt"
    },
    {
      "x": -4,
      "y": 4,
      "z": 5,
      "name": "Rock_Stone"
    },
    {
      "x": -4,
      "y": 5,
      "z": 5,
      "name": "Rock_Stone"
    },
    {
      "x": -4,
      "y": 6,
      "z": 5,
      "name": "Rock_Stone"
    },
    {
      "x": -4,
      "y": 7,
      "z": 5,
      "name": "Rock_Stone"
    },
    {
      "x": -4,
      "y": 8,
      "z": 5,
      "name": "Rock_Stone"
    },
    {
      "x": -4,
      "y": 12,
      "z": 5,
      "name": "Soil_Clay_Smooth_Red"
    },
    {
      "x": -4,
      "y": 13,
      "z": 5,
      "name": "Soil_Clay_Smooth_Red"
    },
    {
      "x": -4,
      "y": 0,
      "z": 6,
      "name": "Rock_Basalt"
    },
    {
      "x": -4,
      "y": 1,
      "z": 6,
      "name": "Rock_Basalt"
    },
    {
      "x": -4,
      "y": 2,
      "z": 6,
      "name": "Rock_Basalt"
    },
    {
      "x": -4,
      "y": 3,
      "z": 6,
      "name": "Rock_Basalt"
    },
    {
      "x": -4,
      "y": 4,
      "z": 6,
      "name": "Rock_Stone"
    },
    {
      "x": -4,
      "y": 5,
      "z": 6,
      "name": "Rock_Stone"
    },
    {
      "x": -4,
      "y": 6,
      "z": 6,
      "name": "Rock_Stone"
    },
    {
      "x": -4,
      "y": 7,
      "z": 6,
      "name": "Rock_Stone"
    },
    {
      "x": -4,
      "y": 8,
      "z": 6,
      "name": "Rock_Stone"
    },
    {
      "x": -4,
      "y": 9,
      "z": 6,
      "name": "Soil_Clay_Red"
    },
    {
      "x": -4,
      "y": 10,
      "z": 6,
      "name": "Soil_Clay_Smooth_Red"
    },
    {
      "x": -4,
      "y": 11,
      "z": 6,
      "name": "Soil_Clay_Smooth_Red"
    },
    {
      "x": -4,
      "y": 12,
      "z": 6,
      "name": "Soil_Clay_Smooth_Red"
    },
    {
      "x": -4,
      "y": 0,
      "z": 7,
      "name": "Rock_Basalt"
    },
    {
      "x": -4,
      "y": 1,
      "z": 7,
      "name": "Rock_Basalt"
    },
    {
      "x": -4,
      "y": 2,
      "z": 7,
      "name": "Rock_Basalt"
    },
    {
      "x": -4,
      "y": 3,
      "z": 7,
      "name": "Rock_Basalt"
    },
    {
      "x": -4,
      "y": 4,
      "z": 7,
      "name": "Rock_Stone"
    },
    {
      "x": -4,
      "y": 5,
      "z": 7,
      "name": "Rock_Stone"
    },
    {
      "x": -4,
      "y": 6,
      "z": 7,
      "name": "Rock_Stone"
    },
    {
      "x": -4,
      "y": 7,
      "z": 7,
      "name": "Rock_Stone"
    },
    {
      "x": -4,
      "y": 8,
      "z": 7,
      "name": "Rock_Stone"
    },
    {
      "x": -4,
      "y": 9,
      "z": 7,
      "name": "Plant_Moss_Rug_Green",
      "support": 15
    },
    {
      "x": -3,
      "y": 0,
      "z": -6,
      "name": "Rock_Basalt"
    },
    {
      "x": -3,
      "y": 1,
      "z": -6,
      "name": "Rock_Basalt"
    },
    {
      "x": -3,
      "y": 2,
      "z": -6,
      "name": "Rock_Basalt"
    },
    {
      "x": -3,
      "y": 3,
      "z": -6,
      "name": "Rock_Basalt"
    },
    {
      "x": -3,
      "y": 4,
      "z": -6,
      "name": "Rock_Stone"
    },
    {
      "x": -3,
      "y": 5,
      "z": -6,
      "name": "Rock_Stone"
    },
    {
      "x": -3,
      "y": 6,
      "z": -6,
      "name": "Rock_Stone"
    },
    {
      "x": -3,
      "y": 7,
      "z": -6,
      "name": "Rock_Stone"
    },
    {
      "x": -3,
      "y": 8,
      "z": -6,
      "name": "Rock_Stone"
    },
    {
      "x": -3,
      "y": 0,
      "z": -5,
      "name": "Rock_Basalt"
    },
    {
      "x": -3,
      "y": 1,
      "z": -5,
      "name": "Rock_Basalt"
    },
    {
      "x": -3,
      "y": 2,
      "z": -5,
      "name": "Rock_Basalt"
    },
    {
      "x": -3,
      "y": 3,
      "z": -5,
      "name": "Rock_Basalt"
    },
    {
      "x": -3,
      "y": 4,
      "z": -5,
      "name": "Rock_Stone"
    },
    {
      "x": -3,
      "y": 5,
      "z": -5,
      "name": "Rock_Stone"
    },
    {
      "x": -3,
      "y": 6,
      "z": -5,
      "name": "Rock_Stone"
    },
    {
      "x": -3,
      "y": 7,
      "z": -5,
      "name": "Rock_Stone"
    },
    {
      "x": -3,
      "y": 8,
      "z": -5,
      "name": "Rock_Stone"
    },
    {
      "x": -3,
      "y": 9,
      "z": -5,
      "name": "Soil_Clay_Red"
    },
    {
      "x": -3,
      "y": 10,
      "z": -5,
      "name": "Soil_Clay_Smooth_Red"
    },
    {
      "x": -3,
      "y": 11,
      "z": -5,
      "name": "Soil_Clay_Smooth_Red"
    },
    {
      "x": -3,
      "y": 12,
      "z": -5,
      "name": "Soil_Clay_Smooth_Red"
    },
    {
      "x": -3,
      "y": 0,
      "z": -4,
      "name": "Rock_Basalt"
    },
    {
      "x": -3,
      "y": 1,
      "z": -4,
      "name": "Rock_Basalt"
    },
    {
      "x": -3,
      "y": 2,
      "z": -4,
      "name": "Rock_Basalt"
    },
    {
      "x": -3,
      "y": 3,
      "z": -4,
      "name": "Rock_Basalt"
    },
    {
      "x": -3,
      "y": 4,
      "z": -4,
      "name": "Rock_Stone"
    },
    {
      "x": -3,
      "y": 5,
      "z": -4,
      "name": "Rock_Stone"
    },
    {
      "x": -3,
      "y": 6,
      "z": -4,
      "name": "Rock_Stone"
    },
    {
      "x": -3,
      "y": 7,
      "z": -4,
      "name": "Rock_Stone"
    },
    {
      "x": -3,
      "y": 8,
      "z": -4,
      "name": "Rock_Stone"
    },
    {
      "x": -3,
      "y": 9,
      "z": -4,
      "name": "Soil_Clay_Smooth_Grey_Stairs",
      "rotation": 3
    },
    {
      "x": -3,
      "y": 10,
      "z": -4,
      "name": "Soil_Clay_Smooth_Grey_Half",
      "rotation": 7
    },
    {
      "x": -3,
      "y": 11,
      "z": -4,
      "name": "Soil_Clay_Smooth_Grey_Half",
      "rotation": 7
    },
    {
      "x": -3,
      "y": 12,
      "z": -4,
      "name": "Soil_Clay_Smooth_Red"
    },
    {
      "x": -3,
      "y": 13,
      "z": -4,
      "name": "Soil_Clay_Smooth_Red"
    },
    {
      "x": -3,
      "y": 0,
      "z": -3,
      "name": "Rock_Basalt"
    },
    {
      "x": -3,
      "y": 1,
      "z": -3,
      "name": "Rock_Basalt"
    },
    {
      "x": -3,
      "y": 2,
      "z": -3,
      "name": "Rock_Basalt"
    },
    {
      "x": -3,
      "y": 3,
      "z": -3,
      "name": "Rock_Basalt"
    },
    {
      "x": -3,
      "y": 4,
      "z": -3,
      "name": "Rock_Stone"
    },
    {
      "x": -3,
      "y": 5,
      "z": -3,
      "name": "Rock_Stone"
    },
    {
      "x": -3,
      "y": 6,
      "z": -3,
      "name": "Rock_Stone"
    },
    {
      "x": -3,
      "y": 7,
      "z": -3,
      "name": "Rock_Stone"
    },
    {
      "x": -3,
      "y": 8,
      "z": -3,
      "name": "Rock_Stone"
    },
    {
      "x": -3,
      "y": 9,
      "z": -3,
      "name": "Soil_Clay_Grey"
    },
    {
      "x": -3,
      "y": 10,
      "z": -3,
      "name": "Soil_Clay_Grey"
    },
    {
      "x": -3,
      "y": 11,
      "z": -3,
      "name": "Soil_Clay_Grey"
    },
    {
      "x": -3,
      "y": 12,
      "z": -3,
      "name": "Soil_Clay_Grey"
    },
    {
      "x": -3,
      "y": 13,
      "z": -3,
      "name": "Soil_Clay_Smooth_Red"
    },
    {
      "x": -3,
      "y": 14,
      "z": -3,
      "name": "Soil_Clay_Smooth_Red"
    },
    {
      "x": -3,
      "y": 0,
      "z": -2,
      "name": "Rock_Basalt"
    },
    {
      "x": -3,
      "y": 1,
      "z": -2,
      "name": "Rock_Basalt"
    },
    {
      "x": -3,
      "y": 2,
      "z": -2,
      "name": "Rock_Basalt"
    },
    {
      "x": -3,
      "y": 3,
      "z": -2,
      "name": "Rock_Basalt"
    },
    {
      "x": -3,
      "y": 4,
      "z": -2,
      "name": "Rock_Stone"
    },
    {
      "x": -3,
      "y": 5,
      "z": -2,
      "name": "Rock_Stone"
    },
    {
      "x": -3,
      "y": 6,
      "z": -2,
      "name": "Rock_Stone"
    },
    {
      "x": -3,
      "y": 7,
      "z": -2,
      "name": "Rock_Stone"
    },
    {
      "x": -3,
      "y": 8,
      "z": -2,
      "name": "Soil_Ash"
    },
    {
      "x": -3,
      "y": 9,
      "z": -2,
      "name": "Soil_Clay_Smooth_Grey_Stairs",
      "rotation": 3
    },
    {
      "x": -3,
      "y": 10,
      "z": -2,
      "name": "Soil_Clay_Smooth_Grey_Half",
      "rotation": 7
    },
    {
      "x": -3,
      "y": 11,
      "z": -2,
      "name": "Soil_Clay_Smooth_Grey_Half",
      "rotation": 7
    },
    {
      "x": -3,
      "y": 12,
      "z": -2,
      "name": "Soil_Clay_Smooth_Grey_Stairs",
      "rotation": 9
    },
    {
      "x": -3,
      "y": 13,
      "z": -2,
      "name": "Soil_Clay_Grey"
    },
    {
      "x": -3,
      "y": 14,
      "z": -2,
      "name": "Soil_Clay_Smooth_Red"
    },
    {
      "x": -3,
      "y": 0,
      "z": -1,
      "name": "Rock_Basalt"
    },
    {
      "x": -3,
      "y": 1,
      "z": -1,
      "name": "Rock_Basalt"
    },
    {
      "x": -3,
      "y": 2,
      "z": -1,
      "name": "Rock_Basalt"
    },
    {
      "x": -3,
      "y": 3,
      "z": -1,
      "name": "Rock_Basalt"
    },
    {
      "x": -3,
      "y": 4,
      "z": -1,
      "name": "Rock_Stone"
    },
    {
      "x": -3,
      "y": 5,
      "z": -1,
      "name": "Rock_Stone"
    },
    {
      "x": -3,
      "y": 6,
      "z": -1,
      "name": "Rock_Stone"
    },
    {
      "x": -3,
      "y": 7,
      "z": -1,
      "name": "Rock_Stone"
    },
    {
      "x": -3,
      "y": 8,
      "z": -1,
      "name": "Soil_Ash"
    },
    {
      "x": -3,
      "y": 12,
      "z": -1,
      "name": "Soil_Clay_Smooth_Grey_Stairs",
      "rotation": 9
    },
    {
      "x": -3,
      "y": 13,
      "z": -1,
      "name": "Soil_Clay_Grey"
    },
    {
      "x": -3,
      "y": 14,
      "z": -1,
      "name": "Soil_Clay_White"
    },
    {
      "x": -3,
      "y": 0,
      "z": 0,
      "name": "Rock_Basalt"
    },
    {
      "x": -3,
      "y": 1,
      "z": 0,
      "name": "Rock_Basalt"
    },
    {
      "x": -3,
      "y": 2,
      "z": 0,
      "name": "Rock_Basalt"
    },
    {
      "x": -3,
      "y": 3,
      "z": 0,
      "name": "Rock_Basalt"
    },
    {
      "x": -3,
      "y": 4,
      "z": 0,
      "name": "Rock_Stone"
    },
    {
      "x": -3,
      "y": 5,
      "z": 0,
      "name": "Rock_Stone"
    },
    {
      "x": -3,
      "y": 6,
      "z": 0,
      "name": "Rock_Stone"
    },
    {
      "x": -3,
      "y": 7,
      "z": 0,
      "name": "Rock_Stone"
    },
    {
      "x": -3,
      "y": 8,
      "z": 0,
      "name": "Soil_Ash"
    },
    {
      "x": -3,
      "y": 12,
      "z": 0,
      "name": "Soil_Clay_Smooth_Grey_Stairs",
      "rotation": 9
    },
    {
      "x": -3,
      "y": 13,
      "z": 0,
      "name": "Soil_Clay_Grey"
    },
    {
      "x": -3,
      "y": 14,
      "z": 0,
      "name": "Soil_Clay_White"
    },
    {
      "x": -3,
      "y": 0,
      "z": 1,
      "name": "Rock_Basalt"
    },
    {
      "x": -3,
      "y": 1,
      "z": 1,
      "name": "Rock_Basalt"
    },
    {
      "x": -3,
      "y": 2,
      "z": 1,
      "name": "Rock_Basalt"
    },
    {
      "x": -3,
      "y": 3,
      "z": 1,
      "name": "Rock_Basalt"
    },
    {
      "x": -3,
      "y": 4,
      "z": 1,
      "name": "Rock_Stone"
    },
    {
      "x": -3,
      "y": 5,
      "z": 1,
      "name": "Rock_Stone"
    },
    {
      "x": -3,
      "y": 6,
      "z": 1,
      "name": "Rock_Stone"
    },
    {
      "x": -3,
      "y": 7,
      "z": 1,
      "name": "Rock_Stone"
    },
    {
      "x": -3,
      "y": 8,
      "z": 1,
      "name": "Soil_Ash"
    },
    {
      "x": -3,
      "y": 12,
      "z": 1,
      "name": "Soil_Clay_Smooth_Grey_Stairs",
      "rotation": 9
    },
    {
      "x": -3,
      "y": 13,
      "z": 1,
      "name": "Soil_Clay_Grey"
    },
    {
      "x": -3,
      "y": 14,
      "z": 1,
      "name": "Soil_Clay_White"
    },
    {
      "x": -3,
      "y": 0,
      "z": 2,
      "name": "Rock_Basalt"
    },
    {
      "x": -3,
      "y": 1,
      "z": 2,
      "name": "Rock_Basalt"
    },
    {
      "x": -3,
      "y": 2,
      "z": 2,
      "name": "Rock_Basalt"
    },
    {
      "x": -3,
      "y": 3,
      "z": 2,
      "name": "Rock_Basalt"
    },
    {
      "x": -3,
      "y": 4,
      "z": 2,
      "name": "Rock_Stone"
    },
    {
      "x": -3,
      "y": 5,
      "z": 2,
      "name": "Rock_Stone"
    },
    {
      "x": -3,
      "y": 6,
      "z": 2,
      "name": "Rock_Stone"
    },
    {
      "x": -3,
      "y": 7,
      "z": 2,
      "name": "Rock_Stone"
    },
    {
      "x": -3,
      "y": 8,
      "z": 2,
      "name": "Soil_Ash"
    },
    {
      "x": -3,
      "y": 12,
      "z": 2,
      "name": "Soil_Clay_Smooth_Grey_Stairs",
      "rotation": 9
    },
    {
      "x": -3,
      "y": 13,
      "z": 2,
      "name": "Soil_Clay_Grey"
    },
    {
      "x": -3,
      "y": 14,
      "z": 2,
      "name": "Soil_Clay_White"
    },
    {
      "x": -3,
      "y": 0,
      "z": 3,
      "name": "Rock_Basalt"
    },
    {
      "x": -3,
      "y": 1,
      "z": 3,
      "name": "Rock_Basalt"
    },
    {
      "x": -3,
      "y": 2,
      "z": 3,
      "name": "Rock_Basalt"
    },
    {
      "x": -3,
      "y": 3,
      "z": 3,
      "name": "Rock_Basalt"
    },
    {
      "x": -3,
      "y": 4,
      "z": 3,
      "name": "Rock_Stone"
    },
    {
      "x": -3,
      "y": 5,
      "z": 3,
      "name": "Rock_Stone"
    },
    {
      "x": -3,
      "y": 6,
      "z": 3,
      "name": "Rock_Stone"
    },
    {
      "x": -3,
      "y": 7,
      "z": 3,
      "name": "Rock_Stone"
    },
    {
      "x": -3,
      "y": 8,
      "z": 3,
      "name": "Rock_Stone"
    },
    {
      "x": -3,
      "y": 9,
      "z": 3,
      "name": "Soil_Clay_Smooth_Grey_Stairs",
      "rotation": 3
    },
    {
      "x": -3,
      "y": 10,
      "z": 3,
      "name": "Soil_Clay_Smooth_Grey_Half",
      "rotation": 7
    },
    {
      "x": -3,
      "y": 11,
      "z": 3,
      "name": "Soil_Clay_Smooth_Grey_Half",
      "rotation": 7
    },
    {
      "x": -3,
      "y": 12,
      "z": 3,
      "name": "Soil_Clay_Smooth_Grey_Stairs",
      "rotation": 9
    },
    {
      "x": -3,
      "y": 13,
      "z": 3,
      "name": "Soil_Clay_Grey"
    },
    {
      "x": -3,
      "y": 14,
      "z": 3,
      "name": "Soil_Clay_Smooth_Red"
    },
    {
      "x": -3,
      "y": 0,
      "z": 4,
      "name": "Rock_Basalt"
    },
    {
      "x": -3,
      "y": 1,
      "z": 4,
      "name": "Rock_Basalt"
    },
    {
      "x": -3,
      "y": 2,
      "z": 4,
      "name": "Rock_Basalt"
    },
    {
      "x": -3,
      "y": 3,
      "z": 4,
      "name": "Rock_Basalt"
    },
    {
      "x": -3,
      "y": 4,
      "z": 4,
      "name": "Rock_Stone"
    },
    {
      "x": -3,
      "y": 5,
      "z": 4,
      "name": "Rock_Stone"
    },
    {
      "x": -3,
      "y": 6,
      "z": 4,
      "name": "Rock_Stone"
    },
    {
      "x": -3,
      "y": 7,
      "z": 4,
      "name": "Rock_Stone"
    },
    {
      "x": -3,
      "y": 8,
      "z": 4,
      "name": "Rock_Stone"
    },
    {
      "x": -3,
      "y": 9,
      "z": 4,
      "name": "Soil_Clay_Grey"
    },
    {
      "x": -3,
      "y": 10,
      "z": 4,
      "name": "Soil_Clay_Grey"
    },
    {
      "x": -3,
      "y": 11,
      "z": 4,
      "name": "Soil_Clay_Grey"
    },
    {
      "x": -3,
      "y": 12,
      "z": 4,
      "name": "Soil_Clay_Grey"
    },
    {
      "x": -3,
      "y": 13,
      "z": 4,
      "name": "Soil_Clay_Smooth_Red"
    },
    {
      "x": -3,
      "y": 14,
      "z": 4,
      "name": "Soil_Clay_Smooth_Red"
    },
    {
      "x": -3,
      "y": 0,
      "z": 5,
      "name": "Rock_Basalt"
    },
    {
      "x": -3,
      "y": 1,
      "z": 5,
      "name": "Rock_Basalt"
    },
    {
      "x": -3,
      "y": 2,
      "z": 5,
      "name": "Rock_Basalt"
    },
    {
      "x": -3,
      "y": 3,
      "z": 5,
      "name": "Rock_Basalt"
    },
    {
      "x": -3,
      "y": 4,
      "z": 5,
      "name": "Rock_Stone"
    },
    {
      "x": -3,
      "y": 5,
      "z": 5,
      "name": "Rock_Stone"
    },
    {
      "x": -3,
      "y": 6,
      "z": 5,
      "name": "Rock_Stone"
    },
    {
      "x": -3,
      "y": 7,
      "z": 5,
      "name": "Rock_Stone"
    },
    {
      "x": -3,
      "y": 8,
      "z": 5,
      "name": "Rock_Stone"
    },
    {
      "x": -3,
      "y": 9,
      "z": 5,
      "name": "Soil_Clay_Smooth_Grey_Stairs",
      "rotation": 3
    },
    {
      "x": -3,
      "y": 10,
      "z": 5,
      "name": "Soil_Clay_Smooth_Grey_Half",
      "rotation": 7
    },
    {
      "x": -3,
      "y": 11,
      "z": 5,
      "name": "Soil_Clay_Smooth_Grey_Stairs",
      "rotation": 9
    },
    {
      "x": -3,
      "y": 12,
      "z": 5,
      "name": "Soil_Clay_Smooth_Red"
    },
    {
      "x": -3,
      "y": 13,
      "z": 5,
      "name": "Soil_Clay_Smooth_Red"
    },
    {
      "x": -3,
      "y": 0,
      "z": 6,
      "name": "Rock_Basalt"
    },
    {
      "x": -3,
      "y": 1,
      "z": 6,
      "name": "Rock_Basalt"
    },
    {
      "x": -3,
      "y": 2,
      "z": 6,
      "name": "Rock_Basalt"
    },
    {
      "x": -3,
      "y": 3,
      "z": 6,
      "name": "Rock_Basalt"
    },
    {
      "x": -3,
      "y": 4,
      "z": 6,
      "name": "Rock_Stone"
    },
    {
      "x": -3,
      "y": 5,
      "z": 6,
      "name": "Rock_Stone"
    },
    {
      "x": -3,
      "y": 6,
      "z": 6,
      "name": "Rock_Stone"
    },
    {
      "x": -3,
      "y": 7,
      "z": 6,
      "name": "Rock_Stone"
    },
    {
      "x": -3,
      "y": 8,
      "z": 6,
      "name": "Rock_Stone"
    },
    {
      "x": -3,
      "y": 9,
      "z": 6,
      "name": "Soil_Clay_Red"
    },
    {
      "x": -3,
      "y": 10,
      "z": 6,
      "name": "Soil_Clay_Smooth_Red"
    },
    {
      "x": -3,
      "y": 11,
      "z": 6,
      "name": "Soil_Clay_Smooth_Red"
    },
    {
      "x": -3,
      "y": 12,
      "z": 6,
      "name": "Soil_Clay_Smooth_Red"
    },
    {
      "x": -3,
      "y": 0,
      "z": 7,
      "name": "Rock_Basalt"
    },
    {
      "x": -3,
      "y": 1,
      "z": 7,
      "name": "Rock_Basalt"
    },
    {
      "x": -3,
      "y": 2,
      "z": 7,
      "name": "Rock_Basalt"
    },
    {
      "x": -3,
      "y": 3,
      "z": 7,
      "name": "Rock_Basalt"
    },
    {
      "x": -3,
      "y": 4,
      "z": 7,
      "name": "Rock_Stone"
    },
    {
      "x": -3,
      "y": 5,
      "z": 7,
      "name": "Rock_Stone"
    },
    {
      "x": -3,
      "y": 6,
      "z": 7,
      "name": "Rock_Stone"
    },
    {
      "x": -3,
      "y": 7,
      "z": 7,
      "name": "Rock_Stone"
    },
    {
      "x": -3,
      "y": 8,
      "z": 7,
      "name": "Rock_Stone_Mossy"
    },
    {
      "x": -2,
      "y": 0,
      "z": -6,
      "name": "Rock_Basalt"
    },
    {
      "x": -2,
      "y": 1,
      "z": -6,
      "name": "Rock_Basalt"
    },
    {
      "x": -2,
      "y": 2,
      "z": -6,
      "name": "Rock_Basalt"
    },
    {
      "x": -2,
      "y": 3,
      "z": -6,
      "name": "Rock_Basalt"
    },
    {
      "x": -2,
      "y": 4,
      "z": -6,
      "name": "Rock_Stone"
    },
    {
      "x": -2,
      "y": 5,
      "z": -6,
      "name": "Rock_Stone"
    },
    {
      "x": -2,
      "y": 6,
      "z": -6,
      "name": "Rock_Stone"
    },
    {
      "x": -2,
      "y": 7,
      "z": -6,
      "name": "Rock_Stone"
    },
    {
      "x": -2,
      "y": 8,
      "z": -6,
      "name": "Rock_Stone"
    },
    {
      "x": -2,
      "y": 0,
      "z": -5,
      "name": "Rock_Basalt"
    },
    {
      "x": -2,
      "y": 1,
      "z": -5,
      "name": "Rock_Basalt"
    },
    {
      "x": -2,
      "y": 2,
      "z": -5,
      "name": "Rock_Basalt"
    },
    {
      "x": -2,
      "y": 3,
      "z": -5,
      "name": "Rock_Basalt"
    },
    {
      "x": -2,
      "y": 4,
      "z": -5,
      "name": "Rock_Stone"
    },
    {
      "x": -2,
      "y": 5,
      "z": -5,
      "name": "Rock_Stone"
    },
    {
      "x": -2,
      "y": 6,
      "z": -5,
      "name": "Rock_Stone"
    },
    {
      "x": -2,
      "y": 7,
      "z": -5,
      "name": "Rock_Stone"
    },
    {
      "x": -2,
      "y": 8,
      "z": -5,
      "name": "Rock_Stone"
    },
    {
      "x": -2,
      "y": 9,
      "z": -5,
      "name": "Soil_Clay_Red"
    },
    {
      "x": -2,
      "y": 10,
      "z": -5,
      "name": "Soil_Clay_Red"
    },
    {
      "x": -2,
      "y": 11,
      "z": -5,
      "name": "Soil_Clay_Smooth_Red"
    },
    {
      "x": -2,
      "y": 12,
      "z": -5,
      "name": "Soil_Clay_Smooth_Red"
    },
    {
      "x": -2,
      "y": 0,
      "z": -4,
      "name": "Rock_Basalt"
    },
    {
      "x": -2,
      "y": 1,
      "z": -4,
      "name": "Rock_Basalt"
    },
    {
      "x": -2,
      "y": 2,
      "z": -4,
      "name": "Rock_Basalt"
    },
    {
      "x": -2,
      "y": 3,
      "z": -4,
      "name": "Rock_Basalt"
    },
    {
      "x": -2,
      "y": 4,
      "z": -4,
      "name": "Rock_Stone"
    },
    {
      "x": -2,
      "y": 5,
      "z": -4,
      "name": "Rock_Stone"
    },
    {
      "x": -2,
      "y": 6,
      "z": -4,
      "name": "Rock_Stone"
    },
    {
      "x": -2,
      "y": 7,
      "z": -4,
      "name": "Rock_Stone"
    },
    {
      "x": -2,
      "y": 8,
      "z": -4,
      "name": "Rock_Stone"
    },
    {
      "x": -2,
      "y": 12,
      "z": -4,
      "name": "Soil_Clay_Smooth_Red"
    },
    {
      "x": -2,
      "y": 13,
      "z": -4,
      "name": "Soil_Clay_Smooth_Red"
    },
    {
      "x": -2,
      "y": 0,
      "z": -3,
      "name": "Rock_Basalt"
    },
    {
      "x": -2,
      "y": 1,
      "z": -3,
      "name": "Rock_Basalt"
    },
    {
      "x": -2,
      "y": 2,
      "z": -3,
      "name": "Rock_Basalt"
    },
    {
      "x": -2,
      "y": 3,
      "z": -3,
      "name": "Rock_Basalt"
    },
    {
      "x": -2,
      "y": 4,
      "z": -3,
      "name": "Rock_Stone"
    },
    {
      "x": -2,
      "y": 5,
      "z": -3,
      "name": "Rock_Stone"
    },
    {
      "x": -2,
      "y": 6,
      "z": -3,
      "name": "Rock_Stone"
    },
    {
      "x": -2,
      "y": 7,
      "z": -3,
      "name": "Rock_Stone"
    },
    {
      "x": -2,
      "y": 8,
      "z": -3,
      "name": "Rock_Stone"
    },
    {
      "x": -2,
      "y": 13,
      "z": -3,
      "name": "Soil_Clay_Smooth_Red"
    },
    {
      "x": -2,
      "y": 14,
      "z": -3,
      "name": "Soil_Clay_Smooth_Red"
    },
    {
      "x": -2,
      "y": 0,
      "z": -2,
      "name": "Rock_Basalt"
    },
    {
      "x": -2,
      "y": 1,
      "z": -2,
      "name": "Rock_Basalt"
    },
    {
      "x": -2,
      "y": 2,
      "z": -2,
      "name": "Rock_Basalt"
    },
    {
      "x": -2,
      "y": 3,
      "z": -2,
      "name": "Rock_Basalt"
    },
    {
      "x": -2,
      "y": 4,
      "z": -2,
      "name": "Rock_Stone"
    },
    {
      "x": -2,
      "y": 5,
      "z": -2,
      "name": "Rock_Stone"
    },
    {
      "x": -2,
      "y": 6,
      "z": -2,
      "name": "Rock_Stone"
    },
    {
      "x": -2,
      "y": 7,
      "z": -2,
      "name": "Rock_Stone"
    },
    {
      "x": -2,
      "y": 8,
      "z": -2,
      "name": "Rock_Stone"
    },
    {
      "x": -2,
      "y": 14,
      "z": -2,
      "name": "Soil_Clay_Smooth_Red"
    },
    {
      "x": -2,
      "y": 0,
      "z": -1,
      "name": "Rock_Basalt"
    },
    {
      "x": -2,
      "y": 1,
      "z": -1,
      "name": "Rock_Basalt"
    },
    {
      "x": -2,
      "y": 2,
      "z": -1,
      "name": "Rock_Basalt"
    },
    {
      "x": -2,
      "y": 3,
      "z": -1,
      "name": "Rock_Basalt"
    },
    {
      "x": -2,
      "y": 4,
      "z": -1,
      "name": "Rock_Stone"
    },
    {
      "x": -2,
      "y": 5,
      "z": -1,
      "name": "Rock_Stone"
    },
    {
      "x": -2,
      "y": 6,
      "z": -1,
      "name": "Rock_Stone"
    },
    {
      "x": -2,
      "y": 7,
      "z": -1,
      "name": "Rock_Stone"
    },
    {
      "x": -2,
      "y": 8,
      "z": -1,
      "name": "Rock_Stone"
    },
    {
      "x": -2,
      "y": 9,
      "z": -1,
      "name": "Soil_Clay_Smooth_Black"
    },
    {
      "x": -2,
      "y": 10,
      "z": -1,
      "name": "Soil_Clay_Smooth_Black"
    },
    {
      "x": -2,
      "y": 11,
      "z": -1,
      "name": "Soil_Clay_Smooth_Black"
    },
    {
      "x": -2,
      "y": 14,
      "z": -1,
      "name": "Soil_Clay_White"
    },
    {
      "x": -2,
      "y": 0,
      "z": 0,
      "name": "Rock_Basalt"
    },
    {
      "x": -2,
      "y": 1,
      "z": 0,
      "name": "Rock_Basalt"
    },
    {
      "x": -2,
      "y": 2,
      "z": 0,
      "name": "Rock_Basalt"
    },
    {
      "x": -2,
      "y": 3,
      "z": 0,
      "name": "Rock_Basalt"
    },
    {
      "x": -2,
      "y": 4,
      "z": 0,
      "name": "Rock_Stone"
    },
    {
      "x": -2,
      "y": 5,
      "z": 0,
      "name": "Rock_Stone"
    },
    {
      "x": -2,
      "y": 6,
      "z": 0,
      "name": "Rock_Stone"
    },
    {
      "x": -2,
      "y": 7,
      "z": 0,
      "name": "Rock_Stone"
    },
    {
      "x": -2,
      "y": 8,
      "z": 0,
      "name": "Rock_Stone"
    },
    {
      "x": -2,
      "y": 9,
      "z": 0,
      "name": "Soil_Clay_Smooth_Black"
    },
    {
      "x": -2,
      "y": 10,
      "z": 0,
      "name": "Soil_Clay_Smooth_Black"
    },
    {
      "x": -2,
      "y": 11,
      "z": 0,
      "name": "Soil_Clay_Smooth_Black"
    },
    {
      "x": -2,
      "y": 14,
      "z": 0,
      "name": "Soil_Clay_White"
    },
    {
      "x": -2,
      "y": 0,
      "z": 1,
      "name": "Rock_Basalt"
    },
    {
      "x": -2,
      "y": 1,
      "z": 1,
      "name": "Rock_Basalt"
    },
    {
      "x": -2,
      "y": 2,
      "z": 1,
      "name": "Rock_Basalt"
    },
    {
      "x": -2,
      "y": 3,
      "z": 1,
      "name": "Rock_Basalt"
    },
    {
      "x": -2,
      "y": 4,
      "z": 1,
      "name": "Rock_Stone"
    },
    {
      "x": -2,
      "y": 5,
      "z": 1,
      "name": "Rock_Stone"
    },
    {
      "x": -2,
      "y": 6,
      "z": 1,
      "name": "Rock_Stone"
    },
    {
      "x": -2,
      "y": 7,
      "z": 1,
      "name": "Rock_Stone"
    },
    {
      "x": -2,
      "y": 8,
      "z": 1,
      "name": "Rock_Stone"
    },
    {
      "x": -2,
      "y": 9,
      "z": 1,
      "name": "Soil_Clay_Smooth_Black"
    },
    {
      "x": -2,
      "y": 10,
      "z": 1,
      "name": "Soil_Clay_Smooth_Black"
    },
    {
      "x": -2,
      "y": 11,
      "z": 1,
      "name": "Soil_Clay_Smooth_Black"
    },
    {
      "x": -2,
      "y": 14,
      "z": 1,
      "name": "Soil_Clay_White"
    },
    {
      "x": -2,
      "y": 0,
      "z": 2,
      "name": "Rock_Basalt"
    },
    {
      "x": -2,
      "y": 1,
      "z": 2,
      "name": "Rock_Basalt"
    },
    {
      "x": -2,
      "y": 2,
      "z": 2,
      "name": "Rock_Basalt"
    },
    {
      "x": -2,
      "y": 3,
      "z": 2,
      "name": "Rock_Basalt"
    },
    {
      "x": -2,
      "y": 4,
      "z": 2,
      "name": "Rock_Stone"
    },
    {
      "x": -2,
      "y": 5,
      "z": 2,
      "name": "Rock_Stone"
    },
    {
      "x": -2,
      "y": 6,
      "z": 2,
      "name": "Rock_Stone"
    },
    {
      "x": -2,
      "y": 7,
      "z": 2,
      "name": "Rock_Stone"
    },
    {
      "x": -2,
      "y": 8,
      "z": 2,
      "name": "Rock_Stone"
    },
    {
      "x": -2,
      "y": 9,
      "z": 2,
      "name": "Soil_Clay_Smooth_Black"
    },
    {
      "x": -2,
      "y": 10,
      "z": 2,
      "name": "Soil_Clay_Smooth_Black"
    },
    {
      "x": -2,
      "y": 11,
      "z": 2,
      "name": "Soil_Clay_Smooth_Black"
    },
    {
      "x": -2,
      "y": 14,
      "z": 2,
      "name": "Soil_Clay_White"
    },
    {
      "x": -2,
      "y": 0,
      "z": 3,
      "name": "Rock_Basalt"
    },
    {
      "x": -2,
      "y": 1,
      "z": 3,
      "name": "Rock_Basalt"
    },
    {
      "x": -2,
      "y": 2,
      "z": 3,
      "name": "Rock_Basalt"
    },
    {
      "x": -2,
      "y": 3,
      "z": 3,
      "name": "Rock_Basalt"
    },
    {
      "x": -2,
      "y": 4,
      "z": 3,
      "name": "Rock_Stone"
    },
    {
      "x": -2,
      "y": 5,
      "z": 3,
      "name": "Rock_Stone"
    },
    {
      "x": -2,
      "y": 6,
      "z": 3,
      "name": "Rock_Stone"
    },
    {
      "x": -2,
      "y": 7,
      "z": 3,
      "name": "Rock_Stone"
    },
    {
      "x": -2,
      "y": 8,
      "z": 3,
      "name": "Rock_Stone"
    },
    {
      "x": -2,
      "y": 14,
      "z": 3,
      "name": "Soil_Clay_Smooth_Red"
    },
    {
      "x": -2,
      "y": 0,
      "z": 4,
      "name": "Rock_Basalt"
    },
    {
      "x": -2,
      "y": 1,
      "z": 4,
      "name": "Rock_Basalt"
    },
    {
      "x": -2,
      "y": 2,
      "z": 4,
      "name": "Rock_Basalt"
    },
    {
      "x": -2,
      "y": 3,
      "z": 4,
      "name": "Rock_Basalt"
    },
    {
      "x": -2,
      "y": 4,
      "z": 4,
      "name": "Rock_Stone"
    },
    {
      "x": -2,
      "y": 5,
      "z": 4,
      "name": "Rock_Stone"
    },
    {
      "x": -2,
      "y": 6,
      "z": 4,
      "name": "Rock_Stone"
    },
    {
      "x": -2,
      "y": 7,
      "z": 4,
      "name": "Rock_Stone"
    },
    {
      "x": -2,
      "y": 8,
      "z": 4,
      "name": "Rock_Stone"
    },
    {
      "x": -2,
      "y": 13,
      "z": 4,
      "name": "Soil_Clay_Smooth_Red"
    },
    {
      "x": -2,
      "y": 14,
      "z": 4,
      "name": "Soil_Clay_Smooth_Red"
    },
    {
      "x": -2,
      "y": 0,
      "z": 5,
      "name": "Rock_Basalt"
    },
    {
      "x": -2,
      "y": 1,
      "z": 5,
      "name": "Rock_Basalt"
    },
    {
      "x": -2,
      "y": 2,
      "z": 5,
      "name": "Rock_Basalt"
    },
    {
      "x": -2,
      "y": 3,
      "z": 5,
      "name": "Rock_Basalt"
    },
    {
      "x": -2,
      "y": 4,
      "z": 5,
      "name": "Rock_Stone"
    },
    {
      "x": -2,
      "y": 5,
      "z": 5,
      "name": "Rock_Stone"
    },
    {
      "x": -2,
      "y": 6,
      "z": 5,
      "name": "Rock_Stone"
    },
    {
      "x": -2,
      "y": 7,
      "z": 5,
      "name": "Rock_Stone"
    },
    {
      "x": -2,
      "y": 8,
      "z": 5,
      "name": "Rock_Stone"
    },
    {
      "x": -2,
      "y": 12,
      "z": 5,
      "name": "Soil_Clay_Smooth_Red"
    },
    {
      "x": -2,
      "y": 13,
      "z": 5,
      "name": "Soil_Clay_Smooth_Red"
    },
    {
      "x": -2,
      "y": 0,
      "z": 6,
      "name": "Rock_Basalt"
    },
    {
      "x": -2,
      "y": 1,
      "z": 6,
      "name": "Rock_Basalt"
    },
    {
      "x": -2,
      "y": 2,
      "z": 6,
      "name": "Rock_Basalt"
    },
    {
      "x": -2,
      "y": 3,
      "z": 6,
      "name": "Rock_Basalt"
    },
    {
      "x": -2,
      "y": 4,
      "z": 6,
      "name": "Rock_Stone"
    },
    {
      "x": -2,
      "y": 5,
      "z": 6,
      "name": "Rock_Stone"
    },
    {
      "x": -2,
      "y": 6,
      "z": 6,
      "name": "Rock_Stone"
    },
    {
      "x": -2,
      "y": 7,
      "z": 6,
      "name": "Rock_Stone"
    },
    {
      "x": -2,
      "y": 8,
      "z": 6,
      "name": "Rock_Stone"
    },
    {
      "x": -2,
      "y": 9,
      "z": 6,
      "name": "Soil_Clay_Red"
    },
    {
      "x": -2,
      "y": 10,
      "z": 6,
      "name": "Soil_Clay_Red"
    },
    {
      "x": -2,
      "y": 11,
      "z": 6,
      "name": "Soil_Clay_Smooth_Red"
    },
    {
      "x": -2,
      "y": 12,
      "z": 6,
      "name": "Soil_Clay_Smooth_Red"
    },
    {
      "x": -2,
      "y": 0,
      "z": 7,
      "name": "Rock_Basalt"
    },
    {
      "x": -2,
      "y": 1,
      "z": 7,
      "name": "Rock_Basalt"
    },
    {
      "x": -2,
      "y": 2,
      "z": 7,
      "name": "Rock_Basalt"
    },
    {
      "x": -2,
      "y": 3,
      "z": 7,
      "name": "Rock_Basalt"
    },
    {
      "x": -2,
      "y": 4,
      "z": 7,
      "name": "Rock_Stone"
    },
    {
      "x": -2,
      "y": 5,
      "z": 7,
      "name": "Rock_Stone"
    },
    {
      "x": -2,
      "y": 6,
      "z": 7,
      "name": "Rock_Stone"
    },
    {
      "x": -2,
      "y": 7,
      "z": 7,
      "name": "Rock_Stone"
    },
    {
      "x": -2,
      "y": 8,
      "z": 7,
      "name": "Rock_Stone_Mossy"
    },
    {
      "x": -1,
      "y": 0,
      "z": -6,
      "name": "Rock_Basalt"
    },
    {
      "x": -1,
      "y": 1,
      "z": -6,
      "name": "Rock_Basalt"
    },
    {
      "x": -1,
      "y": 2,
      "z": -6,
      "name": "Rock_Basalt"
    },
    {
      "x": -1,
      "y": 3,
      "z": -6,
      "name": "Rock_Basalt"
    },
    {
      "x": -1,
      "y": 4,
      "z": -6,
      "name": "Rock_Stone"
    },
    {
      "x": -1,
      "y": 5,
      "z": -6,
      "name": "Rock_Stone"
    },
    {
      "x": -1,
      "y": 6,
      "z": -6,
      "name": "Rock_Stone"
    },
    {
      "x": -1,
      "y": 7,
      "z": -6,
      "name": "Rock_Stone"
    },
    {
      "x": -1,
      "y": 8,
      "z": -6,
      "name": "Rock_Stone"
    },
    {
      "x": -1,
      "y": 0,
      "z": -5,
      "name": "Rock_Basalt"
    },
    {
      "x": -1,
      "y": 1,
      "z": -5,
      "name": "Rock_Basalt"
    },
    {
      "x": -1,
      "y": 2,
      "z": -5,
      "name": "Rock_Basalt"
    },
    {
      "x": -1,
      "y": 3,
      "z": -5,
      "name": "Rock_Basalt"
    },
    {
      "x": -1,
      "y": 4,
      "z": -5,
      "name": "Rock_Stone"
    },
    {
      "x": -1,
      "y": 5,
      "z": -5,
      "name": "Rock_Stone"
    },
    {
      "x": -1,
      "y": 6,
      "z": -5,
      "name": "Rock_Stone"
    },
    {
      "x": -1,
      "y": 7,
      "z": -5,
      "name": "Rock_Stone"
    },
    {
      "x": -1,
      "y": 8,
      "z": -5,
      "name": "Rock_Stone"
    },
    {
      "x": -1,
      "y": 9,
      "z": -5,
      "name": "Soil_Clay_Red"
    },
    {
      "x": -1,
      "y": 10,
      "z": -5,
      "name": "Soil_Clay_Red"
    },
    {
      "x": -1,
      "y": 11,
      "z": -5,
      "name": "Soil_Clay_Red"
    },
    {
      "x": -1,
      "y": 12,
      "z": -5,
      "name": "Soil_Clay_Smooth_Red"
    },
    {
      "x": -1,
      "y": 0,
      "z": -4,
      "name": "Rock_Basalt"
    },
    {
      "x": -1,
      "y": 1,
      "z": -4,
      "name": "Rock_Basalt"
    },
    {
      "x": -1,
      "y": 2,
      "z": -4,
      "name": "Rock_Basalt"
    },
    {
      "x": -1,
      "y": 3,
      "z": -4,
      "name": "Rock_Basalt"
    },
    {
      "x": -1,
      "y": 4,
      "z": -4,
      "name": "Rock_Stone"
    },
    {
      "x": -1,
      "y": 5,
      "z": -4,
      "name": "Rock_Stone"
    },
    {
      "x": -1,
      "y": 6,
      "z": -4,
      "name": "Rock_Stone"
    },
    {
      "x": -1,
      "y": 7,
      "z": -4,
      "name": "Rock_Stone"
    },
    {
      "x": -1,
      "y": 8,
      "z": -4,
      "name": "Rock_Stone"
    },
    {
      "x": -1,
      "y": 12,
      "z": -4,
      "name": "Soil_Clay_Smooth_Red"
    },
    {
      "x": -1,
      "y": 13,
      "z": -4,
      "name": "Soil_Clay_Smooth_Red"
    },
    {
      "x": -1,
      "y": 0,
      "z": -3,
      "name": "Rock_Basalt"
    },
    {
      "x": -1,
      "y": 1,
      "z": -3,
      "name": "Rock_Basalt"
    },
    {
      "x": -1,
      "y": 2,
      "z": -3,
      "name": "Rock_Basalt"
    },
    {
      "x": -1,
      "y": 3,
      "z": -3,
      "name": "Rock_Basalt"
    },
    {
      "x": -1,
      "y": 4,
      "z": -3,
      "name": "Rock_Stone"
    },
    {
      "x": -1,
      "y": 5,
      "z": -3,
      "name": "Rock_Stone"
    },
    {
      "x": -1,
      "y": 6,
      "z": -3,
      "name": "Rock_Stone"
    },
    {
      "x": -1,
      "y": 7,
      "z": -3,
      "name": "Rock_Stone"
    },
    {
      "x": -1,
      "y": 8,
      "z": -3,
      "name": "Rock_Stone"
    },
    {
      "x": -1,
      "y": 13,
      "z": -3,
      "name": "Soil_Clay_Smooth_Red"
    },
    {
      "x": -1,
      "y": 14,
      "z": -3,
      "name": "Soil_Clay_Smooth_Red"
    },
    {
      "x": -1,
      "y": 0,
      "z": -2,
      "name": "Rock_Basalt"
    },
    {
      "x": -1,
      "y": 1,
      "z": -2,
      "name": "Rock_Basalt"
    },
    {
      "x": -1,
      "y": 2,
      "z": -2,
      "name": "Rock_Basalt"
    },
    {
      "x": -1,
      "y": 3,
      "z": -2,
      "name": "Rock_Basalt"
    },
    {
      "x": -1,
      "y": 4,
      "z": -2,
      "name": "Rock_Stone"
    },
    {
      "x": -1,
      "y": 5,
      "z": -2,
      "name": "Rock_Stone"
    },
    {
      "x": -1,
      "y": 6,
      "z": -2,
      "name": "Rock_Stone"
    },
    {
      "x": -1,
      "y": 7,
      "z": -2,
      "name": "Rock_Stone"
    },
    {
      "x": -1,
      "y": 8,
      "z": -2,
      "name": "Rock_Stone"
    },
    {
      "x": -1,
      "y": 14,
      "z": -2,
      "name": "Soil_Clay_Smooth_Red"
    },
    {
      "x": -1,
      "y": 0,
      "z": -1,
      "name": "Rock_Basalt"
    },
    {
      "x": -1,
      "y": 1,
      "z": -1,
      "name": "Rock_Basalt"
    },
    {
      "x": -1,
      "y": 2,
      "z": -1,
      "name": "Rock_Basalt"
    },
    {
      "x": -1,
      "y": 3,
      "z": -1,
      "name": "Rock_Basalt"
    },
    {
      "x": -1,
      "y": 4,
      "z": -1,
      "name": "Rock_Stone"
    },
    {
      "x": -1,
      "y": 5,
      "z": -1,
      "name": "Rock_Stone"
    },
    {
      "x": -1,
      "y": 6,
      "z": -1,
      "name": "Rock_Stone"
    },
    {
      "x": -1,
      "y": 7,
      "z": -1,
      "name": "Rock_Stone"
    },
    {
      "x": -1,
      "y": 8,
      "z": -1,
      "name": "Rock_Stone"
    },
    {
      "x": -1,
      "y": 14,
      "z": -1,
      "name": "Soil_Clay_White"
    },
    {
      "x": -1,
      "y": 0,
      "z": 0,
      "name": "Rock_Basalt"
    },
    {
      "x": -1,
      "y": 1,
      "z": 0,
      "name": "Rock_Basalt"
    },
    {
      "x": -1,
      "y": 2,
      "z": 0,
      "name": "Rock_Basalt"
    },
    {
      "x": -1,
      "y": 3,
      "z": 0,
      "name": "Rock_Basalt"
    },
    {
      "x": -1,
      "y": 4,
      "z": 0,
      "name": "Rock_Stone"
    },
    {
      "x": -1,
      "y": 5,
      "z": 0,
      "name": "Rock_Stone"
    },
    {
      "x": -1,
      "y": 6,
      "z": 0,
      "name": "Rock_Stone"
    },
    {
      "x": -1,
      "y": 7,
      "z": 0,
      "name": "Rock_Stone"
    },
    {
      "x": -1,
      "y": 8,
      "z": 0,
      "name": "Rock_Stone"
    },
    {
      "x": -1,
      "y": 14,
      "z": 0,
      "name": "Soil_Clay_White"
    },
    {
      "x": -1,
      "y": 0,
      "z": 1,
      "name": "Rock_Basalt"
    },
    {
      "x": -1,
      "y": 1,
      "z": 1,
      "name": "Rock_Basalt"
    },
    {
      "x": -1,
      "y": 2,
      "z": 1,
      "name": "Rock_Basalt"
    },
    {
      "x": -1,
      "y": 3,
      "z": 1,
      "name": "Rock_Basalt"
    },
    {
      "x": -1,
      "y": 4,
      "z": 1,
      "name": "Rock_Stone"
    },
    {
      "x": -1,
      "y": 5,
      "z": 1,
      "name": "Rock_Stone"
    },
    {
      "x": -1,
      "y": 6,
      "z": 1,
      "name": "Rock_Stone"
    },
    {
      "x": -1,
      "y": 7,
      "z": 1,
      "name": "Rock_Stone"
    },
    {
      "x": -1,
      "y": 8,
      "z": 1,
      "name": "Rock_Stone"
    },
    {
      "x": -1,
      "y": 14,
      "z": 1,
      "name": "Soil_Clay_White"
    },
    {
      "x": -1,
      "y": 0,
      "z": 2,
      "name": "Rock_Basalt"
    },
    {
      "x": -1,
      "y": 1,
      "z": 2,
      "name": "Rock_Basalt"
    },
    {
      "x": -1,
      "y": 2,
      "z": 2,
      "name": "Rock_Basalt"
    },
    {
      "x": -1,
      "y": 3,
      "z": 2,
      "name": "Rock_Basalt"
    },
    {
      "x": -1,
      "y": 4,
      "z": 2,
      "name": "Rock_Stone"
    },
    {
      "x": -1,
      "y": 5,
      "z": 2,
      "name": "Rock_Stone"
    },
    {
      "x": -1,
      "y": 6,
      "z": 2,
      "name": "Rock_Stone"
    },
    {
      "x": -1,
      "y": 7,
      "z": 2,
      "name": "Rock_Stone"
    },
    {
      "x": -1,
      "y": 8,
      "z": 2,
      "name": "Rock_Stone"
    },
    {
      "x": -1,
      "y": 14,
      "z": 2,
      "name": "Soil_Clay_White"
    },
    {
      "x": -1,
      "y": 0,
      "z": 3,
      "name": "Rock_Basalt"
    },
    {
      "x": -1,
      "y": 1,
      "z": 3,
      "name": "Rock_Basalt"
    },
    {
      "x": -1,
      "y": 2,
      "z": 3,
      "name": "Rock_Basalt"
    },
    {
      "x": -1,
      "y": 3,
      "z": 3,
      "name": "Rock_Basalt"
    },
    {
      "x": -1,
      "y": 4,
      "z": 3,
      "name": "Rock_Stone"
    },
    {
      "x": -1,
      "y": 5,
      "z": 3,
      "name": "Rock_Stone"
    },
    {
      "x": -1,
      "y": 6,
      "z": 3,
      "name": "Rock_Stone"
    },
    {
      "x": -1,
      "y": 7,
      "z": 3,
      "name": "Rock_Stone"
    },
    {
      "x": -1,
      "y": 8,
      "z": 3,
      "name": "Rock_Stone"
    },
    {
      "x": -1,
      "y": 14,
      "z": 3,
      "name": "Soil_Clay_Smooth_Red"
    },
    {
      "x": -1,
      "y": 0,
      "z": 4,
      "name": "Rock_Basalt"
    },
    {
      "x": -1,
      "y": 1,
      "z": 4,
      "name": "Rock_Basalt"
    },
    {
      "x": -1,
      "y": 2,
      "z": 4,
      "name": "Rock_Basalt"
    },
    {
      "x": -1,
      "y": 3,
      "z": 4,
      "name": "Rock_Basalt"
    },
    {
      "x": -1,
      "y": 4,
      "z": 4,
      "name": "Rock_Stone"
    },
    {
      "x": -1,
      "y": 5,
      "z": 4,
      "name": "Rock_Stone"
    },
    {
      "x": -1,
      "y": 6,
      "z": 4,
      "name": "Rock_Stone"
    },
    {
      "x": -1,
      "y": 7,
      "z": 4,
      "name": "Rock_Stone"
    },
    {
      "x": -1,
      "y": 8,
      "z": 4,
      "name": "Rock_Stone"
    },
    {
      "x": -1,
      "y": 13,
      "z": 4,
      "name": "Soil_Clay_Smooth_Red"
    },
    {
      "x": -1,
      "y": 14,
      "z": 4,
      "name": "Soil_Clay_Smooth_Red"
    },
    {
      "x": -1,
      "y": 0,
      "z": 5,
      "name": "Rock_Basalt"
    },
    {
      "x": -1,
      "y": 1,
      "z": 5,
      "name": "Rock_Basalt"
    },
    {
      "x": -1,
      "y": 2,
      "z": 5,
      "name": "Rock_Basalt"
    },
    {
      "x": -1,
      "y": 3,
      "z": 5,
      "name": "Rock_Basalt"
    },
    {
      "x": -1,
      "y": 4,
      "z": 5,
      "name": "Rock_Stone"
    },
    {
      "x": -1,
      "y": 5,
      "z": 5,
      "name": "Rock_Stone"
    },
    {
      "x": -1,
      "y": 6,
      "z": 5,
      "name": "Rock_Stone"
    },
    {
      "x": -1,
      "y": 7,
      "z": 5,
      "name": "Rock_Stone"
    },
    {
      "x": -1,
      "y": 8,
      "z": 5,
      "name": "Rock_Stone"
    },
    {
      "x": -1,
      "y": 12,
      "z": 5,
      "name": "Soil_Clay_Smooth_Red"
    },
    {
      "x": -1,
      "y": 13,
      "z": 5,
      "name": "Soil_Clay_Smooth_Red"
    },
    {
      "x": -1,
      "y": 0,
      "z": 6,
      "name": "Rock_Basalt"
    },
    {
      "x": -1,
      "y": 1,
      "z": 6,
      "name": "Rock_Basalt"
    },
    {
      "x": -1,
      "y": 2,
      "z": 6,
      "name": "Rock_Basalt"
    },
    {
      "x": -1,
      "y": 3,
      "z": 6,
      "name": "Rock_Basalt"
    },
    {
      "x": -1,
      "y": 4,
      "z": 6,
      "name": "Rock_Stone"
    },
    {
      "x": -1,
      "y": 5,
      "z": 6,
      "name": "Rock_Stone"
    },
    {
      "x": -1,
      "y": 6,
      "z": 6,
      "name": "Rock_Stone"
    },
    {
      "x": -1,
      "y": 7,
      "z": 6,
      "name": "Rock_Stone"
    },
    {
      "x": -1,
      "y": 8,
      "z": 6,
      "name": "Rock_Stone"
    },
    {
      "x": -1,
      "y": 9,
      "z": 6,
      "name": "Soil_Clay_Red"
    },
    {
      "x": -1,
      "y": 10,
      "z": 6,
      "name": "Soil_Clay_Red"
    },
    {
      "x": -1,
      "y": 11,
      "z": 6,
      "name": "Soil_Clay_Red"
    },
    {
      "x": -1,
      "y": 12,
      "z": 6,
      "name": "Soil_Clay_Smooth_Red"
    },
    {
      "x": -1,
      "y": 0,
      "z": 7,
      "name": "Rock_Basalt"
    },
    {
      "x": -1,
      "y": 1,
      "z": 7,
      "name": "Rock_Basalt"
    },
    {
      "x": -1,
      "y": 2,
      "z": 7,
      "name": "Rock_Basalt"
    },
    {
      "x": -1,
      "y": 3,
      "z": 7,
      "name": "Rock_Basalt"
    },
    {
      "x": -1,
      "y": 4,
      "z": 7,
      "name": "Rock_Stone"
    },
    {
      "x": -1,
      "y": 5,
      "z": 7,
      "name": "Rock_Stone"
    },
    {
      "x": -1,
      "y": 6,
      "z": 7,
      "name": "Rock_Stone"
    },
    {
      "x": -1,
      "y": 7,
      "z": 7,
      "name": "Rock_Stone"
    },
    {
      "x": -1,
      "y": 8,
      "z": 7,
      "name": "Rock_Stone"
    },
    {
      "x": 0,
      "y": 0,
      "z": -6,
      "name": "Rock_Basalt"
    },
    {
      "x": 0,
      "y": 1,
      "z": -6,
      "name": "Rock_Basalt"
    },
    {
      "x": 0,
      "y": 2,
      "z": -6,
      "name": "Rock_Basalt"
    },
    {
      "x": 0,
      "y": 3,
      "z": -6,
      "name": "Rock_Basalt"
    },
    {
      "x": 0,
      "y": 4,
      "z": -6,
      "name": "Rock_Stone"
    },
    {
      "x": 0,
      "y": 5,
      "z": -6,
      "name": "Rock_Stone"
    },
    {
      "x": 0,
      "y": 6,
      "z": -6,
      "name": "Rock_Stone"
    },
    {
      "x": 0,
      "y": 7,
      "z": -6,
      "name": "Rock_Stone"
    },
    {
      "x": 0,
      "y": 8,
      "z": -6,
      "name": "Rock_Stone_Mossy"
    },
    {
      "x": 0,
      "y": 0,
      "z": -5,
      "name": "Rock_Basalt"
    },
    {
      "x": 0,
      "y": 1,
      "z": -5,
      "name": "Rock_Basalt"
    },
    {
      "x": 0,
      "y": 2,
      "z": -5,
      "name": "Rock_Basalt"
    },
    {
      "x": 0,
      "y": 3,
      "z": -5,
      "name": "Rock_Basalt"
    },
    {
      "x": 0,
      "y": 4,
      "z": -5,
      "name": "Rock_Stone"
    },
    {
      "x": 0,
      "y": 5,
      "z": -5,
      "name": "Rock_Stone"
    },
    {
      "x": 0,
      "y": 6,
      "z": -5,
      "name": "Rock_Stone"
    },
    {
      "x": 0,
      "y": 7,
      "z": -5,
      "name": "Rock_Stone"
    },
    {
      "x": 0,
      "y": 8,
      "z": -5,
      "name": "Rock_Stone"
    },
    {
      "x": 0,
      "y": 9,
      "z": -5,
      "name": "Soil_Clay_Red"
    },
    {
      "x": 0,
      "y": 10,
      "z": -5,
      "name": "Soil_Clay_Red"
    },
    {
      "x": 0,
      "y": 11,
      "z": -5,
      "name": "Soil_Clay_Red"
    },
    {
      "x": 0,
      "y": 12,
      "z": -5,
      "name": "Soil_Clay_Red"
    },
    {
      "x": 0,
      "y": 0,
      "z": -4,
      "name": "Rock_Basalt"
    },
    {
      "x": 0,
      "y": 1,
      "z": -4,
      "name": "Rock_Basalt"
    },
    {
      "x": 0,
      "y": 2,
      "z": -4,
      "name": "Rock_Basalt"
    },
    {
      "x": 0,
      "y": 3,
      "z": -4,
      "name": "Rock_Basalt"
    },
    {
      "x": 0,
      "y": 4,
      "z": -4,
      "name": "Rock_Stone"
    },
    {
      "x": 0,
      "y": 5,
      "z": -4,
      "name": "Rock_Stone"
    },
    {
      "x": 0,
      "y": 6,
      "z": -4,
      "name": "Rock_Stone"
    },
    {
      "x": 0,
      "y": 7,
      "z": -4,
      "name": "Rock_Stone"
    },
    {
      "x": 0,
      "y": 8,
      "z": -4,
      "name": "Rock_Stone"
    },
    {
      "x": 0,
      "y": 12,
      "z": -4,
      "name": "Soil_Clay_Smooth_Red"
    },
    {
      "x": 0,
      "y": 13,
      "z": -4,
      "name": "Soil_Clay_Smooth_Red"
    },
    {
      "x": 0,
      "y": 0,
      "z": -3,
      "name": "Rock_Basalt"
    },
    {
      "x": 0,
      "y": 1,
      "z": -3,
      "name": "Rock_Basalt"
    },
    {
      "x": 0,
      "y": 2,
      "z": -3,
      "name": "Rock_Basalt"
    },
    {
      "x": 0,
      "y": 3,
      "z": -3,
      "name": "Rock_Basalt"
    },
    {
      "x": 0,
      "y": 4,
      "z": -3,
      "name": "Rock_Stone"
    },
    {
      "x": 0,
      "y": 5,
      "z": -3,
      "name": "Rock_Stone"
    },
    {
      "x": 0,
      "y": 6,
      "z": -3,
      "name": "Rock_Stone"
    },
    {
      "x": 0,
      "y": 7,
      "z": -3,
      "name": "Rock_Stone"
    },
    {
      "x": 0,
      "y": 8,
      "z": -3,
      "name": "Rock_Stone"
    },
    {
      "x": 0,
      "y": 13,
      "z": -3,
      "name": "Soil_Clay_Smooth_Red"
    },
    {
      "x": 0,
      "y": 14,
      "z": -3,
      "name": "Soil_Clay_Smooth_Red"
    },
    {
      "x": 0,
      "y": 0,
      "z": -2,
      "name": "Rock_Basalt"
    },
    {
      "x": 0,
      "y": 1,
      "z": -2,
      "name": "Rock_Basalt"
    },
    {
      "x": 0,
      "y": 2,
      "z": -2,
      "name": "Rock_Basalt"
    },
    {
      "x": 0,
      "y": 3,
      "z": -2,
      "name": "Rock_Basalt"
    },
    {
      "x": 0,
      "y": 4,
      "z": -2,
      "name": "Rock_Stone"
    },
    {
      "x": 0,
      "y": 5,
      "z": -2,
      "name": "Rock_Stone"
    },
    {
      "x": 0,
      "y": 6,
      "z": -2,
      "name": "Rock_Stone"
    },
    {
      "x": 0,
      "y": 7,
      "z": -2,
      "name": "Rock_Stone"
    },
    {
      "x": 0,
      "y": 8,
      "z": -2,
      "name": "Rock_Stone"
    },
    {
      "x": 0,
      "y": 14,
      "z": -2,
      "name": "Soil_Clay_Smooth_Red"
    },
    {
      "x": 0,
      "y": 0,
      "z": -1,
      "name": "Rock_Basalt"
    },
    {
      "x": 0,
      "y": 1,
      "z": -1,
      "name": "Rock_Basalt"
    },
    {
      "x": 0,
      "y": 2,
      "z": -1,
      "name": "Rock_Basalt"
    },
    {
      "x": 0,
      "y": 3,
      "z": -1,
      "name": "Rock_Basalt"
    },
    {
      "x": 0,
      "y": 4,
      "z": -1,
      "name": "Rock_Stone"
    },
    {
      "x": 0,
      "y": 5,
      "z": -1,
      "name": "Rock_Stone"
    },
    {
      "x": 0,
      "y": 6,
      "z": -1,
      "name": "Rock_Stone"
    },
    {
      "x": 0,
      "y": 7,
      "z": -1,
      "name": "Rock_Stone"
    },
    {
      "x": 0,
      "y": 8,
      "z": -1,
      "name": "Rock_Stone"
    },
    {
      "x": 0,
      "y": 14,
      "z": -1,
      "name": "Soil_Clay_White"
    },
    {
      "x": 0,
      "y": 0,
      "z": 0,
      "name": "Rock_Basalt"
    },
    {
      "x": 0,
      "y": 1,
      "z": 0,
      "name": "Rock_Basalt"
    },
    {
      "x": 0,
      "y": 2,
      "z": 0,
      "name": "Rock_Basalt"
    },
    {
      "x": 0,
      "y": 3,
      "z": 0,
      "name": "Rock_Basalt"
    },
    {
      "x": 0,
      "y": 4,
      "z": 0,
      "name": "Rock_Stone"
    },
    {
      "x": 0,
      "y": 5,
      "z": 0,
      "name": "Rock_Stone"
    },
    {
      "x": 0,
      "y": 6,
      "z": 0,
      "name": "Rock_Stone"
    },
    {
      "x": 0,
      "y": 7,
      "z": 0,
      "name": "Rock_Stone"
    },
    {
      "x": 0,
      "y": 8,
      "z": 0,
      "name": "Rock_Stone"
    },
    {
      "x": 0,
      "y": 14,
      "z": 0,
      "name": "Soil_Clay_White"
    },
    {
      "x": 0,
      "y": 0,
      "z": 1,
      "name": "Rock_Basalt"
    },
    {
      "x": 0,
      "y": 1,
      "z": 1,
      "name": "Rock_Basalt"
    },
    {
      "x": 0,
      "y": 2,
      "z": 1,
      "name": "Rock_Basalt"
    },
    {
      "x": 0,
      "y": 3,
      "z": 1,
      "name": "Rock_Basalt"
    },
    {
      "x": 0,
      "y": 4,
      "z": 1,
      "name": "Rock_Stone"
    },
    {
      "x": 0,
      "y": 5,
      "z": 1,
      "name": "Rock_Stone"
    },
    {
      "x": 0,
      "y": 6,
      "z": 1,
      "name": "Rock_Stone"
    },
    {
      "x": 0,
      "y": 7,
      "z": 1,
      "name": "Rock_Stone"
    },
    {
      "x": 0,
      "y": 8,
      "z": 1,
      "name": "Rock_Stone"
    },
    {
      "x": 0,
      "y": 14,
      "z": 1,
      "name": "Soil_Clay_White"
    },
    {
      "x": 0,
      "y": 0,
      "z": 2,
      "name": "Rock_Basalt"
    },
    {
      "x": 0,
      "y": 1,
      "z": 2,
      "name": "Rock_Basalt"
    },
    {
      "x": 0,
      "y": 2,
      "z": 2,
      "name": "Rock_Basalt"
    },
    {
      "x": 0,
      "y": 3,
      "z": 2,
      "name": "Rock_Basalt"
    },
    {
      "x": 0,
      "y": 4,
      "z": 2,
      "name": "Rock_Stone"
    },
    {
      "x": 0,
      "y": 5,
      "z": 2,
      "name": "Rock_Stone"
    },
    {
      "x": 0,
      "y": 6,
      "z": 2,
      "name": "Rock_Stone"
    },
    {
      "x": 0,
      "y": 7,
      "z": 2,
      "name": "Rock_Stone"
    },
    {
      "x": 0,
      "y": 8,
      "z": 2,
      "name": "Rock_Stone"
    },
    {
      "x": 0,
      "y": 14,
      "z": 2,
      "name": "Soil_Clay_White"
    },
    {
      "x": 0,
      "y": 0,
      "z": 3,
      "name": "Rock_Basalt"
    },
    {
      "x": 0,
      "y": 1,
      "z": 3,
      "name": "Rock_Basalt"
    },
    {
      "x": 0,
      "y": 2,
      "z": 3,
      "name": "Rock_Basalt"
    },
    {
      "x": 0,
      "y": 3,
      "z": 3,
      "name": "Rock_Basalt"
    },
    {
      "x": 0,
      "y": 4,
      "z": 3,
      "name": "Rock_Stone"
    },
    {
      "x": 0,
      "y": 5,
      "z": 3,
      "name": "Rock_Stone"
    },
    {
      "x": 0,
      "y": 6,
      "z": 3,
      "name": "Rock_Stone"
    },
    {
      "x": 0,
      "y": 7,
      "z": 3,
      "name": "Rock_Stone"
    },
    {
      "x": 0,
      "y": 8,
      "z": 3,
      "name": "Rock_Stone"
    },
    {
      "x": 0,
      "y": 14,
      "z": 3,
      "name": "Soil_Clay_Smooth_Red"
    },
    {
      "x": 0,
      "y": 0,
      "z": 4,
      "name": "Rock_Basalt"
    },
    {
      "x": 0,
      "y": 1,
      "z": 4,
      "name": "Rock_Basalt"
    },
    {
      "x": 0,
      "y": 2,
      "z": 4,
      "name": "Rock_Basalt"
    },
    {
      "x": 0,
      "y": 3,
      "z": 4,
      "name": "Rock_Basalt"
    },
    {
      "x": 0,
      "y": 4,
      "z": 4,
      "name": "Rock_Stone"
    },
    {
      "x": 0,
      "y": 5,
      "z": 4,
      "name": "Rock_Stone"
    },
    {
      "x": 0,
      "y": 6,
      "z": 4,
      "name": "Rock_Stone"
    },
    {
      "x": 0,
      "y": 7,
      "z": 4,
      "name": "Rock_Stone"
    },
    {
      "x": 0,
      "y": 8,
      "z": 4,
      "name": "Rock_Stone"
    },
    {
      "x": 0,
      "y": 13,
      "z": 4,
      "name": "Soil_Clay_Smooth_Red"
    },
    {
      "x": 0,
      "y": 14,
      "z": 4,
      "name": "Soil_Clay_Smooth_Red"
    },
    {
      "x": 0,
      "y": 0,
      "z": 5,
      "name": "Rock_Basalt"
    },
    {
      "x": 0,
      "y": 1,
      "z": 5,
      "name": "Rock_Basalt"
    },
    {
      "x": 0,
      "y": 2,
      "z": 5,
      "name": "Rock_Basalt"
    },
    {
      "x": 0,
      "y": 3,
      "z": 5,
      "name": "Rock_Basalt"
    },
    {
      "x": 0,
      "y": 4,
      "z": 5,
      "name": "Rock_Stone"
    },
    {
      "x": 0,
      "y": 5,
      "z": 5,
      "name": "Rock_Stone"
    },
    {
      "x": 0,
      "y": 6,
      "z": 5,
      "name": "Rock_Stone"
    },
    {
      "x": 0,
      "y": 7,
      "z": 5,
      "name": "Rock_Stone"
    },
    {
      "x": 0,
      "y": 8,
      "z": 5,
      "name": "Rock_Stone"
    },
    {
      "x": 0,
      "y": 12,
      "z": 5,
      "name": "Soil_Clay_Smooth_Red"
    },
    {
      "x": 0,
      "y": 13,
      "z": 5,
      "name": "Soil_Clay_Smooth_Red"
    },
    {
      "x": 0,
      "y": 0,
      "z": 6,
      "name": "Rock_Basalt"
    },
    {
      "x": 0,
      "y": 1,
      "z": 6,
      "name": "Rock_Basalt"
    },
    {
      "x": 0,
      "y": 2,
      "z": 6,
      "name": "Rock_Basalt"
    },
    {
      "x": 0,
      "y": 3,
      "z": 6,
      "name": "Rock_Basalt"
    },
    {
      "x": 0,
      "y": 4,
      "z": 6,
      "name": "Rock_Stone"
    },
    {
      "x": 0,
      "y": 5,
      "z": 6,
      "name": "Rock_Stone"
    },
    {
      "x": 0,
      "y": 6,
      "z": 6,
      "name": "Rock_Stone"
    },
    {
      "x": 0,
      "y": 7,
      "z": 6,
      "name": "Rock_Stone"
    },
    {
      "x": 0,
      "y": 8,
      "z": 6,
      "name": "Rock_Stone"
    },
    {
      "x": 0,
      "y": 9,
      "z": 6,
      "name": "Soil_Clay_Red"
    },
    {
      "x": 0,
      "y": 10,
      "z": 6,
      "name": "Soil_Clay_Red"
    },
    {
      "x": 0,
      "y": 11,
      "z": 6,
      "name": "Soil_Clay_Red"
    },
    {
      "x": 0,
      "y": 12,
      "z": 6,
      "name": "Soil_Clay_Red"
    },
    {
      "x": 0,
      "y": 0,
      "z": 7,
      "name": "Rock_Basalt"
    },
    {
      "x": 0,
      "y": 1,
      "z": 7,
      "name": "Rock_Basalt"
    },
    {
      "x": 0,
      "y": 2,
      "z": 7,
      "name": "Rock_Basalt"
    },
    {
      "x": 0,
      "y": 3,
      "z": 7,
      "name": "Rock_Basalt"
    },
    {
      "x": 0,
      "y": 4,
      "z": 7,
      "name": "Rock_Stone"
    },
    {
      "x": 0,
      "y": 5,
      "z": 7,
      "name": "Rock_Stone"
    },
    {
      "x": 0,
      "y": 6,
      "z": 7,
      "name": "Rock_Stone"
    },
    {
      "x": 0,
      "y": 7,
      "z": 7,
      "name": "Rock_Stone"
    },
    {
      "x": 0,
      "y": 8,
      "z": 7,
      "name": "Rock_Stone"
    },
    {
      "x": 1,
      "y": 0,
      "z": -6,
      "name": "Rock_Basalt"
    },
    {
      "x": 1,
      "y": 1,
      "z": -6,
      "name": "Rock_Basalt"
    },
    {
      "x": 1,
      "y": 2,
      "z": -6,
      "name": "Rock_Basalt"
    },
    {
      "x": 1,
      "y": 3,
      "z": -6,
      "name": "Rock_Basalt"
    },
    {
      "x": 1,
      "y": 4,
      "z": -6,
      "name": "Rock_Stone"
    },
    {
      "x": 1,
      "y": 5,
      "z": -6,
      "name": "Rock_Stone"
    },
    {
      "x": 1,
      "y": 6,
      "z": -6,
      "name": "Rock_Stone"
    },
    {
      "x": 1,
      "y": 7,
      "z": -6,
      "name": "Rock_Stone"
    },
    {
      "x": 1,
      "y": 8,
      "z": -6,
      "name": "Rock_Stone_Mossy"
    },
    {
      "x": 1,
      "y": 9,
      "z": -6,
      "name": "Plant_Moss_Rug_Green",
      "support": 15
    },
    {
      "x": 1,
      "y": 0,
      "z": -5,
      "name": "Rock_Basalt"
    },
    {
      "x": 1,
      "y": 1,
      "z": -5,
      "name": "Rock_Basalt"
    },
    {
      "x": 1,
      "y": 2,
      "z": -5,
      "name": "Rock_Basalt"
    },
    {
      "x": 1,
      "y": 3,
      "z": -5,
      "name": "Rock_Basalt"
    },
    {
      "x": 1,
      "y": 4,
      "z": -5,
      "name": "Rock_Stone"
    },
    {
      "x": 1,
      "y": 5,
      "z": -5,
      "name": "Rock_Stone"
    },
    {
      "x": 1,
      "y": 6,
      "z": -5,
      "name": "Rock_Stone"
    },
    {
      "x": 1,
      "y": 7,
      "z": -5,
      "name": "Rock_Stone"
    },
    {
      "x": 1,
      "y": 8,
      "z": -5,
      "name": "Rock_Stone"
    },
    {
      "x": 1,
      "y": 9,
      "z": -5,
      "name": "Soil_Clay_Red"
    },
    {
      "x": 1,
      "y": 10,
      "z": -5,
      "name": "Soil_Clay_Red"
    },
    {
      "x": 1,
      "y": 11,
      "z": -5,
      "name": "Soil_Clay_Red"
    },
    {
      "x": 1,
      "y": 12,
      "z": -5,
      "name": "Soil_Clay_Red"
    },
    {
      "x": 1,
      "y": 0,
      "z": -4,
      "name": "Rock_Basalt"
    },
    {
      "x": 1,
      "y": 1,
      "z": -4,
      "name": "Rock_Basalt"
    },
    {
      "x": 1,
      "y": 2,
      "z": -4,
      "name": "Rock_Basalt"
    },
    {
      "x": 1,
      "y": 3,
      "z": -4,
      "name": "Rock_Basalt"
    },
    {
      "x": 1,
      "y": 4,
      "z": -4,
      "name": "Rock_Stone"
    },
    {
      "x": 1,
      "y": 5,
      "z": -4,
      "name": "Rock_Stone"
    },
    {
      "x": 1,
      "y": 6,
      "z": -4,
      "name": "Rock_Stone"
    },
    {
      "x": 1,
      "y": 7,
      "z": -4,
      "name": "Rock_Stone"
    },
    {
      "x": 1,
      "y": 8,
      "z": -4,
      "name": "Rock_Stone"
    },
    {
      "x": 1,
      "y": 12,
      "z": -4,
      "name": "Soil_Clay_Smooth_Red"
    },
    {
      "x": 1,
      "y": 13,
      "z": -4,
      "name": "Soil_Clay_Red"
    },
    {
      "x": 1,
      "y": 0,
      "z": -3,
      "name": "Rock_Basalt"
    },
    {
      "x": 1,
      "y": 1,
      "z": -3,
      "name": "Rock_Basalt"
    },
    {
      "x": 1,
      "y": 2,
      "z": -3,
      "name": "Rock_Basalt"
    },
    {
      "x": 1,
      "y": 3,
      "z": -3,
      "name": "Rock_Basalt"
    },
    {
      "x": 1,
      "y": 4,
      "z": -3,
      "name": "Rock_Stone"
    },
    {
      "x": 1,
      "y": 5,
      "z": -3,
      "name": "Rock_Stone"
    },
    {
      "x": 1,
      "y": 6,
      "z": -3,
      "name": "Rock_Stone"
    },
    {
      "x": 1,
      "y": 7,
      "z": -3,
      "name": "Rock_Stone"
    },
    {
      "x": 1,
      "y": 8,
      "z": -3,
      "name": "Rock_Stone"
    },
    {
      "x": 1,
      "y": 13,
      "z": -3,
      "name": "Soil_Clay_Smooth_Red"
    },
    {
      "x": 1,
      "y": 14,
      "z": -3,
      "name": "Soil_Clay_Smooth_Red"
    },
    {
      "x": 1,
      "y": 0,
      "z": -2,
      "name": "Rock_Basalt"
    },
    {
      "x": 1,
      "y": 1,
      "z": -2,
      "name": "Rock_Basalt"
    },
    {
      "x": 1,
      "y": 2,
      "z": -2,
      "name": "Rock_Basalt"
    },
    {
      "x": 1,
      "y": 3,
      "z": -2,
      "name": "Rock_Basalt"
    },
    {
      "x": 1,
      "y": 4,
      "z": -2,
      "name": "Rock_Stone"
    },
    {
      "x": 1,
      "y": 5,
      "z": -2,
      "name": "Rock_Stone"
    },
    {
      "x": 1,
      "y": 6,
      "z": -2,
      "name": "Rock_Stone"
    },
    {
      "x": 1,
      "y": 7,
      "z": -2,
      "name": "Rock_Stone"
    },
    {
      "x": 1,
      "y": 8,
      "z": -2,
      "name": "Rock_Stone"
    },
    {
      "x": 1,
      "y": 14,
      "z": -2,
      "name": "Soil_Clay_Smooth_Red"
    },
    {
      "x": 1,
      "y": 0,
      "z": -1,
      "name": "Rock_Basalt"
    },
    {
      "x": 1,
      "y": 1,
      "z": -1,
      "name": "Rock_Basalt"
    },
    {
      "x": 1,
      "y": 2,
      "z": -1,
      "name": "Rock_Basalt"
    },
    {
      "x": 1,
      "y": 3,
      "z": -1,
      "name": "Rock_Basalt"
    },
    {
      "x": 1,
      "y": 4,
      "z": -1,
      "name": "Rock_Stone"
    },
    {
      "x": 1,
      "y": 5,
      "z": -1,
      "name": "Rock_Stone"
    },
    {
      "x": 1,
      "y": 6,
      "z": -1,
      "name": "Rock_Stone"
    },
    {
      "x": 1,
      "y": 7,
      "z": -1,
      "name": "Rock_Stone"
    },
    {
      "x": 1,
      "y": 8,
      "z": -1,
      "name": "Rock_Stone"
    },
    {
      "x": 1,
      "y": 14,
      "z": -1,
      "name": "Soil_Clay_White"
    },
    {
      "x": 1,
      "y": 0,
      "z": 0,
      "name": "Rock_Basalt"
    },
    {
      "x": 1,
      "y": 1,
      "z": 0,
      "name": "Rock_Basalt"
    },
    {
      "x": 1,
      "y": 2,
      "z": 0,
      "name": "Rock_Basalt"
    },
    {
      "x": 1,
      "y": 3,
      "z": 0,
      "name": "Rock_Basalt"
    },
    {
      "x": 1,
      "y": 4,
      "z": 0,
      "name": "Rock_Stone"
    },
    {
      "x": 1,
      "y": 5,
      "z": 0,
      "name": "Rock_Stone"
    },
    {
      "x": 1,
      "y": 6,
      "z": 0,
      "name": "Rock_Stone"
    },
    {
      "x": 1,
      "y": 7,
      "z": 0,
      "name": "Rock_Stone"
    },
    {
      "x": 1,
      "y": 8,
      "z": 0,
      "name": "Rock_Stone"
    },
    {
      "x": 1,
      "y": 14,
      "z": 0,
      "name": "Soil_Clay_White"
    },
    {
      "x": 1,
      "y": 0,
      "z": 1,
      "name": "Rock_Basalt"
    },
    {
      "x": 1,
      "y": 1,
      "z": 1,
      "name": "Rock_Basalt"
    },
    {
      "x": 1,
      "y": 2,
      "z": 1,
      "name": "Rock_Basalt"
    },
    {
      "x": 1,
      "y": 3,
      "z": 1,
      "name": "Rock_Basalt"
    },
    {
      "x": 1,
      "y": 4,
      "z": 1,
      "name": "Rock_Stone"
    },
    {
      "x": 1,
      "y": 5,
      "z": 1,
      "name": "Rock_Stone"
    },
    {
      "x": 1,
      "y": 6,
      "z": 1,
      "name": "Rock_Stone"
    },
    {
      "x": 1,
      "y": 7,
      "z": 1,
      "name": "Rock_Stone"
    },
    {
      "x": 1,
      "y": 8,
      "z": 1,
      "name": "Rock_Stone"
    },
    {
      "x": 1,
      "y": 14,
      "z": 1,
      "name": "Soil_Clay_White"
    },
    {
      "x": 1,
      "y": 0,
      "z": 2,
      "name": "Rock_Basalt"
    },
    {
      "x": 1,
      "y": 1,
      "z": 2,
      "name": "Rock_Basalt"
    },
    {
      "x": 1,
      "y": 2,
      "z": 2,
      "name": "Rock_Basalt"
    },
    {
      "x": 1,
      "y": 3,
      "z": 2,
      "name": "Rock_Basalt"
    },
    {
      "x": 1,
      "y": 4,
      "z": 2,
      "name": "Rock_Stone"
    },
    {
      "x": 1,
      "y": 5,
      "z": 2,
      "name": "Rock_Stone"
    },
    {
      "x": 1,
      "y": 6,
      "z": 2,
      "name": "Rock_Stone"
    },
    {
      "x": 1,
      "y": 7,
      "z": 2,
      "name": "Rock_Stone"
    },
    {
      "x": 1,
      "y": 8,
      "z": 2,
      "name": "Rock_Stone"
    },
    {
      "x": 1,
      "y": 14,
      "z": 2,
      "name": "Soil_Clay_White"
    },
    {
      "x": 1,
      "y": 0,
      "z": 3,
      "name": "Rock_Basalt"
    },
    {
      "x": 1,
      "y": 1,
      "z": 3,
      "name": "Rock_Basalt"
    },
    {
      "x": 1,
      "y": 2,
      "z": 3,
      "name": "Rock_Basalt"
    },
    {
      "x": 1,
      "y": 3,
      "z": 3,
      "name": "Rock_Basalt"
    },
    {
      "x": 1,
      "y": 4,
      "z": 3,
      "name": "Rock_Stone"
    },
    {
      "x": 1,
      "y": 5,
      "z": 3,
      "name": "Rock_Stone"
    },
    {
      "x": 1,
      "y": 6,
      "z": 3,
      "name": "Rock_Stone"
    },
    {
      "x": 1,
      "y": 7,
      "z": 3,
      "name": "Rock_Stone"
    },
    {
      "x": 1,
      "y": 8,
      "z": 3,
      "name": "Rock_Stone"
    },
    {
      "x": 1,
      "y": 14,
      "z": 3,
      "name": "Soil_Clay_Smooth_Red"
    },
    {
      "x": 1,
      "y": 0,
      "z": 4,
      "name": "Rock_Basalt"
    },
    {
      "x": 1,
      "y": 1,
      "z": 4,
      "name": "Rock_Basalt"
    },
    {
      "x": 1,
      "y": 2,
      "z": 4,
      "name": "Rock_Basalt"
    },
    {
      "x": 1,
      "y": 3,
      "z": 4,
      "name": "Rock_Basalt"
    },
    {
      "x": 1,
      "y": 4,
      "z": 4,
      "name": "Rock_Stone"
    },
    {
      "x": 1,
      "y": 5,
      "z": 4,
      "name": "Rock_Stone"
    },
    {
      "x": 1,
      "y": 6,
      "z": 4,
      "name": "Rock_Stone"
    },
    {
      "x": 1,
      "y": 7,
      "z": 4,
      "name": "Rock_Stone"
    },
    {
      "x": 1,
      "y": 8,
      "z": 4,
      "name": "Rock_Stone"
    },
    {
      "x": 1,
      "y": 13,
      "z": 4,
      "name": "Soil_Clay_Smooth_Red"
    },
    {
      "x": 1,
      "y": 14,
      "z": 4,
      "name": "Soil_Clay_Smooth_Red"
    },
    {
      "x": 1,
      "y": 0,
      "z": 5,
      "name": "Rock_Basalt"
    },
    {
      "x": 1,
      "y": 1,
      "z": 5,
      "name": "Rock_Basalt"
    },
    {
      "x": 1,
      "y": 2,
      "z": 5,
      "name": "Rock_Basalt"
    },
    {
      "x": 1,
      "y": 3,
      "z": 5,
      "name": "Rock_Basalt"
    },
    {
      "x": 1,
      "y": 4,
      "z": 5,
      "name": "Rock_Stone"
    },
    {
      "x": 1,
      "y": 5,
      "z": 5,
      "name": "Rock_Stone"
    },
    {
      "x": 1,
      "y": 6,
      "z": 5,
      "name": "Rock_Stone"
    },
    {
      "x": 1,
      "y": 7,
      "z": 5,
      "name": "Rock_Stone"
    },
    {
      "x": 1,
      "y": 8,
      "z": 5,
      "name": "Rock_Stone"
    },
    {
      "x": 1,
      "y": 12,
      "z": 5,
      "name": "Soil_Clay_Smooth_Red"
    },
    {
      "x": 1,
      "y": 13,
      "z": 5,
      "name": "Soil_Clay_Red"
    },
    {
      "x": 1,
      "y": 0,
      "z": 6,
      "name": "Rock_Basalt"
    },
    {
      "x": 1,
      "y": 1,
      "z": 6,
      "name": "Rock_Basalt"
    },
    {
      "x": 1,
      "y": 2,
      "z": 6,
      "name": "Rock_Basalt"
    },
    {
      "x": 1,
      "y": 3,
      "z": 6,
      "name": "Rock_Basalt"
    },
    {
      "x": 1,
      "y": 4,
      "z": 6,
