{
  "version": 8,
  "blockIdVersion": 11,
  "anchorX": 0,
  "anchorY": 6,
  "anchorZ": 0,
  "blocks": [
    {
      "x": -3,
      "y": 0,
      "z": -10,
      "name": "Rock_Stone_Brick",
      "rotation": 1
    },
    {
      "x": -3,
      "y": 1,
      "z": -10,
      "name": "Rock_Stone_Brick_Decorative",
      "rotation": 1
    },
    {
      "x": -3,
      "y": 2,
      "z": -10,
      "name": "Soil_Gravel",
      "support": 15,
      "rotation": 1
    },
    {
      "x": -3,
      "y": 3,
      "z": -10,
      "name": "Soil_Gravel",
      "support": 15,
      "rotation": 1
    },
    {
      "x": -3,
      "y": 4,
      "z": -10,
      "name": "Soil_Gravel",
      "support": 15,
      "rotation": 1
    },
    {
      "x": -3,
      "y": 5,
      "z": -10,
      "name": "Soil_Gravel",
      "support": 15,
      "rotation": 1
    },
    {
      "x": -3,
      "y": 6,
      "z": -10,
      "name": "Rock_Stone_Brick_Smooth",
      "rotation": 1
    },
    {
      "x": -3,
      "y": 0,
      "z": -9,
      "name": "Rock_Stone_Brick",
      "rotation": 1
    },
    {
      "x": -3,
      "y": 1,
      "z": -9,
      "name": "Rock_Stone_Brick_Decorative",
      "rotation": 2
    },
    {
      "x": -3,
      "y": 2,
      "z": -9,
      "name": "Soil_Gravel",
      "support": 15,
      "rotation": 2
    },
    {
      "x": -3,
      "y": 3,
      "z": -9,
      "name": "Soil_Gravel",
      "support": 15,
      "rotation": 2
    },
    {
      "x": -3,
      "y": 4,
      "z": -9,
      "name": "Soil_Gravel",
      "support": 15,
      "rotation": 2
    },
    {
      "x": -3,
      "y": 5,
      "z": -9,
      "name": "Soil_Gravel",
      "support": 15,
      "rotation": 2
    },
    {
      "x": -3,
      "y": 6,
      "z": -9,
      "name": "Rock_Stone_Brick_Smooth",
      "rotation": 2
    },
    {
      "x": -3,
      "y": 0,
      "z": -8,
      "name": "Rock_Stone_Brick",
      "rotation": 1
    },
    {
      "x": -3,
      "y": 1,
      "z": -8,
      "name": "Rock_Stone_Brick_Decorative"
    },
    {
      "x": -3,
      "y": 2,
      "z": -8,
      "name": "Soil_Gravel",
      "support": 15
    },
    {
      "x": -3,
      "y": 3,
      "z": -8,
      "name": "Soil_Gravel",
      "support": 15
    },
    {
      "x": -3,
      "y": 4,
      "z": -8,
      "name": "Soil_Gravel",
      "support": 15
    },
    {
      "x": -3,
      "y": 5,
      "z": -8,
      "name": "Soil_Gravel",
      "support": 15
    },
    {
      "x": -3,
      "y": 6,
      "z": -8,
      "name": "Rock_Stone_Brick_Smooth"
    },
    {
      "x": -3,
      "y": 0,
      "z": -7,
      "name": "Rock_Stone_Brick",
      "rotation": 1
    },
    {
      "x": -3,
      "y": 1,
      "z": -7,
      "name": "Rock_Stone_Brick_Decorative"
    },
    {
      "x": -3,
      "y": 2,
      "z": -7,
      "name": "Soil_Gravel",
      "support": 15,
      "rotation": 3
    },
    {
      "x": -3,
      "y": 3,
      "z": -7,
      "name": "Soil_Gravel",
      "support": 15,
      "rotation": 3
    },
    {
      "x": -3,
      "y": 4,
      "z": -7,
      "name": "Soil_Gravel",
      "support": 15,
      "rotation": 3
    },
    {
      "x": -3,
      "y": 5,
      "z": -7,
      "name": "Soil_Gravel",
      "support": 15,
      "rotation": 3
    },
    {
      "x": -3,
      "y": 6,
      "z": -7,
      "name": "Rock_Stone_Brick_Smooth"
    },
    {
      "x": -3,
      "y": 0,
      "z": -6,
      "name": "Rock_Stone_Brick",
      "rotation": 1
    },
    {
      "x": -3,
      "y": 1,
      "z": -6,
      "name": "Rock_Stone_Brick_Decorative",
      "rotation": 3
    },
    {
      "x": -3,
      "y": 2,
      "z": -6,
      "name": "Soil_Gravel",
      "support": 15,
      "rotation": 3
    },
    {
      "x": -3,
      "y": 3,
      "z": -6,
      "name": "Soil_Gravel",
      "support": 15,
      "rotation": 3
    },
    {
      "x": -3,
      "y": 4,
      "z": -6,
      "name": "Soil_Gravel",
      "support": 15,
      "rotation": 3
    },
    {
      "x": -3,
      "y": 5,
      "z": -6,
      "name": "Soil_Gravel",
      "support": 15,
      "rotation": 3
    },
    {
      "x": -3,
      "y": 6,
      "z": -6,
      "name": "Rock_Stone_Brick_Smooth"
    },
    {
      "x": -3,
      "y": 0,
      "z": -5,
      "name": "Rock_Stone_Brick",
      "rotation": 1
    },
    {
      "x": -3,
      "y": 1,
      "z": -5,
      "name": "Rock_Stone_Brick_Decorative",
      "rotation": 3
    },
    {
      "x": -3,
      "y": 2,
      "z": -5,
      "name": "Soil_Gravel",
      "support": 15,
      "rotation": 3
    },
    {
      "x": -3,
      "y": 3,
      "z": -5,
      "name": "Soil_Gravel",
      "support": 15,
      "rotation": 3
    },
    {
      "x": -3,
      "y": 4,
      "z": -5,
      "name": "Soil_Gravel",
      "support": 15,
      "rotation": 3
    },
    {
      "x": -3,
      "y": 5,
      "z": -5,
      "name": "Soil_Gravel",
      "support": 15,
      "rotation": 3
    },
    {
      "x": -3,
      "y": 6,
      "z": -5,
      "name": "Rock_Stone_Brick_Smooth"
    },
    {
      "x": -3,
      "y": 0,
      "z": -4,
      "name": "Rock_Stone_Brick",
      "rotation": 1
    },
    {
      "x": -3,
      "y": 1,
      "z": -4,
      "name": "Rock_Stone_Brick_Decorative",
      "rotation": 3
    },
    {
      "x": -3,
      "y": 2,
      "z": -4,
      "name": "Soil_Gravel",
      "support": 15,
      "rotation": 3
    },
    {
      "x": -3,
      "y": 3,
      "z": -4,
      "name": "Soil_Gravel",
      "support": 15,
      "rotation": 3
    },
    {
      "x": -3,
      "y": 4,
      "z": -4,
      "name": "Soil_Gravel",
      "support": 15,
      "rotation": 3
    },
    {
      "x": -3,
      "y": 5,
      "z": -4,
      "name": "Soil_Gravel",
      "support": 15,
      "rotation": 3
    },
    {
      "x": -3,
      "y": 6,
      "z": -4,
      "name": "Rock_Stone_Brick_Smooth",
      "rotation": 2
    },
    {
      "x": -3,
      "y": 0,
      "z": -3,
      "name": "Rock_Stone_Brick",
      "rotation": 1
    },
    {
      "x": -3,
      "y": 1,
      "z": -3,
      "name": "Rock_Stone_Brick_Decorative",
      "rotation": 3
    },
    {
      "x": -3,
      "y": 2,
      "z": -3,
      "name": "Soil_Gravel",
      "support": 15,
      "rotation": 3
    },
    {
      "x": -3,
      "y": 3,
      "z": -3,
      "name": "Soil_Gravel",
      "support": 15,
      "rotation": 3
    },
    {
      "x": -3,
      "y": 4,
      "z": -3,
      "name": "Soil_Gravel",
      "support": 15,
      "rotation": 3
    },
    {
      "x": -3,
      "y": 5,
      "z": -3,
      "name": "Soil_Gravel",
      "support": 15,
      "rotation": 3
    },
    {
      "x": -3,
      "y": 6,
      "z": -3,
      "name": "Rock_Stone_Brick_Smooth",
      "rotation": 2
    },
    {
      "x": -3,
      "y": 0,
      "z": -2,
      "name": "Rock_Stone_Brick",
      "rotation": 1
    },
    {
      "x": -3,
      "y": 1,
      "z": -2,
      "name": "Rock_Stone_Brick_Decorative",
      "rotation": 1
    },
    {
      "x": -3,
      "y": 2,
      "z": -2,
      "name": "Soil_Gravel",
      "support": 15,
      "rotation": 1
    },
    {
      "x": -3,
      "y": 3,
      "z": -2,
      "name": "Soil_Gravel",
      "support": 15,
      "rotation": 1
    },
    {
      "x": -3,
      "y": 4,
      "z": -2,
      "name": "Soil_Gravel",
      "support": 15,
      "rotation": 1
    },
    {
      "x": -3,
      "y": 5,
      "z": -2,
      "name": "Soil_Gravel",
      "support": 15,
      "rotation": 1
    },
    {
      "x": -3,
      "y": 6,
      "z": -2,
      "name": "Rock_Stone_Brick_Smooth",
      "rotation": 1
    },
    {
      "x": -3,
      "y": 0,
      "z": -1,
      "name": "Rock_Stone_Brick",
      "rotation": 1
    },
    {
      "x": -3,
      "y": 1,
      "z": -1,
      "name": "Rock_Stone_Brick_Decorative",
      "rotation": 2
    },
    {
      "x": -3,
      "y": 2,
      "z": -1,
      "name": "Soil_Gravel",
      "support": 15,
      "rotation": 2
    },
    {
      "x": -3,
      "y": 3,
      "z": -1,
      "name": "Soil_Gravel",
      "support": 15,
      "rotation": 2
    },
    {
      "x": -3,
      "y": 4,
      "z": -1,
      "name": "Soil_Gravel",
      "support": 15,
      "rotation": 2
    },
    {
      "x": -3,
      "y": 5,
      "z": -1,
      "name": "Soil_Gravel",
      "support": 15,
      "rotation": 2
    },
    {
      "x": -3,
      "y": 6,
      "z": -1,
      "name": "Rock_Stone_Brick_Smooth",
      "rotation": 2
    },
    {
      "x": -3,
      "y": 0,
      "z": 0,
      "name": "Rock_Stone_Brick",
      "rotation": 1
    },
    {
      "x": -3,
      "y": 1,
      "z": 0,
      "name": "Rock_Stone_Brick_Decorative",
      "rotation": 2
    },
    {
      "x": -3,
      "y": 2,
      "z": 0,
      "name": "Soil_Gravel",
      "support": 15,
      "rotation": 2
    },
    {
      "x": -3,
      "y": 3,
      "z": 0,
      "name": "Soil_Gravel",
      "support": 15,
      "rotation": 2
    },
    {
      "x": -3,
      "y": 4,
      "z": 0,
      "name": "Soil_Gravel",
      "support": 15,
      "rotation": 2
    },
    {
      "x": -3,
      "y": 5,
      "z": 0,
      "name": "Soil_Gravel",
      "support": 15,
      "rotation": 2
    },
    {
      "x": -3,
      "y": 6,
      "z": 0,
      "name": "Rock_Stone_Brick_Smooth",
      "rotation": 2
    },
    {
      "x": -3,
      "y": 0,
      "z": 1,
      "name": "Rock_Stone_Brick",
      "rotation": 3
    },
    {
      "x": -3,
      "y": 1,
      "z": 1,
      "name": "Rock_Stone_Brick_Decorative",
      "rotation": 1
    },
    {
      "x": -3,
      "y": 2,
      "z": 1,
      "name": "Soil_Gravel",
      "support": 15,
      "rotation": 1
    },
    {
      "x": -3,
      "y": 3,
      "z": 1,
      "name": "Soil_Gravel",
      "support": 15,
      "rotation": 1
    },
    {
      "x": -3,
      "y": 4,
      "z": 1,
      "name": "Soil_Gravel",
      "support": 15,
      "rotation": 1
    },
    {
      "x": -3,
      "y": 5,
      "z": 1,
      "name": "Soil_Gravel",
      "support": 15,
      "rotation": 1
    },
    {
      "x": -3,
      "y": 6,
      "z": 1,
      "name": "Rock_Stone_Brick_Smooth",
      "rotation": 1
    },
    {
      "x": -3,
      "y": 0,
      "z": 2,
      "name": "Rock_Stone_Brick",
      "rotation": 3
    },
    {
      "x": -3,
      "y": 1,
      "z": 2,
      "name": "Rock_Stone_Brick_Decorative",
      "rotation": 2
    },
    {
      "x": -3,
      "y": 2,
      "z": 2,
      "name": "Soil_Gravel",
      "support": 15,
      "rotation": 2
    },
    {
      "x": -3,
      "y": 3,
      "z": 2,
      "name": "Soil_Gravel",
      "support": 15,
      "rotation": 2
    },
    {
      "x": -3,
      "y": 4,
      "z": 2,
      "name": "Soil_Gravel",
      "support": 15,
      "rotation": 2
    },
    {
      "x": -3,
      "y": 5,
      "z": 2,
      "name": "Soil_Gravel",
      "support": 15,
      "rotation": 2
    },
    {
      "x": -3,
      "y": 6,
      "z": 2,
      "name": "Rock_Stone_Brick_Smooth",
      "rotation": 2
    },
    {
      "x": -3,
      "y": 0,
      "z": 3,
      "name": "Rock_Stone_Brick",
      "rotation": 3
    },
    {
      "x": -3,
      "y": 1,
      "z": 3,
      "name": "Rock_Stone_Brick_Decorative"
    },
    {
      "x": -3,
      "y": 2,
      "z": 3,
      "name": "Soil_Gravel",
      "support": 15
    },
    {
      "x": -3,
      "y": 3,
      "z": 3,
      "name": "Soil_Gravel",
      "support": 15
    },
    {
      "x": -3,
      "y": 4,
      "z": 3,
      "name": "Soil_Gravel",
      "support": 15
    },
    {
      "x": -3,
      "y": 5,
      "z": 3,
      "name": "Soil_Gravel",
      "support": 15
    },
    {
      "x": -3,
      "y": 6,
      "z": 3,
      "name": "Rock_Stone_Brick_Smooth"
    },
    {
      "x": -3,
      "y": 0,
      "z": 4,
      "name": "Rock_Stone_Brick",
      "rotation": 3
    },
    {
      "x": -3,
      "y": 1,
      "z": 4,
      "name": "Rock_Stone_Brick_Decorative"
    },
    {
      "x": -3,
      "y": 2,
      "z": 4,
      "name": "Soil_Gravel",
      "support": 15,
      "rotation": 3
    },
    {
      "x": -3,
      "y": 3,
      "z": 4,
      "name": "Soil_Gravel",
      "support": 15,
      "rotation": 3
    },
    {
      "x": -3,
      "y": 4,
      "z": 4,
      "name": "Soil_Gravel",
      "support": 15,
      "rotation": 3
    },
    {
      "x": -3,
      "y": 5,
      "z": 4,
      "name": "Soil_Gravel",
      "support": 15,
      "rotation": 3
    },
    {
      "x": -3,
      "y": 6,
      "z": 4,
      "name": "Rock_Stone_Brick_Smooth"
    },
    {
      "x": -3,
      "y": 0,
      "z": 5,
      "name": "Rock_Stone_Brick",
      "rotation": 3
    },
    {
      "x": -3,
      "y": 1,
      "z": 5,
      "name": "Rock_Stone_Brick_Decorative",
      "rotation": 3
    },
    {
      "x": -3,
      "y": 2,
      "z": 5,
      "name": "Soil_Gravel",
      "support": 15,
      "rotation": 3
    },
    {
      "x": -3,
      "y": 3,
      "z": 5,
      "name": "Soil_Gravel",
      "support": 15,
      "rotation": 3
    },
    {
      "x": -3,
      "y": 4,
      "z": 5,
      "name": "Soil_Gravel",
      "support": 15,
      "rotation": 3
    },
    {
      "x": -3,
      "y": 5,
      "z": 5,
      "name": "Soil_Gravel",
      "support": 15,
      "rotation": 3
    },
    {
      "x": -3,
      "y": 6,
      "z": 5,
      "name": "Rock_Stone_Brick_Smooth"
    },
    {
      "x": -3,
      "y": 0,
      "z": 6,
      "name": "Rock_Stone_Brick",
      "rotation": 3
    },
    {
      "x": -3,
      "y": 1,
      "z": 6,
      "name": "Rock_Stone_Brick_Decorative",
      "rotation": 3
    },
    {
      "x": -3,
      "y": 2,
      "z": 6,
      "name": "Soil_Gravel",
      "support": 15,
      "rotation": 3
    },
    {
      "x": -3,
      "y": 3,
      "z": 6,
      "name": "Soil_Gravel",
      "support": 15,
      "rotation": 3
    },
    {
      "x": -3,
      "y": 4,
      "z": 6,
      "name": "Soil_Gravel",
      "support": 15,
      "rotation": 3
    },
    {
      "x": -3,
      "y": 5,
      "z": 6,
      "name": "Soil_Gravel",
      "support": 15,
      "rotation": 3
    },
    {
      "x": -3,
      "y": 6,
      "z": 6,
      "name": "Rock_Stone_Brick_Smooth"
    },
    {
      "x": -3,
      "y": 0,
      "z": 7,
      "name": "Rock_Stone_Brick",
      "rotation": 3
    },
    {
      "x": -3,
      "y": 1,
      "z": 7,
      "name": "Rock_Stone_Brick_Decorative",
      "rotation": 3
    },
    {
      "x": -3,
      "y": 2,
      "z": 7,
      "name": "Soil_Gravel",
      "support": 15,
      "rotation": 3
    },
    {
      "x": -3,
      "y": 3,
      "z": 7,
      "name": "Soil_Gravel",
      "support": 15,
      "rotation": 3
    },
    {
      "x": -3,
      "y": 4,
      "z": 7,
      "name": "Soil_Gravel",
      "support": 15,
      "rotation": 3
    },
    {
      "x": -3,
      "y": 5,
      "z": 7,
      "name": "Soil_Gravel",
      "support": 15,
      "rotation": 3
    },
    {
      "x": -3,
      "y": 6,
      "z": 7,
      "name": "Rock_Stone_Brick_Smooth",
      "rotation": 2
    },
    {
      "x": -3,
      "y": 0,
      "z": 8,
      "name": "Rock_Stone_Brick",
      "rotation": 3
    },
    {
      "x": -3,
      "y": 1,
      "z": 8,
      "name": "Rock_Stone_Brick_Decorative",
      "rotation": 3
    },
    {
      "x": -3,
      "y": 2,
      "z": 8,
      "name": "Soil_Gravel",
      "support": 15,
      "rotation": 3
    },
    {
      "x": -3,
      "y": 3,
      "z": 8,
      "name": "Soil_Gravel",
      "support": 15,
      "rotation": 3
    },
    {
      "x": -3,
      "y": 4,
      "z": 8,
      "name": "Soil_Gravel",
      "support": 15,
      "rotation": 3
    },
    {
      "x": -3,
      "y": 5,
      "z": 8,
      "name": "Soil_Gravel",
      "support": 15,
      "rotation": 3
    },
    {
      "x": -3,
      "y": 6,
      "z": 8,
      "name": "Rock_Stone_Brick_Smooth",
      "rotation": 2
    },
    {
      "x": -3,
      "y": 0,
      "z": 9,
      "name": "Rock_Stone_Brick",
      "rotation": 3
    },
    {
      "x": -3,
      "y": 1,
      "z": 9,
      "name": "Rock_Stone_Brick_Decorative",
      "rotation": 1
    },
    {
      "x": -3,
      "y": 2,
      "z": 9,
      "name": "Soil_Gravel",
      "support": 15,
      "rotation": 1
    },
    {
      "x": -3,
      "y": 3,
      "z": 9,
      "name": "Soil_Gravel",
      "support": 15,
      "rotation": 1
    },
    {
      "x": -3,
      "y": 4,
      "z": 9,
      "name": "Soil_Gravel",
      "support": 15,
      "rotation": 1
    },
    {
      "x": -3,
      "y": 5,
      "z": 9,
      "name": "Soil_Gravel",
      "support": 15,
      "rotation": 1
    },
    {
      "x": -3,
      "y": 6,
      "z": 9,
      "name": "Rock_Stone_Brick_Smooth",
      "rotation": 1
    },
    {
      "x": -3,
      "y": 0,
      "z": 10,
      "name": "Rock_Stone_Brick",
      "rotation": 3
    },
    {
      "x": -3,
      "y": 1,
      "z": 10,
      "name": "Rock_Stone_Brick_Decorative",
      "rotation": 2
    },
    {
      "x": -3,
      "y": 2,
      "z": 10,
      "name": "Soil_Gravel",
      "support": 15,
      "rotation": 2
    },
    {
      "x": -3,
      "y": 3,
      "z": 10,
      "name": "Soil_Gravel",
      "support": 15,
      "rotation": 2
    },
    {
      "x": -3,
      "y": 4,
      "z": 10,
      "name": "Soil_Gravel",
      "support": 15,
      "rotation": 2
    },
    {
      "x": -3,
      "y": 5,
      "z": 10,
      "name": "Soil_Gravel",
      "support": 15,
      "rotation": 2
    },
    {
      "x": -3,
      "y": 6,
      "z": 10,
      "name": "Rock_Stone_Brick_Smooth",
      "rotation": 2
    },
    {
      "x": -3,
      "y": 0,
      "z": 11,
      "name": "Rock_Stone_Brick",
      "rotation": 3
    },
    {
      "x": -3,
      "y": 1,
      "z": 11,
      "name": "Rock_Stone_Brick_Decorative",
      "rotation": 2
    },
    {
      "x": -3,
      "y": 2,
      "z": 11,
      "name": "Soil_Gravel",
      "support": 15,
      "rotation": 2
    },
    {
      "x": -3,
      "y": 3,
      "z": 11,
      "name": "Soil_Gravel",
      "support": 15,
      "rotation": 2
    },
    {
      "x": -3,
      "y": 4,
      "z": 11,
      "name": "Soil_Gravel",
      "support": 15,
      "rotation": 2
    },
    {
      "x": -3,
      "y": 5,
      "z": 11,
      "name": "Soil_Gravel",
      "support": 15,
      "rotation": 2
    },
    {
      "x": -3,
      "y": 6,
      "z": 11,
      "name": "Rock_Stone_Brick_Smooth",
      "rotation": 2
    },
    {
      "x": -2,
      "y": 0,
      "z": -10,
      "name": "Rock_Stone_Brick"
    },
    {
      "x": -2,
      "y": 1,
      "z": -10,
      "name": "Rock_Stone_Brick"
    },
    {
      "x": -2,
      "y": 2,
      "z": -10,
      "name": "Rock_Stone_Brick"
    },
    {
      "x": -2,
      "y": 3,
      "z": -10,
      "name": "Rock_Stone_Brick"
    },
    {
      "x": -2,
      "y": 4,
      "z": -10,
      "name": "Rock_Stone_Brick"
    },
    {
      "x": -2,
      "y": 5,
      "z": -10,
      "name": "Rock_Stone_Brick_Decorative"
    },
    {
      "x": -2,
      "y": 6,
      "z": -10,
      "name": "Rock_Stone_Brick",
      "rotation": 1
    },
    {
      "x": -2,
      "y": 0,
      "z": -9,
      "name": "Rock_Stone_Brick",
      "rotation": 2
    },
    {
      "x": -2,
      "y": 1,
      "z": -9,
      "name": "Rock_Stone_Brick_Decorative"
    },
    {
      "x": -2,
      "y": 2,
      "z": -9,
      "name": "Soil_Gravel_Half",
      "support": 15,
      "rotation": 5
    },
    {
      "x": -2,
      "y": 3,
      "z": -9,
      "name": "Soil_Gravel_Half",
      "support": 15,
      "rotation": 5
    },
    {
      "x": -2,
      "y": 4,
      "z": -9,
      "name": "Soil_Gravel_Half",
      "support": 15,
      "rotation": 5
    },
    {
      "x": -2,
      "y": 5,
      "z": -9,
      "name": "Soil_Gravel_Half",
      "support": 15,
      "rotation": 5
    },
    {
      "x": -2,
      "y": 6,
      "z": -9,
      "name": "Rock_Stone_Brick",
      "rotation": 3
    },
    {
      "x": -2,
      "y": 0,
      "z": -8,
      "name": "Rock_Stone_Brick",
      "rotation": 2
    },
    {
      "x": -2,
      "y": 1,
      "z": -8,
      "name": "Rock_Stone_Brick_Decorative",
      "rotation": 1
    },
    {
      "x": -2,
      "y": 2,
      "z": -8,
      "name": "Soil_Gravel_Half",
      "support": 15,
      "rotation": 5
    },
    {
      "x": -2,
      "y": 3,
      "z": -8,
      "name": "Soil_Gravel_Half",
      "support": 15,
      "rotation": 5
    },
    {
      "x": -2,
      "y": 4,
      "z": -8,
      "name": "Soil_Gravel_Half",
      "support": 15,
      "rotation": 5
    },
    {
      "x": -2,
      "y": 5,
      "z": -8,
      "name": "Soil_Gravel_Half",
      "support": 15,
      "rotation": 5
    },
    {
      "x": -2,
      "y": 6,
      "z": -8,
      "name": "Rock_Stone_Brick",
      "rotation": 3
    },
    {
      "x": -2,
      "y": 0,
      "z": -7,
      "name": "Rock_Stone_Brick",
      "rotation": 1
    },
    {
      "x": -2,
      "y": 1,
      "z": -7,
      "name": "Rock_Stone_Brick_Decorative",
      "rotation": 1
    },
    {
      "x": -2,
      "y": 2,
      "z": -7,
      "name": "Soil_Gravel_Half",
      "support": 15,
      "rotation": 5
    },
    {
      "x": -2,
      "y": 3,
      "z": -7,
      "name": "Soil_Gravel_Half",
      "support": 15,
      "rotation": 5
    },
    {
      "x": -2,
      "y": 4,
      "z": -7,
      "name": "Soil_Gravel_Half",
      "support": 15,
      "rotation": 5
    },
    {
      "x": -2,
      "y": 5,
      "z": -7,
      "name": "Soil_Gravel_Half",
      "support": 15,
      "rotation": 5
    },
    {
      "x": -2,
      "y": 6,
      "z": -7,
      "name": "Rock_Stone_Brick",
      "rotation": 3
    },
    {
      "x": -2,
      "y": 0,
      "z": -6,
      "name": "Rock_Stone_Brick_Smooth",
      "rotation": 1
    },
    {
      "x": -2,
      "y": 1,
      "z": -6,
      "name": "Rock_Stone_Brick_Decorative",
      "rotation": 3
    },
    {
      "x": -2,
      "y": 2,
      "z": -6,
      "name": "Rock_Stone_Brick_Pillar_Base",
      "rotation": 1
    },
    {
      "x": -2,
      "y": 3,
      "z": -6,
      "name": "Rock_Stone_Brick_Pillar_Middle",
      "rotation": 1
    },
    {
      "x": -2,
      "y": 4,
      "z": -6,
      "name": "Rock_Stone_Brick_Pillar_Middle",
      "rotation": 1
    },
    {
      "x": -2,
      "y": 5,
      "z": -6,
      "name": "Rock_Stone_Brick_Pillar_Base",
      "rotation": 35
    },
    {
      "x": -2,
      "y": 6,
      "z": -6,
      "name": "Rock_Stone_Brick",
      "rotation": 3
    },
    {
      "x": -2,
      "y": 0,
      "z": -5,
      "name": "Rock_Stone_Brick_Smooth",
      "rotation": 1
    },
    {
      "x": -2,
      "y": 1,
      "z": -5,
      "name": "Rock_Stone_Brick_Decorative",
      "rotation": 3
    },
    {
      "x": -2,
      "y": 2,
      "z": -5,
      "name": "Soil_Gravel_Half",
      "support": 15,
      "rotation": 5
    },
    {
      "x": -2,
      "y": 3,
      "z": -5,
      "name": "Soil_Gravel_Half",
      "support": 15,
      "rotation": 5
    },
    {
      "x": -2,
      "y": 4,
      "z": -5,
      "name": "Soil_Gravel_Half",
      "support": 15,
      "rotation": 5
    },
    {
      "x": -2,
      "y": 5,
      "z": -5,
      "name": "Soil_Gravel_Half",
      "support": 15,
      "rotation": 5
    },
    {
      "x": -2,
      "y": 6,
      "z": -5,
      "name": "Rock_Stone_Brick",
      "rotation": 3
    },
    {
      "x": -2,
      "y": 0,
      "z": -4,
      "name": "Rock_Stone_Brick_Smooth",
      "rotation": 1
    },
    {
      "x": -2,
      "y": 1,
      "z": -4,
      "name": "Rock_Stone_Brick_Decorative",
      "rotation": 3
    },
    {
      "x": -2,
      "y": 2,
      "z": -4,
      "name": "Soil_Gravel_Half",
      "support": 15,
      "rotation": 5
    },
    {
      "x": -2,
      "y": 3,
      "z": -4,
      "name": "Soil_Gravel_Half",
      "support": 15,
      "rotation": 5
    },
    {
      "x": -2,
      "y": 4,
      "z": -4,
      "name": "Soil_Gravel_Half",
      "support": 15,
      "rotation": 5
    },
    {
      "x": -2,
      "y": 5,
      "z": -4,
      "name": "Soil_Gravel_Half",
      "support": 15,
      "rotation": 5
    },
    {
      "x": -2,
      "y": 6,
      "z": -4,
      "name": "Rock_Stone_Brick",
      "rotation": 3
    },
    {
      "x": -2,
      "y": 0,
      "z": -3,
      "name": "Rock_Stone_Brick",
      "rotation": 2
    },
    {
      "x": -2,
      "y": 1,
      "z": -3,
      "name": "Rock_Stone_Brick_Decorative",
      "rotation": 2
    },
    {
      "x": -2,
      "y": 2,
      "z": -3,
      "name": "Soil_Gravel_Half",
      "support": 15,
      "rotation": 5
    },
    {
      "x": -2,
      "y": 3,
      "z": -3,
      "name": "Soil_Gravel_Half",
      "support": 15,
      "rotation": 5
    },
    {
      "x": -2,
      "y": 4,
      "z": -3,
      "name": "Soil_Gravel_Half",
      "support": 15,
      "rotation": 5
    },
    {
      "x": -2,
      "y": 5,
      "z": -3,
      "name": "Soil_Gravel_Half",
      "support": 15,
      "rotation": 5
    },
    {
      "x": -2,
      "y": 6,
      "z": -3,
      "name": "Rock_Stone_Brick",
      "rotation": 3
    },
    {
      "x": -2,
      "y": 0,
      "z": -2,
      "name": "Rock_Stone_Brick",
      "rotation": 1
    },
    {
      "x": -2,
      "y": 1,
      "z": -2,
      "name": "Rock_Stone_Brick_Decorative",
      "rotation": 1
    },
    {
      "x": -2,
      "y": 2,
      "z": -2,
      "name": "Rock_Stone_Brick_Pillar_Base",
      "rotation": 2
    },
    {
      "x": -2,
      "y": 3,
      "z": -2,
      "name": "Rock_Stone_Brick_Pillar_Middle",
      "rotation": 2
    },
    {
      "x": -2,
      "y": 4,
      "z": -2,
      "name": "Rock_Stone_Brick_Pillar_Middle",
      "rotation": 2
    },
    {
      "x": -2,
      "y": 5,
      "z": -2,
      "name": "Rock_Stone_Brick_Pillar_Base",
      "rotation": 32
    },
    {
      "x": -2,
      "y": 6,
      "z": -2,
      "name": "Rock_Stone_Brick",
      "rotation": 3
    },
    {
      "x": -2,
      "y": 0,
      "z": -1,
      "name": "Rock_Stone_Brick",
      "rotation": 2
    },
    {
      "x": -2,
      "y": 1,
      "z": -1,
      "name": "Rock_Stone_Brick_Decorative",
      "rotation": 2
    },
    {
      "x": -2,
      "y": 2,
      "z": -1,
      "name": "Soil_Gravel_Half",
      "support": 15,
      "rotation": 5
    },
    {
      "x": -2,
      "y": 3,
      "z": -1,
      "name": "Soil_Gravel_Half",
      "support": 15,
      "rotation": 5
    },
    {
      "x": -2,
      "y": 4,
      "z": -1,
      "name": "Soil_Gravel_Half",
      "support": 15,
      "rotation": 5
    },
    {
      "x": -2,
      "y": 5,
      "z": -1,
      "name": "Soil_Gravel_Half",
      "support": 15,
      "rotation": 5
    },
    {
      "x": -2,
      "y": 6,
      "z": -1,
      "name": "Rock_Stone_Brick",
      "rotation": 3
    },
    {
      "x": -2,
      "y": 0,
      "z": 0,
      "name": "Rock_Stone_Brick",
      "rotation": 2
    },
    {
      "x": -2,
      "y": 1,
      "z": 0,
      "name": "Rock_Stone_Brick_Decorative",
      "rotation": 2
    },
    {
      "x": -2,
      "y": 2,
      "z": 0,
      "name": "Soil_Gravel_Half",
      "support": 15,
      "rotation": 5
    },
    {
      "x": -2,
      "y": 3,
      "z": 0,
      "name": "Soil_Gravel_Half",
      "support": 15,
      "rotation": 5
    },
    {
      "x": -2,
      "y": 4,
      "z": 0,
      "name": "Soil_Gravel_Half",
      "support": 15,
      "rotation": 5
    },
    {
      "x": -2,
      "y": 5,
      "z": 0,
      "name": "Soil_Gravel_Half",
      "support": 15,
      "rotation": 5
    },
    {
      "x": -2,
      "y": 6,
      "z": 0,
      "name": "Rock_Stone_Brick",
      "rotation": 1
    },
    {
      "x": -2,
      "y": 0,
      "z": 1,
      "name": "Rock_Stone_Brick_Smooth"
    },
    {
      "x": -2,
      "y": 1,
      "z": 1,
      "name": "Rock_Stone_Brick_Decorative"
    },
    {
      "x": -2,
      "y": 2,
      "z": 1,
      "name": "Soil_Gravel_Half",
      "support": 15,
      "rotation": 5
    },
    {
      "x": -2,
      "y": 3,
      "z": 1,
      "name": "Soil_Gravel_Half",
      "support": 15,
      "rotation": 5
    },
    {
      "x": -2,
      "y": 4,
      "z": 1,
      "name": "Soil_Gravel_Half",
      "support": 15,
      "rotation": 5
    },
    {
      "x": -2,
      "y": 5,
      "z": 1,
      "name": "Soil_Gravel_Half",
      "support": 15,
      "rotation": 5
    },
    {
      "x": -2,
      "y": 6,
      "z": 1,
      "name": "Rock_Stone_Brick",
      "rotation": 3
    },
    {
      "x": -2,
      "y": 0,
      "z": 2,
      "name": "Rock_Stone_Brick",
      "rotation": 2
    },
    {
      "x": -2,
      "y": 1,
      "z": 2,
      "name": "Rock_Stone_Brick_Decorative"
    },
    {
      "x": -2,
      "y": 2,
      "z": 2,
      "name": "Soil_Gravel_Half",
      "support": 15,
      "rotation": 5
    },
    {
      "x": -2,
      "y": 3,
      "z": 2,
      "name": "Soil_Gravel_Half",
      "support": 15,
      "rotation": 5
    },
    {
      "x": -2,
      "y": 4,
      "z": 2,
      "name": "Soil_Gravel_Half",
      "support": 15,
      "rotation": 5
    },
    {
      "x": -2,
      "y": 5,
      "z": 2,
      "name": "Soil_Gravel_Half",
      "support": 15,
      "rotation": 5
    },
    {
      "x": -2,
      "y": 6,
      "z": 2,
      "name": "Rock_Stone_Brick",
      "rotation": 3
    },
    {
      "x": -2,
      "y": 0,
      "z": 3,
      "name": "Rock_Stone_Brick",
      "rotation": 2
    },
    {
      "x": -2,
      "y": 1,
      "z": 3,
      "name": "Rock_Stone_Brick_Decorative",
      "rotation": 1
    },
    {
      "x": -2,
      "y": 2,
      "z": 3,
      "name": "Rock_Stone_Brick_Pillar_Base",
      "rotation": 1
    },
    {
      "x": -2,
      "y": 3,
      "z": 3,
      "name": "Rock_Stone_Brick_Pillar_Middle",
      "rotation": 1
    },
    {
      "x": -2,
      "y": 4,
      "z": 3,
      "name": "Rock_Stone_Brick_Pillar_Middle",
      "rotation": 1
    },
    {
      "x": -2,
      "y": 5,
      "z": 3,
      "name": "Rock_Stone_Brick_Pillar_Base",
      "rotation": 35
    },
    {
      "x": -2,
      "y": 6,
      "z": 3,
      "name": "Rock_Stone_Brick",
      "rotation": 3
    },
    {
      "x": -2,
      "y": 0,
      "z": 4,
      "name": "Rock_Stone_Brick",
      "rotation": 1
    },
    {
      "x": -2,
      "y": 1,
      "z": 4,
      "name": "Rock_Stone_Brick_Decorative",
      "rotation": 1
    },
    {
      "x": -2,
      "y": 2,
      "z": 4,
      "name": "Soil_Gravel_Half",
      "support": 15,
      "rotation": 5
    },
    {
      "x": -2,
      "y": 3,
      "z": 4,
      "name": "Soil_Gravel_Half",
      "support": 15,
      "rotation": 5
    },
    {
      "x": -2,
      "y": 4,
      "z": 4,
      "name": "Soil_Gravel_Half",
      "support": 15,
      "rotation": 5
    },
    {
      "x": -2,
      "y": 5,
      "z": 4,
      "name": "Soil_Gravel_Half",
      "support": 15,
      "rotation": 5
    },
    {
      "x": -2,
      "y": 6,
      "z": 4,
      "name": "Rock_Stone_Brick",
      "rotation": 3
    },
    {
      "x": -2,
      "y": 0,
      "z": 5,
      "name": "Rock_Stone_Brick_Smooth",
      "rotation": 1
    },
    {
      "x": -2,
      "y": 1,
      "z": 5,
      "name": "Rock_Stone_Brick_Decorative",
      "rotation": 3
    },
    {
      "x": -2,
      "y": 2,
      "z": 5,
      "name": "Soil_Gravel_Half",
      "support": 15,
      "rotation": 5
    },
    {
      "x": -2,
      "y": 3,
      "z": 5,
      "name": "Soil_Gravel_Half",
      "support": 15,
      "rotation": 5
    },
    {
      "x": -2,
      "y": 4,
      "z": 5,
      "name": "Soil_Gravel_Half",
      "support": 15,
      "rotation": 5
    },
    {
      "x": -2,
      "y": 5,
      "z": 5,
      "name": "Soil_Gravel_Half",
      "support": 15,
      "rotation": 5
    },
    {
      "x": -2,
      "y": 6,
      "z": 5,
      "name": "Rock_Stone_Brick",
      "rotation": 3
    },
    {
      "x": -2,
      "y": 0,
      "z": 6,
      "name": "Rock_Stone_Brick_Smooth",
      "rotation": 1
    },
    {
      "x": -2,
      "y": 1,
      "z": 6,
      "name": "Rock_Stone_Brick_Decorative",
      "rotation": 3
    },
    {
      "x": -2,
      "y": 2,
      "z": 6,
      "name": "Soil_Gravel_Half",
      "support": 15,
      "rotation": 5
    },
    {
      "x": -2,
      "y": 3,
      "z": 6,
      "name": "Soil_Gravel_Half",
      "support": 15,
      "rotation": 5
    },
    {
      "x": -2,
      "y": 4,
      "z": 6,
      "name": "Soil_Gravel_Half",
      "support": 15,
      "rotation": 5
    },
    {
      "x": -2,
      "y": 5,
      "z": 6,
      "name": "Soil_Gravel_Half",
      "support": 15,
      "rotation": 5
    },
    {
      "x": -2,
      "y": 6,
      "z": 6,
      "name": "Rock_Stone_Brick",
      "rotation": 3
    },
    {
      "x": -2,
      "y": 0,
      "z": 7,
      "name": "Rock_Stone_Brick_Smooth",
      "rotation": 1
    },
    {
      "x": -2,
      "y": 1,
      "z": 7,
      "name": "Rock_Stone_Brick_Decorative",
      "rotation": 3
    },
    {
      "x": -2,
      "y": 2,
      "z": 7,
      "name": "Rock_Stone_Brick_Pillar_Base",
      "rotation": 2
    },
    {
      "x": -2,
      "y": 3,
      "z": 7,
      "name": "Rock_Stone_Brick_Pillar_Middle",
      "rotation": 2
    },
    {
      "x": -2,
      "y": 4,
      "z": 7,
      "name": "Rock_Stone_Brick_Pillar_Middle",
      "rotation": 2
    },
    {
      "x": -2,
      "y": 5,
      "z": 7,
      "name": "Rock_Stone_Brick_Pillar_Base",
      "rotation": 32
    },
    {
      "x": -2,
      "y": 6,
      "z": 7,
      "name": "Rock_Stone_Brick",
      "rotation": 3
    },
    {
      "x": -2,
      "y": 0,
      "z": 8,
      "name": "Rock_Stone_Brick",
      "rotation": 2
    },
    {
      "x": -2,
      "y": 1,
      "z": 8,
      "name": "Rock_Stone_Brick_Decorative",
      "rotation": 2
    },
    {
      "x": -2,
      "y": 2,
      "z": 8,
      "name": "Soil_Gravel_Half",
      "support": 15,
      "rotation": 5
    },
    {
      "x": -2,
      "y": 3,
      "z": 8,
      "name": "Soil_Gravel_Half",
      "support": 15,
      "rotation": 5
    },
    {
      "x": -2,
      "y": 4,
      "z": 8,
      "name": "Soil_Gravel_Half",
      "support": 15,
      "rotation": 5
    },
    {
      "x": -2,
      "y": 5,
      "z": 8,
      "name": "Soil_Gravel_Half",
      "support": 15,
      "rotation": 5
    },
    {
      "x": -2,
      "y": 6,
      "z": 8,
      "name": "Rock_Stone_Brick",
      "rotation": 3
    },
    {
      "x": -2,
      "y": 0,
      "z": 9,
      "name": "Rock_Stone_Brick",
      "rotation": 1
    },
    {
      "x": -2,
      "y": 1,
      "z": 9,
      "name": "Rock_Stone_Brick_Decorative",
      "rotation": 1
    },
    {
      "x": -2,
      "y": 2,
      "z": 9,
      "name": "Soil_Gravel_Half",
      "support": 15,
      "rotation": 5
    },
    {
      "x": -2,
      "y": 3,
      "z": 9,
      "name": "Soil_Gravel_Half",
      "support": 15,
      "rotation": 5
    },
    {
      "x": -2,
      "y": 4,
      "z": 9,
      "name": "Soil_Gravel_Half",
      "support": 15,
      "rotation": 5
    },
    {
      "x": -2,
      "y": 5,
      "z": 9,
      "name": "Soil_Gravel_Half",
      "support": 15,
      "rotation": 5
    },
    {
      "x": -2,
      "y": 6,
      "z": 9,
      "name": "Rock_Stone_Brick",
      "rotation": 3
    },
    {
      "x": -2,
      "y": 0,
      "z": 10,
      "name": "Rock_Stone_Brick",
      "rotation": 2
    },
    {
      "x": -2,
      "y": 1,
      "z": 10,
      "name": "Rock_Stone_Brick_Decorative",
      "rotation": 2
    },
    {
      "x": -2,
      "y": 2,
      "z": 10,
      "name": "Soil_Gravel_Half",
      "support": 15,
      "rotation": 5
    },
    {
      "x": -2,
      "y": 3,
      "z": 10,
      "name": "Soil_Gravel_Half",
      "support": 15,
      "rotation": 5
    },
    {
      "x": -2,
      "y": 4,
      "z": 10,
      "name": "Soil_Gravel_Half",
      "support": 15,
      "rotation": 5
    },
    {
      "x": -2,
      "y": 5,
      "z": 10,
      "name": "Soil_Gravel_Half",
      "support": 15,
      "rotation": 5
    },
    {
      "x": -2,
      "y": 6,
      "z": 10,
      "name": "Rock_Stone_Brick",
      "rotation": 3
    },
    {
      "x": -2,
      "y": 0,
      "z": 11,
      "name": "Rock_Stone_Brick",
      "rotation": 2
    },
    {
      "x": -2,
      "y": 1,
      "z": 11,
      "name": "Rock_Stone_Brick_Decorative",
      "rotation": 2
    },
    {
      "x": -2,
      "y": 2,
      "z": 11,
      "name": "Rock_Stone_Brick",
      "rotation": 3
    },
    {
      "x": -2,
      "y": 3,
      "z": 11,
      "name": "Rock_Stone_Brick",
      "rotation": 3
    },
    {
      "x": -2,
      "y": 4,
      "z": 11,
      "name": "Rock_Stone_Brick",
      "rotation": 3
    },
    {
      "x": -2,
      "y": 5,
      "z": 11,
      "name": "Rock_Stone_Brick_Decorative",
      "rotation": 3
    },
    {
      "x": -2,
      "y": 6,
      "z": 11,
      "name": "Rock_Stone_Brick",
      "rotation": 3
    },
    {
      "x": -1,
      "y": 0,
      "z": -10,
      "name": "Rock_Stone_Brick_Smooth"
    },
    {
      "x": -1,
      "y": 1,
      "z": -10,
      "name": "Rock_Stone_Brick_Smooth_Half",
      "rotation": 5
    },
    {
      "x": -1,
      "y": 2,
      "z": -10,
      "name": "Rock_Stone_Brick_Smooth_Half",
      "rotation": 5
    },
    {
      "x": -1,
      "y": 3,
      "z": -10,
      "name": "Rock_Stone_Brick_Smooth_Half",
      "rotation": 5
    },
    {
      "x": -1,
      "y": 4,
      "z": -10,
      "name": "*Rock_Stone_Brick_Stairs_State_Definitions_Inverted_Corner_Left",
      "rotation": 33
    },
    {
      "x": -1,
      "y": 5,
      "z": -10,
      "name": "Rock_Stone_Brick_Decorative"
    },
    {
      "x": -1,
      "y": 6,
      "z": -10,
      "name": "Rock_Stone_Brick_Smooth"
    },
    {
      "x": -1,
      "y": 0,
      "z": -9,
      "name": "Rock_Stone_Brick_Smooth"
    },
    {
      "x": -1,
      "y": 1,
      "z": -9,
      "name": "Empty"
    },
    {
      "x": -1,
      "y": 2,
      "z": -9,
      "name": "Empty"
    },
    {
      "x": -1,
      "y": 3,
      "z": -9,
      "name": "Empty"
    },
    {
      "x": -1,
      "y": 4,
      "z": -9,
      "name": "Empty"
    },
    {
      "x": -1,
      "y": 5,
      "z": -9,
      "name": "Empty"
    },
    {
      "x": -1,
      "y": 6,
      "z": -9,
      "name": "Rock_Stone_Brick_Smooth"
    },
    {
      "x": -1,
      "y": 0,
      "z": -8,
      "name": "Rock_Stone_Brick_Smooth"
    },
    {
      "x": -1,
      "y": 1,
      "z": -8,
      "name": "Empty"
    },
    {
      "x": -1,
      "y": 2,
      "z": -8,
      "name": "Empty"
    },
    {
      "x": -1,
      "y": 3,
      "z": -8,
      "name": "Empty"
    },
    {
      "x": -1,
      "y": 4,
      "z": -8,
      "name": "Empty"
    },
    {
      "x": -1,
      "y": 5,
      "z": -8,
      "name": "Empty"
    },
    {
      "x": -1,
      "y": 6,
      "z": -8,
      "name": "Rock_Stone_Brick_Smooth",
      "rotation": 1
    },
    {
      "x": -1,
      "y": 0,
      "z": -7,
      "name": "Rock_Stone_Brick_Smooth"
    },
    {
      "x": -1,
      "y": 1,
      "z": -7,
      "name": "Empty"
    },
    {
      "x": -1,
      "y": 2,
      "z": -7,
      "name": "Empty"
    },
    {
      "x": -1,
      "y": 3,
      "z": -7,
      "name": "Empty"
    },
    {
      "x": -1,
      "y": 4,
      "z": -7,
      "name": "Empty"
    },
    {
      "x": -1,
      "y": 5,
      "z": -7,
      "name": "Empty"
    },
    {
      "x": -1,
      "y": 6,
      "z": -7,
      "name": "Rock_Stone_Brick_Smooth",
      "rotation": 1
    },
    {
      "x": -1,
      "y": 0,
      "z": -6,
      "name": "Rock_Stone_Brick_Smooth",
      "rotation": 1
    },
    {
      "x": -1,
      "y": 1,
      "z": -6,
      "name": "Empty"
    },
    {
      "x": -1,
      "y": 2,
      "z": -6,
      "name": "Empty"
    },
    {
      "x": -1,
      "y": 3,
      "z": -6,
      "name": "Empty"
    },
    {
      "x": -1,
      "y": 4,
      "z": -6,
      "name": "Empty"
    },
    {
      "x": -1,
      "y": 5,
      "z": -6,
      "name": "Empty"
    },
    {
      "x": -1,
      "y": 6,
      "z": -6,
      "name": "Rock_Stone_Brick_Smooth",
      "rotation": 1
    },
    {
      "x": -1,
      "y": 0,
      "z": -5,
      "name": "Rock_Stone_Brick_Smooth",
      "rotation": 1
    },
    {
      "x": -1,
      "y": 1,
      "z": -5,
      "name": "Empty"
    },
    {
      "x": -1,
      "y": 2,
      "z": -5,
      "name": "Empty"
    },
    {
      "x": -1,
      "y": 3,
      "z": -5,
      "name": "Empty"
    },
    {
      "x": -1,
      "y": 4,
      "z": -5,
      "name": "Empty"
    },
    {
      "x": -1,
      "y": 5,
      "z": -5,
      "name": "Empty"
    },
    {
      "x": -1,
      "y": 6,
      "z": -5,
      "name": "Rock_Stone_Brick_Smooth",
      "rotation": 1
    },
    {
      "x": -1,
      "y": 0,
      "z": -4,
      "name": "Rock_Stone_Brick_Smooth",
      "rotation": 2
    },
    {
      "x": -1,
      "y": 1,
      "z": -4,
      "name": "Empty"
    },
    {
      "x": -1,
      "y": 2,
      "z": -4,
      "name": "Empty"
    },
    {
      "x": -1,
      "y": 3,
      "z": -4,
      "name": "Empty"
    },
    {
      "x": -1,
      "y": 4,
      "z": -4,
      "name": "Empty"
    },
    {
      "x": -1,
      "y": 5,
      "z": -4,
      "name": "Empty"
    },
    {
      "x": -1,
      "y": 6,
      "z": -4,
      "name": "Rock_Stone_Brick_Smooth",
      "rotation": 2
    },
    {
      "x": -1,
      "y": 0,
      "z": -3,
      "name": "Rock_Stone_Brick_Smooth",
      "rotation": 2
    },
    {
      "x": -1,
      "y": 1,
      "z": -3,
      "name": "Empty"
    },
    {
      "x": -1,
      "y": 2,
      "z": -3,
      "name": "Empty"
    },
    {
      "x": -1,
      "y": 3,
      "z": -3,
      "name": "Empty"
    },
    {
      "x": -1,
      "y": 4,
      "z": -3,
      "name": "Empty"
    },
    {
      "x": -1,
      "y": 5,
      "z": -3,
      "name": "Empty"
    },
    {
      "x": -1,
      "y": 6,
      "z": -3,
      "name": "Rock_Stone_Brick_Smooth",
      "rotation": 2
    },
    {
      "x": -1,
      "y": 0,
      "z": -2,
      "name": "Rock_Stone_Brick_Smooth",
      "rotation": 1
    },
    {
      "x": -1,
      "y": 1,
      "z": -2,
      "name": "Empty"
    },
    {
      "x": -1,
      "y": 2,
      "z": -2,
      "name": "Empty"
    },
    {
      "x": -1,
      "y": 3,
      "z": -2,
      "name": "Empty"
    },
    {
      "x": -1,
      "y": 4,
      "z": -2,
      "name": "Empty"
    },
    {
      "x": -1,
      "y": 5,
      "z": -2,
      "name": "Empty"
    },
    {
      "x": -1,
      "y": 6,
      "z": -2,
      "name": "Rock_Stone_Brick_Smooth",
      "rotation": 1
    },
    {
      "x": -1,
      "y": 0,
      "z": -1,
      "name": "Rock_Stone_Brick_Smooth",
      "rotation": 2
    },
    {
      "x": -1,
      "y": 1,
      "z": -1,
      "name": "Empty"
    },
    {
      "x": -1,
      "y": 2,
      "z": -1,
      "name": "Empty"
    },
    {
      "x": -1,
      "y": 3,
      "z": -1,
      "name": "Empty"
    },
    {
      "x": -1,
      "y": 4,
      "z": -1,
      "name": "Empty"
    },
    {
      "x": -1,
      "y": 5,
      "z": -1,
      "name": "Empty"
    },
    {
      "x": -1,
      "y": 6,
      "z": -1,
      "name": "Rock_Stone_Brick_Smooth",
      "rotation": 2
    },
    {
      "x": -1,
      "y": 0,
      "z": 0,
      "name": "Rock_Stone_Brick_Smooth",
      "rotation": 2
    },
    {
      "x": -1,
      "y": 1,
      "z": 0,
      "name": "Empty"
    },
    {
      "x": -1,
      "y": 2,
      "z": 0,
      "name": "Empty"
    },
    {
      "x": -1,
      "y": 3,
      "z": 0,
      "name": "Empty"
    },
    {
      "x": -1,
      "y": 4,
      "z": 0,
      "name": "Empty"
    },
    {
      "x": -1,
      "y": 5,
      "z": 0,
      "name": "Empty"
    },
    {
      "x": -1,
      "y": 6,
      "z": 0,
      "name": "Rock_Stone_Brick_Smooth",
      "rotation": 2
    },
    {
      "x": -1,
      "y": 0,
      "z": 1,
      "name": "Rock_Stone_Brick_Smooth"
    },
    {
      "x": -1,
      "y": 1,
      "z": 1,
      "name": "Empty"
    },
    {
      "x": -1,
      "y": 2,
      "z": 1,
      "name": "Empty"
    },
    {
      "x": -1,
      "y": 3,
      "z": 1,
      "name": "Empty"
    },
    {
      "x": -1,
      "y": 4,
      "z": 1,
      "name": "Empty"
    },
    {
      "x": -1,
      "y": 5,
      "z": 1,
      "name": "Empty"
    },
    {
      "x": -1,
      "y": 6,
      "z": 1,
      "name": "Rock_Stone_Brick_Smooth"
    },
    {
      "x": -1,
      "y": 0,
      "z": 2,
      "name": "Rock_Stone_Brick_Smooth"
    },
    {
      "x": -1,
      "y": 1,
      "z": 2,
      "name": "Empty"
    },
    {
      "x": -1,
      "y": 2,
      "z": 2,
      "name": "Empty"
    },
    {
      "x": -1,
      "y": 3,
      "z": 2,
      "name": "Empty"
    },
    {
      "x": -1,
      "y": 4,
      "z": 2,
      "name": "Empty"
    },
    {
      "x": -1,
      "y": 5,
      "z": 2,
      "name": "Empty"
    },
    {
      "x": -1,
      "y": 6,
      "z": 2,
      "name": "Rock_Stone_Brick_Smooth"
    },
    {
      "x": -1,
      "y": 0,
      "z": 3,
      "name": "Rock_Stone_Brick_Smooth"
    },
    {
      "x": -1,
      "y": 1,
      "z": 3,
      "name": "Empty"
    },
    {
      "x": -1,
      "y": 2,
      "z": 3,
      "name": "Empty"
    },
    {
      "x": -1,
      "y": 3,
      "z": 3,
      "name": "Empty"
    },
    {
      "x": -1,
      "y": 4,
      "z": 3,
      "name": "Empty"
    },
    {
      "x": -1,
      "y": 5,
      "z": 3,
      "name": "Empty"
    },
    {
      "x": -1,
      "y": 6,
      "z": 3,
      "name": "Rock_Stone_Brick_Smooth",
      "rotation": 1
    },
    {
      "x": -1,
      "y": 0,
      "z": 4,
      "name": "Rock_Stone_Brick_Smooth"
    },
    {
      "x": -1,
      "y": 1,
      "z": 4,
      "name": "Empty"
    },
    {
      "x": -1,
      "y": 2,
      "z": 4,
      "name": "Empty"
    },
    {
      "x": -1,
      "y": 3,
      "z": 4,
      "name": "Empty"
    },
    {
      "x": -1,
      "y": 4,
      "z": 4,
      "name": "Empty"
    },
    {
      "x": -1,
      "y": 5,
      "z": 4,
      "name": "Empty"
    },
    {
      "x": -1,
      "y": 6,
      "z": 4,
      "name": "Rock_Stone_Brick_Smooth",
      "rotation": 1
    },
    {
      "x": -1,
      "y": 0,
      "z": 5,
      "name": "Rock_Stone_Brick_Smooth",
      "rotation": 1
    },
    {
      "x": -1,
      "y": 1,
      "z": 5,
      "name": "Empty"
    },
    {
      "x": -1,
      "y": 2,
      "z": 5,
      "name": "Empty"
    },
    {
      "x": -1,
      "y": 3,
      "z": 5,
      "name": "Empty"
    },
    {
      "x": -1,
      "y": 4,
      "z": 5,
      "name": "Empty"
    },
    {
      "x": -1,
      "y": 5,
      "z": 5,
      "name": "Empty"
    },
    {
      "x": -1,
      "y": 6,
      "z": 5,
      "name": "Rock_Stone_Brick_Smooth",
      "rotation": 1
    },
    {
      "x": -1,
      "y": 0,
      "z": 6,
      "name": "Rock_Stone_Brick_Smooth",
      "rotation": 1
    },
    {
      "x": -1,
      "y": 1,
      "z": 6,
      "name": "Empty"
    },
    {
      "x": -1,
      "y": 2,
      "z": 6,
      "name": "Empty"
    },
    {
      "x": -1,
      "y": 3,
      "z": 6,
      "name": "Empty"
    },
    {
      "x": -1,
      "y": 4,
      "z": 6,
      "name": "Empty"
    },
    {
      "x": -1,
      "y": 5,
      "z": 6,
      "name": "Empty"
    },
    {
      "x": -1,
      "y": 6,
      "z": 6,
      "name": "Rock_Stone_Brick_Smooth",
      "rotation": 1
    },
    {
      "x": -1,
      "y": 0,
      "z": 7,
      "name": "Rock_Stone_Brick_Smooth",
      "rotation": 2
    },
    {
      "x": -1,
      "y": 1,
      "z": 7,
      "name": "Empty"
    },
    {
      "x": -1,
      "y": 2,
      "z": 7,
      "name": "Empty"
    },
    {
      "x": -1,
      "y": 3,
      "z": 7,
      "name": "Empty"
    },
    {
      "x": -1,
      "y": 4,
      "z": 7,
      "name": "Empty"
    },
    {
      "x": -1,
      "y": 5,
      "z": 7,
      "name": "Empty"
    },
    {
      "x": -1,
      "y": 6,
      "z": 7,
      "name": "Rock_Stone_Brick_Smooth",
      "rotation": 2
    },
    {
      "x": -1,
      "y": 0,
      "z": 8,
      "name": "Rock_Stone_Brick_Smooth",
      "rotation": 2
    },
    {
      "x": -1,
      "y": 1,
      "z": 8,
      "name": "Empty"
    },
    {
      "x": -1,
      "y": 2,
      "z": 8,
      "name": "Empty"
    },
    {
      "x": -1,
      "y": 3,
      "z": 8,
      "name": "Empty"
    },
    {
      "x": -1,
      "y": 4,
      "z": 8,
      "name": "Empty"
    },
    {
      "x": -1,
      "y": 5,
      "z": 8,
      "name": "Empty"
    },
    {
      "x": -1,
      "y": 6,
      "z": 8,
      "name": "Rock_Stone_Brick_Smooth",
      "rotation": 2
    },
    {
      "x": -1,
      "y": 0,
      "z": 9,
      "name": "Rock_Stone_Brick_Smooth",
      "rotation": 1
    },
    {
      "x": -1,
      "y": 1,
      "z": 9,
      "name": "Empty"
    },
    {
      "x": -1,
      "y": 2,
      "z": 9,
      "name": "Empty"
    },
    {
      "x": -1,
      "y": 3,
      "z": 9,
      "name": "Empty"
    },
    {
      "x": -1,
      "y": 4,
      "z": 9,
      "name": "Empty"
    },
    {
      "x": -1,
      "y": 5,
      "z": 9,
      "name": "Empty"
    },
    {
      "x": -1,
      "y": 6,
      "z": 9,
      "name": "Rock_Stone_Brick_Smooth",
      "rotation": 1
    },
    {
      "x": -1,
      "y": 0,
      "z": 10,
      "name": "Rock_Stone_Brick_Smooth",
      "rotation": 2
    },
    {
      "x": -1,
      "y": 1,
      "z": 10,
      "name": "Empty"
    },
    {
      "x": -1,
      "y": 2,
      "z": 10,
      "name": "Empty"
    },
    {
      "x": -1,
      "y": 3,
      "z": 10,
      "name": "Empty"
    },
    {
      "x": -1,
      "y": 4,
      "z": 10,
      "name": "Empty"
    },
    {
      "x": -1,
      "y": 5,
      "z": 10,
      "name": "Empty"
    },
    {
      "x": -1,
      "y": 6,
      "z": 10,
      "name": "Rock_Stone_Brick_Smooth",
      "rotation": 2
    },
    {
      "x": -1,
      "y": 0,
      "z": 11,
      "name": "Rock_Stone_Brick_Smooth",
      "rotation": 2
    },
    {
      "x": -1,
      "y": 1,
      "z": 11,
      "name": "Rock_Stone_Brick_Smooth_Half",
      "rotation": 5
    },
    {
      "x": -1,
      "y": 2,
      "z": 11,
      "name": "Rock_Stone_Brick_Smooth_Half",
      "rotation": 5
    },
    {
      "x": -1,
      "y": 3,
      "z": 11,
      "name": "Rock_Stone_Brick_Smooth_Half",
      "rotation": 5
    },
    {
      "x": -1,
      "y": 4,
      "z": 11,
      "name": "*Rock_Stone_Brick_Stairs_State_Definitions_Inverted_Corner_Right",
      "rotation": 33
    },
    {
      "x": -1,
      "y": 5,
      "z": 11,
      "name": "Rock_Stone_Brick_Decorative",
      "rotation": 2
    },
    {
      "x": -1,
      "y": 6,
      "z": 11,
      "name": "Rock_Stone_Brick_Smooth",
      "rotation": 2
    },
    {
      "x": 0,
      "y": 0,
      "z": -10,
      "name": "Rock_Stone_Brick_Smooth"
    },
    {
      "x": 0,
      "y": 1,
      "z": -10,
      "name": "Empty"
    },
    {
      "x": 0,
      "y": 2,
      "z": -10,
      "name": "Empty"
    },
    {
      "x": 0,
      "y": 3,
      "z": -10,
      "name": "Empty"
    },
    {
      "x": 0,
      "y": 4,
      "z": -10,
      "name": "Rock_Stone_Brick_Stairs",
      "rotation": 32
    },
    {
      "x": 0,
      "y": 5,
      "z": -10,
      "name": "Rock_Stone_Brick_Decorative"
    },
    {
      "x": 0,
      "y": 6,
      "z": -10,
      "name": "Rock_Stone_Brick_Smooth"
    },
    {
      "x": 0,
      "y": 0,
      "z": -9,
      "name": "Rock_Stone_Brick_Smooth"
    },
    {
      "x": 0,
      "y": 1,
      "z": -9,
      "name": "Empty"
    },
    {
      "x": 0,
      "y": 2,
      "z": -9,
      "name": "Empty"
    },
    {
      "x": 0,
      "y": 3,
      "z": -9,
      "name": "Empty"
    },
    {
      "x": 0,
      "y": 4,
      "z": -9,
      "name": "Empty"
    },
    {
      "x": 0,
      "y": 5,
      "z": -9,
      "name": "Empty"
    },
    {
      "x": 0,
      "y": 6,
      "z": -9,
      "name": "Rock_Stone_Brick_Smooth"
    },
    {
      "x": 0,
      "y": 0,
      "z": -8,
      "name": "Rock_Stone_Brick_Smooth",
      "rotation": 3
    },
    {
      "x": 0,
      "y": 1,
      "z": -8,
      "name": "Empty"
    },
    {
      "x": 0,
      "y": 2,
      "z": -8,
      "name": "Empty"
    },
    {
      "x": 0,
      "y": 3,
      "z": -8,
      "name": "Empty"
    },
    {
      "x": 0,
      "y": 4,
      "z": -8,
      "name": "Empty"
    },
    {
      "x": 0,
      "y": 5,
      "z": -8,
      "name": "Empty"
    },
    {
      "x": 0,
      "y": 6,
      "z": -8,
      "name": "Rock_Stone_Brick_Smooth",
      "rotation": 3
    },
    {
      "x": 0,
      "y": 0,
      "z": -7,
      "name": "Rock_Stone_Brick_Smooth"
    },
    {
      "x": 0,
      "y": 1,
      "z": -7,
      "name": "Empty"
    },
    {
      "x": 0,
      "y": 2,
      "z": -7,
      "name": "Empty"
    },
    {
      "x": 0,
      "y": 3,
      "z": -7,
      "name": "Empty"
    },
    {
      "x": 0,
      "y": 4,
      "z": -7,
      "name": "Empty"
    },
    {
      "x": 0,
      "y": 5,
      "z": -7,
      "name": "Empty"
    },
    {
      "x": 0,
      "y": 6,
      "z": -7,
      "name": "Rock_Stone_Brick_Smooth"
    },
    {
      "x": 0,
      "y": 0,
      "z": -6,
      "name": "Rock_Stone_Brick_Smooth"
    },
    {
      "x": 0,
      "y": 1,
      "z": -6,
      "name": "Empty"
    },
    {
      "x": 0,
      "y": 2,
      "z": -6,
      "name": "Empty"
    },
    {
      "x": 0,
      "y": 3,
      "z": -6,
      "name": "Empty"
    },
    {
      "x": 0,
      "y": 4,
      "z": -6,
      "name": "Empty"
    },
    {
      "x": 0,
      "y": 5,
      "z": -6,
      "name": "Empty"
    },
    {
      "x": 0,
      "y": 6,
      "z": -6,
      "name": "Rock_Stone_Brick_Smooth"
    },
    {
      "x": 0,
      "y": 0,
      "z": -5,
      "name": "Rock_Stone_Brick_Smooth"
    },
    {
      "x": 0,
      "y": 1,
      "z": -5,
      "name": "Empty"
    },
    {
      "x": 0,
      "y": 2,
      "z": -5,
      "name": "Empty"
    },
    {
      "x": 0,
      "y": 3,
      "z": -5,
      "name": "Empty"
    },
    {
      "x": 0,
      "y": 4,
      "z": -5,
      "name": "Empty"
    },
    {
      "x": 0,
      "y": 5,
      "z": -5,
      "name": "Empty"
    },
    {
      "x": 0,
      "y": 6,
      "z": -5,
      "name": "Rock_Stone_Brick_Smooth"
    },
    {
      "x": 0,
      "y": 0,
      "z": -4,
      "name": "Rock_Stone_Brick_Smooth",
      "rotation": 3
    },
    {
      "x": 0,
      "y": 1,
      "z": -4,
      "name": "Empty"
    },
    {
      "x": 0,
      "y": 2,
      "z": -4,
      "name": "Empty"
    },
    {
      "x": 0,
      "y": 3,
      "z": -4,
      "name": "Empty"
    },
    {
      "x": 0,
      "y": 4,
      "z": -4,
      "name": "Empty"
    },
    {
      "x": 0,
      "y": 5,
      "z": -4,
      "name": "Empty"
    },
    {
      "x": 0,
      "y": 6,
      "z": -4,
      "name": "Rock_Stone_Brick_Smooth",
      "rotation": 3
    },
    {
      "x": 0,
      "y": 0,
      "z": -3,
      "name": "Rock_Stone_Brick_Smooth"
    },
    {
      "x": 0,
      "y": 1,
      "z": -3,
      "name": "Empty"
    },
    {
      "x": 0,
      "y": 2,
      "z": -3,
      "name": "Empty"
    },
    {
      "x": 0,
      "y": 3,
      "z": -3,
      "name": "Empty"
    },
    {
      "x": 0,
      "y": 4,
      "z": -3,
      "name": "Empty"
    },
    {
      "x": 0,
      "y": 5,
      "z": -3,
      "name": "Empty"
    },
    {
      "x": 0,
      "y": 6,
      "z": -3,
      "name": "Rock_Stone_Brick_Smooth"
    },
    {
      "x": 0,
      "y": 0,
      "z": -2,
      "name": "Rock_Stone_Brick_Smooth"
    },
    {
      "x": 0,
      "y": 1,
      "z": -2,
      "name": "Empty"
    },
    {
      "x": 0,
      "y": 2,
      "z": -2,
      "name": "Empty"
    },
    {
      "x": 0,
      "y": 3,
      "z": -2,
      "name": "Empty"
    },
    {
      "x": 0,
      "y": 4,
      "z": -2,
      "name": "Empty"
    },
    {
      "x": 0,
      "y": 5,
      "z": -2,
      "name": "Empty"
    },
    {
      "x": 0,
      "y": 6,
      "z": -2,
      "name": "Rock_Stone_Brick_Smooth"
    },
    {
      "x": 0,
      "y": 0,
      "z": -1,
      "name": "Rock_Stone_Brick_Smooth"
    },
    {
      "x": 0,
      "y": 1,
      "z": -1,
      "name": "Empty"
    },
    {
      "x": 0,
      "y": 2,
      "z": -1,
      "name": "Empty"
    },
    {
      "x": 0,
      "y": 3,
      "z": -1,
      "name": "Empty"
    },
    {
      "x": 0,
      "y": 4,
      "z": -1,
      "name": "Empty"
    },
    {
      "x": 0,
      "y": 5,
      "z": -1,
      "name": "Empty"
    },
    {
      "x": 0,
      "y": 6,
      "z": -1,
      "name": "Rock_Stone_Brick_Smooth"
    },
    {
      "x": 0,
      "y": 0,
      "z": 0,
      "name": "Rock_Stone_Brick_Smooth",
      "rotation": 3
    },
    {
      "x": 0,
      "y": 1,
      "z": 0,
      "name": "Empty"
    },
    {
      "x": 0,
      "y": 2,
      "z": 0,
      "name": "Empty"
    },
    {
      "x": 0,
      "y": 3,
      "z": 0,
      "name": "Empty"
    },
    {
      "x": 0,
      "y": 4,
      "z": 0,
      "name": "Empty"
    },
    {
      "x": 0,
      "y": 5,
      "z": 0,
      "name": "Empty"
    },
    {
      "x": 0,
      "y": 6,
      "z": 0,
      "name": "Rock_Stone_Brick_Smooth",
      "rotation": 3
    },
    {
      "x": 0,
      "y": 0,
      "z": 1,
      "name": "Rock_Stone_Brick_Smooth",
      "rotation": 1
    },
    {
      "x": 0,
      "y": 1,
      "z": 1,
      "name": "Empty"
    },
    {
      "x": 0,
      "y": 2,
      "z": 1,
      "name": "Empty"
    },
    {
      "x": 0,
      "y": 3,
      "z": 1,
      "name": "Empty"
    },
    {
      "x": 0,
      "y": 4,
      "z": 1,
      "name": "Empty"
    },
    {
      "x": 0,
      "y": 5,
      "z": 1,
      "name": "Empty"
    },
    {
      "x": 0,
      "y": 6,
      "z": 1,
      "name": "Rock_Stone_Brick_Smooth",
      "rotation": 1
    },
    {
      "x": 0,
      "y": 0,
      "z": 2,
      "name": "Rock_Stone_Brick_Smooth",
      "rotation": 2
    },
    {
      "x": 0,
      "y": 1,
      "z": 2,
      "name": "Empty"
    },
    {
      "x": 0,
      "y": 2,
      "z": 2,
      "name": "Empty"
    },
    {
      "x": 0,
      "y": 3,
      "z": 2,
      "name": "Empty"
    },
    {
      "x": 0,
      "y": 4,
      "z": 2,
      "name": "Empty"
    },
    {
      "x": 0,
      "y": 5,
      "z": 2,
      "name": "Empty"
    },
    {
      "x": 0,
      "y": 6,
      "z": 2,
      "name": "Rock_Stone_Brick_Smooth",
      "rotation": 2
    },
    {
      "x": 0,
      "y": 0,
      "z": 3,
      "name": "Rock_Stone_Brick_Smooth",
      "rotation": 2
    },
    {
      "x": 0,
      "y": 1,
      "z": 3,
      "name": "Empty"
    },
    {
      "x": 0,
      "y": 2,
      "z": 3,
      "name": "Empty"
    },
    {
      "x": 0,
      "y": 3,
      "z": 3,
      "name": "Empty"
    },
    {
      "x": 0,
      "y": 4,
      "z": 3,
      "name": "Empty"
    },
    {
      "x": 0,
      "y": 5,
      "z": 3,
      "name": "Empty"
    },
    {
      "x": 0,
      "y": 6,
      "z": 3,
      "name": "Rock_Stone_Brick_Smooth",
      "rotation": 2
    },
    {
      "x": 0,
      "y": 0,
      "z": 4,
      "name": "Rock_Stone_Brick_Smooth",
      "rotation": 2
    },
    {
      "x": 0,
      "y": 1,
      "z": 4,
      "name": "Empty"
    },
    {
      "x": 0,
      "y": 2,
      "z": 4,
      "name": "Empty"
    },
    {
      "x": 0,
      "y": 3,
      "z": 4,
      "name": "Empty"
    },
    {
      "x": 0,
      "y": 4,
      "z": 4,
      "name": "Empty"
    },
    {
      "x": 0,
      "y": 5,
      "z": 4,
      "name": "Empty"
    },
    {
      "x": 0,
      "y": 6,
      "z": 4,
      "name": "Rock_Stone_Brick_Smooth",
      "rotation": 2
    },
    {
      "x": 0,
      "y": 0,
      "z": 5,
      "name": "Rock_Stone_Brick_Smooth",
      "rotation": 1
    },
    {
      "x": 0,
      "y": 1,
      "z": 5,
      "name": "Empty"
    },
    {
      "x": 0,
      "y": 2,
      "z": 5,
      "name": "Empty"
    },
    {
      "x": 0,
      "y": 3,
      "z": 5,
      "name": "Empty"
    },
    {
      "x": 0,
      "y": 4,
      "z": 5,
      "name": "Empty"
    },
    {
      "x": 0,
      "y": 5,
      "z": 5,
      "name": "Empty"
    },
    {
      "x": 0,
      "y": 6,
      "z": 5,
      "name": "Rock_Stone_Brick_Smooth",
      "rotation": 1
    },
    {
      "x": 0,
      "y": 0,
      "z": 6,
      "name": "Rock_Stone_Brick_Smooth",
      "rotation": 2
    },
    {
      "x": 0,
      "y": 1,
      "z": 6,
      "name": "Empty"
    },
    {
      "x": 0,
      "y": 2,
      "z": 6,
      "name": "Empty"
    },
    {
      "x": 0,
      "y": 3,
      "z": 6,
      "name": "Empty"
    },
    {
      "x": 0,
      "y": 4,
      "z": 6,
      "name": "Empty"
    },
    {
      "x": 0,
      "y": 5,
      "z": 6,
      "name": "Empty"
    },
    {
      "x": 0,
      "y": 6,
      "z": 6,
      "name": "Rock_Stone_Brick_Smooth",
      "rotation": 2
    },
    {
      "x": 0,
      "y": 0,
      "z": 7,
      "name": "Rock_Stone_Brick_Smooth",
      "rotation": 2
    },
    {
      "x": 0,
      "y": 1,
      "z": 7,
      "name": "Empty"
    },
    {
      "x": 0,
      "y": 2,
      "z": 7,
      "name": "Empty"
    },
    {
      "x": 0,
      "y": 3,
      "z": 7,
      "name": "Empty"
    },
    {
      "x": 0,
      "y": 4,
      "z": 7,
      "name": "Empty"
    },
    {
      "x": 0,
      "y": 5,
      "z": 7,
      "name": "Empty"
    },
    {
      "x": 0,
      "y": 6,
      "z": 7,
      "name": "Rock_Stone_Brick_Smooth",
      "rotation": 2
    },
    {
      "x": 0,
      "y": 0,
      "z": 8,
      "name": "Rock_Stone_Brick_Smooth",
      "rotation": 2
    },
    {
      "x": 0,
      "y": 1,
      "z": 8,
      "name": "Empty"
    },
    {
      "x": 0,
      "y": 2,
      "z": 8,
      "name": "Empty"
    },
    {
      "x": 0,
      "y": 3,
      "z": 8,
      "name": "Empty"
    },
    {
      "x": 0,
      "y": 4,
      "z": 8,
      "name": "Empty"
    },
    {
      "x": 0,
      "y": 5,
      "z": 8,
      "name": "Empty"
    },
    {
      "x": 0,
      "y": 6,
      "z": 8,
      "name": "Rock_Stone_Brick_Smooth",
      "rotation": 2
    },
    {
      "x": 0,
      "y": 0,
      "z": 9,
      "name": "Rock_Stone_Brick_Smooth",
      "rotation": 1
    },
    {
      "x": 0,
      "y": 1,
      "z": 9,
      "name": "Empty"
    },
    {
      "x": 0,
      "y": 2,
      "z": 9,
      "name": "Empty"
    },
    {
      "x": 0,
      "y": 3,
      "z": 9,
      "name": "Empty"
    },
    {
      "x": 0,
      "y": 4,
      "z": 9,
      "name": "Empty"
    },
    {
      "x": 0,
      "y": 5,
      "z": 9,
      "name": "Empty"
    },
    {
      "x": 0,
      "y": 6,
      "z": 9,
      "name": "Rock_Stone_Brick_Smooth",
      "rotation": 1
    },
    {
      "x": 0,
      "y": 0,
      "z": 10,
      "name": "Rock_Stone_Brick_Smooth",
      "rotation": 2
    },
    {
      "x": 0,
      "y": 1,
      "z": 10,
      "name": "Empty"
    },
    {
      "x": 0,
      "y": 2,
      "z": 10,
      "name": "Empty"
    },
    {
      "x": 0,
      "y": 3,
      "z": 10,
      "name": "Empty"
    },
    {
      "x": 0,
      "y": 4,
      "z": 10,
      "name": "Empty"
    },
    {
      "x": 0,
      "y": 5,
      "z": 10,
      "name": "Empty"
    },
    {
      "x": 0,
      "y": 6,
      "z": 10,
      "name": "Rock_Stone_Brick_Smooth",
      "rotation": 2
    },
    {
      "x": 0,
      "y": 0,
      "z": 11,
      "name": "Rock_Stone_Brick_Smooth",
      "rotation": 2
    },
    {
      "x": 0,
      "y": 1,
      "z": 11,
      "name": "Empty"
    },
    {
      "x": 0,
      "y": 2,
      "z": 11,
      "name": "Empty"
    },
    {
      "x": 0,
      "y": 3,
      "z": 11,
      "name": "Empty"
    },
    {
      "x": 0,
      "y": 4,
      "z": 11,
      "name": "Rock_Stone_Brick_Stairs",
      "rotation": 34
    },
    {
      "x": 0,
      "y": 5,
      "z": 11,
      "name": "Rock_Stone_Brick_Decorative",
      "rotation": 2
    },
    {
      "x": 0,
      "y": 6,
      "z": 11,
      "name": "Rock_Stone_Brick_Smooth",
      "rotation": 2
    },
    {
      "x": 1,
      "y": 0,
      "z": -10,
      "name": "Rock_Stone_Brick_Smooth"
    },
    {
      "x": 1,
      "y": 1,
      "z": -10,
      "name": "Rock_Stone_Brick_Smooth_Half",
      "rotation": 7
    },
    {
      "x": 1,
      "y": 2,
      "z": -10,
      "name": "Rock_Stone_Brick_Smooth_Half",
      "rotation": 7
    },
    {
      "x": 1,
      "y": 3,
      "z": -10,
      "name": "Rock_Stone_Brick_Smooth_Half",
      "rotation": 7
    },
    {
      "x": 1,
      "y": 4,
      "z": -10,
      "name": "*Rock_Stone_Brick_Stairs_State_Definitions_Inverted_Corner_Right",
      "rotation": 35
    },
    {
      "x": 1,
      "y": 5,
      "z": -10,
      "name": "Rock_Stone_Brick_Decorative"
    },
    {
      "x": 1,
      "y": 6,
      "z": -10,
      "name": "Rock_Stone_Brick_Smooth"
    },
    {
      "x": 1,
      "y": 0,
      "z": -9,
      "name": "Rock_Stone_Brick_Smooth"
    },
    {
      "x": 1,
      "y": 1,
      "z": -9,
      "name": "Empty"
    },
    {
      "x": 1,
      "y": 2,
      "z": -9,
      "name": "Empty"
    },
    {
      "x": 1,
      "y": 3,
      "z": -9,
      "name": "Empty"
    },
    {
      "x": 1,
      "y": 4,
      "z": -9,
      "name": "Empty"
    },
    {
      "x": 1,
      "y": 5,
      "z": -9,
      "name": "Empty"
    },
    {
      "x": 1,
      "y": 6,
      "z": -9,
      "name": "Rock_Stone_Brick_Smooth"
    },
    {
      "x": 1,
      "y": 0,
      "z": -8,
      "name": "Rock_Stone_Brick_Smooth",
      "rotation": 3
    },
    {
      "x": 1,
      "y": 1,
      "z": -8,
      "name": "Empty"
    },
    {
      "x": 1,
      "y": 2,
      "z": -8,
      "name": "Empty"
    },
    {
      "x": 1,
      "y": 3,
      "z": -8,
      "name": "Empty"
    },
    {
      "x": 1,
      "y": 4,
      "z": -8,
      "name": "Empty"
    },
    {
      "x": 1,
      "y": 5,
      "z": -8,
      "name": "Empty"
    },
    {
      "x": 1,
      "y": 6,
      "z": -8,
      "name": "Rock_Stone_Brick_Smooth",
      "rotation": 3
    },
    {
      "x": 1,
      "y": 0,
      "z": -7,
      "name": "Rock_Stone_Brick_Smooth"
    },
    {
      "x": 1,
      "y": 1,
      "z": -7,
      "name": "Empty"
    },
    {
      "x": 1,
      "y": 2,
      "z": -7,
      "name": "Empty"
    },
    {
      "x": 1,
      "y": 3,
      "z": -7,
      "name": "Empty"
    },
    {
      "x": 1,
      "y": 4,
      "z": -7,
      "name": "Empty"
    },
    {
      "x": 1,
      "y": 5,
      "z": -7,
      "name": "Empty"
    },
    {
      "x": 1,
      "y": 6,
      "z": -7,
      "name": "Rock_Stone_Brick_Smooth"
    },
    {
      "x": 1,
      "y": 0,
      "z": -6,
      "name": "Rock_Stone_Brick_Smooth"
    },
    {
      "x": 1,
      "y": 1,
      "z": -6,
      "name": "Empty"
    },
    {
      "x": 1,
      "y": 2,
      "z": -6,
      "name": "Empty"
    },
    {
      "x": 1,
      "y": 3,
      "z": -6,
      "name": "Empty"
    },
    {
      "x": 1,
      "y": 4,
      "z": -6,
      "name": "Empty"
    },
    {
      "x": 1,
      "y": 5,
      "z": -6,
      "name": "Empty"
    },
    {
      "x": 1,
      "y": 6,
      "z": -6,
      "name": "Rock_Stone_Brick_Smooth"
    },
    {
      "x": 1,
      "y": 0,
      "z": -5,
      "name": "Rock_Stone_Brick_Smooth",
      "rotation": 3
    },
    {
      "x": 1,
      "y": 1,
      "z": -5,
      "name": "Empty"
    },
    {
      "x": 1,
      "y": 2,
      "z": -5,
      "name": "Empty"
    },
    {
      "x": 1,
      "y": 3,
      "z": -5,
      "name": "Empty"
    },
    {
      "x": 1,
      "y": 4,
      "z": -5,
      "name": "Empty"
    },
    {
      "x": 1,
      "y": 5,
      "z": -5,
      "name": "Empty"
    },
    {
      "x": 1,
      "y": 6,
      "z": -5,
      "name": "Rock_Stone_Brick_Smooth",
      "rotation": 3
    },
    {
      "x": 1,
      "y": 0,
      "z": -4,
      "name": "Rock_Stone_Brick_Smooth",
      "rotation": 3
    },
    {
      "x": 1,
      "y": 1,
      "z": -4,
      "name": "Empty"
    },
    {
      "x": 1,
      "y": 2,
      "z": -4,
      "name": "Empty"
    },
    {
      "x": 1,
      "y": 3,
      "z": -4,
      "name": "Empty"
    },
    {
      "x": 1,
      "y": 4,
      "z": -4,
      "name": "Empty"
    },
    {
      "x": 1,
      "y": 5,
      "z": -4,
      "name": "Empty"
    },
    {
      "x": 1,
      "y": 6,
      "z": -4,
      "name": "Rock_Stone_Brick_Smooth",
      "rotation": 3
    },
    {
      "x": 1,
      "y": 0,
      "z": -3,
      "name": "Rock_Stone_Brick_Smooth",
      "rotation": 2
    },
    {
      "x": 1,
      "y": 1,
      "z": -3,
      "name": "Empty"
    },
    {
      "x": 1,
      "y": 2,
      "z": -3,
      "name": "Empty"
    },
    {
      "x": 1,
      "y": 3,
      "z": -3,
      "name": "Empty"
    },
    {
      "x": 1,
      "y": 4,
      "z": -3,
      "name": "Empty"
    },
    {
      "x": 1,
      "y": 5,
      "z": -3,
      "name": "Empty"
    },
    {
      "x": 1,
      "y": 6,
      "z": -3,
      "name": "Rock_Stone_Brick_Smooth",
      "rotation": 3
    },
    {
      "x": 1,
      "y": 0,
      "z": -2,
      "name": "Rock_Stone_Brick_Smooth",
      "rotation": 2
    },
    {
      "x": 1,
      "y": 1,
      "z": -2,
      "name": "Empty"
    },
    {
      "x": 1,
      "y": 2,
      "z": -2,
      "name": "Empty"
    },
    {
      "x": 1,
      "y": 3,
      "z": -2,
      "name": "Empty"
    },
    {
      "x": 1,
      "y": 4,
      "z": -2,
      "name": "Empty"
    },
    {
      "x": 1,
      "y": 5,
      "z": -2,
      "name": "Empty"
    },
    {
      "x": 1,
      "y": 6,
      "z": -2,
      "name": "Rock_Stone_Brick_Smooth",
      "rotation": 3
    },
    {
      "x": 1,
      "y": 0,
      "z": -1,
      "name": "Rock_Stone_Brick_Smooth",
      "rotation": 2
    },
    {
      "x": 1,
      "y": 1,
      "z": -1,
      "name": "Empty"
    },
    {
      "x": 1,
      "y": 2,
      "z": -1,
      "name": "Empty"
    },
    {
      "x": 1,
      "y": 3,
      "z": -1,
      "name": "Empty"
    },
    {
      "x": 1,
      "y": 4,
      "z": -1,
      "name": "Empty"
    },
    {
      "x": 1,
      "y": 5,
      "z": -1,
      "name": "Empty"
    },
    {
      "x": 1,
      "y": 6,
      "z": -1,
      "name": "Rock_Stone_Brick_Smooth",
      "rotation": 2
    },
    {
      "x": 1,
      "y": 0,
      "z": 0,
      "name": "Rock_Stone_Brick_Smooth",
      "rotation": 2
    },
    {
      "x": 1,
      "y": 1,
      "z": 0,
      "name": "Empty"
    },
    {
      "x": 1,
      "y": 2,
      "z": 0,
      "name": "Empty"
    },
    {
      "x": 1,
      "y": 3,
      "z": 0,
      "name": "Empty"
    },
    {
      "x": 1,
      "y": 4,
      "z": 0,
      "name": "Empty"
    },
    {
      "x": 1,
      "y": 5,
      "z": 0,
      "name": "Empty"
    },
    {
      "x": 1,
      "y": 6,
      "z": 0,
      "name": "Rock_Stone_Brick_Smooth",
      "rotation": 2
    },
    {
      "x": 1,
      "y": 0,
      "z": 1,
      "name": "Rock_Stone_Brick_Smooth"
    },
    {
      "x": 1,
      "y": 1,
      "z": 1,
      "name": "Empty"
    },
    {
      "x": 1,
      "y": 2,
      "z": 1,
      "name": "Empty"
    },
    {
      "x": 1,
      "y": 3,
      "z": 1,
      "name": "Empty"
    },
    {
      "x": 1,
      "y": 4,
      "z": 1,
      "name": "Empty"
    },
    {
      "x": 1,
      "y": 5,
      "z": 1,
      "name": "Empty"
    },
    {
      "x": 1,
      "y": 6,
      "z": 1,
      "name": "Rock_Stone_Brick_Smooth"
    },
    {
      "x": 1,
      "y": 0,
      "z": 2,
      "name": "Rock_Stone_Brick_Smooth"
    },
    {
      "x": 1,
      "y": 1,
      "z": 2,
      "name": "Empty"
    },
    {
      "x": 1,
      "y": 2,
      "z": 2,
      "name": "Empty"
    },
    {
      "x": 1,
      "y": 3,
      "z": 2,
      "name": "Empty"
    },
    {
      "x": 1,
      "y": 4,
      "z": 2,
      "name": "Empty"
    },
    {
      "x": 1,
      "y": 5,
      "z": 2,
      "name": "Empty"
    },
    {
      "x": 1,
      "y": 6,
      "z": 2,
      "name": "Rock_Stone_Brick_Smooth"
    },
    {
      "x": 1,
      "y": 0,
      "z": 3,
      "name": "Rock_Stone_Brick_Smooth",
      "rotation": 3
    },
    {
      "x": 1,
      "y": 1,
      "z": 3,
      "name": "Empty"
    },
    {
      "x": 1,
      "y": 2,
      "z": 3,
      "name": "Empty"
    },
    {
      "x": 1,
      "y": 3,
      "z": 3,
      "name": "Empty"
    },
    {
      "x": 1,
      "y": 4,
      "z": 3,
      "name": "Empty"
    },
    {
      "x": 1,
      "y": 5,
      "z": 3,
      "name": "Empty"
    },
    {
      "x": 1,
      "y": 6,
      "z": 3,
      "name": "Rock_Stone_Brick_Smooth",
      "rotation": 3
    },
    {
      "x": 1,
      "y": 0,
      "z": 4,
      "name": "Rock_Stone_Brick_Smooth"
    },
    {
      "x": 1,
      "y": 1,
      "z": 4,
      "name": "Empty"
    },
    {
      "x": 1,
      "y": 2,
      "z": 4,
      "name": "Empty"
    },
    {
      "x": 1,
      "y": 3,
      "z": 4,
      "name": "Empty"
    },
    {
      "x": 1,
      "y": 4,
      "z": 4,
      "name": "Empty"
    },
    {
      "x": 1,
      "y": 5,
      "z": 4,
      "name": "Empty"
    },
    {
      "x": 1,
      "y": 6,
      "z": 4,
      "name": "Rock_Stone_Brick_Smooth"
    },
    {
      "x": 1,
      "y": 0,
      "z": 5,
      "name": "Rock_Stone_Brick_Smooth"
    },
    {
      "x": 1,
      "y": 1,
      "z": 5,
      "name": "Empty"
    },
    {
      "x": 1,
      "y": 2,
      "z": 5,
      "name": "Empty"
    },
    {
      "x": 1,
      "y": 3,
      "z": 5,
      "name": "Empty"
    },
    {
      "x": 1,
      "y": 4,
      "z": 5,
      "name": "Empty"
    },
    {
      "x": 1,
      "y": 5,
      "z": 5,
      "name": "Empty"
    },
    {
      "x": 1,
      "y": 6,
      "z": 5,
      "name": "Rock_Stone_Brick_Smooth"
    },
    {
      "x": 1,
      "y": 0,
      "z": 6,
      "name": "Rock_Stone_Brick_Smooth",
      "rotation": 3
    },
    {
      "x": 1,
      "y": 1,
      "z": 6,
      "name": "Empty"
    },
    {
      "x": 1,
      "y": 2,
      "z": 6,
      "name": "Empty"
    },
    {
      "x": 1,
      "y": 3,
      "z": 6,
      "name": "Empty"
    },
    {
      "x": 1,
      "y": 4,
      "z": 6,
      "name": "Empty"
    },
    {
      "x": 1,
      "y": 5,
      "z": 6,
      "name": "Empty"
    },
    {
      "x": 1,
      "y": 6,
      "z": 6,
      "name": "Rock_Stone_Brick_Smooth",
      "rotation": 3
    },
    {
      "x": 1,
      "y": 0,
      "z": 7,
      "name": "Rock_Stone_Brick_Smooth",
      "rotation": 3
    },
    {
      "x": 1,
      "y": 1,
      "z": 7,
      "name": "Empty"
    },
    {
      "x": 1,
      "y": 2,
      "z": 7,
      "name": "Empty"
    },
    {
      "x": 1,
      "y": 3,
      "z": 7,
      "name": "Empty"
    },
    {
      "x": 1,
      "y": 4,
      "z": 7,
      "name": "Empty"
    },
    {
      "x": 1,
      "y": 5,
      "z": 7,
      "name": "Empty"
    },
    {
      "x": 1,
      "y": 6,
      "z": 7,
      "name": "Rock_Stone_Brick_Smooth",
      "rotation": 3
    },
    {
      "x": 1,
      "y": 0,
      "z": 8,
      "name": "Rock_Stone_Brick_Smooth",
      "rotation": 2
    },
    {
      "x": 1,
      "y": 1,
      "z": 8,
      "name": "Empty"
    },
    {
      "x": 1,
      "y": 2,
      "z": 8,
      "name": "Empty"
    },
    {
      "x": 1,
      "y": 3,
      "z": 8,
      "name": "Empty"
    },
    {
      "x": 1,
      "y": 4,
      "z": 8,
      "name": "Empty"
    },
    {
      "x": 1,
      "y": 5,
      "z": 8,
      "name": "Empty"
    },
    {
      "x": 1,
      "y": 6,
      "z": 8,
      "name": "Rock_Stone_Brick_Smooth",
      "rotation": 3
    },
    {
      "x": 1,
      "y": 0,
      "z": 9,
      "name": "Rock_Stone_Brick_Smooth",
      "rotation": 2
    },
    {
      "x": 1,
      "y": 1,
      "z": 9,
      "name": "Empty"
    },
    {
      "x": 1,
      "y": 2,
      "z": 9,
      "name": "Empty"
    },
    {
      "x": 1,
      "y": 3,
      "z": 9,
      "name": "Empty"
    },
    {
      "x": 1,
      "y": 4,
      "z": 9,
      "name": "Empty"
    },
    {
      "x": 1,
      "y": 5,
      "z": 9,
      "name": "Empty"
    },
    {
      "x": 1,
      "y": 6,
      "z": 9,
      "name": "Rock_Stone_Brick_Smooth",
      "rotation": 3
    },
    {
      "x": 1,
      "y": 0,
      "z": 10,
      "name": "Rock_Stone_Brick_Smooth",
      "rotation": 2
    },
    {
      "x": 1,
      "y": 1,
      "z": 10,
      "name": "Empty"
    },
    {
      "x": 1,
      "y": 2,
      "z": 10,
      "name": "Empty"
    },
    {
      "x": 1,
      "y": 3,
      "z": 10,
      "name": "Empty"
    },
    {
      "x": 1,
      "y": 4,
      "z": 10,
      "name": "Empty"
    },
    {
      "x": 1,
      "y": 5,
      "z": 10,
      "name": "Empty"
    },
    {
      "x": 1,
      "y": 6,
      "z": 10,
      "name": "Rock_Stone_Brick_Smooth",
      "rotation": 2
    },
    {
      "x": 1,
      "y": 0,
      "z": 11,
      "name": "Rock_Stone_Brick_Smooth",
      "rotation": 2
    },
    {
      "x": 1,
      "y": 1,
      "z": 11,
      "name": "Rock_Stone_Brick_Smooth_Half",
      "rotation": 7
    },
    {
      "x": 1,
      "y": 2,
      "z": 11,
      "name": "Rock_Stone_Brick_Smooth_Half",
      "rotation": 7
    },
    {
      "x": 1,
      "y": 3,
      "z": 11,
      "name": "Rock_Stone_Brick_Smooth_Half",
      "rotation": 7
    },
    {
      "x": 1,
      "y": 4,
      "z": 11,
      "name": "*Rock_Stone_Brick_Stairs_State_Definitions_Inverted_Corner_Left",
      "rotation": 35
    },
    {
      "x": 1,
      "y": 5,
      "z": 11,
      "name": "Rock_Stone_Brick_Decorative",
      "rotation": 2
    },
    {
      "x": 1,
      "y": 6,
      "z": 11,
      "name": "Rock_Stone_Brick_Smooth",
      "rotation": 2
    },
    {
      "x": 2,
      "y": 0,
      "z": -10,
      "name": "Rock_Stone_Brick"
    },
    {
      "x": 2,
      "y": 1,
      "z": -10,
      "name": "Rock_Stone_Brick_Decorative"
    },
    {
      "x": 2,
      "y": 2,
      "z": -10,
      "name": "Rock_Stone_Brick",
      "rotation": 1
    },
    {
      "x": 2,
      "y": 3,
      "z": -10,
      "name": "Rock_Stone_Brick",
      "rotation": 1
    },
    {
      "x": 2,
      "y": 4,
      "z": -10,
      "name": "Rock_Stone_Brick",
      "rotation": 1
    },
    {
      "x": 2,
      "y": 5,
      "z": -10,
      "name": "Rock_Stone_Brick_Decorative",
      "rotation": 1
    },
    {
      "x": 2,
      "y": 6,
      "z": -10,
      "name": "Rock_Stone_Brick",
      "rotation": 1
    },
    {
      "x": 2,
      "y": 0,
      "z": -9,
      "name": "Rock_Stone_Brick"
    },
    {
      "x": 2,
      "y": 1,
      "z": -9,
      "name": "Rock_Stone_Brick_Decorative"
    },
    {
      "x": 2,
      "y": 2,
      "z": -9,
      "name": "Soil_Gravel_Half",
      "support": 15,
      "rotation": 7
    },
    {
      "x": 2,
      "y": 3,
      "z": -9,
      "name": "Soil_Gravel_Half",
      "support": 15,
      "rotation": 7
    },
    {
      "x": 2,
      "y": 4,
      "z": -9,
      "name": "Soil_Gravel_Half",
      "support": 15,
      "rotation": 7
    },
    {
      "x": 2,
      "y": 5,
      "z": -9,
      "name": "Soil_Gravel_Half",
      "support": 15,
      "rotation": 7
    },
    {
      "x": 2,
      "y": 6,
      "z": -9,
      "name": "Rock_Stone_Brick",
      "rotation": 1
    },
    {
      "x": 2,
      "y": 0,
      "z": -8,
      "name": "Rock_Stone_Brick",
      "rotation": 3
    },
    {
      "x": 2,
      "y": 1,
      "z": -8,
      "name": "Rock_Stone_Brick_Decorative",
      "rotation": 3
    },
    {
      "x": 2,
      "y": 2,
      "z": -8,
      "name": "Soil_Gravel_Half",
      "support": 15,
      "rotation": 7
    },
    {
      "x": 2,
      "y": 3,
      "z": -8,
      "name": "Soil_Gravel_Half",
      "support": 15,
      "rotation": 7
    },
    {
      "x": 2,
      "y": 4,
      "z": -8,
      "name": "Soil_Gravel_Half",
      "support": 15,
      "rotation": 7
    },
    {
      "x": 2,
      "y": 5,
      "z": -8,
      "name": "Soil_Gravel_Half",
      "support": 15,
      "rotation": 7
    },
    {
      "x": 2,
      "y": 6,
      "z": -8,
      "name": "Rock_Stone_Brick",
      "rotation": 1
    },
    {
      "x": 2,
      "y": 0,
      "z": -7,
      "name": "Rock_Stone_Brick"
    },
    {
      "x": 2,
      "y": 1,
      "z": -7,
      "name": "Rock_Stone_Brick_Decorative"
    },
    {
      "x": 2,
      "y": 2,
      "z": -7,
      "name": "Soil_Gravel_Half",
      "support": 15,
      "rotation": 7
    },
    {
      "x": 2,
      "y": 3,
      "z": -7,
      "name": "Soil_Gravel_Half",
      "support": 15,
      "rotation": 7
    },
    {
      "x": 2,
      "y": 4,
      "z": -7,
      "name": "Soil_Gravel_Half",
      "support": 15,
      "rotation": 7
    },
    {
      "x": 2,
      "y": 5,
      "z": -7,
      "name": "Soil_Gravel_Half",
      "support": 15,
      "rotation": 7
    },
    {
      "x": 2,
      "y": 6,
      "z": -7,
      "name": "Rock_Stone_Brick",
      "rotation": 1
    },
    {
      "x": 2,
      "y": 0,
      "z": -6,
      "name": "Rock_Stone_Brick_Smooth",
      "rotation": 3
    },
    {
      "x": 2,
      "y": 1,
      "z": -6,
      "name": "Rock_Stone_Brick_Decorative",
      "rotation": 1
    },
    {
      "x": 2,
      "y": 2,
      "z": -6,
      "name": "Rock_Stone_Brick_Pillar_Base"
    },
    {
      "x": 2,
      "y": 3,
      "z": -6,
      "name": "Rock_Stone_Brick_Pillar_Middle"
    },
    {
      "x": 2,
      "y": 4,
      "z": -6,
      "name": "Rock_Stone_Brick_Pillar_Middle"
    },
    {
      "x": 2,
      "y": 5,
      "z": -6,
      "name": "Rock_Stone_Brick_Pillar_Base",
      "rotation": 34
    },
    {
      "x": 2,
      "y": 6,
      "z": -6,
      "name": "Rock_Stone_Brick",
      "rotation": 1
    },
    {
      "x": 2,
      "y": 0,
      "z": -5,
      "name": "Rock_Stone_Brick_Smooth",
      "rotation": 3
    },
    {
      "x": 2,
      "y": 1,
      "z": -5,
      "name": "Empty"
    },
    {
      "x": 2,
      "y": 2,
      "z": -5,
      "name": "Empty"
    },
    {
      "x": 2,
      "y": 3,
      "z": -5,
      "name": "Empty"
    },
    {
      "x": 2,
      "y": 4,
      "z": -5,
      "name": "Empty"
    },
    {
      "x": 2,
      "y": 5,
      "z": -5,
      "name": "Empty"
    },
    {
      "x": 2,
      "y": 6,
      "z": -5,
      "name": "Rock_Stone_Brick_Smooth"
    },
    {
      "x": 2,
      "y": 0,
      "z": -4,
      "name": "Rock_Stone_Brick_Smooth",
      "rotation": 3
    },
    {
      "x": 2,
      "y": 1,
      "z": -4,
      "name": "Empty"
    },
    {
      "x": 2,
      "y": 2,
      "z": -4,
      "name": "Empty"
    },
    {
      "x": 2,
      "y": 3,
      "z": -4,
      "name": "Empty"
    },
    {
      "x": 2,
      "y": 4,
      "z": -4,
      "name": "Empty"
    },
    {
      "x": 2,
      "y": 5,
      "z": -4,
      "name": "Empty"
    },
    {
      "x": 2,
      "y": 6,
      "z": -4,
      "name": "Rock_Stone_Brick_Smooth"
    },
    {
      "x": 2,
      "y": 0,
      "z": -3,
      "name": "Rock_Stone_Brick_Smooth"
    },
    {
      "x": 2,
      "y": 1,
      "z": -3,
      "name": "Empty"
    },
    {
      "x": 2,
      "y": 2,
      "z": -3,
      "name": "Empty"
    },
    {
      "x": 2,
      "y": 3,
      "z": -3,
      "name": "Empty"
    },
    {
      "x": 2,
      "y": 4,
      "z": -3,
      "name": "Empty"
    },
    {
      "x": 2,
      "y": 5,
      "z": -3,
      "name": "Empty"
    },
    {
      "x": 2,
      "y": 6,
      "z": -3,
      "name": "Rock_Stone_Brick_Smooth"
    },
    {
      "x": 2,
      "y": 0,
      "z": -2,
      "name": "Rock_Stone_Brick"
    },
    {
      "x": 2,
      "y": 1,
      "z": -2,
      "name": "Rock_Stone_Brick_Decorative",
      "rotation": 3
    },
    {
      "x": 2,
      "y": 2,
      "z": -2,
      "name": "Rock_Stone_Brick_Pillar_Base",
      "rotation": 3
    },
    {
      "x": 2,
      "y": 3,
      "z": -2,
      "name": "Rock_Stone_Brick_Pillar_Middle",
      "rotation": 3
    },
    {
      "x": 2,
      "y": 4,
      "z": -2,
      "name": "Rock_Stone_Brick_Pillar_Middle",
      "rotation": 3
    },
    {
      "x": 2,
      "y": 5,
      "z": -2,
      "name": "Rock_Stone_Brick_Pillar_Base",
      "rotation": 33
    },
    {
      "x": 2,
      "y": 6,
      "z": -2,
      "name": "Rock_Stone_Brick",
      "rotation": 1
    },
    {
      "x": 2,
      "y": 0,
      "z": -1,
      "name": "Rock_Stone_Brick"
    },
    {
      "x": 2,
      "y": 1,
      "z": -1,
      "name": "Rock_Stone_Brick_Decorative",
      "rotation": 2
    },
    {
      "x": 2,
      "y": 2,
      "z": -1,
      "name": "Soil_Gravel_Half",
      "support": 15,
      "rotation": 7
    },
    {
      "x": 2,
      "y": 3,
      "z": -1,
      "name": "Soil_Gravel_Half",
      "support": 15,
      "rotation": 7
    },
    {
      "x": 2,
      "y": 4,
      "z": -1,
      "name": "Soil_Gravel_Half",
      "support": 15,
      "rotation": 7
    },
    {
      "x": 2,
      "y": 5,
      "z": -1,
      "name": "Soil_Gravel_Half",
      "support": 15,
      "rotation": 7
    },
    {
      "x": 2,
      "y": 6,
      "z": -1,
      "name": "Rock_Stone_Brick"
    },
    {
      "x": 2,
      "y": 0,
      "z": 0,
      "name": "Rock_Stone_Brick_Smooth",
      "rotation": 2
    },
    {
      "x": 2,
      "y": 1,
      "z": 0,
      "name": "Rock_Stone_Brick_Decorative"
    },
    {
      "x": 2,
      "y": 2,
      "z": 0,
      "name": "Soil_Gravel_Half",
      "support": 15,
      "rotation": 7
    },
    {
      "x": 2,
      "y": 3,
      "z": 0,
      "name": "Soil_Gravel_Half",
      "support": 15,
      "rotation": 7
    },
    {
      "x": 2,
      "y": 4,
      "z": 0,
      "name": "Soil_Gravel_Half",
      "support": 15,
      "rotation": 7
    },
    {
      "x": 2,
      "y": 5,
      "z": 0,
      "name": "Soil_Gravel_Half",
      "support": 15,
      "rotation": 7
    },
    {
      "x": 2,
      "y": 6,
      "z": 0,
      "name": "Rock_Stone_Brick"
    },
    {
      "x": 2,
      "y": 0,
      "z": 1,
      "name": "Rock_Stone_Brick"
    },
    {
      "x": 2,
      "y": 1,
      "z": 1,
      "name": "Rock_Stone_Brick_Decorative"
    },
    {
      "x": 2,
      "y": 2,
      "z": 1,
      "name": "Soil_Gravel_Half",
      "support": 15,
      "rotation": 7
    },
    {
      "x": 2,
      "y": 3,
      "z": 1,
      "name": "Soil_Gravel_Half",
      "support": 15,
      "rotation": 7
    },
    {
      "x": 2,
      "y": 4,
      "z": 1,
      "name": "Soil_Gravel_Half",
      "support": 15,
      "rotation": 7
    },
    {
      "x": 2,
      "y": 5,
      "z": 1,
      "name": "Soil_Gravel_Half",
      "support": 15,
      "rotation": 7
    },
    {
      "x": 2,
      "y": 6,
      "z": 1,
      "name": "Rock_Stone_Brick"
    },
    {
      "x": 2,
      "y": 0,
      "z": 2,
      "name": "Rock_Stone_Brick"
    },
    {
      "x": 2,
      "y": 1,
      "z": 2,
      "name": "Rock_Stone_Brick_Decorative"
    },
    {
      "x": 2,
      "y": 2,
      "z": 2,
      "name": "Soil_Gravel_Half",
      "support": 15,
      "rotation": 7
    },
    {
      "x": 2,
      "y": 3,
      "z": 2,
      "name": "Soil_Gravel_Half",
      "support": 15,
      "rotation": 7
    },
    {
      "x": 2,
      "y": 4,
      "z": 2,
      "name": "Soil_Gravel_Half",
      "support": 15,
      "rotation": 7
    },
    {
      "x": 2,
      "y": 5,
      "z": 2,
      "name": "Soil_Gravel_Half",
      "support": 15,
      "rotation": 7
    },
    {
      "x": 2,
      "y": 6,
      "z": 2,
      "name": "Rock_Stone_Brick"
    },
    {
      "x": 2,
      "y": 0,
      "z": 3,
      "name": "Rock_Stone_Brick",
      "rotation": 3
    },
    {
      "x": 2,
      "y": 1,
      "z": 3,
      "name": "Rock_Stone_Brick_Decorative",
      "rotation": 3
    },
    {
      "x": 2,
      "y": 2,
      "z": 3,
      "name": "Rock_Stone_Brick_Pillar_Base"
    },
    {
      "x": 2,
      "y": 3,
      "z": 3,
      "name": "Rock_Stone_Brick_Pillar_Middle"
    },
    {
      "x": 2,
      "y": 4,
      "z": 3,
      "name": "Rock_Stone_Brick_Pillar_Middle"
    },
    {
      "x": 2,
      "y": 5,
      "z": 3,
      "name": "Rock_Stone_Brick_Pillar_Base",
      "rotation": 34
    },
    {
      "x": 2,
      "y": 6,
      "z": 3,
      "name": "Rock_Stone_Brick",
      "rotation": 1
    },
    {
      "x": 2,
      "y": 0,
      "z": 4,
      "name": "Rock_Stone_Brick_Smooth"
    },
    {
      "x": 2,
      "y": 1,
      "z": 4,
      "name": "Empty"
    },
    {
      "x": 2,
      "y": 2,
      "z": 4,
      "name": "Empty"
    },
    {
      "x": 2,
      "y": 3,
      "z": 4,
      "name": "Empty"
    },
    {
      "x": 2,
      "y": 4,
      "z": 4,
      "name": "Empty"
    },
    {
      "x": 2,
      "y": 5,
      "z": 4,
      "name": "Empty"
    },
    {
      "x": 2,
      "y": 6,
      "z": 4,
      "name": "Rock_Stone_Brick_Smooth"
    },
    {
      "x": 2,
      "y": 0,
      "z": 5,
      "name": "Rock_Stone_Brick_Smooth",
      "rotation": 3
    },
    {
      "x": 2,
      "y": 1,
      "z": 5,
      "name": "Empty"
    },
    {
      "x": 2,
      "y": 2,
      "z": 5,
      "name": "Empty"
    },
    {
      "x": 2,
      "y": 3,
      "z": 5,
      "name": "Empty"
    },
    {
      "x": 2,
      "y": 4,
      "z": 5,
      "name": "Empty"
    },
    {
      "x": 2,
      "y": 5,
      "z": 5,
      "name": "Empty"
    },
    {
      "x": 2,
      "y": 6,
      "z": 5,
      "name": "Rock_Stone_Brick_Smooth"
    },
    {
      "x": 2,
      "y": 0,
      "z": 6,
      "name": "Rock_Stone_Brick_Smooth",
      "rotation": 3
    },
    {
      "x": 2,
      "y": 1,
      "z": 6,
      "name": "Empty"
    },
    {
      "x": 2,
      "y": 2,
      "z": 6,
      "name": "Empty"
    },
    {
      "x": 2,
      "y": 3,
      "z": 6,
      "name": "Empty"
    },
    {
      "x": 2,
      "y": 4,
      "z": 6,
      "name": "Empty"
    },
    {
      "x": 2,
      "y": 5,
      "z": 6,
      "name": "Empty"
    },
    {
      "x": 2,
      "y": 6,
      "z": 6,
      "name": "Rock_Stone_Brick_Smooth"
    },
    {
      "x": 2,
      "y": 0,
      "z": 7,
      "name": "Rock_Stone_Brick_Smooth",
      "rotation": 3
    },
    {
      "x": 2,
      "y": 1,
      "z": 7,
      "name": "Rock_Stone_Brick_Decorative",
      "rotation": 1
    },
    {
      "x": 2,
      "y": 2,
      "z": 7,
      "name": "Rock_Stone_Brick_Pillar_Base",
      "rotation": 3
    },
    {
      "x": 2,
      "y": 3,
      "z": 7,
      "name": "Rock_Stone_Brick_Pillar_Middle",
      "rotation": 3
    },
    {
      "x": 2,
      "y": 4,
      "z": 7,
      "name": "Rock_Stone_Brick_Pillar_Middle",
      "rotation": 3
    },
    {
      "x": 2,
      "y": 5,
      "z": 7,
      "name": "Rock_Stone_Brick_Pillar_Base",
      "rotation": 33
    },
    {
      "x": 2,
      "y": 6,
      "z": 7,
      "name": "Rock_Stone_Brick",
      "rotation": 1
    },
    {
      "x": 2,
      "y": 0,
      "z": 8,
      "name": "Rock_Stone_Brick",
      "rotation": 3
    },
    {
      "x": 2,
      "y": 1,
      "z": 8,
      "name": "Rock_Stone_Brick_Decorative",
      "rotation": 3
    },
    {
      "x": 2,
      "y": 2,
      "z": 8,
      "name": "Soil_Gravel_Half",
      "support": 15,
      "rotation": 7
    },
    {
      "x": 2,
      "y": 3,
      "z": 8,
      "name": "Soil_Gravel_Half",
      "support": 15,
      "rotation": 7
    },
    {
      "x": 2,
      "y": 4,
      "z": 8,
      "name": "Soil_Gravel_Half",
      "support": 15,
      "rotation": 7
    },
    {
      "x": 2,
      "y": 5,
      "z": 8,
      "name": "Soil_Gravel_Half",
      "support": 15,
      "rotation": 7
    },
    {
      "x": 2,
      "y": 6,
      "z": 8,
      "name": "Rock_Stone_Brick"
    },
    {
      "x": 2,
      "y": 0,
      "z": 9,
      "name": "Rock_Stone_Brick"
    },
    {
      "x": 2,
      "y": 1,
      "z": 9,
      "name": "Rock_Stone_Brick_Decorative",
      "rotation": 3
    },
    {
      "x": 2,
      "y": 2,
      "z": 9,
      "name": "Soil_Gravel_Half",
      "support": 15,
      "rotation": 7
    },
    {
      "x": 2,
      "y": 3,
      "z": 9,
      "name": "Soil_Gravel_Half",
      "support": 15,
      "rotation": 7
    },
    {
      "x": 2,
      "y": 4,
      "z": 9,
      "name": "Soil_Gravel_Half",
      "support": 15,
      "rotation": 7
    },
    {
      "x": 2,
      "y": 5,
      "z": 9,
      "name": "Soil_Gravel_Half",
      "support": 15,
      "rotation": 7
    },
    {
      "x": 2,
      "y": 6,
      "z": 9,
      "name": "Rock_Stone_Brick"
    },
    {
      "x": 2,
      "y": 0,
      "z": 10,
      "name": "Rock_Stone_Brick"
    },
    {
      "x": 2,
      "y": 1,
      "z": 10,
      "name": "Rock_Stone_Brick_Decorative",
      "rotation": 2
    },
    {
      "x": 2,
      "y": 2,
      "z": 10,
      "name": "Soil_Gravel_Half",
      "support": 15,
      "rotation": 7
    },
    {
      "x": 2,
      "y": 3,
      "z": 10,
      "name": "Soil_Gravel_Half",
      "support": 15,
      "rotation": 7
    },
    {
      "x": 2,
      "y": 4,
      "z": 10,
      "name": "Soil_Gravel_Half",
      "support": 15,
      "rotation": 7
    },
    {
      "x": 2,
      "y": 5,
      "z": 10,
      "name": "Soil_Gravel_Half",
      "support": 15,
      "rotation": 7
    },
    {
      "x": 2,
      "y": 6,
      "z": 10,
      "name": "Rock_Stone_Brick"
    },
    {
      "x": 2,
      "y": 0,
      "z": 11,
      "name": "Rock_Stone_Brick"
    },
    {
      "x": 2,
      "y": 1,
      "z": 11,
      "name": "Rock_Stone_Brick",
      "rotation": 2
    },
    {
      "x": 2,
      "y": 2,
      "z": 11,
      "name": "Rock_Stone_Brick",
      "rotation": 2
    },
    {
      "x": 2,
      "y": 3,
      "z": 11,
      "name": "Rock_Stone_Brick",
      "rotation": 2
    },
    {
      "x": 2,
      "y": 4,
      "z": 11,
      "name": "Rock_Stone_Brick",
      "rotation": 2
    },
    {
      "x": 2,
      "y": 5,
      "z": 11,
      "name": "Rock_Stone_Brick_Decorative",
      "rotation": 2
    },
    {
      "x": 2,
      "y": 6,
      "z": 11,
      "name": "Rock_Stone_Brick",
      "rotation": 3
    },
    {
      "x": 3,
      "y": 0,
      "z": -10,
      "name": "Rock_Stone_Brick",
      "rotation": 1
    },
    {
      "x": 3,
      "y": 1,
      "z": -10,
      "name": "Rock_Stone_Brick_Decorative"
    },
    {
      "x": 3,
      "y": 2,
      "z": -10,
      "name": "Soil_Gravel",
      "support": 15
    },
    {
      "x": 3,
      "y": 3,
      "z": -10,
      "name": "Soil_Gravel",
      "support": 15
    },
    {
      "x": 3,
      "y": 4,
      "z": -10,
      "name": "Soil_Gravel",
      "support": 15
    },
    {
      "x": 3,
      "y": 5,
      "z": -10,
      "name": "Soil_Gravel",
      "support": 15
    },
    {
      "x": 3,
      "y": 6,
      "z": -10,
      "name": "Rock_Stone_Brick_Smooth"
    },
    {
      "x": 3,
      "y": 0,
      "z": -9,
      "name": "Rock_Stone_Brick",
      "rotation": 1
    },
    {
      "x": 3,
      "y": 1,
      "z": -9,
      "name": "Rock_Stone_Brick_Decorative"
    },
    {
      "x": 3,
      "y": 2,
      "z": -9,
      "name": "Soil_Gravel",
      "support": 15
    },
    {
      "x": 3,
      "y": 3,
      "z": -9,
      "name": "Soil_Gravel",
      "support": 15
    },
    {
      "x": 3,
      "y": 4,
      "z": -9,
      "name": "Soil_Gravel",
      "support": 15
    },
    {
      "x": 3,
      "y": 5,
      "z": -9,
      "name": "Soil_Gravel",
      "support": 15
    },
    {
      "x": 3,
      "y": 6,
      "z": -9,
      "name": "Rock_Stone_Brick_Smooth"
    },
    {
      "x": 3,
      "y": 0,
      "z": -8,
      "name": "Rock_Stone_Brick",
      "rotation": 1
    },
    {
      "x": 3,
      "y": 1,
      "z": -8,
      "name": "Rock_Stone_Brick_Decorative",
      "rotation": 3
    },
    {
      "x": 3,
      "y": 2,
      "z": -8,
      "name": "Soil_Gravel",
      "support": 15,
      "rotation": 3
    },
    {
      "x": 3,
      "y": 3,
      "z": -8,
      "name": "Soil_Gravel",
      "support": 15,
      "rotation": 3
    },
    {
      "x": 3,
      "y": 4,
      "z": -8,
      "name": "Soil_Gravel",
      "support": 15,
      "rotation": 3
    },
    {
      "x": 3,
      "y": 5,
      "z": -8,
      "name": "Soil_Gravel",
      "support": 15,
      "rotation": 3
    },
    {
      "x": 3,
      "y": 6,
      "z": -8,
      "name": "Rock_Stone_Brick_Smooth",
      "rotation": 3
    },
    {
      "x": 3,
      "y": 0,
      "z": -7,
      "name": "Rock_Stone_Brick",
      "rotation": 1
    },
    {
      "x": 3,
      "y": 1,
      "z": -7,
      "name": "Rock_Stone_Brick_Decorative",
      "rotation": 1
    },
    {
      "x": 3,
      "y": 2,
      "z": -7,
      "name": "Soil_Gravel",
      "support": 15
    },
    {
      "x": 3,
      "y": 3,
      "z": -7,
      "name": "Soil_Gravel",
      "support": 15
    },
    {
      "x": 3,
      "y": 4,
      "z": -7,
      "name": "Soil_Gravel",
      "support": 15
    },
    {
      "x": 3,
      "y": 5,
      "z": -7,
      "name": "Soil_Gravel",
      "support": 15
    },
    {
      "x": 3,
      "y": 6,
      "z": -7,
      "name": "Rock_Stone_Brick_Smooth"
    },
    {
      "x": 3,
      "y": 0,
      "z": -6,
      "name": "Rock_Stone_Brick",
      "rotation": 1
    },
    {
      "x": 3,
      "y": 1,
      "z": -6,
      "name": "Rock_Stone_Brick_Decorative",
      "rotation": 1
    },
    {
      "x": 3,
      "y": 2,
      "z": -6,
      "name": "Soil_Gravel_Half",
      "support": 15,
      "rotation": 4
    },
    {
      "x": 3,
      "y": 3,
      "z": -6,
      "name": "Soil_Gravel_Half",
      "support": 15,
      "rotation": 4
    },
    {
      "x": 3,
      "y": 4,
      "z": -6,
      "name": "Soil_Gravel_Half",
      "support": 15,
      "rotation": 4
    },
    {
      "x": 3,
      "y": 5,
      "z": -6,
      "name": "Soil_Gravel_Half",
      "support": 15,
      "rotation": 4
    },
    {
      "x": 3,
      "y": 6,
      "z": -6,
      "name": "Rock_Stone_Brick"
    },
    {
      "x": 3,
      "y": 0,
      "z": -5,
      "name": "Rock_Stone_Brick_Smooth"
    },
    {
      "x": 3,
      "y": 1,
      "z": -5,
      "name": "Empty"
    },
    {
      "x": 3,
      "y": 2,
      "z": -5,
      "name": "Empty"
    },
    {
      "x": 3,
      "y": 3,
      "z": -5,
      "name": "Empty"
    },
    {
      "x": 3,
      "y": 4,
      "z": -5,
      "name": "Empty"
    },
    {
      "x": 3,
      "y": 5,
      "z": -5,
      "name": "Empty"
    },
    {
      "x": 3,
      "y": 6,
      "z": -5,
      "name": "Rock_Stone_Brick_Smooth",
      "rotation": 2
    },
    {
      "x": 3,
      "y": 0,
      "z": -4,
      "name": "Rock_Stone_Brick_Smooth"
    },
    {
      "x": 3,
      "y": 1,
      "z": -4,
      "name": "Empty"
    },
    {
      "x": 3,
      "y": 2,
      "z": -4,
      "name": "Empty"
    },
    {
      "x": 3,
      "y": 3,
      "z": -4,
      "name": "Empty"
    },
    {
      "x": 3,
      "y": 4,
      "z": -4,
      "name": "Empty"
    },
    {
      "x": 3,
      "y": 5,
      "z": -4,
