{
  "version": 8,
  "blockIdVersion": 11,
  "anchorX": 0,
  "anchorY": 18,
  "anchorZ": 0,
  "blocks": [
    {
      "x": -16,
      "y": 21,
      "z": -10,
      "name": "Cloth_Block_Wool_Green"
    },
    {
      "x": -16,
      "y": 21,
      "z": -9,
      "name": "Cloth_Block_Wool_Green"
    },
    {
      "x": -16,
      "y": 21,
      "z": -8,
      "name": "Cloth_Block_Wool_Green"
    },
    {
      "x": -16,
      "y": 21,
      "z": -7,
      "name": "Cloth_Block_Wool_Green"
    },
    {
      "x": -16,
      "y": 21,
      "z": -6,
      "name": "Cloth_Block_Wool_Green"
    },
    {
      "x": -16,
      "y": 21,
      "z": -5,
      "name": "Cloth_Block_Wool_Green"
    },
    {
      "x": -16,
      "y": 21,
      "z": -4,
      "name": "Cloth_Block_Wool_Green"
    },
    {
      "x": -16,
      "y": 21,
      "z": -3,
      "name": "Cloth_Block_Wool_Green"
    },
    {
      "x": -16,
      "y": 21,
      "z": -2,
      "name": "Cloth_Block_Wool_Green"
    },
    {
      "x": -16,
      "y": 9,
      "z": -1,
      "name": "Rock_Stone_Brick_Smooth"
    },
    {
      "x": -16,
      "y": 10,
      "z": -1,
      "name": "Soil_Gravel",
      "support": 15
    },
    {
      "x": -16,
      "y": 11,
      "z": -1,
      "name": "Soil_Gravel",
      "support": 15
    },
    {
      "x": -16,
      "y": 12,
      "z": -1,
      "name": "Soil_Gravel",
      "support": 15
    },
    {
      "x": -16,
      "y": 13,
      "z": -1,
      "name": "Soil_Gravel",
      "support": 15
    },
    {
      "x": -16,
      "y": 14,
      "z": -1,
      "name": "Soil_Gravel",
      "support": 15
    },
    {
      "x": -16,
      "y": 15,
      "z": -1,
      "name": "Rock_Stone_Brick_Smooth"
    },
    {
      "x": -16,
      "y": 16,
      "z": -1,
      "name": "Soil_Gravel",
      "support": 15,
      "rotation": 3
    },
    {
      "x": -16,
      "y": 17,
      "z": -1,
      "name": "Soil_Gravel",
      "support": 15,
      "rotation": 3
    },
    {
      "x": -16,
      "y": 21,
      "z": -1,
      "name": "Cloth_Block_Wool_Green"
    },
    {
      "x": -16,
      "y": 9,
      "z": 0,
      "name": "Rock_Stone_Brick_Smooth"
    },
    {
      "x": -16,
      "y": 10,
      "z": 0,
      "name": "Soil_Gravel",
      "support": 15
    },
    {
      "x": -16,
      "y": 11,
      "z": 0,
      "name": "Soil_Gravel",
      "support": 15
    },
    {
      "x": -16,
      "y": 12,
      "z": 0,
      "name": "Soil_Gravel",
      "support": 15
    },
    {
      "x": -16,
      "y": 13,
      "z": 0,
      "name": "Soil_Gravel",
      "support": 15
    },
    {
      "x": -16,
      "y": 14,
      "z": 0,
      "name": "Soil_Gravel",
      "support": 15
    },
    {
      "x": -16,
      "y": 15,
      "z": 0,
      "name": "Rock_Stone_Brick_Smooth"
    },
    {
      "x": -16,
      "y": 16,
      "z": 0,
      "name": "Soil_Gravel",
      "support": 15,
      "rotation": 3
    },
    {
      "x": -16,
      "y": 17,
      "z": 0,
      "name": "Soil_Gravel",
      "support": 15,
      "rotation": 3
    },
    {
      "x": -16,
      "y": 21,
      "z": 0,
      "name": "Cloth_Block_Wool_Green"
    },
    {
      "x": -16,
      "y": 9,
      "z": 1,
      "name": "Rock_Stone_Brick_Smooth"
    },
    {
      "x": -16,
      "y": 10,
      "z": 1,
      "name": "Soil_Gravel",
      "support": 15
    },
    {
      "x": -16,
      "y": 11,
      "z": 1,
      "name": "Soil_Gravel",
      "support": 15
    },
    {
      "x": -16,
      "y": 12,
      "z": 1,
      "name": "Soil_Gravel",
      "support": 15
    },
    {
      "x": -16,
      "y": 13,
      "z": 1,
      "name": "Soil_Gravel",
      "support": 15
    },
    {
      "x": -16,
      "y": 14,
      "z": 1,
      "name": "Soil_Gravel",
      "support": 15
    },
    {
      "x": -16,
      "y": 15,
      "z": 1,
      "name": "Rock_Stone_Brick_Smooth"
    },
    {
      "x": -16,
      "y": 16,
      "z": 1,
      "name": "Soil_Gravel",
      "support": 15,
      "rotation": 3
    },
    {
      "x": -16,
      "y": 17,
      "z": 1,
      "name": "Soil_Gravel",
      "support": 15,
      "rotation": 3
    },
    {
      "x": -16,
      "y": 21,
      "z": 1,
      "name": "Cloth_Block_Wool_Pink"
    },
    {
      "x": -16,
      "y": 9,
      "z": 2,
      "name": "Rock_Stone_Brick_Smooth"
    },
    {
      "x": -16,
      "y": 10,
      "z": 2,
      "name": "Soil_Gravel",
      "support": 15
    },
    {
      "x": -16,
      "y": 11,
      "z": 2,
      "name": "Soil_Gravel",
      "support": 15
    },
    {
      "x": -16,
      "y": 12,
      "z": 2,
      "name": "Soil_Gravel",
      "support": 15
    },
    {
      "x": -16,
      "y": 13,
      "z": 2,
      "name": "Soil_Gravel",
      "support": 15
    },
    {
      "x": -16,
      "y": 14,
      "z": 2,
      "name": "Soil_Gravel",
      "support": 15
    },
    {
      "x": -16,
      "y": 15,
      "z": 2,
      "name": "Rock_Stone_Brick_Smooth"
    },
    {
      "x": -16,
      "y": 16,
      "z": 2,
      "name": "Soil_Gravel",
      "support": 15
    },
    {
      "x": -16,
      "y": 17,
      "z": 2,
      "name": "Soil_Gravel",
      "support": 15
    },
    {
      "x": -16,
      "y": 21,
      "z": 2,
      "name": "Cloth_Block_Wool_Pink"
    },
    {
      "x": -16,
      "y": 21,
      "z": 3,
      "name": "Cloth_Block_Wool_Pink"
    },
    {
      "x": -16,
      "y": 21,
      "z": 4,
      "name": "Cloth_Block_Wool_Pink"
    },
    {
      "x": -16,
      "y": 21,
      "z": 5,
      "name": "Cloth_Block_Wool_Pink"
    },
    {
      "x": -16,
      "y": 21,
      "z": 6,
      "name": "Cloth_Block_Wool_Pink"
    },
    {
      "x": -16,
      "y": 21,
      "z": 7,
      "name": "Cloth_Block_Wool_Pink"
    },
    {
      "x": -16,
      "y": 21,
      "z": 8,
      "name": "Cloth_Block_Wool_Pink"
    },
    {
      "x": -16,
      "y": 21,
      "z": 9,
      "name": "Cloth_Block_Wool_Pink"
    },
    {
      "x": -16,
      "y": 21,
      "z": 10,
      "name": "Cloth_Block_Wool_Pink"
    },
    {
      "x": -16,
      "y": 21,
      "z": 11,
      "name": "Cloth_Block_Wool_Pink"
    },
    {
      "x": -15,
      "y": 21,
      "z": -10,
      "name": "Cloth_Block_Wool_Green"
    },
    {
      "x": -15,
      "y": 9,
      "z": -4,
      "name": "Rock_Stone_Brick_Smooth"
    },
    {
      "x": -15,
      "y": 10,
      "z": -4,
      "name": "Rock_Stone_Brick_Decorative"
    },
    {
      "x": -15,
      "y": 11,
      "z": -4,
      "name": "Rock_Stone_Brick"
    },
    {
      "x": -15,
      "y": 12,
      "z": -4,
      "name": "Rock_Stone_Brick"
    },
    {
      "x": -15,
      "y": 13,
      "z": -4,
      "name": "Rock_Stone_Brick"
    },
    {
      "x": -15,
      "y": 14,
      "z": -4,
      "name": "Rock_Stone_Brick"
    },
    {
      "x": -15,
      "y": 15,
      "z": -4,
      "name": "Rock_Stone_Brick_Smooth"
    },
    {
      "x": -15,
      "y": 9,
      "z": -3,
      "name": "Rock_Stone_Brick_Smooth"
    },
    {
      "x": -15,
      "y": 10,
      "z": -3,
      "name": "Rock_Stone_Brick_Decorative"
    },
    {
      "x": -15,
      "y": 11,
      "z": -3,
      "name": "Rock_Stone_Brick"
    },
    {
      "x": -15,
      "y": 12,
      "z": -3,
      "name": "Rock_Stone_Brick"
    },
    {
      "x": -15,
      "y": 13,
      "z": -3,
      "name": "Rock_Stone_Brick"
    },
    {
      "x": -15,
      "y": 14,
      "z": -3,
      "name": "Rock_Stone_Brick"
    },
    {
      "x": -15,
      "y": 15,
      "z": -3,
      "name": "Rock_Stone_Brick_Smooth"
    },
    {
      "x": -15,
      "y": 16,
      "z": -3,
      "name": "Soil_Gravel",
      "support": 15,
      "rotation": 3
    },
    {
      "x": -15,
      "y": 9,
      "z": -2,
      "name": "Rock_Stone_Brick_Smooth"
    },
    {
      "x": -15,
      "y": 10,
      "z": -2,
      "name": "Rock_Stone_Brick_Decorative"
    },
    {
      "x": -15,
      "y": 11,
      "z": -2,
      "name": "Rock_Stone_Brick"
    },
    {
      "x": -15,
      "y": 12,
      "z": -2,
      "name": "Rock_Stone_Brick"
    },
    {
      "x": -15,
      "y": 13,
      "z": -2,
      "name": "Rock_Stone_Brick"
    },
    {
      "x": -15,
      "y": 14,
      "z": -2,
      "name": "Rock_Stone_Brick"
    },
    {
      "x": -15,
      "y": 15,
      "z": -2,
      "name": "Rock_Stone_Brick_Smooth"
    },
    {
      "x": -15,
      "y": 16,
      "z": -2,
      "name": "Soil_Gravel",
      "support": 15,
      "rotation": 3
    },
    {
      "x": -15,
      "y": 17,
      "z": -2,
      "name": "Soil_Gravel",
      "support": 15,
      "rotation": 3
    },
    {
      "x": -15,
      "y": 9,
      "z": -1,
      "name": "Rock_Stone_Brick_Smooth"
    },
    {
      "x": -15,
      "y": 10,
      "z": -1,
      "name": "Rock_Stone_Brick_Smooth_Half",
      "rotation": 4
    },
    {
      "x": -15,
      "y": 11,
      "z": -1,
      "name": "Rock_Stone_Brick_Smooth_Half",
      "rotation": 4
    },
    {
      "x": -15,
      "y": 12,
      "z": -1,
      "name": "Rock_Stone_Brick_Smooth_Half",
      "rotation": 4
    },
    {
      "x": -15,
      "y": 13,
      "z": -1,
      "name": "Rock_Stone_Brick_Smooth_Half",
      "rotation": 4
    },
    {
      "x": -15,
      "y": 14,
      "z": -1,
      "name": "Rock_Stone_Brick_Smooth_Half",
      "rotation": 4
    },
    {
      "x": -15,
      "y": 15,
      "z": -1,
      "name": "Rock_Stone_Brick_Smooth"
    },
    {
      "x": -15,
      "y": 16,
      "z": -1,
      "name": "Rock_Stone_Brick_Smooth_Half",
      "rotation": 4
    },
    {
      "x": -15,
      "y": 17,
      "z": -1,
      "name": "Cloth_Block_Wool_Pink",
      "rotation": 3
    },
    {
      "x": -15,
      "y": 9,
      "z": 0,
      "name": "Rock_Stone_Brick_Smooth"
    },
    {
      "x": -15,
      "y": 10,
      "z": 0,
      "name": "Furniture_Village_Coffin",
      "rotation": 3
    },
    {
      "x": -15,
      "y": 15,
      "z": 0,
      "name": "Rock_Stone_Brick_Smooth"
    },
    {
      "x": -15,
      "y": 17,
      "z": 0,
      "name": "Cloth_Block_Wool_Pink",
      "rotation": 3
    },
    {
      "x": -15,
      "y": 21,
      "z": 0,
      "name": "Cloth_Block_Wool_Green"
    },
    {
      "x": -15,
      "y": 9,
      "z": 1,
      "name": "Rock_Stone_Brick_Smooth"
    },
    {
      "x": -15,
      "y": 10,
      "z": 1,
      "name": "Furniture_Village_Coffin",
      "filler": 32,
      "rotation": 3
    },
    {
      "x": -15,
      "y": 15,
      "z": 1,
      "name": "Rock_Stone_Brick_Smooth"
    },
    {
      "x": -15,
      "y": 17,
      "z": 1,
      "name": "Cloth_Block_Wool_Pink",
      "rotation": 3
    },
    {
      "x": -15,
      "y": 21,
      "z": 1,
      "name": "Cloth_Block_Wool_Pink"
    },
    {
      "x": -15,
      "y": 9,
      "z": 2,
      "name": "Rock_Stone_Brick_Smooth"
    },
    {
      "x": -15,
      "y": 10,
      "z": 2,
      "name": "Rock_Stone_Brick_Smooth_Half",
      "rotation": 6
    },
    {
      "x": -15,
      "y": 11,
      "z": 2,
      "name": "Rock_Stone_Brick_Smooth_Half",
      "rotation": 6
    },
    {
      "x": -15,
      "y": 12,
      "z": 2,
      "name": "Rock_Stone_Brick_Smooth_Half",
      "rotation": 6
    },
    {
      "x": -15,
      "y": 13,
      "z": 2,
      "name": "Rock_Stone_Brick_Smooth_Half",
      "rotation": 6
    },
    {
      "x": -15,
      "y": 14,
      "z": 2,
      "name": "Rock_Stone_Brick_Smooth_Half",
      "rotation": 6
    },
    {
      "x": -15,
      "y": 15,
      "z": 2,
      "name": "Rock_Stone_Brick_Smooth"
    },
    {
      "x": -15,
      "y": 16,
      "z": 2,
      "name": "Rock_Stone_Brick_Smooth_Half",
      "rotation": 6
    },
    {
      "x": -15,
      "y": 17,
      "z": 2,
      "name": "Cloth_Block_Wool_Pink"
    },
    {
      "x": -15,
      "y": 9,
      "z": 3,
      "name": "Rock_Stone_Brick_Smooth"
    },
    {
      "x": -15,
      "y": 10,
      "z": 3,
      "name": "Rock_Stone_Brick_Decorative"
    },
    {
      "x": -15,
      "y": 11,
      "z": 3,
      "name": "Rock_Stone_Brick"
    },
    {
      "x": -15,
      "y": 12,
      "z": 3,
      "name": "Rock_Stone_Brick"
    },
    {
      "x": -15,
      "y": 13,
      "z": 3,
      "name": "Rock_Stone_Brick"
    },
    {
      "x": -15,
      "y": 14,
      "z": 3,
      "name": "Rock_Stone_Brick"
    },
    {
      "x": -15,
      "y": 15,
      "z": 3,
      "name": "Rock_Stone_Brick_Smooth"
    },
    {
      "x": -15,
      "y": 16,
      "z": 3,
      "name": "Soil_Gravel",
      "support": 15
    },
    {
      "x": -15,
      "y": 17,
      "z": 3,
      "name": "Soil_Gravel",
      "support": 15
    },
    {
      "x": -15,
      "y": 9,
      "z": 4,
      "name": "Rock_Stone_Brick_Smooth"
    },
    {
      "x": -15,
      "y": 10,
      "z": 4,
      "name": "Rock_Stone_Brick_Decorative"
    },
    {
      "x": -15,
      "y": 11,
      "z": 4,
      "name": "Rock_Stone_Brick"
    },
    {
      "x": -15,
      "y": 12,
      "z": 4,
      "name": "Rock_Stone_Brick"
    },
    {
      "x": -15,
      "y": 13,
      "z": 4,
      "name": "Rock_Stone_Brick"
    },
    {
      "x": -15,
      "y": 14,
      "z": 4,
      "name": "Rock_Stone_Brick"
    },
    {
      "x": -15,
      "y": 15,
      "z": 4,
      "name": "Rock_Stone_Brick_Smooth"
    },
    {
      "x": -15,
      "y": 16,
      "z": 4,
      "name": "Soil_Gravel",
      "support": 15
    },
    {
      "x": -15,
      "y": 9,
      "z": 5,
      "name": "Rock_Stone_Brick_Smooth"
    },
    {
      "x": -15,
      "y": 10,
      "z": 5,
      "name": "Rock_Stone_Brick_Decorative"
    },
    {
      "x": -15,
      "y": 11,
      "z": 5,
      "name": "Rock_Stone_Brick"
    },
    {
      "x": -15,
      "y": 12,
      "z": 5,
      "name": "Rock_Stone_Brick"
    },
    {
      "x": -15,
      "y": 13,
      "z": 5,
      "name": "Rock_Stone_Brick"
    },
    {
      "x": -15,
      "y": 14,
      "z": 5,
      "name": "Rock_Stone_Brick"
    },
    {
      "x": -15,
      "y": 15,
      "z": 5,
      "name": "Rock_Stone_Brick_Smooth"
    },
    {
      "x": -15,
      "y": 21,
      "z": 11,
      "name": "Cloth_Block_Wool_Pink"
    },
    {
      "x": -14,
      "y": 21,
      "z": -10,
      "name": "Cloth_Block_Wool_Green"
    },
    {
      "x": -14,
      "y": 9,
      "z": -4,
      "name": "Rock_Stone_Brick_Smooth"
    },
    {
      "x": -14,
      "y": 10,
      "z": -4,
      "name": "Rock_Stone_Brick_Decorative"
    },
    {
      "x": -14,
      "y": 11,
      "z": -4,
      "name": "Rock_Stone_Brick"
    },
    {
      "x": -14,
      "y": 12,
      "z": -4,
      "name": "Rock_Stone_Brick"
    },
    {
      "x": -14,
      "y": 13,
      "z": -4,
      "name": "Rock_Stone_Brick"
    },
    {
      "x": -14,
      "y": 14,
      "z": -4,
      "name": "Rock_Stone_Brick"
    },
    {
      "x": -14,
      "y": 15,
      "z": -4,
      "name": "Rock_Stone_Brick_Smooth"
    },
    {
      "x": -14,
      "y": 16,
      "z": -4,
      "name": "Soil_Gravel",
      "support": 15,
      "rotation": 3
    },
    {
      "x": -14,
      "y": 9,
      "z": -3,
      "name": "Rock_Stone_Brick_Smooth"
    },
    {
      "x": -14,
      "y": 10,
      "z": -3,
      "name": "Rock_Stone_Brick_Decorative"
    },
    {
      "x": -14,
      "y": 11,
      "z": -3,
      "name": "Rock_Stone_Brick_Pillar_Base"
    },
    {
      "x": -14,
      "y": 12,
      "z": -3,
      "name": "Rock_Stone_Brick_Pillar_Middle"
    },
    {
      "x": -14,
      "y": 13,
      "z": -3,
      "name": "Rock_Stone_Brick_Pillar_Middle",
      "rotation": 34
    },
    {
      "x": -14,
      "y": 14,
      "z": -3,
      "name": "Rock_Stone_Brick_Pillar_Base",
      "rotation": 34
    },
    {
      "x": -14,
      "y": 15,
      "z": -3,
      "name": "Rock_Stone_Brick_Smooth"
    },
    {
      "x": -14,
      "y": 16,
      "z": -3,
      "name": "Soil_Gravel",
      "support": 15,
      "rotation": 3
    },
    {
      "x": -14,
      "y": 17,
      "z": -3,
      "name": "Soil_Gravel",
      "support": 15,
      "rotation": 3
    },
    {
      "x": -14,
      "y": 9,
      "z": -2,
      "name": "Rock_Stone_Brick_Smooth"
    },
    {
      "x": -14,
      "y": 11,
      "z": -2,
      "name": "Wood_Torch_Wall",
      "rotation": 1
    },
    {
      "x": -14,
      "y": 15,
      "z": -2,
      "name": "Rock_Stone_Brick_Smooth_Half",
      "rotation": 5
    },
    {
      "x": -14,
      "y": 17,
      "z": -2,
      "name": "Cloth_Block_Wool_Pink",
      "rotation": 3
    },
    {
      "x": -14,
      "y": 9,
      "z": -1,
      "name": "Rock_Stone_Brick_Smooth"
    },
    {
      "x": -14,
      "y": 17,
      "z": -1,
      "name": "Rock_Stone_Brick_Smooth_Half",
      "rotation": 4
    },
    {
      "x": -14,
      "y": 18,
      "z": -1,
      "name": "Cloth_Block_Wool_Pink",
      "rotation": 3
    },
    {
      "x": -14,
      "y": 9,
      "z": 0,
      "name": "Rock_Stone_Brick_Smooth"
    },
    {
      "x": -14,
      "y": 18,
      "z": 0,
      "name": "Cloth_Block_Wool_Pink",
      "rotation": 3
    },
    {
      "x": -14,
      "y": 21,
      "z": 0,
      "name": "Cloth_Block_Wool_Green"
    },
    {
      "x": -14,
      "y": 9,
      "z": 1,
      "name": "Rock_Stone_Brick_Smooth"
    },
    {
      "x": -14,
      "y": 18,
      "z": 1,
      "name": "Cloth_Block_Wool_Pink",
      "rotation": 3
    },
    {
      "x": -14,
      "y": 21,
      "z": 1,
      "name": "Cloth_Block_Wool_Pink"
    },
    {
      "x": -14,
      "y": 9,
      "z": 2,
      "name": "Rock_Stone_Brick_Smooth"
    },
    {
      "x": -14,
      "y": 17,
      "z": 2,
      "name": "Rock_Stone_Brick_Smooth_Half",
      "rotation": 6
    },
    {
      "x": -14,
      "y": 18,
      "z": 2,
      "name": "Cloth_Block_Wool_Pink"
    },
    {
      "x": -14,
      "y": 9,
      "z": 3,
      "name": "Rock_Stone_Brick_Smooth"
    },
    {
      "x": -14,
      "y": 11,
      "z": 3,
      "name": "Wood_Torch_Wall",
      "rotation": 1
    },
    {
      "x": -14,
      "y": 15,
      "z": 3,
      "name": "Rock_Stone_Brick_Smooth_Half",
      "rotation": 5
    },
    {
      "x": -14,
      "y": 17,
      "z": 3,
      "name": "Cloth_Block_Wool_Pink"
    },
    {
      "x": -14,
      "y": 9,
      "z": 4,
      "name": "Rock_Stone_Brick_Smooth"
    },
    {
      "x": -14,
      "y": 10,
      "z": 4,
      "name": "Rock_Stone_Brick_Decorative"
    },
    {
      "x": -14,
      "y": 11,
      "z": 4,
      "name": "Rock_Stone_Brick_Pillar_Base"
    },
    {
      "x": -14,
      "y": 12,
      "z": 4,
      "name": "Rock_Stone_Brick_Pillar_Middle"
    },
    {
      "x": -14,
      "y": 13,
      "z": 4,
      "name": "Rock_Stone_Brick_Pillar_Middle",
      "rotation": 34
    },
    {
      "x": -14,
      "y": 14,
      "z": 4,
      "name": "Rock_Stone_Brick_Pillar_Base",
      "rotation": 34
    },
    {
      "x": -14,
      "y": 15,
      "z": 4,
      "name": "Rock_Stone_Brick_Smooth"
    },
    {
      "x": -14,
      "y": 16,
      "z": 4,
      "name": "Soil_Gravel",
      "support": 15
    },
    {
      "x": -14,
      "y": 17,
      "z": 4,
      "name": "Soil_Gravel",
      "support": 15
    },
    {
      "x": -14,
      "y": 9,
      "z": 5,
      "name": "Rock_Stone_Brick_Smooth"
    },
    {
      "x": -14,
      "y": 10,
      "z": 5,
      "name": "Rock_Stone_Brick_Decorative"
    },
    {
      "x": -14,
      "y": 11,
      "z": 5,
      "name": "Rock_Stone_Brick"
    },
    {
      "x": -14,
      "y": 12,
      "z": 5,
      "name": "Rock_Stone_Brick"
    },
    {
      "x": -14,
      "y": 13,
      "z": 5,
      "name": "Rock_Stone_Brick"
    },
    {
      "x": -14,
      "y": 14,
      "z": 5,
      "name": "Rock_Stone_Brick"
    },
    {
      "x": -14,
      "y": 15,
      "z": 5,
      "name": "Rock_Stone_Brick_Smooth"
    },
    {
      "x": -14,
      "y": 16,
      "z": 5,
      "name": "Soil_Gravel",
      "support": 15
    },
    {
      "x": -14,
      "y": 21,
      "z": 11,
      "name": "Cloth_Block_Wool_Pink"
    },
    {
      "x": -13,
      "y": 21,
      "z": -10,
      "name": "Cloth_Block_Wool_Green"
    },
    {
      "x": -13,
      "y": 9,
      "z": -4,
      "name": "Rock_Stone_Brick_Smooth"
    },
    {
      "x": -13,
      "y": 10,
      "z": -4,
      "name": "Rock_Stone_Brick_Decorative"
    },
    {
      "x": -13,
      "y": 11,
      "z": -4,
      "name": "Rock_Stone_Brick"
    },
    {
      "x": -13,
      "y": 12,
      "z": -4,
      "name": "Rock_Stone_Brick"
    },
    {
      "x": -13,
      "y": 13,
      "z": -4,
      "name": "Rock_Stone_Brick"
    },
    {
      "x": -13,
      "y": 14,
      "z": -4,
      "name": "Rock_Stone_Brick"
    },
    {
      "x": -13,
      "y": 15,
      "z": -4,
      "name": "Rock_Stone_Brick_Smooth"
    },
    {
      "x": -13,
      "y": 16,
      "z": -4,
      "name": "Soil_Gravel",
      "support": 15,
      "rotation": 3
    },
    {
      "x": -13,
      "y": 17,
      "z": -4,
      "name": "Soil_Gravel",
      "support": 15,
      "rotation": 3
    },
    {
      "x": -13,
      "y": 9,
      "z": -3,
      "name": "Rock_Stone_Brick_Smooth"
    },
    {
      "x": -13,
      "y": 15,
      "z": -3,
      "name": "Rock_Stone_Brick_Smooth_Half",
      "rotation": 4
    },
    {
      "x": -13,
      "y": 17,
      "z": -3,
      "name": "Cloth_Block_Wool_Pink",
      "rotation": 3
    },
    {
      "x": -13,
      "y": 9,
      "z": -2,
      "name": "Rock_Stone_Brick_Smooth"
    },
    {
      "x": -13,
      "y": 17,
      "z": -2,
      "name": "Cloth_Block_Wool_Pink",
      "rotation": 3
    },
    {
      "x": -13,
      "y": 9,
      "z": -1,
      "name": "Rock_Stone_Brick_Smooth"
    },
    {
      "x": -13,
      "y": 17,
      "z": -1,
      "name": "Rock_Stone_Brick_Smooth_Half",
      "rotation": 4
    },
    {
      "x": -13,
      "y": 18,
      "z": -1,
      "name": "Cloth_Block_Wool_Pink",
      "rotation": 3
    },
    {
      "x": -13,
      "y": 9,
      "z": 0,
      "name": "Rock_Stone_Brick_Smooth"
    },
    {
      "x": -13,
      "y": 18,
      "z": 0,
      "name": "Cloth_Block_Wool_Pink",
      "rotation": 3
    },
    {
      "x": -13,
      "y": 21,
      "z": 0,
      "name": "Cloth_Block_Wool_Green",
      "rotation": 2
    },
    {
      "x": -13,
      "y": 9,
      "z": 1,
      "name": "Rock_Stone_Brick_Smooth"
    },
    {
      "x": -13,
      "y": 18,
      "z": 1,
      "name": "Cloth_Block_Wool_Pink",
      "rotation": 3
    },
    {
      "x": -13,
      "y": 21,
      "z": 1,
      "name": "Cloth_Block_Wool_Pink"
    },
    {
      "x": -13,
      "y": 9,
      "z": 2,
      "name": "Rock_Stone_Brick_Smooth"
    },
    {
      "x": -13,
      "y": 17,
      "z": 2,
      "name": "Rock_Stone_Brick_Smooth_Half",
      "rotation": 6
    },
    {
      "x": -13,
      "y": 18,
      "z": 2,
      "name": "Cloth_Block_Wool_Pink"
    },
    {
      "x": -13,
      "y": 9,
      "z": 3,
      "name": "Rock_Stone_Brick_Smooth"
    },
    {
      "x": -13,
      "y": 17,
      "z": 3,
      "name": "Cloth_Block_Wool_Pink"
    },
    {
      "x": -13,
      "y": 9,
      "z": 4,
      "name": "Rock_Stone_Brick_Smooth"
    },
    {
      "x": -13,
      "y": 15,
      "z": 4,
      "name": "Rock_Stone_Brick_Smooth_Half",
      "rotation": 6
    },
    {
      "x": -13,
      "y": 17,
      "z": 4,
      "name": "Cloth_Block_Wool_Pink"
    },
    {
      "x": -13,
      "y": 9,
      "z": 5,
      "name": "Rock_Stone_Brick_Smooth"
    },
    {
      "x": -13,
      "y": 10,
      "z": 5,
      "name": "Rock_Stone_Brick_Decorative"
    },
    {
      "x": -13,
      "y": 11,
      "z": 5,
      "name": "Rock_Stone_Brick"
    },
    {
      "x": -13,
      "y": 12,
      "z": 5,
      "name": "Rock_Stone_Brick"
    },
    {
      "x": -13,
      "y": 13,
      "z": 5,
      "name": "Rock_Stone_Brick"
    },
    {
      "x": -13,
      "y": 14,
      "z": 5,
      "name": "Rock_Stone_Brick"
    },
    {
      "x": -13,
      "y": 15,
      "z": 5,
      "name": "Rock_Stone_Brick_Smooth"
    },
    {
      "x": -13,
      "y": 16,
      "z": 5,
      "name": "Soil_Gravel",
      "support": 15
    },
    {
      "x": -13,
      "y": 17,
      "z": 5,
      "name": "Soil_Gravel",
      "support": 15
    },
    {
      "x": -13,
      "y": 21,
      "z": 11,
      "name": "Cloth_Block_Wool_Pink"
    },
    {
      "x": -12,
      "y": 21,
      "z": -10,
      "name": "Cloth_Block_Wool_Green"
    },
    {
      "x": -12,
      "y": 9,
      "z": -5,
      "name": "Rock_Stone_Brick_Smooth"
    },
    {
      "x": -12,
      "y": 10,
      "z": -5,
      "name": "Soil_Gravel",
      "support": 15
    },
    {
      "x": -12,
      "y": 11,
      "z": -5,
      "name": "Soil_Gravel",
      "support": 15
    },
    {
      "x": -12,
      "y": 12,
      "z": -5,
      "name": "Soil_Gravel",
      "support": 15
    },
    {
      "x": -12,
      "y": 13,
      "z": -5,
      "name": "Soil_Gravel",
      "support": 15
    },
    {
      "x": -12,
      "y": 14,
      "z": -5,
      "name": "Soil_Gravel",
      "support": 15
    },
    {
      "x": -12,
      "y": 15,
      "z": -5,
      "name": "Rock_Stone_Brick_Smooth"
    },
    {
      "x": -12,
      "y": 16,
      "z": -5,
      "name": "Soil_Gravel",
      "support": 15,
      "rotation": 3
    },
    {
      "x": -12,
      "y": 17,
      "z": -5,
      "name": "Soil_Gravel",
      "support": 15,
      "rotation": 3
    },
    {
      "x": -12,
      "y": 9,
      "z": -4,
      "name": "Rock_Stone_Brick_Smooth"
    },
    {
      "x": -12,
      "y": 10,
      "z": -4,
      "name": "Rock_Stone_Brick_Smooth_Half",
      "rotation": 5
    },
    {
      "x": -12,
      "y": 11,
      "z": -4,
      "name": "Rock_Stone_Brick_Smooth_Half",
      "rotation": 5
    },
    {
      "x": -12,
      "y": 12,
      "z": -4,
      "name": "Rock_Stone_Brick_Smooth_Half",
      "rotation": 5
    },
    {
      "x": -12,
      "y": 13,
      "z": -4,
      "name": "Rock_Stone_Brick_Smooth_Half",
      "rotation": 5
    },
    {
      "x": -12,
      "y": 14,
      "z": -4,
      "name": "Rock_Stone_Brick_Smooth_Half",
      "rotation": 5
    },
    {
      "x": -12,
      "y": 15,
      "z": -4,
      "name": "Rock_Stone_Brick_Smooth"
    },
    {
      "x": -12,
      "y": 16,
      "z": -4,
      "name": "Rock_Stone_Brick_Smooth_Half",
      "rotation": 5
    },
    {
      "x": -12,
      "y": 17,
      "z": -4,
      "name": "Cloth_Block_Wool_Pink",
      "rotation": 3
    },
    {
      "x": -12,
      "y": 9,
      "z": -3,
      "name": "Rock_Stone_Brick_Smooth"
    },
    {
      "x": -12,
      "y": 17,
      "z": -3,
      "name": "Rock_Stone_Brick_Smooth_Half",
      "rotation": 5
    },
    {
      "x": -12,
      "y": 18,
      "z": -3,
      "name": "Cloth_Block_Wool_Pink",
      "rotation": 3
    },
    {
      "x": -12,
      "y": 9,
      "z": -2,
      "name": "Rock_Stone_Brick_Smooth"
    },
    {
      "x": -12,
      "y": 17,
      "z": -2,
      "name": "Rock_Stone_Brick_Smooth_Half",
      "rotation": 5
    },
    {
      "x": -12,
      "y": 18,
      "z": -2,
      "name": "Cloth_Block_Wool_Pink",
      "rotation": 3
    },
    {
      "x": -12,
      "y": 4,
      "z": -1,
      "name": "Soil_Gravel",
      "support": 15
    },
    {
      "x": -12,
      "y": 5,
      "z": -1,
      "name": "Rock_Stone_Brick_Smooth"
    },
    {
      "x": -12,
      "y": 6,
      "z": -1,
      "name": "Rock_Stone_Brick_Smooth"
    },
    {
      "x": -12,
      "y": 7,
      "z": -1,
      "name": "Rock_Stone_Brick_Smooth"
    },
    {
      "x": -12,
      "y": 8,
      "z": -1,
      "name": "Rock_Stone_Brick_Smooth"
    },
    {
      "x": -12,
      "y": 9,
      "z": -1,
      "name": "Rock_Stone_Brick_Smooth"
    },
    {
      "x": -12,
      "y": 17,
      "z": -1,
      "name": "Rock_Stone_Brick_Smooth_Half",
      "rotation": 33
    },
    {
      "x": -12,
      "y": 18,
      "z": -1,
      "name": "Rock_Stone_Brick_Smooth",
      "rotation": 3
    },
    {
      "x": -12,
      "y": 4,
      "z": 0,
      "name": "Soil_Gravel",
      "support": 15
    },
    {
      "x": -12,
      "y": 5,
      "z": 0,
      "name": "Rock_Stone_Brick_Smooth_Half",
      "rotation": 5
    },
    {
      "x": -12,
      "y": 6,
      "z": 0,
      "name": "Rock_Stone_Brick_Smooth_Half",
      "rotation": 5
    },
    {
      "x": -12,
      "y": 7,
      "z": 0,
      "name": "Rock_Stone_Brick_Smooth_Half",
      "rotation": 5
    },
    {
      "x": -12,
      "y": 8,
      "z": 0,
      "name": "Rock_Stone_Brick_Smooth_Half",
      "rotation": 5
    },
    {
      "x": -12,
      "y": 9,
      "z": 0,
      "name": "Rock_Stone_Brick_Smooth_Half",
      "rotation": 5
    },
    {
      "x": -12,
      "y": 18,
      "z": 0,
      "name": "Rock_Stone_Brick_Smooth_Half",
      "rotation": 5
    },
    {
      "x": -12,
      "y": 19,
      "z": 0,
      "name": "Cloth_Block_Wool_Pink",
      "rotation": 3
    },
    {
      "x": -12,
      "y": 21,
      "z": 0,
      "name": "Cloth_Block_Wool_Green"
    },
    {
      "x": -12,
      "y": 4,
      "z": 1,
      "name": "Soil_Gravel",
      "support": 15
    },
    {
      "x": -12,
      "y": 5,
      "z": 1,
      "name": "Rock_Stone_Brick_Smooth_Half",
      "rotation": 5
    },
    {
      "x": -12,
      "y": 6,
      "z": 1,
      "name": "Rock_Stone_Brick_Smooth_Half",
      "rotation": 5
    },
    {
      "x": -12,
      "y": 7,
      "z": 1,
      "name": "Rock_Stone_Brick_Smooth_Half",
      "rotation": 5
    },
    {
      "x": -12,
      "y": 8,
      "z": 1,
      "name": "Rock_Stone_Brick_Smooth_Half",
      "rotation": 5
    },
    {
      "x": -12,
      "y": 9,
      "z": 1,
      "name": "Rock_Stone_Brick_Smooth_Half",
      "rotation": 5
    },
    {
      "x": -12,
      "y": 18,
      "z": 1,
      "name": "Rock_Stone_Brick_Smooth_Half",
      "rotation": 5
    },
    {
      "x": -12,
      "y": 19,
      "z": 1,
      "name": "Cloth_Block_Wool_Pink",
      "rotation": 3
    },
    {
      "x": -12,
      "y": 21,
      "z": 1,
      "name": "Cloth_Block_Wool_Pink"
    },
    {
      "x": -12,
      "y": 4,
      "z": 2,
      "name": "Soil_Gravel",
      "support": 15
    },
    {
      "x": -12,
      "y": 5,
      "z": 2,
      "name": "Rock_Stone_Brick_Smooth"
    },
    {
      "x": -12,
      "y": 6,
      "z": 2,
      "name": "Rock_Stone_Brick_Smooth"
    },
    {
      "x": -12,
      "y": 7,
      "z": 2,
      "name": "Rock_Stone_Brick_Smooth"
    },
    {
      "x": -12,
      "y": 8,
      "z": 2,
      "name": "Rock_Stone_Brick_Smooth"
    },
    {
      "x": -12,
      "y": 9,
      "z": 2,
      "name": "Rock_Stone_Brick_Smooth"
    },
    {
      "x": -12,
      "y": 17,
      "z": 2,
      "name": "Rock_Stone_Brick_Smooth_Half",
      "rotation": 34
    },
    {
      "x": -12,
      "y": 18,
      "z": 2,
      "name": "Rock_Stone_Brick_Smooth"
    },
    {
      "x": -12,
      "y": 9,
      "z": 3,
      "name": "Rock_Stone_Brick_Smooth"
    },
    {
      "x": -12,
      "y": 17,
      "z": 3,
      "name": "Rock_Stone_Brick_Smooth_Half",
      "rotation": 5
    },
    {
      "x": -12,
      "y": 18,
      "z": 3,
      "name": "Cloth_Block_Wool_Pink"
    },
    {
      "x": -12,
      "y": 9,
      "z": 4,
      "name": "Rock_Stone_Brick_Smooth"
    },
    {
      "x": -12,
      "y": 17,
      "z": 4,
      "name": "Rock_Stone_Brick_Smooth_Half",
      "rotation": 5
    },
    {
      "x": -12,
      "y": 18,
      "z": 4,
      "name": "Cloth_Block_Wool_Pink"
    },
    {
      "x": -12,
      "y": 9,
      "z": 5,
      "name": "Rock_Stone_Brick_Smooth"
    },
    {
      "x": -12,
      "y": 10,
      "z": 5,
      "name": "Rock_Stone_Brick_Smooth_Half",
      "rotation": 5
    },
    {
      "x": -12,
      "y": 11,
      "z": 5,
      "name": "Rock_Stone_Brick_Smooth_Half",
      "rotation": 5
    },
    {
      "x": -12,
      "y": 12,
      "z": 5,
      "name": "Rock_Stone_Brick_Smooth_Half",
      "rotation": 5
    },
    {
      "x": -12,
      "y": 13,
      "z": 5,
      "name": "Rock_Stone_Brick_Smooth_Half",
      "rotation": 5
    },
    {
      "x": -12,
      "y": 14,
      "z": 5,
      "name": "Rock_Stone_Brick_Smooth_Half",
      "rotation": 5
    },
    {
      "x": -12,
      "y": 15,
      "z": 5,
      "name": "Rock_Stone_Brick_Smooth"
    },
    {
      "x": -12,
      "y": 16,
      "z": 5,
      "name": "Rock_Stone_Brick_Smooth_Half",
      "rotation": 5
    },
    {
      "x": -12,
      "y": 17,
      "z": 5,
      "name": "Cloth_Block_Wool_Pink"
    },
    {
      "x": -12,
      "y": 9,
      "z": 6,
      "name": "Rock_Stone_Brick_Smooth"
    },
    {
      "x": -12,
      "y": 10,
      "z": 6,
      "name": "Soil_Gravel",
      "support": 15
    },
    {
      "x": -12,
      "y": 11,
      "z": 6,
      "name": "Soil_Gravel",
      "support": 15
    },
    {
      "x": -12,
      "y": 12,
      "z": 6,
      "name": "Soil_Gravel",
      "support": 15
    },
    {
      "x": -12,
      "y": 13,
      "z": 6,
      "name": "Soil_Gravel",
      "support": 15
    },
    {
      "x": -12,
      "y": 14,
      "z": 6,
      "name": "Soil_Gravel",
      "support": 15
    },
    {
      "x": -12,
      "y": 15,
      "z": 6,
      "name": "Rock_Stone_Brick_Smooth"
    },
    {
      "x": -12,
      "y": 16,
      "z": 6,
      "name": "Soil_Gravel",
      "support": 15
    },
    {
      "x": -12,
      "y": 17,
      "z": 6,
      "name": "Soil_Gravel",
      "support": 15
    },
    {
      "x": -12,
      "y": 21,
      "z": 11,
      "name": "Cloth_Block_Wool_Pink"
    },
    {
      "x": -11,
      "y": 21,
      "z": -10,
      "name": "Cloth_Block_Wool_Green"
    },
    {
      "x": -11,
      "y": 9,
      "z": -5,
      "name": "Rock_Stone_Brick_Smooth"
    },
    {
      "x": -11,
      "y": 10,
      "z": -5,
      "name": "Soil_Gravel",
      "support": 15
    },
    {
      "x": -11,
      "y": 11,
      "z": -5,
      "name": "Soil_Gravel",
      "support": 15
    },
    {
      "x": -11,
      "y": 12,
      "z": -5,
      "name": "Soil_Gravel",
      "support": 15
    },
    {
      "x": -11,
      "y": 13,
      "z": -5,
      "name": "Soil_Gravel",
      "support": 15
    },
    {
      "x": -11,
      "y": 14,
      "z": -5,
      "name": "Soil_Gravel",
      "support": 15
    },
    {
      "x": -11,
      "y": 15,
      "z": -5,
      "name": "Rock_Stone_Brick_Smooth"
    },
    {
      "x": -11,
      "y": 16,
      "z": -5,
      "name": "Soil_Gravel",
      "support": 15,
      "rotation": 3
    },
    {
      "x": -11,
      "y": 17,
      "z": -5,
      "name": "Soil_Gravel",
      "support": 15,
      "rotation": 3
    },
    {
      "x": -11,
      "y": 9,
      "z": -4,
      "name": "Rock_Stone_Brick_Smooth"
    },
    {
      "x": -11,
      "y": 10,
      "z": -4,
      "name": "Furniture_Village_Coffin"
    },
    {
      "x": -11,
      "y": 15,
      "z": -4,
      "name": "Rock_Stone_Brick_Smooth"
    },
    {
      "x": -11,
      "y": 17,
      "z": -4,
      "name": "Cloth_Block_Wool_Pink",
      "rotation": 3
    },
    {
      "x": -11,
      "y": 9,
      "z": -3,
      "name": "Rock_Stone_Brick_Smooth"
    },
    {
      "x": -11,
      "y": 18,
      "z": -3,
      "name": "Cloth_Block_Wool_Pink",
      "rotation": 3
    },
    {
      "x": -11,
      "y": 9,
      "z": -2,
      "name": "Rock_Stone_Brick_Smooth"
    },
    {
      "x": -11,
      "y": 18,
      "z": -2,
      "name": "Cloth_Block_Wool_Pink",
      "rotation": 3
    },
    {
      "x": -11,
      "y": 4,
      "z": -1,
      "name": "Soil_Gravel",
      "support": 15
    },
    {
      "x": -11,
      "y": 5,
      "z": -1,
      "name": "Rock_Stone_Brick_Smooth_Half",
      "rotation": 4
    },
    {
      "x": -11,
      "y": 6,
      "z": -1,
      "name": "Rock_Stone_Brick_Smooth_Half",
      "rotation": 4
    },
    {
      "x": -11,
      "y": 7,
      "z": -1,
      "name": "Rock_Stone_Brick_Smooth_Half",
      "rotation": 4
    },
    {
      "x": -11,
      "y": 8,
      "z": -1,
      "name": "Rock_Stone_Brick_Smooth_Half",
      "rotation": 4
    },
    {
      "x": -11,
      "y": 9,
      "z": -1,
      "name": "Rock_Stone_Brick_Smooth_Half",
      "rotation": 4
    },
    {
      "x": -11,
      "y": 18,
      "z": -1,
      "name": "Rock_Stone_Brick_Smooth_Half",
      "rotation": 4
    },
    {
      "x": -11,
      "y": 19,
      "z": -1,
      "name": "Cloth_Block_Wool_Pink",
      "rotation": 3
    },
    {
      "x": -11,
      "y": 4,
      "z": 0,
      "name": "Soil_Gravel",
      "support": 15
    },
    {
      "x": -11,
      "y": 19,
      "z": 0,
      "name": "Cloth_Block_Wool_Pink",
      "rotation": 3
    },
    {
      "x": -11,
      "y": 21,
      "z": 0,
      "name": "Cloth_Block_Wool_Green"
    },
    {
      "x": -11,
      "y": 4,
      "z": 1,
      "name": "Soil_Gravel",
      "support": 15
    },
    {
      "x": -11,
      "y": 19,
      "z": 1,
      "name": "Cloth_Block_Wool_Pink",
      "rotation": 3
    },
    {
      "x": -11,
      "y": 21,
      "z": 1,
      "name": "Cloth_Block_Wool_Pink"
    },
    {
      "x": -11,
      "y": 4,
      "z": 2,
      "name": "Soil_Gravel",
      "support": 15
    },
    {
      "x": -11,
      "y": 5,
      "z": 2,
      "name": "Rock_Stone_Brick_Smooth_Half",
      "rotation": 6
    },
    {
      "x": -11,
      "y": 6,
      "z": 2,
      "name": "Rock_Stone_Brick_Smooth_Half",
      "rotation": 6
    },
    {
      "x": -11,
      "y": 7,
      "z": 2,
      "name": "Rock_Stone_Brick_Smooth_Half",
      "rotation": 6
    },
    {
      "x": -11,
      "y": 8,
      "z": 2,
      "name": "Rock_Stone_Brick_Smooth_Half",
      "rotation": 6
    },
    {
      "x": -11,
      "y": 9,
      "z": 2,
      "name": "Rock_Stone_Brick_Smooth_Half",
      "rotation": 6
    },
    {
      "x": -11,
      "y": 18,
      "z": 2,
      "name": "Rock_Stone_Brick_Smooth_Half",
      "rotation": 6
    },
    {
      "x": -11,
      "y": 19,
      "z": 2,
      "name": "Cloth_Block_Wool_Pink",
      "rotation": 1
    },
    {
      "x": -11,
      "y": 9,
      "z": 3,
      "name": "Rock_Stone_Brick_Smooth"
    },
    {
      "x": -11,
      "y": 18,
      "z": 3,
      "name": "Cloth_Block_Wool_Pink",
      "rotation": 1
    },
    {
      "x": -11,
      "y": 9,
      "z": 4,
      "name": "Rock_Stone_Brick_Smooth"
    },
    {
      "x": -11,
      "y": 18,
      "z": 4,
      "name": "Cloth_Block_Wool_Pink",
      "rotation": 1
    },
    {
      "x": -11,
      "y": 9,
      "z": 5,
      "name": "Rock_Stone_Brick_Smooth"
    },
    {
      "x": -11,
      "y": 10,
      "z": 5,
      "name": "Furniture_Village_Coffin"
    },
    {
      "x": -11,
      "y": 15,
      "z": 5,
      "name": "Rock_Stone_Brick_Smooth"
    },
    {
      "x": -11,
      "y": 17,
      "z": 5,
      "name": "Cloth_Block_Wool_Pink",
      "rotation": 1
    },
    {
      "x": -11,
      "y": 9,
      "z": 6,
      "name": "Rock_Stone_Brick_Smooth"
    },
    {
      "x": -11,
      "y": 10,
      "z": 6,
      "name": "Soil_Gravel",
      "support": 15
    },
    {
      "x": -11,
      "y": 11,
      "z": 6,
      "name": "Soil_Gravel",
      "support": 15
    },
    {
      "x": -11,
      "y": 12,
      "z": 6,
      "name": "Soil_Gravel",
      "support": 15
    },
    {
      "x": -11,
      "y": 13,
      "z": 6,
      "name": "Soil_Gravel",
      "support": 15
    },
    {
      "x": -11,
      "y": 14,
      "z": 6,
      "name": "Soil_Gravel",
      "support": 15
    },
    {
      "x": -11,
      "y": 15,
      "z": 6,
      "name": "Rock_Stone_Brick_Smooth"
    },
    {
      "x": -11,
      "y": 16,
      "z": 6,
      "name": "Soil_Gravel",
      "support": 15,
      "rotation": 1
    },
    {
      "x": -11,
      "y": 17,
      "z": 6,
      "name": "Soil_Gravel",
      "support": 15,
      "rotation": 1
    },
    {
      "x": -11,
      "y": 21,
      "z": 11,
      "name": "Cloth_Block_Wool_Pink"
    },
    {
      "x": -10,
      "y": 21,
      "z": -10,
      "name": "Cloth_Block_Wool_Green"
    },
    {
      "x": -10,
      "y": 9,
      "z": -5,
      "name": "Rock_Stone_Brick_Smooth"
    },
    {
      "x": -10,
      "y": 10,
      "z": -5,
      "name": "Soil_Gravel",
      "support": 15
    },
    {
      "x": -10,
      "y": 11,
      "z": -5,
      "name": "Soil_Gravel",
      "support": 15
    },
    {
      "x": -10,
      "y": 12,
      "z": -5,
      "name": "Soil_Gravel",
      "support": 15
    },
    {
      "x": -10,
      "y": 13,
      "z": -5,
      "name": "Soil_Gravel",
      "support": 15
    },
    {
      "x": -10,
      "y": 14,
      "z": -5,
      "name": "Soil_Gravel",
      "support": 15
    },
    {
      "x": -10,
      "y": 15,
      "z": -5,
      "name": "Rock_Stone_Brick_Smooth"
    },
    {
      "x": -10,
      "y": 16,
      "z": -5,
      "name": "Soil_Gravel",
      "support": 15,
      "rotation": 3
    },
    {
      "x": -10,
      "y": 17,
      "z": -5,
      "name": "Soil_Gravel",
      "support": 15,
      "rotation": 3
    },
    {
      "x": -10,
      "y": 9,
      "z": -4,
      "name": "Rock_Stone_Brick_Smooth"
    },
    {
      "x": -10,
      "y": 10,
      "z": -4,
      "name": "Furniture_Village_Coffin",
      "filler": 1
    },
    {
      "x": -10,
      "y": 15,
      "z": -4,
      "name": "Rock_Stone_Brick_Smooth"
    },
    {
      "x": -10,
      "y": 17,
      "z": -4,
      "name": "Cloth_Block_Wool_Pink",
      "rotation": 3
    },
    {
      "x": -10,
      "y": 9,
      "z": -3,
      "name": "Rock_Stone_Brick_Smooth"
    },
    {
      "x": -10,
      "y": 18,
      "z": -3,
      "name": "Cloth_Block_Wool_Pink",
      "rotation": 3
    },
    {
      "x": -10,
      "y": 9,
      "z": -2,
      "name": "Rock_Stone_Brick_Smooth"
    },
    {
      "x": -10,
      "y": 18,
      "z": -2,
      "name": "Cloth_Block_Wool_Pink",
      "rotation": 3
    },
    {
      "x": -10,
      "y": 4,
      "z": -1,
      "name": "Soil_Gravel",
      "support": 15
    },
    {
      "x": -10,
      "y": 5,
      "z": -1,
      "name": "Rock_Stone_Brick_Smooth_Half",
      "rotation": 4
    },
    {
      "x": -10,
      "y": 6,
      "z": -1,
      "name": "Rock_Stone_Brick_Smooth_Half",
      "rotation": 4
    },
    {
      "x": -10,
      "y": 7,
      "z": -1,
      "name": "Rock_Stone_Brick_Smooth_Half",
      "rotation": 4
    },
    {
      "x": -10,
      "y": 8,
      "z": -1,
      "name": "Rock_Stone_Brick_Smooth_Half",
      "rotation": 4
    },
    {
      "x": -10,
      "y": 9,
      "z": -1,
      "name": "Rock_Stone_Brick_Smooth_Half",
      "rotation": 4
    },
    {
      "x": -10,
      "y": 18,
      "z": -1,
      "name": "Rock_Stone_Brick_Smooth_Half",
      "rotation": 4
    },
    {
      "x": -10,
      "y": 19,
      "z": -1,
      "name": "Cloth_Block_Wool_Pink",
      "rotation": 3
    },
    {
      "x": -10,
      "y": 4,
      "z": 0,
      "name": "Soil_Gravel",
      "support": 15
    },
    {
      "x": -10,
      "y": 19,
      "z": 0,
      "name": "Cloth_Block_Wool_Pink",
      "rotation": 3
    },
    {
      "x": -10,
      "y": 21,
      "z": 0,
      "name": "Cloth_Block_Wool_Green"
    },
    {
      "x": -10,
      "y": 4,
      "z": 1,
      "name": "Soil_Gravel",
      "support": 15
    },
    {
      "x": -10,
      "y": 19,
      "z": 1,
      "name": "Cloth_Block_Wool_Pink",
      "rotation": 3
    },
    {
      "x": -10,
      "y": 21,
      "z": 1,
      "name": "Cloth_Block_Wool_Pink"
    },
    {
      "x": -10,
      "y": 4,
      "z": 2,
      "name": "Soil_Gravel",
      "support": 15
    },
    {
      "x": -10,
      "y": 5,
      "z": 2,
      "name": "Rock_Stone_Brick_Smooth_Half",
      "rotation": 6
    },
    {
      "x": -10,
      "y": 6,
      "z": 2,
      "name": "Rock_Stone_Brick_Smooth_Half",
      "rotation": 6
    },
    {
      "x": -10,
      "y": 7,
      "z": 2,
      "name": "Rock_Stone_Brick_Smooth_Half",
      "rotation": 6
    },
    {
      "x": -10,
      "y": 8,
      "z": 2,
      "name": "Rock_Stone_Brick_Smooth_Half",
      "rotation": 6
    },
    {
      "x": -10,
      "y": 9,
      "z": 2,
      "name": "Rock_Stone_Brick_Smooth_Half",
      "rotation": 6
    },
    {
      "x": -10,
      "y": 18,
      "z": 2,
      "name": "Rock_Stone_Brick_Smooth_Half",
      "rotation": 6
    },
    {
      "x": -10,
      "y": 19,
      "z": 2,
      "name": "Cloth_Block_Wool_Pink",
      "rotation": 1
    },
    {
      "x": -10,
      "y": 9,
      "z": 3,
      "name": "Rock_Stone_Brick_Smooth"
    },
    {
      "x": -10,
      "y": 18,
      "z": 3,
      "name": "Cloth_Block_Wool_Pink",
      "rotation": 1
    },
    {
      "x": -10,
      "y": 9,
      "z": 4,
      "name": "Rock_Stone_Brick_Smooth"
    },
    {
      "x": -10,
      "y": 18,
      "z": 4,
      "name": "Cloth_Block_Wool_Pink",
      "rotation": 1
    },
    {
      "x": -10,
      "y": 9,
      "z": 5,
      "name": "Rock_Stone_Brick_Smooth"
    },
    {
      "x": -10,
      "y": 10,
      "z": 5,
      "name": "Furniture_Village_Coffin",
      "filler": 1
    },
    {
      "x": -10,
      "y": 15,
      "z": 5,
      "name": "Rock_Stone_Brick_Smooth"
    },
    {
      "x": -10,
      "y": 17,
      "z": 5,
      "name": "Cloth_Block_Wool_Pink",
      "rotation": 1
    },
    {
      "x": -10,
      "y": 9,
      "z": 6,
      "name": "Rock_Stone_Brick_Smooth"
    },
    {
      "x": -10,
      "y": 10,
      "z": 6,
      "name": "Soil_Gravel",
      "support": 15
    },
    {
      "x": -10,
      "y": 11,
      "z": 6,
      "name": "Soil_Gravel",
      "support": 15
    },
    {
      "x": -10,
      "y": 12,
      "z": 6,
      "name": "Soil_Gravel",
      "support": 15
    },
    {
      "x": -10,
      "y": 13,
      "z": 6,
      "name": "Soil_Gravel",
      "support": 15
    },
    {
      "x": -10,
      "y": 14,
      "z": 6,
      "name": "Soil_Gravel",
      "support": 15
    },
    {
      "x": -10,
      "y": 15,
      "z": 6,
      "name": "Rock_Stone_Brick_Smooth"
    },
    {
      "x": -10,
      "y": 16,
      "z": 6,
      "name": "Soil_Gravel",
      "support": 15,
      "rotation": 1
    },
    {
      "x": -10,
      "y": 17,
      "z": 6,
      "name": "Soil_Gravel",
      "support": 15,
      "rotation": 1
    },
    {
      "x": -10,
      "y": 21,
      "z": 11,
      "name": "Cloth_Block_Wool_Pink"
    },
    {
      "x": -9,
      "y": 21,
      "z": -10,
      "name": "Cloth_Block_Wool_Green"
    },
    {
      "x": -9,
      "y": 9,
      "z": -5,
      "name": "Rock_Stone_Brick_Smooth"
    },
    {
      "x": -9,
      "y": 10,
      "z": -5,
      "name": "Soil_Gravel",
      "support": 15
    },
    {
      "x": -9,
      "y": 11,
      "z": -5,
      "name": "Soil_Gravel",
      "support": 15
    },
    {
      "x": -9,
      "y": 12,
      "z": -5,
      "name": "Soil_Gravel",
      "support": 15
    },
    {
      "x": -9,
      "y": 13,
      "z": -5,
      "name": "Soil_Gravel",
      "support": 15
    },
    {
      "x": -9,
      "y": 14,
      "z": -5,
      "name": "Soil_Gravel",
      "support": 15
    },
    {
      "x": -9,
      "y": 15,
      "z": -5,
      "name": "Rock_Stone_Brick_Smooth"
    },
    {
      "x": -9,
      "y": 16,
      "z": -5,
      "name": "Soil_Gravel",
      "support": 15,
      "rotation": 2
    },
    {
      "x": -9,
      "y": 17,
      "z": -5,
      "name": "Soil_Gravel",
      "support": 15,
      "rotation": 2
    },
    {
      "x": -9,
      "y": 9,
      "z": -4,
      "name": "Rock_Stone_Brick_Smooth"
    },
    {
      "x": -9,
      "y": 10,
      "z": -4,
      "name": "Rock_Stone_Brick_Smooth_Half",
      "rotation": 7
    },
    {
      "x": -9,
      "y": 11,
      "z": -4,
      "name": "Rock_Stone_Brick_Smooth_Half",
      "rotation": 7
    },
    {
      "x": -9,
      "y": 12,
      "z": -4,
      "name": "Rock_Stone_Brick_Smooth_Half",
      "rotation": 7
    },
    {
      "x": -9,
      "y": 13,
      "z": -4,
      "name": "Rock_Stone_Brick_Smooth_Half",
      "rotation": 7
    },
    {
      "x": -9,
      "y": 14,
      "z": -4,
      "name": "Rock_Stone_Brick_Smooth_Half",
      "rotation": 7
    },
    {
      "x": -9,
      "y": 15,
      "z": -4,
      "name": "Rock_Stone_Brick_Smooth"
    },
    {
      "x": -9,
      "y": 16,
      "z": -4,
      "name": "Rock_Stone_Brick_Smooth_Half",
      "rotation": 7
    },
    {
      "x": -9,
      "y": 17,
      "z": -4,
      "name": "Cloth_Block_Wool_Pink",
      "rotation": 2
    },
    {
      "x": -9,
      "y": 9,
      "z": -3,
      "name": "Rock_Stone_Brick_Smooth"
    },
    {
      "x": -9,
      "y": 17,
      "z": -3,
      "name": "Rock_Stone_Brick_Smooth_Half",
      "rotation": 7
    },
    {
      "x": -9,
      "y": 18,
      "z": -3,
      "name": "Cloth_Block_Wool_Pink",
      "rotation": 2
    },
    {
      "x": -9,
      "y": 9,
      "z": -2,
      "name": "Rock_Stone_Brick_Smooth"
    },
    {
      "x": -9,
      "y": 17,
      "z": -2,
      "name": "Rock_Stone_Brick_Smooth_Half",
      "rotation": 7
    },
    {
      "x": -9,
      "y": 18,
      "z": -2,
      "name": "Cloth_Block_Wool_Pink",
      "rotation": 2
    },
    {
      "x": -9,
      "y": 4,
      "z": -1,
      "name": "Soil_Gravel",
      "support": 15
    },
    {
      "x": -9,
      "y": 5,
      "z": -1,
      "name": "Rock_Stone_Brick_Smooth"
    },
    {
      "x": -9,
      "y": 6,
      "z": -1,
      "name": "Rock_Stone_Brick_Smooth"
    },
    {
      "x": -9,
      "y": 7,
      "z": -1,
      "name": "Rock_Stone_Brick_Smooth"
    },
    {
      "x": -9,
      "y": 8,
      "z": -1,
      "name": "Rock_Stone_Brick_Smooth"
    },
    {
      "x": -9,
      "y": 9,
      "z": -1,
      "name": "Rock_Stone_Brick_Smooth"
    },
    {
      "x": -9,
      "y": 17,
      "z": -1,
      "name": "Rock_Stone_Brick_Smooth_Half",
      "rotation": 32
    },
    {
      "x": -9,
      "y": 18,
      "z": -1,
      "name": "Rock_Stone_Brick_Smooth",
      "rotation": 2
    },
    {
      "x": -9,
      "y": 4,
      "z": 0,
      "name": "Soil_Gravel",
      "support": 15
    },
    {
      "x": -9,
      "y": 5,
      "z": 0,
      "name": "Rock_Stone_Brick_Smooth_Half",
      "rotation": 7
    },
    {
      "x": -9,
      "y": 6,
      "z": 0,
      "name": "Rock_Stone_Brick_Smooth_Half",
      "rotation": 7
    },
    {
      "x": -9,
      "y": 7,
      "z": 0,
      "name": "Rock_Stone_Brick_Smooth_Half",
      "rotation": 7
    },
    {
      "x": -9,
      "y": 8,
      "z": 0,
      "name": "Rock_Stone_Brick_Smooth_Half",
      "rotation": 7
    },
    {
      "x": -9,
      "y": 9,
      "z": 0,
      "name": "Rock_Stone_Brick_Smooth_Half",
      "rotation": 7
    },
    {
      "x": -9,
      "y": 18,
      "z": 0,
      "name": "Rock_Stone_Brick_Smooth_Half",
      "rotation": 7
    },
    {
      "x": -9,
      "y": 19,
      "z": 0,
      "name": "Cloth_Block_Wool_Pink",
      "rotation": 2
    },
    {
      "x": -9,
      "y": 21,
      "z": 0,
      "name": "Cloth_Block_Wool_Green"
    },
    {
      "x": -9,
      "y": 4,
      "z": 1,
      "name": "Soil_Gravel",
      "support": 15
    },
    {
      "x": -9,
      "y": 5,
      "z": 1,
      "name": "Rock_Stone_Brick_Smooth_Half",
      "rotation": 7
    },
    {
      "x": -9,
      "y": 6,
      "z": 1,
      "name": "Rock_Stone_Brick_Smooth_Half",
      "rotation": 7
    },
    {
      "x": -9,
      "y": 7,
      "z": 1,
      "name": "Rock_Stone_Brick_Smooth_Half",
      "rotation": 7
    },
    {
      "x": -9,
      "y": 8,
      "z": 1,
      "name": "Rock_Stone_Brick_Smooth_Half",
      "rotation": 7
    },
    {
      "x": -9,
      "y": 9,
      "z": 1,
      "name": "Rock_Stone_Brick_Smooth_Half",
      "rotation": 7
    },
    {
      "x": -9,
      "y": 18,
      "z": 1,
      "name": "Rock_Stone_Brick_Smooth_Half",
      "rotation": 7
    },
    {
      "x": -9,
      "y": 19,
      "z": 1,
      "name": "Cloth_Block_Wool_Pink",
      "rotation": 2
    },
    {
      "x": -9,
      "y": 21,
      "z": 1,
      "name": "Cloth_Block_Wool_Pink"
    },
    {
      "x": -9,
      "y": 4,
      "z": 2,
      "name": "Soil_Gravel",
      "support": 15
    },
    {
      "x": -9,
      "y": 5,
      "z": 2,
      "name": "Rock_Stone_Brick_Smooth"
    },
    {
      "x": -9,
      "y": 6,
      "z": 2,
      "name": "Rock_Stone_Brick_Smooth"
    },
    {
      "x": -9,
      "y": 7,
      "z": 2,
      "name": "Rock_Stone_Brick_Smooth"
    },
    {
      "x": -9,
      "y": 8,
      "z": 2,
      "name": "Rock_Stone_Brick_Smooth"
    },
    {
      "x": -9,
      "y": 9,
      "z": 2,
      "name": "Rock_Stone_Brick_Smooth"
    },
    {
      "x": -9,
      "y": 17,
      "z": 2,
      "name": "Rock_Stone_Brick_Smooth_Half",
      "rotation": 35
    },
    {
      "x": -9,
      "y": 18,
      "z": 2,
      "name": "Rock_Stone_Brick_Smooth",
      "rotation": 1
    },
    {
      "x": -9,
      "y": 9,
      "z": 3,
      "name": "Rock_Stone_Brick_Smooth"
    },
    {
      "x": -9,
      "y": 17,
      "z": 3,
      "name": "Rock_Stone_Brick_Smooth_Half",
      "rotation": 7
    },
    {
      "x": -9,
      "y": 18,
      "z": 3,
      "name": "Cloth_Block_Wool_Pink",
      "rotation": 1
    },
    {
      "x": -9,
      "y": 9,
      "z": 4,
      "name": "Rock_Stone_Brick_Smooth"
    },
    {
      "x": -9,
      "y": 17,
      "z": 4,
      "name": "Rock_Stone_Brick_Smooth_Half",
      "rotation": 7
    },
    {
      "x": -9,
      "y": 18,
      "z": 4,
      "name": "Cloth_Block_Wool_Pink",
      "rotation": 1
    },
    {
      "x": -9,
      "y": 9,
      "z": 5,
      "name": "Rock_Stone_Brick_Smooth"
    },
    {
      "x": -9,
      "y": 10,
      "z": 5,
      "name": "Rock_Stone_Brick_Smooth_Half",
      "rotation": 7
    },
    {
      "x": -9,
      "y": 11,
      "z": 5,
      "name": "Rock_Stone_Brick_Smooth_Half",
      "rotation": 7
    },
    {
      "x": -9,
      "y": 12,
      "z": 5,
      "name": "Rock_Stone_Brick_Smooth_Half",
      "rotation": 7
    },
    {
      "x": -9,
      "y": 13,
      "z": 5,
      "name": "Rock_Stone_Brick_Smooth_Half",
      "rotation": 7
    },
    {
      "x": -9,
      "y": 14,
      "z": 5,
      "name": "Rock_Stone_Brick_Smooth_Half",
      "rotation": 7
    },
    {
      "x": -9,
      "y": 15,
      "z": 5,
      "name": "Rock_Stone_Brick_Smooth"
    },
    {
      "x": -9,
      "y": 16,
      "z": 5,
      "name": "Rock_Stone_Brick_Smooth_Half",
      "rotation": 7
    },
    {
      "x": -9,
      "y": 17,
      "z": 5,
      "name": "Cloth_Block_Wool_Pink",
      "rotation": 1
    },
    {
      "x": -9,
      "y": 9,
      "z": 6,
      "name": "Rock_Stone_Brick_Smooth"
    },
    {
      "x": -9,
      "y": 10,
      "z": 6,
      "name": "Soil_Gravel",
      "support": 15
    },
    {
      "x": -9,
      "y": 11,
      "z": 6,
      "name": "Soil_Gravel",
      "support": 15
    },
    {
      "x": -9,
      "y": 12,
      "z": 6,
      "name": "Soil_Gravel",
      "support": 15
    },
    {
      "x": -9,
      "y": 13,
      "z": 6,
      "name": "Soil_Gravel",
      "support": 15
    },
    {
      "x": -9,
      "y": 14,
      "z": 6,
      "name": "Soil_Gravel",
      "support": 15
    },
    {
      "x": -9,
      "y": 15,
      "z": 6,
      "name": "Rock_Stone_Brick_Smooth"
    },
    {
      "x": -9,
      "y": 16,
      "z": 6,
      "name": "Soil_Gravel",
      "support": 15,
      "rotation": 1
    },
    {
      "x": -9,
      "y": 17,
      "z": 6,
      "name": "Soil_Gravel",
      "support": 15,
      "rotation": 1
    },
    {
      "x": -9,
      "y": 21,
      "z": 11,
      "name": "Cloth_Block_Wool_Pink"
    },
    {
      "x": -8,
      "y": 21,
      "z": -10,
      "name": "Cloth_Block_Wool_Green"
    },
    {
      "x": -8,
      "y": 9,
      "z": -4,
      "name": "Rock_Stone_Brick_Smooth"
    },
    {
      "x": -8,
      "y": 10,
      "z": -4,
      "name": "Rock_Stone_Brick_Decorative"
    },
    {
      "x": -8,
      "y": 11,
      "z": -4,
      "name": "Rock_Stone_Brick"
    },
    {
      "x": -8,
      "y": 12,
      "z": -4,
      "name": "Rock_Stone_Brick"
    },
    {
      "x": -8,
      "y": 13,
      "z": -4,
      "name": "Rock_Stone_Brick"
    },
    {
      "x": -8,
      "y": 14,
      "z": -4,
      "name": "Rock_Stone_Brick"
    },
    {
      "x": -8,
      "y": 15,
      "z": -4,
      "name": "Rock_Stone_Brick_Smooth"
    },
    {
      "x": -8,
      "y": 16,
      "z": -4,
      "name": "Soil_Gravel",
      "support": 15,
      "rotation": 2
    },
    {
      "x": -8,
      "y": 17,
      "z": -4,
      "name": "Soil_Gravel",
      "support": 15,
      "rotation": 2
    },
    {
      "x": -8,
      "y": 9,
      "z": -3,
      "name": "Rock_Stone_Brick_Smooth"
    },
    {
      "x": -8,
      "y": 15,
      "z": -3,
      "name": "Rock_Stone_Brick_Smooth_Half",
      "rotation": 4
    },
    {
      "x": -8,
      "y": 17,
      "z": -3,
      "name": "Cloth_Block_Wool_Pink",
      "rotation": 2
    },
    {
      "x": -8,
      "y": 9,
      "z": -2,
      "name": "Rock_Stone_Brick_Smooth"
    },
    {
      "x": -8,
      "y": 17,
      "z": -2,
      "name": "Cloth_Block_Wool_Pink",
      "rotation": 2
    },
    {
      "x": -8,
      "y": 9,
      "z": -1,
      "name": "Rock_Stone_Brick_Smooth"
    },
    {
      "x": -8,
      "y": 17,
      "z": -1,
      "name": "Rock_Stone_Brick_Smooth_Half",
      "rotation": 4
    },
    {
      "x": -8,
      "y": 18,
      "z": -1,
      "name": "Cloth_Block_Wool_Pink",
      "rotation": 2
    },
    {
      "x": -8,
      "y": 9,
      "z": 0,
      "name": "Rock_Stone_Brick_Smooth"
    },
    {
      "x": -8,
      "y": 18,
      "z": 0,
      "name": "Cloth_Block_Wool_Pink",
      "rotation": 2
    },
    {
      "x": -8,
      "y": 21,
      "z": 0,
      "name": "Cloth_Block_Wool_Green"
    },
    {
      "x": -8,
      "y": 9,
      "z": 1,
      "name": "Rock_Stone_Brick_Smooth"
    },
    {
      "x": -8,
      "y": 18,
      "z": 1,
      "name": "Cloth_Block_Wool_Pink",
      "rotation": 2
    },
    {
      "x": -8,
      "y": 21,
      "z": 1,
      "name": "Cloth_Block_Wool_Pink"
    },
    {
      "x": -8,
      "y": 9,
      "z": 2,
      "name": "Rock_Stone_Brick_Smooth"
    },
    {
      "x": -8,
      "y": 17,
      "z": 2,
      "name": "Rock_Stone_Brick_Smooth_Half",
      "rotation": 6
    },
    {
      "x": -8,
      "y": 18,
      "z": 2,
      "name": "Cloth_Block_Wool_Pink",
      "rotation": 1
    },
    {
      "x": -8,
      "y": 9,
      "z": 3,
      "name": "Rock_Stone_Brick_Smooth"
    },
    {
      "x": -8,
      "y": 17,
      "z": 3,
      "name": "Cloth_Block_Wool_Pink",
      "rotation": 1
    },
    {
      "x": -8,
      "y": 9,
      "z": 4,
      "name": "Rock_Stone_Brick_Smooth"
    },
    {
      "x": -8,
      "y": 15,
      "z": 4,
      "name": "Rock_Stone_Brick_Smooth_Half",
      "rotation": 6
    },
    {
      "x": -8,
      "y": 17,
      "z": 4,
      "name": "Cloth_Block_Wool_Pink",
      "rotation": 1
    },
    {
      "x": -8,
      "y": 9,
      "z": 5,
      "name": "Rock_Stone_Brick_Smooth"
    },
    {
      "x": -8,
      "y": 10,
      "z": 5,
      "name": "Rock_Stone_Brick_Decorative"
    },
    {
      "x": -8,
      "y": 11,
      "z": 5,
      "name": "Rock_Stone_Brick"
    },
    {
      "x": -8,
      "y": 12,
      "z": 5,
      "name": "Rock_Stone_Brick"
    },
    {
      "x": -8,
      "y": 13,
      "z": 5,
      "name": "Rock_Stone_Brick"
    },
    {
      "x": -8,
      "y": 14,
      "z": 5,
      "name": "Rock_Stone_Brick"
    },
    {
      "x": -8,
      "y": 15,
      "z": 5,
      "name": "Rock_Stone_Brick_Smooth"
    },
    {
      "x": -8,
      "y": 16,
      "z": 5,
      "name": "Soil_Gravel",
      "support": 15,
      "rotation": 1
    },
    {
      "x": -8,
      "y": 17,
      "z": 5,
      "name": "Soil_Gravel",
      "support": 15,
      "rotation": 1
    },
    {
      "x": -8,
      "y": 21,
      "z": 11,
      "name": "Cloth_Block_Wool_Pink"
    },
    {
      "x": -7,
      "y": 21,
      "z": -10,
      "name": "Cloth_Block_Wool_Green"
    },
    {
      "x": -7,
      "y": 9,
      "z": -4,
      "name": "Rock_Stone_Brick_Smooth"
    },
    {
      "x": -7,
      "y": 10,
      "z": -4,
      "name": "Rock_Stone_Brick_Decorative"
    },
    {
      "x": -7,
      "y": 11,
      "z": -4,
      "name": "Rock_Stone_Brick"
    },
    {
      "x": -7,
      "y": 12,
      "z": -4,
      "name": "Rock_Stone_Brick"
    },
    {
      "x": -7,
      "y": 13,
      "z": -4,
      "name": "Rock_Stone_Brick"
    },
    {
      "x": -7,
      "y": 14,
      "z": -4,
      "name": "Rock_Stone_Brick"
    },
    {
      "x": -7,
      "y": 15,
      "z": -4,
      "name": "Rock_Stone_Brick_Smooth"
    },
    {
      "x": -7,
      "y": 16,
      "z": -4,
      "name": "Soil_Gravel",
      "support": 15,
      "rotation": 2
    },
    {
      "x": -7,
      "y": 9,
      "z": -3,
      "name": "Rock_Stone_Brick_Decorative"
    },
    {
      "x": -7,
      "y": 10,
      "z": -3,
      "name": "Rock_Stone_Brick_Decorative"
    },
    {
      "x": -7,
      "y": 11,
      "z": -3,
      "name": "Rock_Stone_Brick_Pillar_Base"
    },
    {
      "x": -7,
      "y": 12,
      "z": -3,
      "name": "Rock_Stone_Brick_Pillar_Middle"
    },
    {
      "x": -7,
      "y": 13,
      "z": -3,
      "name": "Rock_Stone_Brick_Pillar_Middle"
    },
    {
      "x": -7,
      "y": 14,
      "z": -3,
      "name": "Rock_Stone_Brick_Pillar_Base",
      "rotation": 34
    },
    {
      "x": -7,
      "y": 15,
      "z": -3,
      "name": "Rock_Stone_Brick_Smooth"
    },
    {
      "x": -7,
      "y": 16,
      "z": -3,
      "name": "Soil_Gravel",
      "support": 15,
      "rotation": 2
    },
    {
      "x": -7,
      "y": 17,
      "z": -3,
      "name": "Soil_Gravel",
      "support": 15,
      "rotation": 2
    },
    {
      "x": -7,
      "y": 9,
      "z": -2,
      "name": "Rock_Stone_Brick_Smooth"
    },
    {
      "x": -7,
      "y": 11,
      "z": -2,
      "name": "Wood_Torch_Wall",
      "rotation": 3
    },
    {
      "x": -7,
      "y": 15,
      "z": -2,
      "name": "Rock_Stone_Brick_Smooth_Half",
      "rotation": 7
    },
    {
      "x": -7,
      "y": 17,
      "z": -2,
      "name": "Cloth_Block_Wool_Pink",
      "rotation": 2
    },
    {
      "x": -7,
      "y": 9,
      "z": -1,
      "name": "Rock_Stone_Brick_Smooth"
    },
    {
      "x": -7,
      "y": 17,
      "z": -1,
      "name": "Rock_Stone_Brick_Smooth_Half",
      "rotation": 4
    },
    {
      "x": -7,
      "y": 18,
      "z": -1,
      "name": "Cloth_Block_Wool_Pink",
      "rotation": 2
    },
    {
      "x": -7,
      "y": 9,
      "z": 0,
      "name": "Rock_Stone_Brick_Smooth"
    },
    {
      "x": -7,
      "y": 18,
      "z": 0,
      "name": "Cloth_Block_Wool_Pink",
      "rotation": 2
    },
    {
      "x": -7,
      "y": 21,
      "z": 0,
      "name": "Cloth_Block_Wool_Green"
    },
    {
      "x": -7,
      "y": 9,
      "z": 1,
      "name": "Rock_Stone_Brick_Smooth"
    },
    {
      "x": -7,
      "y": 18,
      "z": 1,
      "name": "Cloth_Block_Wool_Pink",
      "rotation": 2
    },
    {
      "x": -7,
      "y": 21,
      "z": 1,
      "name": "Cloth_Block_Wool_Pink"
    },
    {
      "x": -7,
      "y": 9,
      "z": 2,
      "name": "Rock_Stone_Brick_Smooth"
    },
    {
      "x": -7,
      "y": 17,
      "z": 2,
      "name": "Rock_Stone_Brick_Smooth_Half",
      "rotation": 6
    },
    {
      "x": -7,
      "y": 18,
      "z": 2,
      "name": "Cloth_Block_Wool_Pink",
      "rotation": 1
    },
    {
      "x": -7,
      "y": 9,
      "z": 3,
      "name": "Rock_Stone_Brick_Smooth"
    },
    {
      "x": -7,
      "y": 11,
      "z": 3,
      "name": "Wood_Torch_Wall",
      "rotation": 3
    },
    {
      "x": -7,
      "y": 15,
      "z": 3,
      "name": "Rock_Stone_Brick_Smooth_Half",
      "rotation": 7
    },
    {
      "x": -7,
      "y": 17,
      "z": 3,
      "name": "Cloth_Block_Wool_Pink",
      "rotation": 1
    },
    {
      "x": -7,
      "y": 9,
      "z": 4,
      "name": "Rock_Stone_Brick_Smooth"
    },
    {
      "x": -7,
      "y": 10,
      "z": 4,
      "name": "Rock_Stone_Brick_Decorative"
    },
    {
      "x": -7,
      "y": 11,
      "z": 4,
      "name": "Rock_Stone_Brick_Pillar_Base"
    },
    {
      "x": -7,
      "y": 12,
      "z": 4,
      "name": "Rock_Stone_Brick_Pillar_Middle"
    },
    {
      "x": -7,
      "y": 13,
      "z": 4,
      "name": "Rock_Stone_Brick_Pillar_Middle"
    },
    {
      "x": -7,
      "y": 14,
      "z": 4,
      "name": "Rock_Stone_Brick_Pillar_Base",
      "rotation": 34
    },
    {
      "x": -7,
      "y": 15,
      "z": 4,
      "name": "Rock_Stone_Brick_Smooth"
    },
    {
      "x": -7,
      "y": 16,
      "z": 4,
      "name": "Soil_Gravel",
      "support": 15,
      "rotation": 1
    },
    {
      "x": -7,
      "y": 17,
      "z": 4,
      "name": "Soil_Gravel",
      "support": 15,
      "rotation": 1
    },
    {
      "x": -7,
      "y": 9,
      "z": 5,
      "name": "Rock_Stone_Brick_Smooth"
    },
    {
      "x": -7,
      "y": 10,
      "z": 5,
      "name": "Rock_Stone_Brick_Decorative"
    },
    {
      "x": -7,
      "y": 11,
      "z": 5,
      "name": "Rock_Stone_Brick"
    },
    {
      "x": -7,
      "y": 12,
      "z": 5,
      "name": "Rock_Stone_Brick"
    },
    {
      "x": -7,
      "y": 13,
      "z": 5,
      "name": "Rock_Stone_Brick"
    },
    {
      "x": -7,
      "y": 14,
      "z": 5,
      "name": "Rock_Stone_Brick"
    },
    {
      "x": -7,
      "y": 15,
      "z": 5,
      "name": "Rock_Stone_Brick_Smooth"
    },
    {
      "x": -7,
      "y": 16,
      "z": 5,
      "name": "Soil_Gravel",
      "support": 15,
      "rotation": 1
    },
    {
      "x": -7,
      "y": 21,
      "z": 11,
      "name": "Cloth_Block_Wool_Pink"
    },
    {
      "x": -6,
      "y": 21,
      "z": -10,
      "name": "Cloth_Block_Wool_Green"
    },
    {
      "x": -6,
      "y": 21,
      "z": -9,
      "name": "Cloth_Block_Wool_Green"
    },
    {
      "x": -6,
      "y": 21,
      "z": -8,
      "name": "Cloth_Block_Wool_Green"
    },
    {
      "x": -6,
      "y": 21,
      "z": -7,
      "name": "Cloth_Block_Wool_Green"
    },
    {
      "x": -6,
      "y": 21,
      "z": -6,
      "name": "Cloth_Block_Wool_Green"
    },
    {
      "x": -6,
      "y": 21,
      "z": -5,
      "name": "Cloth_Block_Wool_Green"
    },
    {
      "x": -6,
      "y": 21,
      "z": -4,
      "name": "Cloth_Block_Wool_Green"
    },
    {
      "x": -6,
      "y": 9,
      "z": -3,
      "name": "Rock_Stone_Brick_Smooth"
    },
    {
      "x": -6,
      "y": 10,
      "z": -3,
      "name": "Rock_Stone_Brick_Decorative"
    },
    {
      "x": -6,
      "y": 11,
      "z": -3,
      "name": "Rock_Stone_Brick"
    },
    {
      "x": -6,
      "y": 12,
      "z": -3,
      "name": "Rock_Stone_Brick"
    },
    {
      "x": -6,
      "y": 13,
      "z": -3,
      "name": "Rock_Stone_Brick"
    },
    {
      "x": -6,
      "y": 14,
      "z": -3,
      "name": "Rock_Stone_Brick"
    },
    {
      "x": -6,
      "y": 15,
      "z": -3,
      "name": "Rock_Stone_Brick_Smooth"
    },
    {
      "x": -6,
      "y": 16,
      "z": -3,
      "name": "Soil_Gravel",
      "support": 15,
      "rotation": 2
    },
    {
      "x": -6,
      "y": 21,
      "z": -3,
      "name": "Cloth_Block_Wool_Green"
    },
    {
      "x": -6,
      "y": 9,
      "z": -2,
      "name": "Rock_Stone_Brick_Smooth"
    },
    {
      "x": -6,
      "y": 10,
      "z": -2,
      "name": "Rock_Stone_Brick_Decorative"
    },
    {
      "x": -6,
      "y": 11,
      "z": -2,
      "name": "Rock_Stone_Brick"
    },
    {
      "x": -6,
      "y": 12,
      "z": -2,
      "name": "Rock_Stone_Brick"
    },
    {
      "x": -6,
      "y": 13,
      "z": -2,
      "name": "Rock_Stone_Brick"
    },
    {
      "x": -6,
      "y": 14,
      "z": -2,
      "name": "Rock_Stone_Brick"
    },
    {
      "x": -6,
      "y": 15,
      "z": -2,
      "name": "Rock_Stone_Brick_Smooth"
    },
    {
      "x": -6,
      "y": 16,
      "z": -2,
      "name": "Soil_Gravel",
      "support": 15,
      "rotation": 2
    },
    {
      "x": -6,
      "y": 17,
      "z": -2,
      "name": "Soil_Gravel",
      "support": 15,
      "rotation": 2
    },
    {
      "x": -6,
      "y": 21,
      "z": -2,
      "name": "Cloth_Block_Wool_Green"
    },
    {
      "x": -6,
      "y": 9,
      "z": -1,
      "name": "Rock_Stone_Brick_Smooth"
    },
    {
      "x": -6,
      "y": 10,
      "z": -1,
      "name": "Rock_Stone_Brick_Smooth_Half",
      "rotation": 4
    },
    {
      "x": -6,
      "y": 11,
      "z": -1,
      "name": "Rock_Stone_Brick_Smooth_Half",
      "rotation": 4
    },
    {
      "x": -6,
      "y": 12,
      "z": -1,
      "name": "Rock_Stone_Brick_Smooth_Half",
      "rotation": 4
    },
    {
      "x": -6,
      "y": 13,
      "z": -1,
      "name": "Rock_Stone_Brick_Smooth_Half",
      "rotation": 4
    },
    {
      "x": -6,
      "y": 14,
      "z": -1,
      "name": "Rock_Stone_Brick_Smooth_Half",
      "rotation": 4
    },
    {
      "x": -6,
      "y": 15,
      "z": -1,
      "name": "Rock_Stone_Brick_Smooth"
    },
    {
      "x": -6,
      "y": 16,
      "z": -1,
      "name": "Rock_Stone_Brick_Smooth_Half",
      "rotation": 4
    },
    {
      "x": -6,
      "y": 17,
      "z": -1,
      "name": "Cloth_Block_Wool_Pink",
      "rotation": 2
    },
    {
      "x": -6,
      "y": 21,
      "z": -1,
      "name": "Cloth_Block_Wool_Green"
    },
    {
      "x": -6,
      "y": 9,
      "z": 0,
      "name": "Rock_Stone_Brick_Smooth"
    },
    {
      "x": -6,
      "y": 15,
      "z": 0,
      "name": "Rock_Stone_Brick_Smooth"
    },
    {
      "x": -6,
      "y": 17,
      "z": 0,
      "name": "Cloth_Block_Wool_Pink",
      "rotation": 2
    },
    {
      "x": -6,
      "y": 21,
      "z": 0,
      "name": "Cloth_Block_Wool_Green"
    },
    {
      "x": -6,
      "y": 9,
      "z": 1,
      "name": "Rock_Stone_Brick_Smooth"
    },
    {
      "x": -6,
      "y": 15,
      "z": 1,
      "name": "Rock_Stone_Brick_Smooth"
    },
    {
      "x": -6,
      "y": 17,
      "z": 1,
      "name": "Cloth_Block_Wool_Pink",
      "rotation": 2
    },
    {
      "x": -6,
      "y": 21,
      "z": 1,
      "name": "Cloth_Block_Wool_Pink"
    },
    {
      "x": -6,
      "y": 9,
      "z": 2,
      "name": "Rock_Stone_Brick_Smooth"
    },
    {
      "x": -6,
      "y": 10,
      "z": 2,
      "name": "Rock_Stone_Brick_Smooth_Half",
      "rotation": 6
    },
    {
      "x": -6,
      "y": 11,
      "z": 2,
      "name": "Rock_Stone_Brick_Smooth_Half",
      "rotation": 6
    },
    {
      "x": -6,
      "y": 12,
      "z": 2,
      "name": "Rock_Stone_Brick_Smooth_Half",
      "rotation": 6
    },
    {
      "x": -6,
      "y": 13,
      "z": 2,
      "name": "Rock_Stone_Brick_Smooth_Half",
      "rotation": 6
    },
    {
      "x": -6,
      "y": 14,
      "z": 2,
      "name": "Rock_Stone_Brick_Smooth_Half",
      "rotation": 6
    },
    {
      "x": -6,
      "y": 15,
      "z": 2,
      "name": "Rock_Stone_Brick_Smooth"
    },
    {
      "x": -6,
      "y": 16,
      "z": 2,
      "name": "Rock_Stone_Brick_Smooth_Half",
      "rotation": 6
    },
    {
      "x": -6,
      "y": 17,
      "z": 2,
      "name": "Cloth_Block_Wool_Pink",
      "rotation": 1
    },
    {
      "x": -6,
      "y": 21,
      "z": 2,
      "name": "Cloth_Block_Wool_Pink"
    },
    {
      "x": -6,
      "y": 9,
      "z": 3,
      "name": "Rock_Stone_Brick_Smooth"
    },
    {
      "x": -6,
      "y": 10,
      "z": 3,
      "name": "Rock_Stone_Brick_Decorative"
    },
    {
      "x": -6,
      "y": 11,
      "z": 3,
      "name": "Rock_Stone_Brick"
    },
    {
      "x": -6,
      "y": 12,
      "z": 3,
      "name": "Rock_Stone_Brick"
    },
    {
      "x": -6,
      "y": 13,
      "z": 3,
      "name": "Rock_Stone_Brick"
    },
    {
      "x": -6,
      "y": 14,
      "z": 3,
      "name": "Rock_Stone_Brick"
    },
    {
      "x": -6,
      "y": 15,
      "z": 3,
      "name": "Rock_Stone_Brick_Smooth"
    },
    {
      "x": -6,
      "y": 16,
      "z": 3,
      "name": "Soil_Gravel",
      "support": 15,
      "rotation": 1
    },
    {
      "x": -6,
      "y": 17,
      "z": 3,
      "name": "Soil_Gravel",
      "support": 15,
      "rotation": 1
    },
    {
      "x": -6,
      "y": 21,
      "z": 3,
      "name": "Cloth_Block_Wool_Pink"
    },
    {
      "x": -6,
      "y": 9,
      "z": 4,
      "name": "Rock_Stone_Brick_Smooth"
    },
    {
      "x": -6,
      "y": 10,
      "z": 4,
      "name": "Rock_Stone_Brick_Decorative"
    },
    {
      "x": -6,
      "y": 11,
      "z": 4,
      "name": "Rock_Stone_Brick"
    },
    {
      "x": -6,
      "y": 12,
      "z": 4,
      "name": "Rock_Stone_Brick"
    },
    {
      "x": -6,
      "y": 13,
      "z": 4,
      "name": "Rock_Stone_Brick"
    },
    {
      "x": -6,
      "y": 14,
      "z": 4,
      "name": "Rock_Stone_Brick"
    },
    {
      "x": -6,
      "y": 15,
      "z": 4,
      "name": "Rock_Stone_Brick_Smooth"
    },
    {
      "x": -6,
      "y": 16,
      "z": 4,
      "name": "Soil_Gravel",
      "support": 15,
      "rotation": 1
    },
    {
      "x": -6,
      "y": 21,
      "z": 4,
      "name": "Cloth_Block_Wool_Pink"
    },
    {
      "x": -6,
      "y": 21,
      "z": 5,
      "name": "Cloth_Block_Wool_Pink"
    },
    {
      "x": -6,
      "y": 21,
      "z": 6,
      "name": "Cloth_Block_Wool_Pink"
    },
    {
      "x": -6,
      "y": 21,
      "z": 7,
      "name": "Cloth_Block_Wool_Pink"
    },
    {
      "x": -6,
      "y": 21,
      "z": 8,
      "name": "Cloth_Block_Wool_Pink"
    },
    {
      "x": -6,
      "y": 21,
      "z": 9,
      "name": "Cloth_Block_Wool_Pink"
    },
    {
      "x": -6,
      "y": 21,
      "z": 10,
      "name": "Cloth_Block_Wool_Pink"
    },
    {
      "x": -6,
      "y": 21,
      "z": 11,
      "name": "Cloth_Block_Wool_Pink"
    },
    {
      "x": -5,
      "y": 21,
      "z": -10,
      "name": "Cloth_Block_Wool_Pink",
      "rotation": 2
    },
    {
      "x": -5,
      "y": 21,
      "z": -9,
      "name": "Cloth_Block_Wool_Pink",
      "rotation": 2
    },
    {
      "x": -5,
      "y": 21,
      "z": -8,
      "name": "Cloth_Block_Wool_Pink",
      "rotation": 2
    },
    {
      "x": -5,
      "y": 21,
      "z": -7,
      "name": "Cloth_Block_Wool_Pink",
      "rotation": 2
    },
    {
      "x": -5,
      "y": 21,
      "z": -6,
      "name": "Cloth_Block_Wool_Pink",
      "rotation": 2
    },
    {
      "x": -5,
      "y": 21,
      "z": -5,
      "name": "Cloth_Block_Wool_Pink",
      "rotation": 2
    },
    {
      "x": -5,
      "y": 21,
      "z": -4,
      "name": "Cloth_Block_Wool_Pink",
      "rotation": 2
    },
    {
      "x": -5,
      "y": 21,
      "z": -3,
      "name": "Cloth_Block_Wool_Pink",
      "rotation": 2
    },
    {
      "x": -5,
      "y": 10,
      "z": -2,
      "name": "Rock_Stone_Brick_Decorative",
      "rotation": 2
    },
    {
      "x": -5,
      "y": 11,
      "z": -2,
      "name": "Soil_Gravel",
      "support": 15,
      "rotation": 2
    },
    {
      "x": -5,
      "y": 12,
      "z": -2,
      "name": "Soil_Gravel",
      "support": 15,
      "rotation": 2
    },
    {
      "x": -5,
      "y": 13,
      "z": -2,
      "name": "Soil_Gravel",
      "support": 15,
      "rotation": 2
    },
    {
      "x": -5,
      "y": 14,
      "z": -2,
      "name": "Soil_Gravel",
      "support": 15,
      "rotation": 2
    },
    {
      "x": -5,
      "y": 21,
      "z": -2,
      "name": "Cloth_Block_Wool_Pink",
      "rotation": 2
    },
    {
      "x": -5,
      "y": 9,
      "z": -1,
      "name": "Rock_Stone_Brick_Smooth",
      "rotation": 2
    },
    {
      "x": -5,
      "y": 15,
      "z": -1,
      "name": "Rock_Stone_Brick_Smooth",
      "rotation": 2
    },
    {
      "x": -5,
      "y": 16,
      "z": -1,
      "name": "Soil_Gravel",
      "support": 15,
      "rotation": 2
    },
    {
      "x": -5,
      "y": 21,
      "z": -1,
      "name": "Cloth_Block_Wool_Pink",
      "rotation": 2
    },
    {
      "x": -5,
      "y": 9,
      "z": 0,
      "name": "Rock_Stone_Brick_Smooth",
      "rotation": 2
    },
    {
      "x": -5,
      "y": 15,
      "z": 0,
      "name": "Rock_Stone_Brick_Smooth",
      "rotation": 2
    },
    {
      "x": -5,
      "y": 16,
      "z": 0,
      "name": "Soil_Gravel",
      "support": 15,
      "rotation": 2
    },
    {
      "x": -5,
      "y": 21,
      "z": 0,
      "name": "Cloth_Block_Wool_Pink",
      "rotation": 2
    },
    {
      "x": -5,
      "y": 9,
      "z": 1,
      "name": "Rock_Stone_Brick_Smooth",
      "rotation": 2
    },
    {
      "x": -5,
      "y": 15,
      "z": 1,
      "name": "Rock_Stone_Brick_Smooth",
      "rotation": 2
    },
    {
      "x": -5,
      "y": 16,
      "z": 1,
      "name": "Soil_Gravel",
      "support": 15,
      "rotation": 2
    },
    {
      "x": -5,
      "y": 21,
      "z": 1,
      "name": "Cloth_Block_Wool_Green",
      "rotation": 2
    },
    {
      "x": -5,
      "y": 9,
      "z": 2,
      "name": "Rock_Stone_Brick_Smooth",
      "rotation": 2
    },
    {
      "x": -5,
      "y": 15,
      "z": 2,
      "name": "Rock_Stone_Brick_Smooth",
      "rotation": 2
    },
    {
      "x": -5,
      "y": 16,
      "z": 2,
      "name": "Soil_Gravel",
      "support": 15,
      "rotation": 2
    },
    {
      "x": -5,
      "y": 21,
      "z": 2,
      "name": "Cloth_Block_Wool_Green",
      "rotation": 2
    },
    {
      "x": -5,
      "y": 10,
      "z": 3,
      "name": "Rock_Stone_Brick_Decorative",
      "rotation": 2
    },
    {
      "x": -5,
      "y": 11,
      "z": 3,
      "name": "Soil_Gravel",
      "support": 15,
      "rotation": 2
    },
    {
      "x": -5,
      "y": 12,
      "z": 3,
      "name": "Soil_Gravel",
      "support": 15,
      "rotation": 2
    },
    {
      "x": -5,
      "y": 13,
      "z": 3,
      "name": "Soil_Gravel",
      "support": 15,
      "rotation": 2
    },
    {
      "x": -5,
      "y": 14,
      "z": 3,
      "name": "Soil_Gravel",
      "support": 15,
      "rotation": 2
    },
    {
      "x": -5,
      "y": 21,
      "z": 3,
      "name": "Cloth_Block_Wool_Green",
      "rotation": 2
    },
    {
      "x": -5,
      "y": 21,
      "z": 4,
      "name": "Cloth_Block_Wool_Green",
      "rotation": 2
    },
    {
      "x": -5,
      "y": 21,
      "z": 5,
      "name": "Cloth_Block_Wool_Green",
      "rotation": 2
    },
    {
      "x": -5,
      "y": 21,
      "z": 6,
      "name": "Cloth_Block_Wool_Green",
      "rotation": 2
    },
    {
      "x": -5,
      "y": 21,
      "z": 7,
      "name": "Cloth_Block_Wool_Green",
      "rotation": 2
    },
    {
      "x": -5,
      "y": 21,
      "z": 8,
      "name": "Cloth_Block_Wool_Green",
      "rotation": 2
    },
    {
      "x": -5,
      "y": 21,
      "z": 9,
      "name": "Cloth_Block_Wool_Green",
      "rotation": 2
    },
    {
      "x": -5,
      "y": 21,
      "z": 10,
      "name": "Cloth_Block_Wool_Green",
      "rotation": 2
    },
    {
      "x": -5,
      "y": 21,
      "z": 11,
      "name": "Cloth_Block_Wool_Green",
      "rotation": 2
    },
    {
      "x": -4,
      "y": 21,
      "z": -10,
      "name": "Cloth_Block_Wool_Pink",
      "rotation": 2
    },
    {
      "x": -4,
      "y": 9,
      "z": -2,
      "name": "Rock_Stone_Brick"
    },
    {
      "x": -4,
      "y": 10,
      "z": -2,
      "name": "Rock_Stone_Brick_Decorative",
      "rotation": 2
    },
    {
      "x": -4,
      "y": 11,
      "z": -2,
      "name": "Soil_Gravel",
      "support": 15,
      "rotation": 2
    },
    {
      "x": -4,
      "y": 12,
      "z": -2,
      "name": "Soil_Gravel",
      "support": 15,
      "rotation": 2
    },
    {
      "x": -4,
      "y": 13,
      "z": -2,
      "name": "Soil_Gravel",
      "support": 15,
      "rotation": 2
    },
    {
      "x": -4,
      "y": 14,
      "z": -2,
      "name": "Soil_Gravel",
      "support": 15,
      "rotation": 2
    },
    {
      "x": -4,
      "y": 15,
      "z": -2,
      "name": "Rock_Stone_Brick_Smooth",
      "rotation": 2
    },
    {
      "x": -4,
      "y": 1,
      "z": -1,
      "name": "Rock_Stone_Brick_Smooth"
    },
    {
      "x": -4,
      "y": 2,
      "z": -1,
      "name": "Soil_Gravel",
      "support": 15
    },
    {
      "x": -4,
      "y": 3,
      "z": -1,
      "name": "Soil_Gravel",
      "support": 15
    },
    {
      "x": -4,
      "y": 4,
      "z": -1,
      "name": "Soil_Gravel",
      "support": 15
    },
    {
      "x": -4,
      "y": 5,
      "z": -1,
      "name": "Rock_Stone_Brick_Smooth"
    },
    {
      "x": -4,
      "y": 6,
      "z": -1,
      "name": "Soil_Gravel",
      "support": 15
    },
    {
      "x": -4,
      "y": 7,
      "z": -1,
      "name": "Soil_Gravel",
      "support": 15
    },
    {
      "x": -4,
      "y": 8,
      "z": -1,
      "name": "Soil_Gravel",
      "support": 15
    },
    {
      "x": -4,
      "y": 9,
      "z": -1,
      "name": "Rock_Stone_Brick_Smooth",
      "rotation": 2
    },
    {
      "x": -4,
      "y": 15,
      "z": -1,
      "name": "Rock_Stone_Brick_Smooth",
      "rotation": 2
    },
    {
      "x": -4,
      "y": 1,
      "z": 0,
      "name": "Rock_Stone_Brick_Smooth"
    },
    {
      "x": -4,
      "y": 2,
      "z": 0,
      "name": "Soil_Gravel",
      "support": 15
    },
    {
      "x": -4,
      "y": 3,
      "z": 0,
      "name": "Soil_Gravel",
      "support": 15
    },
    {
      "x": -4,
      "y": 4,
      "z": 0,
      "name": "Soil_Gravel",
      "support": 15
    },
    {
      "x": -4,
      "y": 5,
      "z": 0,
      "name": "Rock_Stone_Brick_Smooth"
    },
    {
      "x": -4,
      "y": 6,
      "z": 0,
      "name": "Soil_Gravel",
      "support": 15
    },
    {
      "x": -4,
      "y": 7,
      "z": 0,
      "name": "Soil_Gravel",
      "support": 15
    },
    {
      "x": -4,
      "y": 8,
      "z": 0,
      "name": "Soil_Gravel",
      "support": 15
    },
    {
      "x": -4,
      "y": 9,
      "z": 0,
      "name": "Rock_Stone_Brick_Smooth",
      "rotation": 2
    },
    {
      "x": -4,
      "y": 15,
      "z": 0,
      "name": "Rock_Stone_Brick_Smooth",
      "rotation": 2
    },
    {
      "x": -4,
      "y": 21,
      "z": 0,
      "name": "Cloth_Block_Wool_Pink",
      "rotation": 2
    },
    {
      "x": -4,
      "y": 1,
      "z": 1,
      "name": "Rock_Stone_Brick_Smooth"
    },
    {
      "x": -4,
      "y": 2,
      "z": 1,
      "name": "Soil_Gravel",
      "support": 15
    },
    {
      "x": -4,
      "y": 3,
      "z": 1,
      "name": "Soil_Gravel",
      "support": 15
    },
    {
      "x": -4,
      "y": 4,
      "z": 1,
      "name": "Soil_Gravel",
      "support": 15
    },
    {
      "x": -4,
      "y": 5,
      "z": 1,
      "name": "Rock_Stone_Brick_Smooth"
    },
    {
      "x": -4,
      "y": 6,
      "z": 1,
      "name": "Soil_Gravel",
      "support": 15
    },
    {
      "x": -4,
      "y": 7,
      "z": 1,
      "name": "Soil_Gravel",
      "support": 15
    },
    {
      "x": -4,
      "y": 8,
      "z": 1,
      "name": "Soil_Gravel",
      "support": 15
    },
    {
      "x": -4,
      "y": 9,
      "z": 1,
      "name": "Rock_Stone_Brick_Smooth",
      "rotation": 2
    },
    {
      "x": -4,
      "y": 15,
      "z": 1,
      "name": "Rock_Stone_Brick_Smooth",
      "rotation": 2
    },
    {
      "x": -4,
      "y": 21,
      "z": 1,
      "name": "Cloth_Block_Wool_Green",
      "rotation": 2
    },
    {
      "x": -4,
      "y": 1,
      "z": 2,
      "name": "Rock_Stone_Brick_Smooth"
    },
    {
      "x": -4,
      "y": 2,
      "z": 2,
      "name": "Soil_Gravel",
      "support": 15
    },
    {
      "x": -4,
      "y": 3,
      "z": 2,
      "name": "Soil_Gravel",
      "support": 15
    },
    {
      "x": -4,
      "y": 4,
      "z": 2,
      "name": "Soil_Gravel",
      "support": 15
    },
    {
      "x": -4,
      "y": 5,
      "z": 2,
      "name": "Rock_Stone_Brick_Smooth"
    },
    {
      "x": -4,
      "y": 6,
      "z": 2,
      "name": "Soil_Gravel",
      "support": 15
    },
    {
      "x": -4,
      "y": 7,
      "z": 2,
      "name": "Soil_Gravel",
      "support": 15
    },
    {
      "x": -4,
      "y": 8,
      "z": 2,
      "name": "Soil_Gravel",
      "support": 15
    },
    {
      "x": -4,
      "y": 9,
      "z": 2,
      "name": "Rock_Stone_Brick_Smooth",
      "rotation": 2
    },
    {
      "x": -4,
      "y": 15,
      "z": 2,
      "name": "Rock_Stone_Brick_Smooth",
      "rotation": 2
    },
    {
      "x": -4,
      "y": 9,
      "z": 3,
      "name": "Rock_Stone_Brick"
    },
    {
      "x": -4,
      "y": 10,
      "z": 3,
      "name": "Rock_Stone_Brick_Decorative",
      "rotation": 2
    },
    {
      "x": -4,
      "y": 11,
      "z": 3,
      "name": "Soil_Gravel",
      "support": 15,
      "rotation": 2
    },
    {
      "x": -4,
      "y": 12,
      "z": 3,
      "name": "Soil_Gravel",
      "support": 15,
      "rotation": 2
    },
    {
      "x": -4,
      "y": 13,
      "z": 3,
      "name": "Soil_Gravel",
      "support": 15,
      "rotation": 2
    },
    {
      "x": -4,
      "y": 14,
      "z": 3,
      "name": "Soil_Gravel",
      "support": 15,
      "rotation": 2
    },
    {
      "x": -4,
      "y": 15,
      "z": 3,
      "name": "Rock_Stone_Brick_Smooth",
      "rotation": 2
    },
    {
      "x": -4,
      "y": 21,
      "z": 11,
      "name": "Cloth_Block_Wool_Green",
      "rotation": 2
    },
    {
      "x": -3,
      "y": 12,
      "z": -10,
      "name": "Rock_Stone_Brick",
      "rotation": 1
    },
    {
      "x": -3,
      "y": 13,
      "z": -10,
      "name": "Rock_Stone_Brick_Decorative",
      "rotation": 1
    },
    {
      "x": -3,
      "y": 14,
      "z": -10,
      "name": "Soil_Gravel",
      "support": 15,
      "rotation": 1
    },
    {
      "x": -3,
      "y": 15,
      "z": -10,
      "name": "Soil_Gravel",
      "support": 15,
      "rotation": 1
    },
    {
      "x": -3,
      "y": 16,
      "z": -10,
      "name": "Soil_Gravel",
      "support": 15,
      "rotation": 1
    },
    {
      "x": -3,
      "y": 17,
      "z": -10,
      "name": "Soil_Gravel",
      "support": 15,
      "rotation": 1
    },
    {
      "x": -3,
      "y": 18,
      "z": -10,
      "name": "Rock_Stone_Brick_Smooth",
      "rotation": 1
    },
    {
      "x": -3,
      "y": 21,
      "z": -10,
      "name": "Cloth_Block_Wool_Pink",
      "rotation": 2
    },
    {
      "x": -3,
      "y": 12,
      "z": -9,
      "name": "Rock_Stone_Brick",
      "rotation": 1
    },
    {
      "x": -3,
      "y": 13,
      "z": -9,
      "name": "Rock_Stone_Brick_Decorative",
      "rotation": 2
    },
    {
      "x": -3,
      "y": 14,
      "z": -9,
      "name": "Soil_Gravel",
      "support": 15,
      "rotation": 2
    },
    {
      "x": -3,
      "y": 15,
      "z": -9,
      "name": "Soil_Gravel",
      "support": 15,
      "rotation": 2
    },
    {
      "x": -3,
      "y": 16,
      "z": -9,
      "name": "Soil_Gravel",
      "support": 15,
      "rotation": 2
    },
    {
      "x": -3,
      "y": 17,
      "z": -9,
      "name": "Soil_Gravel",
      "support": 15,
      "rotation": 2
    },
    {
      "x": -3,
      "y": 18,
      "z": -9,
      "name": "Rock_Stone_Brick_Smooth",
      "rotation": 2
    },
    {
      "x": -3,
      "y": 12,
      "z": -8,
      "name": "Rock_Stone_Brick",
      "rotation": 1
    },
    {
      "x": -3,
      "y": 13,
      "z": -8,
      "name": "Rock_Stone_Brick_Decorative"
    },
    {
      "x": -3,
      "y": 14,
      "z": -8,
      "name": "Soil_Gravel",
      "support": 15
    },
    {
      "x": -3,
      "y": 15,
      "z": -8,
      "name": "Soil_Gravel",
      "support": 15
    },
    {
      "x": -3,
      "y": 16,
      "z": -8,
      "name": "Soil_Gravel",
      "support": 15
    },
    {
      "x": -3,
      "y": 17,
      "z": -8,
      "name": "Soil_Gravel",
      "support": 15
    },
    {
      "x": -3,
      "y": 18,
      "z": -8,
      "name": "Rock_Stone_Brick_Smooth"
    },
    {
      "x": -3,
      "y": 12,
      "z": -7,
      "name": "Rock_Stone_Brick",
      "rotation": 1
    },
    {
      "x": -3,
      "y": 13,
      "z": -7,
      "name": "Rock_Stone_Brick_Decorative"
    },
    {
      "x": -3,
      "y": 14,
      "z": -7,
      "name": "Soil_Gravel",
      "support": 15,
      "rotation": 3
    },
    {
      "x": -3,
      "y": 15,
      "z": -7,
      "name": "Soil_Gravel",
      "support": 15,
      "rotation": 3
    },
    {
      "x": -3,
      "y": 16,
      "z": -7,
      "name": "Soil_Gravel",
      "support": 15,
      "rotation": 3
    },
    {
      "x": -3,
      "y": 17,
      "z": -7,
      "name": "Soil_Gravel",
      "support": 15,
      "rotation": 3
    },
    {
      "x": -3,
      "y": 18,
      "z": -7,
      "name": "Rock_Stone_Brick_Smooth"
    },
    {
      "x": -3,
      "y": 12,
      "z": -6,
      "name": "Rock_Stone_Brick",
      "rotation": 1
    },
    {
      "x": -3,
      "y": 13,
      "z": -6,
      "name": "Rock_Stone_Brick_Decorative",
      "rotation": 3
    },
    {
      "x": -3,
      "y": 14,
      "z": -6,
      "name": "Soil_Gravel",
      "support": 15,
      "rotation": 3
    },
    {
      "x": -3,
      "y": 15,
      "z": -6,
      "name": "Soil_Gravel",
      "support": 15,
      "rotation": 3
    },
    {
      "x": -3,
      "y": 16,
      "z": -6,
      "name": "Soil_Gravel",
      "support": 15,
      "rotation": 3
    },
    {
      "x": -3,
      "y": 17,
      "z": -6,
      "name": "Soil_Gravel",
      "support": 15,
      "rotation": 3
    },
    {
      "x": -3,
      "y": 18,
      "z": -6,
      "name": "Rock_Stone_Brick_Smooth"
    },
    {
      "x": -3,
      "y": 12,
      "z": -5,
      "name": "Rock_Stone_Brick",
      "rotation": 1
    },
    {
      "x": -3,
      "y": 13,
      "z": -5,
      "name": "Rock_Stone_Brick_Decorative",
      "rotation": 3
    },
    {
      "x": -3,
      "y": 14,
      "z": -5,
      "name": "Soil_Gravel",
      "support": 15,
      "rotation": 3
    },
    {
      "x": -3,
      "y": 15,
      "z": -5,
      "name": "Soil_Gravel",
      "support": 15,
      "rotation": 3
    },
    {
      "x": -3,
      "y": 16,
      "z": -5,
      "name": "Soil_Gravel",
      "support": 15,
      "rotation": 3
    },
    {
      "x": -3,
      "y": 17,
      "z": -5,
      "name": "Soil_Gravel",
      "support": 15,
      "rotation": 3
    },
    {
      "x": -3,
      "y": 18,
      "z": -5,
      "name": "Rock_Stone_Brick_Smooth"
    },
    {
      "x": -3,
      "y": 12,
      "z": -4,
      "name": "Rock_Stone_Brick",
      "rotation": 1
    },
    {
      "x": -3,
      "y": 13,
      "z": -4,
      "name": "Rock_Stone_Brick_Decorative",
      "rotation": 3
    },
    {
      "x": -3,
      "y": 14,
      "z": -4,
      "name": "Soil_Gravel",
      "support": 15,
      "rotation": 3
    },
    {
      "x": -3,
      "y": 15,
      "z": -4,
      "name": "Soil_Gravel",
      "support": 15,
      "rotation": 3
    },
    {
      "x": -3,
      "y": 16,
      "z": -4,
      "name": "Soil_Gravel",
      "support": 15,
      "rotation": 3
    },
    {
      "x": -3,
      "y": 17,
      "z": -4,
      "name": "Soil_Gravel",
      "support": 15,
      "rotation": 3
    },
    {
      "x": -3,
      "y": 18,
      "z": -4,
      "name": "Rock_Stone_Brick_Smooth",
      "rotation": 2
    },
    {
      "x": -3,
      "y": 1,
      "z": -3,
      "name": "Rock_Stone_Brick_Smooth",
      "rotation": 2
    },
    {
      "x": -3,
      "y": 2,
      "z": -3,
      "name": "Rock_Stone_Brick_Decorative",
      "rotation": 2
    },
    {
      "x": -3,
      "y": 3,
      "z": -3,
      "name": "Rock_Stone_Brick",
      "rotation": 2
    },
    {
      "x": -3,
      "y": 4,
      "z": -3,
      "name": "Rock_Stone_Brick",
      "rotation": 2
    },
    {
      "x": -3,
      "y": 5,
      "z": -3,
      "name": "Rock_Stone_Brick_Smooth",
      "rotation": 2
    },
    {
      "x": -3,
      "y": 6,
      "z": -3,
      "name": "Rock_Stone_Brick_Decorative",
      "rotation": 2
    },
    {
      "x": -3,
      "y": 7,
      "z": -3,
      "name": "Rock_Stone_Brick",
      "rotation": 2
    },
    {
      "x": -3,
      "y": 8,
      "z": -3,
      "name": "Rock_Stone_Brick",
      "rotation": 2
    },
    {
      "x": -3,
      "y": 9,
      "z": -3,
      "name": "Rock_Stone_Brick",
      "rotation": 1
    },
    {
      "x": -3,
      "y": 10,
      "z": -3,
      "name": "Rock_Stone_Brick_Decorative",
      "rotation": 3
    },
    {
      "x": -3,
      "y": 11,
      "z": -3,
      "name": "Soil_Gravel",
      "support": 15,
      "rotation": 3
    },
    {
      "x": -3,
      "y": 12,
      "z": -3,
      "name": "Soil_Gravel",
      "support": 15,
      "rotation": 3
    },
    {
      "x": -3,
      "y": 13,
      "z": -3,
      "name": "Soil_Gravel",
      "support": 15,
      "rotation": 3
    },
    {
      "x": -3,
      "y": 14,
      "z": -3,
      "name": "Soil_Gravel",
      "support": 15,
      "rotation": 3
    },
    {
      "x": -3,
      "y": 15,
      "z": -3,
      "name": "Rock_Stone_Brick_Smooth",
      "rotation": 2
    },
    {
      "x": -3,
      "y": 1,
      "z": -2,
      "name": "Rock_Stone_Brick_Smooth",
      "rotation": 2
    },
    {
      "x": -3,
      "y": 2,
      "z": -2,
      "name": "Rock_Stone_Brick_Decorative",
      "rotation": 2
    },
    {
      "x": -3,
      "y": 3,
      "z": -2,
      "name": "Rock_Stone_Brick",
      "rotation": 2
    },
    {
      "x": -3,
      "y": 4,
      "z": -2,
      "name": "Rock_Stone_Brick",
      "rotation": 2
    },
    {
      "x": -3,
      "y": 5,
      "z": -2,
      "name": "Rock_Stone_Brick_Smooth",
      "rotation": 2
    },
    {
      "x": -3,
      "y": 6,
      "z": -2,
      "name": "Rock_Stone_Brick_Decorative",
      "rotation": 2
    },
    {
      "x": -3,
      "y": 7,
      "z": -2,
      "name": "Rock_Stone_Brick",
      "rotation": 2
    },
    {
      "x": -3,
      "y": 8,
      "z": -2,
      "name": "Rock_Stone_Brick",
      "rotation": 2
    },
    {
      "x": -3,
      "y": 9,
      "z": -2,
      "name": "Rock_Stone_Brick",
      "rotation": 1
    },
    {
      "x": -3,
      "y": 10,
      "z": -2,
      "name": "Rock_Stone_Brick_Decorative",
      "rotation": 1
    },
    {
      "x": -3,
      "y": 11,
      "z": -2,
      "name": "Rock_Stone_Brick",
      "rotation": 2
    },
    {
      "x": -3,
      "y": 12,
      "z": -2,
      "name": "Rock_Stone_Brick",
      "rotation": 2
    },
    {
      "x": -3,
      "y": 13,
      "z": -2,
      "name": "Rock_Stone_Brick",
      "rotation": 2
    },
    {
      "x": -3,
      "y": 14,
      "z": -2,
      "name": "Rock_Stone_Brick",
      "rotation": 2
    },
    {
      "x": -3,
      "y": 15,
      "z": -2,
      "name": "Rock_Stone_Brick_Smooth",
      "rotation": 1
    },
    {
      "x": -3,
      "y": 1,
      "z": -1,
      "name": "Rock_Stone_Brick_Smooth",
      "rotation": 2
    },
    {
      "x": -3,
      "y": 2,
      "z": -1,
      "name": "Rock_Stone_Brick_Smooth_Half",
      "rotation": 4
    },
    {
      "x": -3,
      "y": 3,
      "z": -1,
      "name": "Rock_Stone_Brick_Smooth_Half",
      "rotation": 4
    },
    {
      "x": -3,
      "y": 4,
      "z": -1,
      "name": "Rock_Stone_Brick_Smooth_Half",
      "rotation": 4
    },
    {
      "x": -3,
      "y": 5,
      "z": -1,
      "name": "Rock_Stone_Brick_Smooth",
      "rotation": 2
    },
    {
      "x": -3,
      "y": 6,
      "z": -1,
      "name": "Rock_Stone_Brick_Smooth_Half",
      "rotation": 4
    },
    {
      "x": -3,
      "y": 7,
      "z": -1,
      "name": "Rock_Stone_Brick_Smooth_Half",
      "rotation": 4
    },
    {
      "x": -3,
      "y": 8,
      "z": -1,
      "name": "Rock_Stone_Brick_Smooth_Half",
      "rotation": 4
    },
    {
      "x": -3,
      "y": 9,
      "z": -1,
      "name": "Rock_Stone_Brick_Smooth",
      "rotation": 2
    },
    {
      "x": -3,
      "y": 10,
      "z": -1,
      "name": "Rock_Stone_Brick_Smooth_Half",
      "rotation": 4
    },
    {
      "x": -3,
      "y": 11,
      "z": -1,
      "name": "Rock_Stone_Brick_Smooth_Half",
      "rotation": 4
    },
    {
      "x": -3,
      "y": 12,
      "z": -1,
      "name": "Rock_Stone_Brick_Smooth_Half",
      "rotation": 4
    },
    {
      "x": -3,
      "y": 13,
      "z": -1,
      "name": "Rock_Stone_Brick_Smooth_Half",
      "rotation": 4
    },
    {
      "x": -3,
      "y": 14,
      "z": -1,
      "name": "Rock_Stone_Brick_Smooth_Half",
      "rotation": 4
    },
    {
      "x": -3,
      "y": 15,
      "z": -1,
      "name": "Rock_Stone_Brick_Smooth",
      "rotation": 2
    },
    {
      "x": -3,
      "y": 1,
      "z": 0,
      "name": "Rock_Stone_Brick_Smooth",
      "rotation": 2
    },
    {
      "x": -3,
      "y": 2,
      "z": 0,
      "name": "Furniture_Village_Coffin",
      "filler": 992,
      "rotation": 1
    },
    {
      "x": -3,
      "y": 5,
      "z": 0,
      "name": "Rock_Stone_Brick_Smooth",
      "rotation": 2
    },
    {
      "x": -3,
      "y": 6,
      "z": 0,
      "name": "Furniture_Village_Coffin",
      "filler": 992,
      "rotation": 1
    },
    {
      "x": -3,
      "y": 9,
      "z": 0,
      "name": "Rock_Stone_Brick_Smooth",
      "rotation": 2
    },
    {
      "x": -3,
      "y": 15,
      "z": 0,
      "name": "Rock_Stone_Brick_Smooth",
      "rotation": 2
    },
    {
      "x": -3,
      "y": 21,
      "z": 0,
      "name": "Cloth_Block_Wool_Pink",
      "rotation": 2
    },
    {
      "x": -3,
      "y": 1,
      "z": 1,
      "name": "Rock_Stone_Brick_Smooth",
      "rotation": 2
    },
    {
      "x": -3,
      "y": 2,
      "z": 1,
      "name": "Furniture_Village_Coffin",
      "rotation": 1
    },
    {
      "x": -3,
      "y": 5,
      "z": 1,
      "name": "Rock_Stone_Brick_Smooth",
      "rotation": 2
    },
    {
      "x": -3,
      "y": 6,
      "z": 1,
      "name": "Furniture_Village_Coffin",
      "rotation": 1
    },
    {
      "x": -3,
      "y": 9,
      "z": 1,
      "name": "Rock_Stone_Brick_Smooth"
    },
    {
      "x": -3,
      "y": 15,
      "z": 1,
      "name": "Rock_Stone_Brick_Smooth",
      "rotation": 1
    },
    {
      "x": -3,
      "y": 21,
      "z": 1,
      "name": "Cloth_Block_Wool_Green",
      "rotation": 2
    },
    {
      "x": -3,
      "y": 1,
      "z": 2,
      "name": "Rock_Stone_Brick_Smooth",
      "rotation": 2
    },
    {
      "x": -3,
      "y": 2,
      "z": 2,
      "name": "Rock_Stone_Brick_Smooth_Half",
      "rotation": 6
    },
    {
      "x": -3,
      "y": 3,
      "z": 2,
      "name": "Rock_Stone_Brick_Smooth_Half",
      "rotation": 6
    },
    {
      "x": -3,
      "y": 4,
      "z": 2,
      "name": "Rock_Stone_Brick_Smooth_Half",
      "rotation": 6
    },
    {
      "x": -3,
      "y": 5,
      "z": 2,
      "name": "Rock_Stone_Brick_Smooth",
      "rotation": 2
    },
    {
      "x": -3,
      "y": 6,
      "z": 2,
