{
  "version": 8,
  "blockIdVersion": 11,
  "anchorX": 0,
  "anchorY": 0,
  "anchorZ": 0,
  "blocks": [
    {
      "x": -3,
      "y": 0,
      "z": -3,
      "name": "Rock_Basalt"
    },
    {
      "x": -3,
      "y": 1,
      "z": -3,
      "name": "Rock_Basalt"
    },
    {
      "x": -3,
      "y": 2,
      "z": -3,
      "name": "Rock_Basalt"
    },
    {
      "x": -3,
      "y": 3,
      "z": -3,
      "name": "Rock_Basalt"
    },
    {
      "x": -3,
      "y": 4,
      "z": -3,
      "name": "Rock_Stone"
    },
    {
      "x": -3,
      "y": 5,
      "z": -3,
      "name": "Rock_Stone"
    },
    {
      "x": -3,
      "y": 6,
      "z": -3,
      "name": "Rock_Stone"
    },
    {
      "x": -3,
      "y": 7,
      "z": -3,
      "name": "Rock_Stone"
    },
    {
      "x": -3,
      "y": 8,
      "z": -3,
      "name": "Rock_Stone_Mossy"
    },
    {
      "x": -3,
      "y": 0,
      "z": -2,
      "name": "Rock_Basalt"
    },
    {
      "x": -3,
      "y": 1,
      "z": -2,
      "name": "Rock_Basalt"
    },
    {
      "x": -3,
      "y": 2,
      "z": -2,
      "name": "Rock_Basalt"
    },
    {
      "x": -3,
      "y": 3,
      "z": -2,
      "name": "Rock_Basalt"
    },
    {
      "x": -3,
      "y": 4,
      "z": -2,
      "name": "Rock_Stone"
    },
    {
      "x": -3,
      "y": 5,
      "z": -2,
      "name": "Rock_Stone"
    },
    {
      "x": -3,
      "y": 6,
      "z": -2,
      "name": "Rock_Stone"
    },
    {
      "x": -3,
      "y": 7,
      "z": -2,
      "name": "Rock_Stone"
    },
    {
      "x": -3,
      "y": 8,
      "z": -2,
      "name": "Soil_Ash"
    },
    {
      "x": -3,
      "y": 0,
      "z": -1,
      "name": "Rock_Basalt"
    },
    {
      "x": -3,
      "y": 1,
      "z": -1,
      "name": "Rock_Basalt"
    },
    {
      "x": -3,
      "y": 2,
      "z": -1,
      "name": "Rock_Basalt"
    },
    {
      "x": -3,
      "y": 3,
      "z": -1,
      "name": "Rock_Basalt"
    },
    {
      "x": -3,
      "y": 4,
      "z": -1,
      "name": "Rock_Stone"
    },
    {
      "x": -3,
      "y": 5,
      "z": -1,
      "name": "Rock_Stone"
    },
    {
      "x": -3,
      "y": 6,
      "z": -1,
      "name": "Rock_Stone"
    },
    {
      "x": -3,
      "y": 7,
      "z": -1,
      "name": "Rock_Stone"
    },
    {
      "x": -3,
      "y": 8,
      "z": -1,
      "name": "Soil_Ash"
    },
    {
      "x": -3,
      "y": 0,
      "z": 0,
      "name": "Rock_Basalt"
    },
    {
      "x": -3,
      "y": 1,
      "z": 0,
      "name": "Rock_Basalt"
    },
    {
      "x": -3,
      "y": 2,
      "z": 0,
      "name": "Rock_Basalt"
    },
    {
      "x": -3,
      "y": 3,
      "z": 0,
      "name": "Rock_Basalt"
    },
    {
      "x": -3,
      "y": 4,
      "z": 0,
      "name": "Rock_Stone"
    },
    {
      "x": -3,
      "y": 5,
      "z": 0,
      "name": "Rock_Stone"
    },
    {
      "x": -3,
      "y": 6,
      "z": 0,
      "name": "Rock_Stone"
    },
    {
      "x": -3,
      "y": 7,
      "z": 0,
      "name": "Rock_Stone"
    },
    {
      "x": -3,
      "y": 8,
      "z": 0,
      "name": "Soil_Ash"
    },
    {
      "x": -3,
      "y": 0,
      "z": 1,
      "name": "Rock_Basalt"
    },
    {
      "x": -3,
      "y": 1,
      "z": 1,
      "name": "Rock_Basalt"
    },
    {
      "x": -3,
      "y": 2,
      "z": 1,
      "name": "Rock_Basalt"
    },
    {
      "x": -3,
      "y": 3,
      "z": 1,
      "name": "Rock_Basalt"
    },
    {
      "x": -3,
      "y": 4,
      "z": 1,
      "name": "Rock_Stone"
    },
    {
      "x": -3,
      "y": 5,
      "z": 1,
      "name": "Rock_Stone"
    },
    {
      "x": -3,
      "y": 6,
      "z": 1,
      "name": "Rock_Stone"
    },
    {
      "x": -3,
      "y": 7,
      "z": 1,
      "name": "Rock_Stone"
    },
    {
      "x": -3,
      "y": 8,
      "z": 1,
      "name": "Soil_Ash"
    },
    {
      "x": -3,
      "y": 0,
      "z": 2,
      "name": "Rock_Basalt"
    },
    {
      "x": -3,
      "y": 1,
      "z": 2,
      "name": "Rock_Basalt"
    },
    {
      "x": -3,
      "y": 2,
      "z": 2,
      "name": "Rock_Basalt"
    },
    {
      "x": -3,
      "y": 3,
      "z": 2,
      "name": "Rock_Basalt"
    },
    {
      "x": -3,
      "y": 4,
      "z": 2,
      "name": "Rock_Stone"
    },
    {
      "x": -3,
      "y": 5,
      "z": 2,
      "name": "Rock_Stone"
    },
    {
      "x": -3,
      "y": 6,
      "z": 2,
      "name": "Rock_Stone"
    },
    {
      "x": -3,
      "y": 7,
      "z": 2,
      "name": "Rock_Stone"
    },
    {
      "x": -3,
      "y": 8,
      "z": 2,
      "name": "Soil_Ash"
    },
    {
      "x": -3,
      "y": 0,
      "z": 3,
      "name": "Rock_Basalt"
    },
    {
      "x": -3,
      "y": 1,
      "z": 3,
      "name": "Rock_Basalt"
    },
    {
      "x": -3,
      "y": 2,
      "z": 3,
      "name": "Rock_Basalt"
    },
    {
      "x": -3,
      "y": 3,
      "z": 3,
      "name": "Rock_Basalt"
    },
    {
      "x": -3,
      "y": 4,
      "z": 3,
      "name": "Rock_Stone"
    },
    {
      "x": -3,
      "y": 5,
      "z": 3,
      "name": "Rock_Stone"
    },
    {
      "x": -3,
      "y": 6,
      "z": 3,
      "name": "Rock_Stone"
    },
    {
      "x": -3,
      "y": 7,
      "z": 3,
      "name": "Rock_Stone"
    },
    {
      "x": -3,
      "y": 8,
      "z": 3,
      "name": "Rock_Stone"
    },
    {
      "x": -2,
      "y": 0,
      "z": -3,
      "name": "Rock_Basalt"
    },
    {
      "x": -2,
      "y": 1,
      "z": -3,
      "name": "Rock_Basalt"
    },
    {
      "x": -2,
      "y": 2,
      "z": -3,
      "name": "Rock_Basalt"
    },
    {
      "x": -2,
      "y": 3,
      "z": -3,
      "name": "Rock_Basalt"
    },
    {
      "x": -2,
      "y": 4,
      "z": -3,
      "name": "Rock_Stone"
    },
    {
      "x": -2,
      "y": 5,
      "z": -3,
      "name": "Rock_Stone"
    },
    {
      "x": -2,
      "y": 6,
      "z": -3,
      "name": "Rock_Stone"
    },
    {
      "x": -2,
      "y": 7,
      "z": -3,
      "name": "Rock_Stone"
    },
    {
      "x": -2,
      "y": 8,
      "z": -3,
      "name": "Rock_Stone"
    },
    {
      "x": -2,
      "y": 0,
      "z": -2,
      "name": "Rock_Basalt"
    },
    {
      "x": -2,
      "y": 1,
      "z": -2,
      "name": "Rock_Basalt"
    },
    {
      "x": -2,
      "y": 2,
      "z": -2,
      "name": "Rock_Basalt"
    },
    {
      "x": -2,
      "y": 3,
      "z": -2,
      "name": "Rock_Basalt"
    },
    {
      "x": -2,
      "y": 4,
      "z": -2,
      "name": "Rock_Stone"
    },
    {
      "x": -2,
      "y": 5,
      "z": -2,
      "name": "Rock_Stone"
    },
    {
      "x": -2,
      "y": 6,
      "z": -2,
      "name": "Rock_Stone"
    },
    {
      "x": -2,
      "y": 7,
      "z": -2,
      "name": "Rock_Stone"
    },
    {
      "x": -2,
      "y": 8,
      "z": -2,
      "name": "Soil_Ash"
    },
    {
      "x": -2,
      "y": 0,
      "z": -1,
      "name": "Rock_Basalt"
    },
    {
      "x": -2,
      "y": 1,
      "z": -1,
      "name": "Rock_Basalt"
    },
    {
      "x": -2,
      "y": 2,
      "z": -1,
      "name": "Rock_Basalt"
    },
    {
      "x": -2,
      "y": 3,
      "z": -1,
      "name": "Rock_Basalt"
    },
    {
      "x": -2,
      "y": 4,
      "z": -1,
      "name": "Rock_Stone"
    },
    {
      "x": -2,
      "y": 5,
      "z": -1,
      "name": "Rock_Stone"
    },
    {
      "x": -2,
      "y": 6,
      "z": -1,
      "name": "Rock_Stone"
    },
    {
      "x": -2,
      "y": 7,
      "z": -1,
      "name": "Rock_Stone"
    },
    {
      "x": -2,
      "y": 8,
      "z": -1,
      "name": "Soil_Ash"
    },
    {
      "x": -2,
      "y": 0,
      "z": 0,
      "name": "Rock_Basalt"
    },
    {
      "x": -2,
      "y": 1,
      "z": 0,
      "name": "Rock_Basalt"
    },
    {
      "x": -2,
      "y": 2,
      "z": 0,
      "name": "Rock_Basalt"
    },
    {
      "x": -2,
      "y": 3,
      "z": 0,
      "name": "Rock_Basalt"
    },
    {
      "x": -2,
      "y": 4,
      "z": 0,
      "name": "Rock_Stone"
    },
    {
      "x": -2,
      "y": 5,
      "z": 0,
      "name": "Rock_Stone"
    },
    {
      "x": -2,
      "y": 6,
      "z": 0,
      "name": "Rock_Stone"
    },
    {
      "x": -2,
      "y": 7,
      "z": 0,
      "name": "Rock_Stone"
    },
    {
      "x": -2,
      "y": 8,
      "z": 0,
      "name": "Cloth_Block_Wool_Gray_Half"
    },
    {
      "x": -2,
      "y": 0,
      "z": 1,
      "name": "Rock_Basalt"
    },
    {
      "x": -2,
      "y": 1,
      "z": 1,
      "name": "Rock_Basalt"
    },
    {
      "x": -2,
      "y": 2,
      "z": 1,
      "name": "Rock_Basalt"
    },
    {
      "x": -2,
      "y": 3,
      "z": 1,
      "name": "Rock_Basalt"
    },
    {
      "x": -2,
      "y": 4,
      "z": 1,
      "name": "Rock_Stone"
    },
    {
      "x": -2,
      "y": 5,
      "z": 1,
      "name": "Rock_Stone"
    },
    {
      "x": -2,
      "y": 6,
      "z": 1,
      "name": "Rock_Stone"
    },
    {
      "x": -2,
      "y": 7,
      "z": 1,
      "name": "Rock_Stone"
    },
    {
      "x": -2,
      "y": 8,
      "z": 1,
      "name": "Soil_Ash"
    },
    {
      "x": -2,
      "y": 0,
      "z": 2,
      "name": "Rock_Basalt"
    },
    {
      "x": -2,
      "y": 1,
      "z": 2,
      "name": "Rock_Basalt"
    },
    {
      "x": -2,
      "y": 2,
      "z": 2,
      "name": "Rock_Basalt"
    },
    {
      "x": -2,
      "y": 3,
      "z": 2,
      "name": "Rock_Basalt"
    },
    {
      "x": -2,
      "y": 4,
      "z": 2,
      "name": "Rock_Stone"
    },
    {
      "x": -2,
      "y": 5,
      "z": 2,
      "name": "Rock_Stone"
    },
    {
      "x": -2,
      "y": 6,
      "z": 2,
      "name": "Rock_Stone"
    },
    {
      "x": -2,
      "y": 7,
      "z": 2,
      "name": "Rock_Stone"
    },
    {
      "x": -2,
      "y": 8,
      "z": 2,
      "name": "Soil_Ash"
    },
    {
      "x": -2,
      "y": 0,
      "z": 3,
      "name": "Rock_Basalt"
    },
    {
      "x": -2,
      "y": 1,
      "z": 3,
      "name": "Rock_Basalt"
    },
    {
      "x": -2,
      "y": 2,
      "z": 3,
      "name": "Rock_Basalt"
    },
    {
      "x": -2,
      "y": 3,
      "z": 3,
      "name": "Rock_Basalt"
    },
    {
      "x": -2,
      "y": 4,
      "z": 3,
      "name": "Rock_Stone"
    },
    {
      "x": -2,
      "y": 5,
      "z": 3,
      "name": "Rock_Stone"
    },
    {
      "x": -2,
      "y": 6,
      "z": 3,
      "name": "Rock_Stone"
    },
    {
      "x": -2,
      "y": 7,
      "z": 3,
      "name": "Rock_Stone"
    },
    {
      "x": -2,
      "y": 8,
      "z": 3,
      "name": "Rock_Stone"
    },
    {
      "x": -1,
      "y": 0,
      "z": -3,
      "name": "Rock_Basalt"
    },
    {
      "x": -1,
      "y": 1,
      "z": -3,
      "name": "Rock_Basalt"
    },
    {
      "x": -1,
      "y": 2,
      "z": -3,
      "name": "Rock_Basalt"
    },
    {
      "x": -1,
      "y": 3,
      "z": -3,
      "name": "Rock_Basalt"
    },
    {
      "x": -1,
      "y": 4,
      "z": -3,
      "name": "Rock_Stone"
    },
    {
      "x": -1,
      "y": 5,
      "z": -3,
      "name": "Rock_Stone"
    },
    {
      "x": -1,
      "y": 6,
      "z": -3,
      "name": "Rock_Stone"
    },
    {
      "x": -1,
      "y": 7,
      "z": -3,
      "name": "Rock_Stone"
    },
    {
      "x": -1,
      "y": 8,
      "z": -3,
      "name": "Rock_Stone"
    },
    {
      "x": -1,
      "y": 0,
      "z": -2,
      "name": "Rock_Basalt"
    },
    {
      "x": -1,
      "y": 1,
      "z": -2,
      "name": "Rock_Basalt"
    },
    {
      "x": -1,
      "y": 2,
      "z": -2,
      "name": "Rock_Basalt"
    },
    {
      "x": -1,
      "y": 3,
      "z": -2,
      "name": "Rock_Basalt"
    },
    {
      "x": -1,
      "y": 4,
      "z": -2,
      "name": "Rock_Stone"
    },
    {
      "x": -1,
      "y": 5,
      "z": -2,
      "name": "Rock_Stone"
    },
    {
      "x": -1,
      "y": 6,
      "z": -2,
      "name": "Rock_Stone"
    },
    {
      "x": -1,
      "y": 7,
      "z": -2,
      "name": "Rock_Stone"
    },
    {
      "x": -1,
      "y": 8,
      "z": -2,
      "name": "Soil_Ash"
    },
    {
      "x": -1,
      "y": 0,
      "z": -1,
      "name": "Rock_Basalt"
    },
    {
      "x": -1,
      "y": 1,
      "z": -1,
      "name": "Rock_Basalt"
    },
    {
      "x": -1,
      "y": 2,
      "z": -1,
      "name": "Rock_Basalt"
    },
    {
      "x": -1,
      "y": 3,
      "z": -1,
      "name": "Rock_Basalt"
    },
    {
      "x": -1,
      "y": 4,
      "z": -1,
      "name": "Rock_Stone"
    },
    {
      "x": -1,
      "y": 5,
      "z": -1,
      "name": "Rock_Stone"
    },
    {
      "x": -1,
      "y": 6,
      "z": -1,
      "name": "Rock_Stone"
    },
    {
      "x": -1,
      "y": 7,
      "z": -1,
      "name": "Rock_Stone"
    },
    {
      "x": -1,
      "y": 8,
      "z": -1,
      "name": "Soil_Ash"
    },
    {
      "x": -1,
      "y": 0,
      "z": 0,
      "name": "Rock_Basalt"
    },
    {
      "x": -1,
      "y": 1,
      "z": 0,
      "name": "Rock_Basalt"
    },
    {
      "x": -1,
      "y": 2,
      "z": 0,
      "name": "Rock_Basalt"
    },
    {
      "x": -1,
      "y": 3,
      "z": 0,
      "name": "Rock_Basalt"
    },
    {
      "x": -1,
      "y": 4,
      "z": 0,
      "name": "Rock_Stone"
    },
    {
      "x": -1,
      "y": 5,
      "z": 0,
      "name": "Rock_Stone"
    },
    {
      "x": -1,
      "y": 6,
      "z": 0,
      "name": "Rock_Stone"
    },
    {
      "x": -1,
      "y": 7,
      "z": 0,
      "name": "Rock_Stone"
    },
    {
      "x": -1,
      "y": 8,
      "z": 0,
      "name": "Cloth_Block_Wool_Gray_Stairs",
      "rotation": 3
    },
    {
      "x": -1,
      "y": 0,
      "z": 1,
      "name": "Rock_Basalt"
    },
    {
      "x": -1,
      "y": 1,
      "z": 1,
      "name": "Rock_Basalt"
    },
    {
      "x": -1,
      "y": 2,
      "z": 1,
      "name": "Rock_Basalt"
    },
    {
      "x": -1,
      "y": 3,
      "z": 1,
      "name": "Rock_Basalt"
    },
    {
      "x": -1,
      "y": 4,
      "z": 1,
      "name": "Rock_Stone"
    },
    {
      "x": -1,
      "y": 5,
      "z": 1,
      "name": "Rock_Stone"
    },
    {
      "x": -1,
      "y": 6,
      "z": 1,
      "name": "Rock_Stone"
    },
    {
      "x": -1,
      "y": 7,
      "z": 1,
      "name": "Rock_Stone"
    },
    {
      "x": -1,
      "y": 8,
      "z": 1,
      "name": "Soil_Ash"
    },
    {
      "x": -1,
      "y": 0,
      "z": 2,
      "name": "Rock_Basalt"
    },
    {
      "x": -1,
      "y": 1,
      "z": 2,
      "name": "Rock_Basalt"
    },
    {
      "x": -1,
      "y": 2,
      "z": 2,
      "name": "Rock_Basalt"
    },
    {
      "x": -1,
      "y": 3,
      "z": 2,
      "name": "Rock_Basalt"
    },
    {
      "x": -1,
      "y": 4,
      "z": 2,
      "name": "Rock_Stone"
    },
    {
      "x": -1,
      "y": 5,
      "z": 2,
      "name": "Rock_Stone"
    },
    {
      "x": -1,
      "y": 6,
      "z": 2,
      "name": "Rock_Stone"
    },
    {
      "x": -1,
      "y": 7,
      "z": 2,
      "name": "Rock_Stone"
    },
    {
      "x": -1,
      "y": 8,
      "z": 2,
      "name": "Soil_Ash"
    },
    {
      "x": -1,
      "y": 0,
      "z": 3,
      "name": "Rock_Basalt"
    },
    {
      "x": -1,
      "y": 1,
      "z": 3,
      "name": "Rock_Basalt"
    },
    {
      "x": -1,
      "y": 2,
      "z": 3,
      "name": "Rock_Basalt"
    },
    {
      "x": -1,
      "y": 3,
      "z": 3,
      "name": "Rock_Basalt"
    },
    {
      "x": -1,
      "y": 4,
      "z": 3,
      "name": "Rock_Stone"
    },
    {
      "x": -1,
      "y": 5,
      "z": 3,
      "name": "Rock_Stone"
    },
    {
      "x": -1,
      "y": 6,
      "z": 3,
      "name": "Rock_Stone"
    },
    {
      "x": -1,
      "y": 7,
      "z": 3,
      "name": "Rock_Stone"
    },
    {
      "x": -1,
      "y": 8,
      "z": 3,
      "name": "Rock_Stone"
    },
    {
      "x": 0,
      "y": 0,
      "z": -3,
      "name": "Rock_Basalt"
    },
    {
      "x": 0,
      "y": 1,
      "z": -3,
      "name": "Rock_Basalt"
    },
    {
      "x": 0,
      "y": 2,
      "z": -3,
      "name": "Rock_Basalt"
    },
    {
      "x": 0,
      "y": 3,
      "z": -3,
      "name": "Rock_Basalt"
    },
    {
      "x": 0,
      "y": 4,
      "z": -3,
      "name": "Rock_Stone"
    },
    {
      "x": 0,
      "y": 5,
      "z": -3,
      "name": "Rock_Stone"
    },
    {
      "x": 0,
      "y": 6,
      "z": -3,
      "name": "Rock_Stone"
    },
    {
      "x": 0,
      "y": 7,
      "z": -3,
      "name": "Rock_Stone"
    },
    {
      "x": 0,
      "y": 8,
      "z": -3,
      "name": "Rock_Stone"
    },
    {
      "x": 0,
      "y": 0,
      "z": -2,
      "name": "Rock_Basalt"
    },
    {
      "x": 0,
      "y": 1,
      "z": -2,
      "name": "Rock_Basalt"
    },
    {
      "x": 0,
      "y": 2,
      "z": -2,
      "name": "Rock_Basalt"
    },
    {
      "x": 0,
      "y": 3,
      "z": -2,
      "name": "Rock_Basalt"
    },
    {
      "x": 0,
      "y": 4,
      "z": -2,
      "name": "Rock_Stone"
    },
    {
      "x": 0,
      "y": 5,
      "z": -2,
      "name": "Rock_Stone"
    },
    {
      "x": 0,
      "y": 6,
      "z": -2,
      "name": "Rock_Stone"
    },
    {
      "x": 0,
      "y": 7,
      "z": -2,
      "name": "Rock_Stone"
    },
    {
      "x": 0,
      "y": 8,
      "z": -2,
      "name": "Soil_Ash"
    },
    {
      "x": 0,
      "y": 0,
      "z": -1,
      "name": "Rock_Basalt"
    },
    {
      "x": 0,
      "y": 1,
      "z": -1,
      "name": "Rock_Basalt"
    },
    {
      "x": 0,
      "y": 2,
      "z": -1,
      "name": "Rock_Basalt"
    },
    {
      "x": 0,
      "y": 3,
      "z": -1,
      "name": "Rock_Basalt"
    },
    {
      "x": 0,
      "y": 4,
      "z": -1,
      "name": "Rock_Stone"
    },
    {
      "x": 0,
      "y": 5,
      "z": -1,
      "name": "Rock_Stone"
    },
    {
      "x": 0,
      "y": 6,
      "z": -1,
      "name": "Rock_Stone"
    },
    {
      "x": 0,
      "y": 7,
      "z": -1,
      "name": "Rock_Stone"
    },
    {
      "x": 0,
      "y": 8,
      "z": -1,
      "name": "Soil_Ash"
    },
    {
      "x": 0,
      "y": 0,
      "z": 0,
      "name": "Rock_Basalt"
    },
    {
      "x": 0,
      "y": 1,
      "z": 0,
      "name": "Rock_Basalt"
    },
    {
      "x": 0,
      "y": 2,
      "z": 0,
      "name": "Rock_Basalt"
    },
    {
      "x": 0,
      "y": 3,
      "z": 0,
      "name": "Rock_Basalt"
    },
    {
      "x": 0,
      "y": 4,
      "z": 0,
      "name": "Rock_Stone"
    },
    {
      "x": 0,
      "y": 5,
      "z": 0,
      "name": "Rock_Stone"
    },
    {
      "x": 0,
      "y": 6,
      "z": 0,
      "name": "Rock_Stone"
    },
    {
      "x": 0,
      "y": 7,
      "z": 0,
      "name": "Rock_Stone"
    },
    {
      "x": 0,
      "y": 8,
      "z": 0,
      "name": "Soil_Ash"
    },
    {
      "x": 0,
      "y": 0,
      "z": 1,
      "name": "Rock_Basalt"
    },
    {
      "x": 0,
      "y": 1,
      "z": 1,
      "name": "Rock_Basalt"
    },
    {
      "x": 0,
      "y": 2,
      "z": 1,
      "name": "Rock_Basalt"
    },
    {
      "x": 0,
      "y": 3,
      "z": 1,
      "name": "Rock_Basalt"
    },
    {
      "x": 0,
      "y": 4,
      "z": 1,
      "name": "Rock_Stone"
    },
    {
      "x": 0,
      "y": 5,
      "z": 1,
      "name": "Rock_Stone"
    },
    {
      "x": 0,
      "y": 6,
      "z": 1,
      "name": "Rock_Stone"
    },
    {
      "x": 0,
      "y": 7,
      "z": 1,
      "name": "Rock_Stone"
    },
    {
      "x": 0,
      "y": 8,
      "z": 1,
      "name": "Soil_Ash"
    },
    {
      "x": 0,
      "y": 0,
      "z": 2,
      "name": "Rock_Basalt"
    },
    {
      "x": 0,
      "y": 1,
      "z": 2,
      "name": "Rock_Basalt"
    },
    {
      "x": 0,
      "y": 2,
      "z": 2,
      "name": "Rock_Basalt"
    },
    {
      "x": 0,
      "y": 3,
      "z": 2,
      "name": "Rock_Basalt"
    },
    {
      "x": 0,
      "y": 4,
      "z": 2,
      "name": "Rock_Stone"
    },
    {
      "x": 0,
      "y": 5,
      "z": 2,
      "name": "Rock_Stone"
    },
    {
      "x": 0,
      "y": 6,
      "z": 2,
      "name": "Rock_Stone"
    },
    {
      "x": 0,
      "y": 7,
      "z": 2,
      "name": "Rock_Stone"
    },
    {
      "x": 0,
      "y": 8,
      "z": 2,
      "name": "Soil_Ash"
    },
    {
      "x": 0,
      "y": 0,
      "z": 3,
      "name": "Rock_Basalt"
    },
    {
      "x": 0,
      "y": 1,
      "z": 3,
      "name": "Rock_Basalt"
    },
    {
      "x": 0,
      "y": 2,
      "z": 3,
      "name": "Rock_Basalt"
    },
    {
      "x": 0,
      "y": 3,
      "z": 3,
      "name": "Rock_Basalt"
    },
    {
      "x": 0,
      "y": 4,
      "z": 3,
      "name": "Rock_Stone"
    },
    {
      "x": 0,
      "y": 5,
      "z": 3,
      "name": "Rock_Stone"
    },
    {
      "x": 0,
      "y": 6,
      "z": 3,
      "name": "Rock_Stone"
    },
    {
      "x": 0,
      "y": 7,
      "z": 3,
      "name": "Rock_Stone"
    },
    {
      "x": 0,
      "y": 8,
      "z": 3,
      "name": "Rock_Stone"
    },
    {
      "x": 1,
      "y": 0,
      "z": -3,
      "name": "Rock_Basalt"
    },
    {
      "x": 1,
      "y": 1,
      "z": -3,
      "name": "Rock_Basalt"
    },
    {
      "x": 1,
      "y": 2,
      "z": -3,
      "name": "Rock_Basalt"
    },
    {
      "x": 1,
      "y": 3,
      "z": -3,
      "name": "Rock_Basalt"
    },
    {
      "x": 1,
      "y": 4,
      "z": -3,
      "name": "Rock_Stone"
    },
    {
      "x": 1,
      "y": 5,
      "z": -3,
      "name": "Rock_Stone"
    },
    {
      "x": 1,
      "y": 6,
      "z": -3,
      "name": "Rock_Stone"
    },
    {
      "x": 1,
      "y": 7,
      "z": -3,
      "name": "Rock_Stone"
    },
    {
      "x": 1,
      "y": 8,
      "z": -3,
      "name": "Rock_Stone"
    },
    {
      "x": 1,
      "y": 0,
      "z": -2,
      "name": "Rock_Basalt"
    },
    {
      "x": 1,
      "y": 1,
      "z": -2,
      "name": "Rock_Basalt"
    },
    {
      "x": 1,
      "y": 2,
      "z": -2,
      "name": "Rock_Basalt"
    },
    {
      "x": 1,
      "y": 3,
      "z": -2,
      "name": "Rock_Basalt"
    },
    {
      "x": 1,
      "y": 4,
      "z": -2,
      "name": "Rock_Stone"
    },
    {
      "x": 1,
      "y": 5,
      "z": -2,
      "name": "Rock_Stone"
    },
    {
      "x": 1,
      "y": 6,
      "z": -2,
      "name": "Rock_Stone"
    },
    {
      "x": 1,
      "y": 7,
      "z": -2,
      "name": "Rock_Stone"
    },
    {
      "x": 1,
      "y": 8,
      "z": -2,
      "name": "Soil_Ash"
    },
    {
      "x": 1,
      "y": 0,
      "z": -1,
      "name": "Rock_Basalt"
    },
    {
      "x": 1,
      "y": 1,
      "z": -1,
      "name": "Rock_Basalt"
    },
    {
      "x": 1,
      "y": 2,
      "z": -1,
      "name": "Rock_Basalt"
    },
    {
      "x": 1,
      "y": 3,
      "z": -1,
      "name": "Rock_Basalt"
    },
    {
      "x": 1,
      "y": 4,
      "z": -1,
      "name": "Rock_Stone"
    },
    {
      "x": 1,
      "y": 5,
      "z": -1,
      "name": "Rock_Stone"
    },
    {
      "x": 1,
      "y": 6,
      "z": -1,
      "name": "Rock_Stone"
    },
    {
      "x": 1,
      "y": 7,
      "z": -1,
      "name": "Rock_Stone"
    },
    {
      "x": 1,
      "y": 8,
      "z": -1,
      "name": "Soil_Ash"
    },
    {
      "x": 1,
      "y": 0,
      "z": 0,
      "name": "Rock_Basalt"
    },
    {
      "x": 1,
      "y": 1,
      "z": 0,
      "name": "Rock_Basalt"
    },
    {
      "x": 1,
      "y": 2,
      "z": 0,
      "name": "Rock_Basalt"
    },
    {
      "x": 1,
      "y": 3,
      "z": 0,
      "name": "Rock_Basalt"
    },
    {
      "x": 1,
      "y": 4,
      "z": 0,
      "name": "Rock_Stone"
    },
    {
      "x": 1,
      "y": 5,
      "z": 0,
      "name": "Rock_Stone"
    },
    {
      "x": 1,
      "y": 6,
      "z": 0,
      "name": "Rock_Stone"
    },
    {
      "x": 1,
      "y": 7,
      "z": 0,
      "name": "Rock_Stone"
    },
    {
      "x": 1,
      "y": 8,
      "z": 0,
      "name": "Cloth_Block_Wool_Gray_Stairs",
      "rotation": 1
    },
    {
      "x": 1,
      "y": 0,
      "z": 1,
      "name": "Rock_Basalt"
    },
    {
      "x": 1,
      "y": 1,
      "z": 1,
      "name": "Rock_Basalt"
    },
    {
      "x": 1,
      "y": 2,
      "z": 1,
      "name": "Rock_Basalt"
    },
    {
      "x": 1,
      "y": 3,
      "z": 1,
      "name": "Rock_Basalt"
    },
    {
      "x": 1,
      "y": 4,
      "z": 1,
      "name": "Rock_Stone"
    },
    {
      "x": 1,
      "y": 5,
      "z": 1,
      "name": "Rock_Stone"
    },
    {
      "x": 1,
      "y": 6,
      "z": 1,
      "name": "Rock_Stone"
    },
    {
      "x": 1,
      "y": 7,
      "z": 1,
      "name": "Rock_Stone"
    },
    {
      "x": 1,
      "y": 8,
      "z": 1,
      "name": "Soil_Ash"
    },
    {
      "x": 1,
      "y": 0,
      "z": 2,
      "name": "Rock_Basalt"
    },
    {
      "x": 1,
      "y": 1,
      "z": 2,
      "name": "Rock_Basalt"
    },
    {
      "x": 1,
      "y": 2,
      "z": 2,
      "name": "Rock_Basalt"
    },
    {
      "x": 1,
      "y": 3,
      "z": 2,
      "name": "Rock_Basalt"
    },
    {
      "x": 1,
      "y": 4,
      "z": 2,
      "name": "Rock_Stone"
    },
    {
      "x": 1,
      "y": 5,
      "z": 2,
      "name": "Rock_Stone"
    },
    {
      "x": 1,
      "y": 6,
      "z": 2,
      "name": "Rock_Stone"
    },
    {
      "x": 1,
      "y": 7,
      "z": 2,
      "name": "Rock_Stone"
    },
    {
      "x": 1,
      "y": 8,
      "z": 2,
      "name": "Soil_Ash"
    },
    {
      "x": 1,
      "y": 0,
      "z": 3,
      "name": "Rock_Basalt"
    },
    {
      "x": 1,
      "y": 1,
      "z": 3,
      "name": "Rock_Basalt"
    },
    {
      "x": 1,
      "y": 2,
      "z": 3,
      "name": "Rock_Basalt"
    },
    {
      "x": 1,
      "y": 3,
      "z": 3,
      "name": "Rock_Basalt"
    },
    {
      "x": 1,
      "y": 4,
      "z": 3,
      "name": "Rock_Stone"
    },
    {
      "x": 1,
      "y": 5,
      "z": 3,
      "name": "Rock_Stone"
    },
    {
      "x": 1,
      "y": 6,
      "z": 3,
      "name": "Rock_Stone"
    },
    {
      "x": 1,
      "y": 7,
      "z": 3,
      "name": "Rock_Stone"
    },
    {
      "x": 1,
      "y": 8,
      "z": 3,
      "name": "Rock_Stone"
    },
    {
      "x": 2,
      "y": 0,
      "z": -3,
      "name": "Rock_Basalt"
    },
    {
      "x": 2,
      "y": 1,
      "z": -3,
      "name": "Rock_Basalt"
    },
    {
      "x": 2,
      "y": 2,
      "z": -3,
      "name": "Rock_Basalt"
    },
    {
      "x": 2,
      "y": 3,
      "z": -3,
      "name": "Rock_Basalt"
    },
    {
      "x": 2,
      "y": 4,
      "z": -3,
      "name": "Rock_Stone"
    },
    {
      "x": 2,
      "y": 5,
      "z": -3,
      "name": "Rock_Stone"
    },
    {
      "x": 2,
      "y": 6,
      "z": -3,
      "name": "Rock_Stone"
    },
    {
      "x": 2,
      "y": 7,
      "z": -3,
      "name": "Rock_Stone"
    },
    {
      "x": 2,
      "y": 8,
      "z": -3,
      "name": "Rock_Stone"
    },
    {
      "x": 2,
      "y": 0,
      "z": -2,
      "name": "Rock_Basalt"
    },
    {
      "x": 2,
      "y": 1,
      "z": -2,
      "name": "Rock_Basalt"
    },
    {
      "x": 2,
      "y": 2,
      "z": -2,
      "name": "Rock_Basalt"
    },
    {
      "x": 2,
      "y": 3,
      "z": -2,
      "name": "Rock_Basalt"
    },
    {
      "x": 2,
      "y": 4,
      "z": -2,
      "name": "Rock_Stone"
    },
    {
      "x": 2,
      "y": 5,
      "z": -2,
      "name": "Rock_Stone"
    },
    {
      "x": 2,
      "y": 6,
      "z": -2,
      "name": "Rock_Stone"
    },
    {
      "x": 2,
      "y": 7,
      "z": -2,
      "name": "Rock_Stone"
    },
    {
      "x": 2,
      "y": 8,
      "z": -2,
      "name": "Soil_Ash"
    },
    {
      "x": 2,
      "y": 0,
      "z": -1,
      "name": "Rock_Basalt"
    },
    {
      "x": 2,
      "y": 1,
      "z": -1,
      "name": "Rock_Basalt"
    },
    {
      "x": 2,
      "y": 2,
      "z": -1,
      "name": "Rock_Basalt"
    },
    {
      "x": 2,
      "y": 3,
      "z": -1,
      "name": "Rock_Basalt"
    },
    {
      "x": 2,
      "y": 4,
      "z": -1,
      "name": "Rock_Stone"
    },
    {
      "x": 2,
      "y": 5,
      "z": -1,
      "name": "Rock_Stone"
    },
    {
      "x": 2,
      "y": 6,
      "z": -1,
      "name": "Rock_Stone"
    },
    {
      "x": 2,
      "y": 7,
      "z": -1,
      "name": "Rock_Stone"
    },
    {
      "x": 2,
      "y": 8,
      "z": -1,
      "name": "Soil_Ash"
    },
    {
      "x": 2,
      "y": 0,
      "z": 0,
      "name": "Rock_Basalt"
    },
    {
      "x": 2,
      "y": 1,
      "z": 0,
      "name": "Rock_Basalt"
    },
    {
      "x": 2,
      "y": 2,
      "z": 0,
      "name": "Rock_Basalt"
    },
    {
      "x": 2,
      "y": 3,
      "z": 0,
      "name": "Rock_Basalt"
    },
    {
      "x": 2,
      "y": 4,
      "z": 0,
      "name": "Rock_Stone"
    },
    {
      "x": 2,
      "y": 5,
      "z": 0,
      "name": "Rock_Stone"
    },
    {
      "x": 2,
      "y": 6,
      "z": 0,
      "name": "Rock_Stone"
    },
    {
      "x": 2,
      "y": 7,
      "z": 0,
      "name": "Rock_Stone"
    },
    {
      "x": 2,
      "y": 8,
      "z": 0,
      "name": "Cloth_Block_Wool_Gray_Half"
    },
    {
      "x": 2,
      "y": 0,
      "z": 1,
      "name": "Rock_Basalt"
    },
    {
      "x": 2,
      "y": 1,
      "z": 1,
      "name": "Rock_Basalt"
    },
    {
      "x": 2,
      "y": 2,
      "z": 1,
      "name": "Rock_Basalt"
    },
    {
      "x": 2,
      "y": 3,
      "z": 1,
      "name": "Rock_Basalt"
    },
    {
      "x": 2,
      "y": 4,
      "z": 1,
      "name": "Rock_Stone"
    },
    {
      "x": 2,
      "y": 5,
      "z": 1,
      "name": "Rock_Stone"
    },
    {
      "x": 2,
      "y": 6,
      "z": 1,
      "name": "Rock_Stone"
    },
    {
      "x": 2,
      "y": 7,
      "z": 1,
      "name": "Rock_Stone"
    },
    {
      "x": 2,
      "y": 8,
      "z": 1,
      "name": "Soil_Ash"
    },
    {
      "x": 2,
      "y": 0,
      "z": 2,
      "name": "Rock_Basalt"
    },
    {
      "x": 2,
      "y": 1,
      "z": 2,
      "name": "Rock_Basalt"
    },
    {
      "x": 2,
      "y": 2,
      "z": 2,
      "name": "Rock_Basalt"
    },
    {
      "x": 2,
      "y": 3,
      "z": 2,
      "name": "Rock_Basalt"
    },
    {
      "x": 2,
      "y": 4,
      "z": 2,
      "name": "Rock_Stone"
    },
    {
      "x": 2,
      "y": 5,
      "z": 2,
      "name": "Rock_Stone"
    },
    {
      "x": 2,
      "y": 6,
      "z": 2,
      "name": "Rock_Stone"
    },
    {
      "x": 2,
      "y": 7,
      "z": 2,
      "name": "Rock_Stone"
    },
    {
      "x": 2,
      "y": 8,
      "z": 2,
      "name": "Soil_Ash"
    },
    {
      "x": 2,
      "y": 0,
      "z": 3,
      "name": "Rock_Basalt"
    },
    {
      "x": 2,
      "y": 1,
      "z": 3,
      "name": "Rock_Basalt"
    },
    {
      "x": 2,
      "y": 2,
      "z": 3,
      "name": "Rock_Basalt"
    },
    {
      "x": 2,
      "y": 3,
      "z": 3,
      "name": "Rock_Basalt"
    },
    {
      "x": 2,
      "y": 4,
      "z": 3,
      "name": "Rock_Stone"
    },
    {
      "x": 2,
      "y": 5,
      "z": 3,
      "name": "Rock_Stone"
    },
    {
      "x": 2,
      "y": 6,
      "z": 3,
      "name": "Rock_Stone"
    },
    {
      "x": 2,
      "y": 7,
      "z": 3,
      "name": "Rock_Stone"
    },
    {
      "x": 2,
      "y": 8,
      "z": 3,
      "name": "Rock_Stone_Mossy"
    },
    {
      "x": 3,
      "y": 0,
      "z": -3,
      "name": "Rock_Basalt"
    },
    {
      "x": 3,
      "y": 1,
      "z": -3,
      "name": "Rock_Basalt"
    },
    {
      "x": 3,
      "y": 2,
      "z": -3,
      "name": "Rock_Basalt"
    },
    {
      "x": 3,
      "y": 3,
      "z": -3,
      "name": "Rock_Basalt"
    },
    {
      "x": 3,
      "y": 4,
      "z": -3,
      "name": "Rock_Stone"
    },
    {
      "x": 3,
      "y": 5,
      "z": -3,
      "name": "Rock_Stone"
    },
    {
      "x": 3,
      "y": 6,
      "z": -3,
      "name": "Rock_Stone"
    },
    {
      "x": 3,
      "y": 7,
      "z": -3,
      "name": "Rock_Stone"
    },
    {
      "x": 3,
      "y": 8,
      "z": -3,
      "name": "Rock_Stone"
    },
    {
      "x": 3,
      "y": 0,
      "z": -2,
      "name": "Rock_Basalt"
    },
    {
      "x": 3,
      "y": 1,
      "z": -2,
      "name": "Rock_Basalt"
    },
    {
      "x": 3,
      "y": 2,
      "z": -2,
      "name": "Rock_Basalt"
    },
    {
      "x": 3,
      "y": 3,
      "z": -2,
      "name": "Rock_Basalt"
    },
    {
      "x": 3,
      "y": 4,
      "z": -2,
      "name": "Rock_Stone"
    },
    {
      "x": 3,
      "y": 5,
      "z": -2,
      "name": "Rock_Stone"
    },
    {
      "x": 3,
      "y": 6,
      "z": -2,
      "name": "Rock_Stone"
    },
    {
      "x": 3,
      "y": 7,
      "z": -2,
      "name": "Rock_Stone"
    },
    {
      "x": 3,
      "y": 8,
      "z": -2,
      "name": "Soil_Ash"
    },
    {
      "x": 3,
      "y": 0,
      "z": -1,
      "name": "Rock_Basalt"
    },
    {
      "x": 3,
      "y": 1,
      "z": -1,
      "name": "Rock_Basalt"
    },
    {
      "x": 3,
      "y": 2,
      "z": -1,
      "name": "Rock_Basalt"
    },
    {
      "x": 3,
      "y": 3,
      "z": -1,
      "name": "Rock_Basalt"
    },
    {
      "x": 3,
      "y": 4,
      "z": -1,
      "name": "Rock_Stone"
    },
    {
      "x": 3,
      "y": 5,
      "z": -1,
      "name": "Rock_Stone"
    },
    {
      "x": 3,
      "y": 6,
      "z": -1,
      "name": "Rock_Stone"
    },
    {
      "x": 3,
      "y": 7,
      "z": -1,
      "name": "Rock_Stone"
    },
    {
      "x": 3,
      "y": 8,
      "z": -1,
      "name": "Soil_Ash"
    },
    {
      "x": 3,
      "y": 0,
      "z": 0,
      "name": "Rock_Basalt"
    },
    {
      "x": 3,
      "y": 1,
      "z": 0,
      "name": "Rock_Basalt"
    },
    {
      "x": 3,
      "y": 2,
      "z": 0,
      "name": "Rock_Basalt"
    },
    {
      "x": 3,
      "y": 3,
      "z": 0,
      "name": "Rock_Basalt"
    },
    {
      "x": 3,
      "y": 4,
      "z": 0,
      "name": "Rock_Stone"
    },
    {
      "x": 3,
      "y": 5,
      "z": 0,
      "name": "Rock_Stone"
    },
    {
      "x": 3,
      "y": 6,
      "z": 0,
      "name": "Rock_Stone"
    },
    {
      "x": 3,
      "y": 7,
      "z": 0,
      "name": "Rock_Stone"
    },
    {
      "x": 3,
      "y": 8,
      "z": 0,
      "name": "Soil_Ash"
    },
    {
      "x": 3,
      "y": 0,
      "z": 1,
      "name": "Rock_Basalt"
    },
    {
      "x": 3,
      "y": 1,
      "z": 1,
      "name": "Rock_Basalt"
    },
    {
      "x": 3,
      "y": 2,
      "z": 1,
      "name": "Rock_Basalt"
    },
    {
      "x": 3,
      "y": 3,
      "z": 1,
      "name": "Rock_Basalt"
    },
    {
      "x": 3,
      "y": 4,
      "z": 1,
      "name": "Rock_Stone"
    },
    {
      "x": 3,
      "y": 5,
      "z": 1,
      "name": "Rock_Stone"
    },
    {
      "x": 3,
      "y": 6,
      "z": 1,
      "name": "Rock_Stone"
    },
    {
      "x": 3,
      "y": 7,
      "z": 1,
      "name": "Rock_Stone"
    },
    {
      "x": 3,
      "y": 8,
      "z": 1,
      "name": "Soil_Ash"
    },
    {
      "x": 3,
      "y": 0,
      "z": 2,
      "name": "Rock_Basalt"
    },
    {
      "x": 3,
      "y": 1,
      "z": 2,
      "name": "Rock_Basalt"
    },
    {
      "x": 3,
      "y": 2,
      "z": 2,
      "name": "Rock_Basalt"
    },
    {
      "x": 3,
      "y": 3,
      "z": 2,
      "name": "Rock_Basalt"
    },
    {
      "x": 3,
      "y": 4,
      "z": 2,
      "name": "Rock_Stone"
    },
    {
      "x": 3,
      "y": 5,
      "z": 2,
      "name": "Rock_Stone"
    },
    {
      "x": 3,
      "y": 6,
      "z": 2,
      "name": "Rock_Stone"
    },
    {
      "x": 3,
      "y": 7,
      "z": 2,
      "name": "Rock_Stone"
    },
    {
      "x": 3,
      "y": 8,
      "z": 2,
      "name": "Soil_Ash"
    },
    {
      "x": 3,
      "y": 0,
      "z": 3,
      "name": "Rock_Basalt"
    },
    {
      "x": 3,
      "y": 1,
      "z": 3,
      "name": "Rock_Basalt"
    },
    {
      "x": 3,
      "y": 2,
      "z": 3,
      "name": "Rock_Basalt"
    },
    {
      "x": 3,
      "y": 3,
      "z": 3,
      "name": "Rock_Basalt"
    },
    {
      "x": 3,
      "y": 4,
      "z": 3,
      "name": "Rock_Stone"
    },
    {
      "x": 3,
      "y": 5,
      "z": 3,
      "name": "Rock_Stone"
    },
    {
      "x": 3,
      "y": 6,
      "z": 3,
      "name": "Rock_Stone"
    },
    {
      "x": 3,
      "y": 7,
      "z": 3,
      "name": "Rock_Stone"
    },
    {
      "x": 3,
      "y": 8,
      "z": 3,
      "name": "Rock_Stone"
    }
  ],
  "fluids": [
    {
      "x": -3,
      "y": 0,
      "z": -3,
      "name": "Water_Source",
      "level": 1
    },
    {
      "x": -3,
      "y": 1,
      "z": -3,
      "name": "Water_Source",
      "level": 1
    },
    {
      "x": -3,
      "y": 2,
      "z": -3,
      "name": "Water_Source",
      "level": 1
    },
    {
      "x": -3,
      "y": 3,
      "z": -3,
      "name": "Water_Source",
      "level": 1
    },
    {
      "x": -3,
      "y": 4,
      "z": -3,
      "name": "Empty",
      "level": 0
    },
    {
      "x": -3,
      "y": 5,
      "z": -3,
      "name": "Empty",
      "level": 0
    },
    {
      "x": -3,
      "y": 6,
      "z": -3,
      "name": "Empty",
      "level": 0
    },
    {
      "x": -3,
      "y": 7,
      "z": -3,
      "name": "Empty",
      "level": 0
    },
    {
      "x": -3,
      "y": 8,
      "z": -3,
      "name": "Empty",
      "level": 0
    },
    {
      "x": -3,
      "y": 0,
      "z": -2,
      "name": "Water_Source",
      "level": 1
    },
    {
      "x": -3,
      "y": 1,
      "z": -2,
      "name": "Water_Source",
      "level": 1
    },
    {
      "x": -3,
      "y": 2,
      "z": -2,
      "name": "Water_Source",
      "level": 1
    },
    {
      "x": -3,
      "y": 3,
      "z": -2,
      "name": "Water_Source",
      "level": 1
    },
    {
      "x": -3,
      "y": 4,
      "z": -2,
      "name": "Empty",
      "level": 0
    },
    {
      "x": -3,
      "y": 5,
      "z": -2,
      "name": "Empty",
      "level": 0
    },
    {
      "x": -3,
      "y": 6,
      "z": -2,
      "name": "Empty",
      "level": 0
    },
    {
      "x": -3,
      "y": 7,
      "z": -2,
      "name": "Empty",
      "level": 0
    },
    {
      "x": -3,
      "y": 8,
      "z": -2,
      "name": "Empty",
      "level": 0
    },
    {
      "x": -3,
      "y": 0,
      "z": -1,
      "name": "Water_Source",
      "level": 1
    },
    {
      "x": -3,
      "y": 1,
      "z": -1,
      "name": "Water_Source",
      "level": 1
    },
    {
      "x": -3,
      "y": 2,
      "z": -1,
      "name": "Water_Source",
      "level": 1
    },
    {
      "x": -3,
      "y": 3,
      "z": -1,
      "name": "Water_Source",
      "level": 1
    },
    {
      "x": -3,
      "y": 4,
      "z": -1,
      "name": "Empty",
      "level": 0
    },
    {
      "x": -3,
      "y": 5,
      "z": -1,
      "name": "Empty",
      "level": 0
    },
    {
      "x": -3,
      "y": 6,
      "z": -1,
      "name": "Empty",
      "level": 0
    },
    {
      "x": -3,
      "y": 7,
      "z": -1,
      "name": "Empty",
      "level": 0
    },
    {
      "x": -3,
      "y": 8,
      "z": -1,
      "name": "Empty",
      "level": 0
    },
    {
      "x": -3,
      "y": 0,
      "z": 0,
      "name": "Water_Source",
      "level": 1
    },
    {
      "x": -3,
      "y": 1,
      "z": 0,
      "name": "Water_Source",
      "level": 1
    },
    {
      "x": -3,
      "y": 2,
      "z": 0,
      "name": "Water_Source",
      "level": 1
    },
    {
      "x": -3,
      "y": 3,
      "z": 0,
      "name": "Water_Source",
      "level": 1
    },
    {
      "x": -3,
      "y": 4,
      "z": 0,
      "name": "Empty",
      "level": 0
    },
    {
      "x": -3,
      "y": 5,
      "z": 0,
      "name": "Empty",
      "level": 0
    },
    {
      "x": -3,
      "y": 6,
      "z": 0,
      "name": "Empty",
      "level": 0
    },
    {
      "x": -3,
      "y": 7,
      "z": 0,
      "name": "Empty",
      "level": 0
    },
    {
      "x": -3,
      "y": 8,
      "z": 0,
      "name": "Empty",
      "level": 0
    },
    {
      "x": -3,
      "y": 0,
      "z": 1,
      "name": "Water_Source",
      "level": 1
    },
    {
      "x": -3,
      "y": 1,
      "z": 1,
      "name": "Water_Source",
      "level": 1
    },
    {
      "x": -3,
      "y": 2,
      "z": 1,
      "name": "Water_Source",
      "level": 1
    },
    {
      "x": -3,
      "y": 3,
      "z": 1,
      "name": "Water_Source",
      "level": 1
    },
    {
      "x": -3,
      "y": 4,
      "z": 1,
      "name": "Empty",
      "level": 0
    },
    {
      "x": -3,
      "y": 5,
      "z": 1,
      "name": "Empty",
      "level": 0
    },
    {
      "x": -3,
      "y": 6,
      "z": 1,
      "name": "Empty",
      "level": 0
    },
    {
      "x": -3,
      "y": 7,
      "z": 1,
      "name": "Empty",
      "level": 0
    },
    {
      "x": -3,
      "y": 8,
      "z": 1,
      "name": "Empty",
      "level": 0
    },
    {
      "x": -3,
      "y": 0,
      "z": 2,
      "name": "Water_Source",
      "level": 1
    },
    {
      "x": -3,
      "y": 1,
      "z": 2,
      "name": "Water_Source",
      "level": 1
    },
    {
      "x": -3,
      "y": 2,
      "z": 2,
      "name": "Water_Source",
      "level": 1
    },
    {
      "x": -3,
      "y": 3,
      "z": 2,
      "name": "Water_Source",
      "level": 1
    },
    {
      "x": -3,
      "y": 4,
      "z": 2,
      "name": "Empty",
      "level": 0
    },
    {
      "x": -3,
      "y": 5,
      "z": 2,
      "name": "Empty",
      "level": 0
    },
    {
      "x": -3,
      "y": 6,
      "z": 2,
      "name": "Empty",
      "level": 0
    },
    {
      "x": -3,
      "y": 7,
      "z": 2,
      "name": "Empty",
      "level": 0
    },
    {
      "x": -3,
      "y": 8,
      "z": 2,
      "name": "Empty",
      "level": 0
    },
    {
      "x": -3,
      "y": 0,
      "z": 3,
      "name": "Water_Source",
      "level": 1
    },
    {
      "x": -3,
      "y": 1,
      "z": 3,
      "name": "Water_Source",
      "level": 1
    },
    {
      "x": -3,
      "y": 2,
      "z": 3,
      "name": "Water_Source",
      "level": 1
    },
    {
      "x": -3,
      "y": 3,
      "z": 3,
      "name": "Water_Source",
      "level": 1
    },
    {
      "x": -3,
      "y": 4,
      "z": 3,
      "name": "Empty",
      "level": 0
    },
    {
      "x": -3,
      "y": 5,
      "z": 3,
      "name": "Empty",
      "level": 0
    },
    {
      "x": -3,
      "y": 6,
      "z": 3,
      "name": "Empty",
      "level": 0
    },
    {
      "x": -3,
      "y": 7,
      "z": 3,
      "name": "Empty",
      "level": 0
    },
    {
      "x": -3,
      "y": 8,
      "z": 3,
      "name": "Empty",
      "level": 0
    },
    {
      "x": -2,
      "y": 0,
      "z": -3,
      "name": "Water_Source",
      "level": 1
    },
    {
      "x": -2,
      "y": 1,
      "z": -3,
      "name": "Water_Source",
      "level": 1
    },
    {
      "x": -2,
      "y": 2,
      "z": -3,
      "name": "Water_Source",
      "level": 1
    },
    {
      "x": -2,
      "y": 3,
      "z": -3,
      "name": "Water_Source",
      "level": 1
    },
    {
      "x": -2,
      "y": 4,
      "z": -3,
      "name": "Empty",
      "level": 0
    },
    {
      "x": -2,
      "y": 5,
      "z": -3,
      "name": "Empty",
      "level": 0
    },
    {
      "x": -2,
      "y": 6,
      "z": -3,
      "name": "Empty",
      "level": 0
    },
    {
      "x": -2,
      "y": 7,
      "z": -3,
      "name": "Empty",
      "level": 0
    },
    {
      "x": -2,
      "y": 8,
      "z": -3,
      "name": "Empty",
      "level": 0
    },
    {
      "x": -2,
      "y": 0,
      "z": -2,
      "name": "Water_Source",
      "level": 1
    },
    {
      "x": -2,
      "y": 1,
      "z": -2,
      "name": "Water_Source",
      "level": 1
    },
    {
      "x": -2,
      "y": 2,
      "z": -2,
      "name": "Water_Source",
      "level": 1
    },
    {
      "x": -2,
      "y": 3,
      "z": -2,
      "name": "Water_Source",
      "level": 1
    },
    {
      "x": -2,
      "y": 4,
      "z": -2,
      "name": "Empty",
      "level": 0
    },
    {
      "x": -2,
      "y": 5,
      "z": -2,
      "name": "Empty",
      "level": 0
    },
    {
      "x": -2,
      "y": 6,
      "z": -2,
      "name": "Empty",
      "level": 0
    },
    {
      "x": -2,
      "y": 7,
      "z": -2,
      "name": "Empty",
      "level": 0
    },
    {
      "x": -2,
      "y": 8,
      "z": -2,
      "name": "Empty",
      "level": 0
    },
    {
      "x": -2,
      "y": 0,
      "z": -1,
      "name": "Water_Source",
      "level": 1
    },
    {
      "x": -2,
      "y": 1,
      "z": -1,
      "name": "Water_Source",
      "level": 1
    },
    {
      "x": -2,
      "y": 2,
      "z": -1,
      "name": "Water_Source",
      "level": 1
    },
    {
      "x": -2,
      "y": 3,
      "z": -1,
      "name": "Water_Source",
      "level": 1
    },
    {
      "x": -2,
      "y": 4,
      "z": -1,
      "name": "Empty",
      "level": 0
    },
    {
      "x": -2,
      "y": 5,
      "z": -1,
      "name": "Empty",
      "level": 0
    },
    {
      "x": -2,
      "y": 6,
      "z": -1,
      "name": "Empty",
      "level": 0
    },
    {
      "x": -2,
      "y": 7,
      "z": -1,
      "name": "Empty",
      "level": 0
    },
    {
      "x": -2,
      "y": 8,
      "z": -1,
      "name": "Empty",
      "level": 0
    },
    {
      "x": -2,
      "y": 0,
      "z": 0,
      "name": "Water_Source",
      "level": 1
    },
    {
      "x": -2,
      "y": 1,
      "z": 0,
      "name": "Water_Source",
      "level": 1
    },
    {
      "x": -2,
      "y": 2,
      "z": 0,
      "name": "Water_Source",
      "level": 1
    },
    {
      "x": -2,
      "y": 3,
      "z": 0,
      "name": "Water_Source",
      "level": 1
    },
    {
      "x": -2,
      "y": 4,
      "z": 0,
      "name": "Empty",
      "level": 0
    },
    {
      "x": -2,
      "y": 5,
      "z": 0,
      "name": "Empty",
      "level": 0
    },
    {
      "x": -2,
      "y": 6,
      "z": 0,
      "name": "Empty",
      "level": 0
    },
    {
      "x": -2,
      "y": 7,
      "z": 0,
      "name": "Empty",
      "level": 0
    },
    {
      "x": -2,
      "y": 8,
      "z": 0,
      "name": "Empty",
      "level": 0
    },
    {
      "x": -2,
      "y": 0,
      "z": 1,
      "name": "Water_Source",
      "level": 1
    },
    {
      "x": -2,
      "y": 1,
      "z": 1,
      "name": "Water_Source",
      "level": 1
    },
    {
      "x": -2,
      "y": 2,
      "z": 1,
      "name": "Water_Source",
      "level": 1
    },
    {
      "x": -2,
      "y": 3,
      "z": 1,
      "name": "Water_Source",
      "level": 1
    },
    {
      "x": -2,
      "y": 4,
      "z": 1,
      "name": "Empty",
      "level": 0
    },
    {
      "x": -2,
      "y": 5,
      "z": 1,
      "name": "Empty",
      "level": 0
    },
    {
      "x": -2,
      "y": 6,
      "z": 1,
      "name": "Empty",
      "level": 0
    },
    {
      "x": -2,
      "y": 7,
      "z": 1,
      "name": "Empty",
      "level": 0
    },
    {
      "x": -2,
      "y": 8,
      "z": 1,
      "name": "Empty",
      "level": 0
    },
    {
      "x": -2,
      "y": 0,
      "z": 2,
      "name": "Water_Source",
      "level": 1
    },
    {
      "x": -2,
      "y": 1,
      "z": 2,
      "name": "Water_Source",
      "level": 1
    },
    {
      "x": -2,
      "y": 2,
      "z": 2,
      "name": "Water_Source",
      "level": 1
    },
    {
      "x": -2,
      "y": 3,
      "z": 2,
      "name": "Water_Source",
      "level": 1
    },
    {
      "x": -2,
      "y": 4,
      "z": 2,
      "name": "Empty",
      "level": 0
    },
    {
      "x": -2,
      "y": 5,
      "z": 2,
      "name": "Empty",
      "level": 0
    },
    {
      "x": -2,
      "y": 6,
      "z": 2,
      "name": "Empty",
      "level": 0
    },
    {
      "x": -2,
      "y": 7,
      "z": 2,
      "name": "Empty",
      "level": 0
    },
    {
      "x": -2,
      "y": 8,
      "z": 2,
      "name": "Empty",
      "level": 0
    },
    {
      "x": -2,
      "y": 0,
      "z": 3,
      "name": "Water_Source",
      "level": 1
    },
    {
      "x": -2,
      "y": 1,
      "z": 3,
      "name": "Water_Source",
      "level": 1
    },
    {
      "x": -2,
      "y": 2,
      "z": 3,
      "name": "Water_Source",
      "level": 1
    },
    {
      "x": -2,
      "y": 3,
      "z": 3,
      "name": "Water_Source",
      "level": 1
    },
    {
      "x": -2,
      "y": 4,
      "z": 3,
      "name": "Empty",
      "level": 0
    },
    {
      "x": -2,
      "y": 5,
      "z": 3,
      "name": "Empty",
      "level": 0
    },
    {
      "x": -2,
      "y": 6,
      "z": 3,
      "name": "Empty",
      "level": 0
    },
    {
      "x": -2,
      "y": 7,
      "z": 3,
      "name": "Empty",
      "level": 0
    },
    {
      "x": -2,
      "y": 8,
      "z": 3,
      "name": "Empty",
      "level": 0
    },
    {
      "x": -1,
      "y": 0,
      "z": -3,
      "name": "Water_Source",
      "level": 1
    },
    {
      "x": -1,
      "y": 1,
      "z": -3,
      "name": "Water_Source",
      "level": 1
    },
    {
      "x": -1,
      "y": 2,
      "z": -3,
      "name": "Water_Source",
      "level": 1
    },
    {
      "x": -1,
      "y": 3,
      "z": -3,
      "name": "Water_Source",
      "level": 1
    },
    {
      "x": -1,
      "y": 4,
      "z": -3,
      "name": "Empty",
      "level": 0
    },
    {
      "x": -1,
      "y": 5,
      "z": -3,
      "name": "Empty",
      "level": 0
    },
    {
      "x": -1,
      "y": 6,
      "z": -3,
      "name": "Empty",
      "level": 0
    },
    {
      "x": -1,
      "y": 7,
      "z": -3,
      "name": "Empty",
      "level": 0
    },
    {
      "x": -1,
      "y": 8,
      "z": -3,
      "name": "Empty",
      "level": 0
    },
    {
      "x": -1,
      "y": 0,
      "z": -2,
      "name": "Water_Source",
      "level": 1
    },
    {
      "x": -1,
      "y": 1,
      "z": -2,
      "name": "Water_Source",
      "level": 1
    },
    {
      "x": -1,
      "y": 2,
      "z": -2,
      "name": "Water_Source",
      "level": 1
    },
    {
      "x": -1,
      "y": 3,
      "z": -2,
      "name": "Water_Source",
      "level": 1
    },
    {
      "x": -1,
      "y": 4,
      "z": -2,
      "name": "Empty",
      "level": 0
    },
    {
      "x": -1,
      "y": 5,
      "z": -2,
      "name": "Empty",
      "level": 0
    },
    {
      "x": -1,
      "y": 6,
      "z": -2,
      "name": "Empty",
      "level": 0
    },
    {
      "x": -1,
      "y": 7,
      "z": -2,
      "name": "Empty",
      "level": 0
    },
    {
      "x": -1,
      "y": 8,
      "z": -2,
      "name": "Empty",
      "level": 0
    },
    {
      "x": -1,
      "y": 0,
      "z": -1,
      "name": "Water_Source",
      "level": 1
    },
    {
      "x": -1,
      "y": 1,
      "z": -1,
      "name": "Water_Source",
      "level": 1
    },
    {
      "x": -1,
      "y": 2,
      "z": -1,
      "name": "Water_Source",
      "level": 1
    },
    {
      "x": -1,
      "y": 3,
      "z": -1,
      "name": "Water_Source",
      "level": 1
    },
    {
      "x": -1,
      "y": 4,
      "z": -1,
      "name": "Empty",
      "level": 0
    },
    {
      "x": -1,
      "y": 5,
      "z": -1,
      "name": "Empty",
      "level": 0
    },
    {
      "x": -1,
      "y": 6,
      "z": -1,
      "name": "Empty",
      "level": 0
    },
    {
      "x": -1,
      "y": 7,
      "z": -1,
      "name": "Empty",
      "level": 0
    },
    {
      "x": -1,
      "y": 8,
      "z": -1,
      "name": "Empty",
      "level": 0
    },
    {
      "x": -1,
      "y": 0,
      "z": 0,
      "name": "Water_Source",
      "level": 1
    },
    {
      "x": -1,
      "y": 1,
      "z": 0,
      "name": "Water_Source",
      "level": 1
    },
    {
      "x": -1,
      "y": 2,
      "z": 0,
      "name": "Water_Source",
      "level": 1
    },
    {
      "x": -1,
      "y": 3,
      "z": 0,
      "name": "Water_Source",
      "level": 1
    },
    {
      "x": -1,
      "y": 4,
      "z": 0,
      "name": "Empty",
      "level": 0
    },
    {
      "x": -1,
      "y": 5,
      "z": 0,
      "name": "Empty",
      "level": 0
    },
    {
      "x": -1,
      "y": 6,
      "z": 0,
      "name": "Empty",
      "level": 0
    },
    {
      "x": -1,
      "y": 7,
      "z": 0,
      "name": "Empty",
      "level": 0
    },
    {
      "x": -1,
      "y": 8,
      "z": 0,
      "name": "Empty",
      "level": 0
    },
    {
      "x": -1,
      "y": 0,
      "z": 1,
      "name": "Water_Source",
      "level": 1
    },
    {
      "x": -1,
      "y": 1,
      "z": 1,
      "name": "Water_Source",
      "level": 1
    },
    {
      "x": -1,
      "y": 2,
      "z": 1,
      "name": "Water_Source",
      "level": 1
    },
    {
      "x": -1,
      "y": 3,
      "z": 1,
      "name": "Water_Source",
      "level": 1
    },
    {
      "x": -1,
      "y": 4,
      "z": 1,
      "name": "Empty",
      "level": 0
    },
    {
      "x": -1,
      "y": 5,
      "z": 1,
      "name": "Empty",
      "level": 0
    },
    {
      "x": -1,
      "y": 6,
      "z": 1,
      "name": "Empty",
      "level": 0
    },
    {
      "x": -1,
      "y": 7,
      "z": 1,
      "name": "Empty",
      "level": 0
    },
    {
      "x": -1,
      "y": 8,
      "z": 1,
      "name": "Empty",
      "level": 0
    },
    {
      "x": -1,
      "y": 0,
      "z": 2,
      "name": "Water_Source",
      "level": 1
    },
    {
      "x": -1,
      "y": 1,
      "z": 2,
      "name": "Water_Source",
      "level": 1
    },
    {
      "x": -1,
      "y": 2,
      "z": 2,
      "name": "Water_Source",
      "level": 1
    },
    {
      "x": -1,
      "y": 3,
      "z": 2,
      "name": "Water_Source",
      "level": 1
    },
    {
      "x": -1,
      "y": 4,
      "z": 2,
      "name": "Empty",
      "level": 0
    },
    {
      "x": -1,
      "y": 5,
      "z": 2,
      "name": "Empty",
      "level": 0
    },
    {
      "x": -1,
      "y": 6,
      "z": 2,
      "name": "Empty",
      "level": 0
    },
    {
      "x": -1,
      "y": 7,
      "z": 2,
      "name": "Empty",
      "level": 0
    },
    {
      "x": -1,
      "y": 8,
      "z": 2,
      "name": "Empty",
      "level": 0
    },
    {
      "x": -1,
      "y": 0,
      "z": 3,
      "name": "Water_Source",
      "level": 1
    },
    {
      "x": -1,
      "y": 1,
      "z": 3,
      "name": "Water_Source",
      "level": 1
    },
    {
      "x": -1,
      "y": 2,
      "z": 3,
      "name": "Water_Source",
      "level": 1
    },
    {
      "x": -1,
      "y": 3,
      "z": 3,
      "name": "Water_Source",
      "level": 1
    },
    {
      "x": -1,
      "y": 4,
      "z": 3,
      "name": "Empty",
      "level": 0
    },
    {
      "x": -1,
      "y": 5,
      "z": 3,
      "name": "Empty",
      "level": 0
    },
    {
      "x": -1,
      "y": 6,
      "z": 3,
      "name": "Empty",
      "level": 0
    },
    {
      "x": -1,
      "y": 7,
      "z": 3,
      "name": "Empty",
      "level": 0
    },
    {
      "x": -1,
      "y": 8,
      "z": 3,
      "name": "Empty",
      "level": 0
    },
    {
      "x": 0,
      "y": 0,
      "z": -3,
      "name": "Water_Source",
      "level": 1
    },
    {
      "x": 0,
      "y": 1,
      "z": -3,
      "name": "Water_Source",
      "level": 1
    },
    {
      "x": 0,
      "y": 2,
      "z": -3,
      "name": "Water_Source",
      "level": 1
    },
    {
      "x": 0,
      "y": 3,
      "z": -3,
      "name": "Water_Source",
      "level": 1
    },
    {
      "x": 0,
      "y": 4,
      "z": -3,
      "name": "Empty",
      "level": 0
    },
    {
      "x": 0,
      "y": 5,
      "z": -3,
      "name": "Empty",
      "level": 0
    },
    {
      "x": 0,
      "y": 6,
      "z": -3,
      "name": "Empty",
      "level": 0
    },
    {
      "x": 0,
      "y": 7,
      "z": -3,
      "name": "Empty",
      "level": 0
    },
    {
      "x": 0,
      "y": 8,
      "z": -3,
      "name": "Empty",
      "level": 0
    },
    {
      "x": 0,
      "y": 0,
      "z": -2,
      "name": "Water_Source",
      "level": 1
    },
    {
      "x": 0,
      "y": 1,
      "z": -2,
      "name": "Water_Source",
      "level": 1
    },
    {
      "x": 0,
      "y": 2,
      "z": -2,
      "name": "Water_Source",
      "level": 1
    },
    {
      "x": 0,
      "y": 3,
      "z": -2,
      "name": "Water_Source",
      "level": 1
    },
    {
      "x": 0,
      "y": 4,
      "z": -2,
      "name": "Empty",
      "level": 0
    },
    {
      "x": 0,
      "y": 5,
      "z": -2,
      "name": "Empty",
      "level": 0
    },
    {
      "x": 0,
      "y": 6,
      "z": -2,
      "name": "Empty",
      "level": 0
    },
    {
      "x": 0,
      "y": 7,
      "z": -2,
      "name": "Empty",
      "level": 0
    },
    {
      "x": 0,
      "y": 8,
      "z": -2,
      "name": "Empty",
      "level": 0
    },
    {
      "x": 0,
      "y": 0,
      "z": -1,
      "name": "Water_Source",
      "level": 1
    },
    {
      "x": 0,
      "y": 1,
      "z": -1,
      "name": "Water_Source",
      "level": 1
    },
    {
      "x": 0,
      "y": 2,
      "z": -1,
      "name": "Water_Source",
      "level": 1
    },
    {
      "x": 0,
      "y": 3,
      "z": -1,
      "name": "Water_Source",
      "level": 1
    },
    {
      "x": 0,
      "y": 4,
      "z": -1,
      "name": "Empty",
      "level": 0
    },
    {
      "x": 0,
      "y": 5,
      "z": -1,
      "name": "Empty",
      "level": 0
    },
    {
      "x": 0,
      "y": 6,
      "z": -1,
      "name": "Empty",
      "level": 0
    },
    {
      "x": 0,
      "y": 7,
      "z": -1,
      "name": "Empty",
      "level": 0
    },
    {
      "x": 0,
      "y": 8,
      "z": -1,
      "name": "Empty",
      "level": 0
    },
    {
      "x": 0,
      "y": 0,
      "z": 0,
      "name": "Water_Source",
      "level": 1
    },
    {
      "x": 0,
      "y": 1,
      "z": 0,
      "name": "Water_Source",
      "level": 1
    },
    {
      "x": 0,
      "y": 2,
      "z": 0,
      "name": "Water_Source",
      "level": 1
    },
    {
      "x": 0,
      "y": 3,
      "z": 0,
      "name": "Water_Source",
      "level": 1
    },
    {
      "x": 0,
      "y": 4,
      "z": 0,
      "name": "Empty",
      "level": 0
    },
    {
      "x": 0,
      "y": 5,
      "z": 0,
      "name": "Empty",
      "level": 0
    },
    {
      "x": 0,
      "y": 6,
      "z": 0,
      "name": "Empty",
      "level": 0
    },
    {
      "x": 0,
      "y": 7,
      "z": 0,
      "name": "Empty",
      "level": 0
    },
    {
      "x": 0,
      "y": 8,
      "z": 0,
      "name": "Empty",
      "level": 0
    },
    {
      "x": 0,
      "y": 0,
      "z": 1,
      "name": "Water_Source",
      "level": 1
    },
    {
      "x": 0,
      "y": 1,
      "z": 1,
      "name": "Water_Source",
      "level": 1
    },
    {
      "x": 0,
      "y": 2,
      "z": 1,
      "name": "Water_Source",
      "level": 1
    },
    {
      "x": 0,
      "y": 3,
      "z": 1,
      "name": "Water_Source",
      "level": 1
    },
    {
      "x": 0,
      "y": 4,
      "z": 1,
      "name": "Empty",
      "level": 0
    },
    {
      "x": 0,
      "y": 5,
      "z": 1,
      "name": "Empty",
      "level": 0
    },
    {
      "x": 0,
      "y": 6,
      "z": 1,
      "name": "Empty",
      "level": 0
    },
    {
      "x": 0,
      "y": 7,
      "z": 1,
      "name": "Empty",
      "level": 0
    },
    {
      "x": 0,
      "y": 8,
      "z": 1,
      "name": "Empty",
      "level": 0
    },
    {
      "x": 0,
      "y": 0,
      "z": 2,
      "name": "Water_Source",
      "level": 1
    },
    {
      "x": 0,
      "y": 1,
      "z": 2,
      "name": "Water_Source",
      "level": 1
    },
    {
      "x": 0,
      "y": 2,
      "z": 2,
      "name": "Water_Source",
      "level": 1
    },
    {
      "x": 0,
      "y": 3,
      "z": 2,
      "name": "Water_Source",
      "level": 1
    },
    {
      "x": 0,
      "y": 4,
      "z": 2,
      "name": "Empty",
      "level": 0
    },
    {
      "x": 0,
      "y": 5,
      "z": 2,
      "name": "Empty",
      "level": 0
    },
    {
      "x": 0,
      "y": 6,
      "z": 2,
      "name": "Empty",
      "level": 0
    },
    {
      "x": 0,
      "y": 7,
      "z": 2,
      "name": "Empty",
      "level": 0
    },
    {
      "x": 0,
      "y": 8,
      "z": 2,
      "name": "Empty",
      "level": 0
    },
    {
      "x": 0,
      "y": 0,
      "z": 3,
      "name": "Water_Source",
      "level": 1
    },
    {
      "x": 0,
      "y": 1,
      "z": 3,
      "name": "Water_Source",
      "level": 1
    },
    {
      "x": 0,
      "y": 2,
      "z": 3,
      "name": "Water_Source",
      "level": 1
    },
    {
      "x": 0,
      "y": 3,
      "z": 3,
      "name": "Water_Source",
      "level": 1
    },
    {
      "x": 0,
      "y": 4,
      "z": 3,
      "name": "Empty",
      "level": 0
    },
    {
      "x": 0,
      "y": 5,
      "z": 3,
      "name": "Empty",
      "level": 0
    },
    {
      "x": 0,
      "y": 6,
      "z": 3,
      "name": "Empty",
      "level": 0
    },
    {
      "x": 0,
      "y": 7,
      "z": 3,
      "name": "Empty",
      "level": 0
    },
    {
      "x": 0,
      "y": 8,
      "z": 3,
      "name": "Empty",
      "level": 0
    },
    {
      "x": 1,
      "y": 0,
      "z": -3,
      "name": "Water_Source",
      "level": 1
    },
    {
      "x": 1,
      "y": 1,
      "z": -3,
      "name": "Water_Source",
      "level": 1
    },
    {
      "x": 1,
      "y": 2,
      "z": -3,
      "name": "Water_Source",
      "level": 1
    },
    {
      "x": 1,
      "y": 3,
      "z": -3,
      "name": "Water_Source",
      "level": 1
    },
    {
      "x": 1,
      "y": 4,
      "z": -3,
      "name": "Empty",
      "level": 0
    },
    {
      "x": 1,
      "y": 5,
      "z": -3,
      "name": "Empty",
      "level": 0
    },
    {
      "x": 1,
      "y": 6,
      "z": -3,
      "name": "Empty",
      "level": 0
    },
    {
      "x": 1,
      "y": 7,
      "z": -3,
      "name": "Empty",
      "level": 0
    },
    {
      "x": 1,
      "y": 8,
      "z": -3,
      "name": "Empty",
      "level": 0
    },
    {
      "x": 1,
      "y": 0,
      "z": -2,
      "name": "Water_Source",
      "level": 1
    },
    {
      "x": 1,
      "y": 1,
      "z": -2,
      "name": "Water_Source",
      "level": 1
    },
    {
      "x": 1,
      "y": 2,
      "z": -2,
      "name": "Water_Source",
      "level": 1
    },
    {
      "x": 1,
      "y": 3,
      "z": -2,
      "name": "Water_Source",
      "level": 1
    },
    {
      "x": 1,
      "y": 4,
      "z": -2,
      "name": "Empty",
      "level": 0
    },
    {
      "x": 1,
      "y": 5,
      "z": -2,
      "name": "Empty",
      "level": 0
    },
    {
      "x": 1,
      "y": 6,
      "z": -2,
      "name": "Empty",
      "level": 0
    },
    {
      "x": 1,
      "y": 7,
      "z": -2,
      "name": "Empty",
      "level": 0
    },
    {
      "x": 1,
      "y": 8,
      "z": -2,
      "name": "Empty",
      "level": 0
    },
    {
      "x": 1,
      "y": 0,
      "z": -1,
      "name": "Water_Source",
      "level": 1
    },
    {
      "x": 1,
      "y": 1,
      "z": -1,
      "name": "Water_Source",
      "level": 1
    },
    {
      "x": 1,
      "y": 2,
      "z": -1,
      "name": "Water_Source",
      "level": 1
    },
    {
      "x": 1,
      "y": 3,
      "z": -1,
      "name": "Water_Source",
      "level": 1
    },
    {
      "x": 1,
      "y": 4,
      "z": -1,
      "name": "Empty",
      "level": 0
    },
    {
      "x": 1,
      "y": 5,
      "z": -1,
      "name": "Empty",
      "level": 0
    },
    {
      "x": 1,
      "y": 6,
      "z": -1,
      "name": "Empty",
      "level": 0
    },
    {
      "x": 1,
      "y": 7,
      "z": -1,
      "name": "Empty",
      "level": 0
    },
    {
      "x": 1,
      "y": 8,
      "z": -1,
      "name": "Empty",
      "level": 0
    },
    {
      "x": 1,
      "y": 0,
      "z": 0,
      "name": "Water_Source",
      "level": 1
    },
    {
      "x": 1,
      "y": 1,
      "z": 0,
      "name": "Water_Source",
      "level": 1
    },
    {
      "x": 1,
      "y": 2,
      "z": 0,
      "name": "Water_Source",
      "level": 1
    },
    {
      "x": 1,
      "y": 3,
      "z": 0,
      "name": "Water_Source",
      "level": 1
    },
    {
      "x": 1,
      "y": 4,
      "z": 0,
      "name": "Empty",
      "level": 0
    },
    {
      "x": 1,
      "y": 5,
      "z": 0,
      "name": "Empty",
      "level": 0
    },
    {
      "x": 1,
      "y": 6,
      "z": 0,
      "name": "Empty",
      "level": 0
    },
    {
      "x": 1,
      "y": 7,
      "z": 0,
      "name": "Empty",
      "level": 0
    },
    {
      "x": 1,
      "y": 8,
      "z": 0,
      "name": "Empty",
      "level": 0
    },
    {
      "x": 1,
      "y": 0,
      "z": 1,
      "name": "Water_Source",
      "level": 1
    },
    {
      "x": 1,
      "y": 1,
      "z": 1,
      "name": "Water_Source",
      "level": 1
    },
    {
      "x": 1,
      "y": 2,
      "z": 1,
      "name": "Water_Source",
      "level": 1
    },
    {
      "x": 1,
      "y": 3,
      "z": 1,
      "name": "Water_Source",
      "level": 1
    },
    {
      "x": 1,
      "y": 4,
      "z": 1,
      "name": "Empty",
      "level": 0
    },
    {
      "x": 1,
      "y": 5,
      "z": 1,
      "name": "Empty",
      "level": 0
    },
    {
      "x": 1,
      "y": 6,
      "z": 1,
      "name": "Empty",
      "level": 0
    },
    {
      "x": 1,
      "y": 7,
      "z": 1,
      "name": "Empty",
      "level": 0
    },
    {
      "x": 1,
      "y": 8,
      "z": 1,
      "name": "Empty",
      "level": 0
    },
    {
      "x": 1,
      "y": 0,
      "z": 2,
      "name": "Water_Source",
      "level": 1
    },
    {
      "x": 1,
      "y": 1,
      "z": 2,
      "name": "Water_Source",
      "level": 1
    },
    {
      "x": 1,
      "y": 2,
      "z": 2,
      "name": "Water_Source",
      "level": 1
    },
    {
      "x": 1,
      "y": 3,
      "z": 2,
      "name": "Water_Source",
      "level": 1
    },
    {
      "x": 1,
      "y": 4,
      "z": 2,
      "name": "Empty",
      "level": 0
    },
    {
      "x": 1,
      "y": 5,
      "z": 2,
      "name": "Empty",
      "level": 0
    },
    {
      "x": 1,
      "y": 6,
      "z": 2,
      "name": "Empty",
      "level": 0
    },
    {
      "x": 1,
      "y": 7,
      "z": 2,
      "name": "Empty",
      "level": 0
    },
    {
      "x": 1,
      "y": 8,
      "z": 2,
      "name": "Empty",
      "level": 0
    },
    {
      "x": 1,
      "y": 0,
      "z": 3,
      "name": "Water_Source",
      "level": 1
    },
    {
      "x": 1,
      "y": 1,
      "z": 3,
      "name": "Water_Source",
      "level": 1
    },
    {
      "x": 1,
      "y": 2,
      "z": 3,
      "name": "Water_Source",
      "level": 1
    },
    {
      "x": 1,
      "y": 3,
      "z": 3,
      "name": "Water_Source",
      "level": 1
    },
    {
      "x": 1,
      "y": 4,
      "z": 3,
      "name": "Empty",
      "level": 0
    },
    {
      "x": 1,
      "y": 5,
      "z": 3,
      "name": "Empty",
      "level": 0
    },
    {
      "x": 1,
      "y": 6,
      "z": 3,
      "name": "Empty",
      "level": 0
    },
    {
      "x": 1,
      "y": 7,
      "z": 3,
      "name": "Empty",
      "level": 0
    },
    {
      "x": 1,
      "y": 8,
      "z": 3,
      "name": "Empty",
      "level": 0
    },
    {
      "x": 2,
      "y": 0,
      "z": -3,
      "name": "Water_Source",
      "level": 1
    },
    {
      "x": 2,
      "y": 1,
      "z": -3,
      "name": "Water_Source",
      "level": 1
    },
    {
      "x": 2,
      "y": 2,
      "z": -3,
      "name": "Water_Source",
      "level": 1
    },
    {
      "x": 2,
      "y": 3,
      "z": -3,
      "name": "Water_Source",
      "level": 1
    },
    {
      "x": 2,
      "y": 4,
      "z": -3,
      "name": "Empty",
      "level": 0
    },
    {
      "x": 2,
      "y": 5,
      "z": -3,
      "name": "Empty",
      "level": 0
    },
    {
      "x": 2,
      "y": 6,
      "z": -3,
      "name": "Empty",
      "level": 0
    },
    {
      "x": 2,
      "y": 7,
      "z": -3,
      "name": "Empty",
      "level": 0
    },
    {
      "x": 2,
      "y": 8,
      "z": -3,
      "name": "Empty",
      "level": 0
    },
    {
      "x": 2,
      "y": 0,
      "z": -2,
      "name": "Water_Source",
      "level": 1
    },
    {
      "x": 2,
      "y": 1,
      "z": -2,
      "name": "Water_Source",
      "level": 1
    },
    {
      "x": 2,
      "y": 2,
      "z": -2,
      "name": "Water_Source",
      "level": 1
    },
    {
      "x": 2,
      "y": 3,
      "z": -2,
      "name": "Water_Source",
      "level": 1
    },
    {
      "x": 2,
      "y": 4,
      "z": -2,
      "name": "Empty",
      "level": 0
    },
    {
      "x": 2,
      "y": 5,
      "z": -2,
      "name": "Empty",
      "level": 0
    },
    {
      "x": 2,
      "y": 6,
      "z": -2,
      "name": "Empty",
      "level": 0
    },
    {
      "x": 2,
      "y": 7,
      "z": -2,
      "name": "Empty",
      "level": 0
    },
    {
      "x": 2,
      "y": 8,
      "z": -2,
      "name": "Empty",
      "level": 0
    },
    {
      "x": 2,
      "y": 0,
      "z": -1,
      "name": "Water_Source",
      "level": 1
    },
    {
      "x": 2,
      "y": 1,
      "z": -1,
      "name": "Water_Source",
      "level": 1
    },
    {
      "x": 2,
      "y": 2,
      "z": -1,
      "name": "Water_Source",
      "level": 1
    },
    {
      "x": 2,
      "y": 3,
      "z": -1,
      "name": "Water_Source",
      "level": 1
    },
    {
      "x": 2,
      "y": 4,
      "z": -1,
      "name": "Empty",
      "level": 0
    },
    {
      "x": 2,
      "y": 5,
      "z": -1,
      "name": "Empty",
      "level": 0
    },
    {
      "x": 2,
      "y": 6,
      "z": -1,
      "name": "Empty",
      "level": 0
    },
    {
      "x": 2,
      "y": 7,
      "z": -1,
      "name": "Empty",
      "level": 0
    },
    {
      "x": 2,
      "y": 8,
      "z": -1,
      "name": "Empty",
      "level": 0
    },
    {
      "x": 2,
      "y": 0,
      "z": 0,
      "name": "Water_Source",
      "level": 1
    },
    {
      "x": 2,
      "y": 1,
      "z": 0,
      "name": "Water_Source",
      "level": 1
    },
    {
      "x": 2,
      "y": 2,
      "z": 0,
      "name": "Water_Source",
      "level": 1
    },
    {
      "x": 2,
      "y": 3,
      "z": 0,
      "name": "Water_Source",
      "level": 1
    },
    {
      "x": 2,
      "y": 4,
      "z": 0,
      "name": "Empty",
      "level": 0
    },
    {
      "x": 2,
      "y": 5,
      "z": 0,
      "name": "Empty",
      "level": 0
    },
    {
      "x": 2,
      "y": 6,
      "z": 0,
      "name": "Empty",
      "level": 0
    },
    {
      "x": 2,
      "y": 7,
      "z": 0,
      "name": "Empty",
      "level": 0
    },
    {
      "x": 2,
      "y": 8,
      "z": 0,
      "name": "Empty",
      "level": 0
    },
    {
      "x": 2,
      "y": 0,
      "z": 1,
      "name": "Water_Source",
      "level": 1
    },
    {
      "x": 2,
      "y": 1,
      "z": 1,
      "name": "Water_Source",
      "level": 1
    },
    {
      "x": 2,
      "y": 2,
      "z": 1,
      "name": "Water_Source",
      "level": 1
    },
    {
      "x": 2,
      "y": 3,
      "z": 1,
      "name": "Water_Source",
      "level": 1
    },
    {
      "x": 2,
      "y": 4,
      "z": 1,
      "name": "Empty",
      "level": 0
    },
    {
      "x": 2,
      "y": 5,
      "z": 1,
      "name": "Empty",
      "level": 0
    },
    {
      "x": 2,
      "y": 6,
      "z": 1,
      "name": "Empty",
      "level": 0
    },
    {
      "x": 2,
      "y": 7,
      "z": 1,
      "name": "Empty",
      "level": 0
    },
    {
      "x": 2,
      "y": 8,
      "z": 1,
      "name": "Empty",
      "level": 0
    },
    {
      "x": 2,
      "y": 0,
      "z": 2,
      "name": "Water_Source",
      "level": 1
    },
    {
      "x": 2,
      "y": 1,
      "z": 2,
      "name": "Water_Source",
      "level": 1
    },
    {
      "x": 2,
      "y": 2,
      "z": 2,
      "name": "Water_Source",
      "level": 1
    },
    {
      "x": 2,
      "y": 3,
      "z": 2,
      "name": "Water_Source",
      "level": 1
    },
    {
      "x": 2,
      "y": 4,
      "z": 2,
      "name": "Empty",
      "level": 0
    },
    {
      "x": 2,
      "y": 5,
      "z": 2,
      "name": "Empty",
      "level": 0
    },
    {
      "x": 2,
      "y": 6,
      "z": 2,
      "name": "Empty",
      "level": 0
    },
    {
      "x": 2,
      "y": 7,
      "z": 2,
      "name": "Empty",
      "level": 0
    },
    {
      "x": 2,
      "y": 8,
      "z": 2,
      "name": "Empty",
      "level": 0
    },
    {
      "x": 2,
      "y": 0,
      "z": 3,
      "name": "Water_Source",
      "level": 1
    },
    {
      "x": 2,
      "y": 1,
      "z": 3,
      "name": "Water_Source",
      "level": 1
    },
    {
      "x": 2,
      "y": 2,
      "z": 3,
      "name": "Water_Source",
      "level": 1
    },
    {
      "x": 2,
      "y": 3,
      "z": 3,
      "name": "Water_Source",
      "level": 1
    },
    {
      "x": 2,
      "y": 4,
      "z": 3,
      "name": "Empty",
      "level": 0
    },
    {
      "x": 2,
      "y": 5,
      "z": 3,
      "name": "Empty",
      "level": 0
    },
    {
      "x": 2,
      "y": 6,
      "z": 3,
      "name": "Empty",
      "level": 0
    },
    {
      "x": 2,
      "y": 7,
      "z": 3,
      "name": "Empty",
      "level": 0
    },
    {
      "x": 2,
      "y": 8,
      "z": 3,
      "name": "Empty",
      "level": 0
    },
    {
      "x": 3,
      "y": 0,
      "z": -3,
      "name": "Water_Source",
      "level": 1
    },
    {
      "x": 3,
      "y": 1,
      "z": -3,
      "name": "Water_Source",
      "level": 1
    },
    {
      "x": 3,
      "y": 2,
      "z": -3,
      "name": "Water_Source",
      "level": 1
    },
    {
      "x": 3,
      "y": 3,
      "z": -3,
      "name": "Water_Source",
      "level": 1
    },
    {
      "x": 3,
      "y": 4,
      "z": -3,
      "name": "Empty",
      "level": 0
    },
    {
      "x": 3,
      "y": 5,
      "z": -3,
      "name": "Empty",
      "level": 0
    },
    {
      "x": 3,
      "y": 6,
      "z": -3,
      "name": "Empty",
      "level": 0
    },
    {
      "x": 3,
      "y": 7,
      "z": -3,
      "name": "Empty",
      "level": 0
    },
    {
      "x": 3,
      "y": 8,
      "z": -3,
      "name": "Empty",
      "level": 0
    },
    {
      "x": 3,
      "y": 0,
      "z": -2,
      "name": "Water_Source",
      "level": 1
    },
    {
      "x": 3,
      "y": 1,
      "z": -2,
      "name": "Water_Source",
      "level": 1
    },
    {
      "x": 3,
      "y": 2,
      "z": -2,
      "name": "Water_Source",
      "level": 1
    },
    {
      "x": 3,
      "y": 3,
      "z": -2,
      "name": "Water_Source",
      "level": 1
    },
    {
      "x": 3,
      "y": 4,
      "z": -2,
      "name": "Empty",
      "level": 0
    },
    {
      "x": 3,
      "y": 5,
      "z": -2,
      "name": "Empty",
      "level": 0
    },
    {
      "x": 3,
      "y": 6,
      "z": -2,
      "name": "Empty",
      "level": 0
    },
    {
      "x": 3,
      "y": 7,
      "z": -2,
      "name": "Empty",
      "level": 0
    },
    {
      "x": 3,
      "y": 8,
      "z": -2,
      "name": "Empty",
      "level": 0
    },
    {
      "x": 3,
      "y": 0,
      "z": -1,
      "name": "Water_Source",
      "level": 1
    },
    {
      "x": 3,
      "y": 1,
      "z": -1,
      "name": "Water_Source",
      "level": 1
    },
    {
      "x": 3,
      "y": 2,
      "z": -1,
      "name": "Water_Source",
      "level": 1
    },
    {
      "x": 3,
      "y": 3,
      "z": -1,
      "name": "Water_Source",
      "level": 1
    },
    {
      "x": 3,
      "y": 4,
      "z": -1,
      "name": "Empty",
      "level": 0
    },
    {
      "x": 3,
      "y": 5,
      "z": -1,
      "name": "Empty",
      "level": 0
    },
    {
      "x": 3,
      "y": 6,
      "z": -1,
      "name": "Empty",
      "level": 0
    },
    {
      "x": 3,
      "y": 7,
      "z": -1,
      "name": "Empty",
      "level": 0
    },
    {
      "x": 3,
      "y": 8,
      "z": -1,
      "name": "Empty",
      "level": 0
    },
    {
      "x": 3,
      "y": 0,
      "z": 0,
      "name": "Water_Source",
      "level": 1
    },
    {
      "x": 3,
      "y": 1,
      "z": 0,
      "name": "Water_Source",
      "level": 1
    },
    {
      "x": 3,
      "y": 2,
      "z": 0,
      "name": "Water_Source",
      "level": 1
    },
    {
      "x": 3,
      "y": 3,
      "z": 0,
      "name": "Water_Source",
      "level": 1
    },
    {
      "x": 3,
      "y": 4,
      "z": 0,
      "name": "Empty",
      "level": 0
    },
    {
      "x": 3,
      "y": 5,
      "z": 0,
      "name": "Empty",
      "level": 0
    },
    {
      "x": 3,
      "y": 6,
      "z": 0,
      "name": "Empty",
      "level": 0
    },
    {
      "x": 3,
      "y": 7,
      "z": 0,
      "name": "Empty",
      "level": 0
    },
    {
      "x": 3,
      "y": 8,
      "z": 0,
      "name": "Empty",
      "level": 0
    },
    {
      "x": 3,
      "y": 0,
      "z": 1,
      "name": "Water_Source",
      "level": 1
    },
    {
      "x": 3,
      "y": 1,
      "z": 1,
      "name": "Water_Source",
      "level": 1
    },
    {
      "x": 3,
      "y": 2,
      "z": 1,
      "name": "Water_Source",
      "level": 1
    },
    {
      "x": 3,
      "y": 3,
      "z": 1,
      "name": "Water_Source",
      "level": 1
    },
    {
      "x": 3,
      "y": 4,
      "z": 1,
      "name": "Empty",
      "level": 0
    },
    {
      "x": 3,
      "y": 5,
      "z": 1,
      "name": "Empty",
      "level": 0
    },
    {
      "x": 3,
      "y": 6,
      "z": 1,
      "name": "Empty",
      "level": 0
    },
    {
      "x": 3,
      "y": 7,
      "z": 1,
      "name": "Empty",
      "level": 0
    },
    {
      "x": 3,
      "y": 8,
      "z": 1,
      "name": "Empty",
      "level": 0
    },
    {
      "x": 3,
      "y": 0,
      "z": 2,
      "name": "Water_Source",
      "level": 1
    },
    {
      "x": 3,
      "y": 1,
      "z": 2,
      "name": "Water_Source",
      "level": 1
    },
    {
      "x": 3,
      "y": 2,
      "z": 2,
      "name": "Water_Source",
      "level": 1
    },
    {
      "x": 3,
      "y": 3,
      "z": 2,
      "name": "Water_Source",
      "level": 1
    },
    {
      "x": 3,
      "y": 4,
      "z": 2,
      "name": "Empty",
      "level": 0
    },
    {
      "x": 3,
      "y": 5,
      "z": 2,
      "name": "Empty",
      "level": 0
    },
    {
      "x": 3,
      "y": 6,
      "z": 2,
      "name": "Empty",
      "level": 0
    },
    {
      "x": 3,
      "y": 7,
      "z": 2,
      "name": "Empty",
      "level": 0
    },
    {
      "x": 3,
      "y": 8,
      "z": 2,
      "name": "Empty",
      "level": 0
    },
    {
      "x": 3,
      "y": 0,
      "z": 3,
      "name": "Water_Source",
      "level": 1
    },
    {
      "x": 3,
      "y": 1,
      "z": 3,
      "name": "Water_Source",
      "level": 1
    },
    {
      "x": 3,
      "y": 2,
      "z": 3,
      "name": "Water_Source",
      "level": 1
    },
    {
      "x": 3,
      "y": 3,
      "z": 3,
      "name": "Water_Source",
      "level": 1
    },
    {
      "x": 3,
      "y": 4,
      "z": 3,
      "name": "Empty",
      "level": 0
    },
    {
      "x": 3,
      "y": 5,
      "z": 3,
      "name": "Empty",
      "level": 0
    },
    {
      "x": 3,
      "y": 6,
      "z": 3,
      "name": "Empty",
      "level": 0
    },
    {
      "x": 3,
      "y": 7,
      "z": 3,
      "name": "Empty",
      "level": 0
    },
    {
      "x": 3,
      "y": 8,
      "z": 3,
      "name": "Empty",
      "level": 0
    }
  ]
}