{
  "version": 8,
  "blockIdVersion": 11,
  "anchorX": 0,
  "anchorY": 17,
  "anchorZ": 0,
  "blocks": [
    {
      "x": -11,
      "y": 5,
      "z": -2,
      "name": "Rock_Stone_Brick",
      "rotation": 2
    },
    {
      "x": -11,
      "y": 6,
      "z": -2,
      "name": "Soil_Gravel",
      "rotation": 2
    },
    {
      "x": -11,
      "y": 7,
      "z": -2,
      "name": "Soil_Gravel",
      "rotation": 2
    },
    {
      "x": -11,
      "y": 8,
      "z": -2,
      "name": "Soil_Gravel",
      "rotation": 2
    },
    {
      "x": -11,
      "y": 9,
      "z": -2,
      "name": "Soil_Gravel",
      "rotation": 2
    },
    {
      "x": -11,
      "y": 5,
      "z": 2,
      "name": "Rock_Stone_Brick",
      "rotation": 2
    },
    {
      "x": -11,
      "y": 6,
      "z": 2,
      "name": "Soil_Gravel",
      "rotation": 2
    },
    {
      "x": -11,
      "y": 7,
      "z": 2,
      "name": "Soil_Gravel",
      "rotation": 2
    },
    {
      "x": -11,
      "y": 8,
      "z": 2,
      "name": "Soil_Gravel",
      "rotation": 2
    },
    {
      "x": -11,
      "y": 9,
      "z": 2,
      "name": "Soil_Gravel",
      "rotation": 2
    },
    {
      "x": -10,
      "y": 4,
      "z": -11,
      "name": "Rock_Stone_Brick",
      "rotation": 2
    },
    {
      "x": -10,
      "y": 5,
      "z": -11,
      "name": "Rock_Stone_Brick",
      "rotation": 2
    },
    {
      "x": -10,
      "y": 6,
      "z": -11,
      "name": "Rock_Stone_Brick",
      "rotation": 2
    },
    {
      "x": -10,
      "y": 7,
      "z": -11,
      "name": "Rock_Stone_Brick",
      "rotation": 2
    },
    {
      "x": -10,
      "y": 8,
      "z": -11,
      "name": "Rock_Stone_Brick",
      "rotation": 2
    },
    {
      "x": -10,
      "y": 9,
      "z": -11,
      "name": "Rock_Stone_Brick",
      "rotation": 2
    },
    {
      "x": -10,
      "y": 10,
      "z": -11,
      "name": "Rock_Stone_Brick",
      "rotation": 2
    },
    {
      "x": -10,
      "y": 11,
      "z": -11,
      "name": "Rock_Stone_Brick_Decorative",
      "rotation": 2
    },
    {
      "x": -10,
      "y": 4,
      "z": -10,
      "name": "Rock_Stone_Brick",
      "rotation": 2
    },
    {
      "x": -10,
      "y": 5,
      "z": -10,
      "name": "Rock_Stone_Brick",
      "rotation": 2
    },
    {
      "x": -10,
      "y": 6,
      "z": -10,
      "name": "Rock_Stone_Brick",
      "rotation": 2
    },
    {
      "x": -10,
      "y": 7,
      "z": -10,
      "name": "Rock_Stone_Brick",
      "rotation": 2
    },
    {
      "x": -10,
      "y": 8,
      "z": -10,
      "name": "Rock_Stone_Brick",
      "rotation": 2
    },
    {
      "x": -10,
      "y": 9,
      "z": -10,
      "name": "Rock_Stone_Brick",
      "rotation": 2
    },
    {
      "x": -10,
      "y": 10,
      "z": -10,
      "name": "Rock_Stone_Brick",
      "rotation": 2
    },
    {
      "x": -10,
      "y": 11,
      "z": -10,
      "name": "Rock_Stone_Brick_Decorative",
      "rotation": 2
    },
    {
      "x": -10,
      "y": 4,
      "z": -9,
      "name": "Rock_Stone_Brick",
      "rotation": 2
    },
    {
      "x": -10,
      "y": 5,
      "z": -9,
      "name": "Rock_Stone_Brick",
      "rotation": 2
    },
    {
      "x": -10,
      "y": 6,
      "z": -9,
      "name": "Rock_Stone_Brick",
      "rotation": 2
    },
    {
      "x": -10,
      "y": 7,
      "z": -9,
      "name": "Rock_Stone_Brick",
      "rotation": 2
    },
    {
      "x": -10,
      "y": 8,
      "z": -9,
      "name": "Rock_Stone_Brick",
      "rotation": 2
    },
    {
      "x": -10,
      "y": 9,
      "z": -9,
      "name": "Rock_Stone_Brick",
      "rotation": 2
    },
    {
      "x": -10,
      "y": 10,
      "z": -9,
      "name": "Rock_Stone_Brick",
      "rotation": 2
    },
    {
      "x": -10,
      "y": 11,
      "z": -9,
      "name": "Rock_Stone_Brick_Decorative",
      "rotation": 2
    },
    {
      "x": -10,
      "y": 4,
      "z": -8,
      "name": "Rock_Stone_Brick",
      "rotation": 2
    },
    {
      "x": -10,
      "y": 5,
      "z": -8,
      "name": "Rock_Stone_Brick",
      "rotation": 2
    },
    {
      "x": -10,
      "y": 6,
      "z": -8,
      "name": "Rock_Stone_Brick",
      "rotation": 2
    },
    {
      "x": -10,
      "y": 7,
      "z": -8,
      "name": "Rock_Stone_Brick",
      "rotation": 2
    },
    {
      "x": -10,
      "y": 8,
      "z": -8,
      "name": "Rock_Stone_Brick",
      "rotation": 2
    },
    {
      "x": -10,
      "y": 9,
      "z": -8,
      "name": "Rock_Stone_Brick",
      "rotation": 2
    },
    {
      "x": -10,
      "y": 10,
      "z": -8,
      "name": "Rock_Stone_Brick",
      "rotation": 2
    },
    {
      "x": -10,
      "y": 11,
      "z": -8,
      "name": "Rock_Stone_Brick_Decorative",
      "rotation": 2
    },
    {
      "x": -10,
      "y": 4,
      "z": -7,
      "name": "Rock_Stone_Brick",
      "rotation": 2
    },
    {
      "x": -10,
      "y": 5,
      "z": -7,
      "name": "Rock_Stone_Brick",
      "rotation": 2
    },
    {
      "x": -10,
      "y": 6,
      "z": -7,
      "name": "Rock_Stone_Brick",
      "rotation": 2
    },
    {
      "x": -10,
      "y": 7,
      "z": -7,
      "name": "Rock_Stone_Brick",
      "rotation": 2
    },
    {
      "x": -10,
      "y": 8,
      "z": -7,
      "name": "Rock_Stone_Brick",
      "rotation": 2
    },
    {
      "x": -10,
      "y": 9,
      "z": -7,
      "name": "Rock_Stone_Brick",
      "rotation": 2
    },
    {
      "x": -10,
      "y": 10,
      "z": -7,
      "name": "Rock_Stone_Brick",
      "rotation": 2
    },
    {
      "x": -10,
      "y": 11,
      "z": -7,
      "name": "Rock_Stone_Brick_Decorative",
      "rotation": 2
    },
    {
      "x": -10,
      "y": 3,
      "z": -6,
      "name": "Rock_Stone_Brick_Smooth",
      "rotation": 3
    },
    {
      "x": -10,
      "y": 4,
      "z": -6,
      "name": "Rock_Stone_Brick",
      "rotation": 1
    },
    {
      "x": -10,
      "y": 5,
      "z": -6,
      "name": "Rock_Stone_Brick_Decorative"
    },
    {
      "x": -10,
      "y": 6,
      "z": -6,
      "name": "Rock_Stone_Brick",
      "rotation": 1
    },
    {
      "x": -10,
      "y": 7,
      "z": -6,
      "name": "Rock_Stone_Brick",
      "rotation": 1
    },
    {
      "x": -10,
      "y": 8,
      "z": -6,
      "name": "Rock_Stone_Brick",
      "rotation": 1
    },
    {
      "x": -10,
      "y": 9,
      "z": -6,
      "name": "Rock_Stone_Brick",
      "rotation": 1
    },
    {
      "x": -10,
      "y": 10,
      "z": -6,
      "name": "Rock_Stone_Brick"
    },
    {
      "x": -10,
      "y": 4,
      "z": -5,
      "name": "Rock_Stone_Brick_Smooth",
      "rotation": 2
    },
    {
      "x": -10,
      "y": 10,
      "z": -5,
      "name": "Rock_Stone_Brick",
      "rotation": 2
    },
    {
      "x": -10,
      "y": 4,
      "z": -4,
      "name": "Rock_Stone_Brick_Smooth",
      "rotation": 2
    },
    {
      "x": -10,
      "y": 10,
      "z": -4,
      "name": "Rock_Stone_Brick",
      "rotation": 2
    },
    {
      "x": -10,
      "y": 4,
      "z": -3,
      "name": "Rock_Stone_Brick_Smooth",
      "rotation": 2
    },
    {
      "x": -10,
      "y": 5,
      "z": -3,
      "name": "Rock_Stone_Brick",
      "rotation": 2
    },
    {
      "x": -10,
      "y": 6,
      "z": -3,
      "name": "Rock_Stone_Brick",
      "rotation": 2
    },
    {
      "x": -10,
      "y": 7,
      "z": -3,
      "name": "Rock_Stone_Brick",
      "rotation": 2
    },
    {
      "x": -10,
      "y": 8,
      "z": -3,
      "name": "Rock_Stone_Brick",
      "rotation": 2
    },
    {
      "x": -10,
      "y": 9,
      "z": -3,
      "name": "Rock_Stone_Brick",
      "rotation": 2
    },
    {
      "x": -10,
      "y": 10,
      "z": -3,
      "name": "Rock_Stone_Brick",
      "rotation": 2
    },
    {
      "x": -10,
      "y": 4,
      "z": -2,
      "name": "Rock_Stone_Brick_Smooth",
      "rotation": 2
    },
    {
      "x": -10,
      "y": 5,
      "z": -2,
      "name": "Rock_Stone_Brick_Smooth",
      "rotation": 2
    },
    {
      "x": -10,
      "y": 6,
      "z": -2,
      "name": "Rock_Stone_Brick_Pillar_Base",
      "rotation": 2
    },
    {
      "x": -10,
      "y": 7,
      "z": -2,
      "name": "Rock_Stone_Brick_Pillar_Middle",
      "rotation": 2
    },
    {
      "x": -10,
      "y": 8,
      "z": -2,
      "name": "Rock_Stone_Brick_Pillar_Middle",
      "rotation": 2
    },
    {
      "x": -10,
      "y": 9,
      "z": -2,
      "name": "Rock_Stone_Brick_Pillar_Base",
      "rotation": 10
    },
    {
      "x": -10,
      "y": 10,
      "z": -2,
      "name": "Rock_Stone_Brick",
      "rotation": 2
    },
    {
      "x": -10,
      "y": 4,
      "z": -1,
      "name": "Rock_Stone_Brick_Smooth",
      "rotation": 2
    },
    {
      "x": -10,
      "y": 5,
      "z": -1,
      "name": "Rock_Stone_Brick_Decorative",
      "rotation": 2
    },
    {
      "x": -10,
      "y": 6,
      "z": -1,
      "name": "Soil_Gravel_Half",
      "rotation": 5
    },
    {
      "x": -10,
      "y": 7,
      "z": -1,
      "name": "Soil_Gravel_Half",
      "rotation": 5
    },
    {
      "x": -10,
      "y": 8,
      "z": -1,
      "name": "Soil_Gravel_Half",
      "rotation": 5
    },
    {
      "x": -10,
      "y": 9,
      "z": -1,
      "name": "Soil_Gravel_Half",
      "rotation": 5
    },
    {
      "x": -10,
      "y": 10,
      "z": -1,
      "name": "Rock_Stone_Brick",
      "rotation": 2
    },
    {
      "x": -10,
      "y": 4,
      "z": 0,
      "name": "Rock_Stone_Brick_Smooth",
      "rotation": 2
    },
    {
      "x": -10,
      "y": 5,
      "z": 0,
      "name": "Rock_Stone_Brick_Decorative",
      "rotation": 2
    },
    {
      "x": -10,
      "y": 6,
      "z": 0,
      "name": "Soil_Gravel_Half",
      "rotation": 5
    },
    {
      "x": -10,
      "y": 7,
      "z": 0,
      "name": "Soil_Gravel_Half",
      "rotation": 5
    },
    {
      "x": -10,
      "y": 8,
      "z": 0,
      "name": "Soil_Gravel_Half",
      "rotation": 5
    },
    {
      "x": -10,
      "y": 9,
      "z": 0,
      "name": "Soil_Gravel_Half",
      "rotation": 5
    },
    {
      "x": -10,
      "y": 10,
      "z": 0,
      "name": "Rock_Stone_Brick",
      "rotation": 2
    },
    {
      "x": -10,
      "y": 4,
      "z": 1,
      "name": "Rock_Stone_Brick_Smooth",
      "rotation": 2
    },
    {
      "x": -10,
      "y": 5,
      "z": 1,
      "name": "Rock_Stone_Brick_Decorative",
      "rotation": 2
    },
    {
      "x": -10,
      "y": 6,
      "z": 1,
      "name": "Soil_Gravel_Half",
      "rotation": 5
    },
    {
      "x": -10,
      "y": 7,
      "z": 1,
      "name": "Soil_Gravel_Half",
      "rotation": 5
    },
    {
      "x": -10,
      "y": 8,
      "z": 1,
      "name": "Soil_Gravel_Half",
      "rotation": 5
    },
    {
      "x": -10,
      "y": 9,
      "z": 1,
      "name": "Soil_Gravel_Half",
      "rotation": 5
    },
    {
      "x": -10,
      "y": 10,
      "z": 1,
      "name": "Rock_Stone_Brick",
      "rotation": 2
    },
    {
      "x": -10,
      "y": 4,
      "z": 2,
      "name": "Rock_Stone_Brick_Smooth",
      "rotation": 2
    },
    {
      "x": -10,
      "y": 5,
      "z": 2,
      "name": "Rock_Stone_Brick_Smooth",
      "rotation": 2
    },
    {
      "x": -10,
      "y": 6,
      "z": 2,
      "name": "Rock_Stone_Brick_Pillar_Base",
      "rotation": 2
    },
    {
      "x": -10,
      "y": 7,
      "z": 2,
      "name": "Rock_Stone_Brick_Pillar_Middle",
      "rotation": 2
    },
    {
      "x": -10,
      "y": 8,
      "z": 2,
      "name": "Rock_Stone_Brick_Pillar_Middle",
      "rotation": 2
    },
    {
      "x": -10,
      "y": 9,
      "z": 2,
      "name": "Rock_Stone_Brick_Pillar_Base",
      "rotation": 10
    },
    {
      "x": -10,
      "y": 10,
      "z": 2,
      "name": "Rock_Stone_Brick",
      "rotation": 2
    },
    {
      "x": -10,
      "y": 4,
      "z": 3,
      "name": "Rock_Stone_Brick_Smooth",
      "rotation": 2
    },
    {
      "x": -10,
      "y": 5,
      "z": 3,
      "name": "Rock_Stone_Brick_Decorative",
      "rotation": 2
    },
    {
      "x": -10,
      "y": 6,
      "z": 3,
      "name": "Rock_Stone_Brick",
      "rotation": 2
    },
    {
      "x": -10,
      "y": 7,
      "z": 3,
      "name": "Rock_Stone_Brick",
      "rotation": 2
    },
    {
      "x": -10,
      "y": 8,
      "z": 3,
      "name": "Rock_Stone_Brick",
      "rotation": 2
    },
    {
      "x": -10,
      "y": 9,
      "z": 3,
      "name": "Rock_Stone_Brick",
      "rotation": 2
    },
    {
      "x": -10,
      "y": 10,
      "z": 3,
      "name": "Rock_Stone_Brick",
      "rotation": 2
    },
    {
      "x": -9,
      "y": 4,
      "z": -12,
      "name": "Rock_Stone_Brick",
      "rotation": 2
    },
    {
      "x": -9,
      "y": 5,
      "z": -12,
      "name": "Rock_Stone_Brick",
      "rotation": 2
    },
    {
      "x": -9,
      "y": 6,
      "z": -12,
      "name": "Rock_Stone_Brick",
      "rotation": 2
    },
    {
      "x": -9,
      "y": 7,
      "z": -12,
      "name": "Rock_Stone_Brick",
      "rotation": 2
    },
    {
      "x": -9,
      "y": 8,
      "z": -12,
      "name": "Rock_Stone_Brick",
      "rotation": 2
    },
    {
      "x": -9,
      "y": 9,
      "z": -12,
      "name": "Rock_Stone_Brick",
      "rotation": 2
    },
    {
      "x": -9,
      "y": 10,
      "z": -12,
      "name": "Rock_Stone_Brick",
      "rotation": 2
    },
    {
      "x": -9,
      "y": 11,
      "z": -12,
      "name": "Rock_Stone_Brick_Decorative",
      "rotation": 2
    },
    {
      "x": -9,
      "y": 4,
      "z": -11,
      "name": "Rock_Stone_Brick_Smooth",
      "rotation": 2
    },
    {
      "x": -9,
      "y": 11,
      "z": -11,
      "name": "Rock_Stone_Brick_Smooth_Half",
      "rotation": 10
    },
    {
      "x": -9,
      "y": 4,
      "z": -10,
      "name": "Rock_Stone_Brick_Smooth",
      "rotation": 2
    },
    {
      "x": -9,
      "y": 11,
      "z": -10,
      "name": "Rock_Stone_Brick_Smooth_Half",
      "rotation": 10
    },
    {
      "x": -9,
      "y": 4,
      "z": -9,
      "name": "Rock_Stone_Brick_Smooth",
      "rotation": 2
    },
    {
      "x": -9,
      "y": 11,
      "z": -9,
      "name": "Rock_Stone_Brick_Smooth_Half",
      "rotation": 10
    },
    {
      "x": -9,
      "y": 4,
      "z": -8,
      "name": "Rock_Stone_Brick_Smooth",
      "rotation": 2
    },
    {
      "x": -9,
      "y": 11,
      "z": -8,
      "name": "Rock_Stone_Brick_Smooth_Half",
      "rotation": 10
    },
    {
      "x": -9,
      "y": 3,
      "z": -7,
      "name": "Rock_Stone_Brick_Smooth",
      "rotation": 3
    },
    {
      "x": -9,
      "y": 4,
      "z": -7,
      "name": "Rock_Stone_Brick_Smooth",
      "rotation": 2
    },
    {
      "x": -9,
      "y": 11,
      "z": -7,
      "name": "Rock_Stone_Brick_Smooth_Half",
      "rotation": 10
    },
    {
      "x": -9,
      "y": 3,
      "z": -6,
      "name": "Rock_Stone_Brick_Smooth",
      "rotation": 3
    },
    {
      "x": -9,
      "y": 4,
      "z": -6,
      "name": "Rock_Stone_Brick",
      "rotation": 1
    },
    {
      "x": -9,
      "y": 5,
      "z": -6,
      "name": "Rock_Stone_Brick_Decorative"
    },
    {
      "x": -9,
      "y": 6,
      "z": -6,
      "name": "Rock_Stone_Brick"
    },
    {
      "x": -9,
      "y": 7,
      "z": -6,
      "name": "Rock_Stone_Brick"
    },
    {
      "x": -9,
      "y": 8,
      "z": -6,
      "name": "Rock_Stone_Brick"
    },
    {
      "x": -9,
      "y": 9,
      "z": -6,
      "name": "Rock_Stone_Brick"
    },
    {
      "x": -9,
      "y": 10,
      "z": -6,
      "name": "Rock_Stone_Brick"
    },
    {
      "x": -9,
      "y": 11,
      "z": -6,
      "name": "Rock_Stone_Brick_Decorative",
      "rotation": 2
    },
    {
      "x": -9,
      "y": 4,
      "z": -5,
      "name": "Rock_Stone_Brick_Smooth",
      "rotation": 2
    },
    {
      "x": -9,
      "y": 5,
      "z": -5,
      "name": "Rock_Stone_Brick_Decorative",
      "rotation": 2
    },
    {
      "x": -9,
      "y": 6,
      "z": -5,
      "name": "Rock_Stone_Brick",
      "rotation": 2
    },
    {
      "x": -9,
      "y": 7,
      "z": -5,
      "name": "Rock_Stone_Brick",
      "rotation": 2
    },
    {
      "x": -9,
      "y": 8,
      "z": -5,
      "name": "Rock_Stone_Brick",
      "rotation": 2
    },
    {
      "x": -9,
      "y": 9,
      "z": -5,
      "name": "Rock_Stone_Brick",
      "rotation": 2
    },
    {
      "x": -9,
      "y": 10,
      "z": -5,
      "name": "Rock_Stone_Brick",
      "rotation": 2
    },
    {
      "x": -9,
      "y": 11,
      "z": -5,
      "name": "Rock_Stone_Brick",
      "rotation": 2
    },
    {
      "x": -9,
      "y": 4,
      "z": -4,
      "name": "Rock_Stone_Brick_Smooth",
      "rotation": 2
    },
    {
      "x": -9,
      "y": 5,
      "z": -4,
      "name": "Rock_Stone_Brick_Decorative",
      "rotation": 2
    },
    {
      "x": -9,
      "y": 6,
      "z": -4,
      "name": "Rock_Stone_Brick",
      "rotation": 2
    },
    {
      "x": -9,
      "y": 7,
      "z": -4,
      "name": "Rock_Stone_Brick",
      "rotation": 2
    },
    {
      "x": -9,
      "y": 8,
      "z": -4,
      "name": "Rock_Stone_Brick",
      "rotation": 2
    },
    {
      "x": -9,
      "y": 9,
      "z": -4,
      "name": "Rock_Stone_Brick",
      "rotation": 2
    },
    {
      "x": -9,
      "y": 10,
      "z": -4,
      "name": "Rock_Stone_Brick",
      "rotation": 2
    },
    {
      "x": -9,
      "y": 11,
      "z": -4,
      "name": "Rock_Stone_Brick",
      "rotation": 2
    },
    {
      "x": -9,
      "y": 4,
      "z": -3,
      "name": "Rock_Stone_Brick_Smooth",
      "rotation": 2
    },
    {
      "x": -9,
      "y": 5,
      "z": -3,
      "name": "Rock_Stone_Brick_Smooth",
      "rotation": 2
    },
    {
      "x": -9,
      "y": 6,
      "z": -3,
      "name": "Rock_Stone_Brick",
      "rotation": 2
    },
    {
      "x": -9,
      "y": 7,
      "z": -3,
      "name": "Rock_Stone_Brick",
      "rotation": 2
    },
    {
      "x": -9,
      "y": 8,
      "z": -3,
      "name": "Rock_Stone_Brick",
      "rotation": 2
    },
    {
      "x": -9,
      "y": 9,
      "z": -3,
      "name": "Rock_Stone_Brick",
      "rotation": 2
    },
    {
      "x": -9,
      "y": 10,
      "z": -3,
      "name": "Rock_Stone_Brick",
      "rotation": 2
    },
    {
      "x": -9,
      "y": 11,
      "z": -3,
      "name": "Rock_Stone_Brick",
      "rotation": 2
    },
    {
      "x": -9,
      "y": 4,
      "z": -2,
      "name": "Rock_Stone_Brick_Smooth",
      "rotation": 2
    },
    {
      "x": -9,
      "y": 5,
      "z": -2,
      "name": "Furniture_Temple_Dark_Candle",
      "rotation": 2
    },
    {
      "x": -9,
      "y": 6,
      "z": -2,
      "name": "Furniture_Temple_Dark_Candle",
      "filler": 1024,
      "rotation": 2
    },
    {
      "x": -9,
      "y": 11,
      "z": -2,
      "name": "Rock_Stone_Brick_Smooth",
      "rotation": 2
    },
    {
      "x": -9,
      "y": 4,
      "z": -1,
      "name": "Rock_Stone_Brick_Smooth",
      "rotation": 2
    },
    {
      "x": -9,
      "y": 11,
      "z": -1,
      "name": "Rock_Stone_Brick_Smooth",
      "rotation": 2
    },
    {
      "x": -9,
      "y": 4,
      "z": 0,
      "name": "Rock_Stone_Brick_Smooth",
      "rotation": 2
    },
    {
      "x": -9,
      "y": 11,
      "z": 0,
      "name": "Rock_Stone_Brick_Smooth",
      "rotation": 2
    },
    {
      "x": -9,
      "y": 4,
      "z": 1,
      "name": "Rock_Stone_Brick_Smooth",
      "rotation": 2
    },
    {
      "x": -9,
      "y": 11,
      "z": 1,
      "name": "Rock_Stone_Brick_Smooth",
      "rotation": 2
    },
    {
      "x": -9,
      "y": 4,
      "z": 2,
      "name": "Rock_Stone_Brick_Smooth",
      "rotation": 2
    },
    {
      "x": -9,
      "y": 5,
      "z": 2,
      "name": "Furniture_Temple_Dark_Candle",
      "rotation": 2
    },
    {
      "x": -9,
      "y": 6,
      "z": 2,
      "name": "Furniture_Temple_Dark_Candle",
      "filler": 1024,
      "rotation": 2
    },
    {
      "x": -9,
      "y": 11,
      "z": 2,
      "name": "Rock_Stone_Brick_Smooth",
      "rotation": 2
    },
    {
      "x": -9,
      "y": 4,
      "z": 3,
      "name": "Rock_Stone_Brick_Smooth",
      "rotation": 2
    },
    {
      "x": -9,
      "y": 5,
      "z": 3,
      "name": "Rock_Stone_Brick_Smooth",
      "rotation": 2
    },
    {
      "x": -9,
      "y": 6,
      "z": 3,
      "name": "Rock_Stone_Brick_Pillar_Base",
      "rotation": 2
    },
    {
      "x": -9,
      "y": 7,
      "z": 3,
      "name": "Rock_Stone_Brick_Pillar_Middle",
      "rotation": 2
    },
    {
      "x": -9,
      "y": 8,
      "z": 3,
      "name": "Rock_Stone_Brick_Pillar_Middle",
      "rotation": 2
    },
    {
      "x": -9,
      "y": 9,
      "z": 3,
      "name": "Rock_Stone_Brick_Pillar_Base",
      "rotation": 10
    },
    {
      "x": -9,
      "y": 10,
      "z": 3,
      "name": "Rock_Stone_Brick",
      "rotation": 2
    },
    {
      "x": -9,
      "y": 5,
      "z": 4,
      "name": "Rock_Stone_Brick_Smooth",
      "rotation": 2
    },
    {
      "x": -9,
      "y": 6,
      "z": 4,
      "name": "Soil_Gravel",
      "rotation": 2
    },
    {
      "x": -9,
      "y": 7,
      "z": 4,
      "name": "Soil_Gravel",
      "rotation": 2
    },
    {
      "x": -9,
      "y": 8,
      "z": 4,
      "name": "Soil_Gravel",
      "rotation": 2
    },
    {
      "x": -9,
      "y": 9,
      "z": 4,
      "name": "Soil_Gravel",
      "rotation": 2
    },
    {
      "x": -8,
      "y": 4,
      "z": -12,
      "name": "Rock_Stone_Brick",
      "rotation": 2
    },
    {
      "x": -8,
      "y": 5,
      "z": -12,
      "name": "Rock_Stone_Brick",
      "rotation": 2
    },
    {
      "x": -8,
      "y": 6,
      "z": -12,
      "name": "Rock_Stone_Brick",
      "rotation": 2
    },
    {
      "x": -8,
      "y": 7,
      "z": -12,
      "name": "Rock_Stone_Brick",
      "rotation": 2
    },
    {
      "x": -8,
      "y": 8,
      "z": -12,
      "name": "Rock_Stone_Brick",
      "rotation": 2
    },
    {
      "x": -8,
      "y": 9,
      "z": -12,
      "name": "Rock_Stone_Brick",
      "rotation": 2
    },
    {
      "x": -8,
      "y": 10,
      "z": -12,
      "name": "Rock_Stone_Brick",
      "rotation": 2
    },
    {
      "x": -8,
      "y": 11,
      "z": -12,
      "name": "Rock_Stone_Brick_Decorative",
      "rotation": 2
    },
    {
      "x": -8,
      "y": 4,
      "z": -11,
      "name": "Rock_Stone_Brick_Smooth",
      "rotation": 2
    },
    {
      "x": -8,
      "y": 11,
      "z": -11,
      "name": "Rock_Stone_Brick_Smooth_Half",
      "rotation": 10
    },
    {
      "x": -8,
      "y": 4,
      "z": -10,
      "name": "Rock_Stone_Brick_Smooth",
      "rotation": 2
    },
    {
      "x": -8,
      "y": 11,
      "z": -10,
      "name": "Rock_Stone_Brick_Smooth_Half",
      "rotation": 10
    },
    {
      "x": -8,
      "y": 4,
      "z": -9,
      "name": "Rock_Stone_Brick_Smooth",
      "rotation": 2
    },
    {
      "x": -8,
      "y": 11,
      "z": -9,
      "name": "Rock_Stone_Brick_Smooth_Half",
      "rotation": 10
    },
    {
      "x": -8,
      "y": 4,
      "z": -8,
      "name": "Rock_Stone_Brick_Smooth",
      "rotation": 2
    },
    {
      "x": -8,
      "y": 11,
      "z": -8,
      "name": "Rock_Stone_Brick_Smooth_Half",
      "rotation": 10
    },
    {
      "x": -8,
      "y": 3,
      "z": -7,
      "name": "Rock_Stone_Brick_Smooth",
      "rotation": 3
    },
    {
      "x": -8,
      "y": 4,
      "z": -7,
      "name": "Rock_Stone_Brick_Smooth",
      "rotation": 2
    },
    {
      "x": -8,
      "y": 11,
      "z": -7,
      "name": "Rock_Stone_Brick_Smooth_Half",
      "rotation": 10
    },
    {
      "x": -8,
      "y": 3,
      "z": -6,
      "name": "Rock_Stone_Brick_Smooth",
      "rotation": 3
    },
    {
      "x": -8,
      "y": 4,
      "z": -6,
      "name": "Rock_Stone_Brick_Smooth",
      "rotation": 3
    },
    {
      "x": -8,
      "y": 5,
      "z": -6,
      "name": "Rock_Stone_Brick_Smooth_Half",
      "rotation": 5
    },
    {
      "x": -8,
      "y": 6,
      "z": -6,
      "name": "Rock_Stone_Brick_Smooth_Half",
      "rotation": 5
    },
    {
      "x": -8,
      "y": 7,
      "z": -6,
      "name": "Rock_Stone_Brick_Smooth_Half",
      "rotation": 5
    },
    {
      "x": -8,
      "y": 8,
      "z": -6,
      "name": "Rock_Stone_Brick_Stairs",
      "rotation": 11
    },
    {
      "x": -8,
      "y": 9,
      "z": -6,
      "name": "Rock_Stone_Brick_Decorative"
    },
    {
      "x": -8,
      "y": 10,
      "z": -6,
      "name": "Rock_Stone_Brick"
    },
    {
      "x": -8,
      "y": 11,
      "z": -6,
      "name": "Rock_Stone_Brick_Decorative",
      "rotation": 2
    },
    {
      "x": -8,
      "y": 4,
      "z": -5,
      "name": "Rock_Stone_Brick_Smooth",
      "rotation": 2
    },
    {
      "x": -8,
      "y": 8,
      "z": -5,
      "name": "Rock_Stone_Brick_Stairs",
      "rotation": 11
    },
    {
      "x": -8,
      "y": 10,
      "z": -5,
      "name": "Rock_Stone_Brick",
      "rotation": 2
    },
    {
      "x": -8,
      "y": 11,
      "z": -5,
      "name": "Rock_Stone_Brick_Smooth",
      "rotation": 2
    },
    {
      "x": -8,
      "y": 4,
      "z": -4,
      "name": "Rock_Stone_Brick_Smooth",
      "rotation": 2
    },
    {
      "x": -8,
      "y": 8,
      "z": -4,
      "name": "Rock_Stone_Brick_Stairs",
      "rotation": 11
    },
    {
      "x": -8,
      "y": 10,
      "z": -4,
      "name": "Rock_Stone_Brick",
      "rotation": 2
    },
    {
      "x": -8,
      "y": 11,
      "z": -4,
      "name": "Rock_Stone_Brick_Smooth",
      "rotation": 2
    },
    {
      "x": -8,
      "y": 4,
      "z": -3,
      "name": "Rock_Stone_Brick_Smooth",
      "rotation": 2
    },
    {
      "x": -8,
      "y": 5,
      "z": -3,
      "name": "Rock_Stone_Brick_Smooth_Half",
      "rotation": 5
    },
    {
      "x": -8,
      "y": 6,
      "z": -3,
      "name": "Rock_Stone_Brick_Smooth_Half",
      "rotation": 5
    },
    {
      "x": -8,
      "y": 7,
      "z": -3,
      "name": "Rock_Stone_Brick_Smooth_Half",
      "rotation": 5
    },
    {
      "x": -8,
      "y": 8,
      "z": -3,
      "name": "Rock_Stone_Brick_Stairs",
      "rotation": 11
    },
    {
      "x": -8,
      "y": 9,
      "z": -3,
      "name": "Rock_Stone_Brick_Decorative",
      "rotation": 2
    },
    {
      "x": -8,
      "y": 10,
      "z": -3,
      "name": "Rock_Stone_Brick",
      "rotation": 2
    },
    {
      "x": -8,
      "y": 11,
      "z": -3,
      "name": "Rock_Stone_Brick_Smooth",
      "rotation": 2
    },
    {
      "x": -8,
      "y": 4,
      "z": -2,
      "name": "Rock_Stone_Brick_Smooth",
      "rotation": 2
    },
    {
      "x": -8,
      "y": 11,
      "z": -2,
      "name": "Rock_Stone_Brick_Smooth",
      "rotation": 2
    },
    {
      "x": -8,
      "y": 4,
      "z": -1,
      "name": "Rock_Stone_Brick_Smooth",
      "rotation": 2
    },
    {
      "x": -8,
      "y": 11,
      "z": -1,
      "name": "Rock_Stone_Brick_Smooth",
      "rotation": 2
    },
    {
      "x": -8,
      "y": 4,
      "z": 0,
      "name": "Rock_Stone_Brick_Smooth",
      "rotation": 2
    },
    {
      "x": -8,
      "y": 11,
      "z": 0,
      "name": "Rock_Stone_Brick_Smooth",
      "rotation": 2
    },
    {
      "x": -8,
      "y": 4,
      "z": 1,
      "name": "Rock_Stone_Brick_Smooth",
      "rotation": 2
    },
    {
      "x": -8,
      "y": 11,
      "z": 1,
      "name": "Rock_Stone_Brick_Smooth",
      "rotation": 2
    },
    {
      "x": -8,
      "y": 4,
      "z": 2,
      "name": "Rock_Stone_Brick_Smooth",
      "rotation": 2
    },
    {
      "x": -8,
      "y": 11,
      "z": 2,
      "name": "Rock_Stone_Brick_Smooth",
      "rotation": 2
    },
    {
      "x": -8,
      "y": 4,
      "z": 3,
      "name": "Rock_Stone_Brick_Smooth",
      "rotation": 2
    },
    {
      "x": -8,
      "y": 5,
      "z": 3,
      "name": "Rock_Stone_Brick_Decorative",
      "rotation": 2
    },
    {
      "x": -8,
      "y": 6,
      "z": 3,
      "name": "Soil_Gravel_Half",
      "rotation": 6
    },
    {
      "x": -8,
      "y": 7,
      "z": 3,
      "name": "Soil_Gravel_Half",
      "rotation": 6
    },
    {
      "x": -8,
      "y": 8,
      "z": 3,
      "name": "Soil_Gravel_Half",
      "rotation": 6
    },
    {
      "x": -8,
      "y": 9,
      "z": 3,
      "name": "Soil_Gravel_Half",
      "rotation": 6
    },
    {
      "x": -8,
      "y": 10,
      "z": 3,
      "name": "Rock_Stone_Brick",
      "rotation": 2
    },
    {
      "x": -7,
      "y": 4,
      "z": -12,
      "name": "Rock_Stone_Brick",
      "rotation": 2
    },
    {
      "x": -7,
      "y": 5,
      "z": -12,
      "name": "Rock_Stone_Brick",
      "rotation": 2
    },
    {
      "x": -7,
      "y": 6,
      "z": -12,
      "name": "Rock_Stone_Brick",
      "rotation": 2
    },
    {
      "x": -7,
      "y": 7,
      "z": -12,
      "name": "Rock_Stone_Brick",
      "rotation": 2
    },
    {
      "x": -7,
      "y": 8,
      "z": -12,
      "name": "Rock_Stone_Brick",
      "rotation": 2
    },
    {
      "x": -7,
      "y": 9,
      "z": -12,
      "name": "Rock_Stone_Brick",
      "rotation": 2
    },
    {
      "x": -7,
      "y": 10,
      "z": -12,
      "name": "Rock_Stone_Brick",
      "rotation": 2
    },
    {
      "x": -7,
      "y": 11,
      "z": -12,
      "name": "Rock_Stone_Brick_Decorative",
      "rotation": 2
    },
    {
      "x": -7,
      "y": 4,
      "z": -11,
      "name": "Rock_Stone_Brick_Smooth",
      "rotation": 2
    },
    {
      "x": -7,
      "y": 5,
      "z": -11,
      "name": "Furniture_Dungeon_Chest_Epic",
      "components": {
        "Components": {
          "ItemContainerBlock": {
            "ItemContainer": {
              "Capacity": 18,
              "Items": {}
            },
            "Capacity": 18
          }
        }
      }
    },
    {
      "x": -7,
      "y": 11,
      "z": -11,
      "name": "Rock_Stone_Brick_Smooth_Half",
      "rotation": 10
    },
    {
      "x": -7,
      "y": 4,
      "z": -10,
      "name": "Rock_Stone_Brick_Smooth",
      "rotation": 2
    },
    {
      "x": -7,
      "y": 11,
      "z": -10,
      "name": "Rock_Stone_Brick_Smooth_Half",
      "rotation": 10
    },
    {
      "x": -7,
      "y": 4,
      "z": -9,
      "name": "Rock_Stone_Brick_Smooth",
      "rotation": 2
    },
    {
      "x": -7,
      "y": 11,
      "z": -9,
      "name": "Rock_Stone_Brick_Smooth_Half",
      "rotation": 10
    },
    {
      "x": -7,
      "y": 4,
      "z": -8,
      "name": "Rock_Stone_Brick_Smooth",
      "rotation": 2
    },
    {
      "x": -7,
      "y": 11,
      "z": -8,
      "name": "Rock_Stone_Brick_Smooth_Half",
      "rotation": 10
    },
    {
      "x": -7,
      "y": 3,
      "z": -7,
      "name": "Rock_Stone_Brick_Smooth",
      "rotation": 3
    },
    {
      "x": -7,
      "y": 4,
      "z": -7,
      "name": "Rock_Stone_Brick_Smooth",
      "rotation": 2
    },
    {
      "x": -7,
      "y": 11,
      "z": -7,
      "name": "Rock_Stone_Brick_Smooth_Half",
      "rotation": 10
    },
    {
      "x": -7,
      "y": 3,
      "z": -6,
      "name": "Rock_Stone_Brick_Smooth",
      "rotation": 3
    },
    {
      "x": -7,
      "y": 4,
      "z": -6,
      "name": "Rock_Stone_Brick_Smooth",
      "rotation": 3
    },
    {
      "x": -7,
      "y": 8,
      "z": -6,
      "name": "Rock_Stone_Brick_Smooth_Half",
      "rotation": 8
    },
    {
      "x": -7,
      "y": 9,
      "z": -6,
      "name": "Rock_Stone_Brick_Decorative"
    },
    {
      "x": -7,
      "y": 10,
      "z": -6,
      "name": "Rock_Stone_Brick"
    },
    {
      "x": -7,
      "y": 11,
      "z": -6,
      "name": "Rock_Stone_Brick_Decorative",
      "rotation": 2
    },
    {
      "x": -7,
      "y": 4,
      "z": -5,
      "name": "Rock_Stone_Brick_Smooth",
      "rotation": 2
    },
    {
      "x": -7,
      "y": 8,
      "z": -5,
      "name": "Rock_Stone_Brick_Smooth_Half",
      "rotation": 10
    },
    {
      "x": -7,
      "y": 10,
      "z": -5,
      "name": "Rock_Stone_Brick",
      "rotation": 2
    },
    {
      "x": -7,
      "y": 11,
      "z": -5,
      "name": "Rock_Stone_Brick_Smooth",
      "rotation": 2
    },
    {
      "x": -7,
      "y": 4,
      "z": -4,
      "name": "Rock_Stone_Brick_Smooth",
      "rotation": 2
    },
    {
      "x": -7,
      "y": 8,
      "z": -4,
      "name": "Rock_Stone_Brick_Smooth_Half",
      "rotation": 10
    },
    {
      "x": -7,
      "y": 10,
      "z": -4,
      "name": "Rock_Stone_Brick",
      "rotation": 2
    },
    {
      "x": -7,
      "y": 11,
      "z": -4,
      "name": "Rock_Stone_Brick_Smooth",
      "rotation": 2
    },
    {
      "x": -7,
      "y": 4,
      "z": -3,
      "name": "Rock_Stone_Brick_Smooth",
      "rotation": 2
    },
    {
      "x": -7,
      "y": 8,
      "z": -3,
      "name": "Rock_Stone_Brick_Smooth_Half",
      "rotation": 10
    },
    {
      "x": -7,
      "y": 9,
      "z": -3,
      "name": "Rock_Stone_Brick_Decorative",
      "rotation": 2
    },
    {
      "x": -7,
      "y": 10,
      "z": -3,
      "name": "Rock_Stone_Brick",
      "rotation": 2
    },
    {
      "x": -7,
      "y": 11,
      "z": -3,
      "name": "Rock_Stone_Brick_Smooth",
      "rotation": 2
    },
    {
      "x": -7,
      "y": 4,
      "z": -2,
      "name": "Rock_Stone_Brick_Smooth",
      "rotation": 2
    },
    {
      "x": -7,
      "y": 11,
      "z": -2,
      "name": "Rock_Stone_Brick_Smooth",
      "rotation": 2
    },
    {
      "x": -7,
      "y": 4,
      "z": -1,
      "name": "Rock_Stone_Brick_Smooth",
      "rotation": 2
    },
    {
      "x": -7,
      "y": 11,
      "z": -1,
      "name": "Rock_Stone_Brick_Smooth",
      "rotation": 2
    },
    {
      "x": -7,
      "y": 4,
      "z": 0,
      "name": "Rock_Stone_Brick_Smooth",
      "rotation": 2
    },
    {
      "x": -7,
      "y": 11,
      "z": 0,
      "name": "Rock_Stone_Brick_Smooth",
      "rotation": 2
    },
    {
      "x": -7,
      "y": 4,
      "z": 1,
      "name": "Rock_Stone_Brick_Smooth",
      "rotation": 2
    },
    {
      "x": -7,
      "y": 11,
      "z": 1,
      "name": "Rock_Stone_Brick_Smooth",
      "rotation": 2
    },
    {
      "x": -7,
      "y": 4,
      "z": 2,
      "name": "Rock_Stone_Brick_Smooth",
      "rotation": 2
    },
    {
      "x": -7,
      "y": 11,
      "z": 2,
      "name": "Rock_Stone_Brick_Smooth",
      "rotation": 2
    },
    {
      "x": -7,
      "y": 4,
      "z": 3,
      "name": "Rock_Stone_Brick_Smooth",
      "rotation": 2
    },
    {
      "x": -7,
      "y": 5,
      "z": 3,
      "name": "Rock_Stone_Brick_Decorative",
      "rotation": 2
    },
    {
      "x": -7,
      "y": 6,
      "z": 3,
      "name": "Soil_Gravel_Half",
      "rotation": 6
    },
    {
      "x": -7,
      "y": 7,
      "z": 3,
      "name": "Soil_Gravel_Half",
      "rotation": 6
    },
    {
      "x": -7,
      "y": 8,
      "z": 3,
      "name": "Soil_Gravel_Half",
      "rotation": 6
    },
    {
      "x": -7,
      "y": 9,
      "z": 3,
      "name": "Soil_Gravel_Half",
      "rotation": 6
    },
    {
      "x": -7,
      "y": 10,
      "z": 3,
      "name": "Rock_Stone_Brick",
      "rotation": 2
    },
    {
      "x": -6,
      "y": 4,
      "z": -12,
      "name": "Rock_Stone_Brick",
      "rotation": 2
    },
    {
      "x": -6,
      "y": 5,
      "z": -12,
      "name": "Rock_Stone_Brick",
      "rotation": 2
    },
    {
      "x": -6,
      "y": 6,
      "z": -12,
      "name": "Rock_Stone_Brick",
      "rotation": 2
    },
    {
      "x": -6,
      "y": 7,
      "z": -12,
      "name": "Rock_Stone_Brick",
      "rotation": 2
    },
    {
      "x": -6,
      "y": 8,
      "z": -12,
      "name": "Rock_Stone_Brick",
      "rotation": 2
    },
    {
      "x": -6,
      "y": 9,
      "z": -12,
      "name": "Rock_Stone_Brick",
      "rotation": 2
    },
    {
      "x": -6,
      "y": 10,
      "z": -12,
      "name": "Rock_Stone_Brick",
      "rotation": 2
    },
    {
      "x": -6,
      "y": 11,
      "z": -12,
      "name": "Rock_Stone_Brick_Decorative",
      "rotation": 2
    },
    {
      "x": -6,
      "y": 4,
      "z": -11,
      "name": "Rock_Stone_Brick_Smooth",
      "rotation": 2
    },
    {
      "x": -6,
      "y": 11,
      "z": -11,
      "name": "Rock_Stone_Brick_Smooth_Half",
      "rotation": 10
    },
    {
      "x": -6,
      "y": 4,
      "z": -10,
      "name": "Rock_Stone_Brick_Smooth",
      "rotation": 2
    },
    {
      "x": -6,
      "y": 11,
      "z": -10,
      "name": "Rock_Stone_Brick_Smooth_Half",
      "rotation": 10
    },
    {
      "x": -6,
      "y": 4,
      "z": -9,
      "name": "Rock_Stone_Brick_Smooth",
      "rotation": 2
    },
    {
      "x": -6,
      "y": 11,
      "z": -9,
      "name": "Rock_Stone_Brick_Smooth_Half",
      "rotation": 10
    },
    {
      "x": -6,
      "y": 4,
      "z": -8,
      "name": "Rock_Stone_Brick_Smooth",
      "rotation": 2
    },
    {
      "x": -6,
      "y": 11,
      "z": -8,
      "name": "Rock_Stone_Brick_Smooth_Half",
      "rotation": 10
    },
    {
      "x": -6,
      "y": 4,
      "z": -7,
      "name": "Rock_Stone_Brick_Smooth",
      "rotation": 2
    },
    {
      "x": -6,
      "y": 11,
      "z": -7,
      "name": "Rock_Stone_Brick_Smooth_Half",
      "rotation": 10
    },
    {
      "x": -6,
      "y": 4,
      "z": -6,
      "name": "Rock_Stone_Brick_Smooth"
    },
    {
      "x": -6,
      "y": 5,
      "z": -6,
      "name": "Rock_Stone_Brick_Smooth_Half",
      "rotation": 7
    },
    {
      "x": -6,
      "y": 6,
      "z": -6,
      "name": "Rock_Stone_Brick_Smooth_Half",
      "rotation": 7
    },
    {
      "x": -6,
      "y": 7,
      "z": -6,
      "name": "Rock_Stone_Brick_Smooth_Half",
      "rotation": 7
    },
    {
      "x": -6,
      "y": 8,
      "z": -6,
      "name": "Rock_Stone_Brick_Stairs",
      "rotation": 9
    },
    {
      "x": -6,
      "y": 9,
      "z": -6,
      "name": "Rock_Stone_Brick_Decorative"
    },
    {
      "x": -6,
      "y": 10,
      "z": -6,
      "name": "Rock_Stone_Brick"
    },
    {
      "x": -6,
      "y": 11,
      "z": -6,
      "name": "Rock_Stone_Brick_Decorative",
      "rotation": 2
    },
    {
      "x": -6,
      "y": 4,
      "z": -5,
      "name": "Rock_Stone_Brick_Smooth",
      "rotation": 2
    },
    {
      "x": -6,
      "y": 8,
      "z": -5,
      "name": "Rock_Stone_Brick_Stairs",
      "rotation": 9
    },
    {
      "x": -6,
      "y": 10,
      "z": -5,
      "name": "Rock_Stone_Brick",
      "rotation": 2
    },
    {
      "x": -6,
      "y": 11,
      "z": -5,
      "name": "Rock_Stone_Brick_Smooth",
      "rotation": 2
    },
    {
      "x": -6,
      "y": 4,
      "z": -4,
      "name": "Rock_Stone_Brick_Smooth",
      "rotation": 2
    },
    {
      "x": -6,
      "y": 8,
      "z": -4,
      "name": "Rock_Stone_Brick_Stairs",
      "rotation": 9
    },
    {
      "x": -6,
      "y": 10,
      "z": -4,
      "name": "Rock_Stone_Brick",
      "rotation": 2
    },
    {
      "x": -6,
      "y": 11,
      "z": -4,
      "name": "Rock_Stone_Brick_Smooth",
      "rotation": 2
    },
    {
      "x": -6,
      "y": 4,
      "z": -3,
      "name": "Rock_Stone_Brick_Smooth",
      "rotation": 2
    },
    {
      "x": -6,
      "y": 5,
      "z": -3,
      "name": "Rock_Stone_Brick_Smooth_Half",
      "rotation": 7
    },
    {
      "x": -6,
      "y": 6,
      "z": -3,
      "name": "Rock_Stone_Brick_Smooth_Half",
      "rotation": 7
    },
    {
      "x": -6,
      "y": 7,
      "z": -3,
      "name": "Rock_Stone_Brick_Smooth_Half",
      "rotation": 7
    },
    {
      "x": -6,
      "y": 8,
      "z": -3,
      "name": "Rock_Stone_Brick_Stairs",
      "rotation": 9
    },
    {
      "x": -6,
      "y": 9,
      "z": -3,
      "name": "Rock_Stone_Brick_Decorative",
      "rotation": 2
    },
    {
      "x": -6,
      "y": 10,
      "z": -3,
      "name": "Rock_Stone_Brick",
      "rotation": 2
    },
    {
      "x": -6,
      "y": 11,
      "z": -3,
      "name": "Rock_Stone_Brick_Smooth",
      "rotation": 2
    },
    {
      "x": -6,
      "y": 4,
      "z": -2,
      "name": "Rock_Stone_Brick_Smooth",
      "rotation": 2
    },
    {
      "x": -6,
      "y": 11,
      "z": -2,
      "name": "Rock_Stone_Brick_Smooth",
      "rotation": 2
    },
    {
      "x": -6,
      "y": 4,
      "z": -1,
      "name": "Rock_Stone_Brick_Smooth",
      "rotation": 2
    },
    {
      "x": -6,
      "y": 11,
      "z": -1,
      "name": "Rock_Stone_Brick_Smooth",
      "rotation": 2
    },
    {
      "x": -6,
      "y": 4,
      "z": 0,
      "name": "Rock_Stone_Brick_Smooth",
      "rotation": 2
    },
    {
      "x": -6,
      "y": 11,
      "z": 0,
      "name": "Rock_Stone_Brick_Smooth",
      "rotation": 2
    },
    {
      "x": -6,
      "y": 4,
      "z": 1,
      "name": "Rock_Stone_Brick_Smooth",
      "rotation": 2
    },
    {
      "x": -6,
      "y": 11,
      "z": 1,
      "name": "Rock_Stone_Brick_Smooth",
      "rotation": 2
    },
    {
      "x": -6,
      "y": 4,
      "z": 2,
      "name": "Rock_Stone_Brick_Smooth",
      "rotation": 2
    },
    {
      "x": -6,
      "y": 11,
      "z": 2,
      "name": "Rock_Stone_Brick_Smooth",
      "rotation": 2
    },
    {
      "x": -6,
      "y": 4,
      "z": 3,
      "name": "Rock_Stone_Brick_Smooth",
      "rotation": 2
    },
    {
      "x": -6,
      "y": 5,
      "z": 3,
      "name": "Rock_Stone_Brick_Decorative",
      "rotation": 2
    },
    {
      "x": -6,
      "y": 6,
      "z": 3,
      "name": "Soil_Gravel_Half",
      "rotation": 6
    },
    {
      "x": -6,
      "y": 7,
      "z": 3,
      "name": "Soil_Gravel_Half",
      "rotation": 6
    },
    {
      "x": -6,
      "y": 8,
      "z": 3,
      "name": "Soil_Gravel_Half",
      "rotation": 6
    },
    {
      "x": -6,
      "y": 9,
      "z": 3,
      "name": "Soil_Gravel_Half",
      "rotation": 6
    },
    {
      "x": -6,
      "y": 10,
      "z": 3,
      "name": "Rock_Stone_Brick",
      "rotation": 2
    },
    {
      "x": -5,
      "y": 4,
      "z": -12,
      "name": "Rock_Stone_Brick",
      "rotation": 2
    },
    {
      "x": -5,
      "y": 5,
      "z": -12,
      "name": "Rock_Stone_Brick",
      "rotation": 2
    },
    {
      "x": -5,
      "y": 6,
      "z": -12,
      "name": "Rock_Stone_Brick",
      "rotation": 2
    },
    {
      "x": -5,
      "y": 7,
      "z": -12,
      "name": "Rock_Stone_Brick",
      "rotation": 2
    },
    {
      "x": -5,
      "y": 8,
      "z": -12,
      "name": "Rock_Stone_Brick",
      "rotation": 2
    },
    {
      "x": -5,
      "y": 9,
      "z": -12,
      "name": "Rock_Stone_Brick",
      "rotation": 2
    },
    {
      "x": -5,
      "y": 10,
      "z": -12,
      "name": "Rock_Stone_Brick",
      "rotation": 2
    },
    {
      "x": -5,
      "y": 11,
      "z": -12,
      "name": "Rock_Stone_Brick_Decorative",
      "rotation": 2
    },
    {
      "x": -5,
      "y": 4,
      "z": -11,
      "name": "Rock_Stone_Brick_Smooth",
      "rotation": 2
    },
    {
      "x": -5,
      "y": 11,
      "z": -11,
      "name": "Rock_Stone_Brick_Smooth_Half",
      "rotation": 10
    },
    {
      "x": -5,
      "y": 4,
      "z": -10,
      "name": "Rock_Stone_Brick_Smooth",
      "rotation": 2
    },
    {
      "x": -5,
      "y": 11,
      "z": -10,
      "name": "Rock_Stone_Brick_Smooth_Half",
      "rotation": 10
    },
    {
      "x": -5,
      "y": 4,
      "z": -9,
      "name": "Rock_Stone_Brick_Smooth",
      "rotation": 2
    },
    {
      "x": -5,
      "y": 11,
      "z": -9,
      "name": "Rock_Stone_Brick_Smooth_Half",
      "rotation": 10
    },
    {
      "x": -5,
      "y": 4,
      "z": -8,
      "name": "Rock_Stone_Brick_Smooth",
      "rotation": 2
    },
    {
      "x": -5,
      "y": 11,
      "z": -8,
      "name": "Rock_Stone_Brick_Smooth_Half",
      "rotation": 10
    },
    {
      "x": -5,
      "y": 4,
      "z": -7,
      "name": "Rock_Stone_Brick_Smooth",
      "rotation": 2
    },
    {
      "x": -5,
      "y": 11,
      "z": -7,
      "name": "Rock_Stone_Brick_Smooth_Half",
      "rotation": 10
    },
    {
      "x": -5,
      "y": 4,
      "z": -6,
      "name": "Rock_Stone_Brick",
      "rotation": 1
    },
    {
      "x": -5,
      "y": 5,
      "z": -6,
      "name": "Rock_Stone_Brick_Decorative"
    },
    {
      "x": -5,
      "y": 6,
      "z": -6,
      "name": "Rock_Stone_Brick"
    },
    {
      "x": -5,
      "y": 7,
      "z": -6,
      "name": "Rock_Stone_Brick"
    },
    {
      "x": -5,
      "y": 8,
      "z": -6,
      "name": "Rock_Stone_Brick"
    },
    {
      "x": -5,
      "y": 9,
      "z": -6,
      "name": "Rock_Stone_Brick"
    },
    {
      "x": -5,
      "y": 10,
      "z": -6,
      "name": "Rock_Stone_Brick"
    },
    {
      "x": -5,
      "y": 11,
      "z": -6,
      "name": "Rock_Stone_Brick_Decorative",
      "rotation": 2
    },
    {
      "x": -5,
      "y": 4,
      "z": -5,
      "name": "Rock_Stone_Brick_Smooth",
      "rotation": 2
    },
    {
      "x": -5,
      "y": 5,
      "z": -5,
      "name": "Rock_Stone_Brick_Decorative",
      "rotation": 2
    },
    {
      "x": -5,
      "y": 6,
      "z": -5,
      "name": "Rock_Stone_Brick",
      "rotation": 2
    },
    {
      "x": -5,
      "y": 7,
      "z": -5,
      "name": "Rock_Stone_Brick",
      "rotation": 2
    },
    {
      "x": -5,
      "y": 8,
      "z": -5,
      "name": "Rock_Stone_Brick",
      "rotation": 2
    },
    {
      "x": -5,
      "y": 9,
      "z": -5,
      "name": "Rock_Stone_Brick",
      "rotation": 2
    },
    {
      "x": -5,
      "y": 10,
      "z": -5,
      "name": "Rock_Stone_Brick",
      "rotation": 2
    },
    {
      "x": -5,
      "y": 11,
      "z": -5,
      "name": "Rock_Stone_Brick",
      "rotation": 2
    },
    {
      "x": -5,
      "y": 4,
      "z": -4,
      "name": "Rock_Stone_Brick_Smooth",
      "rotation": 2
    },
    {
      "x": -5,
      "y": 5,
      "z": -4,
      "name": "Rock_Stone_Brick_Decorative",
      "rotation": 2
    },
    {
      "x": -5,
      "y": 6,
      "z": -4,
      "name": "Rock_Stone_Brick",
      "rotation": 2
    },
    {
      "x": -5,
      "y": 7,
      "z": -4,
      "name": "Rock_Stone_Brick",
      "rotation": 2
    },
    {
      "x": -5,
      "y": 8,
      "z": -4,
      "name": "Rock_Stone_Brick",
      "rotation": 2
    },
    {
      "x": -5,
      "y": 9,
      "z": -4,
      "name": "Rock_Stone_Brick",
      "rotation": 2
    },
    {
      "x": -5,
      "y": 10,
      "z": -4,
      "name": "Rock_Stone_Brick",
      "rotation": 2
    },
    {
      "x": -5,
      "y": 11,
      "z": -4,
      "name": "Rock_Stone_Brick",
      "rotation": 2
    },
    {
      "x": -5,
      "y": 4,
      "z": -3,
      "name": "Rock_Stone_Brick_Smooth",
      "rotation": 2
    },
    {
      "x": -5,
      "y": 5,
      "z": -3,
      "name": "Rock_Stone_Brick_Smooth",
      "rotation": 2
    },
    {
      "x": -5,
      "y": 6,
      "z": -3,
      "name": "Rock_Stone_Brick",
      "rotation": 2
    },
    {
      "x": -5,
      "y": 7,
      "z": -3,
      "name": "Rock_Stone_Brick",
      "rotation": 2
    },
    {
      "x": -5,
      "y": 8,
      "z": -3,
      "name": "Rock_Stone_Brick",
      "rotation": 2
    },
    {
      "x": -5,
      "y": 9,
      "z": -3,
      "name": "Rock_Stone_Brick",
      "rotation": 2
    },
    {
      "x": -5,
      "y": 10,
      "z": -3,
      "name": "Rock_Stone_Brick",
      "rotation": 2
    },
    {
      "x": -5,
      "y": 11,
      "z": -3,
      "name": "Rock_Stone_Brick",
      "rotation": 2
    },
    {
      "x": -5,
      "y": 4,
      "z": -2,
      "name": "Rock_Stone_Brick_Smooth",
      "rotation": 2
    },
    {
      "x": -5,
      "y": 5,
      "z": -2,
      "name": "Furniture_Temple_Dark_Candle",
      "rotation": 2
    },
    {
      "x": -5,
      "y": 6,
      "z": -2,
      "name": "Furniture_Temple_Dark_Candle",
      "filler": 1024,
      "rotation": 2
    },
    {
      "x": -5,
      "y": 11,
      "z": -2,
      "name": "Rock_Stone_Brick_Smooth",
      "rotation": 2
    },
    {
      "x": -5,
      "y": 4,
      "z": -1,
      "name": "Rock_Stone_Brick_Smooth",
      "rotation": 2
    },
    {
      "x": -5,
      "y": 11,
      "z": -1,
      "name": "Rock_Stone_Brick_Stairs",
      "rotation": 11
    },
    {
      "x": -5,
      "y": 4,
      "z": 0,
      "name": "Rock_Stone_Brick_Smooth",
      "rotation": 2
    },
    {
      "x": -5,
      "y": 11,
      "z": 0,
      "name": "Rock_Stone_Brick_Stairs",
      "rotation": 11
    },
    {
      "x": -5,
      "y": 4,
      "z": 1,
      "name": "Rock_Stone_Brick_Smooth",
      "rotation": 2
    },
    {
      "x": -5,
      "y": 11,
      "z": 1,
      "name": "Rock_Stone_Brick_Stairs",
      "rotation": 11
    },
    {
      "x": -5,
      "y": 4,
      "z": 2,
      "name": "Rock_Stone_Brick_Smooth",
      "rotation": 2
    },
    {
      "x": -5,
      "y": 5,
      "z": 2,
      "name": "Furniture_Temple_Dark_Candle",
      "rotation": 2
    },
    {
      "x": -5,
      "y": 6,
      "z": 2,
      "name": "Furniture_Temple_Dark_Candle",
      "filler": 1024,
      "rotation": 2
    },
    {
      "x": -5,
      "y": 11,
      "z": 2,
      "name": "Rock_Stone_Brick_Smooth",
      "rotation": 2
    },
    {
      "x": -5,
      "y": 4,
      "z": 3,
      "name": "Rock_Stone_Brick_Smooth",
      "rotation": 2
    },
    {
      "x": -5,
      "y": 5,
      "z": 3,
      "name": "Rock_Stone_Brick_Smooth",
      "rotation": 2
    },
    {
      "x": -5,
      "y": 6,
      "z": 3,
      "name": "Rock_Stone_Brick_Pillar_Base",
      "rotation": 2
    },
    {
      "x": -5,
      "y": 7,
      "z": 3,
      "name": "Rock_Stone_Brick_Pillar_Middle",
      "rotation": 2
    },
    {
      "x": -5,
      "y": 8,
      "z": 3,
      "name": "Rock_Stone_Brick_Pillar_Middle",
      "rotation": 2
    },
    {
      "x": -5,
      "y": 9,
      "z": 3,
      "name": "Rock_Stone_Brick_Pillar_Base",
      "rotation": 10
    },
    {
      "x": -5,
      "y": 10,
      "z": 3,
      "name": "Rock_Stone_Brick",
      "rotation": 2
    },
    {
      "x": -5,
      "y": 5,
      "z": 4,
      "name": "Rock_Stone_Brick_Smooth",
      "rotation": 2
    },
    {
      "x": -5,
      "y": 6,
      "z": 4,
      "name": "Soil_Gravel",
      "rotation": 2
    },
    {
      "x": -5,
      "y": 7,
      "z": 4,
      "name": "Soil_Gravel",
      "rotation": 2
    },
    {
      "x": -5,
      "y": 8,
      "z": 4,
      "name": "Soil_Gravel",
      "rotation": 2
    },
    {
      "x": -5,
      "y": 9,
      "z": 4,
      "name": "Soil_Gravel",
      "rotation": 2
    },
    {
      "x": -4,
      "y": 4,
      "z": -11,
      "name": "Rock_Stone_Brick",
      "rotation": 2
    },
    {
      "x": -4,
      "y": 5,
      "z": -11,
      "name": "Rock_Stone_Brick",
      "rotation": 2
    },
    {
      "x": -4,
      "y": 6,
      "z": -11,
      "name": "Rock_Stone_Brick",
      "rotation": 2
    },
    {
      "x": -4,
      "y": 7,
      "z": -11,
      "name": "Rock_Stone_Brick",
      "rotation": 2
    },
    {
      "x": -4,
      "y": 8,
      "z": -11,
      "name": "Rock_Stone_Brick",
      "rotation": 2
    },
    {
      "x": -4,
      "y": 9,
      "z": -11,
      "name": "Rock_Stone_Brick",
      "rotation": 2
    },
    {
      "x": -4,
      "y": 10,
      "z": -11,
      "name": "Rock_Stone_Brick",
      "rotation": 2
    },
    {
      "x": -4,
      "y": 11,
      "z": -11,
      "name": "Rock_Stone_Brick_Decorative",
      "rotation": 2
    },
    {
      "x": -4,
      "y": 4,
      "z": -10,
      "name": "Rock_Stone_Brick",
      "rotation": 2
    },
    {
      "x": -4,
      "y": 5,
      "z": -10,
      "name": "Rock_Stone_Brick",
      "rotation": 2
    },
    {
      "x": -4,
      "y": 6,
      "z": -10,
      "name": "Rock_Stone_Brick",
      "rotation": 2
    },
    {
      "x": -4,
      "y": 7,
      "z": -10,
      "name": "Rock_Stone_Brick",
      "rotation": 2
    },
    {
      "x": -4,
      "y": 8,
      "z": -10,
      "name": "Rock_Stone_Brick",
      "rotation": 2
    },
    {
      "x": -4,
      "y": 9,
      "z": -10,
      "name": "Rock_Stone_Brick",
      "rotation": 2
    },
    {
      "x": -4,
      "y": 10,
      "z": -10,
      "name": "Rock_Stone_Brick",
      "rotation": 2
    },
    {
      "x": -4,
      "y": 11,
      "z": -10,
      "name": "Rock_Stone_Brick_Decorative",
      "rotation": 2
    },
    {
      "x": -4,
      "y": 4,
      "z": -9,
      "name": "Rock_Stone_Brick",
      "rotation": 2
    },
    {
      "x": -4,
      "y": 5,
      "z": -9,
      "name": "Rock_Stone_Brick",
      "rotation": 2
    },
    {
      "x": -4,
      "y": 6,
      "z": -9,
      "name": "Rock_Stone_Brick",
      "rotation": 2
    },
    {
      "x": -4,
      "y": 7,
      "z": -9,
      "name": "Rock_Stone_Brick",
      "rotation": 2
    },
    {
      "x": -4,
      "y": 8,
      "z": -9,
      "name": "Rock_Stone_Brick",
      "rotation": 2
    },
    {
      "x": -4,
      "y": 9,
      "z": -9,
      "name": "Rock_Stone_Brick",
      "rotation": 2
    },
    {
      "x": -4,
      "y": 10,
      "z": -9,
      "name": "Rock_Stone_Brick",
      "rotation": 2
    },
    {
      "x": -4,
      "y": 11,
      "z": -9,
      "name": "Rock_Stone_Brick_Decorative",
      "rotation": 2
    },
    {
      "x": -4,
      "y": 4,
      "z": -8,
      "name": "Rock_Stone_Brick",
      "rotation": 2
    },
    {
      "x": -4,
      "y": 5,
      "z": -8,
      "name": "Rock_Stone_Brick",
      "rotation": 2
    },
    {
      "x": -4,
      "y": 6,
      "z": -8,
      "name": "Rock_Stone_Brick",
      "rotation": 2
    },
    {
      "x": -4,
      "y": 7,
      "z": -8,
      "name": "Rock_Stone_Brick",
      "rotation": 2
    },
    {
      "x": -4,
      "y": 8,
      "z": -8,
      "name": "Rock_Stone_Brick",
      "rotation": 2
    },
    {
      "x": -4,
      "y": 9,
      "z": -8,
      "name": "Rock_Stone_Brick",
      "rotation": 2
    },
    {
      "x": -4,
      "y": 10,
      "z": -8,
      "name": "Rock_Stone_Brick",
      "rotation": 2
    },
    {
      "x": -4,
      "y": 11,
      "z": -8,
      "name": "Rock_Stone_Brick_Decorative",
      "rotation": 2
    },
    {
      "x": -4,
      "y": 4,
      "z": -7,
      "name": "Rock_Stone_Brick",
      "rotation": 2
    },
    {
      "x": -4,
      "y": 5,
      "z": -7,
      "name": "Rock_Stone_Brick",
      "rotation": 2
    },
    {
      "x": -4,
      "y": 6,
      "z": -7,
      "name": "Rock_Stone_Brick",
      "rotation": 2
    },
    {
      "x": -4,
      "y": 7,
      "z": -7,
      "name": "Rock_Stone_Brick",
      "rotation": 2
    },
    {
      "x": -4,
      "y": 8,
      "z": -7,
      "name": "Rock_Stone_Brick",
      "rotation": 2
    },
    {
      "x": -4,
      "y": 9,
      "z": -7,
      "name": "Rock_Stone_Brick",
      "rotation": 2
    },
    {
      "x": -4,
      "y": 10,
      "z": -7,
      "name": "Rock_Stone_Brick",
      "rotation": 2
    },
    {
      "x": -4,
      "y": 11,
      "z": -7,
      "name": "Rock_Stone_Brick_Decorative",
      "rotation": 2
    },
    {
      "x": -4,
      "y": 4,
      "z": -6,
      "name": "Rock_Stone_Brick",
      "rotation": 1
    },
    {
      "x": -4,
      "y": 5,
      "z": -6,
      "name": "Rock_Stone_Brick_Decorative"
    },
    {
      "x": -4,
      "y": 6,
      "z": -6,
      "name": "Rock_Stone_Brick",
      "rotation": 1
    },
    {
      "x": -4,
      "y": 7,
      "z": -6,
      "name": "Rock_Stone_Brick",
      "rotation": 1
    },
    {
      "x": -4,
      "y": 8,
      "z": -6,
      "name": "Rock_Stone_Brick",
      "rotation": 1
    },
    {
      "x": -4,
      "y": 9,
      "z": -6,
      "name": "Rock_Stone_Brick",
      "rotation": 1
    },
    {
      "x": -4,
      "y": 10,
      "z": -6,
      "name": "Rock_Stone_Brick"
    },
    {
      "x": -4,
      "y": 11,
      "z": -6,
      "name": "Rock_Stone_Brick",
      "rotation": 2
    },
    {
      "x": -4,
      "y": 4,
      "z": -5,
      "name": "Rock_Stone_Brick_Smooth",
      "rotation": 2
    },
    {
      "x": -4,
      "y": 11,
      "z": -5,
      "name": "Rock_Stone_Brick",
      "rotation": 2
    },
    {
      "x": -4,
      "y": 4,
      "z": -4,
      "name": "Rock_Stone_Brick_Smooth",
      "rotation": 2
    },
    {
      "x": -4,
      "y": 11,
      "z": -4,
      "name": "Rock_Stone_Brick",
      "rotation": 2
    },
    {
      "x": -4,
      "y": 4,
      "z": -3,
      "name": "Rock_Stone_Brick_Smooth",
      "rotation": 2
    },
    {
      "x": -4,
      "y": 5,
      "z": -3,
      "name": "Rock_Stone_Brick",
      "rotation": 2
    },
    {
      "x": -4,
      "y": 6,
      "z": -3,
      "name": "Rock_Stone_Brick",
      "rotation": 2
    },
    {
      "x": -4,
      "y": 7,
      "z": -3,
      "name": "Rock_Stone_Brick",
      "rotation": 2
    },
    {
      "x": -4,
      "y": 8,
      "z": -3,
      "name": "Rock_Stone_Brick",
      "rotation": 2
    },
    {
      "x": -4,
      "y": 9,
      "z": -3,
      "name": "Rock_Stone_Brick",
      "rotation": 2
    },
    {
      "x": -4,
      "y": 10,
      "z": -3,
      "name": "Rock_Stone_Brick",
      "rotation": 2
    },
    {
      "x": -4,
      "y": 11,
      "z": -3,
      "name": "Rock_Stone_Brick",
      "rotation": 2
    },
    {
      "x": -4,
      "y": 4,
      "z": -2,
      "name": "Rock_Stone_Brick_Smooth",
      "rotation": 2
    },
    {
      "x": -4,
      "y": 5,
      "z": -2,
      "name": "Rock_Stone_Brick_Smooth",
      "rotation": 2
    },
    {
      "x": -4,
      "y": 6,
      "z": -2,
      "name": "Rock_Stone_Brick_Pillar_Base",
      "rotation": 2
    },
    {
      "x": -4,
      "y": 7,
      "z": -2,
      "name": "Rock_Stone_Brick_Pillar_Middle",
      "rotation": 2
    },
    {
      "x": -4,
      "y": 8,
      "z": -2,
      "name": "Rock_Stone_Brick_Pillar_Middle",
      "rotation": 2
    },
    {
      "x": -4,
      "y": 9,
      "z": -2,
      "name": "Rock_Stone_Brick_Pillar_Middle",
      "rotation": 2
    },
    {
      "x": -4,
      "y": 10,
      "z": -2,
      "name": "Rock_Stone_Brick_Pillar_Middle",
      "rotation": 10
    },
    {
      "x": -4,
      "y": 11,
      "z": -2,
      "name": "Rock_Stone_Brick_Pillar_Base",
      "rotation": 10
    },
    {
      "x": -4,
      "y": 12,
      "z": -2,
      "name": "Rock_Stone_Brick",
      "rotation": 2
    },
    {
      "x": -4,
      "y": 4,
      "z": -1,
      "name": "Rock_Stone_Brick_Smooth",
      "rotation": 2
    },
    {
      "x": -4,
      "y": 12,
      "z": -1,
      "name": "Rock_Stone_Brick_Stairs",
      "rotation": 11
    },
    {
      "x": -4,
      "y": 4,
      "z": 0,
      "name": "Rock_Stone_Brick_Smooth",
      "rotation": 2
    },
    {
      "x": -4,
      "y": 12,
      "z": 0,
      "name": "Rock_Stone_Brick_Stairs",
      "rotation": 11
    },
    {
      "x": -4,
      "y": 4,
      "z": 1,
      "name": "Rock_Stone_Brick_Smooth",
      "rotation": 2
    },
    {
      "x": -4,
      "y": 12,
      "z": 1,
      "name": "Rock_Stone_Brick_Stairs",
      "rotation": 11
    },
    {
      "x": -4,
      "y": 4,
      "z": 2,
      "name": "Rock_Stone_Brick_Smooth",
      "rotation": 2
    },
    {
      "x": -4,
      "y": 5,
      "z": 2,
      "name": "Rock_Stone_Brick_Smooth",
      "rotation": 2
    },
    {
      "x": -4,
      "y": 6,
      "z": 2,
      "name": "Rock_Stone_Brick_Pillar_Base",
      "rotation": 2
    },
    {
      "x": -4,
      "y": 7,
      "z": 2,
      "name": "Rock_Stone_Brick_Pillar_Middle",
      "rotation": 2
    },
    {
      "x": -4,
      "y": 8,
      "z": 2,
      "name": "Rock_Stone_Brick_Pillar_Middle",
      "rotation": 2
    },
    {
      "x": -4,
      "y": 9,
      "z": 2,
      "name": "Rock_Stone_Brick_Pillar_Middle",
      "rotation": 2
    },
    {
      "x": -4,
      "y": 10,
      "z": 2,
      "name": "Rock_Stone_Brick_Pillar_Middle",
      "rotation": 10
    },
    {
      "x": -4,
      "y": 11,
      "z": 2,
      "name": "Rock_Stone_Brick_Pillar_Base",
      "rotation": 10
    },
    {
      "x": -4,
      "y": 12,
      "z": 2,
      "name": "Rock_Stone_Brick",
      "rotation": 2
    },
    {
      "x": -4,
      "y": 4,
      "z": 3,
      "name": "Rock_Stone_Brick_Smooth",
      "rotation": 2
    },
    {
      "x": -4,
      "y": 5,
      "z": 3,
      "name": "Rock_Stone_Brick_Decorative",
      "rotation": 2
    },
    {
      "x": -4,
      "y": 6,
      "z": 3,
      "name": "Rock_Stone_Brick",
      "rotation": 2
    },
    {
      "x": -4,
      "y": 7,
      "z": 3,
      "name": "Rock_Stone_Brick",
      "rotation": 2
    },
    {
      "x": -4,
      "y": 8,
      "z": 3,
      "name": "Rock_Stone_Brick",
      "rotation": 2
    },
    {
      "x": -4,
      "y": 9,
      "z": 3,
      "name": "Rock_Stone_Brick",
      "rotation": 2
    },
    {
      "x": -4,
      "y": 10,
      "z": 3,
      "name": "Rock_Stone_Brick",
      "rotation": 2
    },
    {
      "x": -4,
      "y": 11,
      "z": 3,
      "name": "Rock_Stone_Brick",
      "rotation": 2
    },
    {
      "x": -3,
      "y": 5,
      "z": -2,
      "name": "Rock_Stone_Brick_Decorative",
      "rotation": 2
    },
    {
      "x": -3,
      "y": 6,
      "z": -2,
      "name": "Rock_Stone_Brick_Decorative",
      "rotation": 2
    },
    {
      "x": -3,
      "y": 7,
      "z": -2,
      "name": "Soil_Gravel_Half",
      "rotation": 4
    },
    {
      "x": -3,
      "y": 8,
      "z": -2,
      "name": "Soil_Gravel_Half",
      "rotation": 4
    },
    {
      "x": -3,
      "y": 9,
      "z": -2,
      "name": "Soil_Gravel_Half",
      "rotation": 4
    },
    {
      "x": -3,
      "y": 10,
      "z": -2,
      "name": "Soil_Gravel_Half",
      "rotation": 4
    },
    {
      "x": -3,
      "y": 11,
      "z": -2,
      "name": "Soil_Gravel_Half",
      "rotation": 4
    },
    {
      "x": -3,
      "y": 12,
      "z": -2,
      "name": "Rock_Stone_Brick",
      "rotation": 2
    },
    {
      "x": -3,
      "y": 4,
      "z": -1,
      "name": "Rock_Stone_Brick_Smooth",
      "rotation": 2
    },
    {
      "x": -3,
      "y": 5,
      "z": -1,
      "name": "Rock_Stone_Brick_Stairs",
      "rotation": 3
    },
    {
      "x": -3,
      "y": 12,
      "z": -1,
      "name": "Rock_Stone_Brick_Smooth_Half",
      "rotation": 10
    },
    {
      "x": -3,
      "y": 4,
      "z": 0,
      "name": "Rock_Stone_Brick_Smooth",
      "rotation": 2
    },
    {
      "x": -3,
      "y": 5,
      "z": 0,
      "name": "Rock_Stone_Brick_Stairs",
      "rotation": 3
    },
    {
      "x": -3,
      "y": 12,
      "z": 0,
      "name": "Rock_Stone_Brick_Smooth_Half",
      "rotation": 10
    },
    {
      "x": -3,
      "y": 4,
      "z": 1,
      "name": "Rock_Stone_Brick_Smooth",
      "rotation": 2
    },
    {
      "x": -3,
      "y": 5,
      "z": 1,
      "name": "Rock_Stone_Brick_Stairs",
      "rotation": 3
    },
    {
      "x": -3,
      "y": 12,
      "z": 1,
      "name": "Rock_Stone_Brick_Smooth_Half",
      "rotation": 10
    },
    {
      "x": -3,
      "y": 5,
      "z": 2,
      "name": "Rock_Stone_Brick_Decorative",
      "rotation": 2
    },
    {
      "x": -3,
      "y": 6,
      "z": 2,
      "name": "Rock_Stone_Brick_Decorative",
      "rotation": 2
    },
    {
      "x": -3,
      "y": 7,
      "z": 2,
      "name": "Soil_Gravel_Half",
      "rotation": 6
    },
    {
      "x": -3,
      "y": 8,
      "z": 2,
      "name": "Soil_Gravel_Half",
      "rotation": 6
    },
    {
      "x": -3,
      "y": 9,
      "z": 2,
      "name": "Soil_Gravel_Half",
      "rotation": 6
    },
    {
      "x": -3,
      "y": 10,
      "z": 2,
      "name": "Soil_Gravel_Half",
      "rotation": 6
    },
    {
      "x": -3,
      "y": 11,
      "z": 2,
      "name": "Soil_Gravel_Half",
      "rotation": 6
    },
    {
      "x": -3,
      "y": 12,
      "z": 2,
      "name": "Rock_Stone_Brick",
      "rotation": 2
    },
    {
      "x": -2,
      "y": 6,
      "z": -2,
      "name": "Rock_Stone_Brick_Decorative",
      "rotation": 2
    },
    {
      "x": -2,
      "y": 7,
      "z": -2,
      "name": "Rock_Stone_Brick_Decorative",
      "rotation": 2
    },
    {
      "x": -2,
      "y": 8,
      "z": -2,
      "name": "Soil_Gravel_Half",
      "rotation": 4
    },
    {
      "x": -2,
      "y": 9,
      "z": -2,
      "name": "Soil_Gravel_Half",
      "rotation": 4
    },
    {
      "x": -2,
      "y": 10,
      "z": -2,
      "name": "Soil_Gravel_Half",
      "rotation": 4
    },
    {
      "x": -2,
      "y": 11,
      "z": -2,
      "name": "Soil_Gravel_Half",
      "rotation": 4
    },
    {
      "x": -2,
      "y": 12,
      "z": -2,
      "name": "Rock_Stone_Brick",
      "rotation": 2
    },
    {
      "x": -2,
      "y": 6,
      "z": -1,
      "name": "Rock_Stone_Brick_Stairs",
      "rotation": 3
    },
    {
      "x": -2,
      "y": 12,
      "z": -1,
      "name": "Rock_Stone_Brick_Smooth_Half",
      "rotation": 10
    },
    {
      "x": -2,
      "y": 6,
      "z": 0,
      "name": "Rock_Stone_Brick_Stairs",
      "rotation": 3
    },
    {
      "x": -2,
      "y": 12,
      "z": 0,
      "name": "Rock_Stone_Brick_Smooth_Half",
      "rotation": 10
    },
    {
      "x": -2,
      "y": 6,
      "z": 1,
      "name": "Rock_Stone_Brick_Stairs",
      "rotation": 3
    },
    {
      "x": -2,
      "y": 12,
      "z": 1,
      "name": "Rock_Stone_Brick_Smooth_Half",
      "rotation": 10
    },
    {
      "x": -2,
      "y": 6,
      "z": 2,
      "name": "Rock_Stone_Brick_Decorative",
      "rotation": 2
    },
    {
      "x": -2,
      "y": 7,
      "z": 2,
      "name": "Rock_Stone_Brick_Decorative",
      "rotation": 2
    },
    {
      "x": -2,
      "y": 8,
      "z": 2,
      "name": "Soil_Gravel_Half",
      "rotation": 6
    },
    {
      "x": -2,
      "y": 9,
      "z": 2,
      "name": "Soil_Gravel_Half",
      "rotation": 6
    },
    {
      "x": -2,
      "y": 10,
      "z": 2,
      "name": "Soil_Gravel_Half",
      "rotation": 6
    },
    {
      "x": -2,
      "y": 11,
      "z": 2,
      "name": "Soil_Gravel_Half",
      "rotation": 6
    },
    {
      "x": -2,
      "y": 12,
      "z": 2,
      "name": "Rock_Stone_Brick",
      "rotation": 2
    },
    {
      "x": -1,
      "y": 7,
      "z": -2,
      "name": "Rock_Stone_Brick_Decorative",
      "rotation": 2
    },
    {
      "x": -1,
      "y": 8,
      "z": -2,
      "name": "Rock_Stone_Brick_Decorative",
      "rotation": 2
    },
    {
      "x": -1,
      "y": 9,
      "z": -2,
      "name": "Soil_Gravel_Half",
      "rotation": 4
    },
    {
      "x": -1,
      "y": 10,
      "z": -2,
      "name": "Soil_Gravel_Half",
      "rotation": 4
    },
    {
      "x": -1,
      "y": 11,
      "z": -2,
      "name": "Soil_Gravel_Half",
      "rotation": 4
    },
    {
      "x": -1,
      "y": 12,
      "z": -2,
      "name": "Rock_Stone_Brick",
      "rotation": 2
    },
    {
      "x": -1,
      "y": 7,
      "z": -1,
      "name": "Rock_Stone_Brick_Stairs",
      "rotation": 3
    },
    {
      "x": -1,
      "y": 12,
      "z": -1,
      "name": "Rock_Stone_Brick_Smooth_Half",
      "rotation": 10
    },
    {
      "x": -1,
      "y": 7,
      "z": 0,
      "name": "Rock_Stone_Brick_Stairs",
      "rotation": 3
    },
    {
      "x": -1,
      "y": 12,
      "z": 0,
      "name": "Rock_Stone_Brick_Smooth_Half",
      "rotation": 10
    },
    {
      "x": -1,
      "y": 7,
      "z": 1,
      "name": "Rock_Stone_Brick_Stairs",
      "rotation": 3
    },
    {
      "x": -1,
      "y": 12,
      "z": 1,
      "name": "Rock_Stone_Brick_Smooth_Half",
      "rotation": 10
    },
    {
      "x": -1,
      "y": 7,
      "z": 2,
      "name": "Rock_Stone_Brick_Decorative",
      "rotation": 2
    },
    {
      "x": -1,
      "y": 8,
      "z": 2,
      "name": "Rock_Stone_Brick_Decorative",
      "rotation": 2
    },
    {
      "x": -1,
      "y": 9,
      "z": 2,
      "name": "Soil_Gravel_Half",
      "rotation": 6
    },
    {
      "x": -1,
      "y": 10,
      "z": 2,
      "name": "Soil_Gravel_Half",
      "rotation": 6
    },
    {
      "x": -1,
      "y": 11,
      "z": 2,
      "name": "Soil_Gravel_Half",
      "rotation": 6
    },
    {
      "x": -1,
      "y": 12,
      "z": 2,
      "name": "Rock_Stone_Brick",
      "rotation": 2
    },
    {
      "x": 0,
      "y": 8,
      "z": -9,
      "name": "Rock_Stone_Brick_Smooth",
      "rotation": 2
    },
    {
      "x": 0,
      "y": 9,
      "z": -9,
      "name": "Rock_Stone_Brick",
      "rotation": 2
    },
    {
      "x": 0,
      "y": 10,
      "z": -9,
      "name": "Rock_Stone_Brick",
      "rotation": 2
    },
    {
      "x": 0,
      "y": 11,
      "z": -9,
      "name": "Rock_Stone_Brick",
      "rotation": 2
    },
    {
      "x": 0,
      "y": 12,
      "z": -9,
      "name": "Rock_Stone_Brick",
      "rotation": 2
    },
    {
      "x": 0,
      "y": 13,
      "z": -9,
      "name": "Rock_Stone_Brick",
      "rotation": 2
    },
    {
      "x": 0,
      "y": 8,
      "z": -6,
      "name": "Rock_Stone_Brick_Smooth",
      "rotation": 2
    },
    {
      "x": 0,
      "y": 9,
      "z": -6,
      "name": "Rock_Stone_Brick_Decorative",
      "rotation": 2
    },
    {
      "x": 0,
      "y": 10,
      "z": -6,
      "name": "Soil_Gravel",
      "rotation": 2
    },
    {
      "x": 0,
      "y": 11,
      "z": -6,
      "name": "Soil_Gravel",
      "rotation": 2
    },
    {
      "x": 0,
      "y": 12,
      "z": -6,
      "name": "Soil_Gravel",
      "rotation": 2
    },
    {
      "x": 0,
      "y": 13,
      "z": -6,
      "name": "Soil_Gravel",
      "rotation": 2
    },
    {
      "x": 0,
      "y": 8,
      "z": -3,
      "name": "Rock_Stone_Brick_Decorative",
      "rotation": 2
    },
    {
      "x": 0,
      "y": 9,
      "z": -3,
      "name": "Rock_Stone_Brick_Decorative",
      "rotation": 2
    },
    {
      "x": 0,
      "y": 10,
      "z": -3,
      "name": "Rock_Stone_Brick",
      "rotation": 2
    },
    {
      "x": 0,
      "y": 11,
      "z": -3,
      "name": "Rock_Stone_Brick",
      "rotation": 2
    },
    {
      "x": 0,
      "y": 12,
      "z": -3,
      "name": "Rock_Stone_Brick",
      "rotation": 2
    },
    {
      "x": 0,
      "y": 13,
      "z": -3,
      "name": "Rock_Stone_Brick",
      "rotation": 2
    },
    {
      "x": 0,
      "y": 14,
      "z": -3,
      "name": "Rock_Stone_Brick",
      "rotation": 2
    },
    {
      "x": 0,
      "y": 8,
      "z": -2,
      "name": "Rock_Stone_Brick_Decorative",
      "rotation": 2
    },
    {
      "x": 0,
      "y": 9,
      "z": -2,
      "name": "Rock_Stone_Brick_Decorative",
      "rotation": 2
    },
    {
      "x": 0,
      "y": 10,
      "z": -2,
      "name": "Rock_Stone_Brick",
      "rotation": 2
    },
    {
      "x": 0,
      "y": 11,
      "z": -2,
      "name": "Rock_Stone_Brick",
      "rotation": 2
    },
    {
      "x": 0,
      "y": 12,
      "z": -2,
      "name": "Rock_Stone_Brick",
      "rotation": 2
    },
    {
      "x": 0,
      "y": 13,
      "z": -2,
      "name": "Rock_Stone_Brick",
      "rotation": 2
    },
    {
      "x": 0,
      "y": 8,
      "z": -1,
      "name": "Rock_Stone_Brick_Stairs",
      "rotation": 3
    },
    {
      "x": 0,
      "y": 9,
      "z": -1,
      "name": "Rock_Stone_Brick_Smooth_Half",
      "rotation": 4
    },
    {
      "x": 0,
      "y": 10,
      "z": -1,
      "name": "Rock_Stone_Brick_Smooth_Half",
      "rotation": 4
    },
    {
      "x": 0,
      "y": 11,
      "z": -1,
      "name": "Rock_Stone_Brick_Smooth_Half",
      "rotation": 4
    },
    {
      "x": 0,
      "y": 12,
      "z": -1,
      "name": "Rock_Stone_Brick_Stairs",
      "rotation": 10
    },
    {
      "x": 0,
      "y": 13,
      "z": -1,
      "name": "Rock_Stone_Brick_Decorative",
      "rotation": 2
    },
    {
      "x": 0,
      "y": 8,
      "z": 0,
      "name": "Rock_Stone_Brick_Stairs",
      "rotation": 3
    },
    {
      "x": 0,
      "y": 12,
      "z": 0,
      "name": "Rock_Stone_Brick_Smooth_Half",
      "rotation": 10
    },
    {
      "x": 0,
      "y": 13,
      "z": 0,
      "name": "Rock_Stone_Brick_Decorative",
      "rotation": 2
    },
    {
      "x": 0,
      "y": 8,
      "z": 1,
      "name": "Rock_Stone_Brick_Stairs",
      "rotation": 3
    },
    {
      "x": 0,
      "y": 9,
      "z": 1,
      "name": "Rock_Stone_Brick_Smooth_Half",
      "rotation": 6
    },
    {
      "x": 0,
      "y": 10,
      "z": 1,
      "name": "Rock_Stone_Brick_Smooth_Half",
      "rotation": 6
    },
    {
      "x": 0,
      "y": 11,
      "z": 1,
      "name": "Rock_Stone_Brick_Smooth_Half",
      "rotation": 6
    },
    {
      "x": 0,
      "y": 12,
      "z": 1,
      "name": "Rock_Stone_Brick_Stairs",
      "rotation": 8
    },
    {
      "x": 0,
      "y": 13,
      "z": 1,
      "name": "Rock_Stone_Brick_Decorative",
      "rotation": 2
    },
    {
      "x": 0,
      "y": 8,
      "z": 2,
      "name": "Rock_Stone_Brick_Decorative",
      "rotation": 2
    },
    {
      "x": 0,
      "y": 9,
      "z": 2,
      "name": "Rock_Stone_Brick_Decorative",
      "rotation": 2
    },
    {
      "x": 0,
      "y": 10,
      "z": 2,
      "name": "Rock_Stone_Brick",
      "rotation": 2
    },
    {
      "x": 0,
      "y": 11,
      "z": 2,
      "name": "Rock_Stone_Brick",
      "rotation": 2
    },
    {
      "x": 0,
      "y": 12,
      "z": 2,
      "name": "Rock_Stone_Brick",
      "rotation": 2
    },
    {
      "x": 0,
      "y": 13,
      "z": 2,
      "name": "Rock_Stone_Brick",
      "rotation": 2
    },
    {
      "x": 0,
      "y": 8,
      "z": 3,
      "name": "Rock_Stone_Brick_Decorative",
      "rotation": 2
    },
    {
      "x": 0,
      "y": 9,
      "z": 3,
      "name": "Rock_Stone_Brick_Decorative",
      "rotation": 2
    },
    {
      "x": 0,
      "y": 10,
      "z": 3,
      "name": "Rock_Stone_Brick",
      "rotation": 2
    },
    {
      "x": 0,
      "y": 11,
      "z": 3,
      "name": "Rock_Stone_Brick",
      "rotation": 2
    },
    {
      "x": 0,
      "y": 12,
      "z": 3,
      "name": "Rock_Stone_Brick",
      "rotation": 2
    },
    {
      "x": 0,
      "y": 13,
      "z": 3,
      "name": "Rock_Stone_Brick",
      "rotation": 2
    },
    {
      "x": 0,
      "y": 8,
      "z": 4,
      "name": "Rock_Stone_Brick_Smooth",
      "rotation": 2
    },
    {
      "x": 0,
      "y": 9,
      "z": 4,
      "name": "Rock_Stone_Brick_Decorative",
      "rotation": 2
    },
    {
      "x": 0,
      "y": 10,
      "z": 4,
      "name": "Rock_Stone_Brick",
      "rotation": 2
    },
    {
      "x": 0,
      "y": 11,
      "z": 4,
      "name": "Rock_Stone_Brick",
      "rotation": 2
    },
    {
      "x": 0,
      "y": 12,
      "z": 4,
      "name": "Rock_Stone_Brick",
      "rotation": 2
    },
    {
      "x": 0,
      "y": 13,
      "z": 4,
      "name": "Rock_Stone_Brick",
      "rotation": 2
    },
    {
      "x": 0,
      "y": 14,
      "z": 4,
      "name": "Rock_Stone_Brick",
      "rotation": 2
    },
    {
      "x": 0,
      "y": 8,
      "z": 5,
      "name": "Rock_Stone_Brick_Smooth",
      "rotation": 2
    },
    {
      "x": 1,
      "y": 8,
      "z": -10,
      "name": "Rock_Stone_Brick_Smooth",
      "rotation": 2
    },
    {
      "x": 1,
      "y": 9,
      "z": -10,
      "name": "Soil_Gravel",
      "rotation": 2
    },
    {
      "x": 1,
      "y": 10,
      "z": -10,
      "name": "Soil_Gravel",
      "rotation": 2
    },
    {
      "x": 1,
      "y": 11,
      "z": -10,
      "name": "Soil_Gravel",
      "rotation": 2
    },
    {
      "x": 1,
      "y": 12,
      "z": -10,
      "name": "Soil_Gravel",
      "rotation": 2
    },
    {
      "x": 1,
      "y": 13,
      "z": -10,
      "name": "Soil_Gravel",
      "rotation": 2
    },
    {
      "x": 1,
      "y": 8,
      "z": -9,
      "name": "Rock_Stone_Brick_Smooth",
      "rotation": 2
    },
    {
      "x": 1,
      "y": 9,
      "z": -9,
      "name": "Rock_Stone_Brick_Smooth",
      "rotation": 2
    },
    {
      "x": 1,
      "y": 10,
      "z": -9,
      "name": "Rock_Stone_Brick_Pillar_Base",
      "rotation": 2
    },
    {
      "x": 1,
      "y": 11,
      "z": -9,
      "name": "Rock_Stone_Brick_Pillar_Middle",
      "rotation": 2
    },
    {
      "x": 1,
      "y": 12,
      "z": -9,
      "name": "Rock_Stone_Brick_Pillar_Middle",
      "rotation": 2
    },
    {
      "x": 1,
      "y": 13,
      "z": -9,
      "name": "Rock_Stone_Brick_Pillar_Base",
      "rotation": 10
    },
    {
      "x": 1,
      "y": 14,
      "z": -9,
      "name": "Rock_Stone_Brick",
      "rotation": 2
    },
    {
      "x": 1,
      "y": 8,
      "z": -8,
      "name": "Rock_Stone_Brick_Smooth",
      "rotation": 2
    },
    {
      "x": 1,
      "y": 9,
      "z": -8,
      "name": "Rock_Stone_Brick_Decorative",
      "rotation": 2
    },
    {
      "x": 1,
      "y": 10,
      "z": -8,
      "name": "Soil_Gravel_Half",
      "rotation": 5
    },
    {
      "x": 1,
      "y": 11,
      "z": -8,
      "name": "Soil_Gravel_Half",
      "rotation": 5
    },
    {
      "x": 1,
      "y": 12,
      "z": -8,
      "name": "Soil_Gravel_Half",
      "rotation": 5
    },
    {
      "x": 1,
      "y": 13,
      "z": -8,
      "name": "Soil_Gravel_Half",
      "rotation": 5
    },
    {
      "x": 1,
      "y": 14,
      "z": -8,
      "name": "Rock_Stone_Brick",
      "rotation": 2
    },
    {
      "x": 1,
      "y": 8,
      "z": -7,
      "name": "Rock_Stone_Brick_Smooth",
      "rotation": 2
    },
    {
      "x": 1,
      "y": 9,
      "z": -7,
      "name": "Rock_Stone_Brick_Decorative",
      "rotation": 2
    },
    {
      "x": 1,
      "y": 10,
      "z": -7,
      "name": "Soil_Gravel_Half",
      "rotation": 5
    },
    {
      "x": 1,
      "y": 11,
      "z": -7,
      "name": "Soil_Gravel_Half",
      "rotation": 5
    },
    {
      "x": 1,
      "y": 12,
      "z": -7,
      "name": "Soil_Gravel_Half",
      "rotation": 5
    },
    {
      "x": 1,
      "y": 13,
      "z": -7,
      "name": "Soil_Gravel_Half",
      "rotation": 5
    },
    {
      "x": 1,
      "y": 14,
      "z": -7,
      "name": "Rock_Stone_Brick",
      "rotation": 2
    },
    {
      "x": 1,
      "y": 8,
      "z": -6,
      "name": "Rock_Stone_Brick_Smooth",
      "rotation": 2
    },
    {
      "x": 1,
      "y": 9,
      "z": -6,
      "name": "Rock_Stone_Brick_Smooth",
      "rotation": 2
    },
    {
      "x": 1,
      "y": 10,
      "z": -6,
      "name": "Rock_Stone_Brick_Pillar_Base",
      "rotation": 2
    },
    {
      "x": 1,
      "y": 11,
      "z": -6,
      "name": "Rock_Stone_Brick_Pillar_Middle",
      "rotation": 2
    },
    {
      "x": 1,
      "y": 12,
      "z": -6,
      "name": "Rock_Stone_Brick_Pillar_Middle",
      "rotation": 2
    },
    {
      "x": 1,
      "y": 13,
      "z": -6,
      "name": "Rock_Stone_Brick_Pillar_Base",
      "rotation": 10
    },
    {
      "x": 1,
      "y": 14,
      "z": -6,
      "name": "Rock_Stone_Brick",
      "rotation": 2
    },
    {
      "x": 1,
      "y": 8,
      "z": -5,
      "name": "Rock_Stone_Brick_Smooth",
      "rotation": 2
    },
    {
      "x": 1,
      "y": 9,
      "z": -5,
      "name": "Rock_Stone_Brick_Decorative",
      "rotation": 2
    },
    {
      "x": 1,
      "y": 10,
      "z": -5,
      "name": "Soil_Gravel_Half",
      "rotation": 5
    },
    {
      "x": 1,
      "y": 11,
      "z": -5,
      "name": "Soil_Gravel_Half",
      "rotation": 5
    },
    {
      "x": 1,
      "y": 12,
      "z": -5,
      "name": "Soil_Gravel_Half",
      "rotation": 5
    },
    {
      "x": 1,
      "y": 13,
      "z": -5,
      "name": "Soil_Gravel_Half",
      "rotation": 5
    },
    {
      "x": 1,
      "y": 14,
      "z": -5,
      "name": "Rock_Stone_Brick",
      "rotation": 2
    },
    {
      "x": 1,
      "y": 8,
      "z": -4,
      "name": "Rock_Stone_Brick_Smooth",
      "rotation": 2
    },
    {
      "x": 1,
      "y": 9,
      "z": -4,
      "name": "Rock_Stone_Brick_Decorative",
      "rotation": 2
    },
    {
      "x": 1,
      "y": 10,
      "z": -4,
      "name": "Soil_Gravel_Half",
      "rotation": 5
    },
    {
      "x": 1,
      "y": 11,
      "z": -4,
      "name": "Soil_Gravel_Half",
      "rotation": 5
    },
    {
      "x": 1,
      "y": 12,
      "z": -4,
      "name": "Soil_Gravel_Half",
      "rotation": 5
    },
    {
      "x": 1,
      "y": 13,
      "z": -4,
      "name": "Soil_Gravel_Half",
      "rotation": 5
    },
    {
      "x": 1,
      "y": 14,
      "z": -4,
      "name": "Rock_Stone_Brick",
      "rotation": 2
    },
    {
      "x": 1,
      "y": 8,
      "z": -3,
      "name": "Rock_Stone_Brick_Smooth",
      "rotation": 2
    },
    {
      "x": 1,
      "y": 9,
      "z": -3,
      "name": "Rock_Stone_Brick_Smooth",
      "rotation": 2
    },
    {
      "x": 1,
      "y": 10,
      "z": -3,
      "name": "Rock_Stone_Brick_Pillar_Base",
      "rotation": 2
    },
    {
      "x": 1,
      "y": 11,
      "z": -3,
      "name": "Rock_Stone_Brick_Pillar_Middle",
      "rotation": 2
    },
    {
      "x": 1,
      "y": 12,
      "z": -3,
      "name": "Rock_Stone_Brick_Pillar_Middle",
      "rotation": 2
    },
    {
      "x": 1,
      "y": 13,
      "z": -3,
      "name": "Rock_Stone_Brick_Pillar_Base",
      "rotation": 10
    },
    {
      "x": 1,
      "y": 14,
      "z": -3,
      "name": "Rock_Stone_Brick",
      "rotation": 2
    },
    {
      "x": 1,
      "y": 8,
      "z": -2,
      "name": "Rock_Stone_Brick_Smooth",
      "rotation": 2
    },
    {
      "x": 1,
      "y": 14,
      "z": -2,
      "name": "Rock_Stone_Brick_Smooth",
      "rotation": 2
    },
    {
      "x": 1,
      "y": 8,
      "z": -1,
      "name": "Rock_Stone_Brick_Smooth",
      "rotation": 2
    },
    {
      "x": 1,
      "y": 14,
      "z": -1,
      "name": "Rock_Stone_Brick_Smooth",
      "rotation": 2
    },
    {
      "x": 1,
      "y": 8,
      "z": 0,
      "name": "Rock_Stone_Brick_Smooth",
      "rotation": 2
    },
    {
      "x": 1,
      "y": 14,
      "z": 0,
      "name": "Rock_Stone_Brick_Smooth",
      "rotation": 2
    },
    {
      "x": 1,
      "y": 8,
      "z": 1,
      "name": "Rock_Stone_Brick_Smooth",
      "rotation": 2
    },
    {
      "x": 1,
      "y": 14,
      "z": 1,
      "name": "Rock_Stone_Brick_Smooth",
      "rotation": 2
    },
    {
      "x": 1,
      "y": 8,
      "z": 2,
      "name": "Rock_Stone_Brick_Smooth",
      "rotation": 2
    },
    {
      "x": 1,
      "y": 14,
      "z": 2,
      "name": "Rock_Stone_Brick_Smooth",
      "rotation": 2
    },
    {
      "x": 1,
      "y": 8,
      "z": 3,
      "name": "Rock_Stone_Brick_Smooth",
      "rotation": 2
    },
    {
      "x": 1,
      "y": 9,
      "z": 3,
      "name": "Rock_Stone_Brick_Smooth",
      "rotation": 2
    },
    {
      "x": 1,
      "y": 10,
      "z": 3,
      "name": "Rock_Stone_Brick_Pillar_Base",
      "rotation": 2
    },
    {
      "x": 1,
      "y": 11,
      "z": 3,
      "name": "Rock_Stone_Brick_Pillar_Middle",
      "rotation": 2
    },
    {
      "x": 1,
      "y": 12,
      "z": 3,
      "name": "Rock_Stone_Brick_Pillar_Middle",
      "rotation": 2
    },
    {
      "x": 1,
      "y": 13,
      "z": 3,
      "name": "Rock_Stone_Brick_Pillar_Base",
      "rotation": 10
    },
    {
      "x": 1,
      "y": 14,
      "z": 3,
      "name": "Rock_Stone_Brick_Smooth",
      "rotation": 2
    },
    {
      "x": 1,
      "y": 8,
      "z": 4,
      "name": "Rock_Stone_Brick_Smooth",
      "rotation": 2
    },
    {
      "x": 1,
      "y": 9,
      "z": 4,
      "name": "Rock_Stone_Brick_Decorative",
      "rotation": 2
    },
    {
      "x": 1,
      "y": 10,
      "z": 4,
      "name": "Rock_Stone_Brick",
      "rotation": 2
    },
    {
      "x": 1,
      "y": 11,
      "z": 4,
      "name": "Rock_Stone_Brick",
      "rotation": 2
    },
    {
      "x": 1,
      "y": 12,
      "z": 4,
      "name": "Rock_Stone_Brick",
      "rotation": 2
    },
    {
      "x": 1,
      "y": 13,
      "z": 4,
      "name": "Rock_Stone_Brick",
      "rotation": 2
    },
    {
      "x": 1,
      "y": 14,
      "z": 4,
      "name": "Rock_Stone_Brick",
      "rotation": 2
    },
    {
      "x": 1,
      "y": 8,
      "z": 5,
      "name": "Rock_Stone_Brick_Smooth",
      "rotation": 2
    },
    {
      "x": 2,
      "y": 9,
      "z": -15,
      "name": "Rock_Stone_Brick_Smooth",
      "rotation": 2
    },
    {
      "x": 2,
      "y": 10,
      "z": -15,
      "name": "Rock_Stone_Brick_Decorative",
      "rotation": 2
    },
    {
      "x": 2,
      "y": 11,
      "z": -15,
      "name": "Rock_Stone_Brick",
      "rotation": 2
    },
    {
      "x": 2,
      "y": 12,
      "z": -15,
      "name": "Rock_Stone_Brick",
      "rotation": 2
    },
    {
      "x": 2,
      "y": 13,
      "z": -15,
      "name": "Rock_Stone_Brick",
      "rotation": 2
    },
    {
      "x": 2,
      "y": 14,
      "z": -15,
      "name": "Rock_Stone_Brick",
      "rotation": 2
    },
    {
      "x": 2,
      "y": 15,
      "z": -15,
      "name": "Rock_Stone_Brick",
      "rotation": 2
    },
    {
      "x": 2,
      "y": 16,
      "z": -15,
      "name": "Rock_Stone_Brick_Smooth",
      "rotation": 2
    },
    {
      "x": 2,
      "y": 10,
      "z": -14,
      "name": "Rock_Stone_Brick_Decorative",
      "rotation": 2
    },
    {
      "x": 2,
      "y": 11,
      "z": -14,
      "name": "Soil_Gravel_Half",
      "rotation": 5
    },
    {
      "x": 2,
      "y": 12,
      "z": -14,
      "name": "Soil_Gravel_Half",
      "rotation": 5
    },
    {
      "x": 2,
      "y": 13,
      "z": -14,
      "name": "Soil_Gravel_Half",
      "rotation": 5
    },
    {
      "x": 2,
      "y": 14,
      "z": -14,
      "name": "Soil_Gravel_Half",
      "rotation": 5
    },
    {
      "x": 2,
      "y": 15,
      "z": -14,
      "name": "Rock_Stone_Brick",
      "rotation": 2
    },
    {
      "x": 2,
      "y": 9,
      "z": -13,
      "name": "Rock_Stone_Brick_Smooth",
      "rotation": 2
    },
    {
      "x": 2,
      "y": 10,
      "z": -13,
      "name": "Rock_Stone_Brick_Decorative",
      "rotation": 2
    },
    {
      "x": 2,
      "y": 11,
      "z": -13,
      "name": "Soil_Gravel_Half",
      "rotation": 5
    },
    {
      "x": 2,
      "y": 12,
      "z": -13,
      "name": "Soil_Gravel_Half",
      "rotation": 5
    },
    {
      "x": 2,
      "y": 13,
      "z": -13,
      "name": "Soil_Gravel_Half",
      "rotation": 5
    },
    {
      "x": 2,
      "y": 14,
      "z": -13,
      "name": "Soil_Gravel_Half",
      "rotation": 5
    },
    {
      "x": 2,
      "y": 15,
      "z": -13,
      "name": "Rock_Stone_Brick_Decorative",
      "rotation": 2
    },
    {
      "x": 2,
      "y": 16,
      "z": -13,
      "name": "Rock_Stone_Brick",
      "rotation": 2
    },
    {
      "x": 2,
      "y": 9,
      "z": -12,
      "name": "Rock_Stone_Brick_Smooth",
      "rotation": 2
    },
    {
      "x": 2,
      "y": 10,
      "z": -12,
      "name": "Rock_Stone_Brick_Decorative",
      "rotation": 2
    },
    {
      "x": 2,
      "y": 11,
      "z": -12,
      "name": "Soil_Gravel_Half",
      "rotation": 5
    },
    {
      "x": 2,
      "y": 12,
      "z": -12,
      "name": "Soil_Gravel_Half",
      "rotation": 5
    },
    {
      "x": 2,
      "y": 13,
      "z": -12,
      "name": "Soil_Gravel_Half",
      "rotation": 5
    },
    {
      "x": 2,
      "y": 14,
      "z": -12,
      "name": "Soil_Gravel_Half",
      "rotation": 5
    },
    {
      "x": 2,
      "y": 15,
      "z": -12,
      "name": "Rock_Stone_Brick_Decorative",
      "rotation": 2
    },
    {
      "x": 2,
      "y": 16,
      "z": -12,
      "name": "Rock_Stone_Brick",
      "rotation": 2
    },
    {
      "x": 2,
      "y": 9,
      "z": -11,
      "name": "Rock_Stone_Brick_Smooth",
      "rotation": 2
    },
    {
      "x": 2,
      "y": 10,
      "z": -11,
      "name": "Rock_Stone_Brick_Decorative",
      "rotation": 2
    },
    {
      "x": 2,
      "y": 11,
      "z": -11,
      "name": "Soil_Gravel_Half",
      "rotation": 5
    },
    {
      "x": 2,
      "y": 12,
      "z": -11,
      "name": "Soil_Gravel_Half",
      "rotation": 5
    },
    {
      "x": 2,
      "y": 13,
      "z": -11,
      "name": "Soil_Gravel_Half",
      "rotation": 5
    },
    {
      "x": 2,
      "y": 14,
      "z": -11,
      "name": "Soil_Gravel_Half",
      "rotation": 5
    },
    {
      "x": 2,
      "y": 15,
      "z": -11,
      "name": "Rock_Stone_Brick",
      "rotation": 2
    },
    {
      "x": 2,
      "y": 8,
      "z": -10,
      "name": "Rock_Stone_Brick_Smooth",
      "rotation": 2
    },
    {
      "x": 2,
      "y": 9,
      "z": -10,
      "name": "Rock_Stone_Brick_Smooth",
      "rotation": 2
    },
    {
      "x": 2,
      "y": 10,
      "z": -10,
      "name": "Rock_Stone_Brick_Decorative",
      "rotation": 2
    },
    {
      "x": 2,
      "y": 11,
      "z": -10,
      "name": "Rock_Stone_Brick",
      "rotation": 2
    },
    {
      "x": 2,
      "y": 12,
      "z": -10,
      "name": "Rock_Stone_Brick",
      "rotation": 2
    },
    {
      "x": 2,
      "y": 13,
      "z": -10,
      "name": "Rock_Stone_Brick",
      "rotation": 2
    },
    {
      "x": 2,
      "y": 14,
      "z": -10,
      "name": "Rock_Stone_Brick",
      "rotation": 2
    },
    {
      "x": 2,
      "y": 15,
      "z": -10,
      "name": "Rock_Stone_Brick",
      "rotation": 2
    },
    {
      "x": 2,
      "y": 8,
      "z": -9,
      "name": "Rock_Stone_Brick_Smooth",
      "rotation": 2
    },
    {
      "x": 2,
      "y": 9,
      "z": -9,
      "name": "Furniture_Temple_Dark_Candle",
      "rotation": 2
    },
    {
      "x": 2,
      "y": 10,
      "z": -9,
      "name": "Furniture_Temple_Dark_Candle",
      "filler": 1024,
      "rotation": 2
    },
    {
      "x": 2,
      "y": 14,
      "z": -9,
      "name": "Rock_Stone_Brick_Smooth_Half",
      "rotation": 10
    },
    {
      "x": 2,
      "y": 8,
      "z": -8,
      "name": "Rock_Stone_Brick_Smooth",
      "rotation": 2
    },
    {
      "x": 2,
      "y": 14,
      "z": -8,
      "name": "Rock_Stone_Brick_Smooth_Half",
      "rotation": 10
    },
    {
      "x": 2,
      "y": 8,
      "z": -7,
      "name": "Rock_Stone_Brick_Smooth",
      "rotation": 2
    },
    {
      "x": 2,
      "y": 14,
      "z": -7,
      "name": "Rock_Stone_Brick_Smooth_Half",
      "rotation": 10
    },
    {
      "x": 2,
      "y": 8,
      "z": -6,
      "name": "Rock_Stone_Brick_Smooth",
      "rotation": 2
    },
    {
      "x": 2,
      "y": 14,
      "z": -6,
      "name": "Rock_Stone_Brick_Smooth_Half",
      "rotation": 10
    },
    {
      "x": 2,
      "y": 8,
      "z": -5,
      "name": "Rock_Stone_Brick_Smooth",
      "rotation": 2
    },
    {
      "x": 2,
      "y": 14,
      "z": -5,
      "name": "Rock_Stone_Brick_Smooth_Half",
      "rotation": 10
    },
    {
      "x": 2,
      "y": 8,
      "z": -4,
      "name": "Rock_Stone_Brick_Smooth",
      "rotation": 2
    },
    {
      "x": 2,
      "y": 14,
      "z": -4,
      "name": "Rock_Stone_Brick_Smooth_Half",
      "rotation": 10
    },
    {
      "x": 2,
      "y": 8,
      "z": -3,
      "name": "Rock_Stone_Brick_Smooth",
      "rotation": 2
    },
    {
      "x": 2,
      "y": 14,
      "z": -3,
      "name": "Rock_Stone_Brick",
      "rotation": 2
    },
    {
      "x": 2,
      "y": 8,
      "z": -2,
      "name": "Rock_Stone_Brick_Smooth",
      "rotation": 2
    },
    {
      "x": 2,
      "y": 14,
      "z": -2,
      "name": "Rock_Stone_Brick_Smooth",
      "rotation": 2
    },
    {
      "x": 2,
      "y": 8,
      "z": -1,
      "name": "Rock_Stone_Brick_Smooth",
      "rotation": 2
    },
    {
      "x": 2,
      "y": 14,
      "z": -1,
      "name": "Rock_Stone_Brick_Smooth",
      "rotation": 2
    },
    {
      "x": 2,
      "y": 8,
      "z": 0,
      "name": "Rock_Stone_Brick_Smooth",
      "rotation": 2
    },
    {
      "x": 2,
      "y": 14,
      "z": 0,
      "name": "Rock_Stone_Brick_Smooth",
      "rotation": 2
    },
    {
      "x": 2,
      "y": 8,
      "z": 1,
      "name": "Rock_Stone_Brick_Smooth",
      "rotation": 2
    },
    {
      "x": 2,
      "y": 14,
      "z": 1,
      "name": "Rock_Stone_Brick_Smooth",
      "rotation": 2
    },
    {
      "x": 2,
      "y": 8,
      "z": 2,
      "name": "Rock_Stone_Brick_Smooth",
      "rotation": 2
    },
    {
      "x": 2,
      "y": 14,
      "z": 2,
      "name": "Rock_Stone_Brick_Smooth",
      "rotation": 2
    },
    {
      "x": 2,
      "y": 8,
      "z": 3,
      "name": "Rock_Stone_Brick_Smooth",
      "rotation": 2
    },
    {
      "x": 2,
      "y": 9,
      "z": 3,
      "name": "Furniture_Temple_Dark_Candle",
      "rotation": 2
    },
    {
      "x": 2,
      "y": 10,
      "z": 3,
      "name": "Furniture_Temple_Dark_Candle",
      "filler": 1024,
      "rotation": 2
    },
    {
      "x": 2,
      "y": 14,
      "z": 3,
      "name": "Rock_Stone_Brick_Smooth",
      "rotation": 2
    },
    {
      "x": 2,
      "y": 8,
      "z": 4,
      "name": "Rock_Stone_Brick_Smooth",
      "rotation": 2
    },
    {
      "x": 2,
      "y": 9,
      "z": 4,
      "name": "Rock_Stone_Brick_Decorative",
      "rotation": 2
    },
    {
      "x": 2,
      "y": 10,
      "z": 4,
      "name": "Soil_Gravel_Half",
      "rotation": 6
    },
    {
      "x": 2,
      "y": 11,
      "z": 4,
      "name": "Soil_Gravel_Half",
      "rotation": 6
    },
    {
      "x": 2,
      "y": 12,
      "z": 4,
      "name": "Soil_Gravel_Half",
      "rotation": 6
    },
    {
      "x": 2,
      "y": 13,
      "z": 4,
      "name": "Soil_Gravel_Half",
      "rotation": 6
    },
    {
      "x": 2,
      "y": 14,
      "z": 4,
      "name": "Rock_Stone_Brick",
      "rotation": 2
    },
    {
      "x": 2,
      "y": 8,
      "z": 5,
      "name": "Rock_Stone_Brick_Smooth",
      "rotation": 2
    },
    {
      "x": 2,
      "y": 8,
      "z": 9,
      "name": "Rock_Stone_Brick_Smooth",
      "rotation": 2
    },
    {
      "x": 2,
      "y": 9,
      "z": 9,
      "name": "Rock_Stone_Brick_Decorative"
    },
    {
      "x": 2,
      "y": 10,
      "z": 9,
      "name": "Soil_Gravel",
      "rotation": 3
    },
    {
      "x": 2,
      "y": 11,
      "z": 9,
      "name": "Soil_Gravel",
      "rotation": 3
    },
    {
      "x": 2,
      "y": 12,
      "z": 9,
      "name": "Soil_Gravel",
      "rotation": 3
    },
    {
      "x": 2,
      "y": 13,
      "z": 9,
      "name": "Soil_Gravel",
      "rotation": 3
    },
    {
      "x": 2,
      "y": 14,
      "z": 9,
      "name": "Rock_Stone_Brick_Smooth"
    },
    {
      "x": 2,
      "y": 8,
      "z": 10,
      "name": "Rock_Stone_Brick_Smooth",
      "rotation": 2
    },
    {
      "x": 2,
      "y": 11,
      "z": 10,
      "name": "Rock_Stone_Brick",
      "rotation": 3
    },
    {
      "x": 2,
      "y": 12,
      "z": 10,
      "name": "Rock_Stone_Brick_Decorative",
      "rotation": 3
    },
    {
      "x": 2,
      "y": 13,
      "z": 10,
      "name": "Soil_Gravel",
      "rotation": 3
    },
    {
      "x": 2,
      "y": 14,
      "z": 10,
      "name": "Soil_Gravel",
      "rotation": 3
    },
    {
      "x": 2,
      "y": 15,
      "z": 10,
      "name": "Soil_Gravel",
      "rotation": 3
    },
    {
      "x": 2,
      "y": 16,
      "z": 10,
      "name": "Soil_Gravel",
      "rotation": 3
    },
    {
      "x": 2,
      "y": 17,
      "z": 10,
      "name": "Rock_Stone_Brick_Smooth"
    },
    {
      "x": 2,
      "y": 11,
      "z": 11,
      "name": "Rock_Stone_Brick",
      "rotation": 3
    },
    {
      "x": 2,
      "y": 12,
      "z": 11,
      "name": "Rock_Stone_Brick_Decorative",
      "rotation": 3
    },
    {
      "x": 2,
      "y": 13,
      "z": 11,
      "name": "Soil_Gravel",
      "rotation": 3
    },
    {
      "x": 2,
      "y": 14,
      "z": 11,
      "name": "Soil_Gravel",
      "rotation": 3
    },
    {
      "x": 2,
      "y": 15,
      "z": 11,
      "name": "Soil_Gravel",
      "rotation": 3
    },
    {
      "x": 2,
      "y": 16,
      "z": 11,
      "name": "Soil_Gravel",
      "rotation": 3
    },
    {
      "x": 2,
      "y": 17,
      "z": 11,
      "name": "Rock_Stone_Brick_Smooth"
    },
    {
      "x": 2,
      "y": 11,
      "z": 12,
      "name": "Rock_Stone_Brick",
      "rotation": 3
    },
    {
      "x": 2,
      "y": 12,
      "z": 12,
      "name": "Rock_Stone_Brick_Decorative",
      "rotation": 3
    },
    {
      "x": 2,
      "y": 13,
      "z": 12,
      "name": "Soil_Gravel",
      "rotation": 3
    },
    {
      "x": 2,
      "y": 14,
      "z": 12,
      "name": "Soil_Gravel",
      "rotation": 3
    },
    {
      "x": 2,
      "y": 15,
      "z": 12,
      "name": "Soil_Gravel",
      "rotation": 3
    },
    {
      "x": 2,
      "y": 16,
      "z": 12,
      "name": "Soil_Gravel",
      "rotation": 3
    },
    {
      "x": 2,
      "y": 17,
      "z": 12,
      "name": "Rock_Stone_Brick_Smooth",
      "rotation": 2
    },
    {
      "x": 2,
      "y": 11,
      "z": 13,
      "name": "Rock_Stone_Brick",
      "rotation": 3
    },
    {
      "x": 2,
      "y": 12,
      "z": 13,
      "name": "Rock_Stone_Brick_Decorative",
      "rotation": 3
    },
    {
      "x": 2,
      "y": 13,
      "z": 13,
      "name": "Soil_Gravel",
      "rotation": 3
    },
    {
      "x": 2,
      "y": 14,
      "z": 13,
      "name": "Soil_Gravel",
      "rotation": 3
    },
    {
      "x": 2,
      "y": 15,
      "z": 13,
      "name": "Soil_Gravel",
      "rotation": 3
    },
    {
      "x": 2,
      "y": 16,
      "z": 13,
      "name": "Soil_Gravel",
      "rotation": 3
    },
    {
      "x": 2,
      "y": 17,
      "z": 13,
      "name": "Rock_Stone_Brick_Smooth",
      "rotation": 2
    },
    {
      "x": 2,
      "y": 11,
      "z": 14,
      "name": "Rock_Stone_Brick",
      "rotation": 3
    },
    {
      "x": 2,
      "y": 12,
      "z": 14,
      "name": "Rock_Stone_Brick_Decorative",
      "rotation": 1
    },
    {
      "x": 2,
      "y": 13,
      "z": 14,
      "name": "Soil_Gravel",
      "rotation": 1
    },
    {
      "x": 2,
      "y": 14,
      "z": 14,
      "name": "Soil_Gravel",
      "rotation": 1
    },
    {
      "x": 2,
      "y": 15,
      "z": 14,
      "name": "Soil_Gravel",
      "rotation": 1
    },
    {
      "x": 2,
      "y": 16,
      "z": 14,
      "name": "Soil_Gravel",
      "rotation": 1
    },
    {
      "x": 2,
      "y": 17,
      "z": 14,
      "name": "Rock_Stone_Brick_Smooth",
      "rotation": 1
    },
    {
      "x": 2,
      "y": 11,
      "z": 15,
      "name": "Rock_Stone_Brick",
      "rotation": 3
    },
    {
      "x": 2,
      "y": 12,
      "z": 15,
      "name": "Rock_Stone_Brick_Decorative",
      "rotation": 2
    },
    {
      "x": 2,
      "y": 13,
      "z": 15,
      "name": "Soil_Gravel",
      "rotation": 2
    },
    {
      "x": 2,
      "y": 14,
      "z": 15,
