{
  "version": 8,
  "blockIdVersion": 11,
  "anchorX": 1,
  "anchorY": 20,
  "anchorZ": 0,
  "blocks": [
    {
      "x": -10,
      "y": 14,
      "z": -13,
      "name": "Rock_Stone_Brick_Decorative"
    },
    {
      "x": -10,
      "y": 15,
      "z": -13,
      "name": "Soil_Gravel",
      "support": 15
    },
    {
      "x": -10,
      "y": 16,
      "z": -13,
      "name": "Soil_Gravel",
      "support": 15
    },
    {
      "x": -10,
      "y": 17,
      "z": -13,
      "name": "Soil_Gravel",
      "support": 15
    },
    {
      "x": -10,
      "y": 18,
      "z": -13,
      "name": "Soil_Gravel",
      "support": 15
    },
    {
      "x": -10,
      "y": 14,
      "z": -9,
      "name": "Rock_Stone_Brick_Decorative"
    },
    {
      "x": -10,
      "y": 15,
      "z": -9,
      "name": "Soil_Gravel",
      "support": 15
    },
    {
      "x": -10,
      "y": 16,
      "z": -9,
      "name": "Soil_Gravel",
      "support": 15
    },
    {
      "x": -10,
      "y": 17,
      "z": -9,
      "name": "Soil_Gravel",
      "support": 15
    },
    {
      "x": -10,
      "y": 18,
      "z": -9,
      "name": "Soil_Gravel",
      "support": 15
    },
    {
      "x": -10,
      "y": 14,
      "z": -6,
      "name": "Rock_Stone_Brick_Decorative"
    },
    {
      "x": -10,
      "y": 15,
      "z": -6,
      "name": "Soil_Gravel",
      "support": 15
    },
    {
      "x": -10,
      "y": 16,
      "z": -6,
      "name": "Soil_Gravel",
      "support": 15
    },
    {
      "x": -10,
      "y": 17,
      "z": -6,
      "name": "Soil_Gravel",
      "support": 15
    },
    {
      "x": -10,
      "y": 18,
      "z": -6,
      "name": "Soil_Gravel",
      "support": 15
    },
    {
      "x": -10,
      "y": 14,
      "z": -2,
      "name": "Rock_Stone_Brick_Decorative"
    },
    {
      "x": -10,
      "y": 15,
      "z": -2,
      "name": "Soil_Gravel",
      "support": 15
    },
    {
      "x": -10,
      "y": 16,
      "z": -2,
      "name": "Soil_Gravel",
      "support": 15
    },
    {
      "x": -10,
      "y": 17,
      "z": -2,
      "name": "Soil_Gravel",
      "support": 15
    },
    {
      "x": -10,
      "y": 18,
      "z": -2,
      "name": "Soil_Gravel",
      "support": 15
    },
    {
      "x": -10,
      "y": 14,
      "z": 2,
      "name": "Rock_Stone_Brick_Decorative"
    },
    {
      "x": -10,
      "y": 15,
      "z": 2,
      "name": "Soil_Gravel",
      "support": 15
    },
    {
      "x": -10,
      "y": 16,
      "z": 2,
      "name": "Soil_Gravel",
      "support": 15
    },
    {
      "x": -10,
      "y": 17,
      "z": 2,
      "name": "Soil_Gravel",
      "support": 15
    },
    {
      "x": -10,
      "y": 18,
      "z": 2,
      "name": "Soil_Gravel",
      "support": 15
    },
    {
      "x": -10,
      "y": 14,
      "z": 6,
      "name": "Rock_Stone_Brick_Decorative"
    },
    {
      "x": -10,
      "y": 15,
      "z": 6,
      "name": "Soil_Gravel",
      "support": 15
    },
    {
      "x": -10,
      "y": 16,
      "z": 6,
      "name": "Soil_Gravel",
      "support": 15
    },
    {
      "x": -10,
      "y": 17,
      "z": 6,
      "name": "Soil_Gravel",
      "support": 15
    },
    {
      "x": -10,
      "y": 18,
      "z": 6,
      "name": "Soil_Gravel",
      "support": 15
    },
    {
      "x": -10,
      "y": 14,
      "z": 9,
      "name": "Rock_Stone_Brick_Decorative"
    },
    {
      "x": -10,
      "y": 15,
      "z": 9,
      "name": "Soil_Gravel",
      "support": 15
    },
    {
      "x": -10,
      "y": 16,
      "z": 9,
      "name": "Soil_Gravel",
      "support": 15
    },
    {
      "x": -10,
      "y": 17,
      "z": 9,
      "name": "Soil_Gravel",
      "support": 15
    },
    {
      "x": -10,
      "y": 18,
      "z": 9,
      "name": "Soil_Gravel",
      "support": 15
    },
    {
      "x": -10,
      "y": 14,
      "z": 13,
      "name": "Rock_Stone_Brick_Decorative"
    },
    {
      "x": -10,
      "y": 15,
      "z": 13,
      "name": "Soil_Gravel",
      "support": 15
    },
    {
      "x": -10,
      "y": 16,
      "z": 13,
      "name": "Soil_Gravel",
      "support": 15
    },
    {
      "x": -10,
      "y": 17,
      "z": 13,
      "name": "Soil_Gravel",
      "support": 15
    },
    {
      "x": -10,
      "y": 18,
      "z": 13,
      "name": "Soil_Gravel",
      "support": 15
    },
    {
      "x": -9,
      "y": 13,
      "z": -16,
      "name": "Rock_Stone_Brick_Smooth"
    },
    {
      "x": -9,
      "y": 14,
      "z": -16,
      "name": "Rock_Stone_Brick"
    },
    {
      "x": -9,
      "y": 15,
      "z": -16,
      "name": "Rock_Stone_Brick"
    },
    {
      "x": -9,
      "y": 16,
      "z": -16,
      "name": "Rock_Stone_Brick"
    },
    {
      "x": -9,
      "y": 17,
      "z": -16,
      "name": "Rock_Stone_Brick"
    },
    {
      "x": -9,
      "y": 18,
      "z": -16,
      "name": "Rock_Stone_Brick"
    },
    {
      "x": -9,
      "y": 19,
      "z": -16,
      "name": "Rock_Stone_Brick_Smooth"
    },
    {
      "x": -9,
      "y": 13,
      "z": -15,
      "name": "Rock_Stone_Brick_Smooth"
    },
    {
      "x": -9,
      "y": 14,
      "z": -15,
      "name": "Rock_Stone_Brick_Decorative"
    },
    {
      "x": -9,
      "y": 15,
      "z": -15,
      "name": "Soil_Gravel_Half",
      "rotation": 5
    },
    {
      "x": -9,
      "y": 16,
      "z": -15,
      "name": "Soil_Gravel_Half",
      "rotation": 5
    },
    {
      "x": -9,
      "y": 17,
      "z": -15,
      "name": "Soil_Gravel_Half",
      "rotation": 5
    },
    {
      "x": -9,
      "y": 18,
      "z": -15,
      "name": "Soil_Gravel_Half",
      "rotation": 5
    },
    {
      "x": -9,
      "y": 19,
      "z": -15,
      "name": "Rock_Stone_Brick"
    },
    {
      "x": -9,
      "y": 13,
      "z": -14,
      "name": "Rock_Stone_Brick_Smooth"
    },
    {
      "x": -9,
      "y": 14,
      "z": -14,
      "name": "Rock_Stone_Brick_Decorative"
    },
    {
      "x": -9,
      "y": 15,
      "z": -14,
      "name": "Soil_Gravel_Half",
      "rotation": 5
    },
    {
      "x": -9,
      "y": 16,
      "z": -14,
      "name": "Soil_Gravel_Half",
      "rotation": 5
    },
    {
      "x": -9,
      "y": 17,
      "z": -14,
      "name": "Soil_Gravel_Half",
      "rotation": 5
    },
    {
      "x": -9,
      "y": 18,
      "z": -14,
      "name": "Soil_Gravel_Half",
      "rotation": 5
    },
    {
      "x": -9,
      "y": 19,
      "z": -14,
      "name": "Rock_Stone_Brick"
    },
    {
      "x": -9,
      "y": 13,
      "z": -13,
      "name": "Rock_Stone_Brick_Smooth"
    },
    {
      "x": -9,
      "y": 14,
      "z": -13,
      "name": "Rock_Stone_Brick_Decorative"
    },
    {
      "x": -9,
      "y": 15,
      "z": -13,
      "name": "Rock_Stone_Brick_Pillar_Base",
      "rotation": 2
    },
    {
      "x": -9,
      "y": 16,
      "z": -13,
      "name": "Rock_Stone_Brick_Pillar_Middle",
      "rotation": 2
    },
    {
      "x": -9,
      "y": 17,
      "z": -13,
      "name": "Rock_Stone_Brick_Pillar_Middle",
      "rotation": 2
    },
    {
      "x": -9,
      "y": 18,
      "z": -13,
      "name": "Rock_Stone_Brick_Pillar_Base",
      "rotation": 32
    },
    {
      "x": -9,
      "y": 19,
      "z": -13,
      "name": "Rock_Stone_Brick"
    },
    {
      "x": -9,
      "y": 13,
      "z": -12,
      "name": "Rock_Stone_Brick_Smooth"
    },
    {
      "x": -9,
      "y": 14,
      "z": -12,
      "name": "Rock_Stone_Brick_Decorative"
    },
    {
      "x": -9,
      "y": 15,
      "z": -12,
      "name": "Soil_Gravel_Half",
      "rotation": 5
    },
    {
      "x": -9,
      "y": 16,
      "z": -12,
      "name": "Soil_Gravel_Half",
      "rotation": 5
    },
    {
      "x": -9,
      "y": 17,
      "z": -12,
      "name": "Soil_Gravel_Half",
      "rotation": 5
    },
    {
      "x": -9,
      "y": 18,
      "z": -12,
      "name": "Soil_Gravel_Half",
      "rotation": 5
    },
    {
      "x": -9,
      "y": 19,
      "z": -12,
      "name": "Rock_Stone_Brick"
    },
    {
      "x": -9,
      "y": 13,
      "z": -11,
      "name": "Rock_Stone_Brick_Smooth"
    },
    {
      "x": -9,
      "y": 14,
      "z": -11,
      "name": "Rock_Stone_Brick_Decorative"
    },
    {
      "x": -9,
      "y": 15,
      "z": -11,
      "name": "Soil_Gravel_Half",
      "rotation": 5
    },
    {
      "x": -9,
      "y": 16,
      "z": -11,
      "name": "Soil_Gravel_Half",
      "rotation": 5
    },
    {
      "x": -9,
      "y": 17,
      "z": -11,
      "name": "Soil_Gravel_Half",
      "rotation": 5
    },
    {
      "x": -9,
      "y": 18,
      "z": -11,
      "name": "Soil_Gravel_Half",
      "rotation": 5
    },
    {
      "x": -9,
      "y": 19,
      "z": -11,
      "name": "Rock_Stone_Brick"
    },
    {
      "x": -9,
      "y": 13,
      "z": -10,
      "name": "Rock_Stone_Brick_Smooth"
    },
    {
      "x": -9,
      "y": 14,
      "z": -10,
      "name": "Rock_Stone_Brick_Decorative"
    },
    {
      "x": -9,
      "y": 15,
      "z": -10,
      "name": "Soil_Gravel_Half",
      "rotation": 5
    },
    {
      "x": -9,
      "y": 16,
      "z": -10,
      "name": "Soil_Gravel_Half",
      "rotation": 5
    },
    {
      "x": -9,
      "y": 17,
      "z": -10,
      "name": "Soil_Gravel_Half",
      "rotation": 5
    },
    {
      "x": -9,
      "y": 18,
      "z": -10,
      "name": "Soil_Gravel_Half",
      "rotation": 5
    },
    {
      "x": -9,
      "y": 19,
      "z": -10,
      "name": "Rock_Stone_Brick"
    },
    {
      "x": -9,
      "y": 13,
      "z": -9,
      "name": "Rock_Stone_Brick_Smooth"
    },
    {
      "x": -9,
      "y": 14,
      "z": -9,
      "name": "Rock_Stone_Brick_Decorative"
    },
    {
      "x": -9,
      "y": 15,
      "z": -9,
      "name": "Rock_Stone_Brick_Pillar_Base",
      "rotation": 2
    },
    {
      "x": -9,
      "y": 16,
      "z": -9,
      "name": "Rock_Stone_Brick_Pillar_Middle",
      "rotation": 2
    },
    {
      "x": -9,
      "y": 17,
      "z": -9,
      "name": "Rock_Stone_Brick_Pillar_Middle",
      "rotation": 2
    },
    {
      "x": -9,
      "y": 18,
      "z": -9,
      "name": "Rock_Stone_Brick_Pillar_Base",
      "rotation": 32
    },
    {
      "x": -9,
      "y": 19,
      "z": -9,
      "name": "Rock_Stone_Brick"
    },
    {
      "x": -9,
      "y": 13,
      "z": -8,
      "name": "Rock_Stone_Brick_Smooth"
    },
    {
      "x": -9,
      "y": 14,
      "z": -8,
      "name": "Rock_Stone_Brick_Decorative"
    },
    {
      "x": -9,
      "y": 15,
      "z": -8,
      "name": "Soil_Gravel_Half",
      "rotation": 5
    },
    {
      "x": -9,
      "y": 16,
      "z": -8,
      "name": "Soil_Gravel_Half",
      "rotation": 5
    },
    {
      "x": -9,
      "y": 17,
      "z": -8,
      "name": "Soil_Gravel_Half",
      "rotation": 5
    },
    {
      "x": -9,
      "y": 18,
      "z": -8,
      "name": "Soil_Gravel_Half",
      "rotation": 5
    },
    {
      "x": -9,
      "y": 19,
      "z": -8,
      "name": "Rock_Stone_Brick"
    },
    {
      "x": -9,
      "y": 13,
      "z": -7,
      "name": "Rock_Stone_Brick_Smooth"
    },
    {
      "x": -9,
      "y": 14,
      "z": -7,
      "name": "Rock_Stone_Brick_Decorative"
    },
    {
      "x": -9,
      "y": 15,
      "z": -7,
      "name": "Soil_Gravel_Half",
      "rotation": 5
    },
    {
      "x": -9,
      "y": 16,
      "z": -7,
      "name": "Soil_Gravel_Half",
      "rotation": 5
    },
    {
      "x": -9,
      "y": 17,
      "z": -7,
      "name": "Soil_Gravel_Half",
      "rotation": 5
    },
    {
      "x": -9,
      "y": 18,
      "z": -7,
      "name": "Soil_Gravel_Half",
      "rotation": 5
    },
    {
      "x": -9,
      "y": 19,
      "z": -7,
      "name": "Rock_Stone_Brick"
    },
    {
      "x": -9,
      "y": 13,
      "z": -6,
      "name": "Rock_Stone_Brick_Smooth"
    },
    {
      "x": -9,
      "y": 14,
      "z": -6,
      "name": "Rock_Stone_Brick_Decorative"
    },
    {
      "x": -9,
      "y": 15,
      "z": -6,
      "name": "Rock_Stone_Brick_Pillar_Base",
      "rotation": 2
    },
    {
      "x": -9,
      "y": 16,
      "z": -6,
      "name": "Rock_Stone_Brick_Pillar_Middle",
      "rotation": 2
    },
    {
      "x": -9,
      "y": 17,
      "z": -6,
      "name": "Rock_Stone_Brick_Pillar_Middle",
      "rotation": 2
    },
    {
      "x": -9,
      "y": 18,
      "z": -6,
      "name": "Rock_Stone_Brick_Pillar_Base",
      "rotation": 32
    },
    {
      "x": -9,
      "y": 19,
      "z": -6,
      "name": "Rock_Stone_Brick"
    },
    {
      "x": -9,
      "y": 13,
      "z": -5,
      "name": "Rock_Stone_Brick_Smooth"
    },
    {
      "x": -9,
      "y": 14,
      "z": -5,
      "name": "Rock_Stone_Brick_Decorative"
    },
    {
      "x": -9,
      "y": 15,
      "z": -5,
      "name": "Soil_Gravel_Half",
      "rotation": 5
    },
    {
      "x": -9,
      "y": 16,
      "z": -5,
      "name": "Soil_Gravel_Half",
      "rotation": 5
    },
    {
      "x": -9,
      "y": 17,
      "z": -5,
      "name": "Soil_Gravel_Half",
      "rotation": 5
    },
    {
      "x": -9,
      "y": 18,
      "z": -5,
      "name": "Soil_Gravel_Half",
      "rotation": 5
    },
    {
      "x": -9,
      "y": 19,
      "z": -5,
      "name": "Rock_Stone_Brick"
    },
    {
      "x": -9,
      "y": 13,
      "z": -4,
      "name": "Rock_Stone_Brick_Smooth"
    },
    {
      "x": -9,
      "y": 14,
      "z": -4,
      "name": "Rock_Stone_Brick_Decorative"
    },
    {
      "x": -9,
      "y": 15,
      "z": -4,
      "name": "Soil_Gravel_Half",
      "rotation": 5
    },
    {
      "x": -9,
      "y": 16,
      "z": -4,
      "name": "Soil_Gravel_Half",
      "rotation": 5
    },
    {
      "x": -9,
      "y": 17,
      "z": -4,
      "name": "Soil_Gravel_Half",
      "rotation": 5
    },
    {
      "x": -9,
      "y": 18,
      "z": -4,
      "name": "Soil_Gravel_Half",
      "rotation": 5
    },
    {
      "x": -9,
      "y": 19,
      "z": -4,
      "name": "Rock_Stone_Brick"
    },
    {
      "x": -9,
      "y": 13,
      "z": -3,
      "name": "Rock_Stone_Brick_Smooth"
    },
    {
      "x": -9,
      "y": 14,
      "z": -3,
      "name": "Rock_Stone_Brick_Decorative"
    },
    {
      "x": -9,
      "y": 15,
      "z": -3,
      "name": "Soil_Gravel_Half",
      "rotation": 5
    },
    {
      "x": -9,
      "y": 16,
      "z": -3,
      "name": "Soil_Gravel_Half",
      "rotation": 5
    },
    {
      "x": -9,
      "y": 17,
      "z": -3,
      "name": "Soil_Gravel_Half",
      "rotation": 5
    },
    {
      "x": -9,
      "y": 18,
      "z": -3,
      "name": "Soil_Gravel_Half",
      "rotation": 5
    },
    {
      "x": -9,
      "y": 19,
      "z": -3,
      "name": "Rock_Stone_Brick"
    },
    {
      "x": -9,
      "y": 13,
      "z": -2,
      "name": "Rock_Stone_Brick_Smooth"
    },
    {
      "x": -9,
      "y": 14,
      "z": -2,
      "name": "Rock_Stone_Brick_Decorative"
    },
    {
      "x": -9,
      "y": 15,
      "z": -2,
      "name": "Rock_Stone_Brick_Pillar_Base",
      "rotation": 2
    },
    {
      "x": -9,
      "y": 16,
      "z": -2,
      "name": "Rock_Stone_Brick_Pillar_Middle",
      "rotation": 2
    },
    {
      "x": -9,
      "y": 17,
      "z": -2,
      "name": "Rock_Stone_Brick_Pillar_Middle",
      "rotation": 2
    },
    {
      "x": -9,
      "y": 18,
      "z": -2,
      "name": "Rock_Stone_Brick_Pillar_Base",
      "rotation": 32
    },
    {
      "x": -9,
      "y": 19,
      "z": -2,
      "name": "Rock_Stone_Brick"
    },
    {
      "x": -9,
      "y": 13,
      "z": -1,
      "name": "Rock_Stone_Brick_Smooth"
    },
    {
      "x": -9,
      "y": 14,
      "z": -1,
      "name": "Rock_Stone_Brick_Decorative"
    },
    {
      "x": -9,
      "y": 15,
      "z": -1,
      "name": "Soil_Gravel_Half",
      "rotation": 5
    },
    {
      "x": -9,
      "y": 16,
      "z": -1,
      "name": "Soil_Gravel_Half",
      "rotation": 5
    },
    {
      "x": -9,
      "y": 17,
      "z": -1,
      "name": "Soil_Gravel_Half",
      "rotation": 5
    },
    {
      "x": -9,
      "y": 18,
      "z": -1,
      "name": "Soil_Gravel_Half",
      "rotation": 5
    },
    {
      "x": -9,
      "y": 19,
      "z": -1,
      "name": "Rock_Stone_Brick"
    },
    {
      "x": -9,
      "y": 13,
      "z": 0,
      "name": "Rock_Stone_Brick_Smooth"
    },
    {
      "x": -9,
      "y": 14,
      "z": 0,
      "name": "Rock_Stone_Brick_Decorative"
    },
    {
      "x": -9,
      "y": 15,
      "z": 0,
      "name": "Soil_Gravel_Half",
      "rotation": 5
    },
    {
      "x": -9,
      "y": 16,
      "z": 0,
      "name": "Soil_Gravel_Half",
      "rotation": 5
    },
    {
      "x": -9,
      "y": 17,
      "z": 0,
      "name": "Soil_Gravel_Half",
      "rotation": 5
    },
    {
      "x": -9,
      "y": 18,
      "z": 0,
      "name": "Soil_Gravel_Half",
      "rotation": 5
    },
    {
      "x": -9,
      "y": 19,
      "z": 0,
      "name": "Rock_Stone_Brick"
    },
    {
      "x": -9,
      "y": 13,
      "z": 1,
      "name": "Rock_Stone_Brick_Smooth"
    },
    {
      "x": -9,
      "y": 14,
      "z": 1,
      "name": "Rock_Stone_Brick_Decorative"
    },
    {
      "x": -9,
      "y": 15,
      "z": 1,
      "name": "Soil_Gravel_Half",
      "rotation": 5
    },
    {
      "x": -9,
      "y": 16,
      "z": 1,
      "name": "Soil_Gravel_Half",
      "rotation": 5
    },
    {
      "x": -9,
      "y": 17,
      "z": 1,
      "name": "Soil_Gravel_Half",
      "rotation": 5
    },
    {
      "x": -9,
      "y": 18,
      "z": 1,
      "name": "Soil_Gravel_Half",
      "rotation": 5
    },
    {
      "x": -9,
      "y": 19,
      "z": 1,
      "name": "Rock_Stone_Brick"
    },
    {
      "x": -9,
      "y": 13,
      "z": 2,
      "name": "Rock_Stone_Brick_Smooth"
    },
    {
      "x": -9,
      "y": 14,
      "z": 2,
      "name": "Rock_Stone_Brick_Decorative"
    },
    {
      "x": -9,
      "y": 15,
      "z": 2,
      "name": "Rock_Stone_Brick_Pillar_Base"
    },
    {
      "x": -9,
      "y": 16,
      "z": 2,
      "name": "Rock_Stone_Brick_Pillar_Middle"
    },
    {
      "x": -9,
      "y": 17,
      "z": 2,
      "name": "Rock_Stone_Brick_Pillar_Middle"
    },
    {
      "x": -9,
      "y": 18,
      "z": 2,
      "name": "Rock_Stone_Brick_Pillar_Base",
      "rotation": 8
    },
    {
      "x": -9,
      "y": 19,
      "z": 2,
      "name": "Rock_Stone_Brick"
    },
    {
      "x": -9,
      "y": 13,
      "z": 3,
      "name": "Rock_Stone_Brick_Smooth"
    },
    {
      "x": -9,
      "y": 14,
      "z": 3,
      "name": "Rock_Stone_Brick_Decorative"
    },
    {
      "x": -9,
      "y": 15,
      "z": 3,
      "name": "Soil_Gravel_Half",
      "rotation": 5
    },
    {
      "x": -9,
      "y": 16,
      "z": 3,
      "name": "Soil_Gravel_Half",
      "rotation": 5
    },
    {
      "x": -9,
      "y": 17,
      "z": 3,
      "name": "Soil_Gravel_Half",
      "rotation": 5
    },
    {
      "x": -9,
      "y": 18,
      "z": 3,
      "name": "Soil_Gravel_Half",
      "rotation": 5
    },
    {
      "x": -9,
      "y": 19,
      "z": 3,
      "name": "Rock_Stone_Brick"
    },
    {
      "x": -9,
      "y": 13,
      "z": 4,
      "name": "Rock_Stone_Brick_Smooth"
    },
    {
      "x": -9,
      "y": 14,
      "z": 4,
      "name": "Rock_Stone_Brick_Decorative"
    },
    {
      "x": -9,
      "y": 15,
      "z": 4,
      "name": "Soil_Gravel_Half",
      "rotation": 5
    },
    {
      "x": -9,
      "y": 16,
      "z": 4,
      "name": "Soil_Gravel_Half",
      "rotation": 5
    },
    {
      "x": -9,
      "y": 17,
      "z": 4,
      "name": "Soil_Gravel_Half",
      "rotation": 5
    },
    {
      "x": -9,
      "y": 18,
      "z": 4,
      "name": "Soil_Gravel_Half",
      "rotation": 5
    },
    {
      "x": -9,
      "y": 19,
      "z": 4,
      "name": "Rock_Stone_Brick"
    },
    {
      "x": -9,
      "y": 13,
      "z": 5,
      "name": "Rock_Stone_Brick_Smooth"
    },
    {
      "x": -9,
      "y": 14,
      "z": 5,
      "name": "Rock_Stone_Brick_Decorative"
    },
    {
      "x": -9,
      "y": 15,
      "z": 5,
      "name": "Soil_Gravel_Half",
      "rotation": 5
    },
    {
      "x": -9,
      "y": 16,
      "z": 5,
      "name": "Soil_Gravel_Half",
      "rotation": 5
    },
    {
      "x": -9,
      "y": 17,
      "z": 5,
      "name": "Soil_Gravel_Half",
      "rotation": 5
    },
    {
      "x": -9,
      "y": 18,
      "z": 5,
      "name": "Soil_Gravel_Half",
      "rotation": 5
    },
    {
      "x": -9,
      "y": 19,
      "z": 5,
      "name": "Rock_Stone_Brick"
    },
    {
      "x": -9,
      "y": 13,
      "z": 6,
      "name": "Rock_Stone_Brick_Smooth"
    },
    {
      "x": -9,
      "y": 14,
      "z": 6,
      "name": "Rock_Stone_Brick_Decorative"
    },
    {
      "x": -9,
      "y": 15,
      "z": 6,
      "name": "Rock_Stone_Brick_Pillar_Base"
    },
    {
      "x": -9,
      "y": 16,
      "z": 6,
      "name": "Rock_Stone_Brick_Pillar_Middle"
    },
    {
      "x": -9,
      "y": 17,
      "z": 6,
      "name": "Rock_Stone_Brick_Pillar_Middle"
    },
    {
      "x": -9,
      "y": 18,
      "z": 6,
      "name": "Rock_Stone_Brick_Pillar_Base",
      "rotation": 8
    },
    {
      "x": -9,
      "y": 19,
      "z": 6,
      "name": "Rock_Stone_Brick"
    },
    {
      "x": -9,
      "y": 13,
      "z": 7,
      "name": "Rock_Stone_Brick_Smooth"
    },
    {
      "x": -9,
      "y": 14,
      "z": 7,
      "name": "Rock_Stone_Brick_Decorative"
    },
    {
      "x": -9,
      "y": 15,
      "z": 7,
      "name": "Soil_Gravel_Half",
      "rotation": 5
    },
    {
      "x": -9,
      "y": 16,
      "z": 7,
      "name": "Soil_Gravel_Half",
      "rotation": 5
    },
    {
      "x": -9,
      "y": 17,
      "z": 7,
      "name": "Soil_Gravel_Half",
      "rotation": 5
    },
    {
      "x": -9,
      "y": 18,
      "z": 7,
      "name": "Soil_Gravel_Half",
      "rotation": 5
    },
    {
      "x": -9,
      "y": 19,
      "z": 7,
      "name": "Rock_Stone_Brick"
    },
    {
      "x": -9,
      "y": 13,
      "z": 8,
      "name": "Rock_Stone_Brick_Smooth"
    },
    {
      "x": -9,
      "y": 14,
      "z": 8,
      "name": "Rock_Stone_Brick_Decorative"
    },
    {
      "x": -9,
      "y": 15,
      "z": 8,
      "name": "Soil_Gravel_Half",
      "rotation": 5
    },
    {
      "x": -9,
      "y": 16,
      "z": 8,
      "name": "Soil_Gravel_Half",
      "rotation": 5
    },
    {
      "x": -9,
      "y": 17,
      "z": 8,
      "name": "Soil_Gravel_Half",
      "rotation": 5
    },
    {
      "x": -9,
      "y": 18,
      "z": 8,
      "name": "Soil_Gravel_Half",
      "rotation": 5
    },
    {
      "x": -9,
      "y": 19,
      "z": 8,
      "name": "Rock_Stone_Brick"
    },
    {
      "x": -9,
      "y": 13,
      "z": 9,
      "name": "Rock_Stone_Brick_Smooth"
    },
    {
      "x": -9,
      "y": 14,
      "z": 9,
      "name": "Rock_Stone_Brick_Decorative"
    },
    {
      "x": -9,
      "y": 15,
      "z": 9,
      "name": "Rock_Stone_Brick_Pillar_Base"
    },
    {
      "x": -9,
      "y": 16,
      "z": 9,
      "name": "Rock_Stone_Brick_Pillar_Middle"
    },
    {
      "x": -9,
      "y": 17,
      "z": 9,
      "name": "Rock_Stone_Brick_Pillar_Middle"
    },
    {
      "x": -9,
      "y": 18,
      "z": 9,
      "name": "Rock_Stone_Brick_Pillar_Base",
      "rotation": 8
    },
    {
      "x": -9,
      "y": 19,
      "z": 9,
      "name": "Rock_Stone_Brick"
    },
    {
      "x": -9,
      "y": 13,
      "z": 10,
      "name": "Rock_Stone_Brick_Smooth"
    },
    {
      "x": -9,
      "y": 14,
      "z": 10,
      "name": "Rock_Stone_Brick_Decorative"
    },
    {
      "x": -9,
      "y": 15,
      "z": 10,
      "name": "Soil_Gravel_Half",
      "rotation": 5
    },
    {
      "x": -9,
      "y": 16,
      "z": 10,
      "name": "Soil_Gravel_Half",
      "rotation": 5
    },
    {
      "x": -9,
      "y": 17,
      "z": 10,
      "name": "Soil_Gravel_Half",
      "rotation": 5
    },
    {
      "x": -9,
      "y": 18,
      "z": 10,
      "name": "Soil_Gravel_Half",
      "rotation": 5
    },
    {
      "x": -9,
      "y": 19,
      "z": 10,
      "name": "Rock_Stone_Brick"
    },
    {
      "x": -9,
      "y": 13,
      "z": 11,
      "name": "Rock_Stone_Brick_Smooth"
    },
    {
      "x": -9,
      "y": 14,
      "z": 11,
      "name": "Rock_Stone_Brick_Decorative"
    },
    {
      "x": -9,
      "y": 15,
      "z": 11,
      "name": "Soil_Gravel_Half",
      "rotation": 5
    },
    {
      "x": -9,
      "y": 16,
      "z": 11,
      "name": "Soil_Gravel_Half",
      "rotation": 5
    },
    {
      "x": -9,
      "y": 17,
      "z": 11,
      "name": "Soil_Gravel_Half",
      "rotation": 5
    },
    {
      "x": -9,
      "y": 18,
      "z": 11,
      "name": "Soil_Gravel_Half",
      "rotation": 5
    },
    {
      "x": -9,
      "y": 19,
      "z": 11,
      "name": "Rock_Stone_Brick"
    },
    {
      "x": -9,
      "y": 13,
      "z": 12,
      "name": "Rock_Stone_Brick_Smooth"
    },
    {
      "x": -9,
      "y": 14,
      "z": 12,
      "name": "Rock_Stone_Brick_Decorative"
    },
    {
      "x": -9,
      "y": 15,
      "z": 12,
      "name": "Soil_Gravel_Half",
      "rotation": 5
    },
    {
      "x": -9,
      "y": 16,
      "z": 12,
      "name": "Soil_Gravel_Half",
      "rotation": 5
    },
    {
      "x": -9,
      "y": 17,
      "z": 12,
      "name": "Soil_Gravel_Half",
      "rotation": 5
    },
    {
      "x": -9,
      "y": 18,
      "z": 12,
      "name": "Soil_Gravel_Half",
      "rotation": 5
    },
    {
      "x": -9,
      "y": 19,
      "z": 12,
      "name": "Rock_Stone_Brick"
    },
    {
      "x": -9,
      "y": 13,
      "z": 13,
      "name": "Rock_Stone_Brick_Smooth"
    },
    {
      "x": -9,
      "y": 14,
      "z": 13,
      "name": "Rock_Stone_Brick_Decorative"
    },
    {
      "x": -9,
      "y": 15,
      "z": 13,
      "name": "Rock_Stone_Brick_Pillar_Base"
    },
    {
      "x": -9,
      "y": 16,
      "z": 13,
      "name": "Rock_Stone_Brick_Pillar_Middle"
    },
    {
      "x": -9,
      "y": 17,
      "z": 13,
      "name": "Rock_Stone_Brick_Pillar_Middle"
    },
    {
      "x": -9,
      "y": 18,
      "z": 13,
      "name": "Rock_Stone_Brick_Pillar_Base",
      "rotation": 8
    },
    {
      "x": -9,
      "y": 19,
      "z": 13,
      "name": "Rock_Stone_Brick"
    },
    {
      "x": -9,
      "y": 13,
      "z": 14,
      "name": "Rock_Stone_Brick_Smooth"
    },
    {
      "x": -9,
      "y": 14,
      "z": 14,
      "name": "Rock_Stone_Brick_Decorative"
    },
    {
      "x": -9,
      "y": 15,
      "z": 14,
      "name": "Soil_Gravel_Half",
      "rotation": 5
    },
    {
      "x": -9,
      "y": 16,
      "z": 14,
      "name": "Soil_Gravel_Half",
      "rotation": 5
    },
    {
      "x": -9,
      "y": 17,
      "z": 14,
      "name": "Soil_Gravel_Half",
      "rotation": 5
    },
    {
      "x": -9,
      "y": 18,
      "z": 14,
      "name": "Soil_Gravel_Half",
      "rotation": 5
    },
    {
      "x": -9,
      "y": 19,
      "z": 14,
      "name": "Rock_Stone_Brick"
    },
    {
      "x": -9,
      "y": 13,
      "z": 15,
      "name": "Rock_Stone_Brick_Smooth"
    },
    {
      "x": -9,
      "y": 14,
      "z": 15,
      "name": "Rock_Stone_Brick_Decorative"
    },
    {
      "x": -9,
      "y": 15,
      "z": 15,
      "name": "Soil_Gravel_Half",
      "rotation": 5
    },
    {
      "x": -9,
      "y": 16,
      "z": 15,
      "name": "Soil_Gravel_Half",
      "rotation": 5
    },
    {
      "x": -9,
      "y": 17,
      "z": 15,
      "name": "Soil_Gravel_Half",
      "rotation": 5
    },
    {
      "x": -9,
      "y": 18,
      "z": 15,
      "name": "Soil_Gravel_Half",
      "rotation": 5
    },
    {
      "x": -9,
      "y": 19,
      "z": 15,
      "name": "Rock_Stone_Brick"
    },
    {
      "x": -9,
      "y": 13,
      "z": 16,
      "name": "Rock_Stone_Brick_Smooth"
    },
    {
      "x": -9,
      "y": 14,
      "z": 16,
      "name": "Rock_Stone_Brick"
    },
    {
      "x": -9,
      "y": 15,
      "z": 16,
      "name": "Rock_Stone_Brick"
    },
    {
      "x": -9,
      "y": 16,
      "z": 16,
      "name": "Rock_Stone_Brick"
    },
    {
      "x": -9,
      "y": 17,
      "z": 16,
      "name": "Rock_Stone_Brick"
    },
    {
      "x": -9,
      "y": 18,
      "z": 16,
      "name": "Rock_Stone_Brick"
    },
    {
      "x": -9,
      "y": 19,
      "z": 16,
      "name": "Rock_Stone_Brick_Smooth"
    },
    {
      "x": -8,
      "y": 13,
      "z": -16,
      "name": "Rock_Stone_Brick_Smooth"
    },
    {
      "x": -8,
      "y": 14,
      "z": -16,
      "name": "Rock_Stone_Brick_Decorative"
    },
    {
      "x": -8,
      "y": 15,
      "z": -16,
      "name": "Soil_Gravel_Half",
      "rotation": 4
    },
    {
      "x": -8,
      "y": 16,
      "z": -16,
      "name": "Soil_Gravel_Half",
      "rotation": 4
    },
    {
      "x": -8,
      "y": 17,
      "z": -16,
      "name": "Soil_Gravel_Half",
      "rotation": 4
    },
    {
      "x": -8,
      "y": 18,
      "z": -16,
      "name": "Soil_Gravel_Half",
      "rotation": 4
    },
    {
      "x": -8,
      "y": 19,
      "z": -16,
      "name": "Rock_Stone_Brick"
    },
    {
      "x": -8,
      "y": 13,
      "z": -15,
      "name": "Rock_Stone_Brick_Smooth"
    },
    {
      "x": -8,
      "y": 19,
      "z": -15,
      "name": "Rock_Stone_Brick_Smooth"
    },
    {
      "x": -8,
      "y": 13,
      "z": -14,
      "name": "Rock_Stone_Brick_Smooth"
    },
    {
      "x": -8,
      "y": 19,
      "z": -14,
      "name": "Rock_Stone_Brick_Smooth"
    },
    {
      "x": -8,
      "y": 13,
      "z": -13,
      "name": "Rock_Stone_Brick_Smooth"
    },
    {
      "x": -8,
      "y": 19,
      "z": -13,
      "name": "Rock_Stone_Brick_Smooth"
    },
    {
      "x": -8,
      "y": 13,
      "z": -12,
      "name": "Rock_Stone_Brick_Smooth"
    },
    {
      "x": -8,
      "y": 19,
      "z": -12,
      "name": "Rock_Stone_Brick_Smooth"
    },
    {
      "x": -8,
      "y": 13,
      "z": -11,
      "name": "Rock_Stone_Brick_Smooth"
    },
    {
      "x": -8,
      "y": 19,
      "z": -11,
      "name": "Rock_Stone_Brick_Smooth"
    },
    {
      "x": -8,
      "y": 13,
      "z": -10,
      "name": "Rock_Stone_Brick_Smooth"
    },
    {
      "x": -8,
      "y": 19,
      "z": -10,
      "name": "Rock_Stone_Brick_Smooth"
    },
    {
      "x": -8,
      "y": 13,
      "z": -9,
      "name": "Rock_Stone_Brick_Smooth"
    },
    {
      "x": -8,
      "y": 19,
      "z": -9,
      "name": "Rock_Stone_Brick_Smooth"
    },
    {
      "x": -8,
      "y": 13,
      "z": -8,
      "name": "Rock_Stone_Brick_Smooth"
    },
    {
      "x": -8,
      "y": 19,
      "z": -8,
      "name": "Rock_Stone_Brick_Smooth"
    },
    {
      "x": -8,
      "y": 13,
      "z": -7,
      "name": "Rock_Stone_Brick_Smooth"
    },
    {
      "x": -8,
      "y": 19,
      "z": -7,
      "name": "Rock_Stone_Brick_Smooth"
    },
    {
      "x": -8,
      "y": 13,
      "z": -6,
      "name": "Rock_Stone_Brick_Smooth"
    },
    {
      "x": -8,
      "y": 19,
      "z": -6,
      "name": "Rock_Stone_Brick_Smooth"
    },
    {
      "x": -8,
      "y": 13,
      "z": -5,
      "name": "Rock_Stone_Brick_Smooth"
    },
    {
      "x": -8,
      "y": 19,
      "z": -5,
      "name": "Rock_Stone_Brick_Smooth"
    },
    {
      "x": -8,
      "y": 13,
      "z": -4,
      "name": "Rock_Stone_Brick_Smooth"
    },
    {
      "x": -8,
      "y": 19,
      "z": -4,
      "name": "Rock_Stone_Brick_Smooth"
    },
    {
      "x": -8,
      "y": 13,
      "z": -3,
      "name": "Rock_Stone_Brick_Smooth"
    },
    {
      "x": -8,
      "y": 19,
      "z": -3,
      "name": "Rock_Stone_Brick_Smooth"
    },
    {
      "x": -8,
      "y": 13,
      "z": -2,
      "name": "Rock_Stone_Brick_Smooth"
    },
    {
      "x": -8,
      "y": 19,
      "z": -2,
      "name": "Rock_Stone_Brick_Smooth"
    },
    {
      "x": -8,
      "y": 13,
      "z": -1,
      "name": "Rock_Stone_Brick_Smooth"
    },
    {
      "x": -8,
      "y": 19,
      "z": -1,
      "name": "Rock_Stone_Brick_Smooth"
    },
    {
      "x": -8,
      "y": 13,
      "z": 0,
      "name": "Rock_Stone_Brick_Smooth"
    },
    {
      "x": -8,
      "y": 19,
      "z": 0,
      "name": "Rock_Stone_Brick_Smooth"
    },
    {
      "x": -8,
      "y": 13,
      "z": 1,
      "name": "Rock_Stone_Brick_Smooth"
    },
    {
      "x": -8,
      "y": 19,
      "z": 1,
      "name": "Rock_Stone_Brick_Smooth"
    },
    {
      "x": -8,
      "y": 13,
      "z": 2,
      "name": "Rock_Stone_Brick_Smooth"
    },
    {
      "x": -8,
      "y": 19,
      "z": 2,
      "name": "Rock_Stone_Brick_Smooth"
    },
    {
      "x": -8,
      "y": 13,
      "z": 3,
      "name": "Rock_Stone_Brick_Smooth"
    },
    {
      "x": -8,
      "y": 19,
      "z": 3,
      "name": "Rock_Stone_Brick_Smooth"
    },
    {
      "x": -8,
      "y": 13,
      "z": 4,
      "name": "Rock_Stone_Brick_Smooth"
    },
    {
      "x": -8,
      "y": 19,
      "z": 4,
      "name": "Rock_Stone_Brick_Smooth"
    },
    {
      "x": -8,
      "y": 13,
      "z": 5,
      "name": "Rock_Stone_Brick_Smooth"
    },
    {
      "x": -8,
      "y": 19,
      "z": 5,
      "name": "Rock_Stone_Brick_Smooth"
    },
    {
      "x": -8,
      "y": 13,
      "z": 6,
      "name": "Rock_Stone_Brick_Smooth"
    },
    {
      "x": -8,
      "y": 19,
      "z": 6,
      "name": "Rock_Stone_Brick_Smooth"
    },
    {
      "x": -8,
      "y": 13,
      "z": 7,
      "name": "Rock_Stone_Brick_Smooth"
    },
    {
      "x": -8,
      "y": 19,
      "z": 7,
      "name": "Rock_Stone_Brick_Smooth"
    },
    {
      "x": -8,
      "y": 13,
      "z": 8,
      "name": "Rock_Stone_Brick_Smooth"
    },
    {
      "x": -8,
      "y": 19,
      "z": 8,
      "name": "Rock_Stone_Brick_Smooth"
    },
    {
      "x": -8,
      "y": 13,
      "z": 9,
      "name": "Rock_Stone_Brick_Smooth"
    },
    {
      "x": -8,
      "y": 19,
      "z": 9,
      "name": "Rock_Stone_Brick_Smooth"
    },
    {
      "x": -8,
      "y": 13,
      "z": 10,
      "name": "Rock_Stone_Brick_Smooth"
    },
    {
      "x": -8,
      "y": 19,
      "z": 10,
      "name": "Rock_Stone_Brick_Smooth"
    },
    {
      "x": -8,
      "y": 13,
      "z": 11,
      "name": "Rock_Stone_Brick_Smooth"
    },
    {
      "x": -8,
      "y": 19,
      "z": 11,
      "name": "Rock_Stone_Brick_Smooth"
    },
    {
      "x": -8,
      "y": 13,
      "z": 12,
      "name": "Rock_Stone_Brick_Smooth"
    },
    {
      "x": -8,
      "y": 19,
      "z": 12,
      "name": "Rock_Stone_Brick_Smooth"
    },
    {
      "x": -8,
      "y": 13,
      "z": 13,
      "name": "Rock_Stone_Brick_Smooth"
    },
    {
      "x": -8,
      "y": 19,
      "z": 13,
      "name": "Rock_Stone_Brick_Smooth"
    },
    {
      "x": -8,
      "y": 13,
      "z": 14,
      "name": "Rock_Stone_Brick_Smooth"
    },
    {
      "x": -8,
      "y": 19,
      "z": 14,
      "name": "Rock_Stone_Brick_Smooth"
    },
    {
      "x": -8,
      "y": 13,
      "z": 15,
      "name": "Rock_Stone_Brick_Smooth"
    },
    {
      "x": -8,
      "y": 19,
      "z": 15,
      "name": "Rock_Stone_Brick_Smooth"
    },
    {
      "x": -8,
      "y": 13,
      "z": 16,
      "name": "Rock_Stone_Brick_Smooth"
    },
    {
      "x": -8,
      "y": 14,
      "z": 16,
      "name": "Rock_Stone_Brick_Decorative"
    },
    {
      "x": -8,
      "y": 15,
      "z": 16,
      "name": "Soil_Gravel_Half",
      "rotation": 6
    },
    {
      "x": -8,
      "y": 16,
      "z": 16,
      "name": "Soil_Gravel_Half",
      "rotation": 6
    },
    {
      "x": -8,
      "y": 17,
      "z": 16,
      "name": "Soil_Gravel_Half",
      "rotation": 6
    },
    {
      "x": -8,
      "y": 18,
      "z": 16,
      "name": "Soil_Gravel_Half",
      "rotation": 6
    },
    {
      "x": -8,
      "y": 19,
      "z": 16,
      "name": "Rock_Stone_Brick"
    },
    {
      "x": -7,
      "y": 13,
      "z": -16,
      "name": "Rock_Stone_Brick_Smooth"
    },
    {
      "x": -7,
      "y": 14,
      "z": -16,
      "name": "Rock_Stone_Brick_Decorative"
    },
    {
      "x": -7,
      "y": 15,
      "z": -16,
      "name": "Soil_Gravel_Half",
      "rotation": 4
    },
    {
      "x": -7,
      "y": 16,
      "z": -16,
      "name": "Soil_Gravel_Half",
      "rotation": 4
    },
    {
      "x": -7,
      "y": 17,
      "z": -16,
      "name": "Soil_Gravel_Half",
      "rotation": 4
    },
    {
      "x": -7,
      "y": 18,
      "z": -16,
      "name": "Soil_Gravel_Half",
      "rotation": 4
    },
    {
      "x": -7,
      "y": 19,
      "z": -16,
      "name": "Rock_Stone_Brick"
    },
    {
      "x": -7,
      "y": 13,
      "z": -15,
      "name": "Rock_Stone_Brick_Smooth"
    },
    {
      "x": -7,
      "y": 19,
      "z": -15,
      "name": "Rock_Stone_Brick_Smooth"
    },
    {
      "x": -7,
      "y": 13,
      "z": -14,
      "name": "Rock_Stone_Brick_Smooth"
    },
    {
      "x": -7,
      "y": 19,
      "z": -14,
      "name": "Rock_Stone_Brick_Smooth"
    },
    {
      "x": -7,
      "y": 13,
      "z": -13,
      "name": "Rock_Stone_Brick_Smooth"
    },
    {
      "x": -7,
      "y": 19,
      "z": -13,
      "name": "Rock_Stone_Brick_Smooth"
    },
    {
      "x": -7,
      "y": 13,
      "z": -12,
      "name": "Rock_Stone_Brick_Smooth"
    },
    {
      "x": -7,
      "y": 19,
      "z": -12,
      "name": "Rock_Stone_Brick_Smooth"
    },
    {
      "x": -7,
      "y": 13,
      "z": -11,
      "name": "Rock_Stone_Brick_Smooth"
    },
    {
      "x": -7,
      "y": 19,
      "z": -11,
      "name": "Rock_Stone_Brick_Smooth"
    },
    {
      "x": -7,
      "y": 13,
      "z": -10,
      "name": "Rock_Stone_Brick_Smooth"
    },
    {
      "x": -7,
      "y": 19,
      "z": -10,
      "name": "Rock_Stone_Brick_Smooth"
    },
    {
      "x": -7,
      "y": 13,
      "z": -9,
      "name": "Rock_Stone_Brick_Smooth"
    },
    {
      "x": -7,
      "y": 19,
      "z": -9,
      "name": "Rock_Stone_Brick_Smooth"
    },
    {
      "x": -7,
      "y": 13,
      "z": -8,
      "name": "Rock_Stone_Brick_Smooth"
    },
    {
      "x": -7,
      "y": 19,
      "z": -8,
      "name": "Rock_Stone_Brick_Smooth"
    },
    {
      "x": -7,
      "y": 13,
      "z": -7,
      "name": "Rock_Stone_Brick_Smooth"
    },
    {
      "x": -7,
      "y": 19,
      "z": -7,
      "name": "Rock_Stone_Brick_Smooth"
    },
    {
      "x": -7,
      "y": 13,
      "z": -6,
      "name": "Rock_Stone_Brick_Smooth"
    },
    {
      "x": -7,
      "y": 19,
      "z": -6,
      "name": "Rock_Stone_Brick_Smooth"
    },
    {
      "x": -7,
      "y": 13,
      "z": -5,
      "name": "Rock_Stone_Brick_Smooth"
    },
    {
      "x": -7,
      "y": 19,
      "z": -5,
      "name": "Rock_Stone_Brick_Smooth"
    },
    {
      "x": -7,
      "y": 13,
      "z": -4,
      "name": "Rock_Stone_Brick_Smooth"
    },
    {
      "x": -7,
      "y": 19,
      "z": -4,
      "name": "Rock_Stone_Brick_Smooth"
    },
    {
      "x": -7,
      "y": 13,
      "z": -3,
      "name": "Rock_Stone_Brick_Smooth"
    },
    {
      "x": -7,
      "y": 19,
      "z": -3,
      "name": "Rock_Stone_Brick_Smooth"
    },
    {
      "x": -7,
      "y": 13,
      "z": -2,
      "name": "Rock_Stone_Brick_Smooth"
    },
    {
      "x": -7,
      "y": 19,
      "z": -2,
      "name": "Rock_Stone_Brick_Smooth"
    },
    {
      "x": -7,
      "y": 13,
      "z": -1,
      "name": "Rock_Stone_Brick_Smooth"
    },
    {
      "x": -7,
      "y": 19,
      "z": -1,
      "name": "Rock_Stone_Brick_Smooth"
    },
    {
      "x": -7,
      "y": 13,
      "z": 0,
      "name": "Rock_Stone_Brick_Smooth"
    },
    {
      "x": -7,
      "y": 19,
      "z": 0,
      "name": "Rock_Stone_Brick_Smooth"
    },
    {
      "x": -7,
      "y": 13,
      "z": 1,
      "name": "Rock_Stone_Brick_Smooth"
    },
    {
      "x": -7,
      "y": 19,
      "z": 1,
      "name": "Rock_Stone_Brick_Smooth"
    },
    {
      "x": -7,
      "y": 13,
      "z": 2,
      "name": "Rock_Stone_Brick_Smooth"
    },
    {
      "x": -7,
      "y": 19,
      "z": 2,
      "name": "Rock_Stone_Brick_Smooth"
    },
    {
      "x": -7,
      "y": 13,
      "z": 3,
      "name": "Rock_Stone_Brick_Smooth"
    },
    {
      "x": -7,
      "y": 19,
      "z": 3,
      "name": "Rock_Stone_Brick_Smooth"
    },
    {
      "x": -7,
      "y": 13,
      "z": 4,
      "name": "Rock_Stone_Brick_Smooth"
    },
    {
      "x": -7,
      "y": 19,
      "z": 4,
      "name": "Rock_Stone_Brick_Smooth"
    },
    {
      "x": -7,
      "y": 13,
      "z": 5,
      "name": "Rock_Stone_Brick_Smooth"
    },
    {
      "x": -7,
      "y": 19,
      "z": 5,
      "name": "Rock_Stone_Brick_Smooth"
    },
    {
      "x": -7,
      "y": 13,
      "z": 6,
      "name": "Rock_Stone_Brick_Smooth"
    },
    {
      "x": -7,
      "y": 19,
      "z": 6,
      "name": "Rock_Stone_Brick_Smooth"
    },
    {
      "x": -7,
      "y": 13,
      "z": 7,
      "name": "Rock_Stone_Brick_Smooth"
    },
    {
      "x": -7,
      "y": 19,
      "z": 7,
      "name": "Rock_Stone_Brick_Smooth"
    },
    {
      "x": -7,
      "y": 13,
      "z": 8,
      "name": "Rock_Stone_Brick_Smooth"
    },
    {
      "x": -7,
      "y": 19,
      "z": 8,
      "name": "Rock_Stone_Brick_Smooth"
    },
    {
      "x": -7,
      "y": 13,
      "z": 9,
      "name": "Rock_Stone_Brick_Smooth"
    },
    {
      "x": -7,
      "y": 19,
      "z": 9,
      "name": "Rock_Stone_Brick_Smooth"
    },
    {
      "x": -7,
      "y": 13,
      "z": 10,
      "name": "Rock_Stone_Brick_Smooth"
    },
    {
      "x": -7,
      "y": 19,
      "z": 10,
      "name": "Rock_Stone_Brick_Smooth"
    },
    {
      "x": -7,
      "y": 13,
      "z": 11,
      "name": "Rock_Stone_Brick_Smooth"
    },
    {
      "x": -7,
      "y": 19,
      "z": 11,
      "name": "Rock_Stone_Brick_Smooth"
    },
    {
      "x": -7,
      "y": 13,
      "z": 12,
      "name": "Rock_Stone_Brick_Smooth"
    },
    {
      "x": -7,
      "y": 19,
      "z": 12,
      "name": "Rock_Stone_Brick_Smooth"
    },
    {
      "x": -7,
      "y": 13,
      "z": 13,
      "name": "Rock_Stone_Brick_Smooth"
    },
    {
      "x": -7,
      "y": 19,
      "z": 13,
      "name": "Rock_Stone_Brick_Smooth"
    },
    {
      "x": -7,
      "y": 13,
      "z": 14,
      "name": "Rock_Stone_Brick_Smooth"
    },
    {
      "x": -7,
      "y": 19,
      "z": 14,
      "name": "Rock_Stone_Brick_Smooth"
    },
    {
      "x": -7,
      "y": 13,
      "z": 15,
      "name": "Rock_Stone_Brick_Smooth"
    },
    {
      "x": -7,
      "y": 19,
      "z": 15,
      "name": "Rock_Stone_Brick_Smooth"
    },
    {
      "x": -7,
      "y": 13,
      "z": 16,
      "name": "Rock_Stone_Brick_Smooth"
    },
    {
      "x": -7,
      "y": 14,
      "z": 16,
      "name": "Rock_Stone_Brick_Decorative"
    },
    {
      "x": -7,
      "y": 15,
      "z": 16,
      "name": "Soil_Gravel_Half",
      "rotation": 6
    },
    {
      "x": -7,
      "y": 16,
      "z": 16,
      "name": "Soil_Gravel_Half",
      "rotation": 6
    },
    {
      "x": -7,
      "y": 17,
      "z": 16,
      "name": "Soil_Gravel_Half",
      "rotation": 6
    },
    {
      "x": -7,
      "y": 18,
      "z": 16,
      "name": "Soil_Gravel_Half",
      "rotation": 6
    },
    {
      "x": -7,
      "y": 19,
      "z": 16,
      "name": "Rock_Stone_Brick"
    },
    {
      "x": -6,
      "y": 13,
      "z": -16,
      "name": "Rock_Stone_Brick_Smooth"
    },
    {
      "x": -6,
      "y": 14,
      "z": -16,
      "name": "Rock_Stone_Brick_Decorative"
    },
    {
      "x": -6,
      "y": 15,
      "z": -16,
      "name": "Soil_Gravel_Half",
      "rotation": 4
    },
    {
      "x": -6,
      "y": 16,
      "z": -16,
      "name": "Soil_Gravel_Half",
      "rotation": 4
    },
    {
      "x": -6,
      "y": 17,
      "z": -16,
      "name": "Soil_Gravel_Half",
      "rotation": 4
    },
    {
      "x": -6,
      "y": 18,
      "z": -16,
      "name": "Soil_Gravel_Half",
      "rotation": 4
    },
    {
      "x": -6,
      "y": 19,
      "z": -16,
      "name": "Rock_Stone_Brick"
    },
    {
      "x": -6,
      "y": 13,
      "z": -15,
      "name": "Rock_Stone_Brick_Smooth"
    },
    {
      "x": -6,
      "y": 19,
      "z": -15,
      "name": "Rock_Stone_Brick_Smooth"
    },
    {
      "x": -6,
      "y": 13,
      "z": -14,
      "name": "Rock_Stone_Brick_Smooth"
    },
    {
      "x": -6,
      "y": 19,
      "z": -14,
      "name": "Rock_Stone_Brick_Smooth"
    },
    {
      "x": -6,
      "y": 13,
      "z": -13,
      "name": "Rock_Stone_Brick_Smooth"
    },
    {
      "x": -6,
      "y": 19,
      "z": -13,
      "name": "Rock_Stone_Brick_Smooth"
    },
    {
      "x": -6,
      "y": 13,
      "z": -12,
      "name": "Rock_Stone_Brick_Smooth"
    },
    {
      "x": -6,
      "y": 19,
      "z": -12,
      "name": "Rock_Stone_Brick_Smooth"
    },
    {
      "x": -6,
      "y": 13,
      "z": -11,
      "name": "Rock_Stone_Brick_Smooth"
    },
    {
      "x": -6,
      "y": 19,
      "z": -11,
      "name": "Rock_Stone_Brick_Smooth"
    },
    {
      "x": -6,
      "y": 13,
      "z": -10,
      "name": "Rock_Stone_Brick_Smooth"
    },
    {
      "x": -6,
      "y": 19,
      "z": -10,
      "name": "Rock_Stone_Brick_Smooth"
    },
    {
      "x": -6,
      "y": 13,
      "z": -9,
      "name": "Rock_Stone_Brick_Smooth"
    },
    {
      "x": -6,
      "y": 19,
      "z": -9,
      "name": "Rock_Stone_Brick_Smooth"
    },
    {
      "x": -6,
      "y": 13,
      "z": -8,
      "name": "Rock_Stone_Brick_Smooth"
    },
    {
      "x": -6,
      "y": 19,
      "z": -8,
      "name": "Rock_Stone_Brick_Smooth"
    },
    {
      "x": -6,
      "y": 13,
      "z": -7,
      "name": "Rock_Stone_Brick_Smooth"
    },
    {
      "x": -6,
      "y": 19,
      "z": -7,
      "name": "Rock_Stone_Brick_Smooth"
    },
    {
      "x": -6,
      "y": 13,
      "z": -6,
      "name": "Rock_Stone_Brick_Smooth"
    },
    {
      "x": -6,
      "y": 19,
      "z": -6,
      "name": "Rock_Stone_Brick_Smooth"
    },
    {
      "x": -6,
      "y": 13,
      "z": -5,
      "name": "Rock_Stone_Brick_Smooth"
    },
    {
      "x": -6,
      "y": 19,
      "z": -5,
      "name": "Rock_Stone_Brick_Smooth"
    },
    {
      "x": -6,
      "y": 13,
      "z": -4,
      "name": "Rock_Stone_Brick_Smooth"
    },
    {
      "x": -6,
      "y": 19,
      "z": -4,
      "name": "Rock_Stone_Brick_Smooth"
    },
    {
      "x": -6,
      "y": 13,
      "z": -3,
      "name": "Rock_Stone_Brick_Smooth"
    },
    {
      "x": -6,
      "y": 19,
      "z": -3,
      "name": "Rock_Stone_Brick_Smooth"
    },
    {
      "x": -6,
      "y": 13,
      "z": -2,
      "name": "Rock_Stone_Brick_Smooth"
    },
    {
      "x": -6,
      "y": 19,
      "z": -2,
      "name": "Rock_Stone_Brick_Smooth"
    },
    {
      "x": -6,
      "y": 13,
      "z": -1,
      "name": "Rock_Stone_Brick_Smooth"
    },
    {
      "x": -6,
      "y": 19,
      "z": -1,
      "name": "Rock_Stone_Brick_Smooth"
    },
    {
      "x": -6,
      "y": 13,
      "z": 0,
      "name": "Rock_Stone_Brick_Smooth"
    },
    {
      "x": -6,
      "y": 19,
      "z": 0,
      "name": "Rock_Stone_Brick_Smooth"
    },
    {
      "x": -6,
      "y": 13,
      "z": 1,
      "name": "Rock_Stone_Brick_Smooth"
    },
    {
      "x": -6,
      "y": 19,
      "z": 1,
      "name": "Rock_Stone_Brick_Smooth"
    },
    {
      "x": -6,
      "y": 13,
      "z": 2,
      "name": "Rock_Stone_Brick_Smooth"
    },
    {
      "x": -6,
      "y": 19,
      "z": 2,
      "name": "Rock_Stone_Brick_Smooth"
    },
    {
      "x": -6,
      "y": 13,
      "z": 3,
      "name": "Rock_Stone_Brick_Smooth"
    },
    {
      "x": -6,
      "y": 19,
      "z": 3,
      "name": "Rock_Stone_Brick_Smooth"
    },
    {
      "x": -6,
      "y": 13,
      "z": 4,
      "name": "Rock_Stone_Brick_Smooth"
    },
    {
      "x": -6,
      "y": 19,
      "z": 4,
      "name": "Rock_Stone_Brick_Smooth"
    },
    {
      "x": -6,
      "y": 13,
      "z": 5,
      "name": "Rock_Stone_Brick_Smooth"
    },
    {
      "x": -6,
      "y": 19,
      "z": 5,
      "name": "Rock_Stone_Brick_Smooth"
    },
    {
      "x": -6,
      "y": 13,
      "z": 6,
      "name": "Rock_Stone_Brick_Smooth"
    },
    {
      "x": -6,
      "y": 19,
      "z": 6,
      "name": "Rock_Stone_Brick_Smooth"
    },
    {
      "x": -6,
      "y": 13,
      "z": 7,
      "name": "Rock_Stone_Brick_Smooth"
    },
    {
      "x": -6,
      "y": 19,
      "z": 7,
      "name": "Rock_Stone_Brick_Smooth"
    },
    {
      "x": -6,
      "y": 13,
      "z": 8,
      "name": "Rock_Stone_Brick_Smooth"
    },
    {
      "x": -6,
      "y": 19,
      "z": 8,
      "name": "Rock_Stone_Brick_Smooth"
    },
    {
      "x": -6,
      "y": 13,
      "z": 9,
      "name": "Rock_Stone_Brick_Smooth"
    },
    {
      "x": -6,
      "y": 19,
      "z": 9,
      "name": "Rock_Stone_Brick_Smooth"
    },
    {
      "x": -6,
      "y": 13,
      "z": 10,
      "name": "Rock_Stone_Brick_Smooth"
    },
    {
      "x": -6,
      "y": 19,
      "z": 10,
      "name": "Rock_Stone_Brick_Smooth"
    },
    {
      "x": -6,
      "y": 13,
      "z": 11,
      "name": "Rock_Stone_Brick_Smooth"
    },
    {
      "x": -6,
      "y": 19,
      "z": 11,
      "name": "Rock_Stone_Brick_Smooth"
    },
    {
      "x": -6,
      "y": 13,
      "z": 12,
      "name": "Rock_Stone_Brick_Smooth"
    },
    {
      "x": -6,
      "y": 19,
      "z": 12,
      "name": "Rock_Stone_Brick_Smooth"
    },
    {
      "x": -6,
      "y": 13,
      "z": 13,
      "name": "Rock_Stone_Brick_Smooth"
    },
    {
      "x": -6,
      "y": 19,
      "z": 13,
      "name": "Rock_Stone_Brick_Smooth"
    },
    {
      "x": -6,
      "y": 13,
      "z": 14,
      "name": "Rock_Stone_Brick_Smooth"
    },
    {
      "x": -6,
      "y": 19,
      "z": 14,
      "name": "Rock_Stone_Brick_Smooth"
    },
    {
      "x": -6,
      "y": 13,
      "z": 15,
      "name": "Rock_Stone_Brick_Smooth"
    },
    {
      "x": -6,
      "y": 19,
      "z": 15,
      "name": "Rock_Stone_Brick_Smooth"
    },
    {
      "x": -6,
      "y": 13,
      "z": 16,
      "name": "Rock_Stone_Brick_Smooth"
    },
    {
      "x": -6,
      "y": 14,
      "z": 16,
      "name": "Rock_Stone_Brick_Decorative"
    },
    {
      "x": -6,
      "y": 15,
      "z": 16,
      "name": "Soil_Gravel_Half",
      "rotation": 6
    },
    {
      "x": -6,
      "y": 16,
      "z": 16,
      "name": "Soil_Gravel_Half",
      "rotation": 6
    },
    {
      "x": -6,
      "y": 17,
      "z": 16,
      "name": "Soil_Gravel_Half",
      "rotation": 6
    },
    {
      "x": -6,
      "y": 18,
      "z": 16,
      "name": "Soil_Gravel_Half",
      "rotation": 6
    },
    {
      "x": -6,
      "y": 19,
      "z": 16,
      "name": "Rock_Stone_Brick"
    },
    {
      "x": -5,
      "y": 13,
      "z": -16,
      "name": "Rock_Stone_Brick_Smooth"
    },
    {
      "x": -5,
      "y": 14,
      "z": -16,
      "name": "Rock_Stone_Brick_Decorative"
    },
    {
      "x": -5,
      "y": 15,
      "z": -16,
      "name": "Rock_Stone_Brick_Pillar_Base",
      "rotation": 2
    },
    {
      "x": -5,
      "y": 16,
      "z": -16,
      "name": "Rock_Stone_Brick_Pillar_Middle",
      "rotation": 2
    },
    {
      "x": -5,
      "y": 17,
      "z": -16,
      "name": "Rock_Stone_Brick_Pillar_Middle",
      "rotation": 2
    },
    {
      "x": -5,
      "y": 18,
      "z": -16,
      "name": "Rock_Stone_Brick_Pillar_Base",
      "rotation": 32
    },
    {
      "x": -5,
      "y": 19,
      "z": -16,
      "name": "Rock_Stone_Brick"
    },
    {
      "x": -5,
      "y": 13,
      "z": -15,
      "name": "Rock_Stone_Brick_Smooth"
    },
    {
      "x": -5,
      "y": 19,
      "z": -15,
      "name": "Rock_Stone_Brick_Smooth"
    },
    {
      "x": -5,
      "y": 13,
      "z": -14,
      "name": "Rock_Stone_Brick_Smooth"
    },
    {
      "x": -5,
      "y": 19,
      "z": -14,
      "name": "Rock_Stone_Brick_Smooth"
    },
    {
      "x": -5,
      "y": 13,
      "z": -13,
      "name": "Rock_Stone_Brick_Smooth"
    },
    {
      "x": -5,
      "y": 19,
      "z": -13,
      "name": "Rock_Stone_Brick_Smooth"
    },
    {
      "x": -5,
      "y": 13,
      "z": -12,
      "name": "Rock_Stone_Brick_Smooth"
    },
    {
      "x": -5,
      "y": 19,
      "z": -12,
      "name": "Rock_Stone_Brick_Smooth"
    },
    {
      "x": -5,
      "y": 13,
      "z": -11,
      "name": "Rock_Stone_Brick_Smooth"
    },
    {
      "x": -5,
      "y": 19,
      "z": -11,
      "name": "Rock_Stone_Brick_Smooth"
    },
    {
      "x": -5,
      "y": 13,
      "z": -10,
      "name": "Rock_Stone_Brick_Smooth"
    },
    {
      "x": -5,
      "y": 19,
      "z": -10,
      "name": "Rock_Stone_Brick_Smooth"
    },
    {
      "x": -5,
      "y": 13,
      "z": -9,
      "name": "Rock_Stone_Brick_Smooth"
    },
    {
      "x": -5,
      "y": 19,
      "z": -9,
      "name": "Rock_Stone_Brick_Smooth"
    },
    {
      "x": -5,
      "y": 13,
      "z": -8,
      "name": "Rock_Stone_Brick_Smooth"
    },
    {
      "x": -5,
      "y": 19,
      "z": -8,
      "name": "Rock_Stone_Brick_Smooth"
    },
    {
      "x": -5,
      "y": 13,
      "z": -7,
      "name": "Rock_Stone_Brick_Smooth"
    },
    {
      "x": -5,
      "y": 19,
      "z": -7,
      "name": "Rock_Stone_Brick_Smooth"
    },
    {
      "x": -5,
      "y": 13,
      "z": -6,
      "name": "Rock_Stone_Brick_Smooth"
    },
    {
      "x": -5,
      "y": 19,
      "z": -6,
      "name": "Rock_Stone_Brick_Smooth"
    },
    {
      "x": -5,
      "y": 13,
      "z": -5,
      "name": "Rock_Stone_Brick_Smooth"
    },
    {
      "x": -5,
      "y": 19,
      "z": -5,
      "name": "Rock_Stone_Brick_Smooth"
    },
    {
      "x": -5,
      "y": 13,
      "z": -4,
      "name": "Rock_Stone_Brick_Smooth"
    },
    {
      "x": -5,
      "y": 19,
      "z": -4,
      "name": "Rock_Stone_Brick_Smooth"
    },
    {
      "x": -5,
      "y": 13,
      "z": -3,
      "name": "Rock_Stone_Brick_Smooth"
    },
    {
      "x": -5,
      "y": 19,
      "z": -3,
      "name": "Rock_Stone_Brick_Smooth"
    },
    {
      "x": -5,
      "y": 13,
      "z": -2,
      "name": "Rock_Stone_Brick_Smooth"
    },
    {
      "x": -5,
      "y": 19,
      "z": -2,
      "name": "Rock_Stone_Brick_Smooth"
    },
    {
      "x": -5,
      "y": 13,
      "z": -1,
      "name": "Rock_Stone_Brick_Smooth"
    },
    {
      "x": -5,
      "y": 19,
      "z": -1,
      "name": "Rock_Stone_Brick_Smooth"
    },
    {
      "x": -5,
      "y": 13,
      "z": 0,
      "name": "Rock_Stone_Brick_Smooth"
    },
    {
      "x": -5,
      "y": 19,
      "z": 0,
      "name": "Rock_Stone_Brick_Smooth"
    },
    {
      "x": -5,
      "y": 13,
      "z": 1,
      "name": "Rock_Stone_Brick_Smooth"
    },
    {
      "x": -5,
      "y": 19,
      "z": 1,
      "name": "Rock_Stone_Brick_Smooth"
    },
    {
      "x": -5,
      "y": 13,
      "z": 2,
      "name": "Rock_Stone_Brick_Smooth"
    },
    {
      "x": -5,
      "y": 19,
      "z": 2,
      "name": "Rock_Stone_Brick_Smooth"
    },
    {
      "x": -5,
      "y": 13,
      "z": 3,
      "name": "Rock_Stone_Brick_Smooth"
    },
    {
      "x": -5,
      "y": 19,
      "z": 3,
      "name": "Rock_Stone_Brick_Smooth"
    },
    {
      "x": -5,
      "y": 13,
      "z": 4,
      "name": "Rock_Stone_Brick_Smooth"
    },
    {
      "x": -5,
      "y": 19,
      "z": 4,
      "name": "Rock_Stone_Brick_Smooth"
    },
    {
      "x": -5,
      "y": 13,
      "z": 5,
      "name": "Rock_Stone_Brick_Smooth"
    },
    {
      "x": -5,
      "y": 19,
      "z": 5,
      "name": "Rock_Stone_Brick_Smooth"
    },
    {
      "x": -5,
      "y": 13,
      "z": 6,
      "name": "Rock_Stone_Brick_Smooth"
    },
    {
      "x": -5,
      "y": 19,
      "z": 6,
      "name": "Rock_Stone_Brick_Smooth"
    },
    {
      "x": -5,
      "y": 13,
      "z": 7,
      "name": "Rock_Stone_Brick_Smooth"
    },
    {
      "x": -5,
      "y": 19,
      "z": 7,
      "name": "Rock_Stone_Brick_Smooth"
    },
    {
      "x": -5,
      "y": 13,
      "z": 8,
      "name": "Rock_Stone_Brick_Smooth"
    },
    {
      "x": -5,
      "y": 19,
      "z": 8,
      "name": "Rock_Stone_Brick_Smooth"
    },
    {
      "x": -5,
      "y": 13,
      "z": 9,
      "name": "Rock_Stone_Brick_Smooth"
    },
    {
      "x": -5,
      "y": 19,
      "z": 9,
      "name": "Rock_Stone_Brick_Smooth"
    },
    {
      "x": -5,
      "y": 13,
      "z": 10,
      "name": "Rock_Stone_Brick_Smooth"
    },
    {
      "x": -5,
      "y": 19,
      "z": 10,
      "name": "Rock_Stone_Brick_Smooth"
    },
    {
      "x": -5,
      "y": 13,
      "z": 11,
      "name": "Rock_Stone_Brick_Smooth"
    },
    {
      "x": -5,
      "y": 19,
      "z": 11,
      "name": "Rock_Stone_Brick_Smooth"
    },
    {
      "x": -5,
      "y": 13,
      "z": 12,
      "name": "Rock_Stone_Brick_Smooth"
    },
    {
      "x": -5,
      "y": 19,
      "z": 12,
      "name": "Rock_Stone_Brick_Smooth"
    },
    {
      "x": -5,
      "y": 13,
      "z": 13,
      "name": "Rock_Stone_Brick_Smooth"
    },
    {
      "x": -5,
      "y": 19,
      "z": 13,
      "name": "Rock_Stone_Brick_Smooth"
    },
    {
      "x": -5,
      "y": 13,
      "z": 14,
      "name": "Rock_Stone_Brick_Smooth"
    },
    {
      "x": -5,
      "y": 19,
      "z": 14,
      "name": "Rock_Stone_Brick_Smooth"
    },
    {
      "x": -5,
      "y": 13,
      "z": 15,
      "name": "Rock_Stone_Brick_Smooth"
    },
    {
      "x": -5,
      "y": 19,
      "z": 15,
      "name": "Rock_Stone_Brick_Smooth"
    },
    {
      "x": -5,
      "y": 13,
      "z": 16,
      "name": "Rock_Stone_Brick_Smooth"
    },
    {
      "x": -5,
      "y": 14,
      "z": 16,
      "name": "Rock_Stone_Brick_Decorative"
    },
    {
      "x": -5,
      "y": 15,
      "z": 16,
      "name": "Rock_Stone_Brick_Pillar_Base"
    },
    {
      "x": -5,
      "y": 16,
      "z": 16,
      "name": "Rock_Stone_Brick_Pillar_Middle"
    },
    {
      "x": -5,
      "y": 17,
      "z": 16,
      "name": "Rock_Stone_Brick_Pillar_Middle"
    },
    {
      "x": -5,
      "y": 18,
      "z": 16,
      "name": "Rock_Stone_Brick_Pillar_Base",
      "rotation": 8
    },
    {
      "x": -5,
      "y": 19,
      "z": 16,
      "name": "Rock_Stone_Brick"
    },
    {
      "x": -4,
      "y": 13,
      "z": -16,
      "name": "Rock_Stone_Brick_Smooth"
    },
    {
      "x": -4,
      "y": 14,
      "z": -16,
      "name": "Rock_Stone_Brick_Decorative"
    },
    {
      "x": -4,
      "y": 15,
      "z": -16,
      "name": "Soil_Gravel_Half",
      "rotation": 4
    },
    {
      "x": -4,
      "y": 16,
      "z": -16,
      "name": "Soil_Gravel_Half",
      "rotation": 4
    },
    {
      "x": -4,
      "y": 17,
      "z": -16,
      "name": "Soil_Gravel_Half",
      "rotation": 4
    },
    {
      "x": -4,
      "y": 18,
      "z": -16,
      "name": "Soil_Gravel_Half",
      "rotation": 4
    },
    {
      "x": -4,
      "y": 19,
      "z": -16,
      "name": "Rock_Stone_Brick"
    },
    {
      "x": -4,
      "y": 13,
      "z": -15,
      "name": "Rock_Stone_Brick_Smooth"
    },
    {
      "x": -4,
      "y": 19,
      "z": -15,
      "name": "Rock_Stone_Brick_Smooth"
    },
    {
      "x": -4,
      "y": 13,
      "z": -14,
      "name": "Rock_Stone_Brick_Smooth"
    },
    {
      "x": -4,
      "y": 19,
      "z": -14,
      "name": "Rock_Stone_Brick_Smooth"
    },
    {
      "x": -4,
      "y": 13,
      "z": -13,
      "name": "Rock_Stone_Brick_Smooth"
    },
    {
      "x": -4,
      "y": 19,
      "z": -13,
      "name": "Rock_Stone_Brick_Smooth"
    },
    {
      "x": -4,
      "y": 13,
      "z": -12,
      "name": "Rock_Stone_Brick_Smooth"
    },
    {
      "x": -4,
      "y": 19,
      "z": -12,
      "name": "Rock_Stone_Brick_Smooth"
    },
    {
      "x": -4,
      "y": 13,
      "z": -11,
      "name": "Rock_Stone_Brick_Smooth"
    },
    {
      "x": -4,
      "y": 19,
      "z": -11,
      "name": "Rock_Stone_Brick_Smooth"
    },
    {
      "x": -4,
      "y": 13,
      "z": -10,
      "name": "Rock_Stone_Brick_Smooth"
    },
    {
      "x": -4,
      "y": 19,
      "z": -10,
      "name": "Rock_Stone_Brick_Smooth"
    },
    {
      "x": -4,
      "y": 13,
      "z": -9,
      "name": "Rock_Stone_Brick_Smooth"
    },
    {
      "x": -4,
      "y": 19,
      "z": -9,
      "name": "Rock_Stone_Brick_Smooth"
    },
    {
      "x": -4,
      "y": 13,
      "z": -8,
      "name": "Rock_Stone_Brick_Smooth"
    },
    {
      "x": -4,
      "y": 19,
      "z": -8,
      "name": "Rock_Stone_Brick_Smooth"
    },
    {
      "x": -4,
      "y": 13,
      "z": -7,
      "name": "Rock_Stone_Brick_Smooth"
    },
    {
      "x": -4,
      "y": 19,
      "z": -7,
      "name": "Rock_Stone_Brick_Smooth"
    },
    {
      "x": -4,
      "y": 13,
      "z": -6,
      "name": "Rock_Stone_Brick_Smooth"
    },
    {
      "x": -4,
      "y": 19,
      "z": -6,
      "name": "Rock_Stone_Brick_Smooth"
    },
    {
      "x": -4,
      "y": 13,
      "z": -5,
      "name": "Rock_Stone_Brick_Smooth"
    },
    {
      "x": -4,
      "y": 19,
      "z": -5,
      "name": "Rock_Stone_Brick_Smooth"
    },
    {
      "x": -4,
      "y": 13,
      "z": -4,
      "name": "Rock_Stone_Brick_Smooth"
    },
    {
      "x": -4,
      "y": 19,
      "z": -4,
      "name": "Rock_Stone_Brick_Smooth"
    },
    {
      "x": -4,
      "y": 13,
      "z": -3,
      "name": "Rock_Stone_Brick_Smooth"
    },
    {
      "x": -4,
      "y": 19,
      "z": -3,
      "name": "Rock_Stone_Brick_Smooth"
    },
    {
      "x": -4,
      "y": 13,
      "z": -2,
      "name": "Rock_Stone_Brick_Smooth"
    },
    {
      "x": -4,
      "y": 19,
      "z": -2,
      "name": "Rock_Stone_Brick_Smooth"
    },
    {
      "x": -4,
      "y": 13,
      "z": -1,
      "name": "Rock_Stone_Brick_Smooth"
    },
    {
      "x": -4,
      "y": 19,
      "z": -1,
      "name": "Rock_Stone_Brick_Smooth"
    },
    {
      "x": -4,
      "y": 13,
      "z": 0,
      "name": "Rock_Stone_Brick_Smooth"
    },
    {
      "x": -4,
      "y": 19,
      "z": 0,
      "name": "Rock_Stone_Brick_Smooth"
    },
    {
      "x": -4,
      "y": 13,
      "z": 1,
      "name": "Rock_Stone_Brick_Smooth"
    },
    {
      "x": -4,
      "y": 19,
      "z": 1,
      "name": "Rock_Stone_Brick_Smooth"
    },
    {
      "x": -4,
      "y": 13,
      "z": 2,
      "name": "Rock_Stone_Brick_Smooth"
    },
    {
      "x": -4,
      "y": 19,
      "z": 2,
      "name": "Rock_Stone_Brick_Smooth"
    },
    {
      "x": -4,
      "y": 13,
      "z": 3,
      "name": "Rock_Stone_Brick_Smooth"
    },
    {
      "x": -4,
      "y": 19,
      "z": 3,
      "name": "Rock_Stone_Brick_Smooth"
    },
    {
      "x": -4,
      "y": 13,
      "z": 4,
      "name": "Rock_Stone_Brick_Smooth"
    },
    {
      "x": -4,
      "y": 19,
      "z": 4,
      "name": "Rock_Stone_Brick_Smooth"
    },
    {
      "x": -4,
      "y": 13,
      "z": 5,
      "name": "Rock_Stone_Brick_Smooth"
    },
    {
      "x": -4,
      "y": 19,
      "z": 5,
      "name": "Rock_Stone_Brick_Smooth"
    },
    {
      "x": -4,
      "y": 13,
      "z": 6,
      "name": "Rock_Stone_Brick_Smooth"
    },
    {
      "x": -4,
      "y": 19,
      "z": 6,
      "name": "Rock_Stone_Brick_Smooth"
    },
    {
      "x": -4,
      "y": 13,
      "z": 7,
      "name": "Rock_Stone_Brick_Smooth"
    },
    {
      "x": -4,
      "y": 19,
      "z": 7,
      "name": "Rock_Stone_Brick_Smooth"
    },
    {
      "x": -4,
      "y": 13,
      "z": 8,
      "name": "Rock_Stone_Brick_Smooth"
    },
    {
      "x": -4,
      "y": 19,
      "z": 8,
      "name": "Rock_Stone_Brick_Smooth"
    },
    {
      "x": -4,
      "y": 13,
      "z": 9,
      "name": "Rock_Stone_Brick_Smooth"
    },
    {
      "x": -4,
      "y": 19,
      "z": 9,
      "name": "Rock_Stone_Brick_Smooth"
    },
    {
      "x": -4,
      "y": 13,
      "z": 10,
      "name": "Rock_Stone_Brick_Smooth"
    },
    {
      "x": -4,
      "y": 19,
      "z": 10,
      "name": "Rock_Stone_Brick_Smooth"
    },
    {
      "x": -4,
      "y": 13,
      "z": 11,
      "name": "Rock_Stone_Brick_Smooth"
    },
    {
      "x": -4,
      "y": 19,
      "z": 11,
      "name": "Rock_Stone_Brick_Smooth"
    },
    {
      "x": -4,
      "y": 13,
      "z": 12,
      "name": "Rock_Stone_Brick_Smooth"
    },
    {
      "x": -4,
      "y": 19,
      "z": 12,
      "name": "Rock_Stone_Brick_Smooth"
    },
    {
      "x": -4,
      "y": 13,
      "z": 13,
      "name": "Rock_Stone_Brick_Smooth"
    },
    {
      "x": -4,
      "y": 19,
      "z": 13,
      "name": "Rock_Stone_Brick_Smooth"
    },
    {
      "x": -4,
      "y": 13,
      "z": 14,
      "name": "Rock_Stone_Brick_Smooth"
    },
    {
      "x": -4,
      "y": 19,
      "z": 14,
      "name": "Rock_Stone_Brick_Smooth"
    },
    {
      "x": -4,
      "y": 13,
      "z": 15,
      "name": "Rock_Stone_Brick_Smooth"
    },
    {
      "x": -4,
      "y": 19,
      "z": 15,
      "name": "Rock_Stone_Brick_Smooth"
    },
    {
      "x": -4,
      "y": 13,
      "z": 16,
      "name": "Rock_Stone_Brick_Smooth"
    },
    {
      "x": -4,
      "y": 14,
      "z": 16,
      "name": "Rock_Stone_Brick_Decorative"
    },
    {
      "x": -4,
      "y": 15,
      "z": 16,
      "name": "Soil_Gravel_Half",
      "rotation": 6
    },
    {
      "x": -4,
      "y": 16,
      "z": 16,
      "name": "Soil_Gravel_Half",
      "support": 15,
      "rotation": 6
    },
    {
      "x": -4,
      "y": 17,
      "z": 16,
      "name": "Soil_Gravel_Half",
      "support": 15,
      "rotation": 6
    },
    {
      "x": -4,
      "y": 18,
      "z": 16,
      "name": "Soil_Gravel_Half",
      "support": 15,
      "rotation": 6
    },
    {
      "x": -4,
      "y": 19,
      "z": 16,
      "name": "Rock_Stone_Brick"
    },
    {
      "x": -3,
      "y": 13,
      "z": -16,
      "name": "Rock_Stone_Brick_Smooth"
    },
    {
      "x": -3,
      "y": 14,
      "z": -16,
      "name": "Rock_Stone_Brick_Decorative"
    },
    {
      "x": -3,
      "y": 15,
      "z": -16,
      "name": "Soil_Gravel_Half",
      "rotation": 4
    },
    {
      "x": -3,
      "y": 16,
      "z": -16,
      "name": "Soil_Gravel_Half",
      "rotation": 4
    },
    {
      "x": -3,
      "y": 17,
      "z": -16,
      "name": "Soil_Gravel_Half",
      "rotation": 4
    },
    {
      "x": -3,
      "y": 18,
      "z": -16,
      "name": "Soil_Gravel_Half",
      "rotation": 4
    },
    {
      "x": -3,
      "y": 19,
      "z": -16,
      "name": "Rock_Stone_Brick"
    },
    {
      "x": -3,
      "y": 13,
      "z": -15,
      "name": "Rock_Stone_Brick_Smooth"
    },
    {
      "x": -3,
      "y": 19,
      "z": -15,
      "name": "Rock_Stone_Brick_Smooth"
    },
    {
      "x": -3,
      "y": 13,
      "z": -14,
      "name": "Rock_Stone_Brick_Smooth"
    },
    {
      "x": -3,
      "y": 19,
      "z": -14,
      "name": "Rock_Stone_Brick_Smooth"
    },
    {
      "x": -3,
      "y": 13,
      "z": -13,
      "name": "Rock_Stone_Brick_Smooth"
    },
    {
      "x": -3,
      "y": 19,
      "z": -13,
      "name": "Rock_Stone_Brick_Smooth"
    },
    {
      "x": -3,
      "y": 13,
      "z": -12,
      "name": "Rock_Stone_Brick_Smooth"
    },
    {
      "x": -3,
      "y": 19,
      "z": -12,
      "name": "Rock_Stone_Brick_Smooth"
    },
    {
      "x": -3,
      "y": 13,
      "z": -11,
      "name": "Rock_Stone_Brick_Smooth"
    },
    {
      "x": -3,
      "y": 19,
      "z": -11,
      "name": "Rock_Stone_Brick_Smooth"
    },
    {
      "x": -3,
      "y": 13,
      "z": -10,
      "name": "Rock_Stone_Brick_Smooth"
    },
    {
      "x": -3,
      "y": 19,
      "z": -10,
      "name": "Rock_Stone_Brick_Smooth"
    },
    {
      "x": -3,
      "y": 13,
      "z": -9,
      "name": "Rock_Stone_Brick_Smooth"
    },
    {
      "x": -3,
      "y": 19,
      "z": -9,
      "name": "Rock_Stone_Brick_Smooth"
    },
    {
      "x": -3,
      "y": 13,
      "z": -8,
      "name": "Rock_Stone_Brick_Smooth"
    },
    {
      "x": -3,
      "y": 19,
      "z": -8,
      "name": "Rock_Stone_Brick_Smooth"
    },
    {
      "x": -3,
      "y": 13,
      "z": -7,
      "name": "Rock_Stone_Brick_Smooth"
    },
    {
      "x": -3,
      "y": 19,
      "z": -7,
      "name": "Rock_Stone_Brick_Smooth"
    },
    {
      "x": -3,
      "y": 13,
      "z": -6,
      "name": "Rock_Stone_Brick_Smooth"
    },
    {
      "x": -3,
      "y": 19,
      "z": -6,
      "name": "Rock_Stone_Brick_Smooth"
    },
    {
      "x": -3,
      "y": 13,
      "z": -5,
      "name": "Rock_Stone_Brick_Smooth"
    },
    {
      "x": -3,
      "y": 19,
      "z": -5,
      "name": "Rock_Stone_Brick_Smooth"
    },
    {
      "x": -3,
      "y": 13,
      "z": -4,
      "name": "Rock_Stone_Brick_Smooth"
    },
    {
      "x": -3,
      "y": 19,
      "z": -4,
      "name": "Rock_Stone_Brick_Smooth"
    },
    {
      "x": -3,
      "y": 13,
      "z": -3,
      "name": "Rock_Stone_Brick_Smooth"
    },
    {
      "x": -3,
      "y": 19,
      "z": -3,
      "name": "Rock_Stone_Brick_Smooth"
    },
    {
      "x": -3,
      "y": 13,
      "z": -2,
      "name": "Rock_Stone_Brick_Smooth"
    },
    {
      "x": -3,
      "y": 19,
      "z": -2,
      "name": "Rock_Stone_Brick_Smooth"
    },
    {
      "x": -3,
      "y": 13,
      "z": -1,
      "name": "Rock_Stone_Brick_Smooth"
    },
    {
      "x": -3,
      "y": 19,
      "z": -1,
      "name": "Rock_Stone_Brick_Smooth"
    },
    {
      "x": -3,
      "y": 13,
      "z": 0,
      "name": "Rock_Stone_Brick_Smooth"
    },
    {
      "x": -3,
      "y": 19,
      "z": 0,
      "name": "Rock_Stone_Brick_Smooth"
    },
    {
      "x": -3,
      "y": 13,
      "z": 1,
      "name": "Rock_Stone_Brick_Smooth"
    },
    {
      "x": -3,
      "y": 19,
      "z": 1,
      "name": "Rock_Stone_Brick_Smooth"
    },
    {
      "x": -3,
      "y": 13,
      "z": 2,
      "name": "Rock_Stone_Brick_Smooth"
    },
    {
      "x": -3,
      "y": 19,
      "z": 2,
      "name": "Rock_Stone_Brick_Smooth"
    },
    {
      "x": -3,
      "y": 13,
      "z": 3,
      "name": "Rock_Stone_Brick_Smooth"
    },
    {
      "x": -3,
      "y": 19,
      "z": 3,
      "name": "Rock_Stone_Brick_Smooth"
    },
    {
      "x": -3,
      "y": 13,
      "z": 4,
      "name": "Rock_Stone_Brick_Smooth"
    },
    {
      "x": -3,
      "y": 19,
      "z": 4,
      "name": "Rock_Stone_Brick_Smooth"
    },
    {
      "x": -3,
      "y": 13,
      "z": 5,
      "name": "Rock_Stone_Brick_Smooth"
    },
    {
      "x": -3,
      "y": 19,
      "z": 5,
      "name": "Rock_Stone_Brick_Smooth"
    },
    {
      "x": -3,
      "y": 13,
      "z": 6,
      "name": "Rock_Stone_Brick_Smooth"
    },
    {
      "x": -3,
      "y": 19,
      "z": 6,
      "name": "Rock_Stone_Brick_Smooth"
    },
    {
      "x": -3,
      "y": 13,
      "z": 7,
      "name": "Rock_Stone_Brick_Smooth"
    },
    {
      "x": -3,
      "y": 19,
      "z": 7,
      "name": "Rock_Stone_Brick_Smooth"
    },
    {
      "x": -3,
      "y": 13,
      "z": 8,
      "name": "Rock_Stone_Brick_Smooth"
    },
    {
      "x": -3,
      "y": 19,
      "z": 8,
      "name": "Rock_Stone_Brick_Smooth"
    },
    {
      "x": -3,
      "y": 13,
      "z": 9,
      "name": "Rock_Stone_Brick_Smooth"
    },
    {
      "x": -3,
      "y": 19,
      "z": 9,
      "name": "Rock_Stone_Brick_Smooth"
    },
    {
      "x": -3,
      "y": 13,
      "z": 10,
      "name": "Rock_Stone_Brick_Smooth"
    },
    {
      "x": -3,
      "y": 19,
      "z": 10,
      "name": "Rock_Stone_Brick_Smooth"
    },
    {
      "x": -3,
      "y": 13,
      "z": 11,
      "name": "Rock_Stone_Brick_Smooth"
    },
    {
      "x": -3,
      "y": 19,
      "z": 11,
      "name": "Rock_Stone_Brick_Smooth"
    },
    {
      "x": -3,
      "y": 13,
      "z": 12,
      "name": "Rock_Stone_Brick_Smooth"
    },
    {
      "x": -3,
      "y": 19,
      "z": 12,
      "name": "Rock_Stone_Brick_Smooth"
    },
    {
      "x": -3,
      "y": 13,
      "z": 13,
      "name": "Rock_Stone_Brick_Smooth"
    },
    {
      "x": -3,
      "y": 19,
      "z": 13,
      "name": "Rock_Stone_Brick_Smooth"
    },
    {
      "x": -3,
      "y": 13,
      "z": 14,
      "name": "Rock_Stone_Brick_Smooth"
    },
    {
      "x": -3,
      "y": 19,
      "z": 14,
      "name": "Rock_Stone_Brick_Smooth"
    },
    {
      "x": -3,
      "y": 13,
      "z": 15,
      "name": "Rock_Stone_Brick_Smooth"
    },
    {
      "x": -3,
      "y": 19,
      "z": 15,
      "name": "Rock_Stone_Brick_Smooth"
    },
    {
      "x": -3,
      "y": 13,
      "z": 16,
      "name": "Rock_Stone_Brick_Smooth"
    },
    {
      "x": -3,
      "y": 14,
      "z": 16,
      "name": "Rock_Stone_Brick_Decorative"
    },
    {
      "x": -3,
      "y": 15,
      "z": 16,
      "name": "Soil_Gravel_Half",
      "rotation": 6
    },
    {
      "x": -3,
      "y": 16,
      "z": 16,
      "name": "Soil_Gravel_Half",
      "rotation": 6
    },
    {
      "x": -3,
      "y": 17,
      "z": 16,
      "name": "Soil_Gravel_Half",
      "rotation": 6
    },
    {
      "x": -3,
      "y": 18,
      "z": 16,
      "name": "Soil_Gravel_Half",
      "rotation": 6
    },
    {
      "x": -3,
      "y": 19,
      "z": 16,
      "name": "Rock_Stone_Brick"
    },
    {
      "x": -2,
      "y": 13,
      "z": -16,
      "name": "Rock_Stone_Brick_Smooth"
    },
    {
      "x": -2,
      "y": 14,
      "z": -16,
      "name": "Rock_Stone_Brick_Decorative"
    },
    {
      "x": -2,
      "y": 15,
      "z": -16,
      "name": "Soil_Gravel_Half",
      "rotation": 4
    },
    {
      "x": -2,
      "y": 16,
      "z": -16,
      "name": "Soil_Gravel_Half",
      "rotation": 4
    },
    {
      "x": -2,
      "y": 17,
      "z": -16,
      "name": "Soil_Gravel_Half",
      "rotation": 4
    },
    {
      "x": -2,
      "y": 18,
      "z": -16,
      "name": "Soil_Gravel_Half",
      "rotation": 4
    },
    {
      "x": -2,
      "y": 19,
      "z": -16,
      "name": "Rock_Stone_Brick"
    },
    {
      "x": -2,
      "y": 13,
      "z": -15,
      "name": "Rock_Stone_Brick_Smooth"
    },
    {
      "x": -2,
      "y": 19,
      "z": -15,
      "name": "Rock_Stone_Brick_Smooth"
    },
    {
      "x": -2,
      "y": 13,
      "z": -14,
      "name": "Rock_Stone_Brick_Smooth"
    },
    {
      "x": -2,
      "y": 19,
      "z": -14,
      "name": "Rock_Stone_Brick_Smooth"
    },
    {
      "x": -2,
      "y": 13,
      "z": -13,
      "name": "Rock_Stone_Brick_Smooth"
    },
    {
      "x": -2,
      "y": 19,
      "z": -13,
      "name": "Rock_Stone_Brick_Smooth"
    },
    {
      "x": -2,
      "y": 13,
      "z": -12,
      "name": "Rock_Stone_Brick_Smooth"
    },
    {
      "x": -2,
      "y": 19,
      "z": -12,
      "name": "Rock_Stone_Brick_Smooth"
    },
    {
      "x": -2,
      "y": 13,
      "z": -11,
      "name": "Rock_Stone_Brick_Smooth"
    },
    {
      "x": -2,
      "y": 19,
      "z": -11,
      "name": "Rock_Stone_Brick_Smooth"
    },
    {
      "x": -2,
      "y": 13,
      "z": -10,
      "name": "Rock_Stone_Brick_Smooth"
    },
    {
      "x": -2,
      "y": 19,
      "z": -10,
      "name": "Rock_Stone_Brick_Smooth"
    },
    {
      "x": -2,
      "y": 13,
      "z": -9,
      "name": "Rock_Stone_Brick_Smooth"
    },
    {
      "x": -2,
      "y": 19,
      "z": -9,
      "name": "Rock_Stone_Brick_Smooth"
    },
    {
      "x": -2,
      "y": 13,
      "z": -8,
      "name": "Rock_Stone_Brick_Smooth"
    },
    {
      "x": -2,
      "y": 19,
      "z": -8,
      "name": "Rock_Stone_Brick_Smooth"
    },
    {
      "x": -2,
      "y": 13,
      "z": -7,
      "name": "Rock_Stone_Brick_Smooth"
    },
    {
      "x": -2,
      "y": 19,
      "z": -7,
      "name": "Rock_Stone_Brick_Smooth"
    },
    {
      "x": -2,
      "y": 13,
      "z": -6,
      "name": "Rock_Stone_Brick_Smooth"
    },
    {
      "x": -2,
      "y": 19,
      "z": -6,
      "name": "Rock_Stone_Brick_Smooth"
    },
    {
      "x": -2,
      "y": 13,
      "z": -5,
      "name": "Rock_Stone_Brick_Smooth"
    },
    {
      "x": -2,
      "y": 19,
      "z": -5,
      "name": "Rock_Stone_Brick_Smooth"
    },
    {
      "x": -2,
      "y": 13,
      "z": -4,
      "name": "Rock_Stone_Brick_Smooth"
    },
    {
      "x": -2,
      "y": 19,
      "z": -4,
      "name": "Rock_Stone_Brick_Smooth"
    },
    {
      "x": -2,
      "y": 13,
      "z": -3,
      "name": "Rock_Stone_Brick_Smooth"
    },
    {
      "x": -2,
      "y": 19,
      "z": -3,
      "name": "Rock_Stone_Brick_Smooth"
    },
    {
      "x": -2,
      "y": 13,
      "z": -2,
      "name": "Rock_Stone_Brick_Smooth"
    },
    {
      "x": -2,
      "y": 19,
      "z": -2,
      "name": "Rock_Stone_Brick_Smooth"
    },
    {
      "x": -2,
      "y": 13,
      "z": -1,
      "name": "Rock_Stone_Brick_Smooth"
    },
    {
      "x": -2,
      "y": 19,
      "z": -1,
      "name": "Rock_Stone_Brick_Smooth"
    },
    {
      "x": -2,
      "y": 13,
      "z": 0,
      "name": "Rock_Stone_Brick_Smooth"
    },
    {
      "x": -2,
      "y": 19,
      "z": 0,
      "name": "Rock_Stone_Brick_Smooth"
    },
    {
      "x": -2,
      "y": 13,
      "z": 1,
      "name": "Rock_Stone_Brick_Smooth"
    },
    {
      "x": -2,
      "y": 19,
      "z": 1,
      "name": "Rock_Stone_Brick_Smooth"
    },
    {
      "x": -2,
      "y": 13,
      "z": 2,
      "name": "Rock_Stone_Brick_Smooth"
    },
    {
      "x": -2,
      "y": 19,
      "z": 2,
      "name": "Rock_Stone_Brick_Smooth"
    },
    {
      "x": -2,
      "y": 13,
      "z": 3,
      "name": "Rock_Stone_Brick_Smooth"
    },
    {
      "x": -2,
      "y": 19,
      "z": 3,
      "name": "Rock_Stone_Brick_Smooth"
    },
    {
      "x": -2,
      "y": 13,
      "z": 4,
      "name": "Rock_Stone_Brick_Smooth"
    },
    {
      "x": -2,
      "y": 19,
      "z": 4,
      "name": "Rock_Stone_Brick_Smooth"
    },
    {
      "x": -2,
      "y": 13,
      "z": 5,
      "name": "Rock_Stone_Brick_Smooth"
    },
    {
      "x": -2,
      "y": 19,
      "z": 5,
      "name": "Rock_Stone_Brick_Smooth"
    },
    {
      "x": -2,
      "y": 13,
      "z": 6,
      "name": "Rock_Stone_Brick_Smooth"
    },
    {
      "x": -2,
      "y": 19,
      "z": 6,
      "name": "Rock_Stone_Brick_Smooth"
    },
    {
      "x": -2,
      "y": 13,
      "z": 7,
      "name": "Rock_Stone_Brick_Smooth"
    },
    {
      "x": -2,
      "y": 19,
      "z": 7,
      "name": "Rock_Stone_Brick_Smooth"
    },
    {
      "x": -2,
      "y": 13,
      "z": 8,
      "name": "Rock_Stone_Brick_Smooth"
    },
    {
      "x": -2,
      "y": 19,
      "z": 8,
      "name": "Rock_Stone_Brick_Smooth"
    },
    {
      "x": -2,
      "y": 13,
      "z": 9,
      "name": "Rock_Stone_Brick_Smooth"
    },
    {
      "x": -2,
      "y": 19,
      "z": 9,
      "name": "Rock_Stone_Brick_Smooth"
    },
    {
      "x": -2,
      "y": 13,
      "z": 10,
      "name": "Rock_Stone_Brick_Smooth"
    },
    {
      "x": -2,
      "y": 19,
      "z": 10,
      "name": "Rock_Stone_Brick_Smooth"
    },
    {
      "x": -2,
      "y": 13,
      "z": 11,
      "name": "Rock_Stone_Brick_Smooth"
    },
    {
      "x": -2,
      "y": 19,
      "z": 11,
      "name": "Rock_Stone_Brick_Smooth"
    },
    {
      "x": -2,
      "y": 13,
      "z": 12,
      "name": "Rock_Stone_Brick_Smooth"
    },
    {
      "x": -2,
      "y": 19,
      "z": 12,
      "name": "Rock_Stone_Brick_Smooth"
    },
    {
      "x": -2,
      "y": 13,
      "z": 13,
      "name": "Rock_Stone_Brick_Smooth"
    },
    {
      "x": -2,
      "y": 19,
      "z": 13,
      "name": "Rock_Stone_Brick_Smooth"
    },
    {
      "x": -2,
      "y": 13,
      "z": 14,
      "name": "Rock_Stone_Brick_Smooth"
    },
    {
      "x": -2,
      "y": 19,
      "z": 14,
      "name": "Rock_Stone_Brick_Smooth"
    },
    {
      "x": -2,
      "y": 13,
      "z": 15,
      "name": "Rock_Stone_Brick_Smooth"
    },
    {
      "x": -2,
      "y": 19,
      "z": 15,
      "name": "Rock_Stone_Brick_Smooth"
    },
    {
      "x": -2,
      "y": 13,
      "z": 16,
      "name": "Rock_Stone_Brick_Smooth"
    },
    {
      "x": -2,
      "y": 14,
      "z": 16,
      "name": "Rock_Stone_Brick_Decorative"
    },
    {
      "x": -2,
      "y": 15,
      "z": 16,
      "name": "Soil_Gravel_Half",
      "rotation": 6
    },
    {
      "x": -2,
      "y": 16,
      "z": 16,
      "name": "Soil_Gravel_Half",
      "rotation": 6
    },
    {
      "x": -2,
      "y": 17,
      "z": 16,
      "name": "Soil_Gravel_Half",
      "rotation": 6
    },
    {
      "x": -2,
      "y": 18,
      "z": 16,
      "name": "Soil_Gravel_Half",
      "rotation": 6
    },
    {
      "x": -2,
      "y": 19,
      "z": 16,
      "name": "Rock_Stone_Brick"
    },
    {
      "x": -1,
      "y": 13,
      "z": -16,
      "name": "Rock_Stone_Brick_Smooth"
    },
    {
      "x": -1,
      "y": 14,
      "z": -16,
      "name": "Rock_Stone_Brick"
    },
    {
      "x": -1,
      "y": 15,
      "z": -16,
      "name": "Rock_Stone_Brick"
    },
    {
      "x": -1,
      "y": 16,
      "z": -16,
      "name": "Rock_Stone_Brick"
    },
    {
      "x": -1,
      "y": 17,
      "z": -16,
      "name": "Rock_Stone_Brick"
    },
    {
      "x": -1,
      "y": 18,
      "z": -16,
      "name": "Rock_Stone_Brick"
    },
    {
      "x": -1,
      "y": 19,
      "z": -16,
      "name": "Rock_Stone_Brick_Smooth"
    },
    {
      "x": -1,
      "y": 13,
      "z": -15,
      "name": "Rock_Stone_Brick_Smooth"
    },
    {
      "x": -1,
      "y": 14,
      "z": -15,
      "name": "Rock_Stone_Brick_Decorative"
    },
    {
      "x": -1,
      "y": 15,
      "z": -15,
      "name": "Soil_Gravel_Half",
      "rotation": 7
    },
    {
      "x": -1,
      "y": 16,
      "z": -15,
      "name": "Soil_Gravel_Half",
      "rotation": 7
    },
    {
      "x": -1,
      "y": 17,
      "z": -15,
      "name": "Soil_Gravel_Half",
      "rotation": 7
    },
    {
      "x": -1,
      "y": 18,
      "z": -15,
      "name": "Soil_Gravel_Half",
      "rotation": 7
    },
    {
      "x": -1,
      "y": 19,
      "z": -15,
      "name": "Rock_Stone_Brick"
    },
    {
      "x": -1,
      "y": 13,
      "z": -14,
      "name": "Rock_Stone_Brick_Smooth"
    },
    {
      "x": -1,
      "y": 14,
      "z": -14,
      "name": "Rock_Stone_Brick_Decorative"
    },
    {
      "x": -1,
      "y": 15,
      "z": -14,
      "name": "Soil_Gravel_Half",
      "rotation": 7
    },
    {
      "x": -1,
      "y": 16,
      "z": -14,
      "name": "Soil_Gravel_Half",
      "rotation": 7
    },
    {
      "x": -1,
      "y": 17,
      "z": -14,
      "name": "Soil_Gravel_Half",
      "rotation": 7
    },
    {
      "x": -1,
      "y": 18,
      "z": -14,
      "name": "Soil_Gravel_Half",
      "rotation": 7
    },
    {
      "x": -1,
      "y": 19,
      "z": -14,
      "name": "Rock_Stone_Brick"
    },
    {
      "x": -1,
      "y": 13,
      "z": -13,
      "name": "Rock_Stone_Brick_Smooth"
    },
    {
      "x": -1,
      "y": 14,
      "z": -13,
      "name": "Rock_Stone_Brick_Decorative"
    },
    {
      "x": -1,
      "y": 15,
      "z": -13,
      "name": "Rock_Stone_Brick_Pillar_Base",
      "rotation": 2
    },
    {
      "x": -1,
      "y": 16,
      "z": -13,
      "name": "Rock_Stone_Brick_Pillar_Middle",
      "rotation": 2
    },
    {
      "x": -1,
      "y": 17,
      "z": -13,
      "name": "Rock_Stone_Brick_Pillar_Middle",
      "rotation": 2
    },
    {
      "x": -1,
      "y": 18,
      "z": -13,
      "name": "Rock_Stone_Brick_Pillar_Base",
      "rotation": 32
    },
    {
      "x": -1,
      "y": 19,
      "z": -13,
      "name": "Rock_Stone_Brick_Smooth"
    },
    {
      "x": -1,
      "y": 13,
      "z": -12,
      "name": "Rock_Stone_Brick_Smooth"
    },
    {
      "x": -1,
      "y": 19,
      "z": -12,
      "name": "Rock_Stone_Brick_Smooth"
    },
    {
      "x": -1,
      "y": 13,
      "z": -11,
      "name": "Rock_Stone_Brick_Smooth"
    },
    {
      "x": -1,
      "y": 19,
      "z": -11,
      "name": "Rock_Stone_Brick_Smooth"
    },
    {
      "x": -1,
      "y": 13,
      "z": -10,
      "name": "Rock_Stone_Brick_Smooth"
    },
    {
      "x": -1,
      "y": 19,
      "z": -10,
      "name": "Rock_Stone_Brick_Smooth"
    },
    {
      "x": -1,
      "y": 13,
      "z": -9,
      "name": "Rock_Stone_Brick_Smooth"
    },
    {
      "x": -1,
      "y": 14,
      "z": -9,
      "name": "Rock_Stone_Brick_Decorative"
    },
    {
      "x": -1,
      "y": 15,
      "z": -9,
      "name": "Rock_Stone_Brick_Pillar_Base",
      "rotation": 2
    },
    {
      "x": -1,
      "y": 16,
      "z": -9,
      "name": "Rock_Stone_Brick_Pillar_Middle",
      "rotation": 2
    },
    {
      "x": -1,
      "y": 17,
      "z": -9,
      "name": "Rock_Stone_Brick_Pillar_Middle",
      "rotation": 2
    },
    {
      "x": -1,
      "y": 18,
      "z": -9,
      "name": "Rock_Stone_Brick_Pillar_Base",
      "rotation": 32
    },
    {
      "x": -1,
      "y": 19,
      "z": -9,
      "name": "Rock_Stone_Brick_Smooth"
    },
    {
      "x": -1,
      "y": 13,
      "z": -8,
      "name": "Rock_Stone_Brick_Smooth"
    },
    {
      "x": -1,
      "y": 14,
      "z": -8,
      "name": "Rock_Stone_Brick_Decorative"
    },
    {
      "x": -1,
      "y": 15,
      "z": -8,
      "name": "Soil_Gravel_Half",
      "rotation": 7
    },
    {
      "x": -1,
      "y": 16,
      "z": -8,
      "name": "Soil_Gravel_Half",
      "rotation": 7
    },
    {
      "x": -1,
      "y": 17,
      "z": -8,
      "name": "Soil_Gravel_Half",
      "rotation": 7
    },
    {
      "x": -1,
      "y": 18,
      "z": -8,
      "name": "Soil_Gravel_Half",
      "rotation": 7
    },
    {
      "x": -1,
      "y": 19,
      "z": -8,
      "name": "Rock_Stone_Brick"
    },
    {
      "x": -1,
      "y": 13,
      "z": -7,
      "name": "Rock_Stone_Brick_Smooth"
    },
    {
      "x": -1,
      "y": 14,
      "z": -7,
      "name": "Rock_Stone_Brick_Decorative"
    },
    {
      "x": -1,
      "y": 15,
      "z": -7,
      "name": "Soil_Gravel_Half",
      "rotation": 7
    },
    {
      "x": -1,
      "y": 16,
      "z": -7,
      "name": "Soil_Gravel_Half",
      "rotation": 7
    },
    {
      "x": -1,
      "y": 17,
      "z": -7,
      "name": "Soil_Gravel_Half",
      "rotation": 7
    },
    {
      "x": -1,
      "y": 18,
      "z": -7,
      "name": "Soil_Gravel_Half",
      "rotation": 7
    },
    {
      "x": -1,
      "y": 19,
      "z": -7,
      "name": "Rock_Stone_Brick"
    },
    {
      "x": -1,
      "y": 13,
      "z": -6,
      "name": "Rock_Stone_Brick_Smooth"
    },
    {
      "x": -1,
      "y": 14,
      "z": -6,
      "name": "Rock_Stone_Brick_Decorative"
    },
    {
      "x": -1,
      "y": 15,
      "z": -6,
      "name": "Rock_Stone_Brick_Pillar_Base",
      "rotation": 2
    },
    {
      "x": -1,
      "y": 16,
      "z": -6,
      "name": "Rock_Stone_Brick_Pillar_Middle",
      "rotation": 2
    },
    {
      "x": -1,
      "y": 17,
      "z": -6,
      "name": "Rock_Stone_Brick_Pillar_Middle",
      "rotation": 2
    },
    {
      "x": -1,
      "y": 18,
      "z": -6,
      "name": "Rock_Stone_Brick_Pillar_Base",
      "rotation": 32
    },
    {
      "x": -1,
      "y": 19,
      "z": -6,
      "name": "Rock_Stone_Brick"
    },
    {
      "x": -1,
      "y": 13,
      "z": -5,
      "name": "Rock_Stone_Brick_Smooth"
    },
    {
      "x": -1,
      "y": 14,
      "z": -5,
      "name": "Rock_Stone_Brick_Decorative"
    },
    {
      "x": -1,
      "y": 15,
      "z": -5,
      "name": "Soil_Gravel_Half",
      "rotation": 7
    },
    {
      "x": -1,
      "y": 16,
      "z": -5,
      "name": "Soil_Gravel_Half",
      "rotation": 7
    },
    {
      "x": -1,
      "y": 17,
      "z": -5,
      "name": "Soil_Gravel_Half",
      "rotation": 7
    },
    {
      "x": -1,
      "y": 18,
      "z": -5,
      "name": "Soil_Gravel_Half",
      "rotation": 7
    },
    {
      "x": -1,
      "y": 19,
      "z": -5,
      "name": "Rock_Stone_Brick"
    },
    {
      "x": -1,
      "y": 13,
      "z": -4,
      "name": "Rock_Stone_Brick_Smooth"
    },
    {
      "x": -1,
      "y": 14,
      "z": -4,
      "name": "Rock_Stone_Brick_Decorative"
    },
    {
      "x": -1,
      "y": 15,
      "z": -4,
      "name": "Soil_Gravel_Half",
      "rotation": 7
    },
    {
      "x": -1,
      "y": 16,
      "z": -4,
      "name": "Soil_Gravel_Half",
      "rotation": 7
    },
    {
      "x": -1,
      "y": 17,
      "z": -4,
      "name": "Soil_Gravel_Half",
      "rotation": 7
    },
    {
      "x": -1,
      "y": 18,
      "z": -4,
      "name": "Soil_Gravel_Half",
      "rotation": 7
    },
    {
      "x": -1,
      "y": 19,
      "z": -4,
      "name": "Rock_Stone_Brick"
    },
    {
      "x": -1,
      "y": 13,
      "z": -3,
      "name": "Rock_Stone_Brick_Smooth"
    },
    {
      "x": -1,
      "y": 14,
      "z": -3,
      "name": "Rock_Stone_Brick_Decorative"
    },
    {
      "x": -1,
      "y": 15,
      "z": -3,
      "name": "Soil_Gravel_Half",
      "rotation": 7
    },
    {
      "x": -1,
      "y": 16,
      "z": -3,
      "name": "Soil_Gravel_Half",
      "rotation": 7
    },
    {
      "x": -1,
      "y": 17,
      "z": -3,
      "name": "Soil_Gravel_Half",
      "rotation": 7
    },
    {
      "x": -1,
      "y": 18,
      "z": -3,
      "name": "Soil_Gravel_Half",
      "rotation": 7
    },
    {
      "x": -1,
      "y": 19,
      "z": -3,
      "name": "Rock_Stone_Brick"
    },
    {
      "x": -1,
      "y": 13,
      "z": -2,
      "name": "Rock_Stone_Brick_Smooth"
    },
    {
      "x": -1,
      "y": 14,
      "z": -2,
      "name": "Rock_Stone_Brick_Decorative"
    },
    {
      "x": -1,
      "y": 15,
      "z": -2,
      "name": "Rock_Stone_Brick_Pillar_Base",
      "rotation": 2
    },
    {
      "x": -1,
      "y": 16,
      "z": -2,
      "name": "Rock_Stone_Brick_Pillar_Middle",
      "rotation": 2
    },
    {
      "x": -1,
      "y": 17,
      "z": -2,
      "name": "Rock_Stone_Brick_Pillar_Middle",
      "rotation": 2
    },
    {
      "x": -1,
      "y": 18,
      "z": -2,
      "name": "Rock_Stone_Brick_Pillar_Base",
      "rotation": 32
    },
    {
      "x": -1,
      "y": 19,
      "z": -2,
      "name": "Rock_Stone_Brick"
    },
    {
      "x": -1,
      "y": 13,
      "z": -1,
      "name": "Rock_Stone_Brick_Smooth"
    },
    {
      "x": -1,
      "y": 14,
      "z": -1,
      "name": "Rock_Stone_Brick_Decorative"
    },
    {
      "x": -1,
      "y": 15,
      "z": -1,
      "name": "Soil_Gravel_Half",
      "rotation": 7
    },
    {
      "x": -1,
      "y": 16,
      "z": -1,
      "name": "Soil_Gravel_Half",
      "rotation": 7
    },
    {
      "x": -1,
      "y": 17,
      "z": -1,
      "name": "Soil_Gravel_Half",
      "rotation": 7
    },
    {
      "x": -1,
      "y": 18,
      "z": -1,
      "name": "Soil_Gravel_Half",
      "rotation": 7
    },
    {
      "x": -1,
      "y": 19,
      "z": -1,
      "name": "Rock_Stone_Brick"
    },
    {
      "x": -1,
      "y": 13,
      "z": 0,
      "name": "Rock_Stone_Brick_Smooth"
    },
    {
      "x": -1,
      "y": 14,
      "z": 0,
      "name": "Rock_Stone_Brick_Decorative"
    },
    {
      "x": -1,
      "y": 15,
      "z": 0,
      "name": "Soil_Gravel_Half",
      "rotation": 7
    },
    {
      "x": -1,
      "y": 16,
      "z": 0,
      "name": "Soil_Gravel_Half",
      "rotation": 7
    },
    {
      "x": -1,
      "y": 17,
      "z": 0,
      "name": "Soil_Gravel_Half",
      "rotation": 7
    },
    {
      "x": -1,
      "y": 18,
      "z": 0,
      "name": "Soil_Gravel_Half",
      "rotation": 7
    },
    {
      "x": -1,
      "y": 19,
      "z": 0,
      "name": "Rock_Stone_Brick"
    },
    {
      "x": -1,
      "y": 13,
      "z": 1,
      "name": "Rock_Stone_Brick_Smooth"
    },
    {
      "x": -1,
      "y": 14,
      "z": 1,
      "name": "Rock_Stone_Brick_Decorative"
    },
    {
      "x": -1,
      "y": 15,
      "z": 1,
      "name": "Soil_Gravel_Half",
      "rotation": 7
    },
    {
      "x": -1,
      "y": 16,
      "z": 1,
      "name": "Soil_Gravel_Half",
      "rotation": 7
    },
    {
      "x": -1,
      "y": 17,
      "z": 1,
      "name": "Soil_Gravel_Half",
      "rotation": 7
    },
    {
      "x": -1,
      "y": 18,
      "z": 1,
      "name": "Soil_Gravel_Half",
      "rotation": 7
    },
    {
      "x": -1,
      "y": 19,
      "z": 1,
      "name": "Rock_Stone_Brick"
    },
    {
      "x": -1,
      "y": 13,
      "z": 2,
      "name": "Rock_Stone_Brick_Smooth"
    },
    {
      "x": -1,
      "y": 14,
      "z": 2,
      "name": "Rock_Stone_Brick_Decorative"
    },
    {
      "x": -1,
      "y": 15,
      "z": 2,
      "name": "Rock_Stone_Brick_Pillar_Base"
    },
    {
      "x": -1,
      "y": 16,
      "z": 2,
      "name": "Rock_Stone_Brick_Pillar_Middle"
    },
    {
      "x": -1,
      "y": 17,
      "z": 2,
      "name": "Rock_Stone_Brick_Pillar_Middle"
    },
    {
      "x": -1,
      "y": 18,
      "z": 2,
      "name": "Rock_Stone_Brick_Pillar_Base",
      "rotation": 8
    },
    {
      "x": -1,
      "y": 19,
      "z": 2,
      "name": "Rock_Stone_Brick"
    },
    {
      "x": -1,
      "y": 13,
      "z": 3,
      "name": "Rock_Stone_Brick_Smooth"
    },
    {
      "x": -1,
      "y": 14,
      "z": 3,
      "name": "Rock_Stone_Brick_Decorative"
    },
    {
      "x": -1,
      "y": 15,
      "z": 3,
      "name": "Soil_Gravel_Half",
      "rotation": 7
    },
    {
      "x": -1,
      "y": 16,
      "z": 3,
      "name": "Soil_Gravel_Half",
      "rotation": 7
    },
    {
      "x": -1,
      "y": 17,
      "z": 3,
      "name": "Soil_Gravel_Half",
      "rotation": 7
    },
    {
      "x": -1,
      "y": 18,
      "z": 3,
      "name": "Soil_Gravel_Half",
      "rotation": 7
    },
    {
      "x": -1,
      "y": 19,
      "z": 3,
      "name": "Rock_Stone_Brick"
    },
    {
      "x": -1,
      "y": 13,
      "z": 4,
      "name": "Rock_Stone_Brick_Smooth"
    },
    {
      "x": -1,
      "y": 14,
      "z": 4,
      "name": "Rock_Stone_Brick_Decorative"
    },
    {
      "x": -1,
      "y": 15,
      "z": 4,
      "name": "Soil_Gravel_Half",
      "rotation": 7
    },
    {
      "x": -1,
      "y": 16,
      "z": 4,
      "name": "Soil_Gravel_Half",
      "rotation": 7
    },
    {
      "x": -1,
      "y": 17,
      "z": 4,
      "name": "Soil_Gravel_Half",
      "rotation": 7
    },
    {
      "x": -1,
      "y": 18,
      "z": 4,
      "name": "Soil_Gravel_Half",
      "rotation": 7
    },
    {
      "x": -1,
      "y": 19,
      "z": 4,
      "name": "Rock_Stone_Brick"
    },
    {
      "x": -1,
      "y": 13,
      "z": 5,
      "name": "Rock_Stone_Brick_Smooth"
    },
    {
      "x": -1,
      "y": 14,
      "z": 5,
      "name": "Rock_Stone_Brick_Decorative"
    },
    {
      "x": -1,
      "y": 15,
      "z": 5,
      "name": "Soil_Gravel_Half",
      "rotation": 7
    },
    {
      "x": -1,
      "y": 16,
      "z": 5,
      "name": "Soil_Gravel_Half",
      "rotation": 7
    },
    {
      "x": -1,
      "y": 17,
      "z": 5,
      "name": "Soil_Gravel_Half",
      "rotation": 7
    },
    {
      "x": -1,
      "y": 18,
      "z": 5,
      "name": "Soil_Gravel_Half",
      "rotation": 7
    },
    {
      "x": -1,
      "y": 19,
      "z": 5,
      "name": "Rock_Stone_Brick"
    },
    {
      "x": -1,
      "y": 13,
      "z": 6,
      "name": "Rock_Stone_Brick_Smooth"
    },
    {
      "x": -1,
      "y": 14,
      "z": 6,
      "name": "Rock_Stone_Brick_Decorative"
    },
    {
      "x": -1,
      "y": 15,
      "z": 6,
      "name": "Rock_Stone_Brick_Pillar_Base"
    },
    {
      "x": -1,
      "y": 16,
      "z": 6,
      "name": "Rock_Stone_Brick_Pillar_Middle"
    },
    {
      "x": -1,
      "y": 17,
      "z": 6,
      "name": "Rock_Stone_Brick_Pillar_Middle"
    },
    {
      "x": -1,
      "y": 18,
      "z": 6,
      "name": "Rock_Stone_Brick_Pillar_Base",
      "rotation": 8
    },
    {
      "x": -1,
      "y": 19,
      "z": 6,
      "name": "Rock_Stone_Brick"
    },
    {
      "x": -1,
      "y": 13,
      "z": 7,
      "name": "Rock_Stone_Brick_Smooth"
    },
    {
      "x": -1,
      "y": 14,
      "z": 7,
      "name": "Rock_Stone_Brick_Decorative"
    },
    {
      "x": -1,
      "y": 15,
      "z": 7,
      "name": "Soil_Gravel_Half",
      "rotation": 7
    },
    {
      "x": -1,
      "y": 16,
      "z": 7,
      "name": "Soil_Gravel_Half",
      "rotation": 7
    },
    {
      "x": -1,
      "y": 17,
      "z": 7,
      "name": "Soil_Gravel_Half",
      "rotation": 7
    },
    {
      "x": -1,
      "y": 18,
      "z": 7,
      "name": "Soil_Gravel_Half",
      "rotation": 7
    },
    {
      "x": -1,
      "y": 19,
      "z": 7,
      "name": "Rock_Stone_Brick"
    },
    {
      "x": -1,
      "y": 13,
      "z": 8,
      "name": "Rock_Stone_Brick_Smooth"
    },
    {
      "x": -1,
      "y": 14,
      "z": 8,
      "name": "Rock_Stone_Brick_Decorative"
    },
    {
      "x": -1,
      "y": 15,
      "z": 8,
      "name": "Soil_Gravel_Half",
      "rotation": 7
    },
    {
      "x": -1,
      "y": 16,
      "z": 8,
      "name": "Soil_Gravel_Half",
      "rotation": 7
    },
    {
      "x": -1,
      "y": 17,
      "z": 8,
      "name": "Soil_Gravel_Half",
      "rotation": 7
    },
    {
      "x": -1,
      "y": 18,
      "z": 8,
      "name": "Soil_Gravel_Half",
      "rotation": 7
    },
    {
      "x": -1,
      "y": 19,
      "z": 8,
      "name": "Rock_Stone_Brick"
    },
    {
      "x": -1,
      "y": 13,
      "z": 9,
      "name": "Rock_Stone_Brick_Smooth"
    },
    {
      "x": -1,
      "y": 14,
      "z": 9,
      "name": "Rock_Stone_Brick_Decorative"
    },
    {
      "x": -1,
      "y": 15,
      "z": 9,
      "name": "Rock_Stone_Brick_Pillar_Base"
    },
    {
      "x": -1,
      "y": 16,
      "z": 9,
      "name": "Rock_Stone_Brick_Pillar_Middle"
    },
    {
      "x": -1,
      "y": 17,
      "z": 9,
      "name": "Rock_Stone_Brick_Pillar_Middle"
    },
    {
      "x": -1,
      "y": 18,
      "z": 9,
      "name": "Rock_Stone_Brick_Pillar_Base",
      "rotation": 8
    },
    {
      "x": -1,
      "y": 19,
      "z": 9,
      "name": "Rock_Stone_Brick_Smooth"
    },
    {
      "x": -1,
      "y": 13,
      "z": 10,
      "name": "Rock_Stone_Brick_Smooth"
    },
    {
      "x": -1,
      "y": 19,
      "z": 10,
      "name": "Rock_Stone_Brick_Smooth"
    },
    {
      "x": -1,
      "y": 13,
      "z": 11,
      "name": "Rock_Stone_Brick_Smooth"
    },
    {
      "x": -1,
      "y": 19,
      "z": 11,
      "name": "Rock_Stone_Brick_Smooth"
    },
    {
      "x": -1,
      "y": 13,
      "z": 12,
      "name": "Rock_Stone_Brick_Smooth"
    },
    {
      "x": -1,
      "y": 19,
      "z": 12,
      "name": "Rock_Stone_Brick_Smooth"
    },
    {
      "x": -1,
      "y": 13,
