{
  "version": 8,
  "blockIdVersion": 11,
  "anchorX": 0,
  "anchorY": 11,
  "anchorZ": 0,
  "blocks": [
    {
      "x": -11,
      "y": 6,
      "z": -8,
      "name": "Rock_Stone_Brick_Smooth",
      "support": 15
    },
    {
      "x": -11,
      "y": 7,
      "z": -8,
      "name": "Soil_Gravel",
      "support": 15
    },
    {
      "x": -11,
      "y": 8,
      "z": -8,
      "name": "Soil_Gravel",
      "support": 15
    },
    {
      "x": -11,
      "y": 9,
      "z": -8,
      "name": "Soil_Gravel"
    },
    {
      "x": -11,
      "y": 10,
      "z": -8,
      "name": "Soil_Gravel"
    },
    {
      "x": -11,
      "y": 6,
      "z": -4,
      "name": "Rock_Stone_Brick_Smooth",
      "support": 15
    },
    {
      "x": -11,
      "y": 7,
      "z": -4,
      "name": "Soil_Gravel",
      "support": 15
    },
    {
      "x": -11,
      "y": 8,
      "z": -4,
      "name": "Soil_Gravel",
      "support": 15
    },
    {
      "x": -11,
      "y": 9,
      "z": -4,
      "name": "Soil_Gravel"
    },
    {
      "x": -11,
      "y": 10,
      "z": -4,
      "name": "Soil_Gravel"
    },
    {
      "x": -11,
      "y": 6,
      "z": 0,
      "name": "Rock_Stone_Brick_Smooth",
      "support": 15
    },
    {
      "x": -11,
      "y": 7,
      "z": 0,
      "name": "Soil_Gravel",
      "support": 15
    },
    {
      "x": -11,
      "y": 8,
      "z": 0,
      "name": "Soil_Gravel",
      "support": 15
    },
    {
      "x": -11,
      "y": 9,
      "z": 0,
      "name": "Soil_Gravel"
    },
    {
      "x": -11,
      "y": 10,
      "z": 0,
      "name": "Soil_Gravel"
    },
    {
      "x": -11,
      "y": 6,
      "z": 2,
      "name": "Rock_Stone_Brick_Smooth",
      "support": 15
    },
    {
      "x": -11,
      "y": 7,
      "z": 2,
      "name": "Soil_Gravel",
      "support": 15
    },
    {
      "x": -11,
      "y": 8,
      "z": 2,
      "name": "Soil_Gravel",
      "support": 15
    },
    {
      "x": -11,
      "y": 9,
      "z": 2,
      "name": "Soil_Gravel"
    },
    {
      "x": -11,
      "y": 10,
      "z": 2,
      "name": "Soil_Gravel"
    },
    {
      "x": -11,
      "y": 6,
      "z": 6,
      "name": "Rock_Stone_Brick_Smooth",
      "support": 15
    },
    {
      "x": -11,
      "y": 7,
      "z": 6,
      "name": "Soil_Gravel",
      "support": 15
    },
    {
      "x": -11,
      "y": 8,
      "z": 6,
      "name": "Soil_Gravel",
      "support": 15
    },
    {
      "x": -11,
      "y": 9,
      "z": 6,
      "name": "Soil_Gravel"
    },
    {
      "x": -11,
      "y": 10,
      "z": 6,
      "name": "Soil_Gravel"
    },
    {
      "x": -11,
      "y": 6,
      "z": 10,
      "name": "Rock_Stone_Brick_Smooth",
      "support": 15
    },
    {
      "x": -11,
      "y": 7,
      "z": 10,
      "name": "Soil_Gravel",
      "support": 15
    },
    {
      "x": -11,
      "y": 8,
      "z": 10,
      "name": "Soil_Gravel",
      "support": 15
    },
    {
      "x": -11,
      "y": 9,
      "z": 10,
      "name": "Soil_Gravel"
    },
    {
      "x": -11,
      "y": 10,
      "z": 10,
      "name": "Soil_Gravel"
    },
    {
      "x": -10,
      "y": 6,
      "z": -9,
      "name": "Rock_Stone_Brick_Smooth",
      "support": 15
    },
    {
      "x": -10,
      "y": 7,
      "z": -9,
      "name": "Soil_Gravel",
      "support": 15
    },
    {
      "x": -10,
      "y": 8,
      "z": -9,
      "name": "Soil_Gravel",
      "support": 15
    },
    {
      "x": -10,
      "y": 9,
      "z": -9,
      "name": "Soil_Gravel"
    },
    {
      "x": -10,
      "y": 10,
      "z": -9,
      "name": "Soil_Gravel"
    },
    {
      "x": -10,
      "y": 5,
      "z": -8,
      "name": "Rock_Stone_Brick_Smooth"
    },
    {
      "x": -10,
      "y": 6,
      "z": -8,
      "name": "Rock_Stone_Brick_Smooth"
    },
    {
      "x": -10,
      "y": 7,
      "z": -8,
      "name": "Rock_Stone_Brick"
    },
    {
      "x": -10,
      "y": 8,
      "z": -8,
      "name": "Rock_Stone_Brick"
    },
    {
      "x": -10,
      "y": 9,
      "z": -8,
      "name": "Rock_Stone_Brick"
    },
    {
      "x": -10,
      "y": 10,
      "z": -8,
      "name": "Rock_Stone_Brick"
    },
    {
      "x": -10,
      "y": 11,
      "z": -8,
      "name": "Rock_Stone_Brick"
    },
    {
      "x": -10,
      "y": 5,
      "z": -7,
      "name": "Rock_Stone_Brick_Smooth",
      "support": 15
    },
    {
      "x": -10,
      "y": 6,
      "z": -7,
      "name": "Rock_Stone_Brick_Decorative",
      "support": 15,
      "rotation": 2
    },
    {
      "x": -10,
      "y": 7,
      "z": -7,
      "name": "Soil_Gravel_Half",
      "support": 15,
      "rotation": 5
    },
    {
      "x": -10,
      "y": 8,
      "z": -7,
      "name": "Soil_Gravel_Half",
      "support": 15,
      "rotation": 5
    },
    {
      "x": -10,
      "y": 9,
      "z": -7,
      "name": "Soil_Gravel_Half",
      "rotation": 5
    },
    {
      "x": -10,
      "y": 10,
      "z": -7,
      "name": "Soil_Gravel_Half",
      "rotation": 5
    },
    {
      "x": -10,
      "y": 11,
      "z": -7,
      "name": "Rock_Stone_Brick"
    },
    {
      "x": -10,
      "y": 5,
      "z": -6,
      "name": "Rock_Stone_Brick_Smooth",
      "support": 15
    },
    {
      "x": -10,
      "y": 6,
      "z": -6,
      "name": "Rock_Stone_Brick_Decorative",
      "support": 15,
      "rotation": 2
    },
    {
      "x": -10,
      "y": 7,
      "z": -6,
      "name": "Soil_Gravel_Half",
      "support": 15,
      "rotation": 5
    },
    {
      "x": -10,
      "y": 8,
      "z": -6,
      "name": "Soil_Gravel_Half",
      "support": 15,
      "rotation": 5
    },
    {
      "x": -10,
      "y": 9,
      "z": -6,
      "name": "Soil_Gravel_Half",
      "rotation": 5
    },
    {
      "x": -10,
      "y": 10,
      "z": -6,
      "name": "Soil_Gravel_Half",
      "rotation": 5
    },
    {
      "x": -10,
      "y": 11,
      "z": -6,
      "name": "Rock_Stone_Brick"
    },
    {
      "x": -10,
      "y": 5,
      "z": -5,
      "name": "Rock_Stone_Brick_Smooth",
      "support": 15
    },
    {
      "x": -10,
      "y": 6,
      "z": -5,
      "name": "Rock_Stone_Brick_Decorative",
      "support": 15,
      "rotation": 2
    },
    {
      "x": -10,
      "y": 7,
      "z": -5,
      "name": "Soil_Gravel_Half",
      "support": 15,
      "rotation": 5
    },
    {
      "x": -10,
      "y": 8,
      "z": -5,
      "name": "Soil_Gravel_Half",
      "support": 15,
      "rotation": 5
    },
    {
      "x": -10,
      "y": 9,
      "z": -5,
      "name": "Soil_Gravel_Half",
      "rotation": 5
    },
    {
      "x": -10,
      "y": 10,
      "z": -5,
      "name": "Soil_Gravel_Half",
      "rotation": 5
    },
    {
      "x": -10,
      "y": 11,
      "z": -5,
      "name": "Rock_Stone_Brick"
    },
    {
      "x": -10,
      "y": 5,
      "z": -4,
      "name": "Rock_Stone_Brick_Smooth"
    },
    {
      "x": -10,
      "y": 6,
      "z": -4,
      "name": "Rock_Stone_Brick_Smooth",
      "rotation": 1
    },
    {
      "x": -10,
      "y": 7,
      "z": -4,
      "name": "Rock_Stone_Brick_Pillar_Base",
      "rotation": 2
    },
    {
      "x": -10,
      "y": 8,
      "z": -4,
      "name": "Rock_Stone_Brick_Pillar_Middle",
      "rotation": 2
    },
    {
      "x": -10,
      "y": 9,
      "z": -4,
      "name": "Rock_Stone_Brick_Pillar_Middle",
      "rotation": 2
    },
    {
      "x": -10,
      "y": 10,
      "z": -4,
      "name": "Rock_Stone_Brick_Pillar_Base",
      "rotation": 10
    },
    {
      "x": -10,
      "y": 11,
      "z": -4,
      "name": "Rock_Stone_Brick_Smooth"
    },
    {
      "x": -10,
      "y": 5,
      "z": -3,
      "name": "Rock_Stone_Brick_Smooth",
      "support": 15
    },
    {
      "x": -10,
      "y": 6,
      "z": -3,
      "name": "Rock_Stone_Brick_Decorative",
      "support": 15,
      "rotation": 2
    },
    {
      "x": -10,
      "y": 7,
      "z": -3,
      "name": "Soil_Gravel_Half",
      "support": 15,
      "rotation": 5
    },
    {
      "x": -10,
      "y": 8,
      "z": -3,
      "name": "Soil_Gravel_Half",
      "support": 15,
      "rotation": 5
    },
    {
      "x": -10,
      "y": 9,
      "z": -3,
      "name": "Soil_Gravel_Half",
      "rotation": 5
    },
    {
      "x": -10,
      "y": 10,
      "z": -3,
      "name": "Soil_Gravel_Half",
      "rotation": 5
    },
    {
      "x": -10,
      "y": 11,
      "z": -3,
      "name": "Rock_Stone_Brick"
    },
    {
      "x": -10,
      "y": 5,
      "z": -2,
      "name": "Rock_Stone_Brick_Smooth",
      "support": 15
    },
    {
      "x": -10,
      "y": 6,
      "z": -2,
      "name": "Rock_Stone_Brick_Decorative",
      "support": 15,
      "rotation": 2
    },
    {
      "x": -10,
      "y": 7,
      "z": -2,
      "name": "Soil_Gravel_Half",
      "support": 15,
      "rotation": 5
    },
    {
      "x": -10,
      "y": 8,
      "z": -2,
      "name": "Soil_Gravel_Half",
      "support": 15,
      "rotation": 5
    },
    {
      "x": -10,
      "y": 9,
      "z": -2,
      "name": "Soil_Gravel_Half",
      "rotation": 5
    },
    {
      "x": -10,
      "y": 10,
      "z": -2,
      "name": "Soil_Gravel_Half",
      "rotation": 5
    },
    {
      "x": -10,
      "y": 11,
      "z": -2,
      "name": "Rock_Stone_Brick"
    },
    {
      "x": -10,
      "y": 5,
      "z": -1,
      "name": "Rock_Stone_Brick_Smooth",
      "support": 15
    },
    {
      "x": -10,
      "y": 6,
      "z": -1,
      "name": "Rock_Stone_Brick_Decorative",
      "support": 15,
      "rotation": 2
    },
    {
      "x": -10,
      "y": 7,
      "z": -1,
      "name": "Soil_Gravel_Half",
      "support": 15,
      "rotation": 5
    },
    {
      "x": -10,
      "y": 8,
      "z": -1,
      "name": "Soil_Gravel_Half",
      "support": 15,
      "rotation": 5
    },
    {
      "x": -10,
      "y": 9,
      "z": -1,
      "name": "Soil_Gravel_Half",
      "rotation": 5
    },
    {
      "x": -10,
      "y": 10,
      "z": -1,
      "name": "Soil_Gravel_Half",
      "rotation": 5
    },
    {
      "x": -10,
      "y": 11,
      "z": -1,
      "name": "Rock_Stone_Brick"
    },
    {
      "x": -10,
      "y": 5,
      "z": 0,
      "name": "Rock_Stone_Brick_Smooth"
    },
    {
      "x": -10,
      "y": 6,
      "z": 0,
      "name": "Rock_Stone_Brick_Smooth",
      "rotation": 1
    },
    {
      "x": -10,
      "y": 7,
      "z": 0,
      "name": "Rock_Stone_Brick_Pillar_Base",
      "rotation": 2
    },
    {
      "x": -10,
      "y": 8,
      "z": 0,
      "name": "Rock_Stone_Brick_Pillar_Middle",
      "rotation": 2
    },
    {
      "x": -10,
      "y": 9,
      "z": 0,
      "name": "Rock_Stone_Brick_Pillar_Middle",
      "rotation": 2
    },
    {
      "x": -10,
      "y": 10,
      "z": 0,
      "name": "Rock_Stone_Brick_Pillar_Base",
      "rotation": 10
    },
    {
      "x": -10,
      "y": 11,
      "z": 0,
      "name": "Rock_Stone_Brick_Smooth"
    },
    {
      "x": -10,
      "y": 5,
      "z": 1,
      "name": "Rock_Stone_Brick_Smooth"
    },
    {
      "x": -10,
      "y": 6,
      "z": 1,
      "name": "Rock_Stone_Brick"
    },
    {
      "x": -10,
      "y": 7,
      "z": 1,
      "name": "Rock_Stone_Brick"
    },
    {
      "x": -10,
      "y": 8,
      "z": 1,
      "name": "Rock_Stone_Brick"
    },
    {
      "x": -10,
      "y": 9,
      "z": 1,
      "name": "Rock_Stone_Brick"
    },
    {
      "x": -10,
      "y": 10,
      "z": 1,
      "name": "Rock_Stone_Brick"
    },
    {
      "x": -10,
      "y": 11,
      "z": 1,
      "name": "Rock_Stone_Brick"
    },
    {
      "x": -10,
      "y": 5,
      "z": 2,
      "name": "Rock_Stone_Brick_Smooth"
    },
    {
      "x": -10,
      "y": 6,
      "z": 2,
      "name": "Rock_Stone_Brick_Smooth",
      "rotation": 2
    },
    {
      "x": -10,
      "y": 7,
      "z": 2,
      "name": "Rock_Stone_Brick_Pillar_Base",
      "rotation": 3
    },
    {
      "x": -10,
      "y": 8,
      "z": 2,
      "name": "Rock_Stone_Brick_Pillar_Middle",
      "rotation": 3
    },
    {
      "x": -10,
      "y": 9,
      "z": 2,
      "name": "Rock_Stone_Brick_Pillar_Middle",
      "rotation": 3
    },
    {
      "x": -10,
      "y": 10,
      "z": 2,
      "name": "Rock_Stone_Brick_Pillar_Base",
      "rotation": 11
    },
    {
      "x": -10,
      "y": 11,
      "z": 2,
      "name": "Rock_Stone_Brick"
    },
    {
      "x": -10,
      "y": 5,
      "z": 3,
      "name": "Rock_Stone_Brick_Smooth",
      "support": 15
    },
    {
      "x": -10,
      "y": 6,
      "z": 3,
      "name": "Rock_Stone_Brick_Decorative",
      "support": 15
    },
    {
      "x": -10,
      "y": 7,
      "z": 3,
      "name": "Soil_Gravel_Half",
      "support": 15,
      "rotation": 5
    },
    {
      "x": -10,
      "y": 8,
      "z": 3,
      "name": "Soil_Gravel_Half",
      "support": 15,
      "rotation": 5
    },
    {
      "x": -10,
      "y": 9,
      "z": 3,
      "name": "Soil_Gravel_Half",
      "rotation": 5
    },
    {
      "x": -10,
      "y": 10,
      "z": 3,
      "name": "Soil_Gravel_Half",
      "rotation": 5
    },
    {
      "x": -10,
      "y": 11,
      "z": 3,
      "name": "Rock_Stone_Brick"
    },
    {
      "x": -10,
      "y": 5,
      "z": 4,
      "name": "Rock_Stone_Brick_Smooth",
      "support": 15
    },
    {
      "x": -10,
      "y": 6,
      "z": 4,
      "name": "Rock_Stone_Brick_Decorative",
      "support": 15
    },
    {
      "x": -10,
      "y": 7,
      "z": 4,
      "name": "Soil_Gravel_Half",
      "support": 15,
      "rotation": 5
    },
    {
      "x": -10,
      "y": 8,
      "z": 4,
      "name": "Soil_Gravel_Half",
      "support": 15,
      "rotation": 5
    },
    {
      "x": -10,
      "y": 9,
      "z": 4,
      "name": "Soil_Gravel_Half",
      "rotation": 5
    },
    {
      "x": -10,
      "y": 10,
      "z": 4,
      "name": "Soil_Gravel_Half",
      "rotation": 5
    },
    {
      "x": -10,
      "y": 11,
      "z": 4,
      "name": "Rock_Stone_Brick"
    },
    {
      "x": -10,
      "y": 5,
      "z": 5,
      "name": "Rock_Stone_Brick_Smooth",
      "support": 15
    },
    {
      "x": -10,
      "y": 6,
      "z": 5,
      "name": "Rock_Stone_Brick_Decorative",
      "support": 15
    },
    {
      "x": -10,
      "y": 7,
      "z": 5,
      "name": "Soil_Gravel_Half",
      "support": 15,
      "rotation": 5
    },
    {
      "x": -10,
      "y": 8,
      "z": 5,
      "name": "Soil_Gravel_Half",
      "support": 15,
      "rotation": 5
    },
    {
      "x": -10,
      "y": 9,
      "z": 5,
      "name": "Soil_Gravel_Half",
      "rotation": 5
    },
    {
      "x": -10,
      "y": 10,
      "z": 5,
      "name": "Soil_Gravel_Half",
      "rotation": 5
    },
    {
      "x": -10,
      "y": 11,
      "z": 5,
      "name": "Rock_Stone_Brick"
    },
    {
      "x": -10,
      "y": 5,
      "z": 6,
      "name": "Rock_Stone_Brick_Smooth"
    },
    {
      "x": -10,
      "y": 6,
      "z": 6,
      "name": "Rock_Stone_Brick_Smooth",
      "rotation": 3
    },
    {
      "x": -10,
      "y": 7,
      "z": 6,
      "name": "Rock_Stone_Brick_Pillar_Base"
    },
    {
      "x": -10,
      "y": 8,
      "z": 6,
      "name": "Rock_Stone_Brick_Pillar_Middle"
    },
    {
      "x": -10,
      "y": 9,
      "z": 6,
      "name": "Rock_Stone_Brick_Pillar_Middle"
    },
    {
      "x": -10,
      "y": 10,
      "z": 6,
      "name": "Rock_Stone_Brick_Pillar_Base",
      "rotation": 8
    },
    {
      "x": -10,
      "y": 11,
      "z": 6,
      "name": "Rock_Stone_Brick"
    },
    {
      "x": -10,
      "y": 5,
      "z": 7,
      "name": "Rock_Stone_Brick_Smooth",
      "support": 15
    },
    {
      "x": -10,
      "y": 6,
      "z": 7,
      "name": "Rock_Stone_Brick_Decorative",
      "support": 15
    },
    {
      "x": -10,
      "y": 7,
      "z": 7,
      "name": "Soil_Gravel_Half",
      "support": 15,
      "rotation": 5
    },
    {
      "x": -10,
      "y": 8,
      "z": 7,
      "name": "Soil_Gravel_Half",
      "support": 15,
      "rotation": 5
    },
    {
      "x": -10,
      "y": 9,
      "z": 7,
      "name": "Soil_Gravel_Half",
      "rotation": 5
    },
    {
      "x": -10,
      "y": 10,
      "z": 7,
      "name": "Soil_Gravel_Half",
      "rotation": 5
    },
    {
      "x": -10,
      "y": 11,
      "z": 7,
      "name": "Rock_Stone_Brick"
    },
    {
      "x": -10,
      "y": 5,
      "z": 8,
      "name": "Rock_Stone_Brick_Smooth",
      "support": 15
    },
    {
      "x": -10,
      "y": 6,
      "z": 8,
      "name": "Rock_Stone_Brick_Decorative",
      "support": 15
    },
    {
      "x": -10,
      "y": 7,
      "z": 8,
      "name": "Soil_Gravel_Half",
      "support": 15,
      "rotation": 5
    },
    {
      "x": -10,
      "y": 8,
      "z": 8,
      "name": "Soil_Gravel_Half",
      "support": 15,
      "rotation": 5
    },
    {
      "x": -10,
      "y": 9,
      "z": 8,
      "name": "Soil_Gravel_Half",
      "rotation": 5
    },
    {
      "x": -10,
      "y": 10,
      "z": 8,
      "name": "Soil_Gravel_Half",
      "rotation": 5
    },
    {
      "x": -10,
      "y": 11,
      "z": 8,
      "name": "Rock_Stone_Brick"
    },
    {
      "x": -10,
      "y": 5,
      "z": 9,
      "name": "Rock_Stone_Brick_Smooth",
      "support": 15
    },
    {
      "x": -10,
      "y": 6,
      "z": 9,
      "name": "Rock_Stone_Brick_Decorative",
      "support": 15
    },
    {
      "x": -10,
      "y": 7,
      "z": 9,
      "name": "Soil_Gravel_Half",
      "support": 15,
      "rotation": 5
    },
    {
      "x": -10,
      "y": 8,
      "z": 9,
      "name": "Soil_Gravel_Half",
      "support": 15,
      "rotation": 5
    },
    {
      "x": -10,
      "y": 9,
      "z": 9,
      "name": "Soil_Gravel_Half",
      "rotation": 5
    },
    {
      "x": -10,
      "y": 10,
      "z": 9,
      "name": "Soil_Gravel_Half",
      "rotation": 5
    },
    {
      "x": -10,
      "y": 11,
      "z": 9,
      "name": "Rock_Stone_Brick"
    },
    {
      "x": -10,
      "y": 5,
      "z": 10,
      "name": "Rock_Stone_Brick_Smooth"
    },
    {
      "x": -10,
      "y": 6,
      "z": 10,
      "name": "Rock_Stone_Brick_Smooth",
      "rotation": 3
    },
    {
      "x": -10,
      "y": 7,
      "z": 10,
      "name": "Rock_Stone_Brick_Pillar_Base"
    },
    {
      "x": -10,
      "y": 8,
      "z": 10,
      "name": "Rock_Stone_Brick_Pillar_Middle"
    },
    {
      "x": -10,
      "y": 9,
      "z": 10,
      "name": "Rock_Stone_Brick_Pillar_Middle"
    },
    {
      "x": -10,
      "y": 10,
      "z": 10,
      "name": "Rock_Stone_Brick_Pillar_Base",
      "rotation": 8
    },
    {
      "x": -10,
      "y": 11,
      "z": 10,
      "name": "Rock_Stone_Brick"
    },
    {
      "x": -10,
      "y": 6,
      "z": 11,
      "name": "Rock_Stone_Brick_Smooth",
      "support": 15
    },
    {
      "x": -10,
      "y": 7,
      "z": 11,
      "name": "Soil_Gravel",
      "support": 15
    },
    {
      "x": -10,
      "y": 8,
      "z": 11,
      "name": "Soil_Gravel",
      "support": 15
    },
    {
      "x": -10,
      "y": 9,
      "z": 11,
      "name": "Soil_Gravel"
    },
    {
      "x": -10,
      "y": 10,
      "z": 11,
      "name": "Soil_Gravel"
    },
    {
      "x": -9,
      "y": 5,
      "z": -8,
      "name": "Rock_Stone_Brick_Smooth",
      "support": 15
    },
    {
      "x": -9,
      "y": 6,
      "z": -8,
      "name": "Rock_Stone_Brick_Decorative",
      "support": 15,
      "rotation": 1
    },
    {
      "x": -9,
      "y": 7,
      "z": -8,
      "name": "Soil_Gravel_Half",
      "support": 15,
      "rotation": 4
    },
    {
      "x": -9,
      "y": 8,
      "z": -8,
      "name": "Soil_Gravel_Half",
      "support": 15,
      "rotation": 4
    },
    {
      "x": -9,
      "y": 9,
      "z": -8,
      "name": "Soil_Gravel_Half",
      "rotation": 4
    },
    {
      "x": -9,
      "y": 10,
      "z": -8,
      "name": "Soil_Gravel_Half",
      "rotation": 4
    },
    {
      "x": -9,
      "y": 11,
      "z": -8,
      "name": "Rock_Stone_Brick"
    },
    {
      "x": -9,
      "y": 5,
      "z": -7,
      "name": "Rock_Stone_Brick_Smooth"
    },
    {
      "x": -9,
      "y": 6,
      "z": -7,
      "name": "Furniture_Temple_Dark_Candle"
    },
    {
      "x": -9,
      "y": 7,
      "z": -7,
      "name": "Furniture_Temple_Dark_Candle",
      "filler": 1024
    },
    {
      "x": -9,
      "y": 11,
      "z": -7,
      "name": "Rock_Stone_Brick_Smooth_Half",
      "rotation": 8
    },
    {
      "x": -9,
      "y": 5,
      "z": -6,
      "name": "Rock_Stone_Brick_Smooth"
    },
    {
      "x": -9,
      "y": 11,
      "z": -6,
      "name": "Rock_Stone_Brick_Smooth_Half",
      "rotation": 8
    },
    {
      "x": -9,
      "y": 5,
      "z": -5,
      "name": "Rock_Stone_Brick_Smooth"
    },
    {
      "x": -9,
      "y": 11,
      "z": -5,
      "name": "Rock_Stone_Brick_Smooth_Half",
      "rotation": 8
    },
    {
      "x": -9,
      "y": 5,
      "z": -4,
      "name": "Rock_Stone_Brick_Smooth"
    },
    {
      "x": -9,
      "y": 11,
      "z": -4,
      "name": "Rock_Stone_Brick_Smooth_Half",
      "rotation": 8
    },
    {
      "x": -9,
      "y": 5,
      "z": -3,
      "name": "Rock_Stone_Brick_Smooth"
    },
    {
      "x": -9,
      "y": 11,
      "z": -3,
      "name": "Rock_Stone_Brick_Smooth_Half",
      "rotation": 8
    },
    {
      "x": -9,
      "y": 5,
      "z": -2,
      "name": "Rock_Stone_Brick_Smooth"
    },
    {
      "x": -9,
      "y": 11,
      "z": -2,
      "name": "Rock_Stone_Brick_Smooth_Half",
      "rotation": 8
    },
    {
      "x": -9,
      "y": 5,
      "z": -1,
      "name": "Rock_Stone_Brick_Smooth"
    },
    {
      "x": -9,
      "y": 11,
      "z": -1,
      "name": "Rock_Stone_Brick_Smooth_Half",
      "rotation": 8
    },
    {
      "x": -9,
      "y": 5,
      "z": 0,
      "name": "Rock_Stone_Brick_Smooth"
    },
    {
      "x": -9,
      "y": 11,
      "z": 0,
      "name": "Rock_Stone_Brick_Smooth_Half",
      "rotation": 8
    },
    {
      "x": -9,
      "y": 5,
      "z": 1,
      "name": "Rock_Stone_Brick_Smooth"
    },
    {
      "x": -9,
      "y": 6,
      "z": 1,
      "name": "Rock_Stone_Brick_Smooth_Half",
      "rotation": 5
    },
    {
      "x": -9,
      "y": 7,
      "z": 1,
      "name": "Rock_Stone_Brick_Smooth_Half",
      "rotation": 5
    },
    {
      "x": -9,
      "y": 8,
      "z": 1,
      "name": "Rock_Stone_Brick_Smooth_Half",
      "rotation": 5
    },
    {
      "x": -9,
      "y": 9,
      "z": 1,
      "name": "Rock_Stone_Brick_Stairs",
      "rotation": 11
    },
    {
      "x": -9,
      "y": 10,
      "z": 1,
      "name": "Rock_Stone_Brick_Decorative"
    },
    {
      "x": -9,
      "y": 11,
      "z": 1,
      "name": "Rock_Stone_Brick"
    },
    {
      "x": -9,
      "y": 5,
      "z": 2,
      "name": "Rock_Stone_Brick_Smooth"
    },
    {
      "x": -9,
      "y": 11,
      "z": 2,
      "name": "Rock_Stone_Brick_Smooth_Half",
      "rotation": 8
    },
    {
      "x": -9,
      "y": 5,
      "z": 3,
      "name": "Rock_Stone_Brick_Smooth"
    },
    {
      "x": -9,
      "y": 11,
      "z": 3,
      "name": "Rock_Stone_Brick_Smooth_Half",
      "rotation": 8
    },
    {
      "x": -9,
      "y": 5,
      "z": 4,
      "name": "Rock_Stone_Brick_Smooth"
    },
    {
      "x": -9,
      "y": 11,
      "z": 4,
      "name": "Rock_Stone_Brick_Smooth_Half",
      "rotation": 8
    },
    {
      "x": -9,
      "y": 5,
      "z": 5,
      "name": "Rock_Stone_Brick_Smooth"
    },
    {
      "x": -9,
      "y": 11,
      "z": 5,
      "name": "Rock_Stone_Brick_Smooth_Half",
      "rotation": 8
    },
    {
      "x": -9,
      "y": 5,
      "z": 6,
      "name": "Rock_Stone_Brick_Smooth"
    },
    {
      "x": -9,
      "y": 11,
      "z": 6,
      "name": "Rock_Stone_Brick"
    },
    {
      "x": -9,
      "y": 5,
      "z": 7,
      "name": "Rock_Stone_Brick_Smooth"
    },
    {
      "x": -9,
      "y": 11,
      "z": 7,
      "name": "Rock_Stone_Brick_Smooth_Half",
      "rotation": 8
    },
    {
      "x": -9,
      "y": 5,
      "z": 8,
      "name": "Rock_Stone_Brick_Smooth"
    },
    {
      "x": -9,
      "y": 11,
      "z": 8,
      "name": "Rock_Stone_Brick_Smooth_Half",
      "rotation": 8
    },
    {
      "x": -9,
      "y": 5,
      "z": 9,
      "name": "Rock_Stone_Brick_Smooth"
    },
    {
      "x": -9,
      "y": 11,
      "z": 9,
      "name": "Rock_Stone_Brick_Smooth_Half",
      "rotation": 8
    },
    {
      "x": -9,
      "y": 5,
      "z": 10,
      "name": "Rock_Stone_Brick_Smooth"
    },
    {
      "x": -9,
      "y": 6,
      "z": 10,
      "name": "Furniture_Temple_Dark_Candle"
    },
    {
      "x": -9,
      "y": 7,
      "z": 10,
      "name": "Furniture_Temple_Dark_Candle",
      "filler": 1024
    },
    {
      "x": -9,
      "y": 11,
      "z": 10,
      "name": "Rock_Stone_Brick_Smooth_Half",
      "rotation": 8
    },
    {
      "x": -9,
      "y": 5,
      "z": 11,
      "name": "Rock_Stone_Brick_Smooth"
    },
    {
      "x": -9,
      "y": 6,
      "z": 11,
      "name": "Rock_Stone_Brick_Decorative"
    },
    {
      "x": -9,
      "y": 7,
      "z": 11,
      "name": "Rock_Stone_Brick"
    },
    {
      "x": -9,
      "y": 8,
      "z": 11,
      "name": "Rock_Stone_Brick"
    },
    {
      "x": -9,
      "y": 9,
      "z": 11,
      "name": "Rock_Stone_Brick"
    },
    {
      "x": -9,
      "y": 10,
      "z": 11,
      "name": "Rock_Stone_Brick"
    },
    {
      "x": -9,
      "y": 11,
      "z": 11,
      "name": "Rock_Stone_Brick"
    },
    {
      "x": -9,
      "y": 6,
      "z": 12,
      "name": "Rock_Stone_Brick_Smooth",
      "support": 15
    },
    {
      "x": -9,
      "y": 7,
      "z": 12,
      "name": "Soil_Gravel",
      "support": 15
    },
    {
      "x": -9,
      "y": 8,
      "z": 12,
      "name": "Soil_Gravel",
      "support": 15
    },
    {
      "x": -9,
      "y": 9,
      "z": 12,
      "name": "Soil_Gravel"
    },
    {
      "x": -9,
      "y": 10,
      "z": 12,
      "name": "Soil_Gravel"
    },
    {
      "x": -8,
      "y": 5,
      "z": -8,
      "name": "Rock_Stone_Brick_Smooth",
      "support": 15
    },
    {
      "x": -8,
      "y": 6,
      "z": -8,
      "name": "Rock_Stone_Brick_Decorative",
      "support": 15,
      "rotation": 1
    },
    {
      "x": -8,
      "y": 7,
      "z": -8,
      "name": "Soil_Gravel_Half",
      "support": 15,
      "rotation": 4
    },
    {
      "x": -8,
      "y": 8,
      "z": -8,
      "name": "Soil_Gravel_Half",
      "support": 15,
      "rotation": 4
    },
    {
      "x": -8,
      "y": 9,
      "z": -8,
      "name": "Soil_Gravel_Half",
      "rotation": 4
    },
    {
      "x": -8,
      "y": 10,
      "z": -8,
      "name": "Soil_Gravel_Half",
      "rotation": 4
    },
    {
      "x": -8,
      "y": 11,
      "z": -8,
      "name": "Rock_Stone_Brick"
    },
    {
      "x": -8,
      "y": 5,
      "z": -7,
      "name": "Rock_Stone_Brick_Smooth"
    },
    {
      "x": -8,
      "y": 11,
      "z": -7,
      "name": "Rock_Stone_Brick_Smooth_Half",
      "rotation": 8
    },
    {
      "x": -8,
      "y": 5,
      "z": -6,
      "name": "Rock_Stone_Brick_Smooth"
    },
    {
      "x": -8,
      "y": 11,
      "z": -6,
      "name": "Rock_Stone_Brick_Smooth_Half",
      "rotation": 8
    },
    {
      "x": -8,
      "y": 5,
      "z": -5,
      "name": "Rock_Stone_Brick_Smooth"
    },
    {
      "x": -8,
      "y": 11,
      "z": -5,
      "name": "Rock_Stone_Brick_Smooth_Half",
      "rotation": 8
    },
    {
      "x": -8,
      "y": 5,
      "z": -4,
      "name": "Rock_Stone_Brick_Smooth"
    },
    {
      "x": -8,
      "y": 11,
      "z": -4,
      "name": "Rock_Stone_Brick_Smooth_Half",
      "rotation": 8
    },
    {
      "x": -8,
      "y": 5,
      "z": -3,
      "name": "Rock_Stone_Brick_Smooth"
    },
    {
      "x": -8,
      "y": 11,
      "z": -3,
      "name": "Rock_Stone_Brick_Smooth_Half",
      "rotation": 8
    },
    {
      "x": -8,
      "y": 5,
      "z": -2,
      "name": "Rock_Stone_Brick_Smooth"
    },
    {
      "x": -8,
      "y": 11,
      "z": -2,
      "name": "Rock_Stone_Brick_Smooth_Half",
      "rotation": 8
    },
    {
      "x": -8,
      "y": 5,
      "z": -1,
      "name": "Rock_Stone_Brick_Smooth"
    },
    {
      "x": -8,
      "y": 11,
      "z": -1,
      "name": "Rock_Stone_Brick_Smooth_Half",
      "rotation": 8
    },
    {
      "x": -8,
      "y": 5,
      "z": 0,
      "name": "Rock_Stone_Brick_Smooth"
    },
    {
      "x": -8,
      "y": 11,
      "z": 0,
      "name": "Rock_Stone_Brick_Smooth_Half",
      "rotation": 8
    },
    {
      "x": -8,
      "y": 5,
      "z": 1,
      "name": "Rock_Stone_Brick_Smooth"
    },
    {
      "x": -8,
      "y": 9,
      "z": 1,
      "name": "Rock_Stone_Brick_Smooth_Half",
      "rotation": 8
    },
    {
      "x": -8,
      "y": 10,
      "z": 1,
      "name": "Rock_Stone_Brick_Decorative"
    },
    {
      "x": -8,
      "y": 11,
      "z": 1,
      "name": "Rock_Stone_Brick"
    },
    {
      "x": -8,
      "y": 5,
      "z": 2,
      "name": "Rock_Stone_Brick_Smooth"
    },
    {
      "x": -8,
      "y": 11,
      "z": 2,
      "name": "Rock_Stone_Brick_Smooth_Half",
      "rotation": 8
    },
    {
      "x": -8,
      "y": 5,
      "z": 3,
      "name": "Rock_Stone_Brick_Smooth"
    },
    {
      "x": -8,
      "y": 11,
      "z": 3,
      "name": "Rock_Stone_Brick_Smooth_Half",
      "rotation": 8
    },
    {
      "x": -8,
      "y": 5,
      "z": 4,
      "name": "Rock_Stone_Brick_Smooth"
    },
    {
      "x": -8,
      "y": 11,
      "z": 4,
      "name": "Rock_Stone_Brick_Smooth_Half",
      "rotation": 8
    },
    {
      "x": -8,
      "y": 5,
      "z": 5,
      "name": "Rock_Stone_Brick_Smooth"
    },
    {
      "x": -8,
      "y": 11,
      "z": 5,
      "name": "Rock_Stone_Brick_Smooth_Half",
      "rotation": 8
    },
    {
      "x": -8,
      "y": 5,
      "z": 6,
      "name": "Rock_Stone_Brick_Smooth"
    },
    {
      "x": -8,
      "y": 11,
      "z": 6,
      "name": "Rock_Stone_Brick"
    },
    {
      "x": -8,
      "y": 5,
      "z": 7,
      "name": "Rock_Stone_Brick_Smooth"
    },
    {
      "x": -8,
      "y": 11,
      "z": 7,
      "name": "Rock_Stone_Brick_Smooth_Half",
      "rotation": 8
    },
    {
      "x": -8,
      "y": 5,
      "z": 8,
      "name": "Rock_Stone_Brick_Smooth"
    },
    {
      "x": -8,
      "y": 11,
      "z": 8,
      "name": "Rock_Stone_Brick_Smooth_Half",
      "rotation": 8
    },
    {
      "x": -8,
      "y": 5,
      "z": 9,
      "name": "Rock_Stone_Brick_Smooth"
    },
    {
      "x": -8,
      "y": 11,
      "z": 9,
      "name": "Rock_Stone_Brick_Smooth_Half",
      "rotation": 8
    },
    {
      "x": -8,
      "y": 5,
      "z": 10,
      "name": "Rock_Stone_Brick_Smooth"
    },
    {
      "x": -8,
      "y": 11,
      "z": 10,
      "name": "Rock_Stone_Brick_Smooth_Half",
      "rotation": 8
    },
    {
      "x": -8,
      "y": 5,
      "z": 11,
      "name": "Rock_Stone_Brick_Smooth"
    },
    {
      "x": -8,
      "y": 11,
      "z": 11,
      "name": "Rock_Stone_Brick_Smooth_Half",
      "rotation": 8
    },
    {
      "x": -8,
      "y": 5,
      "z": 12,
      "name": "Rock_Stone_Brick_Smooth"
    },
    {
      "x": -8,
      "y": 6,
      "z": 12,
      "name": "Rock_Stone_Brick_Smooth",
      "rotation": 1
    },
    {
      "x": -8,
      "y": 7,
      "z": 12,
      "name": "Rock_Stone_Brick_Pillar_Base",
      "rotation": 2
    },
    {
      "x": -8,
      "y": 8,
      "z": 12,
      "name": "Rock_Stone_Brick_Pillar_Middle",
      "rotation": 2
    },
    {
      "x": -8,
      "y": 9,
      "z": 12,
      "name": "Rock_Stone_Brick_Pillar_Middle",
      "rotation": 2
    },
    {
      "x": -8,
      "y": 10,
      "z": 12,
      "name": "Rock_Stone_Brick_Pillar_Base",
      "rotation": 10
    },
    {
      "x": -8,
      "y": 11,
      "z": 12,
      "name": "Rock_Stone_Brick"
    },
    {
      "x": -8,
      "y": 6,
      "z": 13,
      "name": "Rock_Stone_Brick_Smooth",
      "support": 15
    },
    {
      "x": -8,
      "y": 7,
      "z": 13,
      "name": "Soil_Gravel",
      "support": 15
    },
    {
      "x": -8,
      "y": 8,
      "z": 13,
      "name": "Soil_Gravel",
      "support": 15
    },
    {
      "x": -8,
      "y": 9,
      "z": 13,
      "name": "Soil_Gravel"
    },
    {
      "x": -8,
      "y": 10,
      "z": 13,
      "name": "Soil_Gravel"
    },
    {
      "x": -7,
      "y": 5,
      "z": -8,
      "name": "Rock_Stone_Brick_Smooth",
      "support": 15
    },
    {
      "x": -7,
      "y": 6,
      "z": -8,
      "name": "Rock_Stone_Brick_Decorative",
      "support": 15,
      "rotation": 1
    },
    {
      "x": -7,
      "y": 7,
      "z": -8,
      "name": "Soil_Gravel_Half",
      "support": 15,
      "rotation": 4
    },
    {
      "x": -7,
      "y": 8,
      "z": -8,
      "name": "Soil_Gravel_Half",
      "support": 15,
      "rotation": 4
    },
    {
      "x": -7,
      "y": 9,
      "z": -8,
      "name": "Soil_Gravel_Half",
      "rotation": 4
    },
    {
      "x": -7,
      "y": 10,
      "z": -8,
      "name": "Soil_Gravel_Half",
      "rotation": 4
    },
    {
      "x": -7,
      "y": 11,
      "z": -8,
      "name": "Rock_Stone_Brick"
    },
    {
      "x": -7,
      "y": 5,
      "z": -7,
      "name": "Rock_Stone_Brick_Smooth"
    },
    {
      "x": -7,
      "y": 11,
      "z": -7,
      "name": "Rock_Stone_Brick_Smooth_Half",
      "rotation": 8
    },
    {
      "x": -7,
      "y": 5,
      "z": -6,
      "name": "Rock_Stone_Brick_Smooth"
    },
    {
      "x": -7,
      "y": 11,
      "z": -6,
      "name": "Rock_Stone_Brick_Smooth_Half",
      "rotation": 8
    },
    {
      "x": -7,
      "y": 5,
      "z": -5,
      "name": "Rock_Stone_Brick_Smooth"
    },
    {
      "x": -7,
      "y": 11,
      "z": -5,
      "name": "Rock_Stone_Brick_Smooth_Half",
      "rotation": 8
    },
    {
      "x": -7,
      "y": 5,
      "z": -4,
      "name": "Rock_Stone_Brick_Smooth"
    },
    {
      "x": -7,
      "y": 11,
      "z": -4,
      "name": "Rock_Stone_Brick_Smooth_Half",
      "rotation": 8
    },
    {
      "x": -7,
      "y": 5,
      "z": -3,
      "name": "Rock_Stone_Brick_Smooth"
    },
    {
      "x": -7,
      "y": 11,
      "z": -3,
      "name": "Rock_Stone_Brick_Smooth_Half",
      "rotation": 8
    },
    {
      "x": -7,
      "y": 5,
      "z": -2,
      "name": "Rock_Stone_Brick_Smooth"
    },
    {
      "x": -7,
      "y": 11,
      "z": -2,
      "name": "Rock_Stone_Brick_Smooth_Half",
      "rotation": 8
    },
    {
      "x": -7,
      "y": 5,
      "z": -1,
      "name": "Rock_Stone_Brick_Smooth"
    },
    {
      "x": -7,
      "y": 11,
      "z": -1,
      "name": "Rock_Stone_Brick_Smooth_Half",
      "rotation": 8
    },
    {
      "x": -7,
      "y": 5,
      "z": 0,
      "name": "Rock_Stone_Brick_Smooth"
    },
    {
      "x": -7,
      "y": 11,
      "z": 0,
      "name": "Rock_Stone_Brick_Smooth_Half",
      "rotation": 8
    },
    {
      "x": -7,
      "y": 5,
      "z": 1,
      "name": "Rock_Stone_Brick_Smooth"
    },
    {
      "x": -7,
      "y": 6,
      "z": 1,
      "name": "Rock_Stone_Brick_Smooth_Half",
      "rotation": 7
    },
    {
      "x": -7,
      "y": 7,
      "z": 1,
      "name": "Rock_Stone_Brick_Smooth_Half",
      "rotation": 7
    },
    {
      "x": -7,
      "y": 8,
      "z": 1,
      "name": "Rock_Stone_Brick_Smooth_Half",
      "rotation": 7
    },
    {
      "x": -7,
      "y": 9,
      "z": 1,
      "name": "Rock_Stone_Brick_Stairs",
      "rotation": 9
    },
    {
      "x": -7,
      "y": 10,
      "z": 1,
      "name": "Rock_Stone_Brick_Decorative"
    },
    {
      "x": -7,
      "y": 11,
      "z": 1,
      "name": "Rock_Stone_Brick"
    },
    {
      "x": -7,
      "y": 5,
      "z": 2,
      "name": "Rock_Stone_Brick_Smooth"
    },
    {
      "x": -7,
      "y": 11,
      "z": 2,
      "name": "Rock_Stone_Brick_Smooth_Half",
      "rotation": 8
    },
    {
      "x": -7,
      "y": 5,
      "z": 3,
      "name": "Rock_Stone_Brick_Smooth"
    },
    {
      "x": -7,
      "y": 11,
      "z": 3,
      "name": "Rock_Stone_Brick_Smooth_Half",
      "rotation": 8
    },
    {
      "x": -7,
      "y": 5,
      "z": 4,
      "name": "Rock_Stone_Brick_Smooth"
    },
    {
      "x": -7,
      "y": 11,
      "z": 4,
      "name": "Rock_Stone_Brick_Smooth_Half",
      "rotation": 8
    },
    {
      "x": -7,
      "y": 5,
      "z": 5,
      "name": "Rock_Stone_Brick_Smooth"
    },
    {
      "x": -7,
      "y": 11,
      "z": 5,
      "name": "Rock_Stone_Brick_Smooth_Half",
      "rotation": 8
    },
    {
      "x": -7,
      "y": 5,
      "z": 6,
      "name": "Rock_Stone_Brick_Smooth"
    },
    {
      "x": -7,
      "y": 11,
      "z": 6,
      "name": "Rock_Stone_Brick"
    },
    {
      "x": -7,
      "y": 5,
      "z": 7,
      "name": "Rock_Stone_Brick_Smooth"
    },
    {
      "x": -7,
      "y": 11,
      "z": 7,
      "name": "Rock_Stone_Brick_Smooth_Half",
      "rotation": 8
    },
    {
      "x": -7,
      "y": 5,
      "z": 8,
      "name": "Rock_Stone_Brick_Smooth"
    },
    {
      "x": -7,
      "y": 11,
      "z": 8,
      "name": "Rock_Stone_Brick_Smooth_Half",
      "rotation": 8
    },
    {
      "x": -7,
      "y": 5,
      "z": 9,
      "name": "Rock_Stone_Brick_Smooth"
    },
    {
      "x": -7,
      "y": 11,
      "z": 9,
      "name": "Rock_Stone_Brick_Smooth_Half",
      "rotation": 8
    },
    {
      "x": -7,
      "y": 5,
      "z": 10,
      "name": "Rock_Stone_Brick_Smooth"
    },
    {
      "x": -7,
      "y": 11,
      "z": 10,
      "name": "Rock_Stone_Brick_Smooth_Half",
      "rotation": 8
    },
    {
      "x": -7,
      "y": 5,
      "z": 11,
      "name": "Rock_Stone_Brick_Smooth"
    },
    {
      "x": -7,
      "y": 11,
      "z": 11,
      "name": "Rock_Stone_Brick_Smooth_Half",
      "rotation": 8
    },
    {
      "x": -7,
      "y": 5,
      "z": 12,
      "name": "Rock_Stone_Brick_Smooth",
      "support": 15
    },
    {
      "x": -7,
      "y": 6,
      "z": 12,
      "name": "Rock_Stone_Brick_Decorative",
      "support": 15,
      "rotation": 1
    },
    {
      "x": -7,
      "y": 7,
      "z": 12,
      "name": "Soil_Gravel_Half",
      "support": 15,
      "rotation": 6
    },
    {
      "x": -7,
      "y": 8,
      "z": 12,
      "name": "Soil_Gravel_Half",
      "support": 15,
      "rotation": 6
    },
    {
      "x": -7,
      "y": 9,
      "z": 12,
      "name": "Soil_Gravel_Half",
      "rotation": 6
    },
    {
      "x": -7,
      "y": 10,
      "z": 12,
      "name": "Soil_Gravel_Half",
      "rotation": 6
    },
    {
      "x": -7,
      "y": 11,
      "z": 12,
      "name": "Rock_Stone_Brick"
    },
    {
      "x": -6,
      "y": 5,
      "z": -8,
      "name": "Rock_Stone_Brick_Smooth",
      "support": 15
    },
    {
      "x": -6,
      "y": 6,
      "z": -8,
      "name": "Rock_Stone_Brick_Decorative",
      "support": 15
    },
    {
      "x": -6,
      "y": 7,
      "z": -8,
      "name": "Soil_Gravel_Half",
      "support": 15,
      "rotation": 4
    },
    {
      "x": -6,
      "y": 8,
      "z": -8,
      "name": "Soil_Gravel_Half",
      "support": 15,
      "rotation": 4
    },
    {
      "x": -6,
      "y": 9,
      "z": -8,
      "name": "Soil_Gravel_Half",
      "rotation": 4
    },
    {
      "x": -6,
      "y": 10,
      "z": -8,
      "name": "Soil_Gravel_Half",
      "rotation": 4
    },
    {
      "x": -6,
      "y": 11,
      "z": -8,
      "name": "Rock_Stone_Brick"
    },
    {
      "x": -6,
      "y": 5,
      "z": -7,
      "name": "Rock_Stone_Brick_Smooth"
    },
    {
      "x": -6,
      "y": 11,
      "z": -7,
      "name": "Rock_Stone_Brick_Smooth_Half",
      "rotation": 8
    },
    {
      "x": -6,
      "y": 5,
      "z": -6,
      "name": "Rock_Stone_Brick_Smooth"
    },
    {
      "x": -6,
      "y": 11,
      "z": -6,
      "name": "Rock_Stone_Brick_Smooth_Half",
      "rotation": 8
    },
    {
      "x": -6,
      "y": 5,
      "z": -5,
      "name": "Rock_Stone_Brick_Smooth"
    },
    {
      "x": -6,
      "y": 11,
      "z": -5,
      "name": "Rock_Stone_Brick_Smooth_Half",
      "rotation": 8
    },
    {
      "x": -6,
      "y": 5,
      "z": -4,
      "name": "Rock_Stone_Brick_Smooth"
    },
    {
      "x": -6,
      "y": 11,
      "z": -4,
      "name": "Rock_Stone_Brick_Smooth_Half",
      "rotation": 8
    },
    {
      "x": -6,
      "y": 5,
      "z": -3,
      "name": "Rock_Stone_Brick_Smooth"
    },
    {
      "x": -6,
      "y": 11,
      "z": -3,
      "name": "Rock_Stone_Brick_Smooth_Half",
      "rotation": 8
    },
    {
      "x": -6,
      "y": 5,
      "z": -2,
      "name": "Rock_Stone_Brick_Smooth"
    },
    {
      "x": -6,
      "y": 11,
      "z": -2,
      "name": "Rock_Stone_Brick_Smooth_Half",
      "rotation": 8
    },
    {
      "x": -6,
      "y": 5,
      "z": -1,
      "name": "Rock_Stone_Brick_Smooth"
    },
    {
      "x": -6,
      "y": 11,
      "z": -1,
      "name": "Rock_Stone_Brick_Smooth_Half",
      "rotation": 8
    },
    {
      "x": -6,
      "y": 5,
      "z": 0,
      "name": "Rock_Stone_Brick_Smooth"
    },
    {
      "x": -6,
      "y": 6,
      "z": 0,
      "name": "Rock_Stone_Brick_Smooth",
      "rotation": 3
    },
    {
      "x": -6,
      "y": 7,
      "z": 0,
      "name": "Rock_Stone_Brick_Pillar_Base"
    },
    {
      "x": -6,
      "y": 8,
      "z": 0,
      "name": "Rock_Stone_Brick_Pillar_Middle",
      "rotation": 8
    },
    {
      "x": -6,
      "y": 9,
      "z": 0,
      "name": "Rock_Stone_Brick_Pillar_Middle"
    },
    {
      "x": -6,
      "y": 10,
      "z": 0,
      "name": "Rock_Stone_Brick_Pillar_Base",
      "rotation": 8
    },
    {
      "x": -6,
      "y": 11,
      "z": 0,
      "name": "Rock_Stone_Brick_Smooth"
    },
    {
      "x": -6,
      "y": 5,
      "z": 1,
      "name": "Rock_Stone_Brick_Smooth"
    },
    {
      "x": -6,
      "y": 6,
      "z": 1,
      "name": "Rock_Stone_Brick"
    },
    {
      "x": -6,
      "y": 7,
      "z": 1,
      "name": "Rock_Stone_Brick"
    },
    {
      "x": -6,
      "y": 8,
      "z": 1,
      "name": "Rock_Stone_Brick"
    },
    {
      "x": -6,
      "y": 9,
      "z": 1,
      "name": "Rock_Stone_Brick"
    },
    {
      "x": -6,
      "y": 10,
      "z": 1,
      "name": "Rock_Stone_Brick"
    },
    {
      "x": -6,
      "y": 11,
      "z": 1,
      "name": "Rock_Stone_Brick"
    },
    {
      "x": -6,
      "y": 5,
      "z": 2,
      "name": "Rock_Stone_Brick_Smooth"
    },
    {
      "x": -6,
      "y": 6,
      "z": 2,
      "name": "Rock_Stone_Brick_Smooth",
      "rotation": 3
    },
    {
      "x": -6,
      "y": 7,
      "z": 2,
      "name": "Rock_Stone_Brick_Pillar_Base"
    },
    {
      "x": -6,
      "y": 8,
      "z": 2,
      "name": "Rock_Stone_Brick_Pillar_Middle"
    },
    {
      "x": -6,
      "y": 9,
      "z": 2,
      "name": "Rock_Stone_Brick_Pillar_Middle"
    },
    {
      "x": -6,
      "y": 10,
      "z": 2,
      "name": "Rock_Stone_Brick_Pillar_Base",
      "rotation": 8
    },
    {
      "x": -6,
      "y": 11,
      "z": 2,
      "name": "Rock_Stone_Brick"
    },
    {
      "x": -6,
      "y": 5,
      "z": 3,
      "name": "Rock_Stone_Brick_Smooth",
      "support": 15
    },
    {
      "x": -6,
      "y": 6,
      "z": 3,
      "name": "Rock_Stone_Brick_Decorative",
      "support": 15
    },
    {
      "x": -6,
      "y": 7,
      "z": 3,
      "name": "Soil_Gravel_Half",
      "support": 15,
      "rotation": 7
    },
    {
      "x": -6,
      "y": 8,
      "z": 3,
      "name": "Soil_Gravel_Half",
      "support": 15,
      "rotation": 7
    },
    {
      "x": -6,
      "y": 9,
      "z": 3,
      "name": "Soil_Gravel_Half",
      "rotation": 7
    },
    {
      "x": -6,
      "y": 10,
      "z": 3,
      "name": "Soil_Gravel_Half",
      "rotation": 7
    },
    {
      "x": -6,
      "y": 11,
      "z": 3,
      "name": "Rock_Stone_Brick"
    },
    {
      "x": -6,
      "y": 5,
      "z": 4,
      "name": "Rock_Stone_Brick_Smooth",
      "support": 15
    },
    {
      "x": -6,
      "y": 6,
      "z": 4,
      "name": "Rock_Stone_Brick_Decorative",
      "support": 15
    },
    {
      "x": -6,
      "y": 7,
      "z": 4,
      "name": "Soil_Gravel_Half",
      "support": 15,
      "rotation": 7
    },
    {
      "x": -6,
      "y": 8,
      "z": 4,
      "name": "Soil_Gravel_Half",
      "support": 15,
      "rotation": 7
    },
    {
      "x": -6,
      "y": 9,
      "z": 4,
      "name": "Soil_Gravel_Half",
      "rotation": 7
    },
    {
      "x": -6,
      "y": 10,
      "z": 4,
      "name": "Soil_Gravel_Half",
      "rotation": 7
    },
    {
      "x": -6,
      "y": 11,
      "z": 4,
      "name": "Rock_Stone_Brick"
    },
    {
      "x": -6,
      "y": 5,
      "z": 5,
      "name": "Rock_Stone_Brick_Smooth",
      "support": 15
    },
    {
      "x": -6,
      "y": 6,
      "z": 5,
      "name": "Rock_Stone_Brick_Decorative",
      "support": 15
    },
    {
      "x": -6,
      "y": 7,
      "z": 5,
      "name": "Soil_Gravel_Half",
      "support": 15,
      "rotation": 7
    },
    {
      "x": -6,
      "y": 8,
      "z": 5,
      "name": "Soil_Gravel_Half",
      "support": 15,
      "rotation": 7
    },
    {
      "x": -6,
      "y": 9,
      "z": 5,
      "name": "Soil_Gravel_Half",
      "rotation": 7
    },
    {
      "x": -6,
      "y": 10,
      "z": 5,
      "name": "Soil_Gravel_Half",
      "rotation": 7
    },
    {
      "x": -6,
      "y": 11,
      "z": 5,
      "name": "Rock_Stone_Brick"
    },
    {
      "x": -6,
      "y": 5,
      "z": 6,
      "name": "Rock_Stone_Brick_Smooth"
    },
    {
      "x": -6,
      "y": 6,
      "z": 6,
      "name": "Rock_Stone_Brick_Smooth",
      "rotation": 3
    },
    {
      "x": -6,
      "y": 7,
      "z": 6,
      "name": "Rock_Stone_Brick_Pillar_Base"
    },
    {
      "x": -6,
      "y": 8,
      "z": 6,
      "name": "Rock_Stone_Brick_Pillar_Middle"
    },
    {
      "x": -6,
      "y": 9,
      "z": 6,
      "name": "Rock_Stone_Brick_Pillar_Middle"
    },
    {
      "x": -6,
      "y": 10,
      "z": 6,
      "name": "Rock_Stone_Brick_Pillar_Base",
      "rotation": 8
    },
    {
      "x": -6,
      "y": 11,
      "z": 6,
      "name": "Rock_Stone_Brick"
    },
    {
      "x": -6,
      "y": 5,
      "z": 7,
      "name": "Rock_Stone_Brick_Smooth"
    },
    {
      "x": -6,
      "y": 11,
      "z": 7,
      "name": "Rock_Stone_Brick_Smooth_Half",
      "rotation": 8
    },
    {
      "x": -6,
      "y": 5,
      "z": 8,
      "name": "Rock_Stone_Brick_Smooth"
    },
    {
      "x": -6,
      "y": 11,
      "z": 8,
      "name": "Rock_Stone_Brick_Smooth_Half",
      "rotation": 8
    },
    {
      "x": -6,
      "y": 5,
      "z": 9,
      "name": "Rock_Stone_Brick_Smooth"
    },
    {
      "x": -6,
      "y": 11,
      "z": 9,
      "name": "Rock_Stone_Brick_Smooth_Half",
      "rotation": 8
    },
    {
      "x": -6,
      "y": 5,
      "z": 10,
      "name": "Rock_Stone_Brick_Smooth"
    },
    {
      "x": -6,
      "y": 11,
      "z": 10,
      "name": "Rock_Stone_Brick_Smooth_Half",
      "rotation": 8
    },
    {
      "x": -6,
      "y": 5,
      "z": 11,
      "name": "Rock_Stone_Brick_Smooth"
    },
    {
      "x": -6,
      "y": 11,
      "z": 11,
      "name": "Rock_Stone_Brick_Smooth_Half",
      "rotation": 8
    },
    {
      "x": -6,
      "y": 5,
      "z": 12,
      "name": "Rock_Stone_Brick_Smooth",
      "support": 15
    },
    {
      "x": -6,
      "y": 6,
      "z": 12,
      "name": "Rock_Stone_Brick_Decorative",
      "support": 15,
      "rotation": 1
    },
    {
      "x": -6,
      "y": 7,
      "z": 12,
      "name": "Soil_Gravel_Half",
      "support": 15,
      "rotation": 6
    },
    {
      "x": -6,
      "y": 8,
      "z": 12,
      "name": "Soil_Gravel_Half",
      "support": 15,
      "rotation": 6
    },
    {
      "x": -6,
      "y": 9,
      "z": 12,
      "name": "Soil_Gravel_Half",
      "rotation": 6
    },
    {
      "x": -6,
      "y": 10,
      "z": 12,
      "name": "Soil_Gravel_Half",
      "rotation": 6
    },
    {
      "x": -6,
      "y": 11,
      "z": 12,
      "name": "Rock_Stone_Brick"
    },
    {
      "x": -5,
      "y": 6,
      "z": -9,
      "name": "Rock_Stone_Brick"
    },
    {
      "x": -5,
      "y": 7,
      "z": -9,
      "name": "Rock_Stone_Brick"
    },
    {
      "x": -5,
      "y": 8,
      "z": -9,
      "name": "Rock_Stone_Brick"
    },
    {
      "x": -5,
      "y": 9,
      "z": -9,
      "name": "Rock_Stone_Brick"
    },
    {
      "x": -5,
      "y": 10,
      "z": -9,
      "name": "Rock_Stone_Brick"
    },
    {
      "x": -5,
      "y": 11,
      "z": -9,
      "name": "Rock_Stone_Brick"
    },
    {
      "x": -5,
      "y": 5,
      "z": -8,
      "name": "Rock_Stone_Brick_Smooth"
    },
    {
      "x": -5,
      "y": 6,
      "z": -8,
      "name": "Rock_Stone_Brick_Smooth"
    },
    {
      "x": -5,
      "y": 7,
      "z": -8,
      "name": "Rock_Stone_Brick_Pillar_Base",
      "rotation": 1
    },
    {
      "x": -5,
      "y": 8,
      "z": -8,
      "name": "Rock_Stone_Brick_Pillar_Middle",
      "rotation": 1
    },
    {
      "x": -5,
      "y": 9,
      "z": -8,
      "name": "Rock_Stone_Brick_Pillar_Middle",
      "rotation": 1
    },
    {
      "x": -5,
      "y": 10,
      "z": -8,
      "name": "Rock_Stone_Brick_Pillar_Base",
      "rotation": 9
    },
    {
      "x": -5,
      "y": 11,
      "z": -8,
      "name": "Rock_Stone_Brick_Smooth"
    },
    {
      "x": -5,
      "y": 5,
      "z": -7,
      "name": "Rock_Stone_Brick_Smooth"
    },
    {
      "x": -5,
      "y": 11,
      "z": -7,
      "name": "Rock_Stone_Brick_Smooth_Half",
      "rotation": 8
    },
    {
      "x": -5,
      "y": 5,
      "z": -6,
      "name": "Rock_Stone_Brick_Smooth"
    },
    {
      "x": -5,
      "y": 11,
      "z": -6,
      "name": "Rock_Stone_Brick_Smooth_Half",
      "rotation": 8
    },
    {
      "x": -5,
      "y": 5,
      "z": -5,
      "name": "Rock_Stone_Brick_Smooth"
    },
    {
      "x": -5,
      "y": 11,
      "z": -5,
      "name": "Rock_Stone_Brick_Smooth_Half",
      "rotation": 8
    },
    {
      "x": -5,
      "y": 5,
      "z": -4,
      "name": "Rock_Stone_Brick_Smooth"
    },
    {
      "x": -5,
      "y": 11,
      "z": -4,
      "name": "Rock_Stone_Brick_Smooth_Half",
      "rotation": 8
    },
    {
      "x": -5,
      "y": 5,
      "z": -3,
      "name": "Rock_Stone_Brick_Smooth"
    },
    {
      "x": -5,
      "y": 11,
      "z": -3,
      "name": "Rock_Stone_Brick_Smooth_Half",
      "rotation": 8
    },
    {
      "x": -5,
      "y": 5,
      "z": -2,
      "name": "Rock_Stone_Brick_Smooth"
    },
    {
      "x": -5,
      "y": 11,
      "z": -2,
      "name": "Rock_Stone_Brick_Smooth_Half",
      "rotation": 8
    },
    {
      "x": -5,
      "y": 5,
      "z": -1,
      "name": "Rock_Stone_Brick_Smooth"
    },
    {
      "x": -5,
      "y": 6,
      "z": -1,
      "name": "Furniture_Castle_Bench",
      "rotation": 2
    },
    {
      "x": -5,
      "y": 11,
      "z": -1,
      "name": "Rock_Stone_Brick_Smooth_Half",
      "rotation": 8
    },
    {
      "x": -5,
      "y": 5,
      "z": 0,
      "name": "Rock_Stone_Brick",
      "support": 15
    },
    {
      "x": -5,
      "y": 6,
      "z": 0,
      "name": "Rock_Stone_Brick_Decorative",
      "support": 15
    },
    {
      "x": -5,
      "y": 7,
      "z": 0,
      "name": "Soil_Gravel_Half",
      "support": 15,
      "rotation": 6
    },
    {
      "x": -5,
      "y": 8,
      "z": 0,
      "name": "Soil_Gravel_Half",
      "support": 15,
      "rotation": 6
    },
    {
      "x": -5,
      "y": 9,
      "z": 0,
      "name": "Soil_Gravel_Half",
      "rotation": 6
    },
    {
      "x": -5,
      "y": 10,
      "z": 0,
      "name": "Soil_Gravel_Half",
      "rotation": 6
    },
    {
      "x": -5,
      "y": 11,
      "z": 0,
      "name": "Rock_Stone_Brick"
    },
    {
      "x": -5,
      "y": 6,
      "z": 2,
      "name": "Rock_Stone_Brick_Decorative",
      "support": 15
    },
    {
      "x": -5,
      "y": 7,
      "z": 2,
      "name": "Soil_Gravel",
      "support": 15
    },
    {
      "x": -5,
      "y": 8,
      "z": 2,
      "name": "Soil_Gravel",
      "support": 15
    },
    {
      "x": -5,
      "y": 9,
      "z": 2,
      "name": "Soil_Gravel"
    },
    {
      "x": -5,
      "y": 10,
      "z": 2,
      "name": "Soil_Gravel"
    },
    {
      "x": -5,
      "y": 5,
      "z": 6,
      "name": "Rock_Stone_Brick_Smooth",
      "support": 15
    },
    {
      "x": -5,
      "y": 6,
      "z": 6,
      "name": "Soil_Gravel",
      "support": 15
    },
    {
      "x": -5,
      "y": 7,
      "z": 6,
      "name": "Soil_Gravel",
      "support": 15
    },
    {
      "x": -5,
      "y": 8,
      "z": 6,
      "name": "Soil_Gravel",
      "support": 15
    },
    {
      "x": -5,
      "y": 9,
      "z": 6,
      "name": "Soil_Gravel"
    },
    {
      "x": -5,
      "y": 10,
      "z": 6,
      "name": "Soil_Gravel"
    },
    {
      "x": -5,
      "y": 5,
      "z": 7,
      "name": "Rock_Stone_Brick_Smooth"
    },
    {
      "x": -5,
      "y": 6,
      "z": 7,
      "name": "Rock_Stone_Brick_Decorative"
    },
    {
      "x": -5,
      "y": 11,
      "z": 7,
      "name": "Rock_Stone_Brick"
    },
    {
      "x": -5,
      "y": 5,
      "z": 8,
      "name": "Rock_Stone_Brick_Smooth"
    },
    {
      "x": -5,
      "y": 11,
      "z": 8,
      "name": "Rock_Stone_Brick_Smooth_Half",
      "rotation": 8
    },
    {
      "x": -5,
      "y": 5,
      "z": 9,
      "name": "Rock_Stone_Brick_Smooth"
    },
    {
      "x": -5,
      "y": 11,
      "z": 9,
      "name": "Rock_Stone_Brick_Smooth_Half",
      "rotation": 8
    },
    {
      "x": -5,
      "y": 5,
      "z": 10,
      "name": "Rock_Stone_Brick_Smooth"
    },
    {
      "x": -5,
      "y": 11,
      "z": 10,
      "name": "Rock_Stone_Brick_Smooth_Half",
      "rotation": 8
    },
    {
      "x": -5,
      "y": 5,
      "z": 11,
      "name": "Rock_Stone_Brick_Smooth"
    },
    {
      "x": -5,
      "y": 11,
      "z": 11,
      "name": "Rock_Stone_Brick_Smooth_Half",
      "rotation": 8
    },
    {
      "x": -5,
      "y": 5,
      "z": 12,
      "name": "Rock_Stone_Brick_Smooth",
      "support": 15
    },
    {
      "x": -5,
      "y": 6,
      "z": 12,
      "name": "Rock_Stone_Brick_Decorative",
      "support": 15,
      "rotation": 1
    },
    {
      "x": -5,
      "y": 7,
      "z": 12,
      "name": "Soil_Gravel_Half",
      "support": 15,
      "rotation": 6
    },
    {
      "x": -5,
      "y": 8,
      "z": 12,
      "name": "Soil_Gravel_Half",
      "support": 15,
      "rotation": 6
    },
    {
      "x": -5,
      "y": 9,
      "z": 12,
      "name": "Soil_Gravel_Half",
      "rotation": 6
    },
    {
      "x": -5,
      "y": 10,
      "z": 12,
      "name": "Soil_Gravel_Half",
      "rotation": 6
    },
    {
      "x": -5,
      "y": 11,
      "z": 12,
      "name": "Rock_Stone_Brick"
    },
    {
      "x": -4,
      "y": 6,
      "z": -9,
      "name": "Rock_Stone_Brick_Decorative",
      "support": 15
    },
    {
      "x": -4,
      "y": 7,
      "z": -9,
      "name": "Soil_Gravel_Half",
      "support": 15,
      "rotation": 4
    },
    {
      "x": -4,
      "y": 8,
      "z": -9,
      "name": "Soil_Gravel_Half",
      "support": 15,
      "rotation": 4
    },
    {
      "x": -4,
      "y": 9,
      "z": -9,
      "name": "Soil_Gravel_Half",
      "rotation": 4
    },
    {
      "x": -4,
      "y": 10,
      "z": -9,
      "name": "Soil_Gravel_Half",
      "rotation": 4
    },
    {
      "x": -4,
      "y": 11,
      "z": -9,
      "name": "Rock_Stone_Brick"
    },
    {
      "x": -4,
      "y": 5,
      "z": -8,
      "name": "Rock_Stone_Brick_Smooth"
    },
    {
      "x": -4,
      "y": 11,
      "z": -8,
      "name": "Rock_Stone_Brick_Smooth_Half",
      "rotation": 8
    },
    {
      "x": -4,
      "y": 5,
      "z": -7,
      "name": "Rock_Stone_Brick_Smooth"
    },
    {
      "x": -4,
      "y": 11,
      "z": -7,
      "name": "Rock_Stone_Brick_Smooth_Half",
      "rotation": 8
    },
    {
      "x": -4,
      "y": 5,
      "z": -6,
      "name": "Rock_Stone_Brick_Smooth"
    },
    {
      "x": -4,
      "y": 11,
      "z": -6,
      "name": "Rock_Stone_Brick_Smooth_Half",
      "rotation": 8
    },
    {
      "x": -4,
      "y": 5,
      "z": -5,
      "name": "Rock_Stone_Brick_Smooth"
    },
    {
      "x": -4,
      "y": 11,
      "z": -5,
      "name": "Rock_Stone_Brick_Smooth_Half",
      "rotation": 8
    },
    {
      "x": -4,
      "y": 5,
      "z": -4,
      "name": "Rock_Stone_Brick_Smooth"
    },
    {
      "x": -4,
      "y": 11,
      "z": -4,
      "name": "Rock_Stone_Brick_Smooth_Half",
      "rotation": 8
    },
    {
      "x": -4,
      "y": 5,
      "z": -3,
      "name": "Rock_Stone_Brick_Smooth"
    },
    {
      "x": -4,
      "y": 11,
      "z": -3,
      "name": "Rock_Stone_Brick_Smooth_Half",
      "rotation": 8
    },
    {
      "x": -4,
      "y": 5,
      "z": -2,
      "name": "Rock_Stone_Brick_Smooth"
    },
    {
      "x": -4,
      "y": 11,
      "z": -2,
      "name": "Rock_Stone_Brick_Smooth_Half",
      "rotation": 8
    },
    {
      "x": -4,
      "y": 5,
      "z": -1,
      "name": "Rock_Stone_Brick_Smooth"
    },
    {
      "x": -4,
      "y": 6,
      "z": -1,
      "name": "Furniture_Castle_Bench",
      "filler": 1,
      "rotation": 2
    },
    {
      "x": -4,
      "y": 11,
      "z": -1,
      "name": "Rock_Stone_Brick_Smooth_Half",
      "rotation": 8
    },
    {
      "x": -4,
      "y": 6,
      "z": 0,
      "name": "Rock_Stone_Brick_Decorative",
      "support": 15
    },
    {
      "x": -4,
      "y": 7,
      "z": 0,
      "name": "Soil_Gravel_Half",
      "support": 15,
      "rotation": 6
    },
    {
      "x": -4,
      "y": 8,
      "z": 0,
      "name": "Soil_Gravel_Half",
      "support": 15,
      "rotation": 6
    },
    {
      "x": -4,
      "y": 9,
      "z": 0,
      "name": "Soil_Gravel_Half",
      "rotation": 6
    },
    {
      "x": -4,
      "y": 10,
      "z": 0,
      "name": "Soil_Gravel_Half",
      "rotation": 6
    },
    {
      "x": -4,
      "y": 11,
      "z": 0,
      "name": "Rock_Stone_Brick"
    },
    {
      "x": -4,
      "y": 5,
      "z": 7,
      "name": "Rock_Stone_Brick_Smooth",
      "support": 15
    },
    {
      "x": -4,
      "y": 6,
      "z": 7,
      "name": "Soil_Gravel",
      "support": 15
    },
    {
      "x": -4,
      "y": 7,
      "z": 7,
      "name": "Soil_Gravel",
      "support": 15
    },
    {
      "x": -4,
      "y": 8,
      "z": 7,
      "name": "Soil_Gravel",
      "support": 15
    },
    {
      "x": -4,
      "y": 9,
      "z": 7,
      "name": "Soil_Gravel"
    },
    {
      "x": -4,
      "y": 10,
      "z": 7,
      "name": "Soil_Gravel"
    },
    {
      "x": -4,
      "y": 5,
      "z": 8,
      "name": "Rock_Stone_Brick_Smooth"
    },
    {
      "x": -4,
      "y": 6,
      "z": 8,
      "name": "Rock_Stone_Brick_Smooth"
    },
    {
      "x": -4,
      "y": 7,
      "z": 8,
      "name": "Rock_Stone_Brick_Pillar_Base",
      "rotation": 1
    },
    {
      "x": -4,
      "y": 8,
      "z": 8,
      "name": "Rock_Stone_Brick_Pillar_Middle",
      "rotation": 1
    },
    {
      "x": -4,
      "y": 9,
      "z": 8,
      "name": "Rock_Stone_Brick_Pillar_Middle",
      "rotation": 1
    },
    {
      "x": -4,
      "y": 10,
      "z": 8,
      "name": "Rock_Stone_Brick_Pillar_Base",
      "rotation": 9
    },
    {
      "x": -4,
      "y": 11,
      "z": 8,
      "name": "Rock_Stone_Brick_Smooth"
    },
    {
      "x": -4,
      "y": 5,
      "z": 9,
      "name": "Rock_Stone_Brick_Smooth"
    },
    {
      "x": -4,
      "y": 11,
      "z": 9,
      "name": "Rock_Stone_Brick_Smooth_Half",
      "rotation": 8
    },
    {
      "x": -4,
      "y": 5,
      "z": 10,
      "name": "Rock_Stone_Brick_Smooth"
    },
    {
      "x": -4,
      "y": 11,
      "z": 10,
      "name": "Rock_Stone_Brick_Smooth_Half",
      "rotation": 8
    },
    {
      "x": -4,
      "y": 5,
      "z": 11,
      "name": "Rock_Stone_Brick_Smooth"
    },
    {
      "x": -4,
      "y": 11,
      "z": 11,
      "name": "Rock_Stone_Brick_Smooth_Half",
      "rotation": 8
    },
    {
      "x": -4,
      "y": 5,
      "z": 12,
      "name": "Rock_Stone_Brick_Smooth"
    },
    {
      "x": -4,
      "y": 6,
      "z": 12,
      "name": "Rock_Stone_Brick_Smooth"
    },
    {
      "x": -4,
      "y": 7,
      "z": 12,
      "name": "Rock_Stone_Brick_Pillar_Base",
      "rotation": 1
    },
    {
      "x": -4,
      "y": 8,
      "z": 12,
      "name": "Rock_Stone_Brick_Pillar_Middle",
      "rotation": 1
    },
    {
      "x": -4,
      "y": 9,
      "z": 12,
      "name": "Rock_Stone_Brick_Pillar_Middle",
      "rotation": 1
    },
    {
      "x": -4,
      "y": 10,
      "z": 12,
      "name": "Rock_Stone_Brick_Pillar_Base",
      "rotation": 9
    },
    {
      "x": -4,
      "y": 11,
      "z": 12,
      "name": "Rock_Stone_Brick_Smooth"
    },
    {
      "x": -4,
      "y": 5,
      "z": 13,
      "name": "Rock_Stone_Brick"
    },
    {
      "x": -4,
      "y": 6,
      "z": 13,
      "name": "Rock_Stone_Brick_Decorative",
      "rotation": 2
    },
    {
      "x": -4,
      "y": 7,
      "z": 13,
      "name": "Soil_Gravel_Half",
      "rotation": 5
    },
    {
      "x": -4,
      "y": 8,
      "z": 13,
      "name": "Soil_Gravel_Half",
      "rotation": 5
    },
    {
      "x": -4,
      "y": 9,
      "z": 13,
      "name": "Soil_Gravel_Half",
      "rotation": 5
    },
    {
      "x": -4,
      "y": 10,
      "z": 13,
      "name": "Soil_Gravel_Half",
      "rotation": 5
    },
    {
      "x": -4,
      "y": 11,
      "z": 13,
      "name": "Rock_Stone_Brick"
    },
    {
      "x": -4,
      "y": 5,
      "z": 14,
      "name": "Rock_Stone_Brick"
    },
    {
      "x": -4,
      "y": 6,
      "z": 14,
      "name": "Rock_Stone_Brick_Decorative",
      "rotation": 2
    },
    {
      "x": -4,
      "y": 7,
      "z": 14,
      "name": "Soil_Gravel_Half",
      "rotation": 5
    },
    {
      "x": -4,
      "y": 8,
      "z": 14,
      "name": "Soil_Gravel_Half",
      "rotation": 5
    },
    {
      "x": -4,
      "y": 9,
      "z": 14,
      "name": "Soil_Gravel_Half",
      "rotation": 5
    },
    {
      "x": -4,
      "y": 10,
      "z": 14,
      "name": "Soil_Gravel_Half",
      "rotation": 5
    },
    {
      "x": -4,
      "y": 11,
      "z": 14,
      "name": "Rock_Stone_Brick"
    },
    {
      "x": -4,
      "y": 5,
      "z": 15,
      "name": "Rock_Stone_Brick"
    },
    {
      "x": -4,
      "y": 6,
      "z": 15,
      "name": "Rock_Stone_Brick"
    },
    {
      "x": -4,
      "y": 7,
      "z": 15,
      "name": "Rock_Stone_Brick"
    },
    {
      "x": -4,
      "y": 8,
      "z": 15,
      "name": "Rock_Stone_Brick"
    },
    {
      "x": -4,
      "y": 9,
      "z": 15,
      "name": "Rock_Stone_Brick"
    },
    {
      "x": -4,
      "y": 10,
      "z": 15,
      "name": "Rock_Stone_Brick"
    },
    {
      "x": -4,
      "y": 11,
      "z": 15,
      "name": "Rock_Stone_Brick"
    },
    {
      "x": -3,
      "y": 5,
      "z": -15,
      "name": "Rock_Stone_Brick",
      "rotation": 2
    },
    {
      "x": -3,
      "y": 6,
      "z": -15,
      "name": "Rock_Stone_Brick",
      "rotation": 2
    },
    {
      "x": -3,
      "y": 7,
      "z": -15,
      "name": "Rock_Stone_Brick",
      "rotation": 2
    },
    {
      "x": -3,
      "y": 8,
      "z": -15,
      "name": "Rock_Stone_Brick",
      "rotation": 2
    },
    {
      "x": -3,
      "y": 9,
      "z": -15,
      "name": "Rock_Stone_Brick",
      "rotation": 2
    },
    {
      "x": -3,
      "y": 10,
      "z": -15,
      "name": "Rock_Stone_Brick",
      "rotation": 2
    },
    {
      "x": -3,
      "y": 11,
      "z": -15,
      "name": "Rock_Stone_Brick_Decorative",
      "rotation": 2
    },
    {
      "x": -3,
      "y": 5,
      "z": -14,
      "name": "Rock_Stone_Brick",
      "rotation": 2
    },
    {
      "x": -3,
      "y": 6,
      "z": -14,
      "name": "Rock_Stone_Brick",
      "rotation": 2
    },
    {
      "x": -3,
      "y": 7,
      "z": -14,
      "name": "Rock_Stone_Brick",
      "rotation": 2
    },
    {
      "x": -3,
      "y": 8,
      "z": -14,
      "name": "Rock_Stone_Brick",
      "rotation": 2
    },
    {
      "x": -3,
      "y": 9,
      "z": -14,
      "name": "Rock_Stone_Brick",
      "rotation": 2
    },
    {
      "x": -3,
      "y": 10,
      "z": -14,
      "name": "Rock_Stone_Brick",
      "rotation": 2
    },
    {
      "x": -3,
      "y": 11,
      "z": -14,
      "name": "Rock_Stone_Brick_Decorative",
      "rotation": 2
    },
    {
      "x": -3,
      "y": 5,
      "z": -13,
      "name": "Rock_Stone_Brick",
      "rotation": 2
    },
    {
      "x": -3,
      "y": 6,
      "z": -13,
      "name": "Rock_Stone_Brick",
      "rotation": 2
    },
    {
      "x": -3,
      "y": 7,
      "z": -13,
      "name": "Rock_Stone_Brick",
      "rotation": 2
    },
    {
      "x": -3,
      "y": 8,
      "z": -13,
      "name": "Rock_Stone_Brick",
      "rotation": 2
    },
    {
      "x": -3,
      "y": 9,
      "z": -13,
      "name": "Rock_Stone_Brick",
      "rotation": 2
    },
    {
      "x": -3,
      "y": 10,
      "z": -13,
      "name": "Rock_Stone_Brick",
      "rotation": 2
    },
    {
      "x": -3,
      "y": 11,
      "z": -13,
      "name": "Rock_Stone_Brick_Decorative",
      "rotation": 2
    },
    {
      "x": -3,
      "y": 5,
      "z": -12,
      "name": "Rock_Stone_Brick",
      "rotation": 2
    },
    {
      "x": -3,
      "y": 6,
      "z": -12,
      "name": "Rock_Stone_Brick",
      "rotation": 2
    },
    {
      "x": -3,
      "y": 7,
      "z": -12,
      "name": "Rock_Stone_Brick",
      "rotation": 2
    },
    {
      "x": -3,
      "y": 8,
      "z": -12,
      "name": "Rock_Stone_Brick",
      "rotation": 2
    },
    {
      "x": -3,
      "y": 9,
      "z": -12,
      "name": "Rock_Stone_Brick",
      "rotation": 2
    },
    {
      "x": -3,
      "y": 10,
      "z": -12,
      "name": "Rock_Stone_Brick",
      "rotation": 2
    },
    {
      "x": -3,
      "y": 11,
      "z": -12,
      "name": "Rock_Stone_Brick_Decorative",
      "rotation": 2
    },
    {
      "x": -3,
      "y": 5,
      "z": -11,
      "name": "Rock_Stone_Brick",
      "rotation": 2
    },
    {
      "x": -3,
      "y": 6,
      "z": -11,
      "name": "Rock_Stone_Brick",
      "rotation": 2
    },
    {
      "x": -3,
      "y": 7,
      "z": -11,
      "name": "Rock_Stone_Brick",
      "rotation": 2
    },
    {
      "x": -3,
      "y": 8,
      "z": -11,
      "name": "Rock_Stone_Brick",
      "rotation": 2
    },
    {
      "x": -3,
      "y": 9,
      "z": -11,
      "name": "Rock_Stone_Brick",
      "rotation": 2
    },
    {
      "x": -3,
      "y": 10,
      "z": -11,
      "name": "Rock_Stone_Brick",
      "rotation": 2
    },
    {
      "x": -3,
      "y": 11,
      "z": -11,
      "name": "Rock_Stone_Brick_Decorative",
      "rotation": 2
    },
    {
      "x": -3,
      "y": 5,
      "z": -10,
      "name": "Rock_Stone_Brick",
      "rotation": 2
    },
    {
      "x": -3,
      "y": 6,
      "z": -10,
      "name": "Rock_Stone_Brick",
      "rotation": 2
    },
    {
      "x": -3,
      "y": 7,
      "z": -10,
      "name": "Rock_Stone_Brick",
      "rotation": 2
    },
    {
      "x": -3,
      "y": 8,
      "z": -10,
      "name": "Rock_Stone_Brick",
      "rotation": 2
    },
    {
      "x": -3,
      "y": 9,
      "z": -10,
      "name": "Rock_Stone_Brick",
      "rotation": 2
    },
    {
      "x": -3,
      "y": 10,
      "z": -10,
      "name": "Rock_Stone_Brick",
      "rotation": 2
    },
    {
      "x": -3,
      "y": 11,
      "z": -10,
      "name": "Rock_Stone_Brick_Decorative",
      "rotation": 2
    },
    {
      "x": -3,
      "y": 6,
      "z": -9,
      "name": "Rock_Stone_Brick_Decorative",
      "support": 15
    },
    {
      "x": -3,
      "y": 7,
      "z": -9,
      "name": "Soil_Gravel_Half",
      "support": 15,
      "rotation": 4
    },
    {
      "x": -3,
      "y": 8,
      "z": -9,
      "name": "Soil_Gravel_Half",
      "support": 15,
      "rotation": 4
    },
    {
      "x": -3,
      "y": 9,
      "z": -9,
      "name": "Soil_Gravel_Half",
      "rotation": 4
    },
    {
      "x": -3,
      "y": 10,
      "z": -9,
      "name": "Soil_Gravel_Half",
      "rotation": 4
    },
    {
      "x": -3,
      "y": 11,
      "z": -9,
      "name": "Rock_Stone_Brick"
    },
    {
      "x": -3,
      "y": 5,
      "z": -8,
      "name": "Rock_Stone_Brick_Smooth"
    },
    {
      "x": -3,
      "y": 6,
      "z": -8,
      "name": "Furniture_Temple_Dark_Candle"
    },
    {
      "x": -3,
      "y": 7,
      "z": -8,
      "name": "Furniture_Temple_Dark_Candle",
      "filler": 1024
    },
    {
      "x": -3,
      "y": 11,
      "z": -8,
      "name": "Rock_Stone_Brick_Smooth_Half",
      "rotation": 8
    },
    {
      "x": -3,
      "y": 5,
      "z": -7,
      "name": "Rock_Stone_Brick_Smooth"
    },
    {
      "x": -3,
      "y": 11,
      "z": -7,
      "name": "Rock_Stone_Brick_Smooth_Half",
      "rotation": 8
    },
    {
      "x": -3,
      "y": 5,
      "z": -6,
      "name": "Rock_Stone_Brick_Smooth"
    },
    {
      "x": -3,
      "y": 11,
      "z": -6,
      "name": "Rock_Stone_Brick_Smooth_Half",
      "rotation": 8
    },
    {
      "x": -3,
      "y": 5,
      "z": -5,
      "name": "Rock_Stone_Brick_Smooth"
    },
    {
      "x": -3,
      "y": 11,
      "z": -5,
      "name": "Rock_Stone_Brick_Smooth_Half",
      "rotation": 8
    },
    {
      "x": -3,
      "y": 5,
      "z": -4,
      "name": "Rock_Stone_Brick_Smooth"
    },
    {
      "x": -3,
      "y": 11,
      "z": -4,
      "name": "Rock_Stone_Brick_Smooth_Half",
      "rotation": 8
    },
    {
      "x": -3,
      "y": 5,
      "z": -3,
      "name": "Rock_Stone_Brick_Smooth"
    },
    {
      "x": -3,
      "y": 11,
      "z": -3,
      "name": "Rock_Stone_Brick_Smooth_Half",
      "rotation": 8
    },
    {
      "x": -3,
      "y": 5,
      "z": -2,
      "name": "Rock_Stone_Brick_Smooth"
    },
    {
      "x": -3,
      "y": 11,
      "z": -2,
      "name": "Rock_Stone_Brick_Smooth_Half",
      "rotation": 8
    },
    {
      "x": -3,
      "y": 5,
      "z": -1,
      "name": "Rock_Stone_Brick_Smooth"
    },
    {
      "x": -3,
      "y": 11,
      "z": -1,
      "name": "Rock_Stone_Brick_Smooth_Half",
      "rotation": 8
    },
    {
      "x": -3,
      "y": 6,
      "z": 0,
      "name": "Rock_Stone_Brick_Smooth"
    },
    {
      "x": -3,
      "y": 7,
      "z": 0,
      "name": "Rock_Stone_Brick_Pillar_Base"
    },
    {
      "x": -3,
      "y": 8,
      "z": 0,
      "name": "Rock_Stone_Brick_Pillar_Middle",
      "rotation": 8
    },
    {
      "x": -3,
      "y": 9,
      "z": 0,
      "name": "Rock_Stone_Brick_Pillar_Middle",
      "rotation": 8
    },
    {
      "x": -3,
      "y": 10,
      "z": 0,
      "name": "Rock_Stone_Brick_Pillar_Base",
      "rotation": 8
    },
    {
      "x": -3,
      "y": 11,
      "z": 0,
      "name": "Rock_Stone_Brick_Smooth"
    },
    {
      "x": -3,
      "y": 6,
      "z": 1,
      "name": "Rock_Stone_Brick_Decorative"
    },
    {
      "x": -3,
      "y": 7,
      "z": 1,
      "name": "Rock_Stone_Brick"
    },
    {
      "x": -3,
      "y": 8,
      "z": 1,
      "name": "Rock_Stone_Brick"
    },
    {
      "x": -3,
      "y": 9,
      "z": 1,
      "name": "Rock_Stone_Brick"
    },
    {
      "x": -3,
      "y": 10,
      "z": 1,
      "name": "Rock_Stone_Brick"
    },
    {
      "x": -3,
      "y": 11,
      "z": 1,
      "name": "Rock_Stone_Brick"
    },
    {
      "x": -3,
      "y": 6,
      "z": 2,
      "name": "Rock_Stone_Brick_Decorative",
      "support": 15
    },
    {
      "x": -3,
      "y": 7,
      "z": 2,
      "name": "Soil_Gravel_Half",
      "support": 15,
      "rotation": 5
    },
    {
      "x": -3,
      "y": 8,
      "z": 2,
      "name": "Soil_Gravel_Half",
      "support": 15,
      "rotation": 5
    },
    {
      "x": -3,
      "y": 9,
      "z": 2,
      "name": "Soil_Gravel_Half",
      "rotation": 5
    },
    {
      "x": -3,
      "y": 10,
      "z": 2,
      "name": "Soil_Gravel_Half",
      "rotation": 5
    },
    {
      "x": -3,
      "y": 11,
      "z": 2,
      "name": "Rock_Stone_Brick"
    },
    {
      "x": -3,
      "y": 6,
      "z": 3,
      "name": "Rock_Stone_Brick_Decorative",
      "support": 15
    },
    {
      "x": -3,
      "y": 7,
      "z": 3,
      "name": "Soil_Gravel_Half",
      "support": 15,
      "rotation": 5
    },
    {
      "x": -3,
      "y": 8,
      "z": 3,
      "name": "Soil_Gravel_Half",
      "support": 15,
      "rotation": 5
    },
    {
      "x": -3,
      "y": 9,
      "z": 3,
      "name": "Soil_Gravel_Half",
      "rotation": 5
    },
    {
      "x": -3,
      "y": 10,
      "z": 3,
      "name": "Soil_Gravel_Half",
      "rotation": 5
    },
    {
      "x": -3,
      "y": 11,
      "z": 3,
      "name": "Rock_Stone_Brick"
    },
    {
      "x": -3,
      "y": 6,
      "z": 4,
      "name": "Rock_Stone_Brick_Decorative",
      "support": 15
    },
    {
      "x": -3,
      "y": 7,
      "z": 4,
      "name": "Soil_Gravel_Half",
      "support": 15,
      "rotation": 5
    },
    {
      "x": -3,
      "y": 8,
      "z": 4,
      "name": "Soil_Gravel_Half",
      "support": 15,
      "rotation": 5
    },
    {
      "x": -3,
      "y": 9,
      "z": 4,
      "name": "Soil_Gravel_Half",
      "rotation": 5
    },
    {
      "x": -3,
      "y": 10,
      "z": 4,
      "name": "Soil_Gravel_Half",
      "rotation": 5
    },
    {
      "x": -3,
      "y": 11,
      "z": 4,
      "name": "Rock_Stone_Brick"
    },
    {
      "x": -3,
      "y": 6,
      "z": 5,
      "name": "Rock_Stone_Brick_Decorative",
      "support": 15
    },
    {
      "x": -3,
      "y": 7,
      "z": 5,
      "name": "Soil_Gravel_Half",
      "support": 15,
      "rotation": 5
    },
    {
      "x": -3,
      "y": 8,
      "z": 5,
      "name": "Soil_Gravel_Half",
      "support": 15,
      "rotation": 5
    },
    {
      "x": -3,
      "y": 9,
      "z": 5,
      "name": "Soil_Gravel_Half",
      "rotation": 5
    },
    {
      "x": -3,
      "y": 10,
      "z": 5,
      "name": "Soil_Gravel_Half",
      "rotation": 5
    },
    {
      "x": -3,
      "y": 11,
      "z": 5,
      "name": "Rock_Stone_Brick"
    },
    {
      "x": -3,
      "y": 7,
      "z": 6,
      "name": "Rock_Stone_Brick"
    },
    {
      "x": -3,
      "y": 8,
      "z": 6,
      "name": "Rock_Stone_Brick"
    },
    {
      "x": -3,
      "y": 9,
      "z": 6,
      "name": "Rock_Stone_Brick"
    },
    {
      "x": -3,
      "y": 10,
      "z": 6,
      "name": "Rock_Stone_Brick"
    },
    {
      "x": -3,
      "y": 5,
      "z": 8,
      "name": "Rock_Stone_Brick_Smooth",
      "support": 15
    },
    {
      "x": -3,
      "y": 6,
      "z": 8,
      "name": "Rock_Stone_Brick_Decorative",
      "support": 15,
      "rotation": 1
    },
    {
      "x": -3,
      "y": 7,
      "z": 8,
      "name": "Soil_Gravel_Half",
      "support": 15,
      "rotation": 4
    },
    {
      "x": -3,
      "y": 8,
      "z": 8,
      "name": "Soil_Gravel_Half",
      "support": 15,
      "rotation": 4
    },
    {
      "x": -3,
      "y": 9,
      "z": 8,
      "name": "Soil_Gravel_Half",
      "rotation": 4
    },
    {
      "x": -3,
      "y": 10,
      "z": 8,
      "name": "Soil_Gravel_Half",
      "rotation": 4
    },
    {
      "x": -3,
      "y": 11,
      "z": 8,
      "name": "Rock_Stone_Brick"
    },
    {
      "x": -3,
      "y": 5,
      "z": 9,
      "name": "Rock_Stone_Brick_Smooth"
    },
    {
      "x": -3,
      "y": 11,
      "z": 9,
      "name": "Rock_Stone_Brick_Smooth_Half",
      "rotation": 8
    },
    {
      "x": -3,
      "y": 5,
      "z": 10,
      "name": "Rock_Stone_Brick_Smooth"
    },
    {
      "x": -3,
      "y": 11,
      "z": 10,
      "name": "Rock_Stone_Brick_Smooth_Half",
      "rotation": 8
    },
    {
      "x": -3,
      "y": 5,
      "z": 11,
      "name": "Rock_Stone_Brick_Smooth"
    },
    {
      "x": -3,
      "y": 11,
      "z": 11,
      "name": "Rock_Stone_Brick_Smooth_Half",
      "rotation": 8
    },
    {
      "x": -3,
      "y": 5,
      "z": 12,
      "name": "Rock_Stone_Brick_Smooth"
    },
    {
      "x": -3,
      "y": 11,
      "z": 12,
      "name": "Rock_Stone_Brick_Smooth_Half",
      "rotation": 8
    },
    {
      "x": -3,
      "y": 5,
      "z": 13,
      "name": "Rock_Stone_Brick_Smooth"
    },
    {
      "x": -3,
      "y": 11,
      "z": 13,
      "name": "Rock_Stone_Brick_Smooth_Half",
      "rotation": 8
    },
    {
      "x": -3,
      "y": 5,
      "z": 14,
      "name": "Rock_Stone_Brick_Smooth"
    },
    {
      "x": -3,
      "y": 11,
      "z": 14,
      "name": "Rock_Stone_Brick_Smooth_Half",
      "rotation": 8
    },
    {
      "x": -3,
      "y": 5,
      "z": 15,
      "name": "Rock_Stone_Brick_Smooth"
    },
    {
      "x": -3,
      "y": 6,
      "z": 15,
      "name": "Rock_Stone_Brick_Smooth"
    },
    {
      "x": -3,
      "y": 7,
      "z": 15,
      "name": "Rock_Stone_Brick_Pillar_Base"
    },
    {
      "x": -3,
      "y": 8,
      "z": 15,
      "name": "Rock_Stone_Brick_Pillar_Middle"
    },
    {
      "x": -3,
      "y": 9,
      "z": 15,
      "name": "Rock_Stone_Brick_Pillar_Middle"
    },
    {
      "x": -3,
      "y": 10,
      "z": 15,
      "name": "Rock_Stone_Brick_Pillar_Base",
      "rotation": 8
    },
    {
      "x": -3,
      "y": 11,
      "z": 15,
      "name": "Rock_Stone_Brick_Smooth"
    },
    {
      "x": -3,
      "y": 5,
      "z": 16,
      "name": "Rock_Stone_Brick"
    },
    {
      "x": -3,
      "y": 6,
      "z": 16,
      "name": "Rock_Stone_Brick_Decorative"
    },
    {
      "x": -3,
      "y": 7,
      "z": 16,
      "name": "Rock_Stone_Brick"
    },
    {
      "x": -3,
      "y": 8,
      "z": 16,
      "name": "Rock_Stone_Brick"
    },
    {
      "x": -3,
      "y": 9,
      "z": 16,
      "name": "Rock_Stone_Brick"
    },
    {
      "x": -3,
      "y": 10,
      "z": 16,
      "name": "Rock_Stone_Brick"
    },
    {
      "x": -2,
      "y": 5,
      "z": -16,
      "name": "Rock_Stone_Brick",
      "rotation": 2
    },
    {
      "x": -2,
      "y": 6,
      "z": -16,
      "name": "Rock_Stone_Brick",
      "rotation": 2
    },
    {
      "x": -2,
      "y": 7,
      "z": -16,
      "name": "Rock_Stone_Brick",
      "rotation": 2
    },
    {
      "x": -2,
      "y": 8,
      "z": -16,
      "name": "Rock_Stone_Brick",
      "rotation": 2
    },
    {
      "x": -2,
      "y": 9,
      "z": -16,
      "name": "Rock_Stone_Brick",
      "rotation": 2
    },
    {
      "x": -2,
      "y": 10,
      "z": -16,
      "name": "Rock_Stone_Brick",
      "rotation": 2
    },
    {
      "x": -2,
      "y": 11,
      "z": -16,
      "name": "Rock_Stone_Brick_Decorative",
      "rotation": 2
    },
    {
      "x": -2,
      "y": 5,
      "z": -15,
      "name": "Rock_Stone_Brick_Smooth",
      "rotation": 2
    },
    {
      "x": -2,
      "y": 11,
      "z": -15,
      "name": "Rock_Stone_Brick_Smooth_Half",
      "rotation": 10
    },
    {
      "x": -2,
      "y": 5,
      "z": -14,
      "name": "Rock_Stone_Brick_Smooth",
      "rotation": 2
    },
    {
      "x": -2,
      "y": 11,
      "z": -14,
      "name": "Rock_Stone_Brick_Smooth_Half",
      "rotation": 10
    },
    {
      "x": -2,
      "y": 5,
      "z": -13,
      "name": "Rock_Stone_Brick_Smooth",
      "rotation": 2
    },
    {
      "x": -2,
      "y": 11,
      "z": -13,
      "name": "Rock_Stone_Brick_Smooth_Half",
      "rotation": 10
    },
    {
      "x": -2,
      "y": 5,
      "z": -12,
      "name": "Rock_Stone_Brick_Smooth",
      "rotation": 2
    },
    {
      "x": -2,
      "y": 11,
      "z": -12,
      "name": "Rock_Stone_Brick_Smooth_Half",
      "rotation": 10
    },
    {
      "x": -2,
      "y": 5,
      "z": -11,
      "name": "Rock_Stone_Brick_Smooth",
      "rotation": 2
    },
    {
      "x": -2,
      "y": 11,
      "z": -11,
      "name": "Rock_Stone_Brick_Smooth_Half",
      "rotation": 10
    },
    {
      "x": -2,
      "y": 5,
      "z": -10,
      "name": "Rock_Stone_Brick_Smooth",
      "rotation": 2
    },
    {
      "x": -2,
      "y": 11,
      "z": -10,
      "name": "Rock_Stone_Brick_Smooth_Half",
      "rotation": 10
    },
    {
      "x": -2,
      "y": 5,
      "z": -9,
      "name": "Rock_Stone_Brick"
    },
    {
      "x": -2,
      "y": 6,
      "z": -9,
      "name": "Rock_Stone_Brick_Decorative"
    },
    {
      "x": -2,
      "y": 7,
      "z": -9,
      "name": "Rock_Stone_Brick"
    },
    {
      "x": -2,
      "y": 8,
      "z": -9,
      "name": "Rock_Stone_Brick"
    },
    {
      "x": -2,
      "y": 9,
      "z": -9,
      "name": "Rock_Stone_Brick"
    },
    {
      "x": -2,
      "y": 10,
      "z": -9,
      "name": "Rock_Stone_Brick"
    },
    {
      "x": -2,
      "y": 11,
      "z": -9,
      "name": "Rock_Stone_Brick_Decorative",
      "rotation": 2
    },
    {
      "x": -2,
      "y": 5,
      "z": -8,
      "name": "Rock_Stone_Brick_Smooth"
    },
    {
      "x": -2,
      "y": 11,
      "z": -8,
      "name": "Rock_Stone_Brick_Smooth_Half",
      "rotation": 8
    },
    {
      "x": -2,
      "y": 5,
      "z": -7,
      "name": "Rock_Stone_Brick_Smooth"
    },
    {
      "x": -2,
      "y": 11,
      "z": -7,
      "name": "Rock_Stone_Brick_Smooth_Half",
      "rotation": 8
    },
    {
      "x": -2,
      "y": 5,
      "z": -6,
      "name": "Rock_Stone_Brick_Smooth"
    },
    {
      "x": -2,
      "y": 11,
      "z": -6,
      "name": "Rock_Stone_Brick_Smooth_Half",
      "rotation": 8
    },
    {
      "x": -2,
      "y": 5,
      "z": -5,
      "name": "Rock_Stone_Brick_Smooth"
    },
    {
      "x": -2,
      "y": 11,
      "z": -5,
      "name": "Rock_Stone_Brick_Smooth_Half",
      "rotation": 8
    },
    {
      "x": -2,
      "y": 5,
      "z": -4,
      "name": "Rock_Stone_Brick_Smooth"
    },
    {
      "x": -2,
      "y": 11,
      "z": -4,
      "name": "Rock_Stone_Brick_Smooth_Half",
      "rotation": 8
    },
    {
      "x": -2,
      "y": 5,
      "z": -3,
      "name": "Rock_Stone_Brick_Smooth"
    },
    {
      "x": -2,
      "y": 11,
      "z": -3,
      "name": "Rock_Stone_Brick_Smooth_Half",
      "rotation": 8
    },
    {
      "x": -2,
      "y": 5,
      "z": -2,
      "name": "Rock_Stone_Brick_Smooth"
    },
    {
      "x": -2,
      "y": 11,
      "z": -2,
      "name": "Rock_Stone_Brick_Smooth_Half",
      "rotation": 8
    },
    {
      "x": -2,
      "y": 5,
      "z": -1,
      "name": "Rock_Stone_Brick_Smooth"
    },
    {
      "x": -2,
      "y": 11,
      "z": -1,
      "name": "Rock_Stone_Brick_Smooth_Half",
      "rotation": 8
    },
    {
      "x": -2,
      "y": 5,
      "z": 0,
      "name": "Rock_Stone_Brick_Smooth"
    },
    {
      "x": -2,
      "y": 11,
      "z": 0,
      "name": "Rock_Stone_Brick_Smooth_Half",
      "rotation": 8
    },
    {
      "x": -2,
      "y": 5,
      "z": 1,
      "name": "Rock_Stone_Brick_Smooth"
    },
    {
      "x": -2,
      "y": 6,
      "z": 1,
      "name": "Rock_Stone_Brick_Decorative"
    },
    {
      "x": -2,
      "y": 7,
      "z": 1,
      "name": "Rock_Stone_Brick"
    },
    {
      "x": -2,
      "y": 8,
      "z": 1,
      "name": "Rock_Stone_Brick"
    },
    {
      "x": -2,
      "y": 9,
      "z": 1,
      "name": "Rock_Stone_Brick"
    },
    {
      "x": -2,
      "y": 10,
      "z": 1,
      "name": "Rock_Stone_Brick"
    },
    {
      "x": -2,
      "y": 11,
      "z": 1,
      "name": "Rock_Stone_Brick"
    },
    {
      "x": -2,
      "y": 5,
      "z": 2,
      "name": "Rock_Stone_Brick_Smooth"
    },
    {
      "x": -2,
      "y": 11,
      "z": 2,
      "name": "Rock_Stone_Brick_Smooth_Half",
      "rotation": 8
    },
    {
      "x": -2,
      "y": 5,
      "z": 3,
      "name": "Rock_Stone_Brick_Smooth"
    },
    {
      "x": -2,
      "y": 11,
      "z": 3,
      "name": "Rock_Stone_Brick_Smooth_Half",
      "rotation": 8
    },
    {
      "x": -2,
      "y": 5,
      "z": 4,
      "name": "Rock_Stone_Brick_Smooth"
    },
    {
      "x": -2,
      "y": 11,
      "z": 4,
      "name": "Rock_Stone_Brick_Smooth_Half",
      "rotation": 8
    },
    {
      "x": -2,
      "y": 5,
      "z": 5,
      "name": "Rock_Stone_Brick_Smooth"
    },
    {
      "x": -2,
      "y": 11,
      "z": 5,
      "name": "Rock_Stone_Brick_Smooth_Half",
      "rotation": 8
    },
    {
      "x": -2,
      "y": 6,
      "z": 6,
      "name": "Rock_Stone_Brick_Decorative",
      "support": 15
    },
    {
      "x": -2,
      "y": 7,
      "z": 6,
      "name": "Soil_Gravel_Half",
      "support": 15,
      "rotation": 6
    },
    {
      "x": -2,
      "y": 8,
      "z": 6,
      "name": "Soil_Gravel_Half",
      "support": 15,
      "rotation": 6
    },
    {
      "x": -2,
      "y": 9,
      "z": 6,
      "name": "Soil_Gravel_Half",
      "rotation": 6
    },
    {
      "x": -2,
      "y": 10,
      "z": 6,
      "name": "Soil_Gravel_Half",
      "rotation": 6
    },
    {
      "x": -2,
      "y": 11,
      "z": 6,
      "name": "Rock_Stone_Brick"
    },
    {
      "x": -2,
      "y": 5,
      "z": 8,
      "name": "Rock_Stone_Brick_Smooth",
      "support": 15
    },
    {
      "x": -2,
      "y": 6,
      "z": 8,
      "name": "Rock_Stone_Brick_Decorative",
      "support": 15,
      "rotation": 1
    },
    {
      "x": -2,
      "y": 7,
      "z": 8,
      "name": "Soil_Gravel_Half",
      "support": 15,
      "rotation": 4
    },
    {
      "x": -2,
      "y": 8,
      "z": 8,
      "name": "Soil_Gravel_Half",
      "support": 15,
      "rotation": 4
    },
    {
      "x": -2,
      "y": 9,
      "z": 8,
      "name": "Soil_Gravel_Half",
      "rotation": 4
    },
    {
      "x": -2,
      "y": 10,
      "z": 8,
      "name": "Soil_Gravel_Half",
      "rotation": 4
    },
    {
      "x": -2,
      "y": 11,
      "z": 8,
      "name": "Rock_Stone_Brick"
    },
    {
      "x": -2,
      "y": 5,
      "z": 9,
      "name": "Rock_Stone_Brick_Smooth"
    },
    {
      "x": -2,
      "y": 11,
      "z": 9,
      "name": "Rock_Stone_Brick_Smooth_Half",
      "rotation": 8
    },
    {
      "x": -2,
      "y": 5,
      "z": 10,
      "name": "Rock_Stone_Brick_Smooth"
    },
    {
      "x": -2,
      "y": 11,
      "z": 10,
      "name": "Rock_Stone_Brick_Smooth_Half",
      "rotation": 8
    },
    {
      "x": -2,
      "y": 5,
      "z": 11,
      "name": "Rock_Stone_Brick_Smooth"
    },
    {
      "x": -2,
      "y": 11,
      "z": 11,
      "name": "Rock_Stone_Brick_Smooth_Half",
      "rotation": 8
    },
    {
      "x": -2,
      "y": 5,
      "z": 12,
      "name": "Rock_Stone_Brick_Smooth"
    },
    {
      "x": -2,
      "y": 11,
      "z": 12,
      "name": "Rock_Stone_Brick_Smooth_Half",
      "rotation": 8
    },
    {
      "x": -2,
      "y": 5,
      "z": 13,
      "name": "Rock_Stone_Brick_Smooth"
    },
    {
      "x": -2,
      "y": 11,
      "z": 13,
      "name": "Rock_Stone_Brick_Smooth_Half",
      "rotation": 8
    },
    {
      "x": -2,
      "y": 5,
      "z": 14,
      "name": "Rock_Stone_Brick_Smooth"
    },
    {
      "x": -2,
      "y": 11,
      "z": 14,
      "name": "Rock_Stone_Brick_Smooth_Half",
      "rotation": 8
    },
    {
      "x": -2,
      "y": 5,
      "z": 15,
      "name": "Rock_Stone_Brick_Smooth"
    },
    {
      "x": -2,
      "y": 11,
      "z": 15,
      "name": "Rock_Stone_Brick_Smooth_Half",
      "rotation": 8
    },
    {
      "x": -2,
      "y": 5,
      "z": 16,
      "name": "Rock_Stone_Brick",
      "support": 15
    },
    {
      "x": -2,
      "y": 6,
      "z": 16,
      "name": "Rock_Stone_Brick_Decorative",
      "support": 15
    },
    {
      "x": -2,
      "y": 7,
      "z": 16,
      "name": "Soil_Gravel_Half",
      "support": 15,
      "rotation": 6
    },
    {
      "x": -2,
      "y": 8,
      "z": 16,
      "name": "Soil_Gravel_Half",
      "support": 15,
      "rotation": 6
    },
    {
      "x": -2,
      "y": 9,
      "z": 16,
      "name": "Soil_Gravel_Half",
      "rotation": 6
    },
    {
      "x": -2,
      "y": 10,
      "z": 16,
      "name": "Soil_Gravel_Half",
      "rotation": 6
    },
    {
      "x": -2,
      "y": 11,
      "z": 16,
      "name": "Rock_Stone_Brick",
      "rotation": 2
    },
    {
      "x": -1,
      "y": 5,
      "z": -16,
      "name": "Rock_Stone_Brick",
      "rotation": 2
    },
    {
      "x": -1,
      "y": 6,
      "z": -16,
      "name": "Rock_Stone_Brick_Smooth_Half",
      "rotation": 5
    },
    {
      "x": -1,
      "y": 7,
      "z": -16,
      "name": "Rock_Stone_Brick_Smooth_Half",
      "rotation": 5
    },
    {
      "x": -1,
      "y": 8,
      "z": -16,
      "name": "Rock_Stone_Brick_Smooth_Half",
      "rotation": 5
    },
    {
      "x": -1,
      "y": 9,
      "z": -16,
      "name": "Rock_Stone_Brick_Stairs",
      "rotation": 11
    },
    {
      "x": -1,
      "y": 10,
      "z": -16,
      "name": "Rock_Stone_Brick_Decorative"
    },
    {
      "x": -1,
      "y": 11,
      "z": -16,
      "name": "Rock_Stone_Brick_Decorative",
      "rotation": 2
    },
    {
      "x": -1,
      "y": 5,
      "z": -15,
      "name": "Rock_Stone_Brick_Smooth",
      "rotation": 2
    },
    {
      "x": -1,
      "y": 11,
      "z": -15,
      "name": "Rock_Stone_Brick_Smooth_Half",
      "rotation": 10
    },
    {
      "x": -1,
      "y": 5,
      "z": -14,
      "name": "Rock_Stone_Brick_Smooth",
      "rotation": 2
    },
    {
      "x": -1,
      "y": 11,
      "z": -14,
      "name": "Rock_Stone_Brick_Smooth_Half",
      "rotation": 10
    },
    {
      "x": -1,
      "y": 5,
      "z": -13,
      "name": "Rock_Stone_Brick_Smooth",
      "rotation": 2
    },
    {
      "x": -1,
      "y": 11,
      "z": -13,
      "name": "Rock_Stone_Brick_Smooth_Half",
      "rotation": 10
    },
    {
      "x": -1,
      "y": 5,
      "z": -12,
      "name": "Rock_Stone_Brick_Smooth",
      "rotation": 2
    },
    {
      "x": -1,
      "y": 11,
      "z": -12,
      "name": "Rock_Stone_Brick_Smooth_Half",
      "rotation": 10
    },
    {
      "x": -1,
      "y": 5,
      "z": -11,
      "name": "Rock_Stone_Brick_Smooth",
      "rotation": 2
    },
    {
      "x": -1,
      "y": 11,
      "z": -11,
      "name": "Rock_Stone_Brick_Smooth_Half",
      "rotation": 10
    },
    {
      "x": -1,
      "y": 5,
      "z": -10,
      "name": "Rock_Stone_Brick_Smooth",
      "rotation": 2
    },
    {
      "x": -1,
      "y": 11,
      "z": -10,
      "name": "Rock_Stone_Brick_Smooth_Half",
      "rotation": 10
    },
    {
      "x": -1,
      "y": 5,
      "z": -9,
      "name": "Rock_Stone_Brick_Smooth"
    },
    {
      "x": -1,
      "y": 6,
      "z": -9,
      "name": "Rock_Stone_Brick_Smooth_Half",
      "rotation": 5
    },
    {
      "x": -1,
      "y": 7,
      "z": -9,
      "name": "Rock_Stone_Brick_Smooth_Half",
      "rotation": 5
    },
    {
      "x": -1,
      "y": 8,
      "z": -9,
      "name": "Rock_Stone_Brick_Smooth_Half",
      "rotation": 5
    },
    {
      "x": -1,
      "y": 9,
      "z": -9,
      "name": "Rock_Stone_Brick_Stairs",
      "rotation": 11
    },
    {
      "x": -1,
      "y": 10,
      "z": -9,
      "name": "Rock_Stone_Brick_Decorative"
    },
    {
      "x": -1,
      "y": 11,
      "z": -9,
      "name": "Rock_Stone_Brick_Decorative",
      "rotation": 2
    },
    {
      "x": -1,
      "y": 5,
      "z": -8,
      "name": "Rock_Stone_Brick_Smooth"
    },
    {
      "x": -1,
      "y": 11,
      "z": -8,
      "name": "Rock_Stone_Brick_Smooth_Half",
      "rotation": 8
    },
    {
      "x": -1,
      "y": 5,
      "z": -7,
      "name": "Rock_Stone_Brick_Smooth"
    },
    {
      "x": -1,
      "y": 11,
      "z": -7,
      "name": "Rock_Stone_Brick_Smooth_Half",
      "rotation": 8
    },
    {
      "x": -1,
      "y": 5,
      "z": -6,
      "name": "Rock_Stone_Brick_Smooth"
    },
    {
      "x": -1,
      "y": 11,
      "z": -6,
      "name": "Rock_Stone_Brick_Smooth_Half",
      "rotation": 8
    },
    {
      "x": -1,
      "y": 5,
      "z": -5,
      "name": "Rock_Stone_Brick_Smooth"
    },
    {
      "x": -1,
      "y": 11,
      "z": -5,
      "name": "Rock_Stone_Brick_Smooth_Half",
      "rotation": 8
    },
    {
      "x": -1,
      "y": 5,
      "z": -4,
      "name": "Rock_Stone_Brick_Smooth"
    },
    {
      "x": -1,
      "y": 11,
      "z": -4,
      "name": "Rock_Stone_Brick_Smooth_Half",
      "rotation": 8
    },
    {
      "x": -1,
      "y": 5,
      "z": -3,
      "name": "Rock_Stone_Brick_Smooth"
    },
    {
      "x": -1,
      "y": 11,
      "z": -3,
      "name": "Rock_Stone_Brick_Smooth_Half",
      "rotation": 8
    },
    {
      "x": -1,
      "y": 5,
      "z": -2,
      "name": "Rock_Stone_Brick_Smooth"
    },
    {
      "x": -1,
      "y": 11,
      "z": -2,
      "name": "Rock_Stone_Brick_Smooth_Half",
      "rotation": 8
    },
    {
      "x": -1,
      "y": 5,
      "z": -1,
      "name": "Rock_Stone_Brick_Smooth"
    },
    {
      "x": -1,
      "y": 11,
      "z": -1,
      "name": "Rock_Stone_Brick_Smooth_Half",
      "rotation": 8
    },
    {
      "x": -1,
      "y": 5,
      "z": 0,
      "name": "Rock_Stone_Brick_Smooth"
    },
    {
      "x": -1,
      "y": 11,
      "z": 0,
      "name": "Rock_Stone_Brick_Smooth_Half",
      "rotation": 8
    },
    {
      "x": -1,
      "y": 5,
      "z": 1,
      "name": "Rock_Stone_Brick_Smooth"
    },
    {
      "x": -1,
      "y": 6,
      "z": 1,
      "name": "Furniture_Temple_Dark_Window"
    },
    {
      "x": -1,
      "y": 7,
      "z": 1,
      "name": "Furniture_Temple_Dark_Window"
    },
    {
      "x": -1,
      "y": 8,
      "z": 1,
      "name": "Furniture_Temple_Dark_Window"
    },
    {
      "x": -1,
      "y": 9,
      "z": 1,
      "name": "Furniture_Temple_Dark_Window"
    },
    {
      "x": -1,
      "y": 10,
      "z": 1,
      "name": "Rock_Stone_Brick_Decorative"
    },
    {
      "x": -1,
      "y": 11,
      "z": 1,
      "name": "Rock_Stone_Brick"
    },
    {
      "x": -1,
      "y": 5,
      "z": 2,
      "name": "Rock_Stone_Brick_Smooth"
    },
    {
      "x": -1,
      "y": 11,
      "z": 2,
      "name": "Rock_Stone_Brick_Smooth_Half",
      "rotation": 8
    },
    {
      "x": -1,
      "y": 5,
      "z": 3,
      "name": "Rock_Stone_Brick_Smooth"
    },
    {
      "x": -1,
      "y": 11,
      "z": 3,
      "name": "Rock_Stone_Brick_Smooth_Half",
      "rotation": 8
    },
    {
      "x": -1,
      "y": 5,
      "z": 4,
      "name": "Rock_Stone_Brick_Smooth"
    },
    {
      "x": -1,
      "y": 11,
      "z": 4,
      "name": "Rock_Stone_Brick_Smooth_Half",
      "rotation": 8
    },
    {
      "x": -1,
      "y": 5,
      "z": 5,
      "name": "Rock_Stone_Brick_Smooth"
    },
    {
      "x": -1,
      "y": 11,
      "z": 5,
      "name": "Rock_Stone_Brick_Smooth_Half",
      "rotation": 8
    },
    {
      "x": -1,
      "y": 6,
      "z": 6,
      "name": "Rock_Stone_Brick_Decorative",
      "support": 15
    },
    {
      "x": -1,
      "y": 7,
      "z": 6,
      "name": "Soil_Gravel_Half",
      "support": 15,
      "rotation": 6
    },
    {
      "x": -1,
      "y": 8,
      "z": 6,
      "name": "Soil_Gravel_Half",
      "support": 15,
      "rotation": 6
    },
    {
      "x": -1,
      "y": 9,
      "z": 6,
      "name": "Soil_Gravel_Half",
      "rotation": 6
    },
    {
      "x": -1,
      "y": 10,
      "z": 6,
      "name": "Soil_Gravel_Half",
      "rotation": 6
    },
    {
      "x": -1,
      "y": 11,
      "z": 6,
      "name": "Rock_Stone_Brick"
    },
    {
      "x": -1,
      "y": 5,
      "z": 8,
      "name": "Rock_Stone_Brick_Smooth",
      "support": 15
    },
    {
      "x": -1,
      "y": 6,
      "z": 8,
      "name": "Rock_Stone_Brick_Decorative",
      "support": 15,
      "rotation": 1
    },
    {
      "x": -1,
      "y": 7,
      "z": 8,
      "name": "Soil_Gravel_Half",
      "support": 15,
      "rotation": 4
    },
    {
      "x": -1,
      "y": 8,
      "z": 8,
      "name": "Soil_Gravel_Half",
      "support": 15,
      "rotation": 4
    },
    {
      "x": -1,
      "y": 9,
      "z": 8,
      "name": "Soil_Gravel_Half",
      "rotation": 4
    },
    {
      "x": -1,
      "y": 10,
      "z": 8,
      "name": "Soil_Gravel_Half",
      "rotation": 4
    },
    {
      "x": -1,
      "y": 11,
      "z": 8,
      "name": "Rock_Stone_Brick"
    },
    {
      "x": -1,
      "y": 5,
      "z": 9,
      "name": "Rock_Stone_Brick_Smooth"
    },
    {
      "x": -1,
      "y": 11,
      "z": 9,
      "name": "Rock_Stone_Brick_Smooth_Half",
      "rotation": 8
    },
    {
      "x": -1,
      "y": 5,
      "z": 10,
      "name": "Rock_Stone_Brick_Smooth"
    },
    {
      "x": -1,
      "y": 11,
      "z": 10,
      "name": "Rock_Stone_Brick_Smooth_Half",
      "rotation": 8
    },
    {
      "x": -1,
      "y": 5,
      "z": 11,
      "name": "Rock_Stone_Brick_Smooth"
    },
    {
      "x": -1,
      "y": 11,
      "z": 11,
      "name": "Rock_Stone_Brick_Smooth_Half",
      "rotation": 8
    },
    {
      "x": -1,
      "y": 5,
      "z": 12,
      "name": "Rock_Stone_Brick_Smooth"
    },
    {
      "x": -1,
      "y": 11,
      "z": 12,
      "name": "Rock_Stone_Brick_Smooth_Half",
      "rotation": 8
    },
    {
      "x": -1,
      "y": 5,
      "z": 13,
      "name": "Rock_Stone_Brick_Smooth"
    },
    {
      "x": -1,
      "y": 11,
      "z": 13,
      "name": "Rock_Stone_Brick_Smooth_Half",
      "rotation": 8
    },
    {
      "x": -1,
      "y": 5,
      "z": 14,
      "name": "Rock_Stone_Brick_Smooth"
    },
    {
      "x": -1,
      "y": 11,
      "z": 14,
      "name": "Rock_Stone_Brick_Smooth_Half",
      "rotation": 8
    },
    {
      "x": -1,
      "y": 5,
      "z": 15,
      "name": "Rock_Stone_Brick_Smooth"
    },
    {
      "x": -1,
      "y": 11,
      "z": 15,
      "name": "Rock_Stone_Brick_Smooth_Half",
      "rotation": 8
    },
    {
      "x": -1,
      "y": 5,
      "z": 16,
      "name": "Rock_Stone_Brick_Smooth",
      "rotation": 2
    },
    {
      "x": -1,
      "y": 6,
      "z": 16,
      "name": "Rock_Stone_Brick_Smooth_Half",
      "rotation": 5
    },
    {
      "x": -1,
      "y": 7,
      "z": 16,
      "name": "Rock_Stone_Brick_Smooth_Half",
      "rotation": 5
    },
    {
      "x": -1,
      "y": 8,
      "z": 16,
      "name": "Rock_Stone_Brick_Smooth_Half",
      "rotation": 5
    },
    {
      "x": -1,
      "y": 9,
      "z": 16,
      "name": "*Rock_Stone_Brick_Stairs_State_Definitions_Inverted_Corner_Right",
      "rotation": 11
    },
    {
      "x": -1,
      "y": 10,
      "z": 16,
      "name": "Rock_Stone_Brick_Decorative",
      "rotation": 2
    },
    {
      "x": -1,
