{
  "version": 8,
  "blockIdVersion": 11,
  "anchorX": 0,
  "anchorY": 6,
  "anchorZ": 0,
  "blocks": [
    {
      "x": -5,
      "y": 0,
      "z": -5,
      "name": "Rock_Stone_Brick",
      "rotation": 1
    },
    {
      "x": -5,
      "y": 1,
      "z": -5,
      "name": "Rock_Stone_Brick_Decorative",
      "rotation": 1
    },
    {
      "x": -5,
      "y": 2,
      "z": -5,
      "name": "Soil_Gravel",
      "support": 15,
      "rotation": 1
    },
    {
      "x": -5,
      "y": 3,
      "z": -5,
      "name": "Soil_Gravel",
      "support": 15,
      "rotation": 1
    },
    {
      "x": -5,
      "y": 4,
      "z": -5,
      "name": "Soil_Gravel",
      "support": 15,
      "rotation": 1
    },
    {
      "x": -5,
      "y": 5,
      "z": -5,
      "name": "Soil_Gravel",
      "support": 15,
      "rotation": 1
    },
    {
      "x": -5,
      "y": 6,
      "z": -5,
      "name": "Rock_Stone_Brick_Smooth",
      "rotation": 1
    },
    {
      "x": -5,
      "y": 0,
      "z": -4,
      "name": "Rock_Stone_Brick",
      "rotation": 1
    },
    {
      "x": -5,
      "y": 1,
      "z": -4,
      "name": "Rock_Stone_Brick_Decorative",
      "rotation": 2
    },
    {
      "x": -5,
      "y": 2,
      "z": -4,
      "name": "Soil_Gravel",
      "support": 15,
      "rotation": 2
    },
    {
      "x": -5,
      "y": 3,
      "z": -4,
      "name": "Soil_Gravel",
      "support": 15,
      "rotation": 2
    },
    {
      "x": -5,
      "y": 4,
      "z": -4,
      "name": "Soil_Gravel",
      "support": 15,
      "rotation": 2
    },
    {
      "x": -5,
      "y": 5,
      "z": -4,
      "name": "Soil_Gravel",
      "support": 15,
      "rotation": 2
    },
    {
      "x": -5,
      "y": 6,
      "z": -4,
      "name": "Rock_Stone_Brick_Smooth",
      "rotation": 2
    },
    {
      "x": -5,
      "y": 0,
      "z": -3,
      "name": "Rock_Stone_Brick",
      "rotation": 1
    },
    {
      "x": -5,
      "y": 1,
      "z": -3,
      "name": "Rock_Stone_Brick_Decorative"
    },
    {
      "x": -5,
      "y": 2,
      "z": -3,
      "name": "Soil_Gravel",
      "support": 15
    },
    {
      "x": -5,
      "y": 3,
      "z": -3,
      "name": "Soil_Gravel",
      "support": 15
    },
    {
      "x": -5,
      "y": 4,
      "z": -3,
      "name": "Soil_Gravel",
      "support": 15
    },
    {
      "x": -5,
      "y": 5,
      "z": -3,
      "name": "Soil_Gravel",
      "support": 15
    },
    {
      "x": -5,
      "y": 6,
      "z": -3,
      "name": "Rock_Stone_Brick_Smooth"
    },
    {
      "x": -5,
      "y": 0,
      "z": -2,
      "name": "Rock_Stone_Brick",
      "rotation": 1
    },
    {
      "x": -5,
      "y": 1,
      "z": -2,
      "name": "Rock_Stone_Brick_Decorative"
    },
    {
      "x": -5,
      "y": 2,
      "z": -2,
      "name": "Rock_Stone_Brick"
    },
    {
      "x": -5,
      "y": 3,
      "z": -2,
      "name": "Rock_Stone_Brick"
    },
    {
      "x": -5,
      "y": 4,
      "z": -2,
      "name": "Rock_Stone_Brick"
    },
    {
      "x": -5,
      "y": 5,
      "z": -2,
      "name": "Rock_Stone_Brick"
    },
    {
      "x": -5,
      "y": 6,
      "z": -2,
      "name": "Rock_Stone_Brick_Smooth"
    },
    {
      "x": -5,
      "y": 0,
      "z": -1,
      "name": "Rock_Stone_Brick",
      "rotation": 1
    },
    {
      "x": -5,
      "y": 6,
      "z": -1,
      "name": "Rock_Stone_Brick_Smooth"
    },
    {
      "x": -5,
      "y": 0,
      "z": 0,
      "name": "Rock_Stone_Brick",
      "rotation": 1
    },
    {
      "x": -5,
      "y": 6,
      "z": 0,
      "name": "Rock_Stone_Brick_Smooth"
    },
    {
      "x": -5,
      "y": 0,
      "z": 1,
      "name": "Rock_Stone_Brick",
      "rotation": 1
    },
    {
      "x": -5,
      "y": 6,
      "z": 1,
      "name": "Rock_Stone_Brick_Smooth",
      "rotation": 2
    },
    {
      "x": -5,
      "y": 0,
      "z": 2,
      "name": "Rock_Stone_Brick",
      "rotation": 1
    },
    {
      "x": -5,
      "y": 1,
      "z": 2,
      "name": "Rock_Stone_Brick_Decorative",
      "rotation": 3
    },
    {
      "x": -5,
      "y": 2,
      "z": 2,
      "name": "Rock_Stone_Brick"
    },
    {
      "x": -5,
      "y": 3,
      "z": 2,
      "name": "Rock_Stone_Brick"
    },
    {
      "x": -5,
      "y": 4,
      "z": 2,
      "name": "Rock_Stone_Brick"
    },
    {
      "x": -5,
      "y": 5,
      "z": 2,
      "name": "Rock_Stone_Brick"
    },
    {
      "x": -5,
      "y": 6,
      "z": 2,
      "name": "Rock_Stone_Brick_Smooth",
      "rotation": 2
    },
    {
      "x": -5,
      "y": 0,
      "z": 3,
      "name": "Rock_Stone_Brick",
      "rotation": 1
    },
    {
      "x": -5,
      "y": 1,
      "z": 3,
      "name": "Rock_Stone_Brick_Decorative",
      "rotation": 1
    },
    {
      "x": -5,
      "y": 2,
      "z": 3,
      "name": "Soil_Gravel",
      "support": 15,
      "rotation": 1
    },
    {
      "x": -5,
      "y": 3,
      "z": 3,
      "name": "Soil_Gravel",
      "support": 15,
      "rotation": 1
    },
    {
      "x": -5,
      "y": 4,
      "z": 3,
      "name": "Soil_Gravel",
      "support": 15,
      "rotation": 1
    },
    {
      "x": -5,
      "y": 5,
      "z": 3,
      "name": "Soil_Gravel",
      "support": 15,
      "rotation": 1
    },
    {
      "x": -5,
      "y": 6,
      "z": 3,
      "name": "Rock_Stone_Brick_Smooth",
      "rotation": 1
    },
    {
      "x": -5,
      "y": 0,
      "z": 4,
      "name": "Rock_Stone_Brick",
      "rotation": 1
    },
    {
      "x": -5,
      "y": 1,
      "z": 4,
      "name": "Rock_Stone_Brick_Decorative",
      "rotation": 2
    },
    {
      "x": -5,
      "y": 2,
      "z": 4,
      "name": "Soil_Gravel",
      "support": 15,
      "rotation": 2
    },
    {
      "x": -5,
      "y": 3,
      "z": 4,
      "name": "Soil_Gravel",
      "support": 15,
      "rotation": 2
    },
    {
      "x": -5,
      "y": 4,
      "z": 4,
      "name": "Soil_Gravel",
      "support": 15,
      "rotation": 2
    },
    {
      "x": -5,
      "y": 5,
      "z": 4,
      "name": "Soil_Gravel",
      "support": 15,
      "rotation": 2
    },
    {
      "x": -5,
      "y": 6,
      "z": 4,
      "name": "Rock_Stone_Brick_Smooth",
      "rotation": 2
    },
    {
      "x": -5,
      "y": 0,
      "z": 5,
      "name": "Rock_Stone_Brick",
      "rotation": 1
    },
    {
      "x": -5,
      "y": 1,
      "z": 5,
      "name": "Rock_Stone_Brick_Decorative",
      "rotation": 2
    },
    {
      "x": -5,
      "y": 2,
      "z": 5,
      "name": "Soil_Gravel",
      "support": 15,
      "rotation": 2
    },
    {
      "x": -5,
      "y": 3,
      "z": 5,
      "name": "Soil_Gravel",
      "support": 15,
      "rotation": 2
    },
    {
      "x": -5,
      "y": 4,
      "z": 5,
      "name": "Soil_Gravel",
      "support": 15,
      "rotation": 2
    },
    {
      "x": -5,
      "y": 5,
      "z": 5,
      "name": "Soil_Gravel",
      "support": 15,
      "rotation": 2
    },
    {
      "x": -5,
      "y": 6,
      "z": 5,
      "name": "Rock_Stone_Brick_Smooth",
      "rotation": 2
    },
    {
      "x": -4,
      "y": 0,
      "z": -5,
      "name": "Rock_Stone_Brick"
    },
    {
      "x": -4,
      "y": 1,
      "z": -5,
      "name": "Rock_Stone_Brick_Decorative"
    },
    {
      "x": -4,
      "y": 2,
      "z": -5,
      "name": "Soil_Gravel",
      "support": 15
    },
    {
      "x": -4,
      "y": 3,
      "z": -5,
      "name": "Soil_Gravel",
      "support": 15
    },
    {
      "x": -4,
      "y": 4,
      "z": -5,
      "name": "Soil_Gravel",
      "support": 15
    },
    {
      "x": -4,
      "y": 5,
      "z": -5,
      "name": "Soil_Gravel",
      "support": 15
    },
    {
      "x": -4,
      "y": 6,
      "z": -5,
      "name": "Rock_Stone_Brick_Smooth"
    },
    {
      "x": -4,
      "y": 0,
      "z": -4,
      "name": "Rock_Stone_Brick",
      "rotation": 2
    },
    {
      "x": -4,
      "y": 1,
      "z": -4,
      "name": "Rock_Stone_Brick_Decorative"
    },
    {
      "x": -4,
      "y": 2,
      "z": -4,
      "name": "Rock_Stone_Brick"
    },
    {
      "x": -4,
      "y": 3,
      "z": -4,
      "name": "Rock_Stone_Brick"
    },
    {
      "x": -4,
      "y": 4,
      "z": -4,
      "name": "Rock_Stone_Brick"
    },
    {
      "x": -4,
      "y": 5,
      "z": -4,
      "name": "Rock_Stone_Brick_Decorative"
    },
    {
      "x": -4,
      "y": 6,
      "z": -4,
      "name": "Rock_Stone_Brick",
      "rotation": 3
    },
    {
      "x": -4,
      "y": 0,
      "z": -3,
      "name": "Rock_Stone_Brick",
      "rotation": 2
    },
    {
      "x": -4,
      "y": 1,
      "z": -3,
      "name": "Rock_Stone_Brick_Decorative",
      "rotation": 1
    },
    {
      "x": -4,
      "y": 2,
      "z": -3,
      "name": "Soil_Gravel_Half",
      "support": 15,
      "rotation": 5
    },
    {
      "x": -4,
      "y": 3,
      "z": -3,
      "name": "Soil_Gravel_Half",
      "support": 15,
      "rotation": 5
    },
    {
      "x": -4,
      "y": 4,
      "z": -3,
      "name": "Soil_Gravel_Half",
      "support": 15,
      "rotation": 5
    },
    {
      "x": -4,
      "y": 5,
      "z": -3,
      "name": "Soil_Gravel_Half",
      "support": 15,
      "rotation": 5
    },
    {
      "x": -4,
      "y": 6,
      "z": -3,
      "name": "Rock_Stone_Brick",
      "rotation": 3
    },
    {
      "x": -4,
      "y": 0,
      "z": -2,
      "name": "Rock_Stone_Brick",
      "rotation": 1
    },
    {
      "x": -4,
      "y": 1,
      "z": -2,
      "name": "Rock_Stone_Brick_Decorative",
      "rotation": 1
    },
    {
      "x": -4,
      "y": 2,
      "z": -2,
      "name": "Rock_Stone_Brick_Pillar_Base",
      "rotation": 1
    },
    {
      "x": -4,
      "y": 3,
      "z": -2,
      "name": "Rock_Stone_Brick_Pillar_Middle",
      "rotation": 1
    },
    {
      "x": -4,
      "y": 4,
      "z": -2,
      "name": "Rock_Stone_Brick_Pillar_Middle",
      "rotation": 1
    },
    {
      "x": -4,
      "y": 5,
      "z": -2,
      "name": "Rock_Stone_Brick_Pillar_Base",
      "rotation": 35
    },
    {
      "x": -4,
      "y": 6,
      "z": -2,
      "name": "Rock_Stone_Brick",
      "rotation": 3
    },
    {
      "x": -4,
      "y": 0,
      "z": -1,
      "name": "Rock_Stone_Brick_Smooth",
      "rotation": 1
    },
    {
      "x": -4,
      "y": 6,
      "z": -1,
      "name": "Rock_Stone_Brick_Smooth"
    },
    {
      "x": -4,
      "y": 0,
      "z": 0,
      "name": "Rock_Stone_Brick_Smooth",
      "rotation": 1
    },
    {
      "x": -4,
      "y": 6,
      "z": 0,
      "name": "Rock_Stone_Brick_Smooth"
    },
    {
      "x": -4,
      "y": 0,
      "z": 1,
      "name": "Rock_Stone_Brick_Smooth",
      "rotation": 1
    },
    {
      "x": -4,
      "y": 6,
      "z": 1,
      "name": "Rock_Stone_Brick_Smooth"
    },
    {
      "x": -4,
      "y": 0,
      "z": 2,
      "name": "Rock_Stone_Brick",
      "rotation": 2
    },
    {
      "x": -4,
      "y": 1,
      "z": 2,
      "name": "Rock_Stone_Brick_Decorative",
      "rotation": 2
    },
    {
      "x": -4,
      "y": 2,
      "z": 2,
      "name": "Rock_Stone_Brick_Pillar_Base",
      "rotation": 2
    },
    {
      "x": -4,
      "y": 3,
      "z": 2,
      "name": "Rock_Stone_Brick_Pillar_Middle",
      "rotation": 2
    },
    {
      "x": -4,
      "y": 4,
      "z": 2,
      "name": "Rock_Stone_Brick_Pillar_Middle",
      "rotation": 2
    },
    {
      "x": -4,
      "y": 5,
      "z": 2,
      "name": "Rock_Stone_Brick_Pillar_Base",
      "rotation": 32
    },
    {
      "x": -4,
      "y": 6,
      "z": 2,
      "name": "Rock_Stone_Brick",
      "rotation": 3
    },
    {
      "x": -4,
      "y": 0,
      "z": 3,
      "name": "Rock_Stone_Brick",
      "rotation": 1
    },
    {
      "x": -4,
      "y": 1,
      "z": 3,
      "name": "Rock_Stone_Brick_Decorative",
      "rotation": 1
    },
    {
      "x": -4,
      "y": 2,
      "z": 3,
      "name": "Soil_Gravel_Half",
      "support": 15,
      "rotation": 5
    },
    {
      "x": -4,
      "y": 3,
      "z": 3,
      "name": "Soil_Gravel_Half",
      "support": 15,
      "rotation": 5
    },
    {
      "x": -4,
      "y": 4,
      "z": 3,
      "name": "Soil_Gravel_Half",
      "support": 15,
      "rotation": 5
    },
    {
      "x": -4,
      "y": 5,
      "z": 3,
      "name": "Soil_Gravel_Half",
      "support": 15,
      "rotation": 5
    },
    {
      "x": -4,
      "y": 6,
      "z": 3,
      "name": "Rock_Stone_Brick",
      "rotation": 3
    },
    {
      "x": -4,
      "y": 0,
      "z": 4,
      "name": "Rock_Stone_Brick",
      "rotation": 2
    },
    {
      "x": -4,
      "y": 1,
      "z": 4,
      "name": "Rock_Stone_Brick_Decorative",
      "rotation": 2
    },
    {
      "x": -4,
      "y": 2,
      "z": 4,
      "name": "Rock_Stone_Brick"
    },
    {
      "x": -4,
      "y": 3,
      "z": 4,
      "name": "Rock_Stone_Brick"
    },
    {
      "x": -4,
      "y": 4,
      "z": 4,
      "name": "Rock_Stone_Brick"
    },
    {
      "x": -4,
      "y": 5,
      "z": 4,
      "name": "Rock_Stone_Brick_Decorative"
    },
    {
      "x": -4,
      "y": 6,
      "z": 4,
      "name": "Rock_Stone_Brick",
      "rotation": 3
    },
    {
      "x": -4,
      "y": 0,
      "z": 5,
      "name": "Rock_Stone_Brick",
      "rotation": 2
    },
    {
      "x": -4,
      "y": 1,
      "z": 5,
      "name": "Rock_Stone_Brick_Decorative",
      "rotation": 2
    },
    {
      "x": -4,
      "y": 2,
      "z": 5,
      "name": "Soil_Gravel",
      "support": 15
    },
    {
      "x": -4,
      "y": 3,
      "z": 5,
      "name": "Soil_Gravel",
      "support": 15
    },
    {
      "x": -4,
      "y": 4,
      "z": 5,
      "name": "Soil_Gravel",
      "support": 15
    },
    {
      "x": -4,
      "y": 5,
      "z": 5,
      "name": "Soil_Gravel",
      "support": 15
    },
    {
      "x": -4,
      "y": 6,
      "z": 5,
      "name": "Rock_Stone_Brick_Smooth"
    },
    {
      "x": -3,
      "y": 0,
      "z": -5,
      "name": "Rock_Stone_Brick"
    },
    {
      "x": -3,
      "y": 1,
      "z": -5,
      "name": "Rock_Stone_Brick_Decorative"
    },
    {
      "x": -3,
      "y": 2,
      "z": -5,
      "name": "*Soil_Gravel_Half_State_Definitions_Block",
      "rotation": 4
    },
    {
      "x": -3,
      "y": 3,
      "z": -5,
      "name": "*Soil_Gravel_Half_State_Definitions_Block",
      "rotation": 4
    },
    {
      "x": -3,
      "y": 4,
      "z": -5,
      "name": "*Soil_Gravel_Half_State_Definitions_Block",
      "rotation": 4
    },
    {
      "x": -3,
      "y": 5,
      "z": -5,
      "name": "*Soil_Gravel_Half_State_Definitions_Block",
      "rotation": 4
    },
    {
      "x": -3,
      "y": 6,
      "z": -5,
      "name": "Rock_Stone_Brick_Smooth"
    },
    {
      "x": -3,
      "y": 0,
      "z": -4,
      "name": "Rock_Stone_Brick_Smooth"
    },
    {
      "x": -3,
      "y": 1,
      "z": -4,
      "name": "Rock_Stone_Brick_Decorative"
    },
    {
      "x": -3,
      "y": 2,
      "z": -4,
      "name": "Soil_Gravel_Half",
      "support": 15,
      "rotation": 4
    },
    {
      "x": -3,
      "y": 3,
      "z": -4,
      "name": "Soil_Gravel_Half",
      "support": 15,
      "rotation": 4
    },
    {
      "x": -3,
      "y": 4,
      "z": -4,
      "name": "Soil_Gravel_Half",
      "support": 15,
      "rotation": 4
    },
    {
      "x": -3,
      "y": 5,
      "z": -4,
      "name": "Soil_Gravel_Half",
      "support": 15,
      "rotation": 4
    },
    {
      "x": -3,
      "y": 6,
      "z": -4,
      "name": "Rock_Stone_Brick"
    },
    {
      "x": -3,
      "y": 0,
      "z": -3,
      "name": "Rock_Stone_Brick_Smooth"
    },
    {
      "x": -3,
      "y": 6,
      "z": -3,
      "name": "Rock_Stone_Brick_Smooth"
    },
    {
      "x": -3,
      "y": 0,
      "z": -2,
      "name": "Rock_Stone_Brick_Smooth"
    },
    {
      "x": -3,
      "y": 6,
      "z": -2,
      "name": "Rock_Stone_Brick_Smooth"
    },
    {
      "x": -3,
      "y": 0,
      "z": -1,
      "name": "Rock_Stone_Brick_Smooth"
    },
    {
      "x": -3,
      "y": 6,
      "z": -1,
      "name": "Rock_Stone_Brick_Smooth"
    },
    {
      "x": -3,
      "y": 0,
      "z": 0,
      "name": "Rock_Stone_Brick_Smooth"
    },
    {
      "x": -3,
      "y": 6,
      "z": 0,
      "name": "Rock_Stone_Brick_Smooth"
    },
    {
      "x": -3,
      "y": 0,
      "z": 1,
      "name": "Rock_Stone_Brick_Smooth"
    },
    {
      "x": -3,
      "y": 6,
      "z": 1,
      "name": "Rock_Stone_Brick_Smooth"
    },
    {
      "x": -3,
      "y": 0,
      "z": 2,
      "name": "Rock_Stone_Brick_Smooth"
    },
    {
      "x": -3,
      "y": 6,
      "z": 2,
      "name": "Rock_Stone_Brick_Smooth"
    },
    {
      "x": -3,
      "y": 0,
      "z": 3,
      "name": "Rock_Stone_Brick_Smooth"
    },
    {
      "x": -3,
      "y": 6,
      "z": 3,
      "name": "Rock_Stone_Brick_Smooth"
    },
    {
      "x": -3,
      "y": 0,
      "z": 4,
      "name": "Rock_Stone_Brick_Smooth"
    },
    {
      "x": -3,
      "y": 1,
      "z": 4,
      "name": "Rock_Stone_Brick_Decorative"
    },
    {
      "x": -3,
      "y": 2,
      "z": 4,
      "name": "Soil_Gravel_Half",
      "support": 15,
      "rotation": 6
    },
    {
      "x": -3,
      "y": 3,
      "z": 4,
      "name": "Soil_Gravel_Half",
      "support": 15,
      "rotation": 6
    },
    {
      "x": -3,
      "y": 4,
      "z": 4,
      "name": "Soil_Gravel_Half",
      "support": 15,
      "rotation": 6
    },
    {
      "x": -3,
      "y": 5,
      "z": 4,
      "name": "Soil_Gravel_Half",
      "support": 15,
      "rotation": 6
    },
    {
      "x": -3,
      "y": 6,
      "z": 4,
      "name": "Rock_Stone_Brick"
    },
    {
      "x": -3,
      "y": 0,
      "z": 5,
      "name": "Rock_Stone_Brick"
    },
    {
      "x": -3,
      "y": 1,
      "z": 5,
      "name": "Rock_Stone_Brick_Decorative"
    },
    {
      "x": -3,
      "y": 2,
      "z": 5,
      "name": "*Soil_Gravel_Half_State_Definitions_Block",
      "rotation": 6
    },
    {
      "x": -3,
      "y": 3,
      "z": 5,
      "name": "*Soil_Gravel_Half_State_Definitions_Block",
      "rotation": 6
    },
    {
      "x": -3,
      "y": 4,
      "z": 5,
      "name": "*Soil_Gravel_Half_State_Definitions_Block",
      "rotation": 6
    },
    {
      "x": -3,
      "y": 5,
      "z": 5,
      "name": "*Soil_Gravel_Half_State_Definitions_Block",
      "rotation": 6
    },
    {
      "x": -3,
      "y": 6,
      "z": 5,
      "name": "Rock_Stone_Brick_Smooth"
    },
    {
      "x": -2,
      "y": 0,
      "z": -5,
      "name": "Rock_Stone_Brick"
    },
    {
      "x": -2,
      "y": 1,
      "z": -5,
      "name": "Rock_Stone_Brick_Decorative"
    },
    {
      "x": -2,
      "y": 2,
      "z": -5,
      "name": "*Soil_Gravel_Half_State_Definitions_Block",
      "rotation": 4
    },
    {
      "x": -2,
      "y": 3,
      "z": -5,
      "name": "*Soil_Gravel_Half_State_Definitions_Block",
      "rotation": 4
    },
    {
      "x": -2,
      "y": 4,
      "z": -5,
      "name": "*Soil_Gravel_Half_State_Definitions_Block",
      "rotation": 4
    },
    {
      "x": -2,
      "y": 5,
      "z": -5,
      "name": "*Soil_Gravel_Half_State_Definitions_Block",
      "rotation": 4
    },
    {
      "x": -2,
      "y": 6,
      "z": -5,
      "name": "Rock_Stone_Brick_Smooth"
    },
    {
      "x": -2,
      "y": 0,
      "z": -4,
      "name": "Rock_Stone_Brick_Smooth"
    },
    {
      "x": -2,
      "y": 1,
      "z": -4,
      "name": "Rock_Stone_Brick_Decorative"
    },
    {
      "x": -2,
      "y": 2,
      "z": -4,
      "name": "Rock_Stone_Brick_Pillar_Base"
    },
    {
      "x": -2,
      "y": 3,
      "z": -4,
      "name": "Rock_Stone_Brick_Pillar_Middle",
      "rotation": 8
    },
    {
      "x": -2,
      "y": 4,
      "z": -4,
      "name": "Rock_Stone_Brick_Pillar_Middle",
      "rotation": 8
    },
    {
      "x": -2,
      "y": 5,
      "z": -4,
      "name": "Rock_Stone_Brick_Pillar_Base",
      "rotation": 8
    },
    {
      "x": -2,
      "y": 6,
      "z": -4,
      "name": "Rock_Stone_Brick"
    },
    {
      "x": -2,
      "y": 0,
      "z": -3,
      "name": "Rock_Stone_Brick_Smooth"
    },
    {
      "x": -2,
      "y": 6,
      "z": -3,
      "name": "Rock_Stone_Brick_Smooth"
    },
    {
      "x": -2,
      "y": 0,
      "z": -2,
      "name": "Rock_Stone_Brick_Smooth"
    },
    {
      "x": -2,
      "y": 6,
      "z": -2,
      "name": "Rock_Stone_Brick_Smooth"
    },
    {
      "x": -2,
      "y": 0,
      "z": -1,
      "name": "Rock_Stone_Brick_Smooth"
    },
    {
      "x": -2,
      "y": 6,
      "z": -1,
      "name": "Rock_Stone_Brick_Smooth"
    },
    {
      "x": -2,
      "y": 0,
      "z": 0,
      "name": "Rock_Stone_Brick_Smooth"
    },
    {
      "x": -2,
      "y": 6,
      "z": 0,
      "name": "Rock_Stone_Brick_Smooth"
    },
    {
      "x": -2,
      "y": 0,
      "z": 1,
      "name": "Rock_Stone_Brick_Smooth"
    },
    {
      "x": -2,
      "y": 6,
      "z": 1,
      "name": "Rock_Stone_Brick_Smooth"
    },
    {
      "x": -2,
      "y": 0,
      "z": 2,
      "name": "Rock_Stone_Brick_Smooth"
    },
    {
      "x": -2,
      "y": 6,
      "z": 2,
      "name": "Rock_Stone_Brick_Smooth"
    },
    {
      "x": -2,
      "y": 0,
      "z": 3,
      "name": "Rock_Stone_Brick_Smooth"
    },
    {
      "x": -2,
      "y": 6,
      "z": 3,
      "name": "Rock_Stone_Brick_Smooth"
    },
    {
      "x": -2,
      "y": 0,
      "z": 4,
      "name": "Rock_Stone_Brick_Smooth"
    },
    {
      "x": -2,
      "y": 1,
      "z": 4,
      "name": "Rock_Stone_Brick_Decorative"
    },
    {
      "x": -2,
      "y": 2,
      "z": 4,
      "name": "Rock_Stone_Brick_Pillar_Base"
    },
    {
      "x": -2,
      "y": 3,
      "z": 4,
      "name": "Rock_Stone_Brick_Pillar_Middle",
      "rotation": 8
    },
    {
      "x": -2,
      "y": 4,
      "z": 4,
      "name": "Rock_Stone_Brick_Pillar_Middle",
      "rotation": 8
    },
    {
      "x": -2,
      "y": 5,
      "z": 4,
      "name": "Rock_Stone_Brick_Pillar_Base",
      "rotation": 8
    },
    {
      "x": -2,
      "y": 6,
      "z": 4,
      "name": "Rock_Stone_Brick_Smooth"
    },
    {
      "x": -2,
      "y": 0,
      "z": 5,
      "name": "Rock_Stone_Brick"
    },
    {
      "x": -2,
      "y": 1,
      "z": 5,
      "name": "Rock_Stone_Brick"
    },
    {
      "x": -2,
      "y": 2,
      "z": 5,
      "name": "Rock_Stone_Brick"
    },
    {
      "x": -2,
      "y": 3,
      "z": 5,
      "name": "Rock_Stone_Brick"
    },
    {
      "x": -2,
      "y": 4,
      "z": 5,
      "name": "Rock_Stone_Brick"
    },
    {
      "x": -2,
      "y": 5,
      "z": 5,
      "name": "Rock_Stone_Brick"
    },
    {
      "x": -2,
      "y": 6,
      "z": 5,
      "name": "Rock_Stone_Brick_Smooth"
    },
    {
      "x": -1,
      "y": 0,
      "z": -5,
      "name": "Rock_Stone_Brick"
    },
    {
      "x": -1,
      "y": 1,
      "z": -5,
      "name": "Rock_Stone_Brick_Decorative"
    },
    {
      "x": -1,
      "y": 2,
      "z": -5,
      "name": "Soil_Gravel",
      "support": 15
    },
    {
      "x": -1,
      "y": 3,
      "z": -5,
      "name": "Soil_Gravel",
      "support": 15
    },
    {
      "x": -1,
      "y": 4,
      "z": -5,
      "name": "Soil_Gravel",
      "support": 15
    },
    {
      "x": -1,
      "y": 5,
      "z": -5,
      "name": "Soil_Gravel",
      "support": 15
    },
    {
      "x": -1,
      "y": 6,
      "z": -5,
      "name": "Rock_Stone_Brick_Smooth"
    },
    {
      "x": -1,
      "y": 0,
      "z": -4,
      "name": "Rock_Stone_Brick_Smooth"
    },
    {
      "x": -1,
      "y": 1,
      "z": -4,
      "name": "Rock_Stone_Brick_Decorative"
    },
    {
      "x": -1,
      "y": 2,
      "z": -4,
      "name": "Soil_Gravel_Half",
      "support": 15,
      "rotation": 4
    },
    {
      "x": -1,
      "y": 3,
      "z": -4,
      "name": "Soil_Gravel_Half",
      "support": 15,
      "rotation": 4
    },
    {
      "x": -1,
      "y": 4,
      "z": -4,
      "name": "Soil_Gravel_Half",
      "support": 15,
      "rotation": 4
    },
    {
      "x": -1,
      "y": 5,
      "z": -4,
      "name": "Soil_Gravel_Half",
      "support": 15,
      "rotation": 4
    },
    {
      "x": -1,
      "y": 6,
      "z": -4,
      "name": "Rock_Stone_Brick"
    },
    {
      "x": -1,
      "y": 0,
      "z": -3,
      "name": "Rock_Stone_Brick_Smooth"
    },
    {
      "x": -1,
      "y": 6,
      "z": -3,
      "name": "Rock_Stone_Brick_Smooth",
      "rotation": 1
    },
    {
      "x": -1,
      "y": 0,
      "z": -2,
      "name": "Rock_Stone_Brick_Smooth"
    },
    {
      "x": -1,
      "y": 6,
      "z": -2,
      "name": "Rock_Stone_Brick_Smooth",
      "rotation": 1
    },
    {
      "x": -1,
      "y": 0,
      "z": -1,
      "name": "Rock_Stone_Brick_Smooth",
      "rotation": 1
    },
    {
      "x": -1,
      "y": 6,
      "z": -1,
      "name": "Rock_Stone_Brick_Smooth",
      "rotation": 1
    },
    {
      "x": -1,
      "y": 0,
      "z": 0,
      "name": "Rock_Stone_Brick_Smooth",
      "rotation": 1
    },
    {
      "x": -1,
      "y": 6,
      "z": 0,
      "name": "Rock_Stone_Brick_Smooth",
      "rotation": 1
    },
    {
      "x": -1,
      "y": 0,
      "z": 1,
      "name": "Rock_Stone_Brick_Smooth",
      "rotation": 2
    },
    {
      "x": -1,
      "y": 6,
      "z": 1,
      "name": "Rock_Stone_Brick_Smooth",
      "rotation": 2
    },
    {
      "x": -1,
      "y": 0,
      "z": 2,
      "name": "Rock_Stone_Brick_Smooth",
      "rotation": 2
    },
    {
      "x": -1,
      "y": 6,
      "z": 2,
      "name": "Rock_Stone_Brick_Smooth",
      "rotation": 2
    },
    {
      "x": -1,
      "y": 0,
      "z": 3,
      "name": "Rock_Stone_Brick_Smooth",
      "rotation": 1
    },
    {
      "x": -1,
      "y": 6,
      "z": 3,
      "name": "Rock_Stone_Brick_Smooth",
      "rotation": 1
    },
    {
      "x": -1,
      "y": 0,
      "z": 4,
      "name": "Rock_Stone_Brick_Smooth",
      "rotation": 2
    },
    {
      "x": -1,
      "y": 6,
      "z": 4,
      "name": "Rock_Stone_Brick_Smooth",
      "rotation": 2
    },
    {
      "x": -1,
      "y": 0,
      "z": 5,
      "name": "Rock_Stone_Brick_Smooth",
      "rotation": 2
    },
    {
      "x": -1,
      "y": 6,
      "z": 5,
      "name": "Rock_Stone_Brick_Smooth",
      "rotation": 2
    },
    {
      "x": 0,
      "y": 0,
      "z": -5,
      "name": "Rock_Stone_Brick"
    },
    {
      "x": 0,
      "y": 1,
      "z": -5,
      "name": "Rock_Stone_Brick_Decorative"
    },
    {
      "x": 0,
      "y": 2,
      "z": -5,
      "name": "Soil_Gravel",
      "support": 15
    },
    {
      "x": 0,
      "y": 3,
      "z": -5,
      "name": "Soil_Gravel",
      "support": 15
    },
    {
      "x": 0,
      "y": 4,
      "z": -5,
      "name": "Soil_Gravel",
      "support": 15
    },
    {
      "x": 0,
      "y": 5,
      "z": -5,
      "name": "Soil_Gravel",
      "support": 15
    },
    {
      "x": 0,
      "y": 6,
      "z": -5,
      "name": "Rock_Stone_Brick_Smooth"
    },
    {
      "x": 0,
      "y": 0,
      "z": -4,
      "name": "Rock_Stone_Brick_Smooth",
      "rotation": 2
    },
    {
      "x": 0,
      "y": 1,
      "z": -4,
      "name": "Rock_Stone_Brick_Decorative"
    },
    {
      "x": 0,
      "y": 2,
      "z": -4,
      "name": "Soil_Gravel_Half",
      "support": 15,
      "rotation": 4
    },
    {
      "x": 0,
      "y": 3,
      "z": -4,
      "name": "Soil_Gravel_Half",
      "support": 15,
      "rotation": 4
    },
    {
      "x": 0,
      "y": 4,
      "z": -4,
      "name": "Soil_Gravel_Half",
      "support": 15,
      "rotation": 4
    },
    {
      "x": 0,
      "y": 5,
      "z": -4,
      "name": "Soil_Gravel_Half",
      "support": 15,
      "rotation": 4
    },
    {
      "x": 0,
      "y": 6,
      "z": -4,
      "name": "Rock_Stone_Brick"
    },
    {
      "x": 0,
      "y": 0,
      "z": -3,
      "name": "Rock_Stone_Brick_Smooth",
      "rotation": 2
    },
    {
      "x": 0,
      "y": 6,
      "z": -3,
      "name": "Rock_Stone_Brick_Smooth",
      "rotation": 2
    },
    {
      "x": 0,
      "y": 0,
      "z": -2,
      "name": "Rock_Stone_Brick_Smooth",
      "rotation": 2
    },
    {
      "x": 0,
      "y": 6,
      "z": -2,
      "name": "Rock_Stone_Brick_Smooth",
      "rotation": 2
    },
    {
      "x": 0,
      "y": 0,
      "z": -1,
      "name": "Rock_Stone_Brick_Smooth",
      "rotation": 1
    },
    {
      "x": 0,
      "y": 6,
      "z": -1,
      "name": "Rock_Stone_Brick_Smooth",
      "rotation": 1
    },
    {
      "x": 0,
      "y": 0,
      "z": 0,
      "name": "Rock_Stone_Brick_Smooth",
      "rotation": 2
    },
    {
      "x": 0,
      "y": 6,
      "z": 0,
      "name": "Rock_Stone_Brick_Smooth"
    },
    {
      "x": 0,
      "y": 0,
      "z": 1,
      "name": "Rock_Stone_Brick_Smooth",
      "rotation": 2
    },
    {
      "x": 0,
      "y": 6,
      "z": 1,
      "name": "Rock_Stone_Brick_Smooth",
      "rotation": 2
    },
    {
      "x": 0,
      "y": 0,
      "z": 2,
      "name": "Rock_Stone_Brick_Smooth",
      "rotation": 2
    },
    {
      "x": 0,
      "y": 6,
      "z": 2,
      "name": "Rock_Stone_Brick_Smooth",
      "rotation": 2
    },
    {
      "x": 0,
      "y": 0,
      "z": 3,
      "name": "Rock_Stone_Brick_Smooth",
      "rotation": 1
    },
    {
      "x": 0,
      "y": 6,
      "z": 3,
      "name": "Rock_Stone_Brick_Smooth",
      "rotation": 1
    },
    {
      "x": 0,
      "y": 0,
      "z": 4,
      "name": "Rock_Stone_Brick_Smooth",
      "rotation": 2
    },
    {
      "x": 0,
      "y": 6,
      "z": 4,
      "name": "Rock_Stone_Brick_Smooth",
      "rotation": 2
    },
    {
      "x": 0,
      "y": 0,
      "z": 5,
      "name": "Rock_Stone_Brick_Smooth",
      "rotation": 2
    },
    {
      "x": 0,
      "y": 6,
      "z": 5,
      "name": "Rock_Stone_Brick_Smooth",
      "rotation": 2
    },
    {
      "x": 1,
      "y": 0,
      "z": -5,
      "name": "Rock_Stone_Brick"
    },
    {
      "x": 1,
      "y": 1,
      "z": -5,
      "name": "Rock_Stone_Brick_Decorative"
    },
    {
      "x": 1,
      "y": 2,
      "z": -5,
      "name": "Soil_Gravel",
      "support": 15
    },
    {
      "x": 1,
      "y": 3,
      "z": -5,
      "name": "Soil_Gravel",
      "support": 15
    },
    {
      "x": 1,
      "y": 4,
      "z": -5,
      "name": "Soil_Gravel",
      "support": 15
    },
    {
      "x": 1,
      "y": 5,
      "z": -5,
      "name": "Soil_Gravel",
      "support": 15
    },
    {
      "x": 1,
      "y": 6,
      "z": -5,
      "name": "Rock_Stone_Brick_Smooth"
    },
    {
      "x": 1,
      "y": 0,
      "z": -4,
      "name": "Rock_Stone_Brick_Smooth"
    },
    {
      "x": 1,
      "y": 1,
      "z": -4,
      "name": "Rock_Stone_Brick_Decorative"
    },
    {
      "x": 1,
      "y": 2,
      "z": -4,
      "name": "Soil_Gravel_Half",
      "support": 15,
      "rotation": 4
    },
    {
      "x": 1,
      "y": 3,
      "z": -4,
      "name": "Soil_Gravel_Half",
      "support": 15,
      "rotation": 4
    },
    {
      "x": 1,
      "y": 4,
      "z": -4,
      "name": "Soil_Gravel_Half",
      "support": 15,
      "rotation": 4
    },
    {
      "x": 1,
      "y": 5,
      "z": -4,
      "name": "Soil_Gravel_Half",
      "support": 15,
      "rotation": 4
    },
    {
      "x": 1,
      "y": 6,
      "z": -4,
      "name": "Rock_Stone_Brick"
    },
    {
      "x": 1,
      "y": 0,
      "z": -3,
      "name": "Rock_Stone_Brick_Smooth",
      "rotation": 3
    },
    {
      "x": 1,
      "y": 6,
      "z": -3,
      "name": "Rock_Stone_Brick_Smooth",
      "rotation": 3
    },
    {
      "x": 1,
      "y": 0,
      "z": -2,
      "name": "Rock_Stone_Brick_Smooth"
    },
    {
      "x": 1,
      "y": 6,
      "z": -2,
      "name": "Rock_Stone_Brick_Smooth"
    },
    {
      "x": 1,
      "y": 0,
      "z": -1,
      "name": "Rock_Stone_Brick_Smooth"
    },
    {
      "x": 1,
      "y": 6,
      "z": -1,
      "name": "Rock_Stone_Brick_Smooth"
    },
    {
      "x": 1,
      "y": 0,
      "z": 0,
      "name": "Rock_Stone_Brick_Smooth",
      "rotation": 3
    },
    {
      "x": 1,
      "y": 6,
      "z": 0,
      "name": "Rock_Stone_Brick_Smooth",
      "rotation": 3
    },
    {
      "x": 1,
      "y": 0,
      "z": 1,
      "name": "Rock_Stone_Brick_Smooth",
      "rotation": 3
    },
    {
      "x": 1,
      "y": 6,
      "z": 1,
      "name": "Rock_Stone_Brick_Smooth",
      "rotation": 3
    },
    {
      "x": 1,
      "y": 0,
      "z": 2,
      "name": "Rock_Stone_Brick_Smooth",
      "rotation": 2
    },
    {
      "x": 1,
      "y": 6,
      "z": 2,
      "name": "Rock_Stone_Brick_Smooth",
      "rotation": 3
    },
    {
      "x": 1,
      "y": 0,
      "z": 3,
      "name": "Rock_Stone_Brick_Smooth",
      "rotation": 2
    },
    {
      "x": 1,
      "y": 6,
      "z": 3,
      "name": "Rock_Stone_Brick_Smooth",
      "rotation": 3
    },
    {
      "x": 1,
      "y": 0,
      "z": 4,
      "name": "Rock_Stone_Brick_Smooth",
      "rotation": 2
    },
    {
      "x": 1,
      "y": 6,
      "z": 4,
      "name": "Rock_Stone_Brick_Smooth",
      "rotation": 2
    },
    {
      "x": 1,
      "y": 0,
      "z": 5,
      "name": "Rock_Stone_Brick_Smooth",
      "rotation": 2
    },
    {
      "x": 1,
      "y": 6,
      "z": 5,
      "name": "Rock_Stone_Brick_Smooth",
      "rotation": 2
    },
    {
      "x": 2,
      "y": 0,
      "z": -5,
      "name": "Rock_Stone_Brick"
    },
    {
      "x": 2,
      "y": 1,
      "z": -5,
      "name": "Rock_Stone_Brick_Decorative",
      "rotation": 2
    },
    {
      "x": 2,
      "y": 2,
      "z": -5,
      "name": "Soil_Gravel",
      "support": 15
    },
    {
      "x": 2,
      "y": 3,
      "z": -5,
      "name": "Soil_Gravel",
      "support": 15
    },
    {
      "x": 2,
      "y": 4,
      "z": -5,
      "name": "Soil_Gravel",
      "support": 15
    },
    {
      "x": 2,
      "y": 5,
      "z": -5,
      "name": "Soil_Gravel",
      "support": 15
    },
    {
      "x": 2,
      "y": 6,
      "z": -5,
      "name": "Rock_Stone_Brick_Smooth"
    },
    {
      "x": 2,
      "y": 0,
      "z": -4,
      "name": "Rock_Stone_Brick_Smooth",
      "rotation": 2
    },
    {
      "x": 2,
      "y": 1,
      "z": -4,
      "name": "Rock_Stone_Brick_Decorative"
    },
    {
      "x": 2,
      "y": 2,
      "z": -4,
      "name": "Rock_Stone_Brick_Pillar_Base"
    },
    {
      "x": 2,
      "y": 3,
      "z": -4,
      "name": "Rock_Stone_Brick_Pillar_Middle",
      "rotation": 8
    },
    {
      "x": 2,
      "y": 4,
      "z": -4,
      "name": "Rock_Stone_Brick_Pillar_Middle",
      "rotation": 8
    },
    {
      "x": 2,
      "y": 5,
      "z": -4,
      "name": "Rock_Stone_Brick_Pillar_Base",
      "rotation": 8
    },
    {
      "x": 2,
      "y": 6,
      "z": -4,
      "name": "Rock_Stone_Brick"
    },
    {
      "x": 2,
      "y": 0,
      "z": -3,
      "name": "Rock_Stone_Brick_Smooth",
      "rotation": 2
    },
    {
      "x": 2,
      "y": 6,
      "z": -3,
      "name": "Rock_Stone_Brick_Smooth",
      "rotation": 2
    },
    {
      "x": 2,
      "y": 0,
      "z": -2,
      "name": "Rock_Stone_Brick_Smooth",
      "rotation": 2
    },
    {
      "x": 2,
      "y": 6,
      "z": -2,
      "name": "Rock_Stone_Brick_Smooth",
      "rotation": 2
    },
    {
      "x": 2,
      "y": 0,
      "z": -1,
      "name": "Rock_Stone_Brick_Smooth",
      "rotation": 2
    },
    {
      "x": 2,
      "y": 6,
      "z": -1,
      "name": "Rock_Stone_Brick_Smooth",
      "rotation": 2
    },
    {
      "x": 2,
      "y": 0,
      "z": 0,
      "name": "Rock_Stone_Brick_Smooth",
      "rotation": 2
    },
    {
      "x": 2,
      "y": 6,
      "z": 0,
      "name": "Rock_Stone_Brick_Smooth",
      "rotation": 2
    },
    {
      "x": 2,
      "y": 0,
      "z": 1,
      "name": "Rock_Stone_Brick_Smooth",
      "rotation": 2
    },
    {
      "x": 2,
      "y": 6,
      "z": 1,
      "name": "Rock_Stone_Brick_Smooth",
      "rotation": 2
    },
    {
      "x": 2,
      "y": 0,
      "z": 2,
      "name": "Rock_Stone_Brick_Smooth",
      "rotation": 2
    },
    {
      "x": 2,
      "y": 6,
      "z": 2,
      "name": "Rock_Stone_Brick_Smooth",
      "rotation": 2
    },
    {
      "x": 2,
      "y": 0,
      "z": 3,
      "name": "Rock_Stone_Brick_Smooth",
      "rotation": 2
    },
    {
      "x": 2,
      "y": 6,
      "z": 3,
      "name": "Rock_Stone_Brick_Smooth",
      "rotation": 2
    },
    {
      "x": 2,
      "y": 0,
      "z": 4,
      "name": "Rock_Stone_Brick_Smooth",
      "rotation": 2
    },
    {
      "x": 2,
      "y": 1,
      "z": 4,
      "name": "Rock_Stone_Brick_Decorative"
    },
    {
      "x": 2,
      "y": 2,
      "z": 4,
      "name": "Rock_Stone_Brick_Pillar_Base"
    },
    {
      "x": 2,
      "y": 3,
      "z": 4,
      "name": "Rock_Stone_Brick_Pillar_Middle",
      "rotation": 8
    },
    {
      "x": 2,
      "y": 4,
      "z": 4,
      "name": "Rock_Stone_Brick_Pillar_Middle",
      "rotation": 8
    },
    {
      "x": 2,
      "y": 5,
      "z": 4,
      "name": "Rock_Stone_Brick_Pillar_Base",
      "rotation": 8
    },
    {
      "x": 2,
      "y": 6,
      "z": 4,
      "name": "Rock_Stone_Brick_Smooth",
      "rotation": 2
    },
    {
      "x": 2,
      "y": 0,
      "z": 5,
      "name": "Rock_Stone_Brick",
      "rotation": 2
    },
    {
      "x": 2,
      "y": 1,
      "z": 5,
      "name": "Rock_Stone_Brick_Decorative",
      "rotation": 2
    },
    {
      "x": 2,
      "y": 2,
      "z": 5,
      "name": "Rock_Stone_Brick",
      "rotation": 2
    },
    {
      "x": 2,
      "y": 3,
      "z": 5,
      "name": "Rock_Stone_Brick",
      "rotation": 2
    },
    {
      "x": 2,
      "y": 4,
      "z": 5,
      "name": "Rock_Stone_Brick",
      "rotation": 2
    },
    {
      "x": 2,
      "y": 5,
      "z": 5,
      "name": "Rock_Stone_Brick"
    },
    {
      "x": 2,
      "y": 6,
      "z": 5,
      "name": "Rock_Stone_Brick_Smooth"
    },
    {
      "x": 3,
      "y": 0,
      "z": -5,
      "name": "Rock_Stone_Brick"
    },
    {
      "x": 3,
      "y": 1,
      "z": -5,
      "name": "Rock_Stone_Brick_Decorative",
      "rotation": 2
    },
    {
      "x": 3,
      "y": 2,
      "z": -5,
      "name": "Soil_Gravel",
      "support": 15
    },
    {
      "x": 3,
      "y": 3,
      "z": -5,
      "name": "Soil_Gravel",
      "support": 15
    },
    {
      "x": 3,
      "y": 4,
      "z": -5,
      "name": "Soil_Gravel",
      "support": 15
    },
    {
      "x": 3,
      "y": 5,
      "z": -5,
      "name": "Soil_Gravel",
      "support": 15
    },
    {
      "x": 3,
      "y": 6,
      "z": -5,
      "name": "Rock_Stone_Brick_Smooth"
    },
    {
      "x": 3,
      "y": 0,
      "z": -4,
      "name": "Rock_Stone_Brick_Smooth",
      "rotation": 2
    },
    {
      "x": 3,
      "y": 1,
      "z": -4,
      "name": "Rock_Stone_Brick_Decorative"
    },
    {
      "x": 3,
      "y": 2,
      "z": -4,
      "name": "Soil_Gravel_Half",
      "support": 15,
      "rotation": 4
    },
    {
      "x": 3,
      "y": 3,
      "z": -4,
      "name": "Soil_Gravel_Half",
      "support": 15,
      "rotation": 4
    },
    {
      "x": 3,
      "y": 4,
      "z": -4,
      "name": "Soil_Gravel_Half",
      "support": 15,
      "rotation": 4
    },
    {
      "x": 3,
      "y": 5,
      "z": -4,
      "name": "Soil_Gravel_Half",
      "support": 15,
      "rotation": 4
    },
    {
      "x": 3,
      "y": 6,
      "z": -4,
      "name": "Rock_Stone_Brick"
    },
    {
      "x": 3,
      "y": 0,
      "z": -3,
      "name": "Rock_Stone_Brick_Smooth",
      "rotation": 2
    },
    {
      "x": 3,
      "y": 6,
      "z": -3,
      "name": "Rock_Stone_Brick_Smooth",
      "rotation": 2
    },
    {
      "x": 3,
      "y": 0,
      "z": -2,
      "name": "Rock_Stone_Brick_Smooth",
      "rotation": 2
    },
    {
      "x": 3,
      "y": 6,
      "z": -2,
      "name": "Rock_Stone_Brick_Smooth",
      "rotation": 2
    },
    {
      "x": 3,
      "y": 0,
      "z": -1,
      "name": "Rock_Stone_Brick_Smooth",
      "rotation": 2
    },
    {
      "x": 3,
      "y": 6,
      "z": -1,
      "name": "Rock_Stone_Brick_Smooth",
      "rotation": 2
    },
    {
      "x": 3,
      "y": 0,
      "z": 0,
      "name": "Rock_Stone_Brick_Smooth",
      "rotation": 2
    },
    {
      "x": 3,
      "y": 6,
      "z": 0,
      "name": "Rock_Stone_Brick_Smooth",
      "rotation": 2
    },
    {
      "x": 3,
      "y": 0,
      "z": 1,
      "name": "Rock_Stone_Brick_Smooth",
      "rotation": 2
    },
    {
      "x": 3,
      "y": 6,
      "z": 1,
      "name": "Rock_Stone_Brick_Smooth",
      "rotation": 2
    },
    {
      "x": 3,
      "y": 0,
      "z": 2,
      "name": "Rock_Stone_Brick_Smooth",
      "rotation": 2
    },
    {
      "x": 3,
      "y": 6,
      "z": 2,
      "name": "Rock_Stone_Brick_Smooth",
      "rotation": 2
    },
    {
      "x": 3,
      "y": 0,
      "z": 3,
      "name": "Rock_Stone_Brick_Smooth",
      "rotation": 2
    },
    {
      "x": 3,
      "y": 6,
      "z": 3,
      "name": "Rock_Stone_Brick_Smooth",
      "rotation": 2
    },
    {
      "x": 3,
      "y": 0,
      "z": 4,
      "name": "Rock_Stone_Brick_Smooth",
      "rotation": 2
    },
    {
      "x": 3,
      "y": 1,
      "z": 4,
      "name": "Rock_Stone_Brick_Decorative"
    },
    {
      "x": 3,
      "y": 2,
      "z": 4,
      "name": "Soil_Gravel_Half",
      "support": 15,
      "rotation": 6
    },
    {
      "x": 3,
      "y": 3,
      "z": 4,
      "name": "Soil_Gravel_Half",
      "support": 15,
      "rotation": 6
    },
    {
      "x": 3,
      "y": 4,
      "z": 4,
      "name": "Soil_Gravel_Half",
      "support": 15,
      "rotation": 6
    },
    {
      "x": 3,
      "y": 5,
      "z": 4,
      "name": "Soil_Gravel_Half",
      "support": 15,
      "rotation": 6
    },
    {
      "x": 3,
      "y": 6,
      "z": 4,
      "name": "Rock_Stone_Brick"
    },
    {
      "x": 3,
      "y": 0,
      "z": 5,
      "name": "Rock_Stone_Brick",
      "rotation": 2
    },
    {
      "x": 3,
      "y": 1,
      "z": 5,
      "name": "Rock_Stone_Brick_Decorative",
      "rotation": 2
    },
    {
      "x": 3,
      "y": 2,
      "z": 5,
      "name": "*Soil_Gravel_Half_State_Definitions_Block",
      "rotation": 6
    },
    {
      "x": 3,
      "y": 3,
      "z": 5,
      "name": "*Soil_Gravel_Half_State_Definitions_Block",
      "rotation": 6
    },
    {
      "x": 3,
      "y": 4,
      "z": 5,
      "name": "*Soil_Gravel_Half_State_Definitions_Block",
      "rotation": 6
    },
    {
      "x": 3,
      "y": 5,
      "z": 5,
      "name": "*Soil_Gravel_Half_State_Definitions_Block",
      "rotation": 6
    },
    {
      "x": 3,
      "y": 6,
      "z": 5,
      "name": "Rock_Stone_Brick_Smooth"
    },
    {
      "x": 4,
      "y": 0,
      "z": -5,
      "name": "Rock_Stone_Brick"
    },
    {
      "x": 4,
      "y": 1,
      "z": -5,
      "name": "Rock_Stone_Brick_Decorative"
    },
    {
      "x": 4,
      "y": 2,
      "z": -5,
      "name": "Soil_Gravel",
      "support": 15
    },
    {
      "x": 4,
      "y": 3,
      "z": -5,
      "name": "Soil_Gravel",
      "support": 15
    },
    {
      "x": 4,
      "y": 4,
      "z": -5,
      "name": "Soil_Gravel",
      "support": 15
    },
    {
      "x": 4,
      "y": 5,
      "z": -5,
      "name": "Soil_Gravel",
      "support": 15
    },
    {
      "x": 4,
      "y": 6,
      "z": -5,
      "name": "Rock_Stone_Brick_Smooth"
    },
    {
      "x": 4,
      "y": 0,
      "z": -4,
      "name": "Rock_Stone_Brick"
    },
    {
      "x": 4,
      "y": 1,
      "z": -4,
      "name": "Rock_Stone_Brick_Decorative"
    },
    {
      "x": 4,
      "y": 2,
      "z": -4,
      "name": "Rock_Stone_Brick"
    },
    {
      "x": 4,
      "y": 3,
      "z": -4,
      "name": "Rock_Stone_Brick"
    },
    {
      "x": 4,
      "y": 4,
      "z": -4,
      "name": "Rock_Stone_Brick"
    },
    {
      "x": 4,
      "y": 5,
      "z": -4,
      "name": "Rock_Stone_Brick_Decorative"
    },
    {
      "x": 4,
      "y": 6,
      "z": -4,
      "name": "Rock_Stone_Brick",
      "rotation": 1
    },
    {
      "x": 4,
      "y": 0,
      "z": -3,
      "name": "Rock_Stone_Brick",
      "rotation": 3
    },
    {
      "x": 4,
      "y": 1,
      "z": -3,
      "name": "Rock_Stone_Brick_Decorative",
      "rotation": 3
    },
    {
      "x": 4,
      "y": 2,
      "z": -3,
      "name": "Soil_Gravel_Half",
      "support": 15,
      "rotation": 7
    },
    {
      "x": 4,
      "y": 3,
      "z": -3,
      "name": "Soil_Gravel_Half",
      "support": 15,
      "rotation": 7
    },
    {
      "x": 4,
      "y": 4,
      "z": -3,
      "name": "Soil_Gravel_Half",
      "support": 15,
      "rotation": 7
    },
    {
      "x": 4,
      "y": 5,
      "z": -3,
      "name": "Soil_Gravel_Half",
      "support": 15,
      "rotation": 7
    },
    {
      "x": 4,
      "y": 6,
      "z": -3,
      "name": "Rock_Stone_Brick",
      "rotation": 1
    },
    {
      "x": 4,
      "y": 0,
      "z": -2,
      "name": "Rock_Stone_Brick"
    },
    {
      "x": 4,
      "y": 1,
      "z": -2,
      "name": "Rock_Stone_Brick_Decorative"
    },
    {
      "x": 4,
      "y": 2,
      "z": -2,
      "name": "Rock_Stone_Brick_Pillar_Base"
    },
    {
      "x": 4,
      "y": 3,
      "z": -2,
      "name": "Rock_Stone_Brick_Pillar_Middle"
    },
    {
      "x": 4,
      "y": 4,
      "z": -2,
      "name": "Rock_Stone_Brick_Pillar_Middle"
    },
    {
      "x": 4,
      "y": 5,
      "z": -2,
      "name": "Rock_Stone_Brick_Pillar_Base",
      "rotation": 34
    },
    {
      "x": 4,
      "y": 6,
      "z": -2,
      "name": "Rock_Stone_Brick",
      "rotation": 1
    },
    {
      "x": 4,
      "y": 0,
      "z": -1,
      "name": "Rock_Stone_Brick_Smooth",
      "rotation": 3
    },
    {
      "x": 4,
      "y": 1,
      "z": -1,
      "name": "Rock_Stone_Brick_Decorative",
      "rotation": 1
    },
    {
      "x": 4,
      "y": 2,
      "z": -1,
      "name": "Soil_Gravel_Half",
      "support": 15,
      "rotation": 7
    },
    {
      "x": 4,
      "y": 3,
      "z": -1,
      "name": "Soil_Gravel_Half",
      "support": 15,
      "rotation": 7
    },
    {
      "x": 4,
      "y": 4,
      "z": -1,
      "name": "Soil_Gravel_Half",
      "support": 15,
      "rotation": 7
    },
    {
      "x": 4,
      "y": 5,
      "z": -1,
      "name": "Soil_Gravel_Half",
      "support": 15,
      "rotation": 7
    },
    {
      "x": 4,
      "y": 6,
      "z": -1,
      "name": "Rock_Stone_Brick",
      "rotation": 1
    },
    {
      "x": 4,
      "y": 0,
      "z": 0,
      "name": "Rock_Stone_Brick_Smooth",
      "rotation": 3
    },
    {
      "x": 4,
      "y": 1,
      "z": 0,
      "name": "Rock_Stone_Brick_Decorative",
      "rotation": 1
    },
    {
      "x": 4,
      "y": 2,
      "z": 0,
      "name": "Soil_Gravel_Half",
      "support": 15,
      "rotation": 7
    },
    {
      "x": 4,
      "y": 3,
      "z": 0,
      "name": "Soil_Gravel_Half",
      "support": 15,
      "rotation": 7
    },
    {
      "x": 4,
      "y": 4,
      "z": 0,
      "name": "Soil_Gravel_Half",
      "support": 15,
      "rotation": 7
    },
    {
      "x": 4,
      "y": 5,
      "z": 0,
      "name": "Soil_Gravel_Half",
      "support": 15,
      "rotation": 7
    },
    {
      "x": 4,
      "y": 6,
      "z": 0,
      "name": "Rock_Stone_Brick",
      "rotation": 1
    },
    {
      "x": 4,
      "y": 0,
      "z": 1,
      "name": "Rock_Stone_Brick_Smooth",
      "rotation": 3
    },
    {
      "x": 4,
      "y": 1,
      "z": 1,
      "name": "Rock_Stone_Brick_Decorative",
      "rotation": 1
    },
    {
      "x": 4,
      "y": 2,
      "z": 1,
      "name": "Soil_Gravel_Half",
      "support": 15,
      "rotation": 7
    },
    {
      "x": 4,
      "y": 3,
      "z": 1,
      "name": "Soil_Gravel_Half",
      "support": 15,
      "rotation": 7
    },
    {
      "x": 4,
      "y": 4,
      "z": 1,
      "name": "Soil_Gravel_Half",
      "support": 15,
      "rotation": 7
    },
    {
      "x": 4,
      "y": 5,
      "z": 1,
      "name": "Soil_Gravel_Half",
      "support": 15,
      "rotation": 7
    },
    {
      "x": 4,
      "y": 6,
      "z": 1,
      "name": "Rock_Stone_Brick",
      "rotation": 1
    },
    {
      "x": 4,
      "y": 0,
      "z": 2,
      "name": "Rock_Stone_Brick",
      "rotation": 3
    },
    {
      "x": 4,
      "y": 1,
      "z": 2,
      "name": "Rock_Stone_Brick_Decorative",
      "rotation": 3
    },
    {
      "x": 4,
      "y": 2,
      "z": 2,
      "name": "Rock_Stone_Brick_Pillar_Base",
      "rotation": 3
    },
    {
      "x": 4,
      "y": 3,
      "z": 2,
      "name": "Rock_Stone_Brick_Pillar_Middle",
      "rotation": 3
    },
    {
      "x": 4,
      "y": 4,
      "z": 2,
      "name": "Rock_Stone_Brick_Pillar_Middle",
      "rotation": 3
    },
    {
      "x": 4,
      "y": 5,
      "z": 2,
      "name": "Rock_Stone_Brick_Pillar_Base",
      "rotation": 33
    },
    {
      "x": 4,
      "y": 6,
      "z": 2,
      "name": "Rock_Stone_Brick",
      "rotation": 1
    },
    {
      "x": 4,
      "y": 0,
      "z": 3,
      "name": "Rock_Stone_Brick"
    },
    {
      "x": 4,
      "y": 1,
      "z": 3,
      "name": "Rock_Stone_Brick_Decorative",
      "rotation": 3
    },
    {
      "x": 4,
      "y": 2,
      "z": 3,
      "name": "Soil_Gravel_Half",
      "support": 15,
      "rotation": 7
    },
    {
      "x": 4,
      "y": 3,
      "z": 3,
      "name": "Soil_Gravel_Half",
      "support": 15,
      "rotation": 7
    },
    {
      "x": 4,
      "y": 4,
      "z": 3,
      "name": "Soil_Gravel_Half",
      "support": 15,
      "rotation": 7
    },
    {
      "x": 4,
      "y": 5,
      "z": 3,
      "name": "Soil_Gravel_Half",
      "support": 15,
      "rotation": 7
    },
    {
      "x": 4,
      "y": 6,
      "z": 3,
      "name": "Rock_Stone_Brick",
      "rotation": 1
    },
    {
      "x": 4,
      "y": 0,
      "z": 4,
      "name": "Rock_Stone_Brick"
    },
    {
      "x": 4,
      "y": 1,
      "z": 4,
      "name": "Rock_Stone_Brick_Decorative",
      "rotation": 2
    },
    {
      "x": 4,
      "y": 2,
      "z": 4,
      "name": "Rock_Stone_Brick"
    },
    {
      "x": 4,
      "y": 3,
      "z": 4,
      "name": "Rock_Stone_Brick"
    },
    {
      "x": 4,
      "y": 4,
      "z": 4,
      "name": "Rock_Stone_Brick"
    },
    {
      "x": 4,
      "y": 5,
      "z": 4,
      "name": "Rock_Stone_Brick"
    },
    {
      "x": 4,
      "y": 6,
      "z": 4,
      "name": "Rock_Stone_Brick",
      "rotation": 1
    },
    {
      "x": 4,
      "y": 0,
      "z": 5,
      "name": "Rock_Stone_Brick",
      "rotation": 2
    },
    {
      "x": 4,
      "y": 1,
      "z": 5,
      "name": "Rock_Stone_Brick_Decorative",
      "rotation": 2
    },
    {
      "x": 4,
      "y": 2,
      "z": 5,
      "name": "Soil_Gravel",
      "support": 15
    },
    {
      "x": 4,
      "y": 3,
      "z": 5,
      "name": "Soil_Gravel",
      "support": 15
    },
    {
      "x": 4,
      "y": 4,
      "z": 5,
      "name": "Soil_Gravel",
      "support": 15
    },
    {
      "x": 4,
      "y": 5,
      "z": 5,
      "name": "Soil_Gravel",
      "support": 15
    },
    {
      "x": 4,
      "y": 6,
      "z": 5,
      "name": "Rock_Stone_Brick_Smooth"
    },
    {
      "x": 5,
      "y": 0,
      "z": -5,
      "name": "Rock_Stone_Brick",
      "rotation": 3
    },
    {
      "x": 5,
      "y": 1,
      "z": -5,
      "name": "Rock_Stone_Brick_Decorative"
    },
    {
      "x": 5,
      "y": 2,
      "z": -5,
      "name": "Soil_Gravel",
      "support": 15
    },
    {
      "x": 5,
      "y": 3,
      "z": -5,
      "name": "Soil_Gravel",
      "support": 15
    },
    {
      "x": 5,
      "y": 4,
      "z": -5,
      "name": "Soil_Gravel",
      "support": 15
    },
    {
      "x": 5,
      "y": 5,
      "z": -5,
      "name": "Soil_Gravel",
      "support": 15
    },
    {
      "x": 5,
      "y": 6,
      "z": -5,
      "name": "Rock_Stone_Brick_Smooth"
    },
    {
      "x": 5,
      "y": 0,
      "z": -4,
      "name": "Rock_Stone_Brick",
      "rotation": 3
    },
    {
      "x": 5,
      "y": 1,
      "z": -4,
      "name": "Rock_Stone_Brick_Decorative"
    },
    {
      "x": 5,
      "y": 2,
      "z": -4,
      "name": "Soil_Gravel",
      "support": 15
    },
    {
      "x": 5,
      "y": 3,
      "z": -4,
      "name": "Soil_Gravel",
      "support": 15
    },
    {
      "x": 5,
      "y": 4,
      "z": -4,
      "name": "Soil_Gravel",
      "support": 15
    },
    {
      "x": 5,
      "y": 5,
      "z": -4,
      "name": "Soil_Gravel",
      "support": 15
    },
    {
      "x": 5,
      "y": 6,
      "z": -4,
      "name": "Rock_Stone_Brick_Smooth"
    },
    {
      "x": 5,
      "y": 0,
      "z": -3,
      "name": "Rock_Stone_Brick",
      "rotation": 3
    },
    {
      "x": 5,
      "y": 1,
      "z": -3,
      "name": "Rock_Stone_Brick_Decorative",
      "rotation": 3
    },
    {
      "x": 5,
      "y": 2,
      "z": -3,
      "name": "Soil_Gravel",
      "support": 15,
      "rotation": 3
    },
    {
      "x": 5,
      "y": 3,
      "z": -3,
      "name": "Soil_Gravel",
      "support": 15,
      "rotation": 3
    },
    {
      "x": 5,
      "y": 4,
      "z": -3,
      "name": "Soil_Gravel",
      "support": 15,
      "rotation": 3
    },
    {
      "x": 5,
      "y": 5,
      "z": -3,
      "name": "Soil_Gravel",
      "support": 15,
      "rotation": 3
    },
    {
      "x": 5,
      "y": 6,
      "z": -3,
      "name": "Rock_Stone_Brick_Smooth",
      "rotation": 3
    },
    {
      "x": 5,
      "y": 0,
      "z": -2,
      "name": "Rock_Stone_Brick",
      "rotation": 3
    },
    {
      "x": 5,
      "y": 1,
      "z": -2,
      "name": "Rock_Stone_Brick_Decorative",
      "rotation": 1
    },
    {
      "x": 5,
      "y": 2,
      "z": -2,
      "name": "Soil_Gravel",
      "support": 15,
      "rotation": 1
    },
    {
      "x": 5,
      "y": 3,
      "z": -2,
      "name": "Soil_Gravel",
      "support": 15,
      "rotation": 1
    },
    {
      "x": 5,
      "y": 4,
      "z": -2,
      "name": "Soil_Gravel",
      "support": 15,
      "rotation": 1
    },
    {
      "x": 5,
      "y": 5,
      "z": -2,
      "name": "Soil_Gravel",
      "support": 15,
      "rotation": 1
    },
    {
      "x": 5,
      "y": 6,
      "z": -2,
      "name": "Rock_Stone_Brick_Smooth"
    },
    {
      "x": 5,
      "y": 0,
      "z": -1,
      "name": "Rock_Stone_Brick",
      "rotation": 3
    },
    {
      "x": 5,
      "y": 1,
      "z": -1,
      "name": "Rock_Stone_Brick_Decorative",
      "rotation": 1
    },
    {
      "x": 5,
      "y": 2,
      "z": -1,
      "name": "Soil_Gravel",
      "support": 15,
      "rotation": 1
    },
    {
      "x": 5,
      "y": 3,
      "z": -1,
      "name": "Soil_Gravel",
      "support": 15,
      "rotation": 1
    },
    {
      "x": 5,
      "y": 4,
      "z": -1,
      "name": "Soil_Gravel",
      "support": 15,
      "rotation": 1
    },
    {
      "x": 5,
      "y": 5,
      "z": -1,
      "name": "Soil_Gravel",
      "support": 15,
      "rotation": 1
    },
    {
      "x": 5,
      "y": 6,
      "z": -1,
      "name": "Rock_Stone_Brick_Smooth"
    },
    {
      "x": 5,
      "y": 0,
      "z": 0,
      "name": "Rock_Stone_Brick",
      "rotation": 3
    },
    {
      "x": 5,
      "y": 1,
      "z": 0,
      "name": "Rock_Stone_Brick_Decorative",
      "rotation": 1
    },
    {
      "x": 5,
      "y": 2,
      "z": 0,
      "name": "Soil_Gravel",
      "support": 15,
      "rotation": 1
    },
    {
      "x": 5,
      "y": 3,
      "z": 0,
      "name": "Soil_Gravel",
      "support": 15,
      "rotation": 1
    },
    {
      "x": 5,
      "y": 4,
      "z": 0,
      "name": "Soil_Gravel",
      "support": 15,
      "rotation": 1
    },
    {
      "x": 5,
      "y": 5,
      "z": 0,
      "name": "Soil_Gravel",
      "support": 15,
      "rotation": 1
    },
    {
      "x": 5,
      "y": 6,
      "z": 0,
      "name": "Rock_Stone_Brick_Smooth",
      "rotation": 2
    },
    {
      "x": 5,
      "y": 0,
      "z": 1,
      "name": "Rock_Stone_Brick",
      "rotation": 3
    },
    {
      "x": 5,
      "y": 1,
      "z": 1,
      "name": "Rock_Stone_Brick_Decorative",
      "rotation": 1
    },
    {
      "x": 5,
      "y": 2,
      "z": 1,
      "name": "Soil_Gravel",
      "support": 15,
      "rotation": 1
    },
    {
      "x": 5,
      "y": 3,
      "z": 1,
      "name": "Soil_Gravel",
      "support": 15,
      "rotation": 1
    },
    {
      "x": 5,
      "y": 4,
      "z": 1,
      "name": "Soil_Gravel",
      "support": 15,
      "rotation": 1
    },
    {
      "x": 5,
      "y": 5,
      "z": 1,
      "name": "Soil_Gravel",
      "support": 15,
      "rotation": 1
    },
    {
      "x": 5,
      "y": 6,
      "z": 1,
      "name": "Rock_Stone_Brick_Smooth",
      "rotation": 2
    },
    {
      "x": 5,
      "y": 0,
      "z": 2,
      "name": "Rock_Stone_Brick",
      "rotation": 3
    },
    {
      "x": 5,
      "y": 1,
      "z": 2,
      "name": "Rock_Stone_Brick_Decorative",
      "rotation": 2
    },
    {
      "x": 5,
      "y": 2,
      "z": 2,
      "name": "Soil_Gravel",
      "support": 15,
      "rotation": 1
    },
    {
      "x": 5,
      "y": 3,
      "z": 2,
      "name": "Soil_Gravel",
      "support": 15,
      "rotation": 1
    },
    {
      "x": 5,
      "y": 4,
      "z": 2,
      "name": "Soil_Gravel",
      "support": 15,
      "rotation": 1
    },
    {
      "x": 5,
      "y": 5,
      "z": 2,
      "name": "Soil_Gravel",
      "support": 15,
      "rotation": 1
    },
    {
      "x": 5,
      "y": 6,
      "z": 2,
      "name": "Rock_Stone_Brick_Smooth",
      "rotation": 2
    },
    {
      "x": 5,
      "y": 0,
      "z": 3,
      "name": "Rock_Stone_Brick",
      "rotation": 3
    },
    {
      "x": 5,
      "y": 1,
      "z": 3,
      "name": "Rock_Stone_Brick_Decorative",
      "rotation": 2
    },
    {
      "x": 5,
      "y": 2,
      "z": 3,
      "name": "Soil_Gravel",
      "support": 15,
      "rotation": 2
    },
    {
      "x": 5,
      "y": 3,
      "z": 3,
      "name": "Soil_Gravel",
      "support": 15,
      "rotation": 2
    },
    {
      "x": 5,
      "y": 4,
      "z": 3,
      "name": "Soil_Gravel",
      "support": 15,
      "rotation": 2
    },
    {
      "x": 5,
      "y": 5,
      "z": 3,
      "name": "Soil_Gravel",
      "support": 15,
      "rotation": 2
    },
    {
      "x": 5,
      "y": 6,
      "z": 3,
      "name": "Rock_Stone_Brick_Smooth",
      "rotation": 2
    },
    {
      "x": 5,
      "y": 0,
      "z": 4,
      "name": "Rock_Stone_Brick",
      "rotation": 3
    },
    {
      "x": 5,
      "y": 1,
      "z": 4,
      "name": "Rock_Stone_Brick_Decorative"
    },
    {
      "x": 5,
      "y": 2,
      "z": 4,
      "name": "Soil_Gravel",
      "support": 15
    },
    {
      "x": 5,
      "y": 3,
      "z": 4,
      "name": "Soil_Gravel",
      "support": 15
    },
    {
      "x": 5,
      "y": 4,
      "z": 4,
      "name": "Soil_Gravel",
      "support": 15
    },
    {
      "x": 5,
      "y": 5,
      "z": 4,
      "name": "Soil_Gravel",
      "support": 15
    },
    {
      "x": 5,
      "y": 6,
      "z": 4,
      "name": "Rock_Stone_Brick_Smooth"
    },
    {
      "x": 5,
      "y": 0,
      "z": 5,
      "name": "Rock_Stone_Brick",
      "rotation": 3
    },
    {
      "x": 5,
      "y": 1,
      "z": 5,
      "name": "Rock_Stone_Brick_Decorative",
      "rotation": 3
    },
    {
      "x": 5,
      "y": 2,
      "z": 5,
      "name": "Soil_Gravel",
      "support": 15,
      "rotation": 3
    },
    {
      "x": 5,
      "y": 3,
      "z": 5,
      "name": "Soil_Gravel",
      "support": 15,
      "rotation": 3
    },
    {
      "x": 5,
      "y": 4,
      "z": 5,
      "name": "Soil_Gravel",
      "support": 15,
      "rotation": 3
    },
    {
      "x": 5,
      "y": 5,
      "z": 5,
      "name": "Soil_Gravel",
      "support": 15,
      "rotation": 3
    },
    {
      "x": 5,
      "y": 6,
      "z": 5,
      "name": "Rock_Stone_Brick_Smooth",
      "rotation": 3
    }
  ]
}