{
  "version": 8,
  "blockIdVersion": 11,
  "anchorX": 0,
  "anchorY": 0,
  "anchorZ": 0,
  "blocks": [
    {
      "x": -7,
      "y": 0,
      "z": -7,
      "name": "Cloth_Block_Wool_Orange",
      "rotation": 1
    },
    {
      "x": -7,
      "y": 1,
      "z": -7,
      "name": "Rock_Ice_Permafrost"
    },
    {
      "x": -7,
      "y": 2,
      "z": -7,
      "name": "Rock_Ice",
      "rotation": 1
    },
    {
      "x": -7,
      "y": 3,
      "z": -7,
      "name": "Rock_Ice_Permafrost",
      "rotation": 1
    },
    {
      "x": -7,
      "y": 4,
      "z": -7,
      "name": "Rock_Ice_Permafrost",
      "rotation": 1
    },
    {
      "x": -7,
      "y": 5,
      "z": -7,
      "name": "Rock_Ice",
      "rotation": 1
    },
    {
      "x": -7,
      "y": 6,
      "z": -7,
      "name": "Rock_Ice",
      "rotation": 1
    },
    {
      "x": -7,
      "y": 7,
      "z": -7,
      "name": "Wood_Ice_Trunk",
      "rotation": 1
    },
    {
      "x": -7,
      "y": 8,
      "z": -7,
      "name": "Rock_Ice_Permafrost"
    },
    {
      "x": -7,
      "y": 9,
      "z": -7,
      "name": "Rock_Ice"
    },
    {
      "x": -7,
      "y": 10,
      "z": -7,
      "name": "Wood_Ice_Trunk"
    },
    {
      "x": -7,
      "y": 11,
      "z": -7,
      "name": "Rock_Ice",
      "rotation": 1
    },
    {
      "x": -7,
      "y": 12,
      "z": -7,
      "name": "Rock_Ice_Permafrost",
      "rotation": 1
    },
    {
      "x": -7,
      "y": 13,
      "z": -7,
      "name": "Wood_Ice_Trunk",
      "rotation": 1
    },
    {
      "x": -7,
      "y": 14,
      "z": -7,
      "name": "Soil_Snow",
      "support": 15
    },
    {
      "x": -7,
      "y": 0,
      "z": -6,
      "name": "Rock_Ice",
      "rotation": 1
    },
    {
      "x": -7,
      "y": 1,
      "z": -6,
      "name": "Rock_Ice_Permafrost",
      "rotation": 1
    },
    {
      "x": -7,
      "y": 2,
      "z": -6,
      "name": "Rock_Ice_Permafrost",
      "rotation": 1
    },
    {
      "x": -7,
      "y": 3,
      "z": -6,
      "name": "Rock_Ice",
      "rotation": 1
    },
    {
      "x": -7,
      "y": 4,
      "z": -6,
      "name": "Rock_Ice_Permafrost",
      "rotation": 1
    },
    {
      "x": -7,
      "y": 5,
      "z": -6,
      "name": "Rock_Ice",
      "rotation": 1
    },
    {
      "x": -7,
      "y": 6,
      "z": -6,
      "name": "Rock_Ice_Permafrost",
      "rotation": 1
    },
    {
      "x": -7,
      "y": 7,
      "z": -6,
      "name": "Rock_Ice_Permafrost",
      "rotation": 1
    },
    {
      "x": -7,
      "y": 8,
      "z": -6,
      "name": "Rock_Ice"
    },
    {
      "x": -7,
      "y": 9,
      "z": -6,
      "name": "Rock_Ice_Permafrost"
    },
    {
      "x": -7,
      "y": 10,
      "z": -6,
      "name": "Rock_Ice"
    },
    {
      "x": -7,
      "y": 11,
      "z": -6,
      "name": "Wood_Ice_Trunk",
      "rotation": 1
    },
    {
      "x": -7,
      "y": 12,
      "z": -6,
      "name": "Rock_Ice",
      "rotation": 1
    },
    {
      "x": -7,
      "y": 13,
      "z": -6,
      "name": "Rock_Ice_Permafrost",
      "rotation": 1
    },
    {
      "x": -7,
      "y": 14,
      "z": -6,
      "name": "Soil_Snow",
      "support": 15
    },
    {
      "x": -7,
      "y": 0,
      "z": -5,
      "name": "Rock_Ice_Permafrost",
      "rotation": 1
    },
    {
      "x": -7,
      "y": 1,
      "z": -5,
      "name": "Rock_Ice_Permafrost",
      "rotation": 1
    },
    {
      "x": -7,
      "y": 2,
      "z": -5,
      "name": "Rock_Ice_Permafrost",
      "rotation": 1
    },
    {
      "x": -7,
      "y": 3,
      "z": -5,
      "name": "Wood_Ice_Trunk",
      "rotation": 1
    },
    {
      "x": -7,
      "y": 4,
      "z": -5,
      "name": "Rock_Ice_Permafrost",
      "rotation": 1
    },
    {
      "x": -7,
      "y": 5,
      "z": -5,
      "name": "Wood_Ice_Trunk",
      "rotation": 1
    },
    {
      "x": -7,
      "y": 6,
      "z": -5,
      "name": "Rock_Ice_Permafrost",
      "rotation": 1
    },
    {
      "x": -7,
      "y": 7,
      "z": -5,
      "name": "Rock_Ice",
      "rotation": 1
    },
    {
      "x": -7,
      "y": 8,
      "z": -5,
      "name": "Rock_Ice"
    },
    {
      "x": -7,
      "y": 9,
      "z": -5,
      "name": "Wood_Ice_Trunk"
    },
    {
      "x": -7,
      "y": 10,
      "z": -5,
      "name": "Rock_Ice"
    },
    {
      "x": -7,
      "y": 11,
      "z": -5,
      "name": "Rock_Ice_Permafrost",
      "rotation": 1
    },
    {
      "x": -7,
      "y": 12,
      "z": -5,
      "name": "Rock_Ice_Permafrost"
    },
    {
      "x": -7,
      "y": 13,
      "z": -5,
      "name": "Rock_Marble_Brick_Wall"
    },
    {
      "x": -7,
      "y": 14,
      "z": -5,
      "name": "Rock_Shale_Brick_Decorative"
    },
    {
      "x": -7,
      "y": 15,
      "z": -5,
      "name": "Rock_Marble_Brick_Wall"
    },
    {
      "x": -7,
      "y": 0,
      "z": -4,
      "name": "Rock_Ice",
      "rotation": 1
    },
    {
      "x": -7,
      "y": 1,
      "z": -4,
      "name": "Rock_Marble_Brick_Stairs",
      "rotation": 2
    },
    {
      "x": -7,
      "y": 10,
      "z": -4,
      "name": "Rock_Marble_Brick_Stairs",
      "rotation": 10
    },
    {
      "x": -7,
      "y": 11,
      "z": -4,
      "name": "Rock_Ice_Permafrost"
    },
    {
      "x": -7,
      "y": 12,
      "z": -4,
      "name": "Soil_Snow_Brick_Stairs",
      "rotation": 2
    },
    {
      "x": -7,
      "y": 0,
      "z": -3,
      "name": "Rock_Ice",
      "rotation": 1
    },
    {
      "x": -7,
      "y": 1,
      "z": -3,
      "name": "Rock_Ice",
      "rotation": 1
    },
    {
      "x": -7,
      "y": 12,
      "z": -3,
      "name": "Soil_Snow_Brick_Stairs",
      "rotation": 10
    },
    {
      "x": -7,
      "y": 13,
      "z": -3,
      "name": "Soil_Snow_Brick_Stairs",
      "rotation": 2
    },
    {
      "x": -7,
      "y": 0,
      "z": -2,
      "name": "Rock_Ice",
      "rotation": 1
    },
    {
      "x": -7,
      "y": 1,
      "z": -2,
      "name": "Rock_Ice_Permafrost",
      "rotation": 1
    },
    {
      "x": -7,
      "y": 13,
      "z": -2,
      "name": "Soil_Snow_Brick_Beam",
      "rotation": 4
    },
    {
      "x": -7,
      "y": 0,
      "z": -1,
      "name": "Rock_Ice_Permafrost",
      "rotation": 1
    },
    {
      "x": -7,
      "y": 1,
      "z": -1,
      "name": "Rock_Ice_Permafrost",
      "rotation": 1
    },
    {
      "x": -7,
      "y": 13,
      "z": -1,
      "name": "Soil_Snow_Brick_Beam",
      "rotation": 4
    },
    {
      "x": -7,
      "y": 0,
      "z": 0,
      "name": "Rock_Ice",
      "rotation": 1
    },
    {
      "x": -7,
      "y": 1,
      "z": 0,
      "name": "Rock_Ice_Permafrost",
      "rotation": 1
    },
    {
      "x": -7,
      "y": 13,
      "z": 0,
      "name": "Soil_Snow_Brick_Beam",
      "rotation": 4
    },
    {
      "x": -7,
      "y": 0,
      "z": 1,
      "name": "Rock_Ice",
      "rotation": 1
    },
    {
      "x": -7,
      "y": 1,
      "z": 1,
      "name": "Rock_Ice",
      "rotation": 1
    },
    {
      "x": -7,
      "y": 13,
      "z": 1,
      "name": "Soil_Snow_Brick_Beam",
      "rotation": 4
    },
    {
      "x": -7,
      "y": 0,
      "z": 2,
      "name": "Rock_Ice",
      "rotation": 1
    },
    {
      "x": -7,
      "y": 1,
      "z": 2,
      "name": "Rock_Ice_Permafrost",
      "rotation": 1
    },
    {
      "x": -7,
      "y": 13,
      "z": 2,
      "name": "Soil_Snow_Brick_Beam",
      "rotation": 4
    },
    {
      "x": -7,
      "y": 0,
      "z": 3,
      "name": "Rock_Ice_Permafrost",
      "rotation": 1
    },
    {
      "x": -7,
      "y": 1,
      "z": 3,
      "name": "Rock_Ice",
      "rotation": 1
    },
    {
      "x": -7,
      "y": 13,
      "z": 3,
      "name": "Soil_Snow_Brick_Beam",
      "rotation": 4
    },
    {
      "x": -7,
      "y": 1,
      "z": 4,
      "name": "Rock_Ice_Permafrost",
      "rotation": 1
    },
    {
      "x": -7,
      "y": 12,
      "z": 4,
      "name": "Soil_Snow_Brick_Stairs",
      "rotation": 8
    },
    {
      "x": -7,
      "y": 13,
      "z": 4,
      "name": "Rock_Marble_Brick_Stairs"
    },
    {
      "x": -7,
      "y": 0,
      "z": 5,
      "name": "Rock_Ice",
      "rotation": 1
    },
    {
      "x": -7,
      "y": 1,
      "z": 5,
      "name": "Rock_Marble_Brick_Stairs"
    },
    {
      "x": -7,
      "y": 10,
      "z": 5,
      "name": "Rock_Marble_Brick_Stairs",
      "rotation": 8
    },
    {
      "x": -7,
      "y": 11,
      "z": 5,
      "name": "Wood_Ice_Trunk"
    },
    {
      "x": -7,
      "y": 12,
      "z": 5,
      "name": "Soil_Snow_Brick_Stairs"
    },
    {
      "x": -7,
      "y": 0,
      "z": 6,
      "name": "Rock_Ice",
      "rotation": 1
    },
    {
      "x": -7,
      "y": 1,
      "z": 6,
      "name": "Rock_Ice_Permafrost",
      "rotation": 1
    },
    {
      "x": -7,
      "y": 2,
      "z": 6,
      "name": "Wood_Ice_Trunk",
      "rotation": 1
    },
    {
      "x": -7,
      "y": 3,
      "z": 6,
      "name": "Rock_Ice",
      "rotation": 1
    },
    {
      "x": -7,
      "y": 4,
      "z": 6,
      "name": "Rock_Ice_Permafrost",
      "rotation": 1
    },
    {
      "x": -7,
      "y": 5,
      "z": 6,
      "name": "Rock_Ice_Permafrost",
      "rotation": 1
    },
    {
      "x": -7,
      "y": 6,
      "z": 6,
      "name": "Rock_Ice",
      "rotation": 1
    },
    {
      "x": -7,
      "y": 7,
      "z": 6,
      "name": "Rock_Ice_Permafrost",
      "rotation": 1
    },
    {
      "x": -7,
      "y": 8,
      "z": 6,
      "name": "Wood_Ice_Trunk"
    },
    {
      "x": -7,
      "y": 9,
      "z": 6,
      "name": "Wood_Ice_Trunk"
    },
    {
      "x": -7,
      "y": 10,
      "z": 6,
      "name": "Wood_Ice_Trunk",
      "rotation": 1
    },
    {
      "x": -7,
      "y": 11,
      "z": 6,
      "name": "Rock_Ice_Permafrost",
      "rotation": 1
    },
    {
      "x": -7,
      "y": 12,
      "z": 6,
      "name": "Rock_Ice"
    },
    {
      "x": -7,
      "y": 13,
      "z": 6,
      "name": "Rock_Marble_Brick_Wall"
    },
    {
      "x": -7,
      "y": 14,
      "z": 6,
      "name": "Rock_Shale_Brick_Decorative"
    },
    {
      "x": -7,
      "y": 15,
      "z": 6,
      "name": "Rock_Marble_Brick_Wall"
    },
    {
      "x": -7,
      "y": 0,
      "z": 7,
      "name": "Rock_Ice",
      "rotation": 1
    },
    {
      "x": -7,
      "y": 1,
      "z": 7,
      "name": "Rock_Ice_Permafrost",
      "rotation": 1
    },
    {
      "x": -7,
      "y": 2,
      "z": 7,
      "name": "Rock_Ice_Permafrost",
      "rotation": 1
    },
    {
      "x": -7,
      "y": 3,
      "z": 7,
      "name": "Rock_Ice",
      "rotation": 1
    },
    {
      "x": -7,
      "y": 4,
      "z": 7,
      "name": "Rock_Ice",
      "rotation": 1
    },
    {
      "x": -7,
      "y": 5,
      "z": 7,
      "name": "Rock_Ice_Permafrost",
      "rotation": 1
    },
    {
      "x": -7,
      "y": 6,
      "z": 7,
      "name": "Rock_Ice",
      "rotation": 1
    },
    {
      "x": -7,
      "y": 7,
      "z": 7,
      "name": "Rock_Ice",
      "rotation": 1
    },
    {
      "x": -7,
      "y": 8,
      "z": 7,
      "name": "Wood_Ice_Trunk"
    },
    {
      "x": -7,
      "y": 9,
      "z": 7,
      "name": "Rock_Ice"
    },
    {
      "x": -7,
      "y": 10,
      "z": 7,
      "name": "Wood_Ice_Trunk",
      "rotation": 1
    },
    {
      "x": -7,
      "y": 11,
      "z": 7,
      "name": "Rock_Ice_Permafrost",
      "rotation": 1
    },
    {
      "x": -7,
      "y": 12,
      "z": 7,
      "name": "Rock_Ice",
      "rotation": 1
    },
    {
      "x": -7,
      "y": 13,
      "z": 7,
      "name": "Rock_Ice_Permafrost",
      "rotation": 1
    },
    {
      "x": -7,
      "y": 14,
      "z": 7,
      "name": "Soil_Snow",
      "support": 15
    },
    {
      "x": -7,
      "y": 0,
      "z": 8,
      "name": "Cloth_Block_Wool_Orange",
      "rotation": 1
    },
    {
      "x": -7,
      "y": 1,
      "z": 8,
      "name": "Rock_Ice"
    },
    {
      "x": -7,
      "y": 2,
      "z": 8,
      "name": "Rock_Ice",
      "rotation": 1
    },
    {
      "x": -7,
      "y": 3,
      "z": 8,
      "name": "Rock_Ice",
      "rotation": 1
    },
    {
      "x": -7,
      "y": 4,
      "z": 8,
      "name": "Wood_Ice_Trunk",
      "rotation": 1
    },
    {
      "x": -7,
      "y": 5,
      "z": 8,
      "name": "Wood_Ice_Trunk",
      "rotation": 1
    },
    {
      "x": -7,
      "y": 6,
      "z": 8,
      "name": "Wood_Ice_Trunk",
      "rotation": 1
    },
    {
      "x": -7,
      "y": 7,
      "z": 8,
      "name": "Rock_Ice_Permafrost",
      "rotation": 1
    },
    {
      "x": -7,
      "y": 8,
      "z": 8,
      "name": "Rock_Ice"
    },
    {
      "x": -7,
      "y": 9,
      "z": 8,
      "name": "Rock_Ice_Permafrost"
    },
    {
      "x": -7,
      "y": 10,
      "z": 8,
      "name": "Rock_Ice",
      "rotation": 1
    },
    {
      "x": -7,
      "y": 11,
      "z": 8,
      "name": "Rock_Ice_Permafrost",
      "rotation": 1
    },
    {
      "x": -7,
      "y": 12,
      "z": 8,
      "name": "Wood_Ice_Trunk",
      "rotation": 1
    },
    {
      "x": -7,
      "y": 13,
      "z": 8,
      "name": "Rock_Ice_Permafrost",
      "rotation": 1
    },
    {
      "x": -7,
      "y": 14,
      "z": 8,
      "name": "Soil_Snow"
    },
    {
      "x": -6,
      "y": 0,
      "z": -7,
      "name": "Rock_Ice_Permafrost",
      "rotation": 1
    },
    {
      "x": -6,
      "y": 1,
      "z": -7,
      "name": "Rock_Ice_Permafrost"
    },
    {
      "x": -6,
      "y": 2,
      "z": -7,
      "name": "Wood_Ice_Trunk",
      "rotation": 1
    },
    {
      "x": -6,
      "y": 3,
      "z": -7,
      "name": "Wood_Ice_Trunk",
      "rotation": 1
    },
    {
      "x": -6,
      "y": 4,
      "z": -7,
      "name": "Wood_Ice_Trunk",
      "rotation": 1
    },
    {
      "x": -6,
      "y": 5,
      "z": -7,
      "name": "Rock_Ice",
      "rotation": 1
    },
    {
      "x": -6,
      "y": 6,
      "z": -7,
      "name": "Rock_Ice_Permafrost",
      "rotation": 1
    },
    {
      "x": -6,
      "y": 7,
      "z": -7,
      "name": "Wood_Ice_Trunk",
      "rotation": 1
    },
    {
      "x": -6,
      "y": 8,
      "z": -7,
      "name": "Rock_Ice"
    },
    {
      "x": -6,
      "y": 9,
      "z": -7,
      "name": "Rock_Ice"
    },
    {
      "x": -6,
      "y": 10,
      "z": -7,
      "name": "Rock_Ice"
    },
    {
      "x": -6,
      "y": 11,
      "z": -7,
      "name": "Rock_Ice_Permafrost",
      "rotation": 1
    },
    {
      "x": -6,
      "y": 12,
      "z": -7,
      "name": "Rock_Ice_Permafrost",
      "rotation": 1
    },
    {
      "x": -6,
      "y": 13,
      "z": -7,
      "name": "Wood_Ice_Trunk",
      "rotation": 1
    },
    {
      "x": -6,
      "y": 14,
      "z": -7,
      "name": "Soil_Snow"
    },
    {
      "x": -6,
      "y": 0,
      "z": -6,
      "name": "Rock_Ice",
      "rotation": 1
    },
    {
      "x": -6,
      "y": 1,
      "z": -6,
      "name": "Rock_Ice_Permafrost",
      "rotation": 1
    },
    {
      "x": -6,
      "y": 2,
      "z": -6,
      "name": "Wood_Ice_Trunk",
      "rotation": 1
    },
    {
      "x": -6,
      "y": 3,
      "z": -6,
      "name": "Furniture_Human_Ruins_Brazier"
    },
    {
      "x": -6,
      "y": 6,
      "z": -6,
      "name": "Rock_Ice",
      "rotation": 1
    },
    {
      "x": -6,
      "y": 7,
      "z": -6,
      "name": "Rock_Ice",
      "rotation": 1
    },
    {
      "x": -6,
      "y": 8,
      "z": -6,
      "name": "Rock_Ice"
    },
    {
      "x": -6,
      "y": 9,
      "z": -6,
      "name": "Wood_Ice_Trunk"
    },
    {
      "x": -6,
      "y": 10,
      "z": -6,
      "name": "Wood_Ice_Trunk"
    },
    {
      "x": -6,
      "y": 11,
      "z": -6,
      "name": "Rock_Ice_Permafrost",
      "rotation": 1
    },
    {
      "x": -6,
      "y": 12,
      "z": -6,
      "name": "Rock_Ice_Permafrost",
      "rotation": 1
    },
    {
      "x": -6,
      "y": 13,
      "z": -6,
      "name": "Rock_Ice",
      "rotation": 1
    },
    {
      "x": -6,
      "y": 14,
      "z": -6,
      "name": "Soil_Snow",
      "support": 15
    },
    {
      "x": -6,
      "y": 0,
      "z": -5,
      "name": "Rock_Ice_Permafrost",
      "rotation": 1
    },
    {
      "x": -6,
      "y": 1,
      "z": -5,
      "name": "Rock_Ice",
      "rotation": 1
    },
    {
      "x": -6,
      "y": 2,
      "z": -5,
      "name": "Rock_Ice",
      "rotation": 1
    },
    {
      "x": -6,
      "y": 3,
      "z": -5,
      "name": "Rock_Marble_Brick_Wall"
    },
    {
      "x": -6,
      "y": 4,
      "z": -5,
      "name": "Rock_Marble_Brick_Wall"
    },
    {
      "x": -6,
      "y": 5,
      "z": -5,
      "name": "Rock_Marble_Brick_Wall"
    },
    {
      "x": -6,
      "y": 6,
      "z": -5,
      "name": "Rock_Marble_Brick_Wall"
    },
    {
      "x": -6,
      "y": 7,
      "z": -5,
      "name": "Rock_Marble_Brick_Wall"
    },
    {
      "x": -6,
      "y": 8,
      "z": -5,
      "name": "Rock_Marble_Brick_Wall"
    },
    {
      "x": -6,
      "y": 9,
      "z": -5,
      "name": "Rock_Ice"
    },
    {
      "x": -6,
      "y": 10,
      "z": -5,
      "name": "Rock_Ice"
    },
    {
      "x": -6,
      "y": 11,
      "z": -5,
      "name": "Rock_Ice",
      "rotation": 1
    },
    {
      "x": -6,
      "y": 12,
      "z": -5,
      "name": "Rock_Ice_Permafrost",
      "rotation": 1
    },
    {
      "x": -6,
      "y": 13,
      "z": -5,
      "name": "Rock_Marble_Brick_Wall"
    },
    {
      "x": -6,
      "y": 14,
      "z": -5,
      "name": "Rock_Shale_Brick_Decorative"
    },
    {
      "x": -6,
      "y": 15,
      "z": -5,
      "name": "Rock_Marble_Brick_Wall"
    },
    {
      "x": -6,
      "y": 0,
      "z": -4,
      "name": "Rock_Ice_Permafrost",
      "rotation": 1
    },
    {
      "x": -6,
      "y": 1,
      "z": -4,
      "name": "Rock_Marble_Brick_Stairs",
      "rotation": 2
    },
    {
      "x": -6,
      "y": 10,
      "z": -4,
      "name": "Soil_Snow_Brick_Stairs",
      "rotation": 10
    },
    {
      "x": -6,
      "y": 11,
      "z": -4,
      "name": "Rock_Ice"
    },
    {
      "x": -6,
      "y": 12,
      "z": -4,
      "name": "Rock_Calcite_Brick_Stairs",
      "rotation": 2
    },
    {
      "x": -6,
      "y": 0,
      "z": -3,
      "name": "Rock_Ice",
      "rotation": 1
    },
    {
      "x": -6,
      "y": 1,
      "z": -3,
      "name": "Rock_Ice",
      "rotation": 1
    },
    {
      "x": -6,
      "y": 12,
      "z": -3,
      "name": "Rock_Calcite_Brick_Stairs",
      "rotation": 10
    },
    {
      "x": -6,
      "y": 13,
      "z": -3,
      "name": "Rock_Marble_Brick_Stairs",
      "rotation": 2
    },
    {
      "x": -6,
      "y": 0,
      "z": -2,
      "name": "Rock_Ice_Permafrost",
      "rotation": 1
    },
    {
      "x": -6,
      "y": 1,
      "z": -2,
      "name": "Rock_Ice_Permafrost",
      "rotation": 1
    },
    {
      "x": -6,
      "y": 0,
      "z": -1,
      "name": "Rock_Ice",
      "rotation": 1
    },
    {
      "x": -6,
      "y": 1,
      "z": -1,
      "name": "Rock_Ice_Permafrost",
      "rotation": 1
    },
    {
      "x": -6,
      "y": 0,
      "z": 0,
      "name": "Rock_Ice",
      "rotation": 1
    },
    {
      "x": -6,
      "y": 1,
      "z": 0,
      "name": "Cloth_Block_Wool_White",
      "rotation": 1
    },
    {
      "x": -6,
      "y": 0,
      "z": 1,
      "name": "Rock_Ice_Permafrost",
      "rotation": 1
    },
    {
      "x": -6,
      "y": 1,
      "z": 1,
      "name": "Rock_Ice",
      "rotation": 1
    },
    {
      "x": -6,
      "y": 0,
      "z": 2,
      "name": "Rock_Ice",
      "rotation": 1
    },
    {
      "x": -6,
      "y": 1,
      "z": 2,
      "name": "Rock_Ice_Permafrost",
      "rotation": 1
    },
    {
      "x": -6,
      "y": 1,
      "z": 3,
      "name": "Rock_Ice",
      "rotation": 1
    },
    {
      "x": -6,
      "y": 0,
      "z": 4,
      "name": "Rock_Ice",
      "rotation": 1
    },
    {
      "x": -6,
      "y": 1,
      "z": 4,
      "name": "Rock_Ice_Permafrost",
      "rotation": 1
    },
    {
      "x": -6,
      "y": 12,
      "z": 4,
      "name": "Rock_Marble_Brick_Stairs",
      "rotation": 8
    },
    {
      "x": -6,
      "y": 13,
      "z": 4,
      "name": "Rock_Calcite_Brick_Stairs"
    },
    {
      "x": -6,
      "y": 1,
      "z": 5,
      "name": "Soil_Snow_Brick_Stairs"
    },
    {
      "x": -6,
      "y": 10,
      "z": 5,
      "name": "Rock_Marble_Brick_Stairs",
      "rotation": 8
    },
    {
      "x": -6,
      "y": 11,
      "z": 5,
      "name": "Wood_Ice_Trunk"
    },
    {
      "x": -6,
      "y": 12,
      "z": 5,
      "name": "Soil_Snow_Brick_Stairs"
    },
    {
      "x": -6,
      "y": 0,
      "z": 6,
      "name": "Rock_Ice",
      "rotation": 1
    },
    {
      "x": -6,
      "y": 1,
      "z": 6,
      "name": "Rock_Ice_Permafrost",
      "rotation": 1
    },
    {
      "x": -6,
      "y": 2,
      "z": 6,
      "name": "Rock_Ice_Permafrost",
      "rotation": 1
    },
    {
      "x": -6,
      "y": 3,
      "z": 6,
      "name": "Rock_Marble_Brick_Wall"
    },
    {
      "x": -6,
      "y": 4,
      "z": 6,
      "name": "Rock_Marble_Brick_Wall"
    },
    {
      "x": -6,
      "y": 5,
      "z": 6,
      "name": "Rock_Marble_Brick_Wall"
    },
    {
      "x": -6,
      "y": 6,
      "z": 6,
      "name": "Rock_Marble_Brick_Wall"
    },
    {
      "x": -6,
      "y": 7,
      "z": 6,
      "name": "Rock_Marble_Brick_Wall"
    },
    {
      "x": -6,
      "y": 8,
      "z": 6,
      "name": "Rock_Marble_Brick_Wall"
    },
    {
      "x": -6,
      "y": 9,
      "z": 6,
      "name": "Rock_Ice"
    },
    {
      "x": -6,
      "y": 10,
      "z": 6,
      "name": "Rock_Ice",
      "rotation": 1
    },
    {
      "x": -6,
      "y": 11,
      "z": 6,
      "name": "Rock_Ice",
      "rotation": 1
    },
    {
      "x": -6,
      "y": 12,
      "z": 6,
      "name": "Rock_Ice"
    },
    {
      "x": -6,
      "y": 13,
      "z": 6,
      "name": "Rock_Marble_Brick_Wall"
    },
    {
      "x": -6,
      "y": 14,
      "z": 6,
      "name": "Rock_Shale_Brick_Decorative"
    },
    {
      "x": -6,
      "y": 15,
      "z": 6,
      "name": "Rock_Marble_Brick_Wall"
    },
    {
      "x": -6,
      "y": 2,
      "z": 7,
      "name": "Rock_Ice",
      "rotation": 1
    },
    {
      "x": -6,
      "y": 3,
      "z": 7,
      "name": "Rock_Ice",
      "rotation": 1
    },
    {
      "x": -6,
      "y": 4,
      "z": 7,
      "name": "Rock_Ice_Permafrost",
      "rotation": 1
    },
    {
      "x": -6,
      "y": 5,
      "z": 7,
      "name": "Rock_Ice",
      "rotation": 1
    },
    {
      "x": -6,
      "y": 6,
      "z": 7,
      "name": "Wood_Ice_Trunk",
      "rotation": 1
    },
    {
      "x": -6,
      "y": 7,
      "z": 7,
      "name": "Rock_Ice_Permafrost",
      "rotation": 1
    },
    {
      "x": -6,
      "y": 8,
      "z": 7,
      "name": "Wood_Ice_Trunk"
    },
    {
      "x": -6,
      "y": 9,
      "z": 7,
      "name": "Rock_Ice_Permafrost"
    },
    {
      "x": -6,
      "y": 10,
      "z": 7,
      "name": "Rock_Ice_Permafrost",
      "rotation": 1
    },
    {
      "x": -6,
      "y": 11,
      "z": 7,
      "name": "Rock_Ice_Permafrost",
      "rotation": 1
    },
    {
      "x": -6,
      "y": 12,
      "z": 7,
      "name": "Rock_Ice"
    },
    {
      "x": -6,
      "y": 13,
      "z": 7,
      "name": "Rock_Ice",
      "rotation": 1
    },
    {
      "x": -6,
      "y": 14,
      "z": 7,
      "name": "Soil_Snow",
      "support": 15
    },
    {
      "x": -6,
      "y": 0,
      "z": 8,
      "name": "Rock_Ice",
      "rotation": 1
    },
    {
      "x": -6,
      "y": 1,
      "z": 8,
      "name": "Rock_Ice_Permafrost"
    },
    {
      "x": -6,
      "y": 2,
      "z": 8,
      "name": "Wood_Ice_Trunk",
      "rotation": 1
    },
    {
      "x": -6,
      "y": 3,
      "z": 8,
      "name": "Wood_Ice_Trunk",
      "rotation": 1
    },
    {
      "x": -6,
      "y": 4,
      "z": 8,
      "name": "Wood_Ice_Trunk",
      "rotation": 1
    },
    {
      "x": -6,
      "y": 5,
      "z": 8,
      "name": "Rock_Ice",
      "rotation": 1
    },
    {
      "x": -6,
      "y": 6,
      "z": 8,
      "name": "Wood_Ice_Trunk",
      "rotation": 1
    },
    {
      "x": -6,
      "y": 7,
      "z": 8,
      "name": "Rock_Ice",
      "rotation": 1
    },
    {
      "x": -6,
      "y": 8,
      "z": 8,
      "name": "Rock_Ice_Permafrost"
    },
    {
      "x": -6,
      "y": 9,
      "z": 8,
      "name": "Rock_Ice_Permafrost"
    },
    {
      "x": -6,
      "y": 10,
      "z": 8,
      "name": "Rock_Ice",
      "rotation": 1
    },
    {
      "x": -6,
      "y": 11,
      "z": 8,
      "name": "Rock_Ice",
      "rotation": 1
    },
    {
      "x": -6,
      "y": 12,
      "z": 8,
      "name": "Wood_Ice_Trunk",
      "rotation": 1
    },
    {
      "x": -6,
      "y": 13,
      "z": 8,
      "name": "Rock_Ice_Permafrost",
      "rotation": 1
    },
    {
      "x": -6,
      "y": 14,
      "z": 8,
      "name": "Soil_Snow",
      "support": 15
    },
    {
      "x": -5,
      "y": 0,
      "z": -7,
      "name": "Rock_Ice",
      "rotation": 1
    },
    {
      "x": -5,
      "y": 1,
      "z": -7,
      "name": "Rock_Ice"
    },
    {
      "x": -5,
      "y": 2,
      "z": -7,
      "name": "Wood_Ice_Trunk",
      "rotation": 1
    },
    {
      "x": -5,
      "y": 3,
      "z": -7,
      "name": "Rock_Ice",
      "rotation": 1
    },
    {
      "x": -5,
      "y": 4,
      "z": -7,
      "name": "Rock_Ice",
      "rotation": 1
    },
    {
      "x": -5,
      "y": 5,
      "z": -7,
      "name": "Rock_Ice_Permafrost",
      "rotation": 1
    },
    {
      "x": -5,
      "y": 6,
      "z": -7,
      "name": "Rock_Ice_Permafrost",
      "rotation": 1
    },
    {
      "x": -5,
      "y": 7,
      "z": -7,
      "name": "Rock_Ice_Permafrost",
      "rotation": 1
    },
    {
      "x": -5,
      "y": 8,
      "z": -7,
      "name": "Rock_Ice"
    },
    {
      "x": -5,
      "y": 9,
      "z": -7,
      "name": "Rock_Ice"
    },
    {
      "x": -5,
      "y": 10,
      "z": -7,
      "name": "Rock_Ice"
    },
    {
      "x": -5,
      "y": 11,
      "z": -7,
      "name": "Rock_Ice_Permafrost",
      "rotation": 1
    },
    {
      "x": -5,
      "y": 12,
      "z": -7,
      "name": "Rock_Ice_Permafrost",
      "rotation": 1
    },
    {
      "x": -5,
      "y": 13,
      "z": -7,
      "name": "Rock_Marble_Brick_Wall",
      "rotation": 1
    },
    {
      "x": -5,
      "y": 14,
      "z": -7,
      "name": "Rock_Shale_Brick_Decorative"
    },
    {
      "x": -5,
      "y": 15,
      "z": -7,
      "name": "Rock_Marble_Brick_Wall",
      "rotation": 1
    },
    {
      "x": -5,
      "y": 0,
      "z": -6,
      "name": "Rock_Ice",
      "rotation": 1
    },
    {
      "x": -5,
      "y": 1,
      "z": -6,
      "name": "Rock_Ice_Permafrost",
      "rotation": 1
    },
    {
      "x": -5,
      "y": 2,
      "z": -6,
      "name": "Rock_Ice",
      "rotation": 1
    },
    {
      "x": -5,
      "y": 3,
      "z": -6,
      "name": "Rock_Marble_Brick_Wall",
      "rotation": 1
    },
    {
      "x": -5,
      "y": 4,
      "z": -6,
      "name": "Rock_Marble_Brick_Wall",
      "rotation": 1
    },
    {
      "x": -5,
      "y": 5,
      "z": -6,
      "name": "Rock_Marble_Brick_Wall",
      "rotation": 1
    },
    {
      "x": -5,
      "y": 6,
      "z": -6,
      "name": "Rock_Marble_Brick_Wall",
      "rotation": 1
    },
    {
      "x": -5,
      "y": 7,
      "z": -6,
      "name": "Rock_Marble_Brick_Wall",
      "rotation": 1
    },
    {
      "x": -5,
      "y": 8,
      "z": -6,
      "name": "Rock_Marble_Brick_Wall",
      "rotation": 1
    },
    {
      "x": -5,
      "y": 9,
      "z": -6,
      "name": "Rock_Ice"
    },
    {
      "x": -5,
      "y": 10,
      "z": -6,
      "name": "Rock_Ice"
    },
    {
      "x": -5,
      "y": 11,
      "z": -6,
      "name": "Rock_Ice",
      "rotation": 1
    },
    {
      "x": -5,
      "y": 12,
      "z": -6,
      "name": "Rock_Ice_Permafrost",
      "rotation": 1
    },
    {
      "x": -5,
      "y": 13,
      "z": -6,
      "name": "Rock_Marble_Brick_Wall",
      "rotation": 1
    },
    {
      "x": -5,
      "y": 14,
      "z": -6,
      "name": "Rock_Shale_Brick_Decorative"
    },
    {
      "x": -5,
      "y": 15,
      "z": -6,
      "name": "Rock_Marble_Brick_Wall",
      "rotation": 1
    },
    {
      "x": -5,
      "y": 0,
      "z": -5,
      "name": "Rock_Ice_Permafrost",
      "rotation": 1
    },
    {
      "x": -5,
      "y": 1,
      "z": -5,
      "name": "Rock_Ice_Permafrost",
      "rotation": 1
    },
    {
      "x": -5,
      "y": 2,
      "z": -5,
      "name": "Wood_Ice_Trunk",
      "rotation": 1
    },
    {
      "x": -5,
      "y": 3,
      "z": -5,
      "name": "Rock_Ice",
      "rotation": 1
    },
    {
      "x": -5,
      "y": 4,
      "z": -5,
      "name": "Rock_Ice_Permafrost",
      "rotation": 1
    },
    {
      "x": -5,
      "y": 5,
      "z": -5,
      "name": "Wood_Ice_Trunk",
      "rotation": 1
    },
    {
      "x": -5,
      "y": 6,
      "z": -5,
      "name": "Rock_Ice",
      "rotation": 1
    },
    {
      "x": -5,
      "y": 7,
      "z": -5,
      "name": "Rock_Ice",
      "rotation": 1
    },
    {
      "x": -5,
      "y": 8,
      "z": -5,
      "name": "Rock_Ice"
    },
    {
      "x": -5,
      "y": 9,
      "z": -5,
      "name": "Rock_Ice_Permafrost"
    },
    {
      "x": -5,
      "y": 10,
      "z": -5,
      "name": "Rock_Ice"
    },
    {
      "x": -5,
      "y": 11,
      "z": -5,
      "name": "Rock_Ice_Permafrost",
      "rotation": 1
    },
    {
      "x": -5,
      "y": 12,
      "z": -5,
      "name": "Rock_Ice",
      "rotation": 1
    },
    {
      "x": -5,
      "y": 13,
      "z": -5,
      "name": "*Rock_Marble_Brick_Wall_State_Definitions_Corner",
      "rotation": 3
    },
    {
      "x": -5,
      "y": 14,
      "z": -5,
      "name": "Rock_Shale_Brick_Decorative"
    },
    {
      "x": -5,
      "y": 15,
      "z": -5,
      "name": "*Rock_Marble_Brick_Wall_State_Definitions_Corner",
      "rotation": 3
    },
    {
      "x": -5,
      "y": 1,
      "z": -4,
      "name": "Rock_Marble_Brick_Stairs",
      "rotation": 2
    },
    {
      "x": -5,
      "y": 10,
      "z": -4,
      "name": "Rock_Marble_Brick_Stairs",
      "rotation": 10
    },
    {
      "x": -5,
      "y": 11,
      "z": -4,
      "name": "Rock_Ice_Permafrost"
    },
    {
      "x": -5,
      "y": 12,
      "z": -4,
      "name": "Rock_Calcite_Brick_Stairs",
      "rotation": 2
    },
    {
      "x": -5,
      "y": 0,
      "z": -3,
      "name": "Rock_Ice_Permafrost",
      "rotation": 1
    },
    {
      "x": -5,
      "y": 1,
      "z": -3,
      "name": "Rock_Ice",
      "rotation": 1
    },
    {
      "x": -5,
      "y": 12,
      "z": -3,
      "name": "Soil_Snow_Brick_Stairs",
      "rotation": 10
    },
    {
      "x": -5,
      "y": 13,
      "z": -3,
      "name": "Soil_Snow_Brick_Stairs",
      "rotation": 2
    },
    {
      "x": -5,
      "y": 1,
      "z": -2,
      "name": "Rock_Ice_Permafrost",
      "rotation": 1
    },
    {
      "x": -5,
      "y": 13,
      "z": -2,
      "name": "Soil_Snow_Brick_Beam",
      "rotation": 4
    },
    {
      "x": -5,
      "y": 0,
      "z": -1,
      "name": "Rock_Ice",
      "rotation": 1
    },
    {
      "x": -5,
      "y": 1,
      "z": -1,
      "name": "Rock_Ice",
      "rotation": 1
    },
    {
      "x": -5,
      "y": 13,
      "z": -1,
      "name": "Soil_Snow_Brick_Beam",
      "rotation": 4
    },
    {
      "x": -5,
      "y": 0,
      "z": 0,
      "name": "Rock_Ice_Permafrost",
      "rotation": 1
    },
    {
      "x": -5,
      "y": 1,
      "z": 0,
      "name": "Rock_Ice_Permafrost",
      "rotation": 1
    },
    {
      "x": -5,
      "y": 13,
      "z": 0,
      "name": "Soil_Snow_Brick_Beam",
      "rotation": 4
    },
    {
      "x": -5,
      "y": 0,
      "z": 1,
      "name": "Cloth_Block_Wool_White",
      "rotation": 1
    },
    {
      "x": -5,
      "y": 1,
      "z": 1,
      "name": "Rock_Ice",
      "rotation": 1
    },
    {
      "x": -5,
      "y": 13,
      "z": 1,
      "name": "Soil_Snow_Brick_Beam",
      "rotation": 4
    },
    {
      "x": -5,
      "y": 0,
      "z": 2,
      "name": "Rock_Ice",
      "rotation": 1
    },
    {
      "x": -5,
      "y": 1,
      "z": 2,
      "name": "Rock_Ice_Permafrost",
      "rotation": 1
    },
    {
      "x": -5,
      "y": 13,
      "z": 2,
      "name": "Soil_Snow_Brick_Beam",
      "rotation": 4
    },
    {
      "x": -5,
      "y": 0,
      "z": 3,
      "name": "Rock_Ice",
      "rotation": 1
    },
    {
      "x": -5,
      "y": 1,
      "z": 3,
      "name": "Rock_Ice",
      "rotation": 1
    },
    {
      "x": -5,
      "y": 13,
      "z": 3,
      "name": "Soil_Snow_Brick_Beam",
      "rotation": 4
    },
    {
      "x": -5,
      "y": 0,
      "z": 4,
      "name": "Rock_Ice_Permafrost",
      "rotation": 1
    },
    {
      "x": -5,
      "y": 1,
      "z": 4,
      "name": "Rock_Ice_Permafrost",
      "rotation": 1
    },
    {
      "x": -5,
      "y": 12,
      "z": 4,
      "name": "Soil_Snow_Brick_Stairs",
      "rotation": 8
    },
    {
      "x": -5,
      "y": 13,
      "z": 4,
      "name": "Soil_Snow_Brick_Stairs"
    },
    {
      "x": -5,
      "y": 0,
      "z": 5,
      "name": "Rock_Ice",
      "rotation": 1
    },
    {
      "x": -5,
      "y": 1,
      "z": 5,
      "name": "Rock_Calcite_Brick_Stairs"
    },
    {
      "x": -5,
      "y": 10,
      "z": 5,
      "name": "Rock_Marble_Brick_Stairs",
      "rotation": 8
    },
    {
      "x": -5,
      "y": 11,
      "z": 5,
      "name": "Rock_Ice"
    },
    {
      "x": -5,
      "y": 12,
      "z": 5,
      "name": "Soil_Snow_Brick_Stairs"
    },
    {
      "x": -5,
      "y": 1,
      "z": 6,
      "name": "Rock_Ice_Permafrost",
      "rotation": 1
    },
    {
      "x": -5,
      "y": 2,
      "z": 6,
      "name": "Rock_Ice",
      "rotation": 1
    },
    {
      "x": -5,
      "y": 3,
      "z": 6,
      "name": "Rock_Ice",
      "rotation": 1
    },
    {
      "x": -5,
      "y": 4,
      "z": 6,
      "name": "Rock_Ice",
      "rotation": 1
    },
    {
      "x": -5,
      "y": 5,
      "z": 6,
      "name": "Rock_Ice_Permafrost",
      "rotation": 1
    },
    {
      "x": -5,
      "y": 6,
      "z": 6,
      "name": "Rock_Ice_Permafrost",
      "rotation": 1
    },
    {
      "x": -5,
      "y": 7,
      "z": 6,
      "name": "Rock_Ice_Permafrost",
      "rotation": 1
    },
    {
      "x": -5,
      "y": 8,
      "z": 6,
      "name": "Rock_Ice"
    },
    {
      "x": -5,
      "y": 9,
      "z": 6,
      "name": "Rock_Ice_Permafrost"
    },
    {
      "x": -5,
      "y": 10,
      "z": 6,
      "name": "Rock_Ice_Permafrost",
      "rotation": 1
    },
    {
      "x": -5,
      "y": 11,
      "z": 6,
      "name": "Rock_Ice",
      "rotation": 1
    },
    {
      "x": -5,
      "y": 12,
      "z": 6,
      "name": "Rock_Ice_Permafrost"
    },
    {
      "x": -5,
      "y": 13,
      "z": 6,
      "name": "*Rock_Marble_Brick_Wall_State_Definitions_Corner"
    },
    {
      "x": -5,
      "y": 14,
      "z": 6,
      "name": "Rock_Shale_Brick_Decorative"
    },
    {
      "x": -5,
      "y": 15,
      "z": 6,
      "name": "*Rock_Marble_Brick_Wall_State_Definitions_Corner"
    },
    {
      "x": -5,
      "y": 0,
      "z": 7,
      "name": "Rock_Ice_Permafrost",
      "rotation": 1
    },
    {
      "x": -5,
      "y": 1,
      "z": 7,
      "name": "Rock_Ice_Permafrost",
      "rotation": 1
    },
    {
      "x": -5,
      "y": 2,
      "z": 7,
      "name": "Wood_Ice_Trunk",
      "rotation": 1
    },
    {
      "x": -5,
      "y": 3,
      "z": 7,
      "name": "Rock_Marble_Brick_Wall",
      "rotation": 1
    },
    {
      "x": -5,
      "y": 4,
      "z": 7,
      "name": "Rock_Marble_Brick_Wall",
      "rotation": 1
    },
    {
      "x": -5,
      "y": 5,
      "z": 7,
      "name": "Rock_Marble_Brick_Wall",
      "rotation": 1
    },
    {
      "x": -5,
      "y": 6,
      "z": 7,
      "name": "Rock_Marble_Brick_Wall",
      "rotation": 1
    },
    {
      "x": -5,
      "y": 7,
      "z": 7,
      "name": "Rock_Marble_Brick_Wall",
      "rotation": 1
    },
    {
      "x": -5,
      "y": 8,
      "z": 7,
      "name": "Rock_Marble_Brick_Wall",
      "rotation": 1
    },
    {
      "x": -5,
      "y": 9,
      "z": 7,
      "name": "Rock_Ice"
    },
    {
      "x": -5,
      "y": 10,
      "z": 7,
      "name": "Rock_Ice",
      "rotation": 1
    },
    {
      "x": -5,
      "y": 11,
      "z": 7,
      "name": "Wood_Ice_Trunk",
      "rotation": 1
    },
    {
      "x": -5,
      "y": 12,
      "z": 7,
      "name": "Rock_Ice"
    },
    {
      "x": -5,
      "y": 13,
      "z": 7,
      "name": "Rock_Marble_Brick_Wall",
      "rotation": 1
    },
    {
      "x": -5,
      "y": 14,
      "z": 7,
      "name": "Rock_Shale_Brick_Decorative"
    },
    {
      "x": -5,
      "y": 15,
      "z": 7,
      "name": "Rock_Marble_Brick_Wall",
      "rotation": 1
    },
    {
      "x": -5,
      "y": 0,
      "z": 8,
      "name": "Rock_Ice",
      "rotation": 1
    },
    {
      "x": -5,
      "y": 1,
      "z": 8,
      "name": "Rock_Ice_Permafrost"
    },
    {
      "x": -5,
      "y": 2,
      "z": 8,
      "name": "Wood_Ice_Trunk",
      "rotation": 1
    },
    {
      "x": -5,
      "y": 3,
      "z": 8,
      "name": "Rock_Ice_Permafrost",
      "rotation": 1
    },
    {
      "x": -5,
      "y": 4,
      "z": 8,
      "name": "Rock_Ice_Permafrost",
      "rotation": 1
    },
    {
      "x": -5,
      "y": 5,
      "z": 8,
      "name": "Rock_Ice",
      "rotation": 1
    },
    {
      "x": -5,
      "y": 6,
      "z": 8,
      "name": "Rock_Ice_Permafrost",
      "rotation": 1
    },
    {
      "x": -5,
      "y": 7,
      "z": 8,
      "name": "Rock_Ice",
      "rotation": 1
    },
    {
      "x": -5,
      "y": 8,
      "z": 8,
      "name": "Wood_Ice_Trunk"
    },
    {
      "x": -5,
      "y": 9,
      "z": 8,
      "name": "Rock_Ice_Permafrost"
    },
    {
      "x": -5,
      "y": 10,
      "z": 8,
      "name": "Rock_Ice_Permafrost",
      "rotation": 1
    },
    {
      "x": -5,
      "y": 11,
      "z": 8,
      "name": "Rock_Ice_Permafrost",
      "rotation": 1
    },
    {
      "x": -5,
      "y": 12,
      "z": 8,
      "name": "Rock_Ice"
    },
    {
      "x": -5,
      "y": 13,
      "z": 8,
      "name": "Rock_Marble_Brick_Wall",
      "rotation": 1
    },
    {
      "x": -5,
      "y": 14,
      "z": 8,
      "name": "Rock_Shale_Brick_Decorative"
    },
    {
      "x": -5,
      "y": 15,
      "z": 8,
      "name": "Rock_Marble_Brick_Wall",
      "rotation": 1
    },
    {
      "x": -4,
      "y": 0,
      "z": -7,
      "name": "Rock_Ice",
      "rotation": 1
    },
    {
      "x": -4,
      "y": 1,
      "z": -7,
      "name": "Rock_Marble_Brick_Stairs",
      "rotation": 3
    },
    {
      "x": -4,
      "y": 10,
      "z": -7,
      "name": "Rock_Marble_Brick_Stairs",
      "rotation": 11
    },
    {
      "x": -4,
      "y": 11,
      "z": -7,
      "name": "Rock_Ice_Permafrost",
      "rotation": 1
    },
    {
      "x": -4,
      "y": 12,
      "z": -7,
      "name": "Rock_Calcite_Brick_Stairs",
      "rotation": 3
    },
    {
      "x": -4,
      "y": 0,
      "z": -6,
      "name": "Rock_Ice_Permafrost",
      "rotation": 1
    },
    {
      "x": -4,
      "y": 1,
      "z": -6,
      "name": "Rock_Calcite_Brick_Stairs",
      "rotation": 3
    },
    {
      "x": -4,
      "y": 10,
      "z": -6,
      "name": "Rock_Marble_Brick_Stairs",
      "rotation": 11
    },
    {
      "x": -4,
      "y": 11,
      "z": -6,
      "name": "Rock_Ice",
      "rotation": 1
    },
    {
      "x": -4,
      "y": 12,
      "z": -6,
      "name": "Rock_Calcite_Brick_Stairs",
      "rotation": 3
    },
    {
      "x": -4,
      "y": 1,
      "z": -5,
      "name": "Rock_Marble_Brick_Stairs",
      "rotation": 3
    },
    {
      "x": -4,
      "y": 10,
      "z": -5,
      "name": "Rock_Marble_Brick_Stairs",
      "rotation": 11
    },
    {
      "x": -4,
      "y": 11,
      "z": -5,
      "name": "Rock_Ice_Permafrost",
      "rotation": 1
    },
    {
      "x": -4,
      "y": 12,
      "z": -5,
      "name": "Rock_Marble_Brick_Stairs",
      "rotation": 3
    },
    {
      "x": -4,
      "y": 0,
      "z": -4,
      "name": "Rock_Ice",
      "rotation": 1
    },
    {
      "x": -4,
      "y": 1,
      "z": -4,
      "name": "*Rock_Marble_Brick_Stairs_State_Definitions_Inverted_Corner_Right",
      "rotation": 3
    },
    {
      "x": -4,
      "y": 11,
      "z": -4,
      "name": "*Rock_Marble_Brick_Wall_State_Definitions_Corner",
      "rotation": 3
    },
    {
      "x": -4,
      "y": 1,
      "z": -3,
      "name": "Rock_Ice",
      "rotation": 1
    },
    {
      "x": -4,
      "y": 1,
      "z": -2,
      "name": "Rock_Ice",
      "rotation": 1
    },
    {
      "x": -4,
      "y": 0,
      "z": -1,
      "name": "Rock_Ice",
      "rotation": 1
    },
    {
      "x": -4,
      "y": 1,
      "z": -1,
      "name": "Rock_Ice",
      "rotation": 1
    },
    {
      "x": -4,
      "y": 0,
      "z": 0,
      "name": "Rock_Ice_Permafrost",
      "rotation": 1
    },
    {
      "x": -4,
      "y": 1,
      "z": 0,
      "name": "Rock_Ice",
      "rotation": 1
    },
    {
      "x": -4,
      "y": 0,
      "z": 1,
      "name": "Rock_Ice_Permafrost",
      "rotation": 1
    },
    {
      "x": -4,
      "y": 1,
      "z": 1,
      "name": "Cloth_Block_Wool_White",
      "rotation": 1
    },
    {
      "x": -4,
      "y": 0,
      "z": 2,
      "name": "Rock_Ice_Permafrost",
      "rotation": 1
    },
    {
      "x": -4,
      "y": 1,
      "z": 2,
      "name": "Cloth_Block_Wool_White",
      "rotation": 1
    },
    {
      "x": -4,
      "y": 0,
      "z": 3,
      "name": "Rock_Ice_Permafrost",
      "rotation": 1
    },
    {
      "x": -4,
      "y": 1,
      "z": 3,
      "name": "Rock_Ice_Permafrost",
      "rotation": 1
    },
    {
      "x": -4,
      "y": 0,
      "z": 4,
      "name": "Rock_Ice",
      "rotation": 1
    },
    {
      "x": -4,
      "y": 1,
      "z": 4,
      "name": "Rock_Ice",
      "rotation": 1
    },
    {
      "x": -4,
      "y": 0,
      "z": 5,
      "name": "Rock_Ice_Permafrost",
      "rotation": 1
    },
    {
      "x": -4,
      "y": 1,
      "z": 5,
      "name": "*Rock_Marble_Brick_Stairs_State_Definitions_Inverted_Corner_Right"
    },
    {
      "x": -4,
      "y": 11,
      "z": 5,
      "name": "*Rock_Marble_Brick_Wall_State_Definitions_Corner"
    },
    {
      "x": -4,
      "y": 0,
      "z": 6,
      "name": "Rock_Ice_Permafrost",
      "rotation": 1
    },
    {
      "x": -4,
      "y": 1,
      "z": 6,
      "name": "Soil_Snow_Brick_Stairs",
      "rotation": 3
    },
    {
      "x": -4,
      "y": 10,
      "z": 6,
      "name": "Soil_Snow_Brick_Stairs",
      "rotation": 11
    },
    {
      "x": -4,
      "y": 11,
      "z": 6,
      "name": "Rock_Ice_Permafrost",
      "rotation": 1
    },
    {
      "x": -4,
      "y": 12,
      "z": 6,
      "name": "Rock_Marble_Brick_Stairs",
      "rotation": 3
    },
    {
      "x": -4,
      "y": 0,
      "z": 7,
      "name": "Rock_Ice",
      "rotation": 1
    },
    {
      "x": -4,
      "y": 1,
      "z": 7,
      "name": "Soil_Snow_Brick_Stairs",
      "rotation": 3
    },
    {
      "x": -4,
      "y": 10,
      "z": 7,
      "name": "Rock_Calcite_Brick_Stairs",
      "rotation": 11
    },
    {
      "x": -4,
      "y": 11,
      "z": 7,
      "name": "Rock_Ice_Permafrost",
      "rotation": 1
    },
    {
      "x": -4,
      "y": 12,
      "z": 7,
      "name": "Soil_Snow_Brick_Stairs",
      "rotation": 3
    },
    {
      "x": -4,
      "y": 0,
      "z": 8,
      "name": "Rock_Ice",
      "rotation": 1
    },
    {
      "x": -4,
      "y": 1,
      "z": 8,
      "name": "Rock_Marble_Brick_Stairs",
      "rotation": 3
    },
    {
      "x": -4,
      "y": 10,
      "z": 8,
      "name": "Soil_Snow_Brick_Stairs",
      "rotation": 11
    },
    {
      "x": -4,
      "y": 11,
      "z": 8,
      "name": "Rock_Ice_Permafrost",
      "rotation": 1
    },
    {
      "x": -4,
      "y": 12,
      "z": 8,
      "name": "Rock_Marble_Brick_Stairs",
      "rotation": 3
    },
    {
      "x": -3,
      "y": 0,
      "z": -7,
      "name": "Rock_Ice",
      "rotation": 1
    },
    {
      "x": -3,
      "y": 1,
      "z": -7,
      "name": "Rock_Ice_Permafrost"
    },
    {
      "x": -3,
      "y": 12,
      "z": -7,
      "name": "Rock_Marble_Brick_Stairs",
      "rotation": 11
    },
    {
      "x": -3,
      "y": 13,
      "z": -7,
      "name": "Rock_Calcite_Brick_Stairs",
      "rotation": 3
    },
    {
      "x": -3,
      "y": 0,
      "z": -6,
      "name": "Rock_Ice",
      "rotation": 1
    },
    {
      "x": -3,
      "y": 1,
      "z": -6,
      "name": "Rock_Ice_Permafrost"
    },
    {
      "x": -3,
      "y": 12,
      "z": -6,
      "name": "Soil_Snow_Brick_Stairs",
      "rotation": 11
    },
    {
      "x": -3,
      "y": 13,
      "z": -6,
      "name": "Soil_Snow_Brick_Stairs",
      "rotation": 3
    },
    {
      "x": -3,
      "y": 1,
      "z": -5,
      "name": "Rock_Ice_Permafrost"
    },
    {
      "x": -3,
      "y": 12,
      "z": -5,
      "name": "Soil_Snow_Brick_Stairs",
      "rotation": 11
    },
    {
      "x": -3,
      "y": 13,
      "z": -5,
      "name": "Rock_Marble_Brick_Stairs",
      "rotation": 3
    },
    {
      "x": -3,
      "y": 0,
      "z": -4,
      "name": "Rock_Ice",
      "rotation": 1
    },
    {
      "x": -3,
      "y": 1,
      "z": -4,
      "name": "Rock_Ice"
    },
    {
      "x": -3,
      "y": 0,
      "z": -3,
      "name": "Rock_Ice_Permafrost",
      "rotation": 1
    },
    {
      "x": -3,
      "y": 1,
      "z": -3,
      "name": "Rock_Ice",
      "rotation": 1
    },
    {
      "x": -3,
      "y": 0,
      "z": -2,
      "name": "Rock_Ice_Permafrost",
      "rotation": 1
    },
    {
      "x": -3,
      "y": 1,
      "z": -2,
      "name": "Rock_Ice",
      "rotation": 1
    },
    {
      "x": -3,
      "y": 0,
      "z": -1,
      "name": "Rock_Ice",
      "rotation": 1
    },
    {
      "x": -3,
      "y": 1,
      "z": -1,
      "name": "Rock_Ice",
      "rotation": 1
    },
    {
      "x": -3,
      "y": 0,
      "z": 0,
      "name": "Rock_Ice_Permafrost",
      "rotation": 1
    },
    {
      "x": -3,
      "y": 1,
      "z": 0,
      "name": "Rock_Ice_Permafrost",
      "rotation": 1
    },
    {
      "x": -3,
      "y": 0,
      "z": 1,
      "name": "Rock_Ice_Permafrost",
      "rotation": 1
    },
    {
      "x": -3,
      "y": 1,
      "z": 1,
      "name": "Rock_Ice",
      "rotation": 1
    },
    {
      "x": -3,
      "y": 0,
      "z": 2,
      "name": "Rock_Ice_Permafrost",
      "rotation": 1
    },
    {
      "x": -3,
      "y": 1,
      "z": 2,
      "name": "Rock_Ice",
      "rotation": 1
    },
    {
      "x": -3,
      "y": 0,
      "z": 3,
      "name": "Rock_Ice_Permafrost",
      "rotation": 1
    },
    {
      "x": -3,
      "y": 1,
      "z": 3,
      "name": "Rock_Ice",
      "rotation": 1
    },
    {
      "x": -3,
      "y": 0,
      "z": 4,
      "name": "Rock_Ice",
      "rotation": 1
    },
    {
      "x": -3,
      "y": 1,
      "z": 4,
      "name": "Rock_Ice",
      "rotation": 1
    },
    {
      "x": -3,
      "y": 0,
      "z": 5,
      "name": "Rock_Ice_Permafrost",
      "rotation": 1
    },
    {
      "x": -3,
      "y": 1,
      "z": 5,
      "name": "Rock_Ice"
    },
    {
      "x": -3,
      "y": 0,
      "z": 6,
      "name": "Rock_Ice_Permafrost",
      "rotation": 1
    },
    {
      "x": -3,
      "y": 1,
      "z": 6,
      "name": "Rock_Ice_Permafrost"
    },
    {
      "x": -3,
      "y": 12,
      "z": 6,
      "name": "Soil_Snow_Brick_Stairs",
      "rotation": 11
    },
    {
      "x": -3,
      "y": 13,
      "z": 6,
      "name": "Soil_Snow_Brick_Stairs",
      "rotation": 3
    },
    {
      "x": -3,
      "y": 0,
      "z": 7,
      "name": "Rock_Ice",
      "rotation": 1
    },
    {
      "x": -3,
      "y": 1,
      "z": 7,
      "name": "Rock_Ice_Permafrost"
    },
    {
      "x": -3,
      "y": 12,
      "z": 7,
      "name": "Rock_Marble_Brick_Stairs",
      "rotation": 11
    },
    {
      "x": -3,
      "y": 13,
      "z": 7,
      "name": "Rock_Marble_Brick_Stairs",
      "rotation": 3
    },
    {
      "x": -3,
      "y": 0,
      "z": 8,
      "name": "Cloth_Block_Wool_White",
      "rotation": 1
    },
    {
      "x": -3,
      "y": 1,
      "z": 8,
      "name": "Rock_Ice"
    },
    {
      "x": -3,
      "y": 12,
      "z": 8,
      "name": "Rock_Marble_Brick_Stairs",
      "rotation": 11
    },
    {
      "x": -3,
      "y": 13,
      "z": 8,
      "name": "Rock_Marble_Brick_Stairs",
      "rotation": 3
    },
    {
      "x": -2,
      "y": 0,
      "z": -7,
      "name": "Rock_Ice",
      "rotation": 1
    },
    {
      "x": -2,
      "y": 1,
      "z": -7,
      "name": "Rock_Ice"
    },
    {
      "x": -2,
      "y": 13,
      "z": -7,
      "name": "Soil_Snow_Brick_Beam",
      "rotation": 5
    },
    {
      "x": -2,
      "y": 0,
      "z": -6,
      "name": "Rock_Ice_Permafrost",
      "rotation": 1
    },
    {
      "x": -2,
      "y": 1,
      "z": -6,
      "name": "Rock_Ice"
    },
    {
      "x": -2,
      "y": 0,
      "z": -5,
      "name": "Rock_Ice",
      "rotation": 1
    },
    {
      "x": -2,
      "y": 1,
      "z": -5,
      "name": "Rock_Ice"
    },
    {
      "x": -2,
      "y": 13,
      "z": -5,
      "name": "Soil_Snow_Brick_Beam",
      "rotation": 5
    },
    {
      "x": -2,
      "y": 0,
      "z": -4,
      "name": "Rock_Ice_Permafrost",
      "rotation": 1
    },
    {
      "x": -2,
      "y": 1,
      "z": -4,
      "name": "Rock_Ice"
    },
    {
      "x": -2,
      "y": 0,
      "z": -3,
      "name": "Rock_Ice_Permafrost",
      "rotation": 1
    },
    {
      "x": -2,
      "y": 1,
      "z": -3,
      "name": "Rock_Ice",
      "rotation": 1
    },
    {
      "x": -2,
      "y": 0,
      "z": -2,
      "name": "Rock_Ice_Permafrost",
      "rotation": 1
    },
    {
      "x": -2,
      "y": 1,
      "z": -2,
      "name": "Rock_Ice_Permafrost",
      "rotation": 1
    },
    {
      "x": -2,
      "y": 0,
      "z": -1,
      "name": "Rock_Ice_Permafrost",
      "rotation": 1
    },
    {
      "x": -2,
      "y": 1,
      "z": -1,
      "name": "Rock_Ice",
      "rotation": 1
    },
    {
      "x": -2,
      "y": 0,
      "z": 0,
      "name": "Rock_Ice",
      "rotation": 1
    },
    {
      "x": -2,
      "y": 1,
      "z": 0,
      "name": "Rock_Ice",
      "rotation": 1
    },
    {
      "x": -2,
      "y": 0,
      "z": 1,
      "name": "Rock_Ice",
      "rotation": 1
    },
    {
      "x": -2,
      "y": 1,
      "z": 1,
      "name": "Rock_Ice",
      "rotation": 1
    },
    {
      "x": -2,
      "y": 0,
      "z": 2,
      "name": "Rock_Ice_Permafrost",
      "rotation": 1
    },
    {
      "x": -2,
      "y": 1,
      "z": 2,
      "name": "Rock_Ice_Permafrost",
      "rotation": 1
    },
    {
      "x": -2,
      "y": 0,
      "z": 3,
      "name": "Rock_Ice",
      "rotation": 1
    },
    {
      "x": -2,
      "y": 1,
      "z": 3,
      "name": "Cloth_Block_Wool_White",
      "rotation": 1
    },
    {
      "x": -2,
      "y": 0,
      "z": 4,
      "name": "Rock_Ice",
      "rotation": 1
    },
    {
      "x": -2,
      "y": 1,
      "z": 4,
      "name": "Rock_Ice_Permafrost",
      "rotation": 1
    },
    {
      "x": -2,
      "y": 0,
      "z": 5,
      "name": "Rock_Ice",
      "rotation": 1
    },
    {
      "x": -2,
      "y": 1,
      "z": 5,
      "name": "Rock_Ice"
    },
    {
      "x": -2,
      "y": 0,
      "z": 6,
      "name": "Rock_Ice",
      "rotation": 1
    },
    {
      "x": -2,
      "y": 1,
      "z": 6,
      "name": "Rock_Ice"
    },
    {
      "x": -2,
      "y": 13,
      "z": 6,
      "name": "Soil_Snow_Brick_Beam",
      "rotation": 5
    },
    {
      "x": -2,
      "y": 0,
      "z": 7,
      "name": "Rock_Ice",
      "rotation": 1
    },
    {
      "x": -2,
      "y": 1,
      "z": 7,
      "name": "Rock_Ice"
    },
    {
      "x": -2,
      "y": 0,
      "z": 8,
      "name": "Cloth_Block_Wool_White",
      "rotation": 1
    },
    {
      "x": -2,
      "y": 1,
      "z": 8,
      "name": "Rock_Ice"
    },
    {
      "x": -2,
      "y": 13,
      "z": 8,
      "name": "Soil_Snow_Brick_Beam",
      "rotation": 5
    },
    {
      "x": -1,
      "y": 0,
      "z": -7,
      "name": "Cloth_Block_Wool_White",
      "rotation": 1
    },
    {
      "x": -1,
      "y": 1,
      "z": -7,
      "name": "Rock_Ice"
    },
    {
      "x": -1,
      "y": 13,
      "z": -7,
      "name": "Soil_Snow_Brick_Beam",
      "rotation": 5
    },
    {
      "x": -1,
      "y": 0,
      "z": -6,
      "name": "Rock_Ice_Permafrost",
      "rotation": 1
    },
    {
      "x": -1,
      "y": 1,
      "z": -6,
      "name": "Rock_Ice"
    },
    {
      "x": -1,
      "y": 0,
      "z": -5,
      "name": "Rock_Ice_Permafrost",
      "rotation": 1
    },
    {
      "x": -1,
      "y": 1,
      "z": -5,
      "name": "Rock_Ice_Permafrost"
    },
    {
      "x": -1,
      "y": 13,
      "z": -5,
      "name": "Soil_Snow_Brick_Beam",
      "rotation": 5
    },
    {
      "x": -1,
      "y": 0,
      "z": -4,
      "name": "Rock_Ice",
      "rotation": 1
    },
    {
      "x": -1,
      "y": 1,
      "z": -4,
      "name": "Rock_Ice"
    },
    {
      "x": -1,
      "y": 0,
      "z": -3,
      "name": "Rock_Ice",
      "rotation": 1
    },
    {
      "x": -1,
      "y": 1,
      "z": -3,
      "name": "Rock_Ice_Permafrost",
      "rotation": 1
    },
    {
      "x": -1,
      "y": 0,
      "z": -2,
      "name": "Rock_Ice_Permafrost",
      "rotation": 1
    },
    {
      "x": -1,
      "y": 1,
      "z": -2,
      "name": "Rock_Ice",
      "rotation": 1
    },
    {
      "x": -1,
      "y": 0,
      "z": -1,
      "name": "Rock_Ice_Permafrost",
      "rotation": 1
    },
    {
      "x": -1,
      "y": 1,
      "z": -1,
      "name": "Rock_Ice_Permafrost",
      "rotation": 1
    },
    {
      "x": -1,
      "y": 0,
      "z": 0,
      "name": "Rock_Ice_Permafrost",
      "rotation": 1
    },
    {
      "x": -1,
      "y": 1,
      "z": 0,
      "name": "Rock_Ice",
      "rotation": 1
    },
    {
      "x": -1,
      "y": 0,
      "z": 1,
      "name": "Rock_Ice",
      "rotation": 1
    },
    {
      "x": -1,
      "y": 1,
      "z": 1,
      "name": "Rock_Ice",
      "rotation": 1
    },
    {
      "x": -1,
      "y": 0,
      "z": 2,
      "name": "Rock_Ice_Permafrost",
      "rotation": 1
    },
    {
      "x": -1,
      "y": 1,
      "z": 2,
      "name": "Rock_Ice_Permafrost",
      "rotation": 1
    },
    {
      "x": -1,
      "y": 0,
      "z": 3,
      "name": "Rock_Ice_Permafrost",
      "rotation": 1
    },
    {
      "x": -1,
      "y": 1,
      "z": 3,
      "name": "Rock_Ice",
      "rotation": 1
    },
    {
      "x": -1,
      "y": 0,
      "z": 4,
      "name": "Rock_Ice_Permafrost",
      "rotation": 1
    },
    {
      "x": -1,
      "y": 1,
      "z": 4,
      "name": "Rock_Ice_Permafrost",
      "rotation": 1
    },
    {
      "x": -1,
      "y": 0,
      "z": 5,
      "name": "Rock_Ice",
      "rotation": 1
    },
    {
      "x": -1,
      "y": 1,
      "z": 5,
      "name": "Rock_Ice_Permafrost"
    },
    {
      "x": -1,
      "y": 0,
      "z": 6,
      "name": "Rock_Ice",
      "rotation": 1
    },
    {
      "x": -1,
      "y": 1,
      "z": 6,
      "name": "Rock_Ice_Permafrost"
    },
    {
      "x": -1,
      "y": 13,
      "z": 6,
      "name": "Soil_Snow_Brick_Beam",
      "rotation": 5
    },
    {
      "x": -1,
      "y": 0,
      "z": 7,
      "name": "Rock_Ice",
      "rotation": 1
    },
    {
      "x": -1,
      "y": 1,
      "z": 7,
      "name": "Rock_Ice"
    },
    {
      "x": -1,
      "y": 0,
      "z": 8,
      "name": "Rock_Ice",
      "rotation": 1
    },
    {
      "x": -1,
      "y": 1,
      "z": 8,
      "name": "Rock_Ice"
    },
    {
      "x": -1,
      "y": 13,
      "z": 8,
      "name": "Soil_Snow_Brick_Beam",
      "rotation": 5
    },
    {
      "x": 0,
      "y": 0,
      "z": -7,
      "name": "Rock_Ice",
      "rotation": 1
    },
    {
      "x": 0,
      "y": 1,
      "z": -7,
      "name": "Cloth_Block_Wool_White"
    },
    {
      "x": 0,
      "y": 13,
      "z": -7,
      "name": "Soil_Snow_Brick_Beam",
      "rotation": 5
    },
    {
      "x": 0,
      "y": 0,
      "z": -6,
      "name": "Rock_Ice_Permafrost",
      "rotation": 1
    },
    {
      "x": 0,
      "y": 1,
      "z": -6,
      "name": "Rock_Ice_Permafrost"
    },
    {
      "x": 0,
      "y": 0,
      "z": -5,
      "name": "Rock_Ice_Permafrost",
      "rotation": 1
    },
    {
      "x": 0,
      "y": 1,
      "z": -5,
      "name": "Rock_Ice_Permafrost"
    },
    {
      "x": 0,
      "y": 13,
      "z": -5,
      "name": "Soil_Snow_Brick_Beam",
      "rotation": 5
    },
    {
      "x": 0,
      "y": 0,
      "z": -4,
      "name": "Cloth_Block_Wool_White",
      "rotation": 1
    },
    {
      "x": 0,
      "y": 1,
      "z": -4,
      "name": "Cloth_Block_Wool_White"
    },
    {
      "x": 0,
      "y": 0,
      "z": -3,
      "name": "Rock_Ice",
      "rotation": 1
    },
    {
      "x": 0,
      "y": 1,
      "z": -3,
      "name": "Rock_Ice",
      "rotation": 1
    },
    {
      "x": 0,
      "y": 0,
      "z": -2,
      "name": "Rock_Ice_Permafrost",
      "rotation": 1
    },
    {
      "x": 0,
      "y": 1,
      "z": -2,
      "name": "Rock_Ice",
      "rotation": 1
    },
    {
      "x": 0,
      "y": 0,
      "z": -1,
      "name": "Cloth_Block_Wool_White",
      "rotation": 1
    },
    {
      "x": 0,
      "y": 1,
      "z": -1,
      "name": "Rock_Ice_Permafrost",
      "rotation": 1
    },
    {
      "x": 0,
      "y": 0,
      "z": 0,
      "name": "Rock_Ice_Permafrost",
      "rotation": 1
    },
    {
      "x": 0,
      "y": 1,
      "z": 0,
      "name": "Rock_Ice_Permafrost",
      "rotation": 1
    },
    {
      "x": 0,
      "y": 0,
      "z": 1,
      "name": "Rock_Ice_Permafrost",
      "rotation": 1
    },
    {
      "x": 0,
      "y": 1,
      "z": 1,
      "name": "Rock_Ice_Permafrost",
      "rotation": 1
    },
    {
      "x": 0,
      "y": 0,
      "z": 2,
      "name": "Rock_Ice_Permafrost",
      "rotation": 1
    },
    {
      "x": 0,
      "y": 1,
      "z": 2,
      "name": "Rock_Ice",
      "rotation": 1
    },
    {
      "x": 0,
      "y": 0,
      "z": 3,
      "name": "Rock_Ice",
      "rotation": 1
    },
    {
      "x": 0,
      "y": 1,
      "z": 3,
      "name": "Rock_Ice_Permafrost",
      "rotation": 1
    },
    {
      "x": 0,
      "y": 0,
      "z": 4,
      "name": "Rock_Ice_Permafrost",
      "rotation": 1
    },
    {
      "x": 0,
      "y": 1,
      "z": 4,
      "name": "Rock_Ice",
      "rotation": 1
    },
    {
      "x": 0,
      "y": 0,
      "z": 5,
      "name": "Rock_Ice_Permafrost",
      "rotation": 1
    },
    {
      "x": 0,
      "y": 1,
      "z": 5,
      "name": "Rock_Ice"
    },
    {
      "x": 0,
      "y": 0,
      "z": 6,
      "name": "Rock_Ice",
      "rotation": 1
    },
    {
      "x": 0,
      "y": 1,
      "z": 6,
      "name": "Rock_Ice"
    },
    {
      "x": 0,
      "y": 13,
      "z": 6,
      "name": "Soil_Snow_Brick_Beam",
      "rotation": 5
    },
    {
      "x": 0,
      "y": 0,
      "z": 7,
      "name": "Rock_Ice_Permafrost",
      "rotation": 1
    },
    {
      "x": 0,
      "y": 1,
      "z": 7,
      "name": "Rock_Ice"
    },
    {
      "x": 0,
      "y": 0,
      "z": 8,
      "name": "Rock_Ice",
      "rotation": 1
    },
    {
      "x": 0,
      "y": 1,
      "z": 8,
      "name": "Rock_Ice"
    },
    {
      "x": 0,
      "y": 13,
      "z": 8,
      "name": "Soil_Snow_Brick_Beam",
      "rotation": 5
    },
    {
      "x": 1,
      "y": 0,
      "z": -7,
      "name": "Rock_Ice",
      "rotation": 1
    },
    {
      "x": 1,
      "y": 1,
      "z": -7,
      "name": "Rock_Ice_Permafrost"
    },
    {
      "x": 1,
      "y": 13,
      "z": -7,
      "name": "Soil_Snow_Brick_Beam",
      "rotation": 5
    },
    {
      "x": 1,
      "y": 0,
      "z": -6,
      "name": "Rock_Ice",
      "rotation": 1
    },
    {
      "x": 1,
      "y": 1,
      "z": -6,
      "name": "Rock_Ice_Permafrost"
    },
    {
      "x": 1,
      "y": 0,
      "z": -5,
      "name": "Rock_Ice",
      "rotation": 1
    },
    {
      "x": 1,
      "y": 1,
      "z": -5,
      "name": "Cloth_Block_Wool_White"
    },
    {
      "x": 1,
      "y": 13,
      "z": -5,
      "name": "Soil_Snow_Brick_Beam",
      "rotation": 5
    },
    {
      "x": 1,
      "y": 0,
      "z": -4,
      "name": "Rock_Ice_Permafrost",
      "rotation": 1
    },
    {
      "x": 1,
      "y": 1,
      "z": -4,
      "name": "Rock_Ice"
    },
    {
      "x": 1,
      "y": 0,
      "z": -3,
      "name": "Rock_Ice",
      "rotation": 1
    },
    {
      "x": 1,
      "y": 1,
      "z": -3,
      "name": "Rock_Ice",
      "rotation": 1
    },
    {
      "x": 1,
      "y": 0,
      "z": -2,
      "name": "Rock_Ice",
      "rotation": 1
    },
    {
      "x": 1,
      "y": 1,
      "z": -2,
      "name": "Rock_Ice",
      "rotation": 1
    },
    {
      "x": 1,
      "y": 0,
      "z": -1,
      "name": "Rock_Ice_Permafrost",
      "rotation": 1
    },
    {
      "x": 1,
      "y": 1,
      "z": -1,
      "name": "Rock_Ice_Permafrost",
      "rotation": 1
    },
    {
      "x": 1,
      "y": 0,
      "z": 0,
      "name": "Rock_Ice",
      "rotation": 1
    },
    {
      "x": 1,
      "y": 1,
      "z": 0,
      "name": "Rock_Ice",
      "rotation": 1
    },
    {
      "x": 1,
      "y": 0,
      "z": 1,
      "name": "Rock_Ice",
      "rotation": 1
    },
    {
      "x": 1,
      "y": 1,
      "z": 1,
      "name": "Cloth_Block_Wool_White",
      "rotation": 1
    },
    {
      "x": 1,
      "y": 0,
      "z": 2,
      "name": "Rock_Ice",
      "rotation": 1
    },
    {
      "x": 1,
      "y": 1,
      "z": 2,
      "name": "Rock_Ice",
      "rotation": 1
    },
    {
      "x": 1,
      "y": 0,
      "z": 3,
      "name": "Rock_Ice_Permafrost",
      "rotation": 1
    },
    {
      "x": 1,
      "y": 1,
      "z": 3,
      "name": "Rock_Ice",
      "rotation": 1
    },
    {
      "x": 1,
      "y": 0,
      "z": 4,
      "name": "Rock_Ice",
      "rotation": 1
    },
    {
      "x": 1,
      "y": 1,
      "z": 4,
      "name": "Rock_Ice_Permafrost",
      "rotation": 1
    },
    {
      "x": 1,
      "y": 0,
      "z": 5,
      "name": "Rock_Ice_Permafrost",
      "rotation": 1
    },
    {
      "x": 1,
      "y": 1,
      "z": 5,
      "name": "Rock_Ice"
    },
    {
      "x": 1,
      "y": 0,
      "z": 6,
      "name": "Rock_Ice_Permafrost",
      "rotation": 1
    },
    {
      "x": 1,
      "y": 1,
      "z": 6,
      "name": "Rock_Ice"
    },
    {
      "x": 1,
      "y": 13,
      "z": 6,
      "name": "Soil_Snow_Brick_Beam",
      "rotation": 5
    },
    {
      "x": 1,
      "y": 0,
      "z": 7,
      "name": "Rock_Ice_Permafrost",
      "rotation": 1
    },
    {
      "x": 1,
      "y": 1,
      "z": 7,
      "name": "Cloth_Block_Wool_White"
    },
    {
      "x": 1,
      "y": 0,
      "z": 8,
      "name": "Rock_Ice",
      "rotation": 1
    },
    {
      "x": 1,
      "y": 1,
      "z": 8,
      "name": "Rock_Ice"
    },
    {
      "x": 1,
      "y": 13,
      "z": 8,
      "name": "Soil_Snow_Brick_Beam",
      "rotation": 5
    },
    {
      "x": 2,
      "y": 0,
      "z": -7,
      "name": "Rock_Ice_Permafrost",
      "rotation": 1
    },
    {
      "x": 2,
      "y": 1,
      "z": -7,
      "name": "Rock_Ice_Permafrost"
    },
    {
      "x": 2,
      "y": 13,
      "z": -7,
      "name": "Soil_Snow_Brick_Beam",
      "rotation": 5
    },
    {
      "x": 2,
      "y": 0,
      "z": -6,
      "name": "Rock_Ice_Permafrost",
      "rotation": 1
    },
    {
      "x": 2,
      "y": 1,
      "z": -6,
      "name": "Rock_Ice"
    },
    {
      "x": 2,
      "y": 0,
      "z": -5,
      "name": "Rock_Ice",
      "rotation": 1
    },
    {
      "x": 2,
      "y": 1,
      "z": -5,
      "name": "Rock_Ice_Permafrost"
    },
    {
      "x": 2,
      "y": 13,
      "z": -5,
      "name": "Soil_Snow_Brick_Beam",
      "rotation": 5
    },
    {
      "x": 2,
      "y": 0,
      "z": -4,
      "name": "Cloth_Block_Wool_White",
      "rotation": 1
    },
    {
      "x": 2,
      "y": 1,
      "z": -4,
      "name": "Rock_Ice"
    },
    {
      "x": 2,
      "y": 0,
      "z": -3,
      "name": "Rock_Ice",
      "rotation": 1
    },
    {
      "x": 2,
      "y": 1,
      "z": -3,
      "name": "Rock_Ice",
      "rotation": 1
    },
    {
      "x": 2,
      "y": 0,
      "z": -2,
      "name": "Rock_Ice_Permafrost",
      "rotation": 1
    },
    {
      "x": 2,
      "y": 1,
      "z": -2,
      "name": "Rock_Ice_Permafrost",
      "rotation": 1
    },
    {
      "x": 2,
      "y": 0,
      "z": -1,
      "name": "Rock_Ice_Permafrost",
      "rotation": 1
    },
    {
      "x": 2,
      "y": 1,
      "z": -1,
      "name": "Rock_Ice_Permafrost",
      "rotation": 1
    },
    {
      "x": 2,
      "y": 0,
      "z": 0,
      "name": "Rock_Ice",
      "rotation": 1
    },
    {
      "x": 2,
      "y": 1,
      "z": 0,
      "name": "Rock_Ice",
      "rotation": 1
    },
    {
      "x": 2,
      "y": 0,
      "z": 1,
      "name": "Rock_Ice",
      "rotation": 1
    },
    {
      "x": 2,
      "y": 1,
      "z": 1,
      "name": "Rock_Ice_Permafrost",
      "rotation": 1
    },
    {
      "x": 2,
      "y": 0,
      "z": 2,
      "name": "Rock_Ice",
      "rotation": 1
    },
    {
      "x": 2,
      "y": 1,
      "z": 2,
      "name": "Rock_Ice_Permafrost",
      "rotation": 1
    },
    {
      "x": 2,
      "y": 0,
      "z": 3,
      "name": "Rock_Ice",
      "rotation": 1
    },
    {
      "x": 2,
      "y": 1,
      "z": 3,
      "name": "Rock_Ice",
      "rotation": 1
    },
    {
      "x": 2,
      "y": 0,
      "z": 4,
      "name": "Rock_Ice_Permafrost",
      "rotation": 1
    },
    {
      "x": 2,
      "y": 1,
      "z": 4,
      "name": "Rock_Ice_Permafrost"
    },
    {
      "x": 2,
      "y": 0,
      "z": 5,
      "name": "Rock_Ice",
      "rotation": 1
    },
    {
      "x": 2,
      "y": 1,
      "z": 5,
      "name": "Rock_Ice_Permafrost"
    },
    {
      "x": 2,
      "y": 0,
      "z": 6,
      "name": "Rock_Ice",
      "rotation": 1
    },
    {
      "x": 2,
      "y": 1,
      "z": 6,
      "name": "Rock_Ice"
    },
    {
      "x": 2,
      "y": 13,
      "z": 6,
      "name": "Soil_Snow_Brick_Beam",
      "rotation": 5
    },
    {
      "x": 2,
      "y": 0,
      "z": 7,
      "name": "Rock_Ice_Permafrost",
      "rotation": 1
    },
    {
      "x": 2,
      "y": 1,
      "z": 7,
      "name": "Cloth_Block_Wool_White"
    },
    {
      "x": 2,
      "y": 0,
      "z": 8,
      "name": "Rock_Ice_Permafrost",
      "rotation": 1
    },
    {
      "x": 2,
      "y": 1,
      "z": 8,
      "name": "Rock_Ice"
    },
    {
      "x": 2,
      "y": 13,
      "z": 8,
      "name": "Soil_Snow_Brick_Beam",
      "rotation": 5
    },
    {
      "x": 3,
      "y": 0,
      "z": -7,
      "name": "Rock_Ice_Permafrost",
      "rotation": 1
    },
    {
      "x": 3,
      "y": 1,
      "z": -7,
      "name": "Rock_Ice"
    },
    {
      "x": 3,
      "y": 13,
      "z": -7,
      "name": "Soil_Snow_Brick_Beam",
      "rotation": 5
    },
    {
      "x": 3,
      "y": 0,
      "z": -6,
      "name": "Rock_Ice",
      "rotation": 1
    },
    {
      "x": 3,
      "y": 1,
      "z": -6,
      "name": "Rock_Ice"
    },
    {
      "x": 3,
      "y": 0,
      "z": -5,
      "name": "Rock_Ice",
      "rotation": 1
    },
    {
      "x": 3,
      "y": 1,
      "z": -5,
      "name": "Rock_Ice_Permafrost"
    },
    {
      "x": 3,
      "y": 13,
      "z": -5,
      "name": "Soil_Snow_Brick_Beam",
      "rotation": 5
    },
    {
      "x": 3,
      "y": 0,
      "z": -4,
      "name": "Rock_Ice",
      "rotation": 1
    },
    {
      "x": 3,
      "y": 1,
      "z": -4,
      "name": "Rock_Ice"
    },
    {
      "x": 3,
      "y": 0,
      "z": -3,
      "name": "Cloth_Block_Wool_White",
      "rotation": 1
    },
    {
      "x": 3,
      "y": 1,
      "z": -3,
      "name": "Rock_Ice_Permafrost",
      "rotation": 1
    },
    {
      "x": 3,
      "y": 0,
      "z": -2,
      "name": "Rock_Ice_Permafrost",
      "rotation": 1
    },
    {
      "x": 3,
      "y": 1,
      "z": -2,
      "name": "Cloth_Block_Wool_White",
      "rotation": 1
    },
    {
      "x": 3,
      "y": 0,
      "z": -1,
      "name": "Rock_Ice_Permafrost",
      "rotation": 1
    },
    {
      "x": 3,
      "y": 1,
      "z": -1,
      "name": "Rock_Ice",
      "rotation": 1
    },
    {
      "x": 3,
      "y": 0,
      "z": 0,
      "name": "Rock_Ice_Permafrost",
      "rotation": 1
    },
    {
      "x": 3,
      "y": 1,
      "z": 0,
      "name": "Rock_Ice",
      "rotation": 1
    },
    {
      "x": 3,
      "y": 0,
      "z": 1,
      "name": "Cloth_Block_Wool_White",
      "rotation": 1
    },
    {
      "x": 3,
      "y": 1,
      "z": 1,
      "name": "Cloth_Block_Wool_White",
      "rotation": 1
    },
    {
      "x": 3,
      "y": 0,
      "z": 2,
      "name": "Rock_Ice_Permafrost",
      "rotation": 1
    },
    {
      "x": 3,
      "y": 1,
      "z": 2,
      "name": "Rock_Ice_Permafrost",
      "rotation": 1
    },
    {
      "x": 3,
      "y": 0,
      "z": 3,
      "name": "Rock_Ice",
      "rotation": 1
    },
    {
      "x": 3,
      "y": 1,
      "z": 3,
      "name": "Rock_Ice_Permafrost",
      "rotation": 1
    },
    {
      "x": 3,
      "y": 0,
      "z": 4,
      "name": "Rock_Ice_Permafrost",
      "rotation": 1
    },
    {
      "x": 3,
      "y": 1,
      "z": 4,
      "name": "Rock_Ice_Permafrost"
    },
    {
      "x": 3,
      "y": 0,
      "z": 5,
      "name": "Rock_Ice_Permafrost",
      "rotation": 1
    },
    {
      "x": 3,
      "y": 1,
      "z": 5,
      "name": "Rock_Ice_Permafrost"
    },
    {
      "x": 3,
      "y": 0,
      "z": 6,
      "name": "Rock_Ice",
      "rotation": 1
    },
    {
      "x": 3,
      "y": 1,
      "z": 6,
      "name": "Rock_Ice"
    },
    {
      "x": 3,
      "y": 13,
      "z": 6,
      "name": "Soil_Snow_Brick_Beam",
      "rotation": 5
    },
    {
      "x": 3,
      "y": 0,
      "z": 7,
      "name": "Rock_Ice_Permafrost",
      "rotation": 1
    },
    {
      "x": 3,
      "y": 1,
      "z": 7,
      "name": "Rock_Ice"
    },
    {
      "x": 3,
      "y": 0,
      "z": 8,
      "name": "Cloth_Block_Wool_White",
      "rotation": 1
    },
    {
      "x": 3,
      "y": 1,
      "z": 8,
      "name": "Rock_Ice_Permafrost"
    },
    {
      "x": 3,
      "y": 13,
      "z": 8,
      "name": "Soil_Snow_Brick_Beam",
      "rotation": 5
    },
    {
      "x": 4,
      "y": 0,
      "z": -7,
      "name": "Rock_Ice",
      "rotation": 1
    },
    {
      "x": 4,
      "y": 1,
      "z": -7,
      "name": "Rock_Ice"
    },
    {
      "x": 4,
      "y": 12,
      "z": -7,
      "name": "Rock_Marble_Brick_Stairs",
      "rotation": 9
    },
    {
      "x": 4,
      "y": 13,
      "z": -7,
      "name": "Soil_Snow_Brick_Stairs",
      "rotation": 1
    },
    {
      "x": 4,
      "y": 0,
      "z": -6,
      "name": "Cloth_Block_Wool_White",
      "rotation": 1
    },
    {
      "x": 4,
      "y": 1,
      "z": -6,
      "name": "Rock_Ice"
    },
    {
      "x": 4,
      "y": 12,
      "z": -6,
      "name": "Rock_Marble_Brick_Stairs",
      "rotation": 9
    },
    {
      "x": 4,
      "y": 13,
      "z": -6,
      "name": "Soil_Snow_Brick_Stairs",
      "rotation": 1
    },
    {
      "x": 4,
      "y": 0,
      "z": -5,
      "name": "Rock_Ice_Permafrost",
      "rotation": 1
    },
    {
      "x": 4,
      "y": 1,
      "z": -5,
      "name": "Rock_Ice_Permafrost"
    },
    {
      "x": 4,
      "y": 12,
      "z": -5,
      "name": "Rock_Marble_Brick_Stairs",
      "rotation": 9
    },
    {
      "x": 4,
      "y": 13,
      "z": -5,
      "name": "Soil_Snow_Brick_Stairs",
      "rotation": 1
    },
    {
      "x": 4,
      "y": 0,
      "z": -4,
      "name": "Rock_Ice",
      "rotation": 1
    },
    {
      "x": 4,
      "y": 1,
      "z": -4,
      "name": "Rock_Ice_Permafrost"
    },
    {
      "x": 4,
      "y": 0,
      "z": -3,
      "name": "Rock_Ice",
      "rotation": 1
    },
    {
      "x": 4,
      "y": 1,
      "z": -3,
      "name": "Rock_Ice",
      "rotation": 1
    },
    {
      "x": 4,
      "y": 0,
      "z": -2,
      "name": "Rock_Ice_Permafrost",
      "rotation": 1
    },
    {
      "x": 4,
      "y": 1,
      "z": -2,
      "name": "Rock_Ice",
      "rotation": 1
    },
    {
      "x": 4,
      "y": 0,
      "z": -1,
      "name": "Rock_Ice_Permafrost",
      "rotation": 1
    },
    {
      "x": 4,
      "y": 1,
      "z": -1,
      "name": "Rock_Ice",
      "rotation": 1
    },
    {
      "x": 4,
      "y": 0,
      "z": 0,
      "name": "Rock_Ice_Permafrost",
      "rotation": 1
    },
    {
      "x": 4,
      "y": 1,
      "z": 0,
      "name": "Rock_Ice_Permafrost",
      "rotation": 1
    },
    {
      "x": 4,
      "y": 0,
      "z": 1,
      "name": "Rock_Ice",
      "rotation": 1
    },
    {
      "x": 4,
      "y": 1,
      "z": 1,
      "name": "Rock_Ice",
      "rotation": 1
    },
    {
      "x": 4,
      "y": 0,
      "z": 2,
      "name": "Rock_Ice_Permafrost",
      "rotation": 1
    },
    {
      "x": 4,
      "y": 1,
      "z": 2,
      "name": "Rock_Ice",
      "rotation": 1
    },
    {
      "x": 4,
      "y": 0,
      "z": 3,
      "name": "Rock_Ice_Permafrost",
      "rotation": 1
    },
    {
      "x": 4,
      "y": 1,
      "z": 3,
      "name": "Rock_Ice_Permafrost",
      "rotation": 1
    },
    {
      "x": 4,
      "y": 0,
      "z": 4,
      "name": "Rock_Ice_Permafrost",
      "rotation": 1
    },
    {
      "x": 4,
      "y": 1,
      "z": 4,
      "name": "Rock_Ice",
      "rotation": 1
    },
    {
      "x": 4,
      "y": 0,
      "z": 5,
      "name": "Rock_Ice_Permafrost",
      "rotation": 1
    },
    {
      "x": 4,
      "y": 1,
      "z": 5,
      "name": "Rock_Ice_Permafrost"
    },
    {
      "x": 4,
      "y": 0,
      "z": 6,
      "name": "Rock_Ice",
      "rotation": 1
    },
    {
      "x": 4,
      "y": 1,
      "z": 6,
      "name": "Rock_Ice_Permafrost"
    },
    {
      "x": 4,
      "y": 12,
      "z": 6,
      "name": "Rock_Marble_Brick_Stairs",
      "rotation": 9
    },
    {
      "x": 4,
      "y": 13,
      "z": 6,
      "name": "Rock_Marble_Brick_Stairs",
      "rotation": 1
    },
    {
      "x": 4,
      "y": 0,
      "z": 7,
      "name": "Rock_Ice_Permafrost",
      "rotation": 1
    },
    {
      "x": 4,
      "y": 1,
      "z": 7,
      "name": "Rock_Ice"
    },
    {
      "x": 4,
      "y": 12,
      "z": 7,
      "name": "Rock_Marble_Brick_Stairs",
      "rotation": 9
    },
    {
      "x": 4,
      "y": 13,
      "z": 7,
      "name": "Rock_Marble_Brick_Stairs",
      "rotation": 1
    },
    {
      "x": 4,
      "y": 0,
      "z": 8,
      "name": "Rock_Ice_Permafrost",
      "rotation": 1
    },
    {
      "x": 4,
      "y": 1,
      "z": 8,
      "name": "Rock_Ice_Permafrost"
    },
    {
      "x": 4,
      "y": 12,
      "z": 8,
      "name": "Soil_Snow_Brick_Stairs",
      "rotation": 9
    },
    {
      "x": 4,
      "y": 13,
      "z": 8,
      "name": "Rock_Marble_Brick_Stairs",
      "rotation": 1
    },
    {
      "x": 5,
      "y": 0,
      "z": -7,
      "name": "Rock_Ice_Permafrost",
      "rotation": 1
    },
    {
      "x": 5,
      "y": 1,
      "z": -7,
      "name": "Rock_Calcite_Brick_Stairs",
      "rotation": 1
    },
    {
      "x": 5,
      "y": 10,
      "z": -7,
      "name": "Rock_Marble_Brick_Stairs",
      "rotation": 9
    },
    {
      "x": 5,
      "y": 11,
      "z": -7,
      "name": "Wood_Ice_Trunk",
      "rotation": 1
    },
    {
      "x": 5,
      "y": 12,
      "z": -7,
      "name": "Rock_Marble_Brick_Stairs",
      "rotation": 1
    },
    {
      "x": 5,
      "y": 0,
      "z": -6,
      "name": "Rock_Ice",
      "rotation": 1
    },
    {
      "x": 5,
      "y": 1,
      "z": -6,
      "name": "Soil_Snow_Brick_Stairs",
      "rotation": 1
    },
    {
      "x": 5,
      "y": 10,
      "z": -6,
      "name": "Rock_Marble_Brick_Stairs",
      "rotation": 9
    },
    {
      "x": 5,
      "y": 11,
      "z": -6,
      "name": "Rock_Ice_Permafrost",
      "rotation": 1
    },
    {
      "x": 5,
      "y": 12,
      "z": -6,
      "name": "Rock_Marble_Brick_Stairs",
      "rotation": 1
    },
    {
      "x": 5,
      "y": 0,
      "z": -5,
      "name": "Rock_Ice_Permafrost",
      "rotation": 1
    },
    {
      "x": 5,
      "y": 1,
      "z": -5,
      "name": "Rock_Marble_Brick_Stairs",
      "rotation": 1
    },
    {
      "x": 5,
      "y": 10,
      "z": -5,
      "name": "Soil_Snow_Brick_Stairs",
      "rotation": 9
    },
    {
      "x": 5,
      "y": 11,
      "z": -5,
      "name": "Rock_Ice",
      "rotation": 1
    },
    {
      "x": 5,
      "y": 12,
      "z": -5,
      "name": "Soil_Snow_Brick_Stairs",
      "rotation": 1
    },
    {
      "x": 5,
      "y": 0,
      "z": -4,
      "name": "Rock_Ice_Permafrost",
      "rotation": 1
    },
    {
      "x": 5,
      "y": 1,
      "z": -4,
      "name": "*Rock_Marble_Brick_Stairs_State_Definitions_Inverted_Corner_Left",
      "rotation": 1
    },
    {
      "x": 5,
      "y": 11,
      "z": -4,
      "name": "*Rock_Marble_Brick_Wall_State_Definitions_Corner",
      "rotation": 2
    },
    {
      "x": 5,
      "y": 0,
      "z": -3,
      "name": "Rock_Ice_Permafrost",
      "rotation": 1
    },
    {
      "x": 5,
      "y": 1,
      "z": -3,
      "name": "Rock_Ice",
      "rotation": 1
    },
    {
      "x": 5,
      "y": 0,
      "z": -2,
      "name": "Rock_Ice",
      "rotation": 1
    },
    {
      "x": 5,
      "y": 1,
      "z": -2,
      "name": "Rock_Ice_Permafrost",
      "rotation": 1
    },
    {
      "x": 5,
      "y": 0,
      "z": -1,
      "name": "Rock_Ice_Permafrost",
      "rotation": 1
    },
    {
      "x": 5,
      "y": 1,
      "z": -1,
      "name": "Rock_Ice_Permafrost",
      "rotation": 1
    },
    {
      "x": 5,
      "y": 0,
      "z": 0,
      "name": "Rock_Ice_Permafrost",
      "rotation": 1
    },
    {
      "x": 5,
      "y": 1,
      "z": 0,
      "name": "Cloth_Block_Wool_White",
      "rotation": 1
    },
    {
      "x": 5,
      "y": 0,
      "z": 1,
      "name": "Rock_Ice_Permafrost",
      "rotation": 1
    },
    {
      "x": 5,
      "y": 1,
      "z": 1,
      "name": "Rock_Ice_Permafrost",
      "rotation": 1
    },
    {
      "x": 5,
      "y": 0,
      "z": 2,
      "name": "Rock_Ice",
      "rotation": 1
    },
    {
      "x": 5,
      "y": 1,
      "z": 2,
      "name": "Rock_Ice",
      "rotation": 1
    },
    {
      "x": 5,
      "y": 0,
      "z": 3,
      "name": "Rock_Ice",
      "rotation": 1
    },
    {
      "x": 5,
      "y": 1,
      "z": 3,
      "name": "Cloth_Block_Wool_White",
      "rotation": 1
    },
    {
      "x": 5,
      "y": 1,
      "z": 4,
      "name": "Rock_Ice_Permafrost",
      "rotation": 1
    },
    {
      "x": 5,
      "y": 0,
      "z": 5,
      "name": "Rock_Ice_Permafrost",
      "rotation": 1
    },
    {
      "x": 5,
      "y": 1,
      "z": 5,
      "name": "*Rock_Marble_Brick_Stairs_State_Definitions_Inverted_Corner_Left"
    },
    {
      "x": 5,
      "y": 11,
      "z": 5,
      "name": "*Rock_Marble_Brick_Wall_State_Definitions_Corner",
      "rotation": 1
    },
    {
      "x": 5,
      "y": 0,
      "z": 6,
      "name": "Rock_Ice_Permafrost",
      "rotation": 1
    },
    {
      "x": 5,
      "y": 1,
      "z": 6,
      "name": "Rock_Marble_Brick_Stairs",
      "rotation": 1
    },
    {
      "x": 5,
      "y": 10,
      "z": 6,
      "name": "Soil_Snow_Brick_Stairs",
      "rotation": 9
    },
    {
      "x": 5,
      "y": 11,
      "z": 6,
      "name": "Rock_Ice_Permafrost",
      "rotation": 1
    },
    {
      "x": 5,
      "y": 12,
      "z": 6,
      "name": "Soil_Snow_Brick_Stairs",
      "rotation": 1
    },
    {
      "x": 5,
      "y": 0,
      "z": 7,
      "name": "Rock_Ice",
      "rotation": 1
    },
    {
      "x": 5,
      "y": 1,
      "z": 7,
      "name": "Rock_Marble_Brick_Stairs",
      "rotation": 1
    },
    {
      "x": 5,
      "y": 10,
      "z": 7,
      "name": "Rock_Marble_Brick_Stairs",
      "rotation": 9
    },
    {
      "x": 5,
      "y": 11,
      "z": 7,
      "name": "Wood_Ice_Trunk",
      "rotation": 1
    },
    {
      "x": 5,
      "y": 12,
      "z": 7,
      "name": "Rock_Marble_Brick_Stairs",
      "rotation": 1
    },
    {
      "x": 5,
      "y": 0,
      "z": 8,
      "name": "Rock_Ice",
      "rotation": 1
    },
    {
      "x": 5,
      "y": 1,
      "z": 8,
      "name": "Rock_Marble_Brick_Stairs",
      "rotation": 1
    },
    {
      "x": 5,
      "y": 10,
      "z": 8,
      "name": "Rock_Calcite_Brick_Stairs",
      "rotation": 9
    },
    {
      "x": 5,
      "y": 11,
      "z": 8,
      "name": "Rock_Ice",
      "rotation": 1
    },
    {
      "x": 5,
      "y": 12,
      "z": 8,
      "name": "Rock_Marble_Brick_Stairs",
      "rotation": 1
    },
    {
      "x": 6,
      "y": 0,
      "z": -7,
      "name": "Rock_Ice",
      "rotation": 1
    },
    {
      "x": 6,
      "y": 1,
      "z": -7,
      "name": "Rock_Ice"
    },
    {
      "x": 6,
      "y": 2,
      "z": -7,
      "name": "Rock_Ice_Permafrost",
      "rotation": 1
    },
    {
      "x": 6,
      "y": 3,
      "z": -7,
      "name": "Rock_Ice_Permafrost",
      "rotation": 1
    },
    {
      "x": 6,
      "y": 4,
      "z": -7,
      "name": "Rock_Ice",
      "rotation": 1
    },
    {
      "x": 6,
      "y": 5,
      "z": -7,
      "name": "Rock_Ice",
      "rotation": 1
    },
    {
      "x": 6,
      "y": 6,
      "z": -7,
      "name": "Wood_Ice_Trunk",
      "rotation": 1
    },
    {
      "x": 6,
      "y": 7,
      "z": -7,
      "name": "Rock_Ice_Permafrost",
      "rotation": 1
    },
    {
      "x": 6,
      "y": 8,
      "z": -7,
      "name": "Rock_Ice_Permafrost"
    },
    {
      "x": 6,
      "y": 9,
      "z": -7,
      "name": "Rock_Ice"
    },
    {
      "x": 6,
      "y": 10,
      "z": -7,
      "name": "Rock_Ice",
      "rotation": 1
    },
    {
      "x": 6,
      "y": 11,
      "z": -7,
      "name": "Rock_Ice_Permafrost",
      "rotation": 1
    },
    {
      "x": 6,
      "y": 12,
      "z": -7,
      "name": "Rock_Ice",
      "rotation": 1
    },
    {
      "x": 6,
      "y": 13,
      "z": -7,
      "name": "Rock_Marble_Brick_Wall",
      "rotation": 3
    },
    {
      "x": 6,
      "y": 14,
      "z": -7,
      "name": "Rock_Shale_Brick_Decorative",
      "rotation": 3
    },
    {
      "x": 6,
      "y": 15,
      "z": -7,
      "name": "Rock_Marble_Brick_Wall",
      "rotation": 1
    },
    {
      "x": 6,
      "y": 0,
      "z": -6,
      "name": "Cloth_Block_Wool_White",
      "rotation": 1
    },
    {
      "x": 6,
      "y": 1,
      "z": -6,
      "name": "Rock_Ice_Permafrost",
      "rotation": 1
    },
    {
      "x": 6,
      "y": 2,
      "z": -6,
      "name": "Rock_Ice",
      "rotation": 1
    },
    {
      "x": 6,
      "y": 3,
      "z": -6,
      "name": "Rock_Marble_Brick_Wall",
      "rotation": 1
    },
    {
      "x": 6,
      "y": 4,
      "z": -6,
      "name": "Rock_Marble_Brick_Wall",
      "rotation": 1
    },
    {
      "x": 6,
      "y": 5,
      "z": -6,
      "name": "Rock_Marble_Brick_Wall",
      "rotation": 1
    },
    {
      "x": 6,
      "y": 6,
      "z": -6,
      "name": "Rock_Marble_Brick_Wall",
      "rotation": 1
    },
    {
      "x": 6,
      "y": 7,
      "z": -6,
      "name": "Rock_Marble_Brick_Wall",
      "rotation": 1
    },
    {
      "x": 6,
      "y": 8,
      "z": -6,
      "name": "Rock_Marble_Brick_Wall",
      "rotation": 1
    },
    {
      "x": 6,
      "y": 9,
      "z": -6,
      "name": "Rock_Ice"
    },
    {
      "x": 6,
      "y": 10,
      "z": -6,
      "name": "Rock_Ice_Permafrost",
      "rotation": 1
    },
    {
      "x": 6,
      "y": 11,
      "z": -6,
      "name": "Rock_Ice_Permafrost",
      "rotation": 1
    },
    {
      "x": 6,
      "y": 12,
      "z": -6,
      "name": "Rock_Ice",
      "rotation": 1
    },
    {
      "x": 6,
      "y": 13,
      "z": -6,
      "name": "Rock_Marble_Brick_Wall",
      "rotation": 3
    },
    {
      "x": 6,
      "y": 14,
      "z": -6,
      "name": "Rock_Shale_Brick_Decorative",
      "rotation": 3
    },
    {
      "x": 6,
      "y": 15,
      "z": -6,
      "name": "Rock_Marble_Brick_Wall",
      "rotation": 1
    },
    {
      "x": 6,
      "y": 0,
      "z": -5,
      "name": "Rock_Ice",
      "rotation": 1
    },
    {
      "x": 6,
      "y": 1,
      "z": -5,
      "name": "Rock_Ice",
      "rotation": 1
    },
    {
      "x": 6,
      "y": 2,
      "z": -5,
      "name": "Rock_Ice",
      "rotation": 1
    },
    {
      "x": 6,
      "y": 3,
      "z": -5,
      "name": "Wood_Ice_Trunk",
      "rotation": 1
    },
    {
      "x": 6,
      "y": 4,
      "z": -5,
      "name": "Rock_Ice",
      "rotation": 1
    },
    {
      "x": 6,
      "y": 5,
      "z": -5,
      "name": "Rock_Ice",
      "rotation": 1
    },
    {
      "x": 6,
      "y": 6,
      "z": -5,
      "name": "Rock_Ice_Permafrost",
      "rotation": 1
    },
    {
      "x": 6,
      "y": 7,
      "z": -5,
      "name": "Wood_Ice_Trunk",
      "rotation": 1
    },
    {
      "x": 6,
      "y": 8,
      "z": -5,
      "name": "Rock_Ice"
    },
    {
      "x": 6,
      "y": 9,
      "z": -5,
      "name": "Rock_Ice"
    },
    {
      "x": 6,
      "y": 10,
      "z": -5,
      "name": "Rock_Ice",
      "rotation": 1
    },
    {
      "x": 6,
      "y": 11,
      "z": -5,
      "name": "Rock_Ice_Permafrost",
      "rotation": 1
    },
    {
      "x": 6,
      "y": 12,
      "z": -5,
      "name": "Rock_Ice",
      "rotation": 1
    },
    {
      "x": 6,
      "y": 13,
      "z": -5,
      "name": "*Rock_Marble_Brick_Wall_State_Definitions_Corner",
      "rotation": 2
    },
    {
      "x": 6,
      "y": 14,
      "z": -5,
      "name": "Rock_Shale_Brick_Decorative",
      "rotation": 3
    },
    {
      "x": 6,
      "y": 15,
      "z": -5,
      "name": "*Rock_Marble_Brick_Wall_State_Definitions_Corner",
      "rotation": 2
    },
    {
      "x": 6,
      "y": 0,
      "z": -4,
      "name": "Rock_Ice_Permafrost",
      "rotation": 1
    },
    {
      "x": 6,
      "y": 1,
      "z": -4,
      "name": "Rock_Marble_Brick_Stairs",
      "rotation": 2
    },
    {
      "x": 6,
      "y": 10,
      "z": -4,
      "name": "Soil_Snow_Brick_Stairs",
      "rotation": 10
    },
    {
      "x": 6,
      "y": 11,
      "z": -4,
      "name": "Rock_Ice"
    },
    {
      "x": 6,
      "y": 12,
      "z": -4,
      "name": "Soil_Snow_Brick_Stairs",
      "rotation": 2
    },
    {
      "x": 6,
      "y": 1,
      "z": -3,
      "name": "Rock_Ice",
      "rotation": 1
    },
    {
      "x": 6,
      "y": 12,
      "z": -3,
      "name": "Soil_Snow_Brick_Stairs",
      "rotation": 10
    },
    {
      "x": 6,
      "y": 13,
      "z": -3,
      "name": "Soil_Snow_Brick_Stairs",
      "rotation": 2
    },
    {
      "x": 6,
      "y": 1,
      "z": -2,
      "name": "Rock_Ice_Permafrost",
      "rotation": 1
    },
    {
      "x": 6,
      "y": 13,
      "z": -2,
      "name": "Soil_Snow_Brick_Beam",
      "rotation": 4
    },
    {
      "x": 6,
      "y": 0,
      "z": -1,
      "name": "Rock_Ice_Permafrost",
      "rotation": 1
    },
    {
      "x": 6,
      "y": 1,
      "z": -1,
      "name": "Cloth_Block_Wool_White",
      "rotation": 1
    },
    {
      "x": 6,
      "y": 13,
      "z": -1,
      "name": "Soil_Snow_Brick_Beam",
      "rotation": 4
    },
    {
      "x": 6,
      "y": 0,
      "z": 0,
      "name": "Rock_Ice",
      "rotation": 1
    },
    {
      "x": 6,
      "y": 1,
      "z": 0,
      "name": "Cloth_Block_Wool_White",
      "rotation": 1
    },
    {
      "x": 6,
      "y": 13,
      "z": 0,
      "name": "Soil_Snow_Brick_Beam",
      "rotation": 4
    },
    {
      "x": 6,
      "y": 0,
      "z": 1,
      "name": "Rock_Ice",
      "rotation": 1
    },
    {
      "x": 6,
      "y": 1,
      "z": 1,
      "name": "Rock_Ice_Permafrost",
      "rotation": 1
    },
    {
      "x": 6,
      "y": 13,
      "z": 1,
      "name": "Soil_Snow_Brick_Beam",
      "rotation": 4
    },
    {
      "x": 6,
      "y": 0,
      "z": 2,
      "name": "Rock_Ice_Permafrost",
      "rotation": 1
    },
    {
      "x": 6,
      "y": 1,
      "z": 2,
      "name": "Rock_Ice_Permafrost",
      "rotation": 1
    },
    {
      "x": 6,
      "y": 13,
      "z": 2,
      "name": "Soil_Snow_Brick_Beam",
      "rotation": 4
    },
    {
      "x": 6,
      "y": 0,
      "z": 3,
      "name": "Rock_Ice",
      "rotation": 1
    },
    {
      "x": 6,
      "y": 1,
      "z": 3,
      "name": "Rock_Ice_Permafrost",
      "rotation": 1
    },
    {
      "x": 6,
      "y": 13,
      "z": 3,
      "name": "Soil_Snow_Brick_Beam",
      "rotation": 4
    },
    {
      "x": 6,
      "y": 1,
      "z": 4,
      "name": "Rock_Ice_Permafrost",
      "rotation": 1
    },
    {
      "x": 6,
      "y": 12,
      "z": 4,
      "name": "Rock_Marble_Brick_Stairs",
      "rotation": 8
    },
    {
      "x": 6,
      "y": 13,
      "z": 4,
      "name": "Soil_Snow_Brick_Stairs"
    },
    {
      "x": 6,
      "y": 0,
      "z": 5,
      "name": "Rock_Ice_Permafrost",
      "rotation": 1
    },
    {
      "x": 6,
      "y": 1,
      "z": 5,
      "name": "Soil_Snow_Brick_Stairs"
    },
    {
      "x": 6,
      "y": 10,
      "z": 5,
      "name": "Rock_Marble_Brick_Stairs",
      "rotation": 8
    },
    {
      "x": 6,
      "y": 11,
      "z": 5,
      "name": "Rock_Ice_Permafrost"
    },
    {
      "x": 6,
      "y": 12,
      "z": 5,
      "name": "Rock_Marble_Brick_Stairs"
    },
    {
      "x": 6,
      "y": 0,
      "z": 6,
      "name": "Rock_Ice",
      "rotation": 1
    },
    {
      "x": 6,
      "y": 1,
      "z": 6,
      "name": "Rock_Ice_Permafrost",
      "rotation": 1
    },
    {
      "x": 6,
      "y": 2,
      "z": 6,
      "name": "Rock_Ice_Permafrost",
      "rotation": 1
    },
    {
      "x": 6,
      "y": 3,
      "z": 6,
      "name": "Rock_Ice",
      "rotation": 1
    },
    {
      "x": 6,
      "y": 4,
      "z": 6,
      "name": "Wood_Ice_Trunk",
      "rotation": 1
    },
    {
      "x": 6,
      "y": 5,
      "z": 6,
      "name": "Rock_Ice_Permafrost",
      "rotation": 1
    },
    {
      "x": 6,
      "y": 6,
      "z": 6,
      "name": "Rock_Ice_Permafrost",
      "rotation": 1
    },
    {
      "x": 6,
      "y": 7,
      "z": 6,
      "name": "Rock_Ice",
      "rotation": 1
    },
    {
      "x": 6,
      "y": 8,
      "z": 6,
      "name": "Rock_Ice"
    },
    {
      "x": 6,
      "y": 9,
      "z": 6,
      "name": "Rock_Ice_Permafrost"
    },
    {
      "x": 6,
      "y": 10,
      "z": 6,
      "name": "Rock_Ice_Permafrost",
      "rotation": 1
    },
    {
      "x": 6,
      "y": 11,
      "z": 6,
      "name": "Rock_Ice",
      "rotation": 1
    },
    {
      "x": 6,
      "y": 12,
      "z": 6,
      "name": "Rock_Ice_Permafrost",
      "rotation": 1
    },
    {
      "x": 6,
      "y": 13,
      "z": 6,
      "name": "*Rock_Marble_Brick_Wall_State_Definitions_Corner",
      "rotation": 1
    },
    {
      "x": 6,
      "y": 14,
      "z": 6,
      "name": "Rock_Shale_Brick_Decorative"
    },
    {
      "x": 6,
      "y": 15,
      "z": 6,
      "name": "*Rock_Marble_Brick_Wall_State_Definitions_Corner",
      "rotation": 1
    },
    {
      "x": 6,
      "y": 0,
      "z": 7,
      "name": "Rock_Ice",
      "rotation": 1
    },
    {
      "x": 6,
      "y": 1,
      "z": 7,
      "name": "Rock_Ice",
      "rotation": 1
    },
    {
      "x": 6,
      "y": 2,
      "z": 7,
      "name": "Rock_Ice",
      "rotation": 1
    },
    {
      "x": 6,
      "y": 3,
      "z": 7,
      "name": "Rock_Ice_Permafrost",
      "rotation": 1
    },
    {
      "x": 6,
      "y": 4,
      "z": 7,
      "name": "Wood_Ice_Trunk",
      "rotation": 1
    },
    {
      "x": 6,
      "y": 5,
      "z": 7,
      "name": "Rock_Ice",
      "rotation": 1
    },
    {
      "x": 6,
      "y": 6,
      "z": 7,
      "name": "Rock_Ice_Permafrost",
      "rotation": 1
    },
    {
      "x": 6,
      "y": 7,
      "z": 7,
      "name": "Rock_Ice_Permafrost",
      "rotation": 1
    },
    {
      "x": 6,
      "y": 8,
      "z": 7,
      "name": "Rock_Ice_Permafrost"
    },
    {
      "x": 6,
      "y": 9,
      "z": 7,
      "name": "Rock_Ice_Permafrost"
    },
    {
      "x": 6,
      "y": 10,
      "z": 7,
      "name": "Rock_Ice_Permafrost",
      "rotation": 1
    },
    {
      "x": 6,
      "y": 11,
      "z": 7,
      "name": "Wood_Ice_Trunk",
      "rotation": 1
    },
    {
      "x": 6,
      "y": 12,
      "z": 7,
      "name": "Rock_Ice",
      "rotation": 1
    },
    {
      "x": 6,
      "y": 13,
      "z": 7,
      "name": "Rock_Marble_Brick_Wall",
      "rotation": 1
    },
    {
      "x": 6,
      "y": 14,
      "z": 7,
      "name": "Rock_Shale_Brick_Decorative"
    },
    {
      "x": 6,
      "y": 15,
      "z": 7,
      "name": "Rock_Marble_Brick_Wall",
      "rotation": 1
    },
    {
      "x": 6,
      "y": 0,
      "z": 8,
      "name": "Cloth_Block_Wool_White",
      "rotation": 1
    },
    {
      "x": 6,
      "y": 1,
      "z": 8,
      "name": "Rock_Ice"
    },
    {
      "x": 6,
      "y": 2,
      "z": 8,
      "name": "Rock_Ice",
      "rotation": 1
    },
    {
      "x": 6,
      "y": 3,
      "z": 8,
      "name": "Rock_Ice",
      "rotation": 1
    },
    {
      "x": 6,
      "y": 4,
      "z": 8,
      "name": "Rock_Ice",
      "rotation": 1
    },
    {
      "x": 6,
      "y": 5,
      "z": 8,
      "name": "Wood_Ice_Trunk",
      "rotation": 1
    },
    {
      "x": 6,
      "y": 6,
      "z": 8,
      "name": "Wood_Ice_Trunk",
      "rotation": 1
    },
    {
      "x": 6,
      "y": 7,
      "z": 8,
      "name": "Rock_Ice",
      "rotation": 1
    },
    {
      "x": 6,
      "y": 8,
      "z": 8,
      "name": "Rock_Ice"
    },
    {
      "x": 6,
      "y": 9,
      "z": 8,
      "name": "Rock_Ice"
    },
    {
      "x": 6,
      "y": 10,
      "z": 8,
      "name": "Wood_Ice_Trunk",
      "rotation": 1
    },
    {
      "x": 6,
      "y": 11,
      "z": 8,
      "name": "Wood_Ice_Trunk",
      "rotation": 1
    },
    {
      "x": 6,
      "y": 12,
      "z": 8,
      "name": "Rock_Ice",
      "rotation": 1
    },
    {
      "x": 6,
      "y": 13,
      "z": 8,
      "name": "Rock_Marble_Brick_Wall",
      "rotation": 1
    },
    {
      "x": 6,
      "y": 14,
      "z": 8,
      "name": "Rock_Shale_Brick_Decorative"
    },
    {
      "x": 6,
      "y": 15,
      "z": 8,
      "name": "Rock_Marble_Brick_Wall",
      "rotation": 1
    },
    {
      "x": 7,
      "y": 0,
      "z": -7,
      "name": "Rock_Ice",
      "rotation": 1
    },
    {
      "x": 7,
      "y": 1,
      "z": -7,
      "name": "Rock_Ice_Permafrost"
    },
    {
      "x": 7,
      "y": 2,
      "z": -7,
      "name": "Wood_Ice_Trunk",
      "rotation": 1
    },
    {
      "x": 7,
      "y": 3,
      "z": -7,
      "name": "Wood_Ice_Trunk",
      "rotation": 1
    },
    {
      "x": 7,
      "y": 4,
      "z": -7,
      "name": "Rock_Ice_Permafrost",
      "rotation": 1
    },
    {
      "x": 7,
      "y": 5,
      "z": -7,
      "name": "Wood_Ice_Trunk",
      "rotation": 1
    },
    {
      "x": 7,
      "y": 6,
      "z": -7,
      "name": "Rock_Ice",
      "rotation": 1
    },
    {
      "x": 7,
      "y": 7,
      "z": -7,
      "name": "Rock_Ice_Permafrost",
      "rotation": 1
    },
    {
      "x": 7,
      "y": 8,
      "z": -7,
      "name": "Rock_Ice"
    },
    {
      "x": 7,
      "y": 9,
      "z": -7,
      "name": "Rock_Ice_Permafrost"
    },
    {
      "x": 7,
      "y": 10,
      "z": -7,
      "name": "Rock_Ice",
      "rotation": 1
    },
    {
      "x": 7,
      "y": 11,
      "z": -7,
      "name": "Rock_Ice",
      "rotation": 1
    },
    {
      "x": 7,
      "y": 12,
      "z": -7,
      "name": "Rock_Ice_Permafrost",
      "rotation": 1
    },
    {
      "x": 7,
      "y": 13,
      "z": -7,
      "name": "Rock_Ice_Permafrost"
    },
    {
      "x": 7,
      "y": 14,
      "z": -7,
      "name": "Soil_Snow",
      "support": 15,
      "rotation": 3
    },
    {
      "x": 7,
      "y": 0,
      "z": -6,
      "name": "Cloth_Block_Wool_White",
      "rotation": 1
    },
    {
      "x": 7,
      "y": 1,
      "z": -6,
      "name": "Rock_Ice_Permafrost"
    },
    {
      "x": 7,
      "y": 2,
      "z": -6,
      "name": "Rock_Ice",
      "rotation": 1
    },
    {
      "x": 7,
      "y": 3,
      "z": -6,
      "name": "Furniture_Human_Ruins_Brazier"
    },
    {
      "x": 7,
      "y": 6,
      "z": -6,
      "name": "Rock_Ice_Permafrost",
      "rotation": 1
    },
    {
      "x": 7,
      "y": 7,
      "z": -6,
      "name": "Wood_Ice_Trunk",
      "rotation": 1
    },
    {
      "x": 7,
      "y": 8,
      "z": -6,
      "name": "Wood_Ice_Trunk"
    },
    {
      "x": 7,
      "y": 9,
      "z": -6,
      "name": "Rock_Ice"
    },
    {
      "x": 7,
      "y": 10,
      "z": -6,
      "name": "Wood_Ice_Trunk",
      "rotation": 1
    },
    {
      "x": 7,
      "y": 11,
      "z": -6,
      "name": "Rock_Ice_Permafrost",
      "rotation": 1
    },
    {
      "x": 7,
      "y": 12,
      "z": -6,
      "name": "Rock_Ice",
      "rotation": 1
    },
    {
      "x": 7,
      "y": 13,
      "z": -6,
      "name": "Rock_Ice"
    },
    {
      "x": 7,
      "y": 14,
      "z": -6,
      "name": "Soil_Snow",
      "support": 15,
      "rotation": 3
    },
    {
      "x": 7,
      "y": 0,
      "z": -5,
      "name": "Rock_Ice_Permafrost",
      "rotation": 1
    },
    {
      "x": 7,
      "y": 1,
      "z": -5,
      "name": "Rock_Ice_Permafrost"
    },
    {
      "x": 7,
      "y": 2,
      "z": -5,
      "name": "Rock_Ice",
      "rotation": 1
    },
    {
      "x": 7,
      "y": 3,
      "z": -5,
      "name": "Rock_Marble_Brick_Wall"
    },
    {
      "x": 7,
      "y": 4,
      "z": -5,
      "name": "Rock_Marble_Brick_Wall"
    },
    {
      "x": 7,
      "y": 5,
      "z": -5,
      "name": "Rock_Marble_Brick_Wall"
    },
    {
      "x": 7,
      "y": 6,
      "z": -5,
      "name": "Rock_Marble_Brick_Wall"
    },
    {
      "x": 7,
      "y": 7,
      "z": -5,
      "name": "Rock_Marble_Brick_Wall"
    },
    {
      "x": 7,
      "y": 8,
      "z": -5,
      "name": "Rock_Marble_Brick_Wall"
    },
    {
