{
  "version": 8,
  "blockIdVersion": 11,
  "anchorX": 0,
  "anchorY": 9,
  "anchorZ": 0,
  "blocks": [
    {
      "x": -10,
      "y": 20,
      "z": -10,
      "name": "Cloth_Block_Wool_Green",
      "rotation": 3
    },
    {
      "x": -10,
      "y": 20,
      "z": -9,
      "name": "Cloth_Block_Wool_Green",
      "rotation": 3
    },
    {
      "x": -10,
      "y": 20,
      "z": -8,
      "name": "Cloth_Block_Wool_Green",
      "rotation": 3
    },
    {
      "x": -10,
      "y": 20,
      "z": -7,
      "name": "Cloth_Block_Wool_Green",
      "rotation": 3
    },
    {
      "x": -10,
      "y": 20,
      "z": -6,
      "name": "Cloth_Block_Wool_Green",
      "rotation": 3
    },
    {
      "x": -10,
      "y": 20,
      "z": -5,
      "name": "Cloth_Block_Wool_Green"
    },
    {
      "x": -10,
      "y": 20,
      "z": -4,
      "name": "Cloth_Block_Wool_Green",
      "rotation": 3
    },
    {
      "x": -10,
      "y": 20,
      "z": -3,
      "name": "Cloth_Block_Wool_Green",
      "rotation": 3
    },
    {
      "x": -10,
      "y": 20,
      "z": -2,
      "name": "Cloth_Block_Wool_Green",
      "rotation": 3
    },
    {
      "x": -10,
      "y": 20,
      "z": -1,
      "name": "Cloth_Block_Wool_Green",
      "rotation": 3
    },
    {
      "x": -10,
      "y": 20,
      "z": 0,
      "name": "Cloth_Block_Wool_Green",
      "rotation": 3
    },
    {
      "x": -10,
      "y": 20,
      "z": 1,
      "name": "Cloth_Block_Wool_Pink",
      "rotation": 2
    },
    {
      "x": -10,
      "y": 20,
      "z": 2,
      "name": "Cloth_Block_Wool_Pink",
      "rotation": 2
    },
    {
      "x": -10,
      "y": 20,
      "z": 3,
      "name": "Cloth_Block_Wool_Pink",
      "rotation": 2
    },
    {
      "x": -10,
      "y": 20,
      "z": 4,
      "name": "Cloth_Block_Wool_Pink",
      "rotation": 2
    },
    {
      "x": -10,
      "y": 20,
      "z": 5,
      "name": "Cloth_Block_Wool_Pink",
      "rotation": 2
    },
    {
      "x": -10,
      "y": 20,
      "z": 6,
      "name": "Cloth_Block_Wool_Pink",
      "rotation": 2
    },
    {
      "x": -10,
      "y": 20,
      "z": 7,
      "name": "Cloth_Block_Wool_Pink",
      "rotation": 2
    },
    {
      "x": -10,
      "y": 20,
      "z": 8,
      "name": "Cloth_Block_Wool_Pink",
      "rotation": 2
    },
    {
      "x": -10,
      "y": 20,
      "z": 9,
      "name": "Cloth_Block_Wool_Pink",
      "rotation": 2
    },
    {
      "x": -10,
      "y": 20,
      "z": 10,
      "name": "Cloth_Block_Wool_Pink",
      "rotation": 2
    },
    {
      "x": -10,
      "y": 20,
      "z": 11,
      "name": "Cloth_Block_Wool_Pink",
      "rotation": 2
    },
    {
      "x": -9,
      "y": 20,
      "z": -10,
      "name": "Cloth_Block_Wool_Green",
      "rotation": 3
    },
    {
      "x": -9,
      "y": 20,
      "z": 0,
      "name": "Cloth_Block_Wool_Green",
      "rotation": 3
    },
    {
      "x": -9,
      "y": 20,
      "z": 1,
      "name": "Cloth_Block_Wool_Pink",
      "rotation": 2
    },
    {
      "x": -9,
      "y": 20,
      "z": 11,
      "name": "Cloth_Block_Wool_Pink",
      "rotation": 2
    },
    {
      "x": -8,
      "y": 20,
      "z": -10,
      "name": "Cloth_Block_Wool_Green",
      "rotation": 3
    },
    {
      "x": -8,
      "y": 20,
      "z": 0,
      "name": "Cloth_Block_Wool_Green",
      "rotation": 3
    },
    {
      "x": -8,
      "y": 20,
      "z": 1,
      "name": "Cloth_Block_Wool_Pink",
      "rotation": 2
    },
    {
      "x": -8,
      "y": 20,
      "z": 11,
      "name": "Cloth_Block_Wool_Pink",
      "rotation": 2
    },
    {
      "x": -7,
      "y": 20,
      "z": -10,
      "name": "Cloth_Block_Wool_Green",
      "rotation": 3
    },
    {
      "x": -7,
      "y": 3,
      "z": -2,
      "name": "Rock_Stone_Brick"
    },
    {
      "x": -7,
      "y": 4,
      "z": -2,
      "name": "Rock_Stone_Brick_Decorative"
    },
    {
      "x": -7,
      "y": 5,
      "z": -2,
      "name": "Soil_Gravel",
      "support": 15
    },
    {
      "x": -7,
      "y": 6,
      "z": -2,
      "name": "Soil_Gravel",
      "support": 15
    },
    {
      "x": -7,
      "y": 7,
      "z": -2,
      "name": "Soil_Gravel",
      "support": 15
    },
    {
      "x": -7,
      "y": 8,
      "z": -2,
      "name": "Soil_Gravel",
      "support": 15
    },
    {
      "x": -7,
      "y": 9,
      "z": -2,
      "name": "Rock_Stone_Brick_Smooth",
      "rotation": 1
    },
    {
      "x": -7,
      "y": 3,
      "z": -1,
      "name": "Rock_Stone_Brick"
    },
    {
      "x": -7,
      "y": 4,
      "z": -1,
      "name": "Rock_Stone_Brick_Decorative",
      "rotation": 1
    },
    {
      "x": -7,
      "y": 5,
      "z": -1,
      "name": "Soil_Gravel_Half",
      "support": 15,
      "rotation": 5
    },
    {
      "x": -7,
      "y": 6,
      "z": -1,
      "name": "Soil_Gravel_Half",
      "support": 15,
      "rotation": 5
    },
    {
      "x": -7,
      "y": 7,
      "z": -1,
      "name": "Soil_Gravel_Half",
      "support": 15,
      "rotation": 5
    },
    {
      "x": -7,
      "y": 8,
      "z": -1,
      "name": "Soil_Gravel_Half",
      "support": 15,
      "rotation": 5
    },
    {
      "x": -7,
      "y": 9,
      "z": -1,
      "name": "Rock_Stone_Brick_Smooth",
      "rotation": 1
    },
    {
      "x": -7,
      "y": 3,
      "z": 0,
      "name": "Rock_Stone_Brick"
    },
    {
      "x": -7,
      "y": 4,
      "z": 0,
      "name": "Rock_Stone_Brick_Decorative",
      "rotation": 1
    },
    {
      "x": -7,
      "y": 5,
      "z": 0,
      "name": "Soil_Gravel_Half",
      "support": 15,
      "rotation": 5
    },
    {
      "x": -7,
      "y": 6,
      "z": 0,
      "name": "Soil_Gravel_Half",
      "support": 15,
      "rotation": 5
    },
    {
      "x": -7,
      "y": 7,
      "z": 0,
      "name": "Soil_Gravel_Half",
      "support": 15,
      "rotation": 5
    },
    {
      "x": -7,
      "y": 8,
      "z": 0,
      "name": "Soil_Gravel_Half",
      "support": 15,
      "rotation": 5
    },
    {
      "x": -7,
      "y": 9,
      "z": 0,
      "name": "Rock_Stone_Brick_Smooth",
      "rotation": 1
    },
    {
      "x": -7,
      "y": 20,
      "z": 0,
      "name": "Cloth_Block_Wool_Green",
      "rotation": 3
    },
    {
      "x": -7,
      "y": 3,
      "z": 1,
      "name": "Rock_Stone_Brick"
    },
    {
      "x": -7,
      "y": 4,
      "z": 1,
      "name": "Rock_Stone_Brick_Decorative",
      "rotation": 1
    },
    {
      "x": -7,
      "y": 5,
      "z": 1,
      "name": "Soil_Gravel",
      "support": 15,
      "rotation": 1
    },
    {
      "x": -7,
      "y": 6,
      "z": 1,
      "name": "Soil_Gravel",
      "support": 15,
      "rotation": 1
    },
    {
      "x": -7,
      "y": 7,
      "z": 1,
      "name": "Soil_Gravel",
      "support": 15,
      "rotation": 1
    },
    {
      "x": -7,
      "y": 8,
      "z": 1,
      "name": "Soil_Gravel",
      "support": 15,
      "rotation": 1
    },
    {
      "x": -7,
      "y": 9,
      "z": 1,
      "name": "Rock_Stone_Brick_Smooth",
      "rotation": 1
    },
    {
      "x": -7,
      "y": 20,
      "z": 1,
      "name": "Cloth_Block_Wool_Pink",
      "rotation": 2
    },
    {
      "x": -7,
      "y": 3,
      "z": 2,
      "name": "Rock_Stone_Brick"
    },
    {
      "x": -7,
      "y": 4,
      "z": 2,
      "name": "Rock_Stone_Brick_Decorative",
      "rotation": 1
    },
    {
      "x": -7,
      "y": 5,
      "z": 2,
      "name": "Soil_Gravel_Half",
      "support": 15,
      "rotation": 5
    },
    {
      "x": -7,
      "y": 6,
      "z": 2,
      "name": "Soil_Gravel_Half",
      "support": 15,
      "rotation": 5
    },
    {
      "x": -7,
      "y": 7,
      "z": 2,
      "name": "Soil_Gravel_Half",
      "support": 15,
      "rotation": 5
    },
    {
      "x": -7,
      "y": 8,
      "z": 2,
      "name": "Soil_Gravel_Half",
      "support": 15,
      "rotation": 5
    },
    {
      "x": -7,
      "y": 9,
      "z": 2,
      "name": "Rock_Stone_Brick_Smooth",
      "rotation": 1
    },
    {
      "x": -7,
      "y": 3,
      "z": 3,
      "name": "Rock_Stone_Brick"
    },
    {
      "x": -7,
      "y": 4,
      "z": 3,
      "name": "Rock_Stone_Brick_Decorative",
      "rotation": 1
    },
    {
      "x": -7,
      "y": 5,
      "z": 3,
      "name": "Soil_Gravel_Half",
      "support": 15,
      "rotation": 5
    },
    {
      "x": -7,
      "y": 6,
      "z": 3,
      "name": "Soil_Gravel_Half",
      "support": 15,
      "rotation": 5
    },
    {
      "x": -7,
      "y": 7,
      "z": 3,
      "name": "Soil_Gravel_Half",
      "support": 15,
      "rotation": 5
    },
    {
      "x": -7,
      "y": 8,
      "z": 3,
      "name": "Soil_Gravel_Half",
      "support": 15,
      "rotation": 5
    },
    {
      "x": -7,
      "y": 9,
      "z": 3,
      "name": "Rock_Stone_Brick_Smooth",
      "rotation": 1
    },
    {
      "x": -7,
      "y": 3,
      "z": 4,
      "name": "Rock_Stone_Brick"
    },
    {
      "x": -7,
      "y": 4,
      "z": 4,
      "name": "Rock_Stone_Brick_Decorative",
      "rotation": 3
    },
    {
      "x": -7,
      "y": 5,
      "z": 4,
      "name": "Soil_Gravel_Half",
      "support": 15,
      "rotation": 5
    },
    {
      "x": -7,
      "y": 6,
      "z": 4,
      "name": "Soil_Gravel_Half",
      "support": 15,
      "rotation": 5
    },
    {
      "x": -7,
      "y": 7,
      "z": 4,
      "name": "Soil_Gravel_Half",
      "support": 15,
      "rotation": 5
    },
    {
      "x": -7,
      "y": 8,
      "z": 4,
      "name": "Soil_Gravel_Half",
      "support": 15,
      "rotation": 5
    },
    {
      "x": -7,
      "y": 9,
      "z": 4,
      "name": "Rock_Stone_Brick_Smooth",
      "rotation": 3
    },
    {
      "x": -7,
      "y": 3,
      "z": 5,
      "name": "Rock_Stone_Brick"
    },
    {
      "x": -7,
      "y": 4,
      "z": 5,
      "name": "Rock_Stone_Brick_Decorative",
      "rotation": 3
    },
    {
      "x": -7,
      "y": 5,
      "z": 5,
      "name": "Soil_Gravel",
      "support": 15,
      "rotation": 3
    },
    {
      "x": -7,
      "y": 6,
      "z": 5,
      "name": "Soil_Gravel",
      "support": 15,
      "rotation": 3
    },
    {
      "x": -7,
      "y": 7,
      "z": 5,
      "name": "Soil_Gravel",
      "support": 15,
      "rotation": 3
    },
    {
      "x": -7,
      "y": 8,
      "z": 5,
      "name": "Soil_Gravel",
      "support": 15,
      "rotation": 3
    },
    {
      "x": -7,
      "y": 9,
      "z": 5,
      "name": "Rock_Stone_Brick_Smooth",
      "rotation": 3
    },
    {
      "x": -7,
      "y": 3,
      "z": 6,
      "name": "Rock_Stone_Brick"
    },
    {
      "x": -7,
      "y": 4,
      "z": 6,
      "name": "Rock_Stone_Brick_Decorative",
      "rotation": 3
    },
    {
      "x": -7,
      "y": 5,
      "z": 6,
      "name": "Soil_Gravel_Half",
      "support": 15,
      "rotation": 5
    },
    {
      "x": -7,
      "y": 6,
      "z": 6,
      "name": "Soil_Gravel_Half",
      "support": 15,
      "rotation": 5
    },
    {
      "x": -7,
      "y": 7,
      "z": 6,
      "name": "Soil_Gravel_Half",
      "support": 15,
      "rotation": 5
    },
    {
      "x": -7,
      "y": 8,
      "z": 6,
      "name": "Soil_Gravel_Half",
      "support": 15,
      "rotation": 5
    },
    {
      "x": -7,
      "y": 9,
      "z": 6,
      "name": "Rock_Stone_Brick_Smooth",
      "rotation": 3
    },
    {
      "x": -7,
      "y": 3,
      "z": 7,
      "name": "Rock_Stone_Brick"
    },
    {
      "x": -7,
      "y": 4,
      "z": 7,
      "name": "Rock_Stone_Brick_Decorative",
      "rotation": 3
    },
    {
      "x": -7,
      "y": 5,
      "z": 7,
      "name": "Soil_Gravel_Half",
      "support": 15,
      "rotation": 5
    },
    {
      "x": -7,
      "y": 6,
      "z": 7,
      "name": "Soil_Gravel_Half",
      "support": 15,
      "rotation": 5
    },
    {
      "x": -7,
      "y": 7,
      "z": 7,
      "name": "Soil_Gravel_Half",
      "support": 15,
      "rotation": 5
    },
    {
      "x": -7,
      "y": 8,
      "z": 7,
      "name": "Soil_Gravel_Half",
      "support": 15,
      "rotation": 5
    },
    {
      "x": -7,
      "y": 9,
      "z": 7,
      "name": "Rock_Stone_Brick_Smooth",
      "rotation": 3
    },
    {
      "x": -7,
      "y": 3,
      "z": 8,
      "name": "Rock_Stone_Brick"
    },
    {
      "x": -7,
      "y": 4,
      "z": 8,
      "name": "Rock_Stone_Brick_Decorative",
      "rotation": 3
    },
    {
      "x": -7,
      "y": 5,
      "z": 8,
      "name": "Soil_Gravel",
      "support": 15,
      "rotation": 3
    },
    {
      "x": -7,
      "y": 6,
      "z": 8,
      "name": "Soil_Gravel",
      "support": 15,
      "rotation": 3
    },
    {
      "x": -7,
      "y": 7,
      "z": 8,
      "name": "Soil_Gravel",
      "support": 15,
      "rotation": 3
    },
    {
      "x": -7,
      "y": 8,
      "z": 8,
      "name": "Soil_Gravel",
      "support": 15,
      "rotation": 3
    },
    {
      "x": -7,
      "y": 9,
      "z": 8,
      "name": "Rock_Stone_Brick_Smooth",
      "rotation": 3
    },
    {
      "x": -7,
      "y": 20,
      "z": 11,
      "name": "Cloth_Block_Wool_Pink",
      "rotation": 2
    },
    {
      "x": -6,
      "y": 20,
      "z": -10,
      "name": "Cloth_Block_Wool_Green",
      "rotation": 3
    },
    {
      "x": -6,
      "y": 3,
      "z": -4,
      "name": "Rock_Stone_Brick"
    },
    {
      "x": -6,
      "y": 4,
      "z": -4,
      "name": "Rock_Stone_Brick_Decorative"
    },
    {
      "x": -6,
      "y": 5,
      "z": -4,
      "name": "Soil_Gravel",
      "support": 15
    },
    {
      "x": -6,
      "y": 6,
      "z": -4,
      "name": "Soil_Gravel",
      "support": 15
    },
    {
      "x": -6,
      "y": 7,
      "z": -4,
      "name": "Soil_Gravel",
      "support": 15
    },
    {
      "x": -6,
      "y": 8,
      "z": -4,
      "name": "Soil_Gravel",
      "support": 15
    },
    {
      "x": -6,
      "y": 9,
      "z": -4,
      "name": "Rock_Stone_Brick_Smooth"
    },
    {
      "x": -6,
      "y": 3,
      "z": -3,
      "name": "Rock_Stone_Brick"
    },
    {
      "x": -6,
      "y": 4,
      "z": -3,
      "name": "Rock_Stone_Brick_Decorative"
    },
    {
      "x": -6,
      "y": 5,
      "z": -3,
      "name": "Soil_Gravel_Half",
      "support": 15,
      "rotation": 5
    },
    {
      "x": -6,
      "y": 6,
      "z": -3,
      "name": "Soil_Gravel_Half",
      "support": 15,
      "rotation": 5
    },
    {
      "x": -6,
      "y": 7,
      "z": -3,
      "name": "Soil_Gravel_Half",
      "support": 15,
      "rotation": 5
    },
    {
      "x": -6,
      "y": 8,
      "z": -3,
      "name": "Soil_Gravel_Half",
      "support": 15,
      "rotation": 5
    },
    {
      "x": -6,
      "y": 9,
      "z": -3,
      "name": "Rock_Stone_Brick_Smooth"
    },
    {
      "x": -6,
      "y": 3,
      "z": -2,
      "name": "Rock_Stone_Brick_Smooth",
      "rotation": 1
    },
    {
      "x": -6,
      "y": 4,
      "z": -2,
      "name": "Rock_Stone_Brick_Smooth_Half",
      "rotation": 5
    },
    {
      "x": -6,
      "y": 9,
      "z": -2,
      "name": "Rock_Stone_Brick_Decorative",
      "rotation": 1
    },
    {
      "x": -6,
      "y": 3,
      "z": -1,
      "name": "Rock_Stone_Brick_Smooth",
      "rotation": 1
    },
    {
      "x": -6,
      "y": 9,
      "z": -1,
      "name": "Rock_Stone_Brick_Decorative",
      "rotation": 1
    },
    {
      "x": -6,
      "y": 10,
      "z": -1,
      "name": "Soil_Gravel",
      "support": 15,
      "rotation": 1
    },
    {
      "x": -6,
      "y": 11,
      "z": -1,
      "name": "Soil_Gravel",
      "support": 15,
      "rotation": 1
    },
    {
      "x": -6,
      "y": 12,
      "z": -1,
      "name": "Soil_Gravel",
      "support": 15,
      "rotation": 1
    },
    {
      "x": -6,
      "y": 3,
      "z": 0,
      "name": "Rock_Stone_Brick_Smooth",
      "rotation": 1
    },
    {
      "x": -6,
      "y": 9,
      "z": 0,
      "name": "Rock_Stone_Brick_Decorative",
      "rotation": 1
    },
    {
      "x": -6,
      "y": 10,
      "z": 0,
      "name": "Soil_Gravel",
      "support": 15,
      "rotation": 1
    },
    {
      "x": -6,
      "y": 11,
      "z": 0,
      "name": "Soil_Gravel",
      "support": 15,
      "rotation": 1
    },
    {
      "x": -6,
      "y": 12,
      "z": 0,
      "name": "Soil_Gravel",
      "support": 15,
      "rotation": 1
    },
    {
      "x": -6,
      "y": 20,
      "z": 0,
      "name": "Cloth_Block_Wool_Green",
      "rotation": 3
    },
    {
      "x": -6,
      "y": 3,
      "z": 1,
      "name": "Rock_Stone_Brick_Decorative",
      "rotation": 1
    },
    {
      "x": -6,
      "y": 4,
      "z": 1,
      "name": "Rock_Stone_Brick_Smooth",
      "rotation": 1
    },
    {
      "x": -6,
      "y": 5,
      "z": 1,
      "name": "Rock_Stone_Brick_Pillar_Base"
    },
    {
      "x": -6,
      "y": 6,
      "z": 1,
      "name": "Rock_Stone_Brick_Pillar_Middle"
    },
    {
      "x": -6,
      "y": 7,
      "z": 1,
      "name": "Rock_Stone_Brick_Pillar_Middle"
    },
    {
      "x": -6,
      "y": 8,
      "z": 1,
      "name": "Rock_Stone_Brick_Pillar_Base",
      "rotation": 34
    },
    {
      "x": -6,
      "y": 9,
      "z": 1,
      "name": "Rock_Stone_Brick_Decorative",
      "rotation": 1
    },
    {
      "x": -6,
      "y": 10,
      "z": 1,
      "name": "Rock_Stone_Brick",
      "rotation": 1
    },
    {
      "x": -6,
      "y": 11,
      "z": 1,
      "name": "Rock_Stone_Brick",
      "rotation": 1
    },
    {
      "x": -6,
      "y": 12,
      "z": 1,
      "name": "Rock_Stone_Brick",
      "rotation": 1
    },
    {
      "x": -6,
      "y": 20,
      "z": 1,
      "name": "Cloth_Block_Wool_Pink",
      "rotation": 2
    },
    {
      "x": -6,
      "y": 3,
      "z": 2,
      "name": "Rock_Stone_Brick_Smooth",
      "rotation": 1
    },
    {
      "x": -6,
      "y": 9,
      "z": 2,
      "name": "Rock_Stone_Brick_Decorative",
      "rotation": 1
    },
    {
      "x": -6,
      "y": 10,
      "z": 2,
      "name": "Soil_Gravel",
      "support": 15,
      "rotation": 1
    },
    {
      "x": -6,
      "y": 11,
      "z": 2,
      "name": "Soil_Gravel",
      "support": 15,
      "rotation": 1
    },
    {
      "x": -6,
      "y": 12,
      "z": 2,
      "name": "Soil_Gravel",
      "support": 15,
      "rotation": 1
    },
    {
      "x": -6,
      "y": 3,
      "z": 3,
      "name": "Rock_Stone_Brick_Smooth",
      "rotation": 1
    },
    {
      "x": -6,
      "y": 9,
      "z": 3,
      "name": "Rock_Stone_Brick_Decorative"
    },
    {
      "x": -6,
      "y": 10,
      "z": 3,
      "name": "Soil_Gravel",
      "support": 15,
      "rotation": 1
    },
    {
      "x": -6,
      "y": 11,
      "z": 3,
      "name": "Soil_Gravel",
      "support": 15,
      "rotation": 1
    },
    {
      "x": -6,
      "y": 12,
      "z": 3,
      "name": "Soil_Gravel",
      "support": 15,
      "rotation": 1
    },
    {
      "x": -6,
      "y": 3,
      "z": 4,
      "name": "Rock_Stone_Brick_Smooth",
      "rotation": 3
    },
    {
      "x": -6,
      "y": 9,
      "z": 4,
      "name": "Rock_Stone_Brick_Decorative",
      "rotation": 3
    },
    {
      "x": -6,
      "y": 10,
      "z": 4,
      "name": "Soil_Gravel",
      "support": 15,
      "rotation": 3
    },
    {
      "x": -6,
      "y": 11,
      "z": 4,
      "name": "Soil_Gravel",
      "support": 15,
      "rotation": 3
    },
    {
      "x": -6,
      "y": 12,
      "z": 4,
      "name": "Soil_Gravel",
      "support": 15,
      "rotation": 3
    },
    {
      "x": -6,
      "y": 3,
      "z": 5,
      "name": "Rock_Stone_Brick_Decorative",
      "rotation": 3
    },
    {
      "x": -6,
      "y": 4,
      "z": 5,
      "name": "Rock_Stone_Brick_Smooth",
      "rotation": 3
    },
    {
      "x": -6,
      "y": 5,
      "z": 5,
      "name": "Rock_Stone_Brick_Pillar_Base",
      "rotation": 2
    },
    {
      "x": -6,
      "y": 6,
      "z": 5,
      "name": "Rock_Stone_Brick_Pillar_Middle",
      "rotation": 2
    },
    {
      "x": -6,
      "y": 7,
      "z": 5,
      "name": "Rock_Stone_Brick_Pillar_Middle",
      "rotation": 2
    },
    {
      "x": -6,
      "y": 8,
      "z": 5,
      "name": "Rock_Stone_Brick_Pillar_Base",
      "rotation": 32
    },
    {
      "x": -6,
      "y": 9,
      "z": 5,
      "name": "Rock_Stone_Brick_Decorative",
      "rotation": 3
    },
    {
      "x": -6,
      "y": 10,
      "z": 5,
      "name": "Rock_Stone_Brick",
      "rotation": 3
    },
    {
      "x": -6,
      "y": 11,
      "z": 5,
      "name": "Rock_Stone_Brick",
      "rotation": 3
    },
    {
      "x": -6,
      "y": 12,
      "z": 5,
      "name": "Rock_Stone_Brick",
      "rotation": 3
    },
    {
      "x": -6,
      "y": 3,
      "z": 6,
      "name": "Rock_Stone_Brick_Smooth",
      "rotation": 3
    },
    {
      "x": -6,
      "y": 9,
      "z": 6,
      "name": "Rock_Stone_Brick_Decorative",
      "rotation": 3
    },
    {
      "x": -6,
      "y": 10,
      "z": 6,
      "name": "Soil_Gravel",
      "support": 15,
      "rotation": 3
    },
    {
      "x": -6,
      "y": 11,
      "z": 6,
      "name": "Soil_Gravel",
      "support": 15,
      "rotation": 3
    },
    {
      "x": -6,
      "y": 12,
      "z": 6,
      "name": "Soil_Gravel",
      "support": 15,
      "rotation": 3
    },
    {
      "x": -6,
      "y": 3,
      "z": 7,
      "name": "Rock_Stone_Brick_Smooth",
      "rotation": 3
    },
    {
      "x": -6,
      "y": 9,
      "z": 7,
      "name": "Rock_Stone_Brick_Decorative",
      "rotation": 3
    },
    {
      "x": -6,
      "y": 10,
      "z": 7,
      "name": "Soil_Gravel",
      "support": 15,
      "rotation": 3
    },
    {
      "x": -6,
      "y": 11,
      "z": 7,
      "name": "Soil_Gravel",
      "support": 15,
      "rotation": 3
    },
    {
      "x": -6,
      "y": 12,
      "z": 7,
      "name": "Soil_Gravel",
      "support": 15,
      "rotation": 3
    },
    {
      "x": -6,
      "y": 3,
      "z": 8,
      "name": "Rock_Stone_Brick_Smooth",
      "rotation": 3
    },
    {
      "x": -6,
      "y": 4,
      "z": 8,
      "name": "Rock_Stone_Brick_Smooth_Half",
      "rotation": 5
    },
    {
      "x": -6,
      "y": 9,
      "z": 8,
      "name": "Rock_Stone_Brick_Decorative",
      "rotation": 3
    },
    {
      "x": -6,
      "y": 3,
      "z": 9,
      "name": "Rock_Stone_Brick"
    },
    {
      "x": -6,
      "y": 4,
      "z": 9,
      "name": "Rock_Stone_Brick_Decorative",
      "rotation": 3
    },
    {
      "x": -6,
      "y": 5,
      "z": 9,
      "name": "Soil_Gravel_Half",
      "support": 15,
      "rotation": 5
    },
    {
      "x": -6,
      "y": 6,
      "z": 9,
      "name": "Soil_Gravel_Half",
      "support": 15,
      "rotation": 5
    },
    {
      "x": -6,
      "y": 7,
      "z": 9,
      "name": "Soil_Gravel_Half",
      "support": 15,
      "rotation": 5
    },
    {
      "x": -6,
      "y": 8,
      "z": 9,
      "name": "Soil_Gravel_Half",
      "support": 15,
      "rotation": 5
    },
    {
      "x": -6,
      "y": 9,
      "z": 9,
      "name": "Rock_Stone_Brick_Smooth",
      "rotation": 2
    },
    {
      "x": -6,
      "y": 3,
      "z": 10,
      "name": "Rock_Stone_Brick"
    },
    {
      "x": -6,
      "y": 4,
      "z": 10,
      "name": "Rock_Stone_Brick_Decorative",
      "rotation": 3
    },
    {
      "x": -6,
      "y": 5,
      "z": 10,
      "name": "Soil_Gravel",
      "support": 15,
      "rotation": 3
    },
    {
      "x": -6,
      "y": 6,
      "z": 10,
      "name": "Soil_Gravel",
      "support": 15,
      "rotation": 3
    },
    {
      "x": -6,
      "y": 7,
      "z": 10,
      "name": "Soil_Gravel",
      "support": 15,
      "rotation": 3
    },
    {
      "x": -6,
      "y": 8,
      "z": 10,
      "name": "Soil_Gravel",
      "support": 15,
      "rotation": 3
    },
    {
      "x": -6,
      "y": 9,
      "z": 10,
      "name": "Rock_Stone_Brick_Smooth",
      "rotation": 2
    },
    {
      "x": -6,
      "y": 20,
      "z": 11,
      "name": "Cloth_Block_Wool_Pink",
      "rotation": 2
    },
    {
      "x": -5,
      "y": 20,
      "z": -10,
      "name": "Cloth_Block_Wool_Green",
      "rotation": 3
    },
    {
      "x": -5,
      "y": 3,
      "z": -4,
      "name": "Rock_Stone_Brick"
    },
    {
      "x": -5,
      "y": 4,
      "z": -4,
      "name": "Rock_Stone_Brick_Decorative"
    },
    {
      "x": -5,
      "y": 5,
      "z": -4,
      "name": "Soil_Gravel_Half",
      "support": 15,
      "rotation": 4
    },
    {
      "x": -5,
      "y": 6,
      "z": -4,
      "name": "Soil_Gravel_Half",
      "support": 15,
      "rotation": 4
    },
    {
      "x": -5,
      "y": 7,
      "z": -4,
      "name": "Soil_Gravel_Half",
      "support": 15,
      "rotation": 4
    },
    {
      "x": -5,
      "y": 8,
      "z": -4,
      "name": "Soil_Gravel_Half",
      "support": 15,
      "rotation": 4
    },
    {
      "x": -5,
      "y": 9,
      "z": -4,
      "name": "Rock_Stone_Brick_Smooth"
    },
    {
      "x": -5,
      "y": 3,
      "z": -3,
      "name": "Rock_Stone_Brick_Smooth",
      "rotation": 1
    },
    {
      "x": -5,
      "y": 9,
      "z": -3,
      "name": "Rock_Stone_Brick_Decorative",
      "rotation": 1
    },
    {
      "x": -5,
      "y": 10,
      "z": -3,
      "name": "Soil_Gravel",
      "support": 15,
      "rotation": 1
    },
    {
      "x": -5,
      "y": 11,
      "z": -3,
      "name": "Soil_Gravel",
      "support": 15,
      "rotation": 1
    },
    {
      "x": -5,
      "y": 12,
      "z": -3,
      "name": "Soil_Gravel",
      "support": 15,
      "rotation": 1
    },
    {
      "x": -5,
      "y": 3,
      "z": -2,
      "name": "Rock_Stone_Brick_Smooth_Stairs",
      "rotation": 1
    },
    {
      "x": -5,
      "y": 9,
      "z": -2,
      "name": "Rock_Stone_Brick_Decorative",
      "rotation": 1
    },
    {
      "x": -5,
      "y": 10,
      "z": -2,
      "name": "*Soil_Gravel_Half_State_Definitions_Block",
      "rotation": 5
    },
    {
      "x": -5,
      "y": 11,
      "z": -2,
      "name": "*Soil_Gravel_Half_State_Definitions_Block",
      "rotation": 5
    },
    {
      "x": -5,
      "y": 12,
      "z": -2,
      "name": "Soil_Gravel",
      "support": 15,
      "rotation": 1
    },
    {
      "x": -5,
      "y": 3,
      "z": -1,
      "name": "Rock_Stone_Brick_Smooth_Stairs",
      "rotation": 1
    },
    {
      "x": -5,
      "y": 9,
      "z": -1,
      "name": "Rock_Stone_Brick_Decorative",
      "rotation": 1
    },
    {
      "x": -5,
      "y": 10,
      "z": -1,
      "name": "Soil_Gravel",
      "support": 15,
      "rotation": 1
    },
    {
      "x": -5,
      "y": 11,
      "z": -1,
      "name": "Soil_Gravel",
      "support": 15,
      "rotation": 1
    },
    {
      "x": -5,
      "y": 12,
      "z": -1,
      "name": "Soil_Gravel",
      "support": 15,
      "rotation": 1
    },
    {
      "x": -5,
      "y": 13,
      "z": -1,
      "name": "Cloth_Block_Wool_Cyan",
      "rotation": 1
    },
    {
      "x": -5,
      "y": 3,
      "z": 0,
      "name": "Rock_Stone_Brick_Smooth_Stairs",
      "rotation": 1
    },
    {
      "x": -5,
      "y": 9,
      "z": 0,
      "name": "*Rock_Stone_Brick_Smooth_Half_State_Definitions_Block",
      "rotation": 5
    },
    {
      "x": -5,
      "y": 10,
      "z": 0,
      "name": "Soil_Gravel_Half",
      "support": 15,
      "rotation": 5
    },
    {
      "x": -5,
      "y": 11,
      "z": 0,
      "name": "Soil_Gravel_Half",
      "support": 15,
      "rotation": 5
    },
    {
      "x": -5,
      "y": 12,
      "z": 0,
      "name": "Cloth_Block_Wool_Cyan",
      "rotation": 1
    },
    {
      "x": -5,
      "y": 13,
      "z": 0,
      "name": "Cloth_Block_Wool_Cyan",
      "rotation": 1
    },
    {
      "x": -5,
      "y": 20,
      "z": 0,
      "name": "Cloth_Block_Wool_Green"
    },
    {
      "x": -5,
      "y": 3,
      "z": 1,
      "name": "Rock_Stone_Brick_Smooth_Stairs",
      "rotation": 1
    },
    {
      "x": -5,
      "y": 9,
      "z": 1,
      "name": "Rock_Stone_Brick_Smooth_Half",
      "rotation": 5
    },
    {
      "x": -5,
      "y": 10,
      "z": 1,
      "name": "Rock_Stone_Brick_Half",
      "rotation": 5
    },
    {
      "x": -5,
      "y": 11,
      "z": 1,
      "name": "Rock_Stone_Brick_Half",
      "rotation": 5
    },
    {
      "x": -5,
      "y": 12,
      "z": 1,
      "name": "Rock_Stone_Brick",
      "rotation": 1
    },
    {
      "x": -5,
      "y": 13,
      "z": 1,
      "name": "Rock_Stone_Brick",
      "rotation": 1
    },
    {
      "x": -5,
      "y": 20,
      "z": 1,
      "name": "Cloth_Block_Wool_Pink"
    },
    {
      "x": -5,
      "y": 3,
      "z": 2,
      "name": "Rock_Stone_Brick_Smooth_Stairs",
      "rotation": 1
    },
    {
      "x": -5,
      "y": 9,
      "z": 2,
      "name": "Rock_Stone_Brick_Smooth_Half",
      "rotation": 5
    },
    {
      "x": -5,
      "y": 12,
      "z": 2,
      "name": "Cloth_Block_Wool_Cyan_Half",
      "rotation": 5
    },
    {
      "x": -5,
      "y": 13,
      "z": 2,
      "name": "Cloth_Block_Wool_Cyan",
      "rotation": 1
    },
    {
      "x": -5,
      "y": 3,
      "z": 3,
      "name": "Rock_Stone_Brick_Smooth_Stairs",
      "rotation": 1
    },
    {
      "x": -5,
      "y": 9,
      "z": 3,
      "name": "Rock_Stone_Brick_Smooth_Half",
      "rotation": 5
    },
    {
      "x": -5,
      "y": 12,
      "z": 3,
      "name": "Cloth_Block_Wool_Cyan_Half",
      "rotation": 5
    },
    {
      "x": -5,
      "y": 13,
      "z": 3,
      "name": "Cloth_Block_Wool_Cyan",
      "rotation": 1
    },
    {
      "x": -5,
      "y": 3,
      "z": 4,
      "name": "Rock_Stone_Brick_Smooth_Stairs",
      "rotation": 1
    },
    {
      "x": -5,
      "y": 9,
      "z": 4,
      "name": "Rock_Stone_Brick_Smooth_Half",
      "rotation": 5
    },
    {
      "x": -5,
      "y": 12,
      "z": 4,
      "name": "Cloth_Block_Wool_Cyan_Half",
      "rotation": 5
    },
    {
      "x": -5,
      "y": 13,
      "z": 4,
      "name": "Cloth_Block_Wool_Cyan",
      "rotation": 3
    },
    {
      "x": -5,
      "y": 3,
      "z": 5,
      "name": "Rock_Stone_Brick_Smooth_Stairs",
      "rotation": 1
    },
    {
      "x": -5,
      "y": 9,
      "z": 5,
      "name": "Rock_Stone_Brick_Smooth_Half",
      "rotation": 5
    },
    {
      "x": -5,
      "y": 10,
      "z": 5,
      "name": "Rock_Stone_Brick_Half",
      "rotation": 5
    },
    {
      "x": -5,
      "y": 11,
      "z": 5,
      "name": "Rock_Stone_Brick_Half",
      "rotation": 5
    },
    {
      "x": -5,
      "y": 12,
      "z": 5,
      "name": "Rock_Stone_Brick",
      "rotation": 3
    },
    {
      "x": -5,
      "y": 13,
      "z": 5,
      "name": "Rock_Stone_Brick",
      "rotation": 3
    },
    {
      "x": -5,
      "y": 3,
      "z": 6,
      "name": "Rock_Stone_Brick_Smooth_Stairs",
      "rotation": 1
    },
    {
      "x": -5,
      "y": 9,
      "z": 6,
      "name": "*Rock_Stone_Brick_Smooth_Half_State_Definitions_Block",
      "rotation": 5
    },
    {
      "x": -5,
      "y": 10,
      "z": 6,
      "name": "Soil_Gravel_Half",
      "support": 15,
      "rotation": 5
    },
    {
      "x": -5,
      "y": 11,
      "z": 6,
      "name": "Soil_Gravel_Half",
      "support": 15,
      "rotation": 5
    },
    {
      "x": -5,
      "y": 12,
      "z": 6,
      "name": "Cloth_Block_Wool_Cyan",
      "rotation": 3
    },
    {
      "x": -5,
      "y": 13,
      "z": 6,
      "name": "Cloth_Block_Wool_Cyan",
      "rotation": 3
    },
    {
      "x": -5,
      "y": 3,
      "z": 7,
      "name": "Rock_Stone_Brick_Smooth_Stairs",
      "rotation": 1
    },
    {
      "x": -5,
      "y": 9,
      "z": 7,
      "name": "Rock_Stone_Brick_Decorative",
      "rotation": 3
    },
    {
      "x": -5,
      "y": 10,
      "z": 7,
      "name": "Soil_Gravel",
      "support": 15,
      "rotation": 3
    },
    {
      "x": -5,
      "y": 11,
      "z": 7,
      "name": "Soil_Gravel",
      "support": 15,
      "rotation": 3
    },
    {
      "x": -5,
      "y": 12,
      "z": 7,
      "name": "Soil_Gravel",
      "support": 15,
      "rotation": 3
    },
    {
      "x": -5,
      "y": 13,
      "z": 7,
      "name": "Cloth_Block_Wool_Cyan",
      "rotation": 3
    },
    {
      "x": -5,
      "y": 3,
      "z": 8,
      "name": "*Rock_Stone_Brick_Smooth_Stairs_State_Definitions_Inverted_Corner_Right",
      "rotation": 2
    },
    {
      "x": -5,
      "y": 9,
      "z": 8,
      "name": "Rock_Stone_Brick_Decorative",
      "rotation": 3
    },
    {
      "x": -5,
      "y": 10,
      "z": 8,
      "name": "*Soil_Gravel_Half_State_Definitions_Block",
      "rotation": 5
    },
    {
      "x": -5,
      "y": 11,
      "z": 8,
      "name": "*Soil_Gravel_Half_State_Definitions_Block",
      "rotation": 5
    },
    {
      "x": -5,
      "y": 12,
      "z": 8,
      "name": "Soil_Gravel",
      "support": 15,
      "rotation": 3
    },
    {
      "x": -5,
      "y": 3,
      "z": 9,
      "name": "Rock_Stone_Brick_Smooth",
      "rotation": 3
    },
    {
      "x": -5,
      "y": 9,
      "z": 9,
      "name": "Rock_Stone_Brick_Decorative",
      "rotation": 3
    },
    {
      "x": -5,
      "y": 10,
      "z": 9,
      "name": "Soil_Gravel",
      "support": 15,
      "rotation": 3
    },
    {
      "x": -5,
      "y": 11,
      "z": 9,
      "name": "Soil_Gravel",
      "support": 15,
      "rotation": 3
    },
    {
      "x": -5,
      "y": 12,
      "z": 9,
      "name": "Soil_Gravel",
      "support": 15,
      "rotation": 3
    },
    {
      "x": -5,
      "y": 3,
      "z": 10,
      "name": "Rock_Stone_Brick"
    },
    {
      "x": -5,
      "y": 4,
      "z": 10,
      "name": "Rock_Stone_Brick_Decorative",
      "rotation": 3
    },
    {
      "x": -5,
      "y": 5,
      "z": 10,
      "name": "Soil_Gravel_Half",
      "support": 15,
      "rotation": 6
    },
    {
      "x": -5,
      "y": 6,
      "z": 10,
      "name": "Soil_Gravel_Half",
      "support": 15,
      "rotation": 6
    },
    {
      "x": -5,
      "y": 7,
      "z": 10,
      "name": "Soil_Gravel_Half",
      "support": 15,
      "rotation": 6
    },
    {
      "x": -5,
      "y": 8,
      "z": 10,
      "name": "Soil_Gravel_Half",
      "support": 15,
      "rotation": 6
    },
    {
      "x": -5,
      "y": 9,
      "z": 10,
      "name": "Rock_Stone_Brick_Smooth",
      "rotation": 2
    },
    {
      "x": -5,
      "y": 20,
      "z": 11,
      "name": "Cloth_Block_Wool_Pink"
    },
    {
      "x": -4,
      "y": 20,
      "z": -10,
      "name": "Cloth_Block_Wool_Green",
      "rotation": 3
    },
    {
      "x": -4,
      "y": 3,
      "z": -5,
      "name": "Rock_Stone_Brick"
    },
    {
      "x": -4,
      "y": 4,
      "z": -5,
      "name": "Rock_Stone_Brick_Decorative"
    },
    {
      "x": -4,
      "y": 5,
      "z": -5,
      "name": "Soil_Gravel",
      "support": 15
    },
    {
      "x": -4,
      "y": 6,
      "z": -5,
      "name": "Soil_Gravel",
      "support": 15
    },
    {
      "x": -4,
      "y": 7,
      "z": -5,
      "name": "Soil_Gravel",
      "support": 15
    },
    {
      "x": -4,
      "y": 8,
      "z": -5,
      "name": "Soil_Gravel",
      "support": 15
    },
    {
      "x": -4,
      "y": 9,
      "z": -5,
      "name": "Rock_Stone_Brick_Smooth"
    },
    {
      "x": -4,
      "y": 3,
      "z": -4,
      "name": "Rock_Stone_Brick_Smooth",
      "rotation": 1
    },
    {
      "x": -4,
      "y": 4,
      "z": -4,
      "name": "Rock_Stone_Brick_Smooth_Half",
      "rotation": 4
    },
    {
      "x": -4,
      "y": 9,
      "z": -4,
      "name": "Rock_Stone_Brick_Decorative",
      "rotation": 1
    },
    {
      "x": -4,
      "y": 3,
      "z": -3,
      "name": "Rock_Stone_Brick_Smooth_Stairs"
    },
    {
      "x": -4,
      "y": 9,
      "z": -3,
      "name": "Rock_Stone_Brick_Decorative",
      "rotation": 1
    },
    {
      "x": -4,
      "y": 10,
      "z": -3,
      "name": "*Soil_Gravel_Half_State_Definitions_Block",
      "rotation": 4
    },
    {
      "x": -4,
      "y": 11,
      "z": -3,
      "name": "*Soil_Gravel_Half_State_Definitions_Block",
      "rotation": 4
    },
    {
      "x": -4,
      "y": 12,
      "z": -3,
      "name": "Soil_Gravel",
      "support": 15,
      "rotation": 1
    },
    {
      "x": -4,
      "y": 3,
      "z": -2,
      "name": "Rock_Stone_Brick_Smooth",
      "rotation": 1
    },
    {
      "x": -4,
      "y": 4,
      "z": -2,
      "name": "Rock_Stone_Brick_Smooth",
      "rotation": 1
    },
    {
      "x": -4,
      "y": 5,
      "z": -2,
      "name": "Rock_Stone_Brick_Pillar_Base",
      "rotation": 3
    },
    {
      "x": -4,
      "y": 6,
      "z": -2,
      "name": "Rock_Stone_Brick_Pillar_Middle",
      "rotation": 33
    },
    {
      "x": -4,
      "y": 7,
      "z": -2,
      "name": "Rock_Stone_Brick_Pillar_Middle"
    },
    {
      "x": -4,
      "y": 8,
      "z": -2,
      "name": "Rock_Stone_Brick_Pillar_Base",
      "rotation": 33
    },
    {
      "x": -4,
      "y": 9,
      "z": -2,
      "name": "*Rock_Stone_Brick_Smooth_Half_State_Definitions_Block",
      "rotation": 4
    },
    {
      "x": -4,
      "y": 10,
      "z": -2,
      "name": "Soil_Gravel",
      "support": 15,
      "rotation": 1
    },
    {
      "x": -4,
      "y": 11,
      "z": -2,
      "name": "Soil_Gravel",
      "support": 15,
      "rotation": 1
    },
    {
      "x": -4,
      "y": 12,
      "z": -2,
      "name": "Soil_Gravel",
      "support": 15,
      "rotation": 1
    },
    {
      "x": -4,
      "y": 3,
      "z": -1,
      "name": "Soil_Gravel",
      "support": 15
    },
    {
      "x": -4,
      "y": 9,
      "z": -1,
      "name": "Rock_Stone_Brick_Smooth_Half",
      "rotation": 5
    },
    {
      "x": -4,
      "y": 11,
      "z": -1,
      "name": "Cloth_Block_Wool_Cyan_Half",
      "rotation": 5
    },
    {
      "x": -4,
      "y": 12,
      "z": -1,
      "name": "Cloth_Block_Wool_Cyan_Stairs",
      "rotation": 33
    },
    {
      "x": -4,
      "y": 13,
      "z": -1,
      "name": "Cloth_Block_Wool_Cyan",
      "rotation": 1
    },
    {
      "x": -4,
      "y": 3,
      "z": 0,
      "name": "Soil_Gravel",
      "support": 15
    },
    {
      "x": -4,
      "y": 13,
      "z": 0,
      "name": "Cloth_Block_Wool_Cyan_Half",
      "rotation": 33
    },
    {
      "x": -4,
      "y": 20,
      "z": 0,
      "name": "Cloth_Block_Wool_Green",
      "rotation": 3
    },
    {
      "x": -4,
      "y": 3,
      "z": 1,
      "name": "Soil_Gravel",
      "support": 15
    },
    {
      "x": -4,
      "y": 12,
      "z": 1,
      "name": "Rock_Stone_Brick_Half",
      "rotation": 33
    },
    {
      "x": -4,
      "y": 13,
      "z": 1,
      "name": "Rock_Stone_Brick",
      "rotation": 1
    },
    {
      "x": -4,
      "y": 14,
      "z": 1,
      "name": "Rock_Stone_Brick",
      "rotation": 1
    },
    {
      "x": -4,
      "y": 20,
      "z": 1,
      "name": "Cloth_Block_Wool_Pink",
      "rotation": 2
    },
    {
      "x": -4,
      "y": 3,
      "z": 2,
      "name": "Soil_Gravel",
      "support": 15
    },
    {
      "x": -4,
      "y": 13,
      "z": 2,
      "name": "Cloth_Block_Wool_Cyan_Half",
      "rotation": 33
    },
    {
      "x": -4,
      "y": 3,
      "z": 3,
      "name": "Soil_Gravel",
      "support": 15
    },
    {
      "x": -4,
      "y": 13,
      "z": 3,
      "name": "Cloth_Block_Wool_Cyan_Half",
      "rotation": 33
    },
    {
      "x": -4,
      "y": 3,
      "z": 4,
      "name": "Soil_Gravel",
      "support": 15,
      "rotation": 2
    },
    {
      "x": -4,
      "y": 13,
      "z": 4,
      "name": "Cloth_Block_Wool_Cyan_Half",
      "rotation": 33
    },
    {
      "x": -4,
      "y": 3,
      "z": 5,
      "name": "Soil_Gravel",
      "support": 15,
      "rotation": 2
    },
    {
      "x": -4,
      "y": 12,
      "z": 5,
      "name": "Rock_Stone_Brick_Half",
      "rotation": 33
    },
    {
      "x": -4,
      "y": 13,
      "z": 5,
      "name": "Rock_Stone_Brick",
      "rotation": 3
    },
    {
      "x": -4,
      "y": 14,
      "z": 5,
      "name": "Rock_Stone_Brick",
      "rotation": 3
    },
    {
      "x": -4,
      "y": 3,
      "z": 6,
      "name": "Soil_Gravel",
      "support": 15,
      "rotation": 2
    },
    {
      "x": -4,
      "y": 13,
      "z": 6,
      "name": "Cloth_Block_Wool_Cyan_Half",
      "rotation": 33
    },
    {
      "x": -4,
      "y": 3,
      "z": 7,
      "name": "Soil_Gravel",
      "support": 15,
      "rotation": 2
    },
    {
      "x": -4,
      "y": 9,
      "z": 7,
      "name": "Rock_Stone_Brick_Smooth_Half",
      "rotation": 5
    },
    {
      "x": -4,
      "y": 11,
      "z": 7,
      "name": "Cloth_Block_Wool_Cyan_Half",
      "rotation": 5
    },
    {
      "x": -4,
      "y": 12,
      "z": 7,
      "name": "Cloth_Block_Wool_Cyan_Stairs",
      "rotation": 33
    },
    {
      "x": -4,
      "y": 13,
      "z": 7,
      "name": "Cloth_Block_Wool_Cyan",
      "rotation": 3
    },
    {
      "x": -4,
      "y": 3,
      "z": 8,
      "name": "Rock_Stone_Brick_Smooth",
      "rotation": 3
    },
    {
      "x": -4,
      "y": 4,
      "z": 8,
      "name": "Rock_Stone_Brick_Smooth",
      "rotation": 3
    },
    {
      "x": -4,
      "y": 5,
      "z": 8,
      "name": "Rock_Stone_Brick_Pillar_Base",
      "rotation": 3
    },
    {
      "x": -4,
      "y": 6,
      "z": 8,
      "name": "Rock_Stone_Brick_Pillar_Middle",
      "rotation": 33
    },
    {
      "x": -4,
      "y": 7,
      "z": 8,
      "name": "Rock_Stone_Brick_Pillar_Middle",
      "rotation": 33
    },
    {
      "x": -4,
      "y": 8,
      "z": 8,
      "name": "Rock_Stone_Brick_Pillar_Base",
      "rotation": 33
    },
    {
      "x": -4,
      "y": 9,
      "z": 8,
      "name": "*Rock_Stone_Brick_Smooth_Half_State_Definitions_Block",
      "rotation": 6
    },
    {
      "x": -4,
      "y": 10,
      "z": 8,
      "name": "Soil_Gravel",
      "support": 15,
      "rotation": 3
    },
    {
      "x": -4,
      "y": 11,
      "z": 8,
      "name": "Soil_Gravel",
      "support": 15,
      "rotation": 3
    },
    {
      "x": -4,
      "y": 12,
      "z": 8,
      "name": "Soil_Gravel",
      "support": 15,
      "rotation": 3
    },
    {
      "x": -4,
      "y": 3,
      "z": 9,
      "name": "*Rock_Stone_Brick_Smooth_Stairs_State_Definitions_Inverted_Corner_Left",
      "rotation": 1
    },
    {
      "x": -4,
      "y": 9,
      "z": 9,
      "name": "Rock_Stone_Brick_Decorative",
      "rotation": 3
    },
    {
      "x": -4,
      "y": 10,
      "z": 9,
      "name": "*Soil_Gravel_Half_State_Definitions_Block",
      "rotation": 6
    },
    {
      "x": -4,
      "y": 11,
      "z": 9,
      "name": "*Soil_Gravel_Half_State_Definitions_Block",
      "rotation": 6
    },
    {
      "x": -4,
      "y": 12,
      "z": 9,
      "name": "Soil_Gravel",
      "support": 15,
      "rotation": 3
    },
    {
      "x": -4,
      "y": 3,
      "z": 10,
      "name": "Rock_Stone_Brick_Smooth",
      "rotation": 3
    },
    {
      "x": -4,
      "y": 4,
      "z": 10,
      "name": "Rock_Stone_Brick_Smooth_Half",
      "rotation": 6
    },
    {
      "x": -4,
      "y": 9,
      "z": 10,
      "name": "Rock_Stone_Brick_Decorative",
      "rotation": 3
    },
    {
      "x": -4,
      "y": 3,
      "z": 11,
      "name": "Rock_Stone_Brick"
    },
    {
      "x": -4,
      "y": 4,
      "z": 11,
      "name": "Rock_Stone_Brick_Decorative",
      "rotation": 3
    },
    {
      "x": -4,
      "y": 5,
      "z": 11,
      "name": "Soil_Gravel",
      "support": 15,
      "rotation": 3
    },
    {
      "x": -4,
      "y": 6,
      "z": 11,
      "name": "Soil_Gravel",
      "support": 15,
      "rotation": 3
    },
    {
      "x": -4,
      "y": 7,
      "z": 11,
      "name": "Soil_Gravel",
      "support": 15,
      "rotation": 3
    },
    {
      "x": -4,
      "y": 8,
      "z": 11,
      "name": "Soil_Gravel",
      "support": 15,
      "rotation": 3
    },
    {
      "x": -4,
      "y": 9,
      "z": 11,
      "name": "Rock_Stone_Brick_Smooth",
      "rotation": 3
    },
    {
      "x": -4,
      "y": 20,
      "z": 11,
      "name": "Cloth_Block_Wool_Pink",
      "rotation": 2
    },
    {
      "x": -3,
      "y": 20,
      "z": -10,
      "name": "Cloth_Block_Wool_Green",
      "rotation": 3
    },
    {
      "x": -3,
      "y": 3,
      "z": -5,
      "name": "Rock_Stone_Brick"
    },
    {
      "x": -3,
      "y": 4,
      "z": -5,
      "name": "Rock_Stone_Brick_Decorative"
    },
    {
      "x": -3,
      "y": 5,
      "z": -5,
      "name": "Soil_Gravel_Half",
      "support": 15,
      "rotation": 4
    },
    {
      "x": -3,
      "y": 6,
      "z": -5,
      "name": "Soil_Gravel_Half",
      "support": 15,
      "rotation": 4
    },
    {
      "x": -3,
      "y": 7,
      "z": -5,
      "name": "Soil_Gravel_Half",
      "support": 15,
      "rotation": 4
    },
    {
      "x": -3,
      "y": 8,
      "z": -5,
      "name": "Soil_Gravel_Half",
      "support": 15,
      "rotation": 4
    },
    {
      "x": -3,
      "y": 9,
      "z": -5,
      "name": "Rock_Stone_Brick_Smooth"
    },
    {
      "x": -3,
      "y": 3,
      "z": -4,
      "name": "Rock_Stone_Brick_Smooth",
      "rotation": 1
    },
    {
      "x": -3,
      "y": 9,
      "z": -4,
      "name": "Rock_Stone_Brick_Decorative",
      "rotation": 1
    },
    {
      "x": -3,
      "y": 10,
      "z": -4,
      "name": "Soil_Gravel",
      "support": 15,
      "rotation": 1
    },
    {
      "x": -3,
      "y": 11,
      "z": -4,
      "name": "Soil_Gravel",
      "support": 15,
      "rotation": 1
    },
    {
      "x": -3,
      "y": 12,
      "z": -4,
      "name": "Soil_Gravel",
      "support": 15,
      "rotation": 1
    },
    {
      "x": -3,
      "y": 3,
      "z": -3,
      "name": "Rock_Stone_Brick_Smooth_Stairs"
    },
    {
      "x": -3,
      "y": 9,
      "z": -3,
      "name": "Rock_Stone_Brick_Decorative",
      "rotation": 1
    },
    {
      "x": -3,
      "y": 10,
      "z": -3,
      "name": "Soil_Gravel",
      "support": 15,
      "rotation": 1
    },
    {
      "x": -3,
      "y": 11,
      "z": -3,
      "name": "Soil_Gravel",
      "support": 15,
      "rotation": 1
    },
    {
      "x": -3,
      "y": 12,
      "z": -3,
      "name": "Soil_Gravel",
      "support": 15,
      "rotation": 1
    },
    {
      "x": -3,
      "y": 13,
      "z": -3,
      "name": "Cloth_Block_Wool_Cyan",
      "rotation": 1
    },
    {
      "x": -3,
      "y": 3,
      "z": -2,
      "name": "Soil_Gravel",
      "support": 15
    },
    {
      "x": -3,
      "y": 9,
      "z": -2,
      "name": "Rock_Stone_Brick_Smooth_Half",
      "rotation": 4
    },
    {
      "x": -3,
      "y": 11,
      "z": -2,
      "name": "Cloth_Block_Wool_Cyan_Half",
      "rotation": 4
    },
    {
      "x": -3,
      "y": 12,
      "z": -2,
      "name": "Cloth_Block_Wool_Cyan_Stairs",
      "rotation": 32
    },
    {
      "x": -3,
      "y": 13,
      "z": -2,
      "name": "Cloth_Block_Wool_Cyan",
      "rotation": 1
    },
    {
      "x": -3,
      "y": 3,
      "z": -1,
      "name": "Soil_Gravel",
      "support": 15
    },
    {
      "x": -3,
      "y": 13,
      "z": -1,
      "name": "Cloth_Block_Wool_Cyan_Half",
      "rotation": 33
    },
    {
      "x": -3,
      "y": 3,
      "z": 0,
      "name": "Soil_Gravel",
      "support": 15
    },
    {
      "x": -3,
      "y": 14,
      "z": 0,
      "name": "Cloth_Block_Wool_Cyan",
      "rotation": 1
    },
    {
      "x": -3,
      "y": 20,
      "z": 0,
      "name": "Cloth_Block_Wool_Green",
      "rotation": 3
    },
    {
      "x": -3,
      "y": 3,
      "z": 1,
      "name": "Soil_Gravel",
      "support": 15
    },
    {
      "x": -3,
      "y": 13,
      "z": 1,
      "name": "Rock_Stone_Brick",
      "rotation": 1
    },
    {
      "x": -3,
      "y": 14,
      "z": 1,
      "name": "Rock_Stone_Brick",
      "rotation": 1
    },
    {
      "x": -3,
      "y": 20,
      "z": 1,
      "name": "Cloth_Block_Wool_Pink",
      "rotation": 2
    },
    {
      "x": -3,
      "y": 3,
      "z": 2,
      "name": "Soil_Gravel",
      "support": 15
    },
    {
      "x": -3,
      "y": 14,
      "z": 2,
      "name": "Cloth_Block_Wool_Cyan",
      "rotation": 1
    },
    {
      "x": -3,
      "y": 3,
      "z": 3,
      "name": "Soil_Gravel",
      "support": 15
    },
    {
      "x": -3,
      "y": 14,
      "z": 3,
      "name": "Cloth_Block_Wool_Cyan",
      "rotation": 1
    },
    {
      "x": -3,
      "y": 3,
      "z": 4,
      "name": "Soil_Gravel",
      "support": 15,
      "rotation": 2
    },
    {
      "x": -3,
      "y": 14,
      "z": 4,
      "name": "Cloth_Block_Wool_Cyan",
      "rotation": 3
    },
    {
      "x": -3,
      "y": 3,
      "z": 5,
      "name": "Soil_Gravel",
      "support": 15,
      "rotation": 2
    },
    {
      "x": -3,
      "y": 13,
      "z": 5,
      "name": "Rock_Stone_Brick",
      "rotation": 3
    },
    {
      "x": -3,
      "y": 14,
      "z": 5,
      "name": "Rock_Stone_Brick",
      "rotation": 3
    },
    {
      "x": -3,
      "y": 3,
      "z": 6,
      "name": "Soil_Gravel",
      "support": 15,
      "rotation": 2
    },
    {
      "x": -3,
      "y": 14,
      "z": 6,
      "name": "Cloth_Block_Wool_Cyan",
      "rotation": 3
    },
    {
      "x": -3,
      "y": 3,
      "z": 7,
      "name": "Soil_Gravel",
      "support": 15,
      "rotation": 2
    },
    {
      "x": -3,
      "y": 13,
      "z": 7,
      "name": "Cloth_Block_Wool_Cyan_Half",
      "rotation": 33
    },
    {
      "x": -3,
      "y": 3,
      "z": 8,
      "name": "Soil_Gravel",
      "support": 15,
      "rotation": 2
    },
    {
      "x": -3,
      "y": 9,
      "z": 8,
      "name": "Rock_Stone_Brick_Smooth_Half",
      "rotation": 6
    },
    {
      "x": -3,
      "y": 11,
      "z": 8,
      "name": "Cloth_Block_Wool_Cyan_Half",
      "rotation": 6
    },
    {
      "x": -3,
      "y": 12,
      "z": 8,
      "name": "Cloth_Block_Wool_Cyan_Stairs",
      "rotation": 34
    },
    {
      "x": -3,
      "y": 13,
      "z": 8,
      "name": "Cloth_Block_Wool_Cyan",
      "rotation": 3
    },
    {
      "x": -3,
      "y": 3,
      "z": 9,
      "name": "Rock_Stone_Brick_Smooth_Stairs",
      "rotation": 2
    },
    {
      "x": -3,
      "y": 9,
      "z": 9,
      "name": "Rock_Stone_Brick_Decorative",
      "rotation": 3
    },
    {
      "x": -3,
      "y": 10,
      "z": 9,
      "name": "Soil_Gravel",
      "support": 15,
      "rotation": 3
    },
    {
      "x": -3,
      "y": 11,
      "z": 9,
      "name": "Soil_Gravel",
      "support": 15,
      "rotation": 3
    },
    {
      "x": -3,
      "y": 12,
      "z": 9,
      "name": "Soil_Gravel",
      "support": 15,
      "rotation": 3
    },
    {
      "x": -3,
      "y": 13,
      "z": 9,
      "name": "Cloth_Block_Wool_Cyan",
      "rotation": 3
    },
    {
      "x": -3,
      "y": 3,
      "z": 10,
      "name": "Rock_Stone_Brick_Smooth",
      "rotation": 3
    },
    {
      "x": -3,
      "y": 9,
      "z": 10,
      "name": "Rock_Stone_Brick_Decorative",
      "rotation": 3
    },
    {
      "x": -3,
      "y": 10,
      "z": 10,
      "name": "Soil_Gravel",
      "support": 15,
      "rotation": 3
    },
    {
      "x": -3,
      "y": 11,
      "z": 10,
      "name": "Soil_Gravel",
      "support": 15,
      "rotation": 3
    },
    {
      "x": -3,
      "y": 12,
      "z": 10,
      "name": "Soil_Gravel",
      "support": 15,
      "rotation": 3
    },
    {
      "x": -3,
      "y": 3,
      "z": 11,
      "name": "Rock_Stone_Brick"
    },
    {
      "x": -3,
      "y": 4,
      "z": 11,
      "name": "Rock_Stone_Brick_Decorative",
      "rotation": 3
    },
    {
      "x": -3,
      "y": 5,
      "z": 11,
      "name": "Soil_Gravel_Half",
      "support": 15,
      "rotation": 6
    },
    {
      "x": -3,
      "y": 6,
      "z": 11,
      "name": "Soil_Gravel_Half",
      "support": 15,
      "rotation": 6
    },
    {
      "x": -3,
      "y": 7,
      "z": 11,
      "name": "Soil_Gravel_Half",
      "support": 15,
      "rotation": 6
    },
    {
      "x": -3,
      "y": 8,
      "z": 11,
      "name": "Soil_Gravel_Half",
      "support": 15,
      "rotation": 6
    },
    {
      "x": -3,
      "y": 9,
      "z": 11,
      "name": "Rock_Stone_Brick_Smooth",
      "rotation": 3
    },
    {
      "x": -3,
      "y": 20,
      "z": 11,
      "name": "Cloth_Block_Wool_Pink",
      "rotation": 2
    },
    {
      "x": -2,
      "y": 20,
      "z": -10,
      "name": "Cloth_Block_Wool_Green",
      "rotation": 3
    },
    {
      "x": -2,
      "y": 3,
      "z": -5,
      "name": "Rock_Stone_Brick"
    },
    {
      "x": -2,
      "y": 4,
      "z": -5,
      "name": "Rock_Stone_Brick_Decorative"
    },
    {
      "x": -2,
      "y": 5,
      "z": -5,
      "name": "Soil_Gravel_Half",
      "support": 15,
      "rotation": 4
    },
    {
      "x": -2,
      "y": 6,
      "z": -5,
      "name": "Soil_Gravel_Half",
      "support": 15,
      "rotation": 4
    },
    {
      "x": -2,
      "y": 7,
      "z": -5,
      "name": "Soil_Gravel_Half",
      "support": 15,
      "rotation": 4
    },
    {
      "x": -2,
      "y": 8,
      "z": -5,
      "name": "Soil_Gravel_Half",
      "support": 15,
      "rotation": 4
    },
    {
      "x": -2,
      "y": 9,
      "z": -5,
      "name": "Rock_Stone_Brick_Smooth"
    },
    {
      "x": -2,
      "y": 3,
      "z": -4,
      "name": "Rock_Stone_Brick_Smooth",
      "rotation": 1
    },
    {
      "x": -2,
      "y": 9,
      "z": -4,
      "name": "Rock_Stone_Brick_Decorative",
      "rotation": 1
    },
    {
      "x": -2,
      "y": 10,
      "z": -4,
      "name": "Soil_Gravel",
      "support": 15,
      "rotation": 1
    },
    {
      "x": -2,
      "y": 11,
      "z": -4,
      "name": "Soil_Gravel",
      "support": 15,
      "rotation": 1
    },
    {
      "x": -2,
      "y": 12,
      "z": -4,
      "name": "Soil_Gravel",
      "support": 15,
      "rotation": 1
    },
    {
      "x": -2,
      "y": 3,
      "z": -3,
      "name": "Rock_Stone_Brick_Smooth_Stairs"
    },
    {
      "x": -2,
      "y": 9,
      "z": -3,
      "name": "*Rock_Stone_Brick_Smooth_Half_State_Definitions_Block",
      "rotation": 4
    },
    {
      "x": -2,
      "y": 10,
      "z": -3,
      "name": "Soil_Gravel_Half",
      "support": 15,
      "rotation": 4
    },
    {
      "x": -2,
      "y": 11,
      "z": -3,
      "name": "Soil_Gravel_Half",
      "support": 15,
      "rotation": 4
    },
    {
      "x": -2,
      "y": 12,
      "z": -3,
      "name": "Cloth_Block_Wool_Cyan",
      "rotation": 1
    },
    {
      "x": -2,
      "y": 13,
      "z": -3,
      "name": "Cloth_Block_Wool_Cyan",
      "rotation": 1
    },
    {
      "x": -2,
      "y": 3,
      "z": -2,
      "name": "*Soil_Gravel_Half_State_Definitions_Block",
      "rotation": 3
    },
    {
      "x": -2,
      "y": 13,
      "z": -2,
      "name": "Cloth_Block_Wool_Cyan_Half",
      "rotation": 33
    },
    {
      "x": -2,
      "y": 3,
      "z": -1,
      "name": "Soil_Gravel",
      "support": 15
    },
    {
      "x": -2,
      "y": 14,
      "z": -1,
      "name": "Cloth_Block_Wool_Cyan",
      "rotation": 1
    },
    {
      "x": -2,
      "y": 3,
      "z": 0,
      "name": "Soil_Gravel",
      "support": 15
    },
    {
      "x": -2,
      "y": 14,
      "z": 0,
      "name": "Cloth_Block_Wool_Cyan",
      "rotation": 1
    },
    {
      "x": -2,
      "y": 20,
      "z": 0,
      "name": "Cloth_Block_Wool_Green",
      "rotation": 3
    },
    {
      "x": -2,
      "y": 3,
      "z": 1,
      "name": "Soil_Gravel",
      "support": 15
    },
    {
      "x": -2,
      "y": 13,
      "z": 1,
      "name": "Rock_Stone_Brick_Half",
      "rotation": 33
    },
    {
      "x": -2,
      "y": 14,
      "z": 1,
      "name": "Rock_Stone_Brick",
      "rotation": 1
    },
    {
      "x": -2,
      "y": 20,
      "z": 1,
      "name": "Cloth_Block_Wool_Pink",
      "rotation": 2
    },
    {
      "x": -2,
      "y": 3,
      "z": 2,
      "name": "Soil_Gravel",
      "support": 15
    },
    {
      "x": -2,
      "y": 4,
      "z": 2,
      "name": "Rock_Stone_Brick_Smooth_Half",
      "rotation": 7
    },
    {
      "x": -2,
      "y": 14,
      "z": 2,
      "name": "Cloth_Block_Wool_Cyan",
      "rotation": 1
    },
    {
      "x": -2,
      "y": 15,
      "z": 2,
      "name": "Cloth_Block_Wool_Cyan",
      "rotation": 1
    },
    {
      "x": -2,
      "y": 16,
      "z": 2,
      "name": "Cloth_Block_Wool_Cyan",
      "rotation": 1
    },
    {
      "x": -2,
      "y": 3,
      "z": 3,
      "name": "Soil_Gravel",
      "support": 15
    },
    {
      "x": -2,
      "y": 4,
      "z": 3,
      "name": "Rock_Stone_Brick_Smooth_Half",
      "rotation": 7
    },
    {
      "x": -2,
      "y": 14,
      "z": 3,
      "name": "Cloth_Block_Wool_Cyan",
      "rotation": 1
    },
    {
      "x": -2,
      "y": 15,
      "z": 3,
      "name": "Cloth_Block_Wool_Cyan",
      "rotation": 1
    },
    {
      "x": -2,
      "y": 16,
      "z": 3,
      "name": "Cloth_Block_Wool_Cyan",
      "rotation": 1
    },
    {
      "x": -2,
      "y": 3,
      "z": 4,
      "name": "Soil_Gravel",
      "support": 15,
      "rotation": 2
    },
    {
      "x": -2,
      "y": 4,
      "z": 4,
      "name": "Rock_Stone_Brick_Smooth_Half",
      "rotation": 7
    },
    {
      "x": -2,
      "y": 14,
      "z": 4,
      "name": "Cloth_Block_Wool_Cyan",
      "rotation": 3
    },
    {
      "x": -2,
      "y": 15,
      "z": 4,
      "name": "Cloth_Block_Wool_Cyan",
      "rotation": 3
    },
    {
      "x": -2,
      "y": 16,
      "z": 4,
      "name": "Cloth_Block_Wool_Cyan",
      "rotation": 3
    },
    {
      "x": -2,
      "y": 3,
      "z": 5,
      "name": "Soil_Gravel",
      "support": 15,
      "rotation": 2
    },
    {
      "x": -2,
      "y": 13,
      "z": 5,
      "name": "Rock_Stone_Brick_Half",
      "rotation": 33
    },
    {
      "x": -2,
      "y": 14,
      "z": 5,
      "name": "Rock_Stone_Brick",
      "rotation": 3
    },
    {
      "x": -2,
      "y": 3,
      "z": 6,
      "name": "Soil_Gravel",
      "support": 15,
      "rotation": 2
    },
    {
      "x": -2,
      "y": 14,
      "z": 6,
      "name": "Cloth_Block_Wool_Cyan",
      "rotation": 3
    },
    {
      "x": -2,
      "y": 3,
      "z": 7,
      "name": "Soil_Gravel",
      "support": 15,
      "rotation": 2
    },
    {
      "x": -2,
      "y": 14,
      "z": 7,
      "name": "Cloth_Block_Wool_Cyan",
      "rotation": 3
    },
    {
      "x": -2,
      "y": 3,
      "z": 8,
      "name": "*Soil_Gravel_Half_State_Definitions_Block",
      "rotation": 3
    },
    {
      "x": -2,
      "y": 13,
      "z": 8,
      "name": "Cloth_Block_Wool_Cyan_Half",
      "rotation": 33
    },
    {
      "x": -2,
      "y": 3,
      "z": 9,
      "name": "Rock_Stone_Brick_Smooth_Stairs",
      "rotation": 2
    },
    {
      "x": -2,
      "y": 9,
      "z": 9,
      "name": "*Rock_Stone_Brick_Smooth_Half_State_Definitions_Block",
      "rotation": 6
    },
    {
      "x": -2,
      "y": 10,
      "z": 9,
      "name": "Soil_Gravel_Half",
      "support": 15,
      "rotation": 6
    },
    {
      "x": -2,
      "y": 11,
      "z": 9,
      "name": "Soil_Gravel_Half",
      "support": 15,
      "rotation": 6
    },
    {
      "x": -2,
      "y": 12,
      "z": 9,
      "name": "Cloth_Block_Wool_Cyan",
      "rotation": 3
    },
    {
      "x": -2,
      "y": 13,
      "z": 9,
      "name": "Cloth_Block_Wool_Cyan",
      "rotation": 3
    },
    {
      "x": -2,
      "y": 3,
      "z": 10,
      "name": "Rock_Stone_Brick_Smooth",
      "rotation": 3
    },
    {
      "x": -2,
      "y": 9,
      "z": 10,
      "name": "Rock_Stone_Brick_Decorative",
      "rotation": 3
    },
    {
      "x": -2,
      "y": 10,
      "z": 10,
      "name": "Soil_Gravel",
      "support": 15,
      "rotation": 3
    },
    {
      "x": -2,
      "y": 11,
      "z": 10,
      "name": "Soil_Gravel",
      "support": 15,
      "rotation": 3
    },
    {
      "x": -2,
      "y": 12,
      "z": 10,
      "name": "Soil_Gravel",
      "support": 15,
      "rotation": 3
    },
    {
      "x": -2,
      "y": 3,
      "z": 11,
      "name": "Rock_Stone_Brick"
    },
    {
      "x": -2,
      "y": 4,
      "z": 11,
      "name": "Rock_Stone_Brick_Decorative",
      "rotation": 3
    },
    {
      "x": -2,
      "y": 5,
      "z": 11,
      "name": "Soil_Gravel_Half",
      "support": 15,
      "rotation": 6
    },
    {
      "x": -2,
      "y": 6,
      "z": 11,
      "name": "Soil_Gravel_Half",
      "support": 15,
      "rotation": 6
    },
    {
      "x": -2,
      "y": 7,
      "z": 11,
      "name": "Soil_Gravel_Half",
      "support": 15,
      "rotation": 6
    },
    {
      "x": -2,
      "y": 8,
      "z": 11,
      "name": "Soil_Gravel_Half",
      "support": 15,
      "rotation": 6
    },
    {
      "x": -2,
      "y": 9,
      "z": 11,
      "name": "Rock_Stone_Brick_Smooth",
      "rotation": 3
    },
    {
      "x": -2,
      "y": 20,
      "z": 11,
      "name": "Cloth_Block_Wool_Pink",
      "rotation": 2
    },
    {
      "x": -1,
      "y": 20,
      "z": -10,
      "name": "Cloth_Block_Wool_Green",
      "rotation": 3
    },
    {
      "x": -1,
      "y": 3,
      "z": -8,
      "name": "Rock_Stone_Brick"
    },
    {
      "x": -1,
      "y": 4,
      "z": -8,
      "name": "Rock_Stone_Brick_Decorative"
    },
    {
      "x": -1,
      "y": 5,
      "z": -8,
      "name": "Rock_Stone_Brick"
    },
    {
      "x": -1,
      "y": 6,
      "z": -8,
      "name": "Rock_Stone_Brick"
    },
    {
      "x": -1,
      "y": 7,
      "z": -8,
      "name": "Rock_Stone_Brick"
    },
    {
      "x": -1,
      "y": 8,
      "z": -8,
      "name": "Rock_Stone_Brick"
    },
    {
      "x": -1,
      "y": 9,
      "z": -8,
      "name": "Rock_Stone_Brick_Smooth"
    },
    {
      "x": -1,
      "y": 3,
      "z": -7,
      "name": "Rock_Stone_Brick"
    },
    {
      "x": -1,
      "y": 4,
      "z": -7,
      "name": "Rock_Stone_Brick_Decorative"
    },
    {
      "x": -1,
      "y": 5,
      "z": -7,
      "name": "Soil_Gravel_Half",
      "support": 15,
      "rotation": 5
    },
    {
      "x": -1,
      "y": 6,
      "z": -7,
      "name": "Soil_Gravel_Half",
      "support": 15,
      "rotation": 5
    },
    {
      "x": -1,
      "y": 7,
      "z": -7,
      "name": "Soil_Gravel_Half",
      "support": 15,
      "rotation": 5
    },
    {
      "x": -1,
      "y": 8,
      "z": -7,
      "name": "Soil_Gravel_Half",
      "support": 15,
      "rotation": 5
    },
    {
      "x": -1,
      "y": 9,
      "z": -7,
      "name": "Rock_Stone_Brick_Smooth"
    },
    {
      "x": -1,
      "y": 3,
      "z": -6,
      "name": "Rock_Stone_Brick"
    },
    {
      "x": -1,
      "y": 4,
      "z": -6,
      "name": "Rock_Stone_Brick_Decorative"
    },
    {
      "x": -1,
      "y": 5,
      "z": -6,
      "name": "Soil_Gravel_Half",
      "support": 15,
      "rotation": 5
    },
    {
      "x": -1,
      "y": 6,
      "z": -6,
      "name": "Soil_Gravel_Half",
      "support": 15,
      "rotation": 5
    },
    {
      "x": -1,
      "y": 7,
      "z": -6,
      "name": "Soil_Gravel_Half",
      "support": 15,
      "rotation": 5
    },
    {
      "x": -1,
      "y": 8,
      "z": -6,
      "name": "Soil_Gravel_Half",
      "support": 15,
      "rotation": 5
    },
    {
      "x": -1,
      "y": 9,
      "z": -6,
      "name": "Rock_Stone_Brick_Smooth",
      "rotation": 1
    },
    {
      "x": -1,
      "y": 3,
      "z": -5,
      "name": "Rock_Stone_Brick_Smooth"
    },
    {
      "x": -1,
      "y": 4,
      "z": -5,
      "name": "Rock_Stone_Brick_Decorative"
    },
    {
      "x": -1,
      "y": 5,
      "z": -5,
      "name": "Soil_Gravel_Half",
      "support": 15,
      "rotation": 5
    },
    {
      "x": -1,
      "y": 6,
      "z": -5,
      "name": "Soil_Gravel_Half",
      "support": 15,
      "rotation": 5
    },
    {
      "x": -1,
      "y": 7,
      "z": -5,
      "name": "Soil_Gravel_Half",
      "support": 15,
      "rotation": 5
    },
    {
      "x": -1,
      "y": 8,
      "z": -5,
      "name": "Soil_Gravel_Half",
      "support": 15,
      "rotation": 5
    },
    {
      "x": -1,
      "y": 9,
      "z": -5,
      "name": "Rock_Stone_Brick_Smooth"
    },
    {
      "x": -1,
      "y": 3,
      "z": -4,
      "name": "Rock_Stone_Brick_Decorative",
      "rotation": 1
    },
    {
      "x": -1,
      "y": 4,
      "z": -4,
      "name": "Rock_Stone_Brick_Smooth",
      "rotation": 1
    },
    {
      "x": -1,
      "y": 5,
      "z": -4,
      "name": "Rock_Stone_Brick_Pillar_Base",
      "rotation": 3
    },
    {
      "x": -1,
      "y": 6,
      "z": -4,
      "name": "Rock_Stone_Brick_Pillar_Middle",
      "rotation": 3
    },
    {
      "x": -1,
      "y": 7,
      "z": -4,
      "name": "Rock_Stone_Brick_Pillar_Middle",
      "rotation": 3
    },
    {
      "x": -1,
      "y": 8,
      "z": -4,
      "name": "Rock_Stone_Brick_Pillar_Base",
      "rotation": 33
    },
    {
      "x": -1,
      "y": 9,
      "z": -4,
      "name": "Rock_Stone_Brick_Decorative",
      "rotation": 1
    },
    {
      "x": -1,
      "y": 10,
      "z": -4,
      "name": "Rock_Stone_Brick",
      "rotation": 1
    },
    {
      "x": -1,
      "y": 11,
      "z": -4,
      "name": "Rock_Stone_Brick",
      "rotation": 1
    },
    {
      "x": -1,
      "y": 12,
      "z": -4,
      "name": "Rock_Stone_Brick",
      "rotation": 1
    },
    {
      "x": -1,
      "y": 3,
      "z": -3,
      "name": "Rock_Stone_Brick_Smooth_Stairs"
    },
    {
      "x": -1,
      "y": 9,
      "z": -3,
      "name": "Rock_Stone_Brick_Smooth_Half",
      "rotation": 4
    },
    {
      "x": -1,
      "y": 10,
      "z": -3,
      "name": "Rock_Stone_Brick_Half",
      "rotation": 4
    },
    {
      "x": -1,
      "y": 11,
      "z": -3,
      "name": "Rock_Stone_Brick_Half",
      "rotation": 4
    },
    {
      "x": -1,
      "y": 12,
      "z": -3,
      "name": "Rock_Stone_Brick",
      "rotation": 1
    },
    {
      "x": -1,
      "y": 13,
      "z": -3,
      "name": "Rock_Stone_Brick",
      "rotation": 1
    },
    {
      "x": -1,
      "y": 3,
      "z": -2,
      "name": "Soil_Gravel",
      "support": 15
    },
    {
      "x": -1,
      "y": 12,
      "z": -2,
      "name": "Rock_Stone_Brick_Half",
      "rotation": 33
    },
    {
      "x": -1,
      "y": 13,
      "z": -2,
      "name": "Rock_Stone_Brick",
      "rotation": 1
    },
    {
      "x": -1,
      "y": 14,
      "z": -2,
      "name": "Rock_Stone_Brick",
      "rotation": 1
    },
    {
      "x": -1,
      "y": 3,
      "z": -1,
      "name": "Soil_Gravel",
      "support": 15
    },
    {
      "x": -1,
      "y": 13,
      "z": -1,
      "name": "Rock_Stone_Brick",
      "rotation": 1
    },
    {
      "x": -1,
      "y": 14,
      "z": -1,
      "name": "Rock_Stone_Brick",
      "rotation": 1
    },
    {
      "x": -1,
      "y": 3,
      "z": 0,
      "name": "Soil_Gravel",
      "support": 15
    },
    {
      "x": -1,
      "y": 13,
      "z": 0,
      "name": "Rock_Stone_Brick_Half",
      "rotation": 33
    },
    {
      "x": -1,
      "y": 14,
      "z": 0,
      "name": "Rock_Stone_Brick",
      "rotation": 1
    },
    {
      "x": -1,
      "y": 20,
      "z": 0,
      "name": "Cloth_Block_Wool_Green",
      "rotation": 3
    },
    {
      "x": -1,
      "y": 3,
      "z": 1,
      "name": "Rock_Stone_Brick_Smooth"
    },
    {
      "x": -1,
      "y": 4,
      "z": 1,
      "name": "Rock_Stone_Brick_Smooth"
    },
    {
      "x": -1,
      "y": 13,
      "z": 1,
      "name": "Rock_Stone_Brick_Half",
      "rotation": 33
    },
    {
      "x": -1,
      "y": 14,
      "z": 1,
      "name": "Rock_Stone_Brick",
      "rotation": 1
    },
    {
      "x": -1,
      "y": 15,
      "z": 1,
      "name": "Cloth_Block_Wool_Cyan",
      "rotation": 1
    },
    {
      "x": -1,
      "y": 16,
      "z": 1,
      "name": "Cloth_Block_Wool_Cyan",
      "rotation": 1
    },
    {
      "x": -1,
      "y": 17,
      "z": 1,
      "name": "Cloth_Block_Wool_Cyan",
      "rotation": 1
    },
    {
      "x": -1,
      "y": 20,
      "z": 1,
      "name": "Cloth_Block_Wool_Pink",
      "rotation": 2
    },
    {
      "x": -1,
      "y": 3,
      "z": 2,
      "name": "Rock_Stone_Brick_Smooth"
    },
    {
      "x": -1,
      "y": 4,
      "z": 2,
      "name": "Rock_Stone_Brick_Smooth_Half",
      "rotation": 5
    },
    {
      "x": -1,
      "y": 14,
      "z": 2,
      "name": "Rock_Stone_Brick_Half",
      "rotation": 5
    },
    {
      "x": -1,
      "y": 16,
      "z": 2,
      "name": "Cloth_Block_Wool_Cyan_Stairs",
      "rotation": 33
    },
    {
      "x": -1,
      "y": 17,
      "z": 2,
      "name": "Cloth_Block_Wool_Cyan",
      "rotation": 1
    },
    {
      "x": -1,
      "y": 3,
      "z": 3,
      "name": "Rock_Stone_Brick_Smooth"
    },
    {
      "x": -1,
      "y": 4,
      "z": 3,
      "name": "Rock_Stone_Brick_Smooth_Half",
      "rotation": 5
    },
    {
      "x": -1,
      "y": 14,
      "z": 3,
      "name": "Rock_Stone_Brick_Half",
      "rotation": 5
    },
    {
      "x": -1,
      "y": 16,
      "z": 3,
      "name": "Cloth_Block_Wool_Cyan_Stairs",
      "rotation": 33
    },
    {
      "x": -1,
      "y": 17,
      "z": 3,
      "name": "Cloth_Block_Wool_Cyan",
      "rotation": 1
    },
    {
      "x": -1,
      "y": 3,
      "z": 4,
      "name": "Rock_Stone_Brick_Smooth",
      "rotation": 2
    },
    {
      "x": -1,
      "y": 4,
      "z": 4,
      "name": "Rock_Stone_Brick_Smooth_Half",
      "rotation": 5
    },
    {
      "x": -1,
      "y": 14,
      "z": 4,
      "name": "Rock_Stone_Brick_Half",
      "rotation": 5
    },
    {
      "x": -1,
      "y": 16,
      "z": 4,
      "name": "Cloth_Block_Wool_Cyan_Stairs",
      "rotation": 33
    },
    {
      "x": -1,
      "y": 17,
      "z": 4,
      "name": "Cloth_Block_Wool_Cyan",
      "rotation": 3
    },
    {
      "x": -1,
      "y": 3,
      "z": 5,
      "name": "Rock_Stone_Brick_Smooth",
      "rotation": 2
    },
    {
      "x": -1,
      "y": 4,
      "z": 5,
      "name": "Rock_Stone_Brick_Smooth",
      "rotation": 2
    },
    {
      "x": -1,
      "y": 13,
      "z": 5,
      "name": "Rock_Stone_Brick_Half",
      "rotation": 33
    },
    {
      "x": -1,
      "y": 14,
      "z": 5,
      "name": "Rock_Stone_Brick",
      "rotation": 3
    },
    {
      "x": -1,
      "y": 15,
      "z": 5,
      "name": "Cloth_Block_Wool_Cyan",
      "rotation": 3
    },
    {
      "x": -1,
      "y": 16,
      "z": 5,
      "name": "Cloth_Block_Wool_Cyan",
      "rotation": 3
    },
    {
      "x": -1,
      "y": 17,
      "z": 5,
      "name": "Cloth_Block_Wool_Cyan",
      "rotation": 3
    },
    {
      "x": -1,
      "y": 3,
      "z": 6,
      "name": "Soil_Gravel",
      "support": 15,
      "rotation": 2
    },
    {
      "x": -1,
      "y": 13,
      "z": 6,
      "name": "Rock_Stone_Brick_Half",
      "rotation": 33
    },
    {
      "x": -1,
      "y": 14,
      "z": 6,
      "name": "Rock_Stone_Brick",
      "rotation": 3
    },
    {
      "x": -1,
      "y": 3,
      "z": 7,
      "name": "Soil_Gravel",
      "support": 15,
      "rotation": 2
    },
    {
      "x": -1,
      "y": 13,
      "z": 7,
      "name": "Rock_Stone_Brick",
      "rotation": 3
    },
    {
      "x": -1,
      "y": 14,
      "z": 7,
      "name": "Rock_Stone_Brick",
      "rotation": 3
    },
    {
      "x": -1,
      "y": 3,
      "z": 8,
      "name": "Soil_Gravel",
      "support": 15,
      "rotation": 2
    },
    {
      "x": -1,
      "y": 12,
      "z": 8,
      "name": "Rock_Stone_Brick_Half",
      "rotation": 33
    },
    {
      "x": -1,
      "y": 13,
      "z": 8,
      "name": "Rock_Stone_Brick",
      "rotation": 3
    },
    {
      "x": -1,
      "y": 14,
      "z": 8,
      "name": "Rock_Stone_Brick",
      "rotation": 3
    },
    {
      "x": -1,
      "y": 3,
      "z": 9,
      "name": "Rock_Stone_Brick_Smooth_Stairs",
      "rotation": 2
    },
    {
      "x": -1,
      "y": 9,
      "z": 9,
      "name": "Rock_Stone_Brick_Smooth_Half",
      "rotation": 6
    },
    {
      "x": -1,
      "y": 10,
      "z": 9,
      "name": "Rock_Stone_Brick_Half",
      "rotation": 6
    },
    {
      "x": -1,
      "y": 11,
      "z": 9,
      "name": "Rock_Stone_Brick_Half",
      "rotation": 6
    },
    {
      "x": -1,
      "y": 12,
      "z": 9,
      "name": "Rock_Stone_Brick",
      "rotation": 3
    },
    {
      "x": -1,
      "y": 13,
      "z": 9,
      "name": "Rock_Stone_Brick",
      "rotation": 3
    },
    {
      "x": -1,
      "y": 3,
      "z": 10,
      "name": "Rock_Stone_Brick_Decorative",
      "rotation": 3
    },
    {
      "x": -1,
      "y": 4,
      "z": 10,
      "name": "Rock_Stone_Brick_Smooth",
      "rotation": 3
    },
    {
      "x": -1,
      "y": 5,
      "z": 10,
      "name": "Rock_Stone_Brick_Pillar_Base",
      "rotation": 3
    },
    {
      "x": -1,
      "y": 6,
      "z": 10,
      "name": "Rock_Stone_Brick_Pillar_Middle",
      "rotation": 3
    },
    {
      "x": -1,
      "y": 7,
      "z": 10,
      "name": "Rock_Stone_Brick_Pillar_Middle",
      "rotation": 3
    },
    {
      "x": -1,
      "y": 8,
      "z": 10,
      "name": "Rock_Stone_Brick_Pillar_Base",
      "rotation": 33
    },
    {
      "x": -1,
      "y": 9,
      "z": 10,
      "name": "Rock_Stone_Brick_Decorative",
      "rotation": 3
    },
    {
      "x": -1,
      "y": 10,
      "z": 10,
      "name": "Rock_Stone_Brick",
      "rotation": 3
    },
    {
      "x": -1,
      "y": 11,
      "z": 10,
      "name": "Rock_Stone_Brick",
      "rotation": 3
    },
    {
      "x": -1,
      "y": 12,
      "z": 10,
      "name": "Rock_Stone_Brick",
      "rotation": 3
    },
    {
      "x": -1,
      "y": 3,
      "z": 11,
      "name": "Rock_Stone_Brick"
    },
    {
      "x": -1,
      "y": 4,
      "z": 11,
      "name": "Rock_Stone_Brick_Decorative",
      "rotation": 3
    },
    {
      "x": -1,
      "y": 5,
      "z": 11,
      "name": "Soil_Gravel",
      "support": 15,
      "rotation": 3
    },
    {
      "x": -1,
      "y": 6,
      "z": 11,
      "name": "Soil_Gravel",
      "support": 15,
      "rotation": 3
    },
    {
      "x": -1,
      "y": 7,
      "z": 11,
      "name": "Soil_Gravel",
      "support": 15,
      "rotation": 3
    },
    {
      "x": -1,
      "y": 8,
      "z": 11,
      "name": "Soil_Gravel",
      "support": 15,
      "rotation": 3
    },
    {
      "x": -1,
      "y": 9,
      "z": 11,
      "name": "Rock_Stone_Brick_Smooth",
      "rotation": 3
    },
    {
      "x": -1,
      "y": 20,
      "z": 11,
      "name": "Cloth_Block_Wool_Pink",
      "rotation": 2
    },
    {
      "x": 0,
      "y": 20,
      "z": -10,
      "name": "Cloth_Block_Wool_Green",
      "rotation": 3
    },
    {
      "x": 0,
      "y": 20,
      "z": -9,
      "name": "Cloth_Block_Wool_Green",
      "rotation": 3
    },
    {
      "x": 0,
      "y": 3,
      "z": -8,
      "name": "Rock_Stone_Brick"
    },
    {
      "x": 0,
      "y": 4,
      "z": -8,
      "name": "Rock_Stone_Brick_Decorative"
    },
    {
      "x": 0,
      "y": 5,
      "z": -8,
      "name": "Soil_Gravel_Half",
      "support": 15,
      "rotation": 4
    },
    {
      "x": 0,
      "y": 6,
      "z": -8,
      "name": "Soil_Gravel_Half",
      "support": 15,
      "rotation": 4
    },
    {
      "x": 0,
      "y": 7,
      "z": -8,
      "name": "Soil_Gravel_Half",
      "support": 15,
      "rotation": 4
    },
    {
      "x": 0,
      "y": 8,
      "z": -8,
      "name": "Soil_Gravel_Half",
      "support": 15,
      "rotation": 4
    },
    {
      "x": 0,
      "y": 9,
      "z": -8,
      "name": "Rock_Stone_Brick_Smooth"
    },
    {
      "x": 0,
      "y": 20,
      "z": -8,
      "name": "Cloth_Block_Wool_Green",
      "rotation": 3
    },
    {
      "x": 0,
      "y": 3,
      "z": -7,
      "name": "Rock_Stone_Brick_Smooth"
    },
    {
      "x": 0,
      "y": 9,
      "z": -7,
      "name": "Rock_Stone_Brick_Smooth"
    },
    {
      "x": 0,
      "y": 20,
      "z": -7,
      "name": "Cloth_Block_Wool_Green",
      "rotation": 3
    },
    {
      "x": 0,
      "y": 3,
      "z": -6,
      "name": "Rock_Stone_Brick_Smooth"
    },
    {
      "x": 0,
      "y": 9,
      "z": -6,
      "name": "Rock_Stone_Brick_Smooth",
      "rotation": 1
    },
    {
      "x": 0,
      "y": 20,
      "z": -6,
      "name": "Cloth_Block_Wool_Green",
      "rotation": 3
    },
    {
      "x": 0,
      "y": 3,
      "z": -5,
      "name": "Rock_Stone_Brick_Smooth"
    },
    {
      "x": 0,
      "y": 9,
      "z": -5,
      "name": "Rock_Stone_Brick_Smooth"
    },
    {
      "x": 0,
      "y": 20,
      "z": -5,
      "name": "Cloth_Block_Wool_Green",
      "rotation": 3
    },
    {
      "x": 0,
      "y": 3,
      "z": -4,
      "name": "Rock_Stone_Brick_Smooth",
      "rotation": 1
    },
    {
      "x": 0,
      "y": 9,
      "z": -4,
      "name": "Rock_Stone_Brick_Decorative",
      "rotation": 1
    },
    {
      "x": 0,
      "y": 10,
      "z": -4,
      "name": "Soil_Gravel",
      "support": 15,
      "rotation": 1
    },
    {
      "x": 0,
      "y": 11,
      "z": -4,
      "name": "Soil_Gravel",
      "support": 15,
      "rotation": 1
    },
    {
      "x": 0,
      "y": 12,
      "z": -4,
      "name": "Soil_Gravel",
      "support": 15,
      "rotation": 1
    },
    {
      "x": 0,
      "y": 20,
      "z": -4,
      "name": "Cloth_Block_Wool_Green",
      "rotation": 3
    },
    {
      "x": 0,
      "y": 3,
      "z": -3,
      "name": "Rock_Stone_Brick_Smooth_Stairs"
    },
    {
      "x": 0,
      "y": 9,
      "z": -3,
      "name": "Rock_Stone_Brick_Smooth_Half",
      "rotation": 4
    },
    {
      "x": 0,
      "y": 12,
      "z": -3,
      "name": "Cloth_Block_Wool_Cyan_Half",
      "rotation": 4
    },
    {
      "x": 0,
      "y": 13,
      "z": -3,
      "name": "Cloth_Block_Wool_Cyan",
      "rotation": 1
    },
    {
      "x": 0,
      "y": 20,
      "z": -3,
      "name": "Cloth_Block_Wool_Green",
      "rotation": 3
    },
    {
      "x": 0,
      "y": 3,
      "z": -2,
      "name": "Soil_Gravel",
      "support": 15
    },
    {
      "x": 0,
      "y": 13,
      "z": -2,
      "name": "Cloth_Block_Wool_Cyan_Half",
      "rotation": 33
    },
    {
      "x": 0,
      "y": 20,
      "z": -2,
      "name": "Cloth_Block_Wool_Green",
      "rotation": 3
    },
    {
      "x": 0,
      "y": 3,
      "z": -1,
      "name": "Soil_Gravel",
      "support": 15
    },
    {
      "x": 0,
      "y": 14,
      "z": -1,
      "name": "Cloth_Block_Wool_Cyan",
      "rotation": 1
    },
    {
      "x": 0,
      "y": 20,
      "z": -1,
      "name": "Cloth_Block_Wool_Green",
      "rotation": 3
    },
    {
      "x": 0,
      "y": 3,
      "z": 0,
      "name": "Soil_Gravel",
      "support": 15
    },
    {
      "x": 0,
      "y": 4,
      "z": 0,
      "name": "Rock_Stone_Brick_Smooth_Half",
      "rotation": 6
    },
    {
      "x": 0,
      "y": 9,
      "z": 0,
      "name": "Editor_Anchor"
    },
    {
      "x": 0,
      "y": 14,
      "z": 0,
      "name": "Cloth_Block_Wool_Cyan",
      "rotation": 1
    },
    {
      "x": 0,
      "y": 15,
      "z": 0,
      "name": "Cloth_Block_Wool_Cyan",
      "rotation": 1
    },
    {
      "x": 0,
      "y": 16,
      "z": 0,
      "name": "Cloth_Block_Wool_Cyan",
      "rotation": 1
    },
    {
      "x": 0,
      "y": 20,
      "z": 0,
      "name": "Cloth_Block_Wool_Green",
      "rotation": 3
    },
    {
      "x": 0,
      "y": 3,
      "z": 1,
      "name": "Rock_Stone_Brick_Smooth"
    },
    {
      "x": 0,
      "y": 4,
      "z": 1,
      "name": "Rock_Stone_Brick_Smooth_Half",
      "rotation": 4
    },
    {
      "x": 0,
      "y": 14,
      "z": 1,
      "name": "Rock_Stone_Brick_Half",
      "rotation": 4
    },
    {
      "x": 0,
      "y": 16,
      "z": 1,
      "name": "Cloth_Block_Wool_Cyan_Stairs",
      "rotation": 32
    },
    {
      "x": 0,
      "y": 17,
      "z": 1,
      "name": "Cloth_Block_Wool_Cyan",
      "rotation": 1
    },
    {
      "x": 0,
      "y": 20,
      "z": 1,
      "name": "Cloth_Block_Wool_Pink",
      "rotation": 2
    },
    {
      "x": 0,
      "y": 3,
      "z": 2,
      "name": "*Rock_Stone_Brick_Smooth_Half_State_Definitions_Block"
    },
    {
      "x": 0,
      "y": 16,
      "z": 2,
      "name": "Cloth_Block_Wool_Cyan_Half",
      "rotation": 33
    },
    {
      "x": 0,
      "y": 17,
      "z": 2,
      "name": "Cloth_Block_Wool_Cyan",
      "rotation": 1
    },
    {
      "x": 0,
      "y": 20,
      "z": 2,
      "name": "Cloth_Block_Wool_Pink",
      "rotation": 2
    },
    {
      "x": 0,
      "y": 3,
      "z": 3,
      "name": "*Rock_Stone_Brick_Smooth_Half_State_Definitions_Block"
    },
    {
      "x": 0,
      "y": 17,
      "z": 3,
      "name": "Cloth_Block_Wool_Cyan",
      "rotation": 1
    },
    {
      "x": 0,
      "y": 20,
      "z": 3,
      "name": "Cloth_Block_Wool_Pink",
      "rotation": 2
    },
    {
      "x": 0,
      "y": 3,
      "z": 4,
      "name": "*Rock_Stone_Brick_Smooth_Half_State_Definitions_Block",
      "rotation": 2
    },
    {
      "x": 0,
      "y": 16,
      "z": 4,
      "name": "Cloth_Block_Wool_Cyan_Half",
      "rotation": 33
    },
    {
      "x": 0,
      "y": 17,
      "z": 4,
      "name": "Cloth_Block_Wool_Cyan",
      "rotation": 3
    },
    {
      "x": 0,
      "y": 20,
      "z": 4,
      "name": "Cloth_Block_Wool_Pink",
      "rotation": 2
    },
    {
      "x": 0,
      "y": 3,
      "z": 5,
      "name": "Rock_Stone_Brick_Smooth",
      "rotation": 2
    },
    {
      "x": 0,
      "y": 4,
      "z": 5,
      "name": "Rock_Stone_Brick_Smooth_Half",
      "rotation": 6
    },
    {
      "x": 0,
      "y": 14,
      "z": 5,
      "name": "Rock_Stone_Brick_Half",
      "rotation": 6
    },
    {
      "x": 0,
      "y": 16,
      "z": 5,
      "name": "Cloth_Block_Wool_Cyan_Stairs",
      "rotation": 34
    },
    {
      "x": 0,
      "y": 17,
      "z": 5,
      "name": "Cloth_Block_Wool_Cyan",
      "rotation": 3
    },
    {
      "x": 0,
      "y": 20,
      "z": 5,
      "name": "Cloth_Block_Wool_Pink",
      "rotation": 2
    },
    {
      "x": 0,
      "y": 3,
      "z": 6,
      "name": "Soil_Gravel",
      "support": 15,
      "rotation": 2
    },
    {
      "x": 0,
      "y": 4,
      "z": 6,
      "name": "Rock_Stone_Brick_Smooth_Half",
      "rotation": 4
    },
    {
      "x": 0,
      "y": 14,
      "z": 6,
      "name": "Cloth_Block_Wool_Cyan",
      "rotation": 3
    },
    {
      "x": 0,
      "y": 15,
      "z": 6,
      "name": "Cloth_Block_Wool_Cyan",
      "rotation": 3
    },
    {
      "x": 0,
      "y": 16,
      "z": 6,
      "name": "Cloth_Block_Wool_Cyan",
      "rotation": 3
    },
    {
      "x": 0,
      "y": 20,
      "z": 6,
      "name": "Cloth_Block_Wool_Pink",
      "rotation": 2
    },
    {
      "x": 0,
      "y": 3,
      "z": 7,
      "name": "Soil_Gravel",
      "support": 15,
      "rotation": 2
    },
    {
      "x": 0,
      "y": 14,
      "z": 7,
      "name": "Cloth_Block_Wool_Cyan",
      "rotation": 3
    },
    {
      "x": 0,
      "y": 20,
      "z": 7,
      "name": "Cloth_Block_Wool_Pink",
      "rotation": 2
    },
    {
      "x": 0,
      "y": 3,
      "z": 8,
      "name": "Soil_Gravel",
      "support": 15,
      "rotation": 2
    },
    {
      "x": 0,
      "y": 13,
      "z": 8,
      "name": "Cloth_Block_Wool_Cyan_Half",
      "rotation": 33
    },
    {
      "x": 0,
      "y": 20,
      "z": 8,
      "name": "Cloth_Block_Wool_Pink",
      "rotation": 2
    },
    {
      "x": 0,
      "y": 3,
      "z": 9,
      "name": "Rock_Stone_Brick_Smooth_Stairs",
      "rotation": 2
    },
    {
      "x": 0,
      "y": 9,
      "z": 9,
      "name": "Rock_Stone_Brick_Smooth_Half",
      "rotation": 6
    },
    {
      "x": 0,
      "y": 12,
      "z": 9,
      "name": "Cloth_Block_Wool_Cyan_Half",
      "rotation": 6
    },
    {
      "x": 0,
      "y": 13,
      "z": 9,
      "name": "Cloth_Block_Wool_Cyan",
      "rotation": 3
    },
    {
      "x": 0,
      "y": 20,
      "z": 9,
      "name": "Cloth_Block_Wool_Pink",
      "rotation": 2
    },
    {
      "x": 0,
      "y": 3,
      "z": 10,
      "name": "Rock_Stone_Brick_Smooth",
      "rotation": 3
    },
    {
      "x": 0,
      "y": 9,
      "z": 10,
      "name": "Rock_Stone_Brick_Decorative",
      "rotation": 3
    },
    {
      "x": 0,
      "y": 10,
      "z": 10,
      "name": "Soil_Gravel",
      "support": 15,
      "rotation": 3
    },
    {
      "x": 0,
      "y": 11,
      "z": 10,
      "name": "Soil_Gravel",
      "support": 15,
      "rotation": 3
    },
    {
      "x": 0,
      "y": 12,
      "z": 10,
      "name": "Soil_Gravel",
      "support": 15,
      "rotation": 3
    },
    {
      "x": 0,
      "y": 20,
      "z": 10,
      "name": "Cloth_Block_Wool_Pink",
      "rotation": 2
    },
    {
      "x": 0,
      "y": 3,
      "z": 11,
      "name": "Rock_Stone_Brick"
    },
    {
      "x": 0,
      "y": 4,
      "z": 11,
      "name": "Rock_Stone_Brick_Decorative",
      "rotation": 3
    },
    {
      "x": 0,
      "y": 5,
      "z": 11,
      "name": "Soil_Gravel_Half",
      "support": 15,
      "rotation": 6
    },
    {
      "x": 0,
      "y": 6,
      "z": 11,
      "name": "Soil_Gravel_Half",
      "support": 15,
      "rotation": 6
    },
    {
      "x": 0,
      "y": 7,
      "z": 11,
      "name": "Soil_Gravel_Half",
      "support": 15,
      "rotation": 6
    },
    {
      "x": 0,
      "y": 8,
      "z": 11,
      "name": "Soil_Gravel_Half",
      "support": 15,
      "rotation": 6
    },
    {
      "x": 0,
      "y": 9,
      "z": 11,
      "name": "Rock_Stone_Brick_Smooth",
      "rotation": 3
    },
    {
      "x": 0,
      "y": 20,
      "z": 11,
      "name": "Cloth_Block_Wool_Pink",
      "rotation": 2
    },
    {
      "x": 1,
      "y": 20,
      "z": -10,
      "name": "Cloth_Block_Wool_Pink"
    },
    {
      "x": 1,
      "y": 20,
      "z": -9,
      "name": "Cloth_Block_Wool_Pink"
    },
    {
      "x": 1,
      "y": 3,
      "z": -8,
      "name": "Rock_Stone_Brick"
    },
    {
      "x": 1,
      "y": 4,
      "z": -8,
      "name": "Rock_Stone_Brick_Decorative"
    },
    {
      "x": 1,
      "y": 5,
      "z": -8,
      "name": "Soil_Gravel_Half",
      "support": 15,
      "rotation": 4
    },
    {
      "x": 1,
      "y": 6,
      "z": -8,
      "name": "Soil_Gravel_Half",
      "support": 15,
      "rotation": 4
    },
    {
      "x": 1,
      "y": 7,
      "z": -8,
      "name": "Soil_Gravel_Half",
      "support": 15,
      "rotation": 4
    },
    {
      "x": 1,
      "y": 8,
      "z": -8,
      "name": "Soil_Gravel_Half",
      "support": 15,
      "rotation": 4
    },
    {
      "x": 1,
      "y": 9,
      "z": -8,
      "name": "Rock_Stone_Brick_Smooth"
    },
    {
      "x": 1,
      "y": 20,
      "z": -8,
      "name": "Cloth_Block_Wool_Pink"
    },
    {
      "x": 1,
      "y": 3,
      "z": -7,
      "name": "Rock_Stone_Brick_Smooth"
    },
    {
      "x": 1,
      "y": 9,
      "z": -7,
      "name": "Rock_Stone_Brick_Smooth"
    },
    {
      "x": 1,
      "y": 20,
      "z": -7,
      "name": "Cloth_Block_Wool_Pink"
    },
    {
      "x": 1,
      "y": 3,
      "z": -6,
      "name": "Rock_Stone_Brick_Smooth"
    },
    {
      "x": 1,
      "y": 9,
      "z": -6,
      "name": "Rock_Stone_Brick_Smooth",
      "rotation": 2
    },
    {
      "x": 1,
      "y": 20,
      "z": -6,
      "name": "Cloth_Block_Wool_Pink"
    },
    {
      "x": 1,
      "y": 3,
      "z": -5,
      "name": "Rock_Stone_Brick_Smooth"
    },
    {
      "x": 1,
      "y": 9,
      "z": -5,
      "name": "*Rock_Stone_Brick_Smooth_Half_State_Definitions_Block",
      "rotation": 4
    },
    {
      "x": 1,
      "y": 20,
      "z": -5,
      "name": "Cloth_Block_Wool_Pink"
    },
    {
      "x": 1,
      "y": 3,
      "z": -4,
      "name": "Rock_Stone_Brick_Smooth",
      "rotation": 2
    },
    {
      "x": 1,
      "y": 9,
      "z": -4,
      "name": "Rock_Stone_Brick_Decorative",
      "rotation": 1
    },
    {
      "x": 1,
      "y": 10,
      "z": -4,
      "name": "Soil_Gravel",
      "support": 15,
      "rotation": 2
    },
    {
      "x": 1,
      "y": 11,
      "z": -4,
      "name": "Soil_Gravel",
      "support": 15,
      "rotation": 2
    },
    {
      "x": 1,
      "y": 12,
      "z": -4,
      "name": "Soil_Gravel",
      "support": 15,
      "rotation": 2
    },
    {
      "x": 1,
      "y": 20,
      "z": -4,
      "name": "Cloth_Block_Wool_Pink"
    },
    {
      "x": 1,
      "y": 3,
      "z": -3,
      "name": "Rock_Stone_Brick_Smooth_Stairs"
    },
    {
      "x": 1,
      "y": 9,
      "z": -3,
      "name": "Rock_Stone_Brick_Smooth_Half",
      "rotation": 4
    },
    {
      "x": 1,
      "y": 12,
      "z": -3,
      "name": "Cloth_Block_Wool_Cyan_Half",
      "rotation": 4
    },
    {
      "x": 1,
      "y": 13,
      "z": -3,
      "name": "Cloth_Block_Wool_Cyan",
      "rotation": 2
    },
    {
      "x": 1,
      "y": 20,
      "z": -3,
      "name": "Cloth_Block_Wool_Pink"
    },
    {
      "x": 1,
      "y": 3,
      "z": -2,
      "name": "Soil_Gravel",
      "support": 15,
      "rotation": 1
    },
    {
      "x": 1,
      "y": 13,
      "z": -2,
      "name": "Cloth_Block_Wool_Cyan_Half",
      "rotation": 32
    },
    {
      "x": 1,
      "y": 20,
      "z": -2,
      "name": "Cloth_Block_Wool_Pink"
    },
    {
      "x": 1,
      "y": 3,
      "z": -1,
      "name": "Soil_Gravel",
      "support": 15,
      "rotation": 1
    },
    {
      "x": 1,
      "y": 14,
      "z": -1,
      "name": "Cloth_Block_Wool_Cyan",
      "rotation": 2
    },
    {
      "x": 1,
      "y": 20,
      "z": -1,
      "name": "Cloth_Block_Wool_Pink"
    },
    {
      "x": 1,
      "y": 3,
      "z": 0,
      "name": "Soil_Gravel",
      "support": 15,
      "rotation": 1
    },
    {
      "x": 1,
      "y": 4,
      "z": 0,
      "name": "Rock_Stone_Brick_Smooth_Half",
      "rotation": 6
    },
    {
      "x": 1,
      "y": 14,
      "z": 0,
      "name": "Cloth_Block_Wool_Cyan",
      "rotation": 2
    },
    {
      "x": 1,
      "y": 15,
      "z": 0,
      "name": "Cloth_Block_Wool_Cyan",
      "rotation": 2
    },
    {
      "x": 1,
      "y": 16,
      "z": 0,
      "name": "Cloth_Block_Wool_Cyan",
      "rotation": 2
    },
    {
      "x": 1,
      "y": 20,
      "z": 0,
      "name": "Cloth_Block_Wool_Pink"
    },
    {
      "x": 1,
      "y": 3,
      "z": 1,
      "name": "Rock_Stone_Brick_Smooth",
      "rotation": 1
    },
    {
      "x": 1,
      "y": 4,
      "z": 1,
      "name": "Rock_Stone_Brick_Smooth_Half",
      "rotation": 4
    },
    {
      "x": 1,
      "y": 14,
      "z": 1,
      "name": "Rock_Stone_Brick_Half",
      "rotation": 4
    },
    {
      "x": 1,
      "y": 16,
      "z": 1,
      "name": "Cloth_Block_Wool_Cyan_Stairs",
      "rotation": 32
    },
    {
      "x": 1,
      "y": 17,
      "z": 1,
      "name": "Cloth_Block_Wool_Cyan",
      "rotation": 2
    },
    {
      "x": 1,
      "y": 20,
      "z": 1,
      "name": "Cloth_Block_Wool_Green",
      "rotation": 1
    },
    {
      "x": 1,
      "y": 3,
      "z": 2,
      "name": "*Rock_Stone_Brick_Smooth_Half_State_Definitions_Block",
      "rotation": 3
    },
    {
      "x": 1,
      "y": 17,
      "z": 2,
      "name": "Cloth_Block_Wool_Cyan",
      "rotation": 2
    },
    {
      "x": 1,
      "y": 20,
      "z": 2,
      "name": "Cloth_Block_Wool_Green",
      "rotation": 1
    },
    {
      "x": 1,
      "y": 3,
      "z": 3,
      "name": "*Rock_Stone_Brick_Smooth_Half_State_Definitions_Block",
      "rotation": 2
    },
    {
      "x": 1,
      "y": 17,
      "z": 3,
      "name": "Cloth_Block_Wool_Cyan",
      "rotation": 3
    },
    {
      "x": 1,
      "y": 20,
      "z": 3,
      "name": "Cloth_Block_Wool_Green",
      "rotation": 1
    },
    {
      "x": 1,
      "y": 3,
      "z": 4,
      "name": "*Rock_Stone_Brick_Smooth_Half_State_Definitions_Block",
      "rotation": 2
    },
    {
      "x": 1,
      "y": 17,
      "z": 4,
      "name": "Cloth_Block_Wool_Cyan",
      "rotation": 3
    },
    {
      "x": 1,
      "y": 20,
      "z": 4,
      "name": "Cloth_Block_Wool_Green",
      "rotation": 1
    },
    {
      "x": 1,
      "y": 3,
      "z": 5,
      "name": "Rock_Stone_Brick_Smooth",
      "rotation": 2
    },
    {
      "x": 1,
      "y": 4,
      "z": 5,
      "name": "Rock_Stone_Brick_Smooth_Half",
      "rotation": 6
    },
    {
      "x": 1,
      "y": 14,
      "z": 5,
      "name": "Rock_Stone_Brick_Half",
      "rotation": 6
    },
    {
      "x": 1,
      "y": 16,
      "z": 5,
      "name": "Cloth_Block_Wool_Cyan_Stairs",
      "rotation": 34
    },
    {
      "x": 1,
      "y": 17,
      "z": 5,
      "name": "Cloth_Block_Wool_Cyan",
      "rotation": 3
    },
    {
      "x": 1,
      "y": 20,
      "z": 5,
      "name": "Cloth_Block_Wool_Green",
      "rotation": 1
    },
    {
      "x": 1,
      "y": 3,
      "z": 6,
      "name": "Soil_Gravel",
      "support": 15,
      "rotation": 2
    },
    {
      "x": 1,
      "y": 4,
      "z": 6,
      "name": "Rock_Stone_Brick_Smooth_Half",
      "rotation": 4
    },
    {
      "x": 1,
      "y": 14,
      "z": 6,
      "name": "Cloth_Block_Wool_Cyan",
      "rotation": 3
    },
    {
      "x": 1,
      "y": 15,
      "z": 6,
      "name": "Cloth_Block_Wool_Cyan",
      "rotation": 3
    },
    {
      "x": 1,
      "y": 16,
      "z": 6,
      "name": "Cloth_Block_Wool_Cyan",
      "rotation": 3
    },
    {
      "x": 1,
      "y": 20,
      "z": 6,
      "name": "Cloth_Block_Wool_Green",
      "rotation": 1
    },
    {
      "x": 1,
      "y": 3,
      "z": 7,
      "name": "Soil_Gravel",
      "support": 15,
      "rotation": 2
    },
    {
      "x": 1,
      "y": 14,
      "z": 7,
      "name": "Cloth_Block_Wool_Cyan",
      "rotation": 3
    },
    {
      "x": 1,
      "y": 20,
      "z": 7,
      "name": "Cloth_Block_Wool_Green",
      "rotation": 1
    },
    {
      "x": 1,
      "y": 3,
      "z": 8,
      "name": "Soil_Gravel",
      "support": 15,
      "rotation": 2
    },
    {
      "x": 1,
      "y": 13,
      "z": 8,
      "name": "Cloth_Block_Wool_Cyan_Half",
      "rotation": 33
    },
    {
      "x": 1,
      "y": 20,
      "z": 8,
      "name": "Cloth_Block_Wool_Green",
      "rotation": 1
    },
    {
      "x": 1,
      "y": 3,
      "z": 9,
      "name": "Rock_Stone_Brick_Smooth_Stairs",
      "rotation": 2
    },
    {
      "x": 1,
      "y": 9,
      "z": 9,
      "name": "Rock_Stone_Brick_Smooth_Half",
      "rotation": 6
    },
    {
      "x": 1,
      "y": 12,
      "z": 9,
      "name": "Cloth_Block_Wool_Cyan_Half",
      "rotation": 6
    },
    {
      "x": 1,
      "y": 13,
      "z": 9,
      "name": "Cloth_Block_Wool_Cyan",
      "rotation": 3
    },
    {
      "x": 1,
      "y": 20,
      "z": 9,
      "name": "Cloth_Block_Wool_Green",
      "rotation": 1
    },
    {
      "x": 1,
      "y": 3,
      "z": 10,
      "name": "Rock_Stone_Brick_Smooth",
      "rotation": 3
    },
    {
      "x": 1,
      "y": 9,
      "z": 10,
      "name": "Rock_Stone_Brick_Decorative"
    },
    {
      "x": 1,
      "y": 10,
      "z": 10,
      "name": "Soil_Gravel",
      "support": 15,
      "rotation": 3
    },
    {
      "x": 1,
      "y": 11,
      "z": 10,
      "name": "Soil_Gravel",
      "support": 15,
      "rotation": 3
    },
    {
      "x": 1,
      "y": 12,
      "z": 10,
      "name": "Soil_Gravel",
      "support": 15,
      "rotation": 3
    },
    {
      "x": 1,
      "y": 20,
      "z": 10,
      "name": "Cloth_Block_Wool_Green",
      "rotation": 1
    },
    {
      "x": 1,
      "y": 3,
      "z": 11,
      "name": "Rock_Stone_Brick"
    },
    {
      "x": 1,
      "y": 4,
      "z": 11,
      "name": "Rock_Stone_Brick_Decorative",
      "rotation": 3
    },
    {
      "x": 1,
      "y": 5,
      "z": 11,
      "name": "Soil_Gravel_Half",
      "support": 15,
      "rotation": 6
    },
    {
      "x": 1,
      "y": 6,
      "z": 11,
      "name": "Soil_Gravel_Half",
      "support": 15,
      "rotation": 6
    },
    {
      "x": 1,
      "y": 7,
      "z": 11,
      "name": "Soil_Gravel_Half",
      "support": 15,
      "rotation": 6
    },
    {
      "x": 1,
      "y": 8,
      "z": 11,
      "name": "Soil_Gravel_Half",
      "support": 15,
      "rotation": 6
    },
    {
      "x": 1,
      "y": 9,
      "z": 11,
      "name": "Rock_Stone_Brick_Smooth",
      "rotation": 3
    },
    {
      "x": 1,
      "y": 20,
      "z": 11,
      "name": "Cloth_Block_Wool_Green",
      "rotation": 1
    },
    {
      "x": 2,
      "y": 20,
      "z": -10,
      "name": "Cloth_Block_Wool_Pink"
    },
    {
      "x": 2,
      "y": 3,
      "z": -8,
      "name": "Rock_Stone_Brick"
    },
    {
      "x": 2,
      "y": 4,
      "z": -8,
      "name": "Rock_Stone_Brick_Decorative"
    },
    {
      "x": 2,
      "y": 5,
      "z": -8,
      "name": "Soil_Gravel_Half",
      "support": 15,
      "rotation": 4
    },
    {
      "x": 2,
      "y": 6,
      "z": -8,
      "name": "Soil_Gravel_Half",
      "support": 15,
      "rotation": 4
    },
    {
      "x": 2,
      "y": 7,
      "z": -8,
      "name": "Soil_Gravel_Half",
      "support": 15,
      "rotation": 4
    },
    {
      "x": 2,
      "y": 8,
      "z": -8,
      "name": "Soil_Gravel_Half",
      "support": 15,
      "rotation": 4
    },
    {
      "x": 2,
      "y": 9,
      "z": -8,
      "name": "Rock_Stone_Brick_Smooth"
    },
    {
      "x": 2,
      "y": 3,
      "z": -7,
      "name": "Rock_Stone_Brick_Smooth"
    },
    {
      "x": 2,
      "y": 9,
      "z": -7,
      "name": "Rock_Stone_Brick_Smooth"
    },
    {
      "x": 2,
      "y": 3,
      "z": -6,
      "name": "Rock_Stone_Brick_Smooth"
    },
    {
      "x": 2,
      "y": 9,
      "z": -6,
      "name": "Rock_Stone_Brick_Smooth",
      "rotation": 1
    },
    {
      "x": 2,
      "y": 3,
      "z": -5,
      "name": "Rock_Stone_Brick_Smooth"
    },
    {
      "x": 2,
      "y": 9,
      "z": -5,
      "name": "Rock_Stone_Brick_Smooth"
    },
    {
      "x": 2,
      "y": 3,
      "z": -4,
      "name": "Rock_Stone_Brick_Smooth",
      "rotation": 1
    },
    {
      "x": 2,
      "y": 9,
      "z": -4,
      "name": "Rock_Stone_Brick_Decorative",
      "rotation": 1
    },
    {
      "x": 2,
      "y": 10,
      "z": -4,
      "name": "Soil_Gravel",
      "support": 15,
      "rotation": 1
    },
    {
      "x": 2,
      "y": 11,
      "z": -4,
      "name": "Soil_Gravel",
      "support": 15,
      "rotation": 1
    },
    {
      "x": 2,
      "y": 12,
      "z": -4,
      "name": "Soil_Gravel",
      "support": 15,
      "rotation": 1
    },
    {
