{
  "version": 8,
  "blockIdVersion": 11,
  "anchorX": 0,
  "anchorY": 22,
  "anchorZ": 0,
  "blocks": [
    {
      "x": -12,
      "y": 16,
      "z": -3,
      "name": "Rock_Stone_Brick"
    },
    {
      "x": -12,
      "y": 17,
      "z": -3,
      "name": "Rock_Stone_Brick_Decorative",
      "rotation": 1
    },
    {
      "x": -12,
      "y": 18,
      "z": -3,
      "name": "Soil_Gravel",
      "support": 15,
      "rotation": 1
    },
    {
      "x": -12,
      "y": 19,
      "z": -3,
      "name": "Soil_Gravel",
      "support": 15,
      "rotation": 1
    },
    {
      "x": -12,
      "y": 20,
      "z": -3,
      "name": "Soil_Gravel",
      "support": 15,
      "rotation": 1
    },
    {
      "x": -12,
      "y": 21,
      "z": -3,
      "name": "Soil_Gravel",
      "support": 15,
      "rotation": 1
    },
    {
      "x": -12,
      "y": 22,
      "z": -3,
      "name": "Rock_Stone_Brick_Smooth",
      "rotation": 1
    },
    {
      "x": -12,
      "y": 16,
      "z": -2,
      "name": "Rock_Stone_Brick"
    },
    {
      "x": -12,
      "y": 17,
      "z": -2,
      "name": "Rock_Stone_Brick_Decorative",
      "rotation": 1
    },
    {
      "x": -12,
      "y": 18,
      "z": -2,
      "name": "Soil_Gravel",
      "support": 15,
      "rotation": 1
    },
    {
      "x": -12,
      "y": 19,
      "z": -2,
      "name": "Soil_Gravel",
      "support": 15,
      "rotation": 1
    },
    {
      "x": -12,
      "y": 20,
      "z": -2,
      "name": "Soil_Gravel",
      "support": 15,
      "rotation": 1
    },
    {
      "x": -12,
      "y": 21,
      "z": -2,
      "name": "Soil_Gravel",
      "support": 15,
      "rotation": 1
    },
    {
      "x": -12,
      "y": 22,
      "z": -2,
      "name": "Rock_Stone_Brick_Smooth",
      "rotation": 1
    },
    {
      "x": -12,
      "y": 16,
      "z": -1,
      "name": "Rock_Stone_Brick"
    },
    {
      "x": -12,
      "y": 17,
      "z": -1,
      "name": "Rock_Stone_Brick_Decorative",
      "rotation": 1
    },
    {
      "x": -12,
      "y": 18,
      "z": -1,
      "name": "Soil_Gravel",
      "support": 15,
      "rotation": 1
    },
    {
      "x": -12,
      "y": 19,
      "z": -1,
      "name": "Soil_Gravel",
      "support": 15,
      "rotation": 1
    },
    {
      "x": -12,
      "y": 20,
      "z": -1,
      "name": "Soil_Gravel",
      "support": 15,
      "rotation": 1
    },
    {
      "x": -12,
      "y": 21,
      "z": -1,
      "name": "Soil_Gravel",
      "support": 15,
      "rotation": 1
    },
    {
      "x": -12,
      "y": 22,
      "z": -1,
      "name": "Rock_Stone_Brick_Smooth",
      "rotation": 1
    },
    {
      "x": -12,
      "y": 16,
      "z": 0,
      "name": "Rock_Stone_Brick"
    },
    {
      "x": -12,
      "y": 17,
      "z": 0,
      "name": "Rock_Stone_Brick_Decorative",
      "rotation": 2
    },
    {
      "x": -12,
      "y": 18,
      "z": 0,
      "name": "Soil_Gravel",
      "support": 15,
      "rotation": 2
    },
    {
      "x": -12,
      "y": 19,
      "z": 0,
      "name": "Soil_Gravel",
      "support": 15,
      "rotation": 2
    },
    {
      "x": -12,
      "y": 20,
      "z": 0,
      "name": "Soil_Gravel",
      "support": 15,
      "rotation": 2
    },
    {
      "x": -12,
      "y": 21,
      "z": 0,
      "name": "Soil_Gravel",
      "support": 15,
      "rotation": 2
    },
    {
      "x": -12,
      "y": 22,
      "z": 0,
      "name": "Rock_Stone_Brick_Smooth",
      "rotation": 2
    },
    {
      "x": -12,
      "y": 16,
      "z": 1,
      "name": "Rock_Stone_Brick"
    },
    {
      "x": -12,
      "y": 17,
      "z": 1,
      "name": "Rock_Stone_Brick_Decorative",
      "rotation": 2
    },
    {
      "x": -12,
      "y": 18,
      "z": 1,
      "name": "Soil_Gravel",
      "support": 15,
      "rotation": 2
    },
    {
      "x": -12,
      "y": 19,
      "z": 1,
      "name": "Soil_Gravel",
      "support": 15,
      "rotation": 2
    },
    {
      "x": -12,
      "y": 20,
      "z": 1,
      "name": "Soil_Gravel",
      "support": 15,
      "rotation": 2
    },
    {
      "x": -12,
      "y": 21,
      "z": 1,
      "name": "Soil_Gravel",
      "support": 15,
      "rotation": 2
    },
    {
      "x": -12,
      "y": 22,
      "z": 1,
      "name": "Rock_Stone_Brick_Smooth",
      "rotation": 2
    },
    {
      "x": -12,
      "y": 16,
      "z": 2,
      "name": "Rock_Stone_Brick"
    },
    {
      "x": -12,
      "y": 17,
      "z": 2,
      "name": "Rock_Stone_Brick_Decorative",
      "rotation": 2
    },
    {
      "x": -12,
      "y": 18,
      "z": 2,
      "name": "Soil_Gravel",
      "support": 15,
      "rotation": 2
    },
    {
      "x": -12,
      "y": 19,
      "z": 2,
      "name": "Soil_Gravel",
      "support": 15,
      "rotation": 2
    },
    {
      "x": -12,
      "y": 20,
      "z": 2,
      "name": "Soil_Gravel",
      "support": 15,
      "rotation": 2
    },
    {
      "x": -12,
      "y": 21,
      "z": 2,
      "name": "Soil_Gravel",
      "support": 15,
      "rotation": 2
    },
    {
      "x": -12,
      "y": 22,
      "z": 2,
      "name": "Rock_Stone_Brick_Smooth",
      "rotation": 2
    },
    {
      "x": -11,
      "y": 16,
      "z": -5,
      "name": "Rock_Stone_Brick"
    },
    {
      "x": -11,
      "y": 17,
      "z": -5,
      "name": "Rock_Stone_Brick_Decorative",
      "rotation": 1
    },
    {
      "x": -11,
      "y": 18,
      "z": -5,
      "name": "Soil_Gravel",
      "support": 15,
      "rotation": 1
    },
    {
      "x": -11,
      "y": 19,
      "z": -5,
      "name": "Soil_Gravel",
      "support": 15,
      "rotation": 1
    },
    {
      "x": -11,
      "y": 20,
      "z": -5,
      "name": "Soil_Gravel",
      "support": 15,
      "rotation": 1
    },
    {
      "x": -11,
      "y": 21,
      "z": -5,
      "name": "Soil_Gravel",
      "support": 15,
      "rotation": 1
    },
    {
      "x": -11,
      "y": 22,
      "z": -5,
      "name": "Rock_Stone_Brick_Smooth",
      "rotation": 1
    },
    {
      "x": -11,
      "y": 16,
      "z": -4,
      "name": "Rock_Stone_Brick"
    },
    {
      "x": -11,
      "y": 17,
      "z": -4,
      "name": "Rock_Stone_Brick_Decorative",
      "rotation": 1
    },
    {
      "x": -11,
      "y": 18,
      "z": -4,
      "name": "Soil_Gravel",
      "support": 15,
      "rotation": 1
    },
    {
      "x": -11,
      "y": 19,
      "z": -4,
      "name": "Soil_Gravel",
      "support": 15,
      "rotation": 1
    },
    {
      "x": -11,
      "y": 20,
      "z": -4,
      "name": "Soil_Gravel",
      "support": 15,
      "rotation": 1
    },
    {
      "x": -11,
      "y": 21,
      "z": -4,
      "name": "Soil_Gravel",
      "support": 15,
      "rotation": 1
    },
    {
      "x": -11,
      "y": 22,
      "z": -4,
      "name": "Rock_Stone_Brick_Smooth",
      "rotation": 1
    },
    {
      "x": -11,
      "y": 7,
      "z": -3,
      "name": "Rock_Stone_Brick"
    },
    {
      "x": -11,
      "y": 8,
      "z": -3,
      "name": "Rock_Stone_Brick"
    },
    {
      "x": -11,
      "y": 9,
      "z": -3,
      "name": "Rock_Stone_Brick"
    },
    {
      "x": -11,
      "y": 10,
      "z": -3,
      "name": "Rock_Stone_Brick"
    },
    {
      "x": -11,
      "y": 11,
      "z": -3,
      "name": "Rock_Stone_Brick"
    },
    {
      "x": -11,
      "y": 12,
      "z": -3,
      "name": "Rock_Stone_Brick"
    },
    {
      "x": -11,
      "y": 13,
      "z": -3,
      "name": "Rock_Stone_Brick"
    },
    {
      "x": -11,
      "y": 14,
      "z": -3,
      "name": "Rock_Stone_Brick"
    },
    {
      "x": -11,
      "y": 15,
      "z": -3,
      "name": "Rock_Stone_Brick"
    },
    {
      "x": -11,
      "y": 16,
      "z": -3,
      "name": "Rock_Stone_Brick",
      "rotation": 1
    },
    {
      "x": -11,
      "y": 17,
      "z": -3,
      "name": "Rock_Stone_Brick_Decorative",
      "rotation": 1
    },
    {
      "x": -11,
      "y": 18,
      "z": -3,
      "name": "Soil_Gravel_Half",
      "support": 15,
      "rotation": 5
    },
    {
      "x": -11,
      "y": 19,
      "z": -3,
      "name": "Soil_Gravel_Half",
      "support": 15,
      "rotation": 5
    },
    {
      "x": -11,
      "y": 20,
      "z": -3,
      "name": "Soil_Gravel_Half",
      "support": 15,
      "rotation": 5
    },
    {
      "x": -11,
      "y": 21,
      "z": -3,
      "name": "Soil_Gravel_Half",
      "support": 15,
      "rotation": 5
    },
    {
      "x": -11,
      "y": 22,
      "z": -3,
      "name": "Rock_Stone_Brick_Smooth",
      "rotation": 1
    },
    {
      "x": -11,
      "y": 7,
      "z": -2,
      "name": "Rock_Stone_Brick"
    },
    {
      "x": -11,
      "y": 8,
      "z": -2,
      "name": "Rock_Stone_Brick"
    },
    {
      "x": -11,
      "y": 9,
      "z": -2,
      "name": "Rock_Stone_Brick"
    },
    {
      "x": -11,
      "y": 10,
      "z": -2,
      "name": "Rock_Stone_Brick"
    },
    {
      "x": -11,
      "y": 11,
      "z": -2,
      "name": "Rock_Stone_Brick"
    },
    {
      "x": -11,
      "y": 12,
      "z": -2,
      "name": "Rock_Stone_Brick"
    },
    {
      "x": -11,
      "y": 13,
      "z": -2,
      "name": "Rock_Stone_Brick"
    },
    {
      "x": -11,
      "y": 14,
      "z": -2,
      "name": "Rock_Stone_Brick"
    },
    {
      "x": -11,
      "y": 15,
      "z": -2,
      "name": "Rock_Stone_Brick"
    },
    {
      "x": -11,
      "y": 16,
      "z": -2,
      "name": "Rock_Stone_Brick",
      "rotation": 1
    },
    {
      "x": -11,
      "y": 17,
      "z": -2,
      "name": "Rock_Stone_Brick_Decorative",
      "rotation": 1
    },
    {
      "x": -11,
      "y": 18,
      "z": -2,
      "name": "Rock_Stone_Brick_Pillar_Base",
      "rotation": 1
    },
    {
      "x": -11,
      "y": 19,
      "z": -2,
      "name": "Rock_Stone_Brick_Pillar_Middle",
      "rotation": 1
    },
    {
      "x": -11,
      "y": 20,
      "z": -2,
      "name": "Rock_Stone_Brick_Pillar_Middle",
      "rotation": 1
    },
    {
      "x": -11,
      "y": 21,
      "z": -2,
      "name": "Rock_Stone_Brick_Pillar_Base",
      "rotation": 35
    },
    {
      "x": -11,
      "y": 22,
      "z": -2,
      "name": "Rock_Stone_Brick_Smooth",
      "rotation": 1
    },
    {
      "x": -11,
      "y": 7,
      "z": -1,
      "name": "Rock_Stone_Brick"
    },
    {
      "x": -11,
      "y": 8,
      "z": -1,
      "name": "Rock_Stone_Brick"
    },
    {
      "x": -11,
      "y": 9,
      "z": -1,
      "name": "Rock_Stone_Brick"
    },
    {
      "x": -11,
      "y": 10,
      "z": -1,
      "name": "Rock_Stone_Brick"
    },
    {
      "x": -11,
      "y": 11,
      "z": -1,
      "name": "Rock_Stone_Brick"
    },
    {
      "x": -11,
      "y": 12,
      "z": -1,
      "name": "Rock_Stone_Brick"
    },
    {
      "x": -11,
      "y": 13,
      "z": -1,
      "name": "Rock_Stone_Brick"
    },
    {
      "x": -11,
      "y": 14,
      "z": -1,
      "name": "Rock_Stone_Brick"
    },
    {
      "x": -11,
      "y": 15,
      "z": -1,
      "name": "Rock_Stone_Brick"
    },
    {
      "x": -11,
      "y": 16,
      "z": -1,
      "name": "Rock_Stone_Brick",
      "rotation": 1
    },
    {
      "x": -11,
      "y": 17,
      "z": -1,
      "name": "Rock_Stone_Brick_Decorative",
      "rotation": 1
    },
    {
      "x": -11,
      "y": 18,
      "z": -1,
      "name": "Soil_Gravel_Half",
      "support": 15,
      "rotation": 5
    },
    {
      "x": -11,
      "y": 19,
      "z": -1,
      "name": "Soil_Gravel_Half",
      "support": 15,
      "rotation": 5
    },
    {
      "x": -11,
      "y": 20,
      "z": -1,
      "name": "Soil_Gravel_Half",
      "support": 15,
      "rotation": 5
    },
    {
      "x": -11,
      "y": 21,
      "z": -1,
      "name": "Soil_Gravel_Half",
      "support": 15,
      "rotation": 5
    },
    {
      "x": -11,
      "y": 22,
      "z": -1,
      "name": "Rock_Stone_Brick_Smooth",
      "rotation": 1
    },
    {
      "x": -11,
      "y": 7,
      "z": 0,
      "name": "Rock_Stone_Brick"
    },
    {
      "x": -11,
      "y": 8,
      "z": 0,
      "name": "Rock_Stone_Brick"
    },
    {
      "x": -11,
      "y": 9,
      "z": 0,
      "name": "Rock_Stone_Brick"
    },
    {
      "x": -11,
      "y": 10,
      "z": 0,
      "name": "Rock_Stone_Brick"
    },
    {
      "x": -11,
      "y": 11,
      "z": 0,
      "name": "Rock_Stone_Brick"
    },
    {
      "x": -11,
      "y": 12,
      "z": 0,
      "name": "Rock_Stone_Brick"
    },
    {
      "x": -11,
      "y": 13,
      "z": 0,
      "name": "Rock_Stone_Brick"
    },
    {
      "x": -11,
      "y": 14,
      "z": 0,
      "name": "Rock_Stone_Brick"
    },
    {
      "x": -11,
      "y": 15,
      "z": 0,
      "name": "Rock_Stone_Brick"
    },
    {
      "x": -11,
      "y": 16,
      "z": 0,
      "name": "Rock_Stone_Brick",
      "rotation": 2
    },
    {
      "x": -11,
      "y": 17,
      "z": 0,
      "name": "Rock_Stone_Brick_Decorative",
      "rotation": 2
    },
    {
      "x": -11,
      "y": 18,
      "z": 0,
      "name": "Soil_Gravel_Half",
      "support": 15,
      "rotation": 5
    },
    {
      "x": -11,
      "y": 19,
      "z": 0,
      "name": "Soil_Gravel_Half",
      "support": 15,
      "rotation": 5
    },
    {
      "x": -11,
      "y": 20,
      "z": 0,
      "name": "Soil_Gravel_Half",
      "support": 15,
      "rotation": 5
    },
    {
      "x": -11,
      "y": 21,
      "z": 0,
      "name": "Soil_Gravel_Half",
      "support": 15,
      "rotation": 5
    },
    {
      "x": -11,
      "y": 22,
      "z": 0,
      "name": "Rock_Stone_Brick_Smooth",
      "rotation": 2
    },
    {
      "x": -11,
      "y": 7,
      "z": 1,
      "name": "Rock_Stone_Brick"
    },
    {
      "x": -11,
      "y": 8,
      "z": 1,
      "name": "Rock_Stone_Brick"
    },
    {
      "x": -11,
      "y": 9,
      "z": 1,
      "name": "Rock_Stone_Brick"
    },
    {
      "x": -11,
      "y": 10,
      "z": 1,
      "name": "Rock_Stone_Brick"
    },
    {
      "x": -11,
      "y": 11,
      "z": 1,
      "name": "Rock_Stone_Brick"
    },
    {
      "x": -11,
      "y": 12,
      "z": 1,
      "name": "Rock_Stone_Brick"
    },
    {
      "x": -11,
      "y": 13,
      "z": 1,
      "name": "Rock_Stone_Brick"
    },
    {
      "x": -11,
      "y": 14,
      "z": 1,
      "name": "Rock_Stone_Brick"
    },
    {
      "x": -11,
      "y": 15,
      "z": 1,
      "name": "Rock_Stone_Brick"
    },
    {
      "x": -11,
      "y": 16,
      "z": 1,
      "name": "Rock_Stone_Brick",
      "rotation": 2
    },
    {
      "x": -11,
      "y": 17,
      "z": 1,
      "name": "Rock_Stone_Brick_Decorative",
      "rotation": 2
    },
    {
      "x": -11,
      "y": 18,
      "z": 1,
      "name": "Soil_Gravel_Half",
      "support": 15,
      "rotation": 5
    },
    {
      "x": -11,
      "y": 19,
      "z": 1,
      "name": "Soil_Gravel_Half",
      "support": 15,
      "rotation": 5
    },
    {
      "x": -11,
      "y": 20,
      "z": 1,
      "name": "Soil_Gravel_Half",
      "support": 15,
      "rotation": 5
    },
    {
      "x": -11,
      "y": 21,
      "z": 1,
      "name": "Soil_Gravel_Half",
      "support": 15,
      "rotation": 5
    },
    {
      "x": -11,
      "y": 22,
      "z": 1,
      "name": "Rock_Stone_Brick_Smooth",
      "rotation": 2
    },
    {
      "x": -11,
      "y": 7,
      "z": 2,
      "name": "Rock_Stone_Brick"
    },
    {
      "x": -11,
      "y": 8,
      "z": 2,
      "name": "Rock_Stone_Brick"
    },
    {
      "x": -11,
      "y": 9,
      "z": 2,
      "name": "Rock_Stone_Brick"
    },
    {
      "x": -11,
      "y": 10,
      "z": 2,
      "name": "Rock_Stone_Brick"
    },
    {
      "x": -11,
      "y": 11,
      "z": 2,
      "name": "Rock_Stone_Brick"
    },
    {
      "x": -11,
      "y": 12,
      "z": 2,
      "name": "Rock_Stone_Brick"
    },
    {
      "x": -11,
      "y": 13,
      "z": 2,
      "name": "Rock_Stone_Brick"
    },
    {
      "x": -11,
      "y": 14,
      "z": 2,
      "name": "Rock_Stone_Brick"
    },
    {
      "x": -11,
      "y": 15,
      "z": 2,
      "name": "Rock_Stone_Brick"
    },
    {
      "x": -11,
      "y": 16,
      "z": 2,
      "name": "Rock_Stone_Brick",
      "rotation": 2
    },
    {
      "x": -11,
      "y": 17,
      "z": 2,
      "name": "Rock_Stone_Brick_Decorative",
      "rotation": 2
    },
    {
      "x": -11,
      "y": 18,
      "z": 2,
      "name": "Rock_Stone_Brick_Pillar_Base",
      "rotation": 2
    },
    {
      "x": -11,
      "y": 19,
      "z": 2,
      "name": "Rock_Stone_Brick_Pillar_Middle",
      "rotation": 2
    },
    {
      "x": -11,
      "y": 20,
      "z": 2,
      "name": "Rock_Stone_Brick_Pillar_Middle",
      "rotation": 2
    },
    {
      "x": -11,
      "y": 21,
      "z": 2,
      "name": "Rock_Stone_Brick_Pillar_Base",
      "rotation": 32
    },
    {
      "x": -11,
      "y": 22,
      "z": 2,
      "name": "Rock_Stone_Brick_Smooth",
      "rotation": 2
    },
    {
      "x": -11,
      "y": 7,
      "z": 3,
      "name": "Rock_Stone_Brick"
    },
    {
      "x": -11,
      "y": 8,
      "z": 3,
      "name": "Rock_Stone_Brick"
    },
    {
      "x": -11,
      "y": 9,
      "z": 3,
      "name": "Rock_Stone_Brick"
    },
    {
      "x": -11,
      "y": 10,
      "z": 3,
      "name": "Rock_Stone_Brick"
    },
    {
      "x": -11,
      "y": 11,
      "z": 3,
      "name": "Rock_Stone_Brick"
    },
    {
      "x": -11,
      "y": 12,
      "z": 3,
      "name": "Rock_Stone_Brick"
    },
    {
      "x": -11,
      "y": 13,
      "z": 3,
      "name": "Rock_Stone_Brick"
    },
    {
      "x": -11,
      "y": 14,
      "z": 3,
      "name": "Rock_Stone_Brick"
    },
    {
      "x": -11,
      "y": 15,
      "z": 3,
      "name": "Rock_Stone_Brick"
    },
    {
      "x": -11,
      "y": 16,
      "z": 3,
      "name": "Rock_Stone_Brick",
      "rotation": 2
    },
    {
      "x": -11,
      "y": 17,
      "z": 3,
      "name": "Rock_Stone_Brick_Decorative",
      "rotation": 2
    },
    {
      "x": -11,
      "y": 18,
      "z": 3,
      "name": "Soil_Gravel_Half",
      "support": 15,
      "rotation": 5
    },
    {
      "x": -11,
      "y": 19,
      "z": 3,
      "name": "Soil_Gravel_Half",
      "support": 15,
      "rotation": 5
    },
    {
      "x": -11,
      "y": 20,
      "z": 3,
      "name": "Soil_Gravel_Half",
      "support": 15,
      "rotation": 5
    },
    {
      "x": -11,
      "y": 21,
      "z": 3,
      "name": "Soil_Gravel_Half",
      "support": 15,
      "rotation": 5
    },
    {
      "x": -11,
      "y": 22,
      "z": 3,
      "name": "Rock_Stone_Brick_Smooth",
      "rotation": 2
    },
    {
      "x": -11,
      "y": 14,
      "z": 4,
      "name": "Rock_Stone_Brick"
    },
    {
      "x": -11,
      "y": 15,
      "z": 4,
      "name": "Rock_Stone_Brick"
    },
    {
      "x": -11,
      "y": 16,
      "z": 4,
      "name": "Rock_Stone_Brick"
    },
    {
      "x": -11,
      "y": 17,
      "z": 4,
      "name": "Rock_Stone_Brick_Decorative",
      "rotation": 2
    },
    {
      "x": -11,
      "y": 18,
      "z": 4,
      "name": "Soil_Gravel",
      "support": 15,
      "rotation": 2
    },
    {
      "x": -11,
      "y": 19,
      "z": 4,
      "name": "Soil_Gravel",
      "support": 15,
      "rotation": 2
    },
    {
      "x": -11,
      "y": 20,
      "z": 4,
      "name": "Soil_Gravel",
      "support": 15,
      "rotation": 2
    },
    {
      "x": -11,
      "y": 21,
      "z": 4,
      "name": "Soil_Gravel",
      "support": 15,
      "rotation": 2
    },
    {
      "x": -11,
      "y": 22,
      "z": 4,
      "name": "Rock_Stone_Brick_Smooth",
      "rotation": 2
    },
    {
      "x": -11,
      "y": 16,
      "z": 5,
      "name": "Rock_Stone_Brick"
    },
    {
      "x": -11,
      "y": 17,
      "z": 5,
      "name": "Rock_Stone_Brick_Decorative",
      "rotation": 2
    },
    {
      "x": -11,
      "y": 18,
      "z": 5,
      "name": "Soil_Gravel",
      "support": 15,
      "rotation": 2
    },
    {
      "x": -11,
      "y": 19,
      "z": 5,
      "name": "Soil_Gravel",
      "support": 15,
      "rotation": 2
    },
    {
      "x": -11,
      "y": 20,
      "z": 5,
      "name": "Soil_Gravel",
      "support": 15,
      "rotation": 2
    },
    {
      "x": -11,
      "y": 21,
      "z": 5,
      "name": "Soil_Gravel",
      "support": 15,
      "rotation": 2
    },
    {
      "x": -11,
      "y": 22,
      "z": 5,
      "name": "Rock_Stone_Brick_Smooth",
      "rotation": 2
    },
    {
      "x": -10,
      "y": 16,
      "z": -7,
      "name": "Rock_Stone_Brick"
    },
    {
      "x": -10,
      "y": 17,
      "z": -7,
      "name": "Rock_Stone_Brick_Decorative",
      "rotation": 1
    },
    {
      "x": -10,
      "y": 18,
      "z": -7,
      "name": "Soil_Gravel",
      "support": 15,
      "rotation": 1
    },
    {
      "x": -10,
      "y": 19,
      "z": -7,
      "name": "Soil_Gravel",
      "support": 15,
      "rotation": 1
    },
    {
      "x": -10,
      "y": 20,
      "z": -7,
      "name": "Soil_Gravel",
      "support": 15,
      "rotation": 1
    },
    {
      "x": -10,
      "y": 21,
      "z": -7,
      "name": "Soil_Gravel",
      "support": 15,
      "rotation": 1
    },
    {
      "x": -10,
      "y": 22,
      "z": -7,
      "name": "Rock_Stone_Brick_Smooth",
      "rotation": 1
    },
    {
      "x": -10,
      "y": 16,
      "z": -6,
      "name": "Rock_Stone_Brick"
    },
    {
      "x": -10,
      "y": 17,
      "z": -6,
      "name": "Rock_Stone_Brick_Decorative",
      "rotation": 1
    },
    {
      "x": -10,
      "y": 18,
      "z": -6,
      "name": "Soil_Gravel",
      "support": 15,
      "rotation": 1
    },
    {
      "x": -10,
      "y": 19,
      "z": -6,
      "name": "Soil_Gravel",
      "support": 15,
      "rotation": 1
    },
    {
      "x": -10,
      "y": 20,
      "z": -6,
      "name": "Soil_Gravel",
      "support": 15,
      "rotation": 1
    },
    {
      "x": -10,
      "y": 21,
      "z": -6,
      "name": "Soil_Gravel",
      "support": 15,
      "rotation": 1
    },
    {
      "x": -10,
      "y": 22,
      "z": -6,
      "name": "Rock_Stone_Brick_Smooth",
      "rotation": 1
    },
    {
      "x": -10,
      "y": 7,
      "z": -5,
      "name": "Rock_Stone_Brick"
    },
    {
      "x": -10,
      "y": 8,
      "z": -5,
      "name": "Rock_Stone_Brick"
    },
    {
      "x": -10,
      "y": 9,
      "z": -5,
      "name": "Rock_Stone_Brick"
    },
    {
      "x": -10,
      "y": 10,
      "z": -5,
      "name": "Rock_Stone_Brick"
    },
    {
      "x": -10,
      "y": 11,
      "z": -5,
      "name": "Rock_Stone_Brick"
    },
    {
      "x": -10,
      "y": 12,
      "z": -5,
      "name": "Rock_Stone_Brick"
    },
    {
      "x": -10,
      "y": 13,
      "z": -5,
      "name": "Rock_Stone_Brick"
    },
    {
      "x": -10,
      "y": 14,
      "z": -5,
      "name": "Rock_Stone_Brick"
    },
    {
      "x": -10,
      "y": 15,
      "z": -5,
      "name": "Rock_Stone_Brick"
    },
    {
      "x": -10,
      "y": 16,
      "z": -5,
      "name": "Rock_Stone_Brick",
      "rotation": 1
    },
    {
      "x": -10,
      "y": 17,
      "z": -5,
      "name": "Rock_Stone_Brick_Decorative",
      "rotation": 1
    },
    {
      "x": -10,
      "y": 18,
      "z": -5,
      "name": "Rock_Stone_Brick_Pillar_Base",
      "rotation": 1
    },
    {
      "x": -10,
      "y": 19,
      "z": -5,
      "name": "Rock_Stone_Brick_Pillar_Middle",
      "rotation": 1
    },
    {
      "x": -10,
      "y": 20,
      "z": -5,
      "name": "Rock_Stone_Brick_Pillar_Middle",
      "rotation": 1
    },
    {
      "x": -10,
      "y": 21,
      "z": -5,
      "name": "Rock_Stone_Brick_Pillar_Base",
      "rotation": 35
    },
    {
      "x": -10,
      "y": 22,
      "z": -5,
      "name": "Rock_Stone_Brick_Smooth",
      "rotation": 1
    },
    {
      "x": -10,
      "y": 7,
      "z": -4,
      "name": "Rock_Stone_Brick_Half",
      "rotation": 5
    },
    {
      "x": -10,
      "y": 8,
      "z": -4,
      "name": "Rock_Stone_Brick_Smooth"
    },
    {
      "x": -10,
      "y": 9,
      "z": -4,
      "name": "Rock_Stone_Brick_Half",
      "rotation": 5
    },
    {
      "x": -10,
      "y": 10,
      "z": -4,
      "name": "Rock_Stone_Brick_Half",
      "rotation": 5
    },
    {
      "x": -10,
      "y": 11,
      "z": -4,
      "name": "Rock_Stone_Brick_Half",
      "rotation": 5
    },
    {
      "x": -10,
      "y": 12,
      "z": -4,
      "name": "Rock_Stone_Brick_Half",
      "rotation": 5
    },
    {
      "x": -10,
      "y": 13,
      "z": -4,
      "name": "Rock_Stone_Brick_Half",
      "rotation": 5
    },
    {
      "x": -10,
      "y": 14,
      "z": -4,
      "name": "Rock_Stone_Brick_Smooth"
    },
    {
      "x": -10,
      "y": 15,
      "z": -4,
      "name": "Rock_Stone_Brick_Smooth"
    },
    {
      "x": -10,
      "y": 16,
      "z": -4,
      "name": "Rock_Stone_Brick_Half",
      "rotation": 5
    },
    {
      "x": -10,
      "y": 17,
      "z": -4,
      "name": "Rock_Stone_Brick_Half",
      "rotation": 5
    },
    {
      "x": -10,
      "y": 22,
      "z": -4,
      "name": "Rock_Stone_Brick_Smooth",
      "rotation": 1
    },
    {
      "x": -10,
      "y": 8,
      "z": -3,
      "name": "Rock_Stone_Brick_Smooth"
    },
    {
      "x": -10,
      "y": 14,
      "z": -3,
      "name": "Rock_Stone_Brick_Smooth"
    },
    {
      "x": -10,
      "y": 15,
      "z": -3,
      "name": "Rock_Stone_Brick_Smooth"
    },
    {
      "x": -10,
      "y": 22,
      "z": -3,
      "name": "Rock_Stone_Brick_Smooth",
      "rotation": 1
    },
    {
      "x": -10,
      "y": 8,
      "z": -2,
      "name": "Rock_Stone_Brick_Smooth"
    },
    {
      "x": -10,
      "y": 14,
      "z": -2,
      "name": "Rock_Stone_Brick_Smooth"
    },
    {
      "x": -10,
      "y": 15,
      "z": -2,
      "name": "Rock_Stone_Brick_Smooth"
    },
    {
      "x": -10,
      "y": 22,
      "z": -2,
      "name": "Rock_Stone_Brick_Smooth",
      "rotation": 1
    },
    {
      "x": -10,
      "y": 8,
      "z": -1,
      "name": "Rock_Stone_Brick_Smooth"
    },
    {
      "x": -10,
      "y": 14,
      "z": -1,
      "name": "Rock_Stone_Brick_Smooth"
    },
    {
      "x": -10,
      "y": 15,
      "z": -1,
      "name": "Rock_Stone_Brick_Smooth"
    },
    {
      "x": -10,
      "y": 22,
      "z": -1,
      "name": "Rock_Stone_Brick_Smooth",
      "rotation": 1
    },
    {
      "x": -10,
      "y": 7,
      "z": 0,
      "name": "Rock_Stone_Brick_Smooth_Half",
      "rotation": 8
    },
    {
      "x": -10,
      "y": 8,
      "z": 0,
      "name": "Rock_Stone_Brick_Smooth"
    },
    {
      "x": -10,
      "y": 13,
      "z": 0,
      "name": "Rock_Stone_Brick_Smooth_Half",
      "rotation": 8
    },
    {
      "x": -10,
      "y": 14,
      "z": 0,
      "name": "Rock_Stone_Brick_Smooth"
    },
    {
      "x": -10,
      "y": 15,
      "z": 0,
      "name": "Rock_Stone_Brick_Smooth_Half"
    },
    {
      "x": -10,
      "y": 22,
      "z": 0,
      "name": "Rock_Stone_Brick_Smooth",
      "rotation": 2
    },
    {
      "x": -10,
      "y": 7,
      "z": 1,
      "name": "Rock_Stone_Brick_Smooth"
    },
    {
      "x": -10,
      "y": 8,
      "z": 1,
      "name": "Rock_Stone_Brick_Smooth_Half"
    },
    {
      "x": -10,
      "y": 13,
      "z": 1,
      "name": "Rock_Stone_Brick_Smooth"
    },
    {
      "x": -10,
      "y": 14,
      "z": 1,
      "name": "Rock_Stone_Brick_Smooth"
    },
    {
      "x": -10,
      "y": 15,
      "z": 1,
      "name": "Rock_Stone_Brick_Smooth_Half"
    },
    {
      "x": -10,
      "y": 22,
      "z": 1,
      "name": "Rock_Stone_Brick_Smooth",
      "rotation": 2
    },
    {
      "x": -10,
      "y": 7,
      "z": 2,
      "name": "Rock_Stone_Brick_Smooth"
    },
    {
      "x": -10,
      "y": 8,
      "z": 2,
      "name": "Rock_Stone_Brick_Smooth_Half"
    },
    {
      "x": -10,
      "y": 13,
      "z": 2,
      "name": "Rock_Stone_Brick_Smooth"
    },
    {
      "x": -10,
      "y": 14,
      "z": 2,
      "name": "Rock_Stone_Brick_Smooth"
    },
    {
      "x": -10,
      "y": 22,
      "z": 2,
      "name": "Rock_Stone_Brick_Smooth",
      "rotation": 2
    },
    {
      "x": -10,
      "y": 7,
      "z": 3,
      "name": "Rock_Stone_Brick_Smooth"
    },
    {
      "x": -10,
      "y": 8,
      "z": 3,
      "name": "Rock_Stone_Brick_Smooth_Half"
    },
    {
      "x": -10,
      "y": 13,
      "z": 3,
      "name": "Rock_Stone_Brick"
    },
    {
      "x": -10,
      "y": 14,
      "z": 3,
      "name": "Rock_Stone_Brick_Smooth"
    },
    {
      "x": -10,
      "y": 22,
      "z": 3,
      "name": "Rock_Stone_Brick_Smooth",
      "rotation": 2
    },
    {
      "x": -10,
      "y": 7,
      "z": 4,
      "name": "Rock_Stone_Brick_Smooth"
    },
    {
      "x": -10,
      "y": 8,
      "z": 4,
      "name": "Rock_Stone_Brick_Half",
      "rotation": 5
    },
    {
      "x": -10,
      "y": 9,
      "z": 4,
      "name": "Rock_Stone_Brick_Half",
      "rotation": 5
    },
    {
      "x": -10,
      "y": 10,
      "z": 4,
      "name": "Rock_Stone_Brick_Half",
      "rotation": 5
    },
    {
      "x": -10,
      "y": 11,
      "z": 4,
      "name": "Rock_Stone_Brick_Half",
      "rotation": 5
    },
    {
      "x": -10,
      "y": 12,
      "z": 4,
      "name": "Rock_Stone_Brick_Half",
      "rotation": 5
    },
    {
      "x": -10,
      "y": 13,
      "z": 4,
      "name": "Rock_Stone_Brick"
    },
    {
      "x": -10,
      "y": 14,
      "z": 4,
      "name": "Rock_Stone_Brick_Smooth"
    },
    {
      "x": -10,
      "y": 15,
      "z": 4,
      "name": "Rock_Stone_Brick_Half",
      "rotation": 5
    },
    {
      "x": -10,
      "y": 16,
      "z": 4,
      "name": "Rock_Stone_Brick_Half",
      "rotation": 5
    },
    {
      "x": -10,
      "y": 17,
      "z": 4,
      "name": "Rock_Stone_Brick_Half",
      "rotation": 5
    },
    {
      "x": -10,
      "y": 22,
      "z": 4,
      "name": "Rock_Stone_Brick_Smooth",
      "rotation": 2
    },
    {
      "x": -10,
      "y": 7,
      "z": 5,
      "name": "Rock_Stone_Brick"
    },
    {
      "x": -10,
      "y": 8,
      "z": 5,
      "name": "Rock_Stone_Brick"
    },
    {
      "x": -10,
      "y": 9,
      "z": 5,
      "name": "Rock_Stone_Brick"
    },
    {
      "x": -10,
      "y": 10,
      "z": 5,
      "name": "Rock_Stone_Brick"
    },
    {
      "x": -10,
      "y": 11,
      "z": 5,
      "name": "Rock_Stone_Brick"
    },
    {
      "x": -10,
      "y": 12,
      "z": 5,
      "name": "Rock_Stone_Brick"
    },
    {
      "x": -10,
      "y": 13,
      "z": 5,
      "name": "Rock_Stone_Brick"
    },
    {
      "x": -10,
      "y": 14,
      "z": 5,
      "name": "Rock_Stone_Brick"
    },
    {
      "x": -10,
      "y": 15,
      "z": 5,
      "name": "Rock_Stone_Brick"
    },
    {
      "x": -10,
      "y": 16,
      "z": 5,
      "name": "Rock_Stone_Brick",
      "rotation": 2
    },
    {
      "x": -10,
      "y": 17,
      "z": 5,
      "name": "Rock_Stone_Brick_Decorative",
      "rotation": 2
    },
    {
      "x": -10,
      "y": 18,
      "z": 5,
      "name": "Rock_Stone_Brick_Pillar_Base",
      "rotation": 2
    },
    {
      "x": -10,
      "y": 19,
      "z": 5,
      "name": "Rock_Stone_Brick_Pillar_Middle",
      "rotation": 2
    },
    {
      "x": -10,
      "y": 20,
      "z": 5,
      "name": "Rock_Stone_Brick_Pillar_Middle",
      "rotation": 2
    },
    {
      "x": -10,
      "y": 21,
      "z": 5,
      "name": "Rock_Stone_Brick_Pillar_Base",
      "rotation": 32
    },
    {
      "x": -10,
      "y": 22,
      "z": 5,
      "name": "Rock_Stone_Brick_Smooth",
      "rotation": 2
    },
    {
      "x": -10,
      "y": 14,
      "z": 6,
      "name": "Rock_Stone_Brick"
    },
    {
      "x": -10,
      "y": 15,
      "z": 6,
      "name": "Rock_Stone_Brick"
    },
    {
      "x": -10,
      "y": 16,
      "z": 6,
      "name": "Rock_Stone_Brick"
    },
    {
      "x": -10,
      "y": 17,
      "z": 6,
      "name": "Rock_Stone_Brick_Decorative",
      "rotation": 2
    },
    {
      "x": -10,
      "y": 18,
      "z": 6,
      "name": "Soil_Gravel",
      "support": 15,
      "rotation": 2
    },
    {
      "x": -10,
      "y": 19,
      "z": 6,
      "name": "Soil_Gravel",
      "support": 15,
      "rotation": 2
    },
    {
      "x": -10,
      "y": 20,
      "z": 6,
      "name": "Soil_Gravel",
      "support": 15,
      "rotation": 2
    },
    {
      "x": -10,
      "y": 21,
      "z": 6,
      "name": "Soil_Gravel",
      "support": 15,
      "rotation": 2
    },
    {
      "x": -10,
      "y": 22,
      "z": 6,
      "name": "Rock_Stone_Brick_Smooth",
      "rotation": 2
    },
    {
      "x": -10,
      "y": 16,
      "z": 7,
      "name": "Rock_Stone_Brick"
    },
    {
      "x": -10,
      "y": 17,
      "z": 7,
      "name": "Rock_Stone_Brick_Decorative",
      "rotation": 2
    },
    {
      "x": -10,
      "y": 18,
      "z": 7,
      "name": "Soil_Gravel",
      "support": 15,
      "rotation": 2
    },
    {
      "x": -10,
      "y": 19,
      "z": 7,
      "name": "Soil_Gravel",
      "support": 15,
      "rotation": 2
    },
    {
      "x": -10,
      "y": 20,
      "z": 7,
      "name": "Soil_Gravel",
      "support": 15,
      "rotation": 2
    },
    {
      "x": -10,
      "y": 21,
      "z": 7,
      "name": "Soil_Gravel",
      "support": 15,
      "rotation": 2
    },
    {
      "x": -10,
      "y": 22,
      "z": 7,
      "name": "Rock_Stone_Brick_Smooth",
      "rotation": 2
    },
    {
      "x": -9,
      "y": 16,
      "z": -8,
      "name": "Rock_Stone_Brick"
    },
    {
      "x": -9,
      "y": 17,
      "z": -8,
      "name": "Rock_Stone_Brick_Decorative",
      "rotation": 1
    },
    {
      "x": -9,
      "y": 18,
      "z": -8,
      "name": "Soil_Gravel",
      "support": 15,
      "rotation": 1
    },
    {
      "x": -9,
      "y": 19,
      "z": -8,
      "name": "Soil_Gravel",
      "support": 15,
      "rotation": 1
    },
    {
      "x": -9,
      "y": 20,
      "z": -8,
      "name": "Soil_Gravel",
      "support": 15,
      "rotation": 1
    },
    {
      "x": -9,
      "y": 21,
      "z": -8,
      "name": "Soil_Gravel",
      "support": 15,
      "rotation": 1
    },
    {
      "x": -9,
      "y": 22,
      "z": -8,
      "name": "Rock_Stone_Brick_Smooth",
      "rotation": 1
    },
    {
      "x": -9,
      "y": 7,
      "z": -7,
      "name": "Rock_Stone_Brick"
    },
    {
      "x": -9,
      "y": 8,
      "z": -7,
      "name": "Rock_Stone_Brick"
    },
    {
      "x": -9,
      "y": 9,
      "z": -7,
      "name": "Rock_Stone_Brick"
    },
    {
      "x": -9,
      "y": 10,
      "z": -7,
      "name": "Rock_Stone_Brick"
    },
    {
      "x": -9,
      "y": 11,
      "z": -7,
      "name": "Rock_Stone_Brick"
    },
    {
      "x": -9,
      "y": 12,
      "z": -7,
      "name": "Rock_Stone_Brick"
    },
    {
      "x": -9,
      "y": 13,
      "z": -7,
      "name": "Rock_Stone_Brick"
    },
    {
      "x": -9,
      "y": 14,
      "z": -7,
      "name": "Rock_Stone_Brick"
    },
    {
      "x": -9,
      "y": 15,
      "z": -7,
      "name": "Rock_Stone_Brick"
    },
    {
      "x": -9,
      "y": 16,
      "z": -7,
      "name": "Rock_Stone_Brick",
      "rotation": 1
    },
    {
      "x": -9,
      "y": 17,
      "z": -7,
      "name": "Rock_Stone_Brick_Decorative",
      "rotation": 1
    },
    {
      "x": -9,
      "y": 18,
      "z": -7,
      "name": "Soil_Gravel_Half",
      "support": 15,
      "rotation": 5
    },
    {
      "x": -9,
      "y": 19,
      "z": -7,
      "name": "Soil_Gravel_Half",
      "support": 15,
      "rotation": 5
    },
    {
      "x": -9,
      "y": 20,
      "z": -7,
      "name": "Soil_Gravel_Half",
      "support": 15,
      "rotation": 5
    },
    {
      "x": -9,
      "y": 21,
      "z": -7,
      "name": "Soil_Gravel_Half",
      "support": 15,
      "rotation": 5
    },
    {
      "x": -9,
      "y": 22,
      "z": -7,
      "name": "Rock_Stone_Brick_Smooth",
      "rotation": 1
    },
    {
      "x": -9,
      "y": 7,
      "z": -6,
      "name": "Rock_Stone_Brick_Half",
      "rotation": 5
    },
    {
      "x": -9,
      "y": 8,
      "z": -6,
      "name": "Rock_Stone_Brick_Smooth"
    },
    {
      "x": -9,
      "y": 9,
      "z": -6,
      "name": "Rock_Stone_Brick_Half",
      "rotation": 5
    },
    {
      "x": -9,
      "y": 10,
      "z": -6,
      "name": "Rock_Stone_Brick_Half",
      "rotation": 5
    },
    {
      "x": -9,
      "y": 11,
      "z": -6,
      "name": "Rock_Stone_Brick_Half",
      "rotation": 5
    },
    {
      "x": -9,
      "y": 12,
      "z": -6,
      "name": "Rock_Stone_Brick_Half",
      "rotation": 5
    },
    {
      "x": -9,
      "y": 13,
      "z": -6,
      "name": "Rock_Stone_Brick_Half",
      "rotation": 5
    },
    {
      "x": -9,
      "y": 14,
      "z": -6,
      "name": "Rock_Stone_Brick_Smooth"
    },
    {
      "x": -9,
      "y": 15,
      "z": -6,
      "name": "Rock_Stone_Brick_Smooth"
    },
    {
      "x": -9,
      "y": 16,
      "z": -6,
      "name": "Rock_Stone_Brick_Half",
      "rotation": 5
    },
    {
      "x": -9,
      "y": 17,
      "z": -6,
      "name": "Rock_Stone_Brick_Half",
      "rotation": 5
    },
    {
      "x": -9,
      "y": 22,
      "z": -6,
      "name": "Rock_Stone_Brick_Smooth",
      "rotation": 1
    },
    {
      "x": -9,
      "y": 8,
      "z": -5,
      "name": "Rock_Stone_Brick_Smooth"
    },
    {
      "x": -9,
      "y": 14,
      "z": -5,
      "name": "Rock_Stone_Brick_Smooth"
    },
    {
      "x": -9,
      "y": 15,
      "z": -5,
      "name": "Rock_Stone_Brick_Smooth"
    },
    {
      "x": -9,
      "y": 22,
      "z": -5,
      "name": "Rock_Stone_Brick_Smooth",
      "rotation": 1
    },
    {
      "x": -9,
      "y": 8,
      "z": -4,
      "name": "Rock_Stone_Brick_Smooth"
    },
    {
      "x": -9,
      "y": 14,
      "z": -4,
      "name": "Rock_Stone_Brick_Smooth"
    },
    {
      "x": -9,
      "y": 15,
      "z": -4,
      "name": "Rock_Stone_Brick_Smooth"
    },
    {
      "x": -9,
      "y": 22,
      "z": -4,
      "name": "Rock_Stone_Brick_Smooth",
      "rotation": 1
    },
    {
      "x": -9,
      "y": 8,
      "z": -3,
      "name": "Rock_Stone_Brick_Smooth"
    },
    {
      "x": -9,
      "y": 14,
      "z": -3,
      "name": "Rock_Stone_Brick_Smooth"
    },
    {
      "x": -9,
      "y": 15,
      "z": -3,
      "name": "Rock_Stone_Brick_Smooth"
    },
    {
      "x": -9,
      "y": 22,
      "z": -3,
      "name": "Rock_Stone_Brick_Smooth",
      "rotation": 1
    },
    {
      "x": -9,
      "y": 8,
      "z": -2,
      "name": "Rock_Stone_Brick_Smooth"
    },
    {
      "x": -9,
      "y": 14,
      "z": -2,
      "name": "Rock_Stone_Brick_Smooth"
    },
    {
      "x": -9,
      "y": 15,
      "z": -2,
      "name": "Rock_Stone_Brick_Smooth"
    },
    {
      "x": -9,
      "y": 22,
      "z": -2,
      "name": "Rock_Stone_Brick_Smooth",
      "rotation": 1
    },
    {
      "x": -9,
      "y": 8,
      "z": -1,
      "name": "Rock_Stone_Brick_Smooth"
    },
    {
      "x": -9,
      "y": 14,
      "z": -1,
      "name": "Rock_Stone_Brick_Smooth"
    },
    {
      "x": -9,
      "y": 15,
      "z": -1,
      "name": "Rock_Stone_Brick_Smooth"
    },
    {
      "x": -9,
      "y": 22,
      "z": -1,
      "name": "Rock_Stone_Brick_Smooth",
      "rotation": 1
    },
    {
      "x": -9,
      "y": 7,
      "z": 0,
      "name": "Rock_Stone_Brick_Smooth_Half",
      "rotation": 8
    },
    {
      "x": -9,
      "y": 8,
      "z": 0,
      "name": "Rock_Stone_Brick_Smooth"
    },
    {
      "x": -9,
      "y": 13,
      "z": 0,
      "name": "Rock_Stone_Brick_Smooth_Half",
      "rotation": 8
    },
    {
      "x": -9,
      "y": 14,
      "z": 0,
      "name": "Rock_Stone_Brick_Smooth"
    },
    {
      "x": -9,
      "y": 15,
      "z": 0,
      "name": "Rock_Stone_Brick_Smooth_Half"
    },
    {
      "x": -9,
      "y": 22,
      "z": 0,
      "name": "Rock_Stone_Brick_Smooth",
      "rotation": 2
    },
    {
      "x": -9,
      "y": 7,
      "z": 1,
      "name": "Rock_Stone_Brick_Smooth"
    },
    {
      "x": -9,
      "y": 8,
      "z": 1,
      "name": "Rock_Stone_Brick_Smooth_Half"
    },
    {
      "x": -9,
      "y": 13,
      "z": 1,
      "name": "Rock_Stone_Brick_Smooth"
    },
    {
      "x": -9,
      "y": 14,
      "z": 1,
      "name": "Rock_Stone_Brick_Smooth"
    },
    {
      "x": -9,
      "y": 15,
      "z": 1,
      "name": "Rock_Stone_Brick_Smooth_Half"
    },
    {
      "x": -9,
      "y": 22,
      "z": 1,
      "name": "Rock_Stone_Brick_Smooth",
      "rotation": 2
    },
    {
      "x": -9,
      "y": 7,
      "z": 2,
      "name": "Rock_Stone_Brick_Smooth"
    },
    {
      "x": -9,
      "y": 8,
      "z": 2,
      "name": "Rock_Stone_Brick_Smooth_Half"
    },
    {
      "x": -9,
      "y": 13,
      "z": 2,
      "name": "Rock_Stone_Brick_Smooth"
    },
    {
      "x": -9,
      "y": 14,
      "z": 2,
      "name": "Rock_Stone_Brick_Smooth"
    },
    {
      "x": -9,
      "y": 22,
      "z": 2,
      "name": "Rock_Stone_Brick_Smooth",
      "rotation": 2
    },
    {
      "x": -9,
      "y": 7,
      "z": 3,
      "name": "Rock_Stone_Brick_Smooth"
    },
    {
      "x": -9,
      "y": 13,
      "z": 3,
      "name": "Rock_Stone_Brick_Smooth"
    },
    {
      "x": -9,
      "y": 14,
      "z": 3,
      "name": "Rock_Stone_Brick_Smooth"
    },
    {
      "x": -9,
      "y": 22,
      "z": 3,
      "name": "Rock_Stone_Brick_Smooth",
      "rotation": 2
    },
    {
      "x": -9,
      "y": 7,
      "z": 4,
      "name": "Rock_Stone_Brick_Smooth"
    },
    {
      "x": -9,
      "y": 13,
      "z": 4,
      "name": "Rock_Stone_Brick_Smooth"
    },
    {
      "x": -9,
      "y": 14,
      "z": 4,
      "name": "Rock_Stone_Brick_Smooth"
    },
    {
      "x": -9,
      "y": 22,
      "z": 4,
      "name": "Rock_Stone_Brick_Smooth",
      "rotation": 2
    },
    {
      "x": -9,
      "y": 7,
      "z": 5,
      "name": "Rock_Stone_Brick_Smooth"
    },
    {
      "x": -9,
      "y": 13,
      "z": 5,
      "name": "Rock_Stone_Brick_Smooth"
    },
    {
      "x": -9,
      "y": 14,
      "z": 5,
      "name": "Rock_Stone_Brick_Smooth"
    },
    {
      "x": -9,
      "y": 22,
      "z": 5,
      "name": "Rock_Stone_Brick_Smooth",
      "rotation": 2
    },
    {
      "x": -9,
      "y": 7,
      "z": 6,
      "name": "Rock_Stone_Brick_Smooth"
    },
    {
      "x": -9,
      "y": 8,
      "z": 6,
      "name": "Rock_Stone_Brick_Half",
      "rotation": 5
    },
    {
      "x": -9,
      "y": 9,
      "z": 6,
      "name": "Rock_Stone_Brick_Half",
      "rotation": 5
    },
    {
      "x": -9,
      "y": 10,
      "z": 6,
      "name": "Rock_Stone_Brick_Half",
      "rotation": 5
    },
    {
      "x": -9,
      "y": 11,
      "z": 6,
      "name": "Rock_Stone_Brick_Half",
      "rotation": 5
    },
    {
      "x": -9,
      "y": 12,
      "z": 6,
      "name": "Rock_Stone_Brick_Half",
      "rotation": 5
    },
    {
      "x": -9,
      "y": 13,
      "z": 6,
      "name": "Rock_Stone_Brick_Smooth"
    },
    {
      "x": -9,
      "y": 14,
      "z": 6,
      "name": "Rock_Stone_Brick_Stairs",
      "rotation": 1
    },
    {
      "x": -9,
      "y": 15,
      "z": 6,
      "name": "Rock_Stone_Brick_Half",
      "rotation": 5
    },
    {
      "x": -9,
      "y": 16,
      "z": 6,
      "name": "Rock_Stone_Brick_Half",
      "rotation": 5
    },
    {
      "x": -9,
      "y": 17,
      "z": 6,
      "name": "Rock_Stone_Brick_Half",
      "rotation": 5
    },
    {
      "x": -9,
      "y": 22,
      "z": 6,
      "name": "Rock_Stone_Brick_Smooth",
      "rotation": 2
    },
    {
      "x": -9,
      "y": 7,
      "z": 7,
      "name": "Rock_Stone_Brick"
    },
    {
      "x": -9,
      "y": 8,
      "z": 7,
      "name": "Rock_Stone_Brick"
    },
    {
      "x": -9,
      "y": 9,
      "z": 7,
      "name": "Rock_Stone_Brick"
    },
    {
      "x": -9,
      "y": 10,
      "z": 7,
      "name": "Rock_Stone_Brick"
    },
    {
      "x": -9,
      "y": 11,
      "z": 7,
      "name": "Rock_Stone_Brick"
    },
    {
      "x": -9,
      "y": 12,
      "z": 7,
      "name": "Rock_Stone_Brick"
    },
    {
      "x": -9,
      "y": 13,
      "z": 7,
      "name": "Rock_Stone_Brick"
    },
    {
      "x": -9,
      "y": 14,
      "z": 7,
      "name": "Rock_Stone_Brick"
    },
    {
      "x": -9,
      "y": 15,
      "z": 7,
      "name": "Rock_Stone_Brick"
    },
    {
      "x": -9,
      "y": 16,
      "z": 7,
      "name": "Rock_Stone_Brick",
      "rotation": 2
    },
    {
      "x": -9,
      "y": 17,
      "z": 7,
      "name": "Rock_Stone_Brick_Decorative",
      "rotation": 2
    },
    {
      "x": -9,
      "y": 18,
      "z": 7,
      "name": "Soil_Gravel_Half",
      "support": 15,
      "rotation": 5
    },
    {
      "x": -9,
      "y": 19,
      "z": 7,
      "name": "Soil_Gravel_Half",
      "support": 15,
      "rotation": 5
    },
    {
      "x": -9,
      "y": 20,
      "z": 7,
      "name": "Soil_Gravel_Half",
      "support": 15,
      "rotation": 5
    },
    {
      "x": -9,
      "y": 21,
      "z": 7,
      "name": "Soil_Gravel_Half",
      "support": 15,
      "rotation": 5
    },
    {
      "x": -9,
      "y": 22,
      "z": 7,
      "name": "Rock_Stone_Brick_Smooth",
      "rotation": 2
    },
    {
      "x": -9,
      "y": 16,
      "z": 8,
      "name": "Rock_Stone_Brick"
    },
    {
      "x": -9,
      "y": 17,
      "z": 8,
      "name": "Rock_Stone_Brick_Decorative",
      "rotation": 2
    },
    {
      "x": -9,
      "y": 18,
      "z": 8,
      "name": "Soil_Gravel",
      "support": 15,
      "rotation": 2
    },
    {
      "x": -9,
      "y": 19,
      "z": 8,
      "name": "Soil_Gravel",
      "support": 15,
      "rotation": 2
    },
    {
      "x": -9,
      "y": 20,
      "z": 8,
      "name": "Soil_Gravel",
      "support": 15,
      "rotation": 2
    },
    {
      "x": -9,
      "y": 21,
      "z": 8,
      "name": "Soil_Gravel",
      "support": 15,
      "rotation": 2
    },
    {
      "x": -9,
      "y": 22,
      "z": 8,
      "name": "Rock_Stone_Brick_Smooth",
      "rotation": 2
    },
    {
      "x": -8,
      "y": 16,
      "z": -9,
      "name": "Rock_Stone_Brick"
    },
    {
      "x": -8,
      "y": 17,
      "z": -9,
      "name": "Rock_Stone_Brick_Decorative",
      "rotation": 1
    },
    {
      "x": -8,
      "y": 18,
      "z": -9,
      "name": "Soil_Gravel",
      "support": 15,
      "rotation": 1
    },
    {
      "x": -8,
      "y": 19,
      "z": -9,
      "name": "Soil_Gravel",
      "support": 15,
      "rotation": 1
    },
    {
      "x": -8,
      "y": 20,
      "z": -9,
      "name": "Soil_Gravel",
      "support": 15,
      "rotation": 1
    },
    {
      "x": -8,
      "y": 21,
      "z": -9,
      "name": "Soil_Gravel",
      "support": 15,
      "rotation": 1
    },
    {
      "x": -8,
      "y": 22,
      "z": -9,
      "name": "Rock_Stone_Brick_Smooth",
      "rotation": 1
    },
    {
      "x": -8,
      "y": 7,
      "z": -8,
      "name": "Rock_Stone_Brick"
    },
    {
      "x": -8,
      "y": 8,
      "z": -8,
      "name": "Rock_Stone_Brick"
    },
    {
      "x": -8,
      "y": 9,
      "z": -8,
      "name": "Rock_Stone_Brick"
    },
    {
      "x": -8,
      "y": 10,
      "z": -8,
      "name": "Rock_Stone_Brick"
    },
    {
      "x": -8,
      "y": 11,
      "z": -8,
      "name": "Rock_Stone_Brick"
    },
    {
      "x": -8,
      "y": 12,
      "z": -8,
      "name": "Rock_Stone_Brick"
    },
    {
      "x": -8,
      "y": 13,
      "z": -8,
      "name": "Rock_Stone_Brick"
    },
    {
      "x": -8,
      "y": 14,
      "z": -8,
      "name": "Rock_Stone_Brick"
    },
    {
      "x": -8,
      "y": 15,
      "z": -8,
      "name": "Rock_Stone_Brick"
    },
    {
      "x": -8,
      "y": 16,
      "z": -8,
      "name": "Rock_Stone_Brick",
      "rotation": 1
    },
    {
      "x": -8,
      "y": 17,
      "z": -8,
      "name": "Rock_Stone_Brick_Decorative",
      "rotation": 1
    },
    {
      "x": -8,
      "y": 18,
      "z": -8,
      "name": "Rock_Stone_Brick_Pillar_Base",
      "rotation": 1
    },
    {
      "x": -8,
      "y": 19,
      "z": -8,
      "name": "Rock_Stone_Brick_Pillar_Middle",
      "rotation": 1
    },
    {
      "x": -8,
      "y": 20,
      "z": -8,
      "name": "Rock_Stone_Brick_Pillar_Middle",
      "rotation": 1
    },
    {
      "x": -8,
      "y": 21,
      "z": -8,
      "name": "Rock_Stone_Brick_Pillar_Base",
      "rotation": 35
    },
    {
      "x": -8,
      "y": 22,
      "z": -8,
      "name": "Rock_Stone_Brick_Smooth",
      "rotation": 1
    },
    {
      "x": -8,
      "y": 8,
      "z": -7,
      "name": "Rock_Stone_Brick_Smooth"
    },
    {
      "x": -8,
      "y": 14,
      "z": -7,
      "name": "Rock_Stone_Brick_Smooth"
    },
    {
      "x": -8,
      "y": 15,
      "z": -7,
      "name": "Rock_Stone_Brick_Smooth"
    },
    {
      "x": -8,
      "y": 16,
      "z": -7,
      "name": "Rock_Stone_Brick_Smooth_Half"
    },
    {
      "x": -8,
      "y": 22,
      "z": -7,
      "name": "Rock_Stone_Brick_Smooth",
      "rotation": 1
    },
    {
      "x": -8,
      "y": 8,
      "z": -6,
      "name": "Rock_Stone_Brick_Smooth"
    },
    {
      "x": -8,
      "y": 14,
      "z": -6,
      "name": "Rock_Stone_Brick_Smooth"
    },
    {
      "x": -8,
      "y": 15,
      "z": -6,
      "name": "Rock_Stone_Brick_Smooth"
    },
    {
      "x": -8,
      "y": 16,
      "z": -6,
      "name": "Rock_Stone_Brick_Smooth_Half"
    },
    {
      "x": -8,
      "y": 22,
      "z": -6,
      "name": "Rock_Stone_Brick_Smooth",
      "rotation": 1
    },
    {
      "x": -8,
      "y": 8,
      "z": -5,
      "name": "Rock_Stone_Brick_Smooth"
    },
    {
      "x": -8,
      "y": 14,
      "z": -5,
      "name": "Rock_Stone_Brick_Smooth"
    },
    {
      "x": -8,
      "y": 15,
      "z": -5,
      "name": "Rock_Stone_Brick_Smooth"
    },
    {
      "x": -8,
      "y": 22,
      "z": -5,
      "name": "Rock_Stone_Brick_Smooth",
      "rotation": 1
    },
    {
      "x": -8,
      "y": 8,
      "z": -4,
      "name": "Rock_Stone_Brick_Smooth"
    },
    {
      "x": -8,
      "y": 14,
      "z": -4,
      "name": "Rock_Stone_Brick_Smooth"
    },
    {
      "x": -8,
      "y": 15,
      "z": -4,
      "name": "Rock_Stone_Brick_Smooth"
    },
    {
      "x": -8,
      "y": 22,
      "z": -4,
      "name": "Rock_Stone_Brick_Smooth",
      "rotation": 1
    },
    {
      "x": -8,
      "y": 8,
      "z": -3,
      "name": "Rock_Stone_Brick_Smooth"
    },
    {
      "x": -8,
      "y": 14,
      "z": -3,
      "name": "Rock_Stone_Brick_Smooth"
    },
    {
      "x": -8,
      "y": 15,
      "z": -3,
      "name": "Rock_Stone_Brick_Smooth"
    },
    {
      "x": -8,
      "y": 22,
      "z": -3,
      "name": "Rock_Stone_Brick_Smooth",
      "rotation": 1
    },
    {
      "x": -8,
      "y": 8,
      "z": -2,
      "name": "Rock_Stone_Brick_Smooth"
    },
    {
      "x": -8,
      "y": 14,
      "z": -2,
      "name": "Rock_Stone_Brick_Smooth"
    },
    {
      "x": -8,
      "y": 15,
      "z": -2,
      "name": "Rock_Stone_Brick_Smooth"
    },
    {
      "x": -8,
      "y": 22,
      "z": -2,
      "name": "Rock_Stone_Brick_Smooth",
      "rotation": 1
    },
    {
      "x": -8,
      "y": 8,
      "z": -1,
      "name": "Rock_Stone_Brick_Smooth"
    },
    {
      "x": -8,
      "y": 14,
      "z": -1,
      "name": "Rock_Stone_Brick_Smooth"
    },
    {
      "x": -8,
      "y": 15,
      "z": -1,
      "name": "Rock_Stone_Brick_Smooth"
    },
    {
      "x": -8,
      "y": 22,
      "z": -1,
      "name": "Rock_Stone_Brick_Smooth",
      "rotation": 1
    },
    {
      "x": -8,
      "y": 7,
      "z": 0,
      "name": "Rock_Stone_Brick_Smooth_Half",
      "rotation": 8
    },
    {
      "x": -8,
      "y": 8,
      "z": 0,
      "name": "Rock_Stone_Brick_Smooth"
    },
    {
      "x": -8,
      "y": 13,
      "z": 0,
      "name": "Rock_Stone_Brick_Smooth_Half",
      "rotation": 8
    },
    {
      "x": -8,
      "y": 14,
      "z": 0,
      "name": "Rock_Stone_Brick_Smooth"
    },
    {
      "x": -8,
      "y": 15,
      "z": 0,
      "name": "Rock_Stone_Brick_Smooth_Half"
    },
    {
      "x": -8,
      "y": 22,
      "z": 0,
      "name": "Rock_Stone_Brick_Smooth",
      "rotation": 2
    },
    {
      "x": -8,
      "y": 7,
      "z": 1,
      "name": "Rock_Stone_Brick_Smooth"
    },
    {
      "x": -8,
      "y": 8,
      "z": 1,
      "name": "Rock_Stone_Brick_Smooth_Half"
    },
    {
      "x": -8,
      "y": 13,
      "z": 1,
      "name": "Rock_Stone_Brick_Smooth"
    },
    {
      "x": -8,
      "y": 14,
      "z": 1,
      "name": "Rock_Stone_Brick_Smooth"
    },
    {
      "x": -8,
      "y": 15,
      "z": 1,
      "name": "Rock_Stone_Brick_Smooth_Half"
    },
    {
      "x": -8,
      "y": 22,
      "z": 1,
      "name": "Rock_Stone_Brick_Smooth",
      "rotation": 2
    },
    {
      "x": -8,
      "y": 7,
      "z": 2,
      "name": "Rock_Stone_Brick_Smooth"
    },
    {
      "x": -8,
      "y": 8,
      "z": 2,
      "name": "Rock_Stone_Brick_Smooth_Half"
    },
    {
      "x": -8,
      "y": 13,
      "z": 2,
      "name": "Rock_Stone_Brick_Smooth"
    },
    {
      "x": -8,
      "y": 14,
      "z": 2,
      "name": "Rock_Stone_Brick_Smooth"
    },
    {
      "x": -8,
      "y": 22,
      "z": 2,
      "name": "Rock_Stone_Brick_Smooth",
      "rotation": 2
    },
    {
      "x": -8,
      "y": 7,
      "z": 3,
      "name": "Rock_Stone_Brick_Smooth"
    },
    {
      "x": -8,
      "y": 13,
      "z": 3,
      "name": "Rock_Stone_Brick_Smooth"
    },
    {
      "x": -8,
      "y": 14,
      "z": 3,
      "name": "Rock_Stone_Brick_Smooth"
    },
    {
      "x": -8,
      "y": 22,
      "z": 3,
      "name": "Rock_Stone_Brick_Smooth",
      "rotation": 2
    },
    {
      "x": -8,
      "y": 7,
      "z": 4,
      "name": "Rock_Stone_Brick_Smooth"
    },
    {
      "x": -8,
      "y": 13,
      "z": 4,
      "name": "Rock_Stone_Brick_Smooth"
    },
    {
      "x": -8,
      "y": 14,
      "z": 4,
      "name": "Rock_Stone_Brick_Smooth"
    },
    {
      "x": -8,
      "y": 22,
      "z": 4,
      "name": "Rock_Stone_Brick_Smooth",
      "rotation": 2
    },
    {
      "x": -8,
      "y": 7,
      "z": 5,
      "name": "Rock_Stone_Brick_Smooth"
    },
    {
      "x": -8,
      "y": 13,
      "z": 5,
      "name": "Rock_Stone_Brick_Smooth"
    },
    {
      "x": -8,
      "y": 14,
      "z": 5,
      "name": "Rock_Stone_Brick_Smooth"
    },
    {
      "x": -8,
      "y": 22,
      "z": 5,
      "name": "Rock_Stone_Brick_Smooth",
      "rotation": 2
    },
    {
      "x": -8,
      "y": 7,
      "z": 6,
      "name": "Rock_Stone_Brick_Smooth"
    },
    {
      "x": -8,
      "y": 13,
      "z": 6,
      "name": "Rock_Stone_Brick_Smooth"
    },
    {
      "x": -8,
      "y": 14,
      "z": 6,
      "name": "Rock_Stone_Brick_Smooth_Half"
    },
    {
      "x": -8,
      "y": 22,
      "z": 6,
      "name": "Rock_Stone_Brick_Smooth",
      "rotation": 2
    },
    {
      "x": -8,
      "y": 7,
      "z": 7,
      "name": "Rock_Stone_Brick_Smooth"
    },
    {
      "x": -8,
      "y": 13,
      "z": 7,
      "name": "Rock_Stone_Brick_Smooth"
    },
    {
      "x": -8,
      "y": 14,
      "z": 7,
      "name": "Rock_Stone_Brick_Smooth_Half"
    },
    {
      "x": -8,
      "y": 22,
      "z": 7,
      "name": "Rock_Stone_Brick_Smooth",
      "rotation": 2
    },
    {
      "x": -8,
      "y": 7,
      "z": 8,
      "name": "Rock_Stone_Brick"
    },
    {
      "x": -8,
      "y": 8,
      "z": 8,
      "name": "Rock_Stone_Brick"
    },
    {
      "x": -8,
      "y": 9,
      "z": 8,
      "name": "Rock_Stone_Brick"
    },
    {
      "x": -8,
      "y": 10,
      "z": 8,
      "name": "Rock_Stone_Brick"
    },
    {
      "x": -8,
      "y": 11,
      "z": 8,
      "name": "Rock_Stone_Brick"
    },
    {
      "x": -8,
      "y": 12,
      "z": 8,
      "name": "Rock_Stone_Brick"
    },
    {
      "x": -8,
      "y": 13,
      "z": 8,
      "name": "Rock_Stone_Brick"
    },
    {
      "x": -8,
      "y": 14,
      "z": 8,
      "name": "Rock_Stone_Brick"
    },
    {
      "x": -8,
      "y": 15,
      "z": 8,
      "name": "Rock_Stone_Brick"
    },
    {
      "x": -8,
      "y": 16,
      "z": 8,
      "name": "Rock_Stone_Brick",
      "rotation": 2
    },
    {
      "x": -8,
      "y": 17,
      "z": 8,
      "name": "Rock_Stone_Brick_Decorative",
      "rotation": 2
    },
    {
      "x": -8,
      "y": 18,
      "z": 8,
      "name": "Rock_Stone_Brick_Pillar_Base",
      "rotation": 2
    },
    {
      "x": -8,
      "y": 19,
      "z": 8,
      "name": "Rock_Stone_Brick_Pillar_Middle",
      "rotation": 2
    },
    {
      "x": -8,
      "y": 20,
      "z": 8,
      "name": "Rock_Stone_Brick_Pillar_Middle",
      "rotation": 2
    },
    {
      "x": -8,
      "y": 21,
      "z": 8,
      "name": "Rock_Stone_Brick_Pillar_Base",
      "rotation": 32
    },
    {
      "x": -8,
      "y": 22,
      "z": 8,
      "name": "Rock_Stone_Brick_Smooth",
      "rotation": 2
    },
    {
      "x": -8,
      "y": 16,
      "z": 9,
      "name": "Rock_Stone_Brick"
    },
    {
      "x": -8,
      "y": 17,
      "z": 9,
      "name": "Rock_Stone_Brick_Decorative",
      "rotation": 2
    },
    {
      "x": -8,
      "y": 18,
      "z": 9,
      "name": "Soil_Gravel",
      "support": 15,
      "rotation": 2
    },
    {
      "x": -8,
      "y": 19,
      "z": 9,
      "name": "Soil_Gravel",
      "support": 15,
      "rotation": 2
    },
    {
      "x": -8,
      "y": 20,
      "z": 9,
      "name": "Soil_Gravel",
      "support": 15,
      "rotation": 2
    },
    {
      "x": -8,
      "y": 21,
      "z": 9,
      "name": "Soil_Gravel",
      "support": 15,
      "rotation": 2
    },
    {
      "x": -8,
      "y": 22,
      "z": 9,
      "name": "Rock_Stone_Brick_Smooth",
      "rotation": 2
    },
    {
      "x": -7,
      "y": 16,
      "z": -10,
      "name": "Rock_Stone_Brick"
    },
    {
      "x": -7,
      "y": 17,
      "z": -10,
      "name": "Rock_Stone_Brick_Decorative",
      "rotation": 1
    },
    {
      "x": -7,
      "y": 18,
      "z": -10,
      "name": "Soil_Gravel",
      "support": 15,
      "rotation": 1
    },
    {
      "x": -7,
      "y": 19,
      "z": -10,
      "name": "Soil_Gravel",
      "support": 15,
      "rotation": 1
    },
    {
      "x": -7,
      "y": 20,
      "z": -10,
      "name": "Soil_Gravel",
      "support": 15,
      "rotation": 1
    },
    {
      "x": -7,
      "y": 21,
      "z": -10,
      "name": "Soil_Gravel",
      "support": 15,
      "rotation": 1
    },
    {
      "x": -7,
      "y": 22,
      "z": -10,
      "name": "Rock_Stone_Brick_Smooth",
      "rotation": 1
    },
    {
      "x": -7,
      "y": 7,
      "z": -9,
      "name": "Rock_Stone_Brick"
    },
    {
      "x": -7,
      "y": 8,
      "z": -9,
      "name": "Rock_Stone_Brick"
    },
    {
      "x": -7,
      "y": 9,
      "z": -9,
      "name": "Rock_Stone_Brick"
    },
    {
      "x": -7,
      "y": 10,
      "z": -9,
      "name": "Rock_Stone_Brick"
    },
    {
      "x": -7,
      "y": 11,
      "z": -9,
      "name": "Rock_Stone_Brick"
    },
    {
      "x": -7,
      "y": 12,
      "z": -9,
      "name": "Rock_Stone_Brick"
    },
    {
      "x": -7,
      "y": 13,
      "z": -9,
      "name": "Rock_Stone_Brick"
    },
    {
      "x": -7,
      "y": 14,
      "z": -9,
      "name": "Rock_Stone_Brick"
    },
    {
      "x": -7,
      "y": 15,
      "z": -9,
      "name": "Rock_Stone_Brick"
    },
    {
      "x": -7,
      "y": 16,
      "z": -9,
      "name": "Rock_Stone_Brick",
      "rotation": 1
    },
    {
      "x": -7,
      "y": 17,
      "z": -9,
      "name": "Rock_Stone_Brick_Decorative",
      "rotation": 1
    },
    {
      "x": -7,
      "y": 18,
      "z": -9,
      "name": "Soil_Gravel_Half",
      "support": 15,
      "rotation": 4
    },
    {
      "x": -7,
      "y": 19,
      "z": -9,
      "name": "Soil_Gravel_Half",
      "support": 15,
      "rotation": 4
    },
    {
      "x": -7,
      "y": 20,
      "z": -9,
      "name": "Soil_Gravel_Half",
      "support": 15,
      "rotation": 4
    },
    {
      "x": -7,
      "y": 21,
      "z": -9,
      "name": "Soil_Gravel_Half",
      "support": 15,
      "rotation": 4
    },
    {
      "x": -7,
      "y": 22,
      "z": -9,
      "name": "Rock_Stone_Brick_Smooth",
      "rotation": 1
    },
    {
      "x": -7,
      "y": 8,
      "z": -8,
      "name": "Rock_Stone_Brick_Smooth"
    },
    {
      "x": -7,
      "y": 14,
      "z": -8,
      "name": "Rock_Stone_Brick_Smooth"
    },
    {
      "x": -7,
      "y": 15,
      "z": -8,
      "name": "Rock_Stone_Brick_Smooth"
    },
    {
      "x": -7,
      "y": 16,
      "z": -8,
      "name": "Rock_Stone_Brick_Smooth_Half"
    },
    {
      "x": -7,
      "y": 22,
      "z": -8,
      "name": "Rock_Stone_Brick_Smooth",
      "rotation": 1
    },
    {
      "x": -7,
      "y": 8,
      "z": -7,
      "name": "Rock_Stone_Brick_Smooth"
    },
    {
      "x": -7,
      "y": 14,
      "z": -7,
      "name": "Rock_Stone_Brick_Smooth"
    },
    {
      "x": -7,
      "y": 15,
      "z": -7,
      "name": "Rock_Stone_Brick_Smooth"
    },
    {
      "x": -7,
      "y": 16,
      "z": -7,
      "name": "Rock_Stone_Brick_Smooth_Half"
    },
    {
      "x": -7,
      "y": 22,
      "z": -7,
      "name": "Rock_Stone_Brick_Smooth",
      "rotation": 1
    },
    {
      "x": -7,
      "y": 8,
      "z": -6,
      "name": "Rock_Stone_Brick_Smooth"
    },
    {
      "x": -7,
      "y": 14,
      "z": -6,
      "name": "Rock_Stone_Brick_Smooth"
    },
    {
      "x": -7,
      "y": 15,
      "z": -6,
      "name": "Rock_Stone_Brick_Smooth"
    },
    {
      "x": -7,
      "y": 16,
      "z": -6,
      "name": "Rock_Stone_Brick_Smooth_Half"
    },
    {
      "x": -7,
      "y": 22,
      "z": -6,
      "name": "Rock_Stone_Brick_Smooth",
      "rotation": 1
    },
    {
      "x": -7,
      "y": 8,
      "z": -5,
      "name": "Rock_Stone_Brick_Smooth"
    },
    {
      "x": -7,
      "y": 14,
      "z": -5,
      "name": "Rock_Stone_Brick_Smooth"
    },
    {
      "x": -7,
      "y": 15,
      "z": -5,
      "name": "Rock_Stone_Brick_Smooth"
    },
    {
      "x": -7,
      "y": 16,
      "z": -5,
      "name": "Rock_Stone_Brick_Smooth_Half"
    },
    {
      "x": -7,
      "y": 22,
      "z": -5,
      "name": "Rock_Stone_Brick_Smooth",
      "rotation": 1
    },
    {
      "x": -7,
      "y": 8,
      "z": -4,
      "name": "Rock_Stone_Brick_Smooth"
    },
    {
      "x": -7,
      "y": 14,
      "z": -4,
      "name": "Rock_Stone_Brick_Smooth"
    },
    {
      "x": -7,
      "y": 15,
      "z": -4,
      "name": "Rock_Stone_Brick_Smooth"
    },
    {
      "x": -7,
      "y": 22,
      "z": -4,
      "name": "Rock_Stone_Brick_Smooth",
      "rotation": 1
    },
    {
      "x": -7,
      "y": 8,
      "z": -3,
      "name": "Rock_Stone_Brick_Smooth"
    },
    {
      "x": -7,
      "y": 14,
      "z": -3,
      "name": "Rock_Stone_Brick_Smooth"
    },
    {
      "x": -7,
      "y": 15,
      "z": -3,
      "name": "Rock_Stone_Brick_Smooth"
    },
    {
      "x": -7,
      "y": 22,
      "z": -3,
      "name": "Rock_Stone_Brick_Smooth",
      "rotation": 1
    },
    {
      "x": -7,
      "y": 7,
      "z": -2,
      "name": "Rock_Stone_Brick_Pillar_Base",
      "rotation": 8
    },
    {
      "x": -7,
      "y": 8,
      "z": -2,
      "name": "Rock_Stone_Brick_Smooth"
    },
    {
      "x": -7,
      "y": 9,
      "z": -2,
      "name": "Rock_Stone_Brick_Decorative"
    },
    {
      "x": -7,
      "y": 10,
      "z": -2,
      "name": "Rock_Stone_Brick_Pillar_Base"
    },
    {
      "x": -7,
      "y": 11,
      "z": -2,
      "name": "Rock_Stone_Brick_Pillar_Middle",
      "rotation": 8
    },
    {
      "x": -7,
      "y": 12,
      "z": -2,
      "name": "Rock_Stone_Brick_Pillar_Middle",
      "rotation": 8
    },
    {
      "x": -7,
      "y": 13,
      "z": -2,
      "name": "Rock_Stone_Brick_Pillar_Base",
      "rotation": 8
    },
    {
      "x": -7,
      "y": 14,
      "z": -2,
      "name": "Rock_Stone_Brick_Smooth"
    },
    {
      "x": -7,
      "y": 15,
      "z": -2,
      "name": "Rock_Stone_Brick"
    },
    {
      "x": -7,
      "y": 16,
      "z": -2,
      "name": "Rock_Stone_Brick_Smooth"
    },
    {
      "x": -7,
      "y": 17,
      "z": -2,
      "name": "Rock_Stone_Brick_Decorative",
      "rotation": 1
    },
    {
      "x": -7,
      "y": 18,
      "z": -2,
      "name": "Rock_Stone_Brick_Pillar_Base",
      "rotation": 1
    },
    {
      "x": -7,
      "y": 19,
      "z": -2,
      "name": "Rock_Stone_Brick_Pillar_Middle",
      "rotation": 1
    },
    {
      "x": -7,
      "y": 20,
      "z": -2,
      "name": "Rock_Stone_Brick_Pillar_Middle",
      "rotation": 1
    },
    {
      "x": -7,
      "y": 21,
      "z": -2,
      "name": "Rock_Stone_Brick_Pillar_Base",
      "rotation": 35
    },
    {
      "x": -7,
      "y": 22,
      "z": -2,
      "name": "Rock_Stone_Brick",
      "rotation": 1
    },
    {
      "x": -7,
      "y": 8,
      "z": -1,
      "name": "Rock_Stone_Brick_Smooth"
    },
    {
      "x": -7,
      "y": 14,
      "z": -1,
      "name": "Rock_Stone_Brick_Smooth"
    },
    {
      "x": -7,
      "y": 15,
      "z": -1,
      "name": "Rock_Stone_Brick_Smooth"
    },
    {
      "x": -7,
      "y": 16,
      "z": -1,
      "name": "Rock_Stone_Brick_Smooth"
    },
    {
      "x": -7,
      "y": 22,
      "z": -1,
      "name": "Rock_Stone_Brick"
    },
    {
      "x": -7,
      "y": 7,
      "z": 0,
      "name": "Rock_Stone_Brick_Smooth_Half",
      "rotation": 8
    },
    {
      "x": -7,
      "y": 8,
      "z": 0,
      "name": "Rock_Stone_Brick_Smooth"
    },
    {
      "x": -7,
      "y": 13,
      "z": 0,
      "name": "Rock_Stone_Brick_Smooth_Half",
      "rotation": 8
    },
    {
      "x": -7,
      "y": 14,
      "z": 0,
      "name": "Rock_Stone_Brick_Smooth"
    },
    {
      "x": -7,
      "y": 15,
      "z": 0,
      "name": "Rock_Stone_Brick_Smooth"
    },
    {
      "x": -7,
      "y": 16,
      "z": 0,
      "name": "Rock_Stone_Brick_Smooth"
    },
    {
      "x": -7,
      "y": 22,
      "z": 0,
      "name": "Rock_Stone_Brick"
    },
    {
      "x": -7,
      "y": 7,
      "z": 1,
      "name": "Rock_Stone_Brick_Smooth"
    },
    {
      "x": -7,
      "y": 8,
      "z": 1,
      "name": "Rock_Stone_Brick_Smooth_Half"
    },
    {
      "x": -7,
      "y": 13,
      "z": 1,
      "name": "Rock_Stone_Brick_Smooth"
    },
    {
      "x": -7,
      "y": 14,
      "z": 1,
      "name": "Rock_Stone_Brick_Smooth"
    },
    {
      "x": -7,
      "y": 15,
      "z": 1,
      "name": "Rock_Stone_Brick_Smooth"
    },
    {
      "x": -7,
      "y": 16,
      "z": 1,
      "name": "Rock_Stone_Brick_Smooth"
    },
    {
      "x": -7,
      "y": 22,
      "z": 1,
      "name": "Rock_Stone_Brick"
    },
    {
      "x": -7,
      "y": 7,
      "z": 2,
      "name": "Rock_Stone_Brick_Smooth"
    },
    {
      "x": -7,
      "y": 8,
      "z": 2,
      "name": "Rock_Stone_Brick_Decorative"
    },
    {
      "x": -7,
      "y": 9,
      "z": 2,
      "name": "Rock_Stone_Brick_Pillar_Base"
    },
    {
      "x": -7,
      "y": 10,
      "z": 2,
      "name": "Rock_Stone_Brick_Pillar_Middle",
      "rotation": 8
    },
    {
      "x": -7,
      "y": 11,
      "z": 2,
      "name": "Rock_Stone_Brick_Pillar_Middle",
      "rotation": 8
    },
    {
      "x": -7,
      "y": 12,
      "z": 2,
      "name": "Rock_Stone_Brick_Pillar_Base",
      "rotation": 8
    },
    {
      "x": -7,
      "y": 13,
      "z": 2,
      "name": "Rock_Stone_Brick_Smooth"
    },
    {
      "x": -7,
      "y": 14,
      "z": 2,
      "name": "Rock_Stone_Brick"
    },
    {
      "x": -7,
      "y": 15,
      "z": 2,
      "name": "Rock_Stone_Brick"
    },
    {
      "x": -7,
      "y": 16,
      "z": 2,
      "name": "Rock_Stone_Brick_Smooth"
    },
    {
      "x": -7,
      "y": 17,
      "z": 2,
      "name": "Rock_Stone_Brick_Decorative",
      "rotation": 2
    },
    {
      "x": -7,
      "y": 18,
      "z": 2,
      "name": "Rock_Stone_Brick_Pillar_Base",
      "rotation": 2
    },
    {
      "x": -7,
      "y": 19,
      "z": 2,
      "name": "Rock_Stone_Brick_Pillar_Middle",
      "rotation": 2
    },
    {
      "x": -7,
      "y": 20,
      "z": 2,
      "name": "Rock_Stone_Brick_Pillar_Middle",
      "rotation": 2
    },
    {
      "x": -7,
      "y": 21,
      "z": 2,
      "name": "Rock_Stone_Brick_Pillar_Base",
      "rotation": 32
    },
    {
      "x": -7,
      "y": 22,
      "z": 2,
      "name": "Rock_Stone_Brick",
      "rotation": 2
    },
    {
      "x": -7,
      "y": 7,
      "z": 3,
      "name": "Rock_Stone_Brick_Smooth"
    },
    {
      "x": -7,
      "y": 13,
      "z": 3,
      "name": "Rock_Stone_Brick_Smooth"
    },
    {
      "x": -7,
      "y": 14,
      "z": 3,
      "name": "Rock_Stone_Brick_Smooth"
    },
    {
      "x": -7,
      "y": 22,
      "z": 3,
      "name": "Rock_Stone_Brick_Smooth",
      "rotation": 2
    },
    {
      "x": -7,
      "y": 7,
      "z": 4,
      "name": "Rock_Stone_Brick_Smooth"
    },
    {
      "x": -7,
      "y": 13,
      "z": 4,
      "name": "Rock_Stone_Brick_Smooth"
    },
    {
      "x": -7,
      "y": 14,
      "z": 4,
      "name": "Rock_Stone_Brick_Smooth"
    },
    {
      "x": -7,
      "y": 22,
      "z": 4,
      "name": "Rock_Stone_Brick_Smooth",
      "rotation": 2
    },
    {
      "x": -7,
      "y": 7,
      "z": 5,
      "name": "Rock_Stone_Brick_Smooth"
    },
    {
      "x": -7,
      "y": 13,
      "z": 5,
      "name": "Rock_Stone_Brick_Smooth"
    },
    {
      "x": -7,
      "y": 14,
      "z": 5,
      "name": "Rock_Stone_Brick_Smooth_Half"
    },
    {
      "x": -7,
      "y": 22,
      "z": 5,
      "name": "Rock_Stone_Brick_Smooth",
      "rotation": 2
    },
    {
      "x": -7,
      "y": 7,
      "z": 6,
      "name": "Rock_Stone_Brick_Smooth"
    },
    {
      "x": -7,
      "y": 13,
      "z": 6,
      "name": "Rock_Stone_Brick_Smooth"
    },
    {
      "x": -7,
      "y": 14,
      "z": 6,
      "name": "Rock_Stone_Brick_Smooth_Half"
    },
    {
      "x": -7,
      "y": 22,
      "z": 6,
      "name": "Rock_Stone_Brick_Smooth",
      "rotation": 2
    },
    {
      "x": -7,
      "y": 7,
      "z": 7,
      "name": "Rock_Stone_Brick_Smooth"
    },
    {
      "x": -7,
      "y": 13,
      "z": 7,
      "name": "Rock_Stone_Brick_Smooth"
    },
    {
      "x": -7,
      "y": 14,
      "z": 7,
      "name": "Rock_Stone_Brick_Smooth_Half"
    },
    {
      "x": -7,
      "y": 22,
      "z": 7,
      "name": "Rock_Stone_Brick_Smooth",
      "rotation": 2
    },
    {
      "x": -7,
      "y": 7,
      "z": 8,
      "name": "Rock_Stone_Brick_Smooth"
    },
    {
      "x": -7,
      "y": 13,
      "z": 8,
      "name": "Rock_Stone_Brick_Smooth"
    },
    {
      "x": -7,
      "y": 14,
      "z": 8,
      "name": "Rock_Stone_Brick_Smooth_Half"
    },
    {
      "x": -7,
      "y": 22,
      "z": 8,
      "name": "Rock_Stone_Brick_Smooth",
      "rotation": 2
    },
    {
      "x": -7,
      "y": 7,
      "z": 9,
      "name": "Rock_Stone_Brick"
    },
    {
      "x": -7,
      "y": 8,
      "z": 9,
      "name": "Rock_Stone_Brick"
    },
    {
      "x": -7,
      "y": 9,
      "z": 9,
      "name": "Rock_Stone_Brick"
    },
    {
      "x": -7,
      "y": 10,
      "z": 9,
      "name": "Rock_Stone_Brick"
    },
    {
      "x": -7,
      "y": 11,
      "z": 9,
      "name": "Rock_Stone_Brick"
    },
    {
      "x": -7,
      "y": 12,
      "z": 9,
      "name": "Rock_Stone_Brick"
    },
    {
      "x": -7,
      "y": 13,
      "z": 9,
      "name": "Rock_Stone_Brick"
    },
    {
      "x": -7,
      "y": 14,
      "z": 9,
      "name": "Rock_Stone_Brick"
    },
    {
      "x": -7,
      "y": 15,
      "z": 9,
      "name": "Rock_Stone_Brick"
    },
    {
      "x": -7,
      "y": 16,
      "z": 9,
      "name": "Rock_Stone_Brick",
      "rotation": 2
    },
    {
      "x": -7,
      "y": 17,
      "z": 9,
      "name": "Rock_Stone_Brick_Decorative",
      "rotation": 2
    },
    {
      "x": -7,
      "y": 18,
      "z": 9,
      "name": "Soil_Gravel_Half",
      "support": 15,
      "rotation": 6
    },
    {
      "x": -7,
      "y": 19,
      "z": 9,
      "name": "Soil_Gravel_Half",
      "support": 15,
      "rotation": 6
    },
    {
      "x": -7,
      "y": 20,
      "z": 9,
      "name": "Soil_Gravel_Half",
      "support": 15,
      "rotation": 6
    },
    {
      "x": -7,
      "y": 21,
      "z": 9,
      "name": "Soil_Gravel_Half",
      "support": 15,
      "rotation": 6
    },
    {
      "x": -7,
      "y": 22,
      "z": 9,
      "name": "Rock_Stone_Brick_Smooth",
      "rotation": 2
    },
    {
      "x": -7,
      "y": 16,
      "z": 10,
      "name": "Rock_Stone_Brick"
    },
    {
      "x": -7,
      "y": 17,
      "z": 10,
      "name": "Rock_Stone_Brick_Decorative",
      "rotation": 2
    },
    {
      "x": -7,
      "y": 18,
      "z": 10,
      "name": "Soil_Gravel",
      "support": 15,
      "rotation": 2
    },
    {
      "x": -7,
      "y": 19,
      "z": 10,
      "name": "Soil_Gravel",
      "support": 15,
      "rotation": 2
    },
    {
      "x": -7,
      "y": 20,
      "z": 10,
      "name": "Soil_Gravel",
      "support": 15,
      "rotation": 2
    },
    {
      "x": -7,
      "y": 21,
      "z": 10,
      "name": "Soil_Gravel",
      "support": 15,
      "rotation": 2
    },
    {
      "x": -7,
      "y": 22,
      "z": 10,
      "name": "Rock_Stone_Brick_Smooth",
      "rotation": 2
    },
    {
      "x": -6,
      "y": 16,
      "z": -10,
      "name": "Rock_Stone_Brick"
    },
    {
      "x": -6,
      "y": 17,
      "z": -10,
      "name": "Rock_Stone_Brick_Decorative",
      "rotation": 1
    },
    {
      "x": -6,
      "y": 18,
      "z": -10,
      "name": "Soil_Gravel",
      "support": 15,
      "rotation": 1
    },
    {
      "x": -6,
      "y": 19,
      "z": -10,
      "name": "Soil_Gravel",
      "support": 15,
      "rotation": 1
    },
    {
      "x": -6,
      "y": 20,
      "z": -10,
      "name": "Soil_Gravel",
      "support": 15,
      "rotation": 1
    },
    {
      "x": -6,
      "y": 21,
      "z": -10,
      "name": "Soil_Gravel",
      "support": 15,
      "rotation": 1
    },
    {
      "x": -6,
      "y": 22,
      "z": -10,
      "name": "Rock_Stone_Brick_Smooth",
      "rotation": 1
    },
    {
      "x": -6,
      "y": 7,
      "z": -9,
      "name": "Rock_Stone_Brick_Half",
      "rotation": 4
    },
    {
      "x": -6,
      "y": 8,
      "z": -9,
      "name": "Rock_Stone_Brick_Smooth"
    },
    {
      "x": -6,
      "y": 9,
      "z": -9,
      "name": "Rock_Stone_Brick_Stairs"
    },
    {
      "x": -6,
      "y": 10,
      "z": -9,
      "name": "Rock_Stone_Brick_Half",
      "rotation": 4
    },
    {
      "x": -6,
      "y": 11,
      "z": -9,
      "name": "Rock_Stone_Brick_Half",
      "rotation": 4
    },
    {
      "x": -6,
      "y": 12,
      "z": -9,
      "name": "Rock_Stone_Brick_Half",
      "rotation": 4
    },
    {
      "x": -6,
      "y": 13,
      "z": -9,
      "name": "Rock_Stone_Brick_Half",
      "rotation": 4
    },
    {
      "x": -6,
      "y": 14,
      "z": -9,
      "name": "Rock_Stone_Brick_Smooth"
    },
    {
      "x": -6,
      "y": 15,
      "z": -9,
      "name": "Rock_Stone_Brick_Smooth"
    },
    {
      "x": -6,
      "y": 16,
      "z": -9,
      "name": "Rock_Stone_Brick_Stairs"
    },
    {
      "x": -6,
      "y": 17,
      "z": -9,
      "name": "Rock_Stone_Brick_Half",
      "rotation": 4
    },
    {
      "x": -6,
      "y": 22,
      "z": -9,
      "name": "Rock_Stone_Brick_Smooth",
      "rotation": 1
    },
    {
      "x": -6,
      "y": 8,
      "z": -8,
      "name": "Rock_Stone_Brick_Smooth"
    },
    {
      "x": -6,
      "y": 9,
      "z": -8,
      "name": "Rock_Stone_Brick_Smooth_Half"
    },
    {
      "x": -6,
      "y": 14,
      "z": -8,
      "name": "Rock_Stone_Brick_Smooth"
    },
    {
      "x": -6,
      "y": 15,
      "z": -8,
      "name": "Rock_Stone_Brick_Smooth"
    },
    {
      "x": -6,
      "y": 16,
      "z": -8,
      "name": "Rock_Stone_Brick_Smooth_Half"
    },
    {
      "x": -6,
      "y": 22,
      "z": -8,
      "name": "Rock_Stone_Brick_Smooth",
      "rotation": 1
    },
    {
      "x": -6,
      "y": 8,
      "z": -7,
      "name": "Rock_Stone_Brick_Smooth"
    },
    {
      "x": -6,
      "y": 14,
      "z": -7,
      "name": "Rock_Stone_Brick_Smooth"
    },
    {
      "x": -6,
      "y": 15,
      "z": -7,
      "name": "Rock_Stone_Brick_Smooth"
    },
    {
      "x": -6,
      "y": 16,
      "z": -7,
      "name": "Rock_Stone_Brick_Smooth_Half"
    },
    {
      "x": -6,
      "y": 22,
      "z": -7,
      "name": "Rock_Stone_Brick_Smooth",
      "rotation": 1
    },
    {
      "x": -6,
      "y": 8,
      "z": -6,
      "name": "Rock_Stone_Brick_Smooth"
    },
    {
      "x": -6,
      "y": 14,
      "z": -6,
      "name": "Rock_Stone_Brick_Smooth"
    },
    {
      "x": -6,
      "y": 15,
      "z": -6,
      "name": "Rock_Stone_Brick_Smooth"
    },
    {
      "x": -6,
      "y": 16,
      "z": -6,
      "name": "Rock_Stone_Brick_Smooth_Half"
    },
    {
      "x": -6,
      "y": 22,
      "z": -6,
      "name": "Rock_Stone_Brick_Smooth",
      "rotation": 1
    },
    {
      "x": -6,
      "y": 8,
      "z": -5,
      "name": "Rock_Stone_Brick_Smooth"
    },
    {
      "x": -6,
      "y": 14,
      "z": -5,
      "name": "Rock_Stone_Brick_Smooth"
    },
    {
      "x": -6,
      "y": 15,
      "z": -5,
      "name": "Rock_Stone_Brick_Smooth"
    },
    {
      "x": -6,
      "y": 16,
      "z": -5,
      "name": "Rock_Stone_Brick_Smooth_Half"
    },
    {
      "x": -6,
      "y": 22,
      "z": -5,
      "name": "Rock_Stone_Brick_Smooth",
      "rotation": 1
    },
    {
      "x": -6,
      "y": 8,
      "z": -4,
      "name": "Rock_Stone_Brick_Smooth"
    },
    {
      "x": -6,
      "y": 14,
      "z": -4,
      "name": "Rock_Stone_Brick_Smooth"
    },
    {
      "x": -6,
      "y": 15,
      "z": -4,
      "name": "Rock_Stone_Brick_Smooth"
    },
    {
      "x": -6,
      "y": 16,
      "z": -4,
      "name": "Rock_Stone_Brick_Smooth_Half"
    },
    {
      "x": -6,
      "y": 22,
      "z": -4,
      "name": "Rock_Stone_Brick",
      "rotation": 1
    },
    {
      "x": -6,
      "y": 8,
      "z": -3,
      "name": "*Rock_Stone_Brick_Stairs_State_Definitions_Inverted_Corner_Right",
      "rotation": 10
    },
    {
      "x": -6,
      "y": 9,
      "z": -3,
      "name": "*Rock_Stone_Brick_Wall_State_Definitions_Corner",
      "rotation": 1
    },
    {
      "x": -6,
      "y": 14,
      "z": -3,
      "name": "*Rock_Stone_Brick_Stairs_State_Definitions_Inverted_Corner_Right",
      "rotation": 10
    },
    {
      "x": -6,
      "y": 15,
      "z": -3,
      "name": "Rock_Stone_Brick_Smooth"
    },
    {
      "x": -6,
      "y": 16,
      "z": -3,
      "name": "*Rock_Stone_Brick_Stairs_State_Definitions_Inverted_Corner_Left",
      "rotation": 11
    },
    {
      "x": -6,
      "y": 17,
      "z": -3,
      "name": "*Rock_Stone_Brick_Wall_State_Definitions_Corner",
      "rotation": 1
    },
    {
      "x": -6,
      "y": 22,
      "z": -3,
      "name": "*Rock_Stone_Brick_Stairs_State_Definitions_Inverted_Corner_Right",
      "rotation": 32
    },
    {
      "x": -6,
      "y": 8,
      "z": -2,
      "name": "Rock_Stone_Brick_Stairs",
      "rotation": 11
    },
    {
      "x": -6,
      "y": 9,
      "z": -2,
      "name": "Rock_Stone_Brick_Wall",
      "rotation": 1
    },
    {
      "x": -6,
      "y": 14,
      "z": -2,
      "name": "Rock_Stone_Brick_Stairs",
      "rotation": 11
    },
    {
      "x": -6,
      "y": 15,
      "z": -2,
      "name": "Rock_Stone_Brick_Half",
      "rotation": 5
    },
    {
      "x": -6,
      "y": 16,
      "z": -2,
      "name": "Rock_Stone_Brick_Stairs",
      "rotation": 33
    },
    {
      "x": -6,
      "y": 17,
      "z": -2,
      "name": "Rock_Stone_Brick_Wall",
      "rotation": 1
    },
    {
      "x": -6,
      "y": 22,
      "z": -2,
      "name": "Rock_Stone_Brick_Stairs",
      "rotation": 33
    },
    {
      "x": -6,
      "y": 8,
      "z": -1,
      "name": "Rock_Stone_Brick_Stairs",
      "rotation": 11
    },
    {
      "x": -6,
      "y": 9,
      "z": -1,
      "name": "Rock_Stone_Brick_Wall",
      "rotation": 1
    },
    {
      "x": -6,
      "y": 14,
      "z": -1,
      "name": "Rock_Stone_Brick_Stairs",
      "rotation": 1
    },
    {
      "x": -6,
      "y": 15,
      "z": -1,
      "name": "Rock_Stone_Brick_Smooth_Half",
      "rotation": 5
    },
    {
      "x": -6,
      "y": 16,
      "z": -1,
      "name": "Rock_Stone_Brick_Stairs",
      "rotation": 33
    },
    {
      "x": -6,
      "y": 17,
      "z": -1,
      "name": "Rock_Stone_Brick_Wall",
      "rotation": 1
    },
    {
      "x": -6,
      "y": 22,
      "z": -1,
      "name": "Rock_Stone_Brick_Stairs",
      "rotation": 33
    },
    {
      "x": -6,
      "y": 7,
      "z": 0,
      "name": "Rock_Stone_Brick_Half",
      "rotation": 8
    },
    {
      "x": -6,
      "y": 8,
      "z": 0,
      "name": "*Rock_Stone_Brick_Half_State_Definitions_Block",
      "rotation": 5
    },
    {
      "x": -6,
      "y": 9,
      "z": 0,
      "name": "Rock_Stone_Brick_Wall",
      "rotation": 1
    },
    {
      "x": -6,
      "y": 13,
      "z": 0,
      "name": "Rock_Stone_Brick_Half",
      "rotation": 8
    },
    {
      "x": -6,
      "y": 14,
      "z": 0,
      "name": "Rock_Stone_Brick_Stairs",
      "rotation": 1
    },
    {
      "x": -6,
      "y": 15,
      "z": 0,
      "name": "Rock_Stone_Brick_Smooth_Half",
      "rotation": 5
    },
    {
      "x": -6,
      "y": 16,
      "z": 0,
      "name": "Rock_Stone_Brick_Stairs",
      "rotation": 33
    },
    {
      "x": -6,
      "y": 17,
      "z": 0,
      "name": "Rock_Stone_Brick_Wall",
      "rotation": 3
    },
    {
      "x": -6,
      "y": 22,
      "z": 0,
      "name": "Rock_Stone_Brick_Stairs",
      "rotation": 33
    },
    {
      "x": -6,
      "y": 7,
      "z": 1,
      "name": "Rock_Stone_Brick_Stairs",
      "rotation": 11
    },
    {
      "x": -6,
      "y": 8,
      "z": 1,
      "name": "Custom_Stone_Bricks_Wall6"
    },
    {
      "x": -6,
      "y": 9,
      "z": 1,
      "name": "Custom_Stone_Bricks_Wall6",
      "rotation": 2
    },
    {
      "x": -6,
      "y": 13,
      "z": 1,
      "name": "Rock_Stone_Brick_Stairs",
      "rotation": 11
    },
    {
      "x": -6,
      "y": 14,
      "z": 1,
      "name": "Rock_Stone_Brick_Smooth_Half",
      "rotation": 5
    },
    {
      "x": -6,
      "y": 15,
      "z": 1,
      "name": "Rock_Stone_Brick_Smooth_Half",
      "rotation": 5
    },
    {
      "x": -6,
      "y": 16,
      "z": 1,
      "name": "Rock_Stone_Brick_Stairs",
      "rotation": 33
    },
    {
      "x": -6,
      "y": 17,
      "z": 1,
      "name": "Rock_Stone_Brick_Wall",
      "rotation": 3
    },
    {
      "x": -6,
      "y": 22,
      "z": 1,
      "name": "Rock_Stone_Brick_Stairs",
      "rotation": 33
    },
    {
      "x": -6,
      "y": 7,
      "z": 2,
      "name": "Rock_Stone_Brick_Stairs",
      "rotation": 11
    },
    {
      "x": -6,
      "y": 8,
      "z": 2,
      "name": "Rock_Stone_Brick_Wall",
      "rotation": 1
    },
    {
      "x": -6,
      "y": 13,
      "z": 2,
      "name": "Rock_Stone_Brick_Stairs",
      "rotation": 11
    },
    {
      "x": -6,
      "y": 14,
      "z": 2,
      "name": "Rock_Stone_Brick_Half",
      "rotation": 5
    },
    {
      "x": -6,
      "y": 15,
      "z": 2,
      "name": "Rock_Stone_Brick_Half",
      "rotation": 5
    },
    {
      "x": -6,
      "y": 16,
      "z": 2,
      "name": "Rock_Stone_Brick_Stairs",
      "rotation": 11
    },
    {
      "x": -6,
      "y": 17,
      "z": 2,
      "name": "Rock_Stone_Brick_Wall",
      "rotation": 3
    },
    {
      "x": -6,
      "y": 22,
      "z": 2,
      "name": "Rock_Stone_Brick_Stairs",
      "rotation": 33
    },
    {
      "x": -6,
      "y": 7,
      "z": 3,
      "name": "*Rock_Stone_Brick_Stairs_State_Definitions_Inverted_Corner_Left",
      "rotation": 8
    },
    {
      "x": -6,
      "y": 8,
      "z": 3,
      "name": "Custom_Stone_Bricks_Wall3",
      "rotation": 2
    },
    {
      "x": -6,
      "y": 13,
      "z": 3,
      "name": "*Rock_Stone_Brick_Stairs_State_Definitions_Inverted_Corner_Left",
      "rotation": 8
    },
    {
      "x": -6,
      "y": 14,
      "z": 3,
      "name": "Rock_Stone_Brick_Smooth"
    },
    {
      "x": -6,
      "y": 15,
      "z": 3,
      "name": "Rock_Stone_Brick_Smooth"
    },
    {
      "x": -6,
      "y": 16,
      "z": 3,
      "name": "*Rock_Stone_Brick_Stairs_State_Definitions_Inverted_Corner_Left",
      "rotation": 8
    },
    {
      "x": -6,
      "y": 17,
      "z": 3,
      "name": "*Rock_Stone_Brick_Wall_State_Definitions_Corner",
      "rotation": 2
    },
    {
      "x": -6,
      "y": 22,
      "z": 3,
      "name": "*Rock_Stone_Brick_Stairs_State_Definitions_Inverted_Corner_Left",
      "rotation": 34
    },
    {
      "x": -6,
      "y": 7,
      "z": 4,
      "name": "Rock_Stone_Brick_Smooth"
    },
    {
      "x": -6,
      "y": 13,
      "z": 4,
      "name": "Rock_Stone_Brick_Smooth"
    },
    {
      "x": -6,
      "y": 14,
      "z": 4,
      "name": "Rock_Stone_Brick_Smooth"
    },
    {
      "x": -6,
      "y": 15,
      "z": 4,
      "name": "Rock_Stone_Brick_Smooth"
    },
    {
      "x": -6,
      "y": 16,
      "z": 4,
      "name": "Rock_Stone_Brick_Smooth"
    },
    {
      "x": -6,
      "y": 22,
      "z": 4,
      "name": "Rock_Stone_Brick",
      "rotation": 2
    },
    {
      "x": -6,
      "y": 7,
      "z": 5,
      "name": "Rock_Stone_Brick_Smooth"
    },
    {
      "x": -6,
      "y": 13,
      "z": 5,
      "name": "Rock_Stone_Brick_Smooth"
    },
    {
      "x": -6,
      "y": 14,
      "z": 5,
      "name": "Rock_Stone_Brick_Smooth_Half"
    },
    {
      "x": -6,
      "y": 22,
      "z": 5,
      "name": "Rock_Stone_Brick_Smooth",
      "rotation": 2
    },
    {
      "x": -6,
      "y": 7,
      "z": 6,
      "name": "Rock_Stone_Brick_Smooth"
    },
    {
      "x": -6,
      "y": 13,
      "z": 6,
      "name": "Rock_Stone_Brick_Smooth"
    },
    {
      "x": -6,
      "y": 14,
      "z": 6,
      "name": "Rock_Stone_Brick_Smooth_Half"
    },
    {
      "x": -6,
      "y": 22,
      "z": 6,
      "name": "Rock_Stone_Brick_Smooth",
      "rotation": 2
    },
    {
      "x": -6,
      "y": 7,
      "z": 7,
      "name": "Rock_Stone_Brick_Smooth"
    },
    {
      "x": -6,
      "y": 13,
      "z": 7,
      "name": "Rock_Stone_Brick_Smooth"
    },
    {
      "x": -6,
      "y": 14,
      "z": 7,
      "name": "Rock_Stone_Brick_Smooth_Half"
    },
    {
      "x": -6,
      "y": 22,
      "z": 7,
      "name": "Rock_Stone_Brick_Smooth",
      "rotation": 2
    },
    {
      "x": -6,
      "y": 7,
      "z": 8,
      "name": "Rock_Stone_Brick_Smooth"
    },
    {
      "x": -6,
      "y": 13,
      "z": 8,
      "name": "Rock_Stone_Brick_Smooth"
    },
    {
      "x": -6,
      "y": 14,
      "z": 8,
      "name": "Rock_Stone_Brick_Smooth_Half"
    },
    {
      "x": -6,
      "y": 22,
      "z": 8,
      "name": "Rock_Stone_Brick_Smooth",
      "rotation": 2
    },
    {
      "x": -6,
      "y": 7,
      "z": 9,
      "name": "Rock_Stone_Brick_Smooth"
    },
    {
      "x": -6,
      "y": 8,
      "z": 9,
      "name": "Rock_Stone_Brick_Half",
      "rotation": 6
    },
    {
      "x": -6,
      "y": 9,
      "z": 9,
      "name": "Rock_Stone_Brick_Half",
      "rotation": 6
    },
    {
      "x": -6,
      "y": 10,
      "z": 9,
      "name": "Rock_Stone_Brick_Half",
      "rotation": 6
    },
    {
      "x": -6,
      "y": 11,
      "z": 9,
      "name": "Rock_Stone_Brick_Half",
      "rotation": 6
    },
    {
      "x": -6,
      "y": 12,
      "z": 9,
      "name": "Rock_Stone_Brick_Half",
      "rotation": 6
    },
    {
      "x": -6,
      "y": 13,
      "z": 9,
      "name": "Rock_Stone_Brick_Smooth"
    },
    {
      "x": -6,
      "y": 14,
      "z": 9,
      "name": "Rock_Stone_Brick_Half",
      "rotation": 6
    },
    {
      "x": -6,
      "y": 15,
      "z": 9,
      "name": "Rock_Stone_Brick_Half",
      "rotation": 6
    },
    {
      "x": -6,
      "y": 16,
      "z": 9,
      "name": "Rock_Stone_Brick_Half",
      "rotation": 6
    },
    {
      "x": -6,
      "y": 17,
      "z": 9,
      "name": "Rock_Stone_Brick_Half",
      "rotation": 6
    },
    {
      "x": -6,
      "y": 22,
      "z": 9,
      "name": "Rock_Stone_Brick_Smooth",
      "rotation": 2
    },
    {
      "x": -6,
      "y": 14,
      "z": 10,
      "name": "Rock_Stone_Brick"
    },
    {
      "x": -6,
      "y": 15,
      "z": 10,
      "name": "Rock_Stone_Brick"
    },
    {
      "x": -6,
      "y": 16,
      "z": 10,
      "name": "Rock_Stone_Brick"
    },
    {
      "x": -6,
      "y": 17,
      "z": 10,
      "name": "Rock_Stone_Brick_Decorative",
      "rotation": 2
    },
    {
      "x": -6,
      "y": 18,
      "z": 10,
      "name": "Soil_Gravel",
      "support": 15,
      "rotation": 2
    },
    {
      "x": -6,
      "y": 19,
      "z": 10,
      "name": "Soil_Gravel",
      "support": 15,
      "rotation": 2
    },
    {
      "x": -6,
      "y": 20,
      "z": 10,
      "name": "Soil_Gravel",
      "support": 15,
      "rotation": 2
    },
    {
      "x": -6,
      "y": 21,
      "z": 10,
      "name": "Soil_Gravel",
      "support": 15,
      "rotation": 2
    },
    {
      "x": -6,
      "y": 22,
      "z": 10,
      "name": "Rock_Stone_Brick_Smooth",
      "rotation": 2
    },
    {
      "x": -5,
      "y": 16,
      "z": -11,
      "name": "Rock_Stone_Brick"
    },
    {
      "x": -5,
      "y": 17,
      "z": -11,
      "name": "Rock_Stone_Brick_Decorative",
      "rotation": 1
    },
    {
      "x": -5,
      "y": 18,
      "z": -11,
      "name": "Soil_Gravel",
      "support": 15,
      "rotation": 1
    },
    {
      "x": -5,
      "y": 19,
      "z": -11,
      "name": "Soil_Gravel",
      "support": 15,
      "rotation": 1
    },
    {
      "x": -5,
      "y": 20,
      "z": -11,
      "name": "Soil_Gravel",
      "support": 15,
      "rotation": 1
    },
    {
      "x": -5,
      "y": 21,
      "z": -11,
      "name": "Soil_Gravel",
      "support": 15,
      "rotation": 1
    },
    {
      "x": -5,
      "y": 22,
      "z": -11,
      "name": "Rock_Stone_Brick_Smooth",
      "rotation": 1
    },
    {
      "x": -5,
      "y": 7,
      "z": -10,
      "name": "Rock_Stone_Brick"
    },
    {
      "x": -5,
      "y": 8,
      "z": -10,
      "name": "Rock_Stone_Brick"
    },
    {
      "x": -5,
      "y": 9,
      "z": -10,
      "name": "Rock_Stone_Brick"
    },
    {
      "x": -5,
      "y": 10,
      "z": -10,
      "name": "Rock_Stone_Brick"
    },
    {
      "x": -5,
      "y": 11,
      "z": -10,
      "name": "Rock_Stone_Brick"
    },
    {
      "x": -5,
      "y": 12,
      "z": -10,
      "name": "Rock_Stone_Brick"
    },
    {
      "x": -5,
      "y": 13,
      "z": -10,
      "name": "Rock_Stone_Brick"
    },
    {
      "x": -5,
      "y": 14,
      "z": -10,
      "name": "Rock_Stone_Brick"
    },
    {
      "x": -5,
      "y": 15,
      "z": -10,
      "name": "Rock_Stone_Brick"
    },
    {
      "x": -5,
      "y": 16,
      "z": -10,
      "name": "Rock_Stone_Brick",
      "rotation": 1
    },
    {
      "x": -5,
      "y": 17,
      "z": -10,
      "name": "Rock_Stone_Brick_Decorative",
      "rotation": 1
    },
    {
      "x": -5,
      "y": 18,
      "z": -10,
      "name": "Rock_Stone_Brick_Pillar_Base",
      "rotation": 1
    },
    {
      "x": -5,
      "y": 19,
      "z": -10,
      "name": "Rock_Stone_Brick_Pillar_Middle",
      "rotation": 1
    },
    {
      "x": -5,
      "y": 20,
      "z": -10,
      "name": "Rock_Stone_Brick_Pillar_Middle",
      "rotation": 1
    },
    {
      "x": -5,
      "y": 21,
      "z": -10,
      "name": "Rock_Stone_Brick_Pillar_Base",
      "rotation": 35
    },
    {
      "x": -5,
      "y": 22,
      "z": -10,
      "name": "Rock_Stone_Brick_Smooth",
      "rotation": 1
    },
    {
      "x": -5,
      "y": 8,
      "z": -9,
      "name": "Rock_Stone_Brick_Smooth"
    },
    {
      "x": -5,
      "y": 9,
      "z": -9,
      "name": "Rock_Stone_Brick_Smooth_Half"
    },
    {
      "x": -5,
      "y": 14,
      "z": -9,
      "name": "Rock_Stone_Brick_Smooth"
    },
    {
      "x": -5,
      "y": 15,
      "z": -9,
      "name": "Rock_Stone_Brick_Smooth"
    },
    {
      "x": -5,
      "y": 16,
      "z": -9,
      "name": "Rock_Stone_Brick_Smooth"
    },
    {
      "x": -5,
      "y": 22,
      "z": -9,
      "name": "Rock_Stone_Brick_Smooth",
      "rotation": 1
    },
    {
      "x": -5,
      "y": 8,
      "z": -8,
      "name": "Rock_Stone_Brick_Smooth"
    },
    {
      "x": -5,
      "y": 9,
      "z": -8,
      "name": "Rock_Stone_Brick_Smooth_Half"
    },
    {
      "x": -5,
      "y": 14,
      "z": -8,
      "name": "Rock_Stone_Brick_Smooth"
    },
    {
      "x": -5,
      "y": 15,
      "z": -8,
      "name": "Rock_Stone_Brick_Smooth"
    },
    {
      "x": -5,
      "y": 16,
      "z": -8,
      "name": "Rock_Stone_Brick_Smooth"
    },
    {
      "x": -5,
      "y": 22,
      "z": -8,
      "name": "Rock_Stone_Brick_Smooth",
      "rotation": 1
    },
    {
      "x": -5,
      "y": 8,
      "z": -7,
      "name": "Rock_Stone_Brick_Smooth"
    },
    {
      "x": -5,
      "y": 9,
      "z": -7,
      "name": "Rock_Stone_Brick_Smooth_Half"
    },
    {
      "x": -5,
      "y": 14,
      "z": -7,
      "name": "Rock_Stone_Brick_Smooth"
    },
    {
      "x": -5,
      "y": 15,
      "z": -7,
      "name": "Rock_Stone_Brick_Smooth"
    },
    {
      "x": -5,
      "y": 16,
      "z": -7,
      "name": "Rock_Stone_Brick_Smooth_Half"
    },
    {
      "x": -5,
      "y": 22,
      "z": -7,
      "name": "Rock_Stone_Brick_Smooth",
      "rotation": 1
    },
    {
      "x": -5,
      "y": 8,
      "z": -6,
      "name": "Rock_Stone_Brick_Smooth"
    },
    {
      "x": -5,
      "y": 9,
      "z": -6,
      "name": "Rock_Stone_Brick_Smooth_Half"
    },
    {
      "x": -5,
      "y": 14,
      "z": -6,
      "name": "Rock_Stone_Brick_Smooth"
    },
    {
      "x": -5,
      "y": 15,
      "z": -6,
      "name": "Rock_Stone_Brick_Smooth"
    },
    {
      "x": -5,
      "y": 16,
      "z": -6,
      "name": "Rock_Stone_Brick_Smooth_Half"
    },
    {
      "x": -5,
      "y": 22,
      "z": -6,
      "name": "Rock_Stone_Brick_Smooth",
      "rotation": 1
    },
    {
      "x": -5,
      "y": 7,
      "z": -5,
      "name": "Rock_Stone_Brick_Pillar_Base",
      "rotation": 8
    },
    {
      "x": -5,
      "y": 8,
      "z": -5,
      "name": "Rock_Stone_Brick_Smooth"
    },
    {
      "x": -5,
      "y": 9,
      "z": -5,
      "name": "Rock_Stone_Brick_Decorative"
    },
    {
      "x": -5,
      "y": 10,
      "z": -5,
      "name": "Rock_Stone_Brick_Pillar_Base"
    },
    {
      "x": -5,
      "y": 11,
      "z": -5,
      "name": "Rock_Stone_Brick_Pillar_Middle"
    },
    {
      "x": -5,
      "y": 12,
      "z": -5,
      "name": "Rock_Stone_Brick_Pillar_Middle"
    },
    {
      "x": -5,
      "y": 13,
      "z": -5,
      "name": "Rock_Stone_Brick_Pillar_Base",
      "rotation": 8
    },
    {
      "x": -5,
      "y": 14,
      "z": -5,
      "name": "Rock_Stone_Brick_Smooth"
    },
    {
      "x": -5,
      "y": 15,
      "z": -5,
      "name": "Rock_Stone_Brick"
    },
    {
      "x": -5,
      "y": 16,
      "z": -5,
      "name": "Rock_Stone_Brick",
      "rotation": 1
    },
    {
      "x": -5,
      "y": 17,
      "z": -5,
      "name": "Rock_Stone_Brick_Decorative",
      "rotation": 1
    },
    {
      "x": -5,
      "y": 18,
      "z": -5,
      "name": "Rock_Stone_Brick_Pillar_Base",
      "rotation": 1
    },
    {
      "x": -5,
      "y": 19,
      "z": -5,
      "name": "Rock_Stone_Brick_Pillar_Middle",
      "rotation": 1
    },
    {
      "x": -5,
      "y": 20,
      "z": -5,
      "name": "Rock_Stone_Brick_Pillar_Middle",
      "rotation": 1
    },
    {
      "x": -5,
      "y": 21,
      "z": -5,
      "name": "Rock_Stone_Brick_Pillar_Base",
      "rotation": 35
    },
    {
      "x": -5,
      "y": 22,
      "z": -5,
      "name": "Rock_Stone_Brick",
      "rotation": 1
    },
    {
      "x": -5,
      "y": 8,
      "z": -4,
      "name": "*Rock_Stone_Brick_Stairs_State_Definitions_Inverted_Corner_Left",
      "rotation": 11
    },
    {
      "x": -5,
      "y": 9,
      "z": -4,
      "name": "*Rock_Stone_Brick_Wall_State_Definitions_Corner",
      "rotation": 1
    },
    {
      "x": -5,
      "y": 14,
      "z": -4,
      "name": "*Rock_Stone_Brick_Stairs_State_Definitions_Inverted_Corner_Left",
      "rotation": 11
    },
    {
      "x": -5,
      "y": 15,
      "z": -4,
      "name": "Rock_Stone_Brick_Smooth_Half",
      "rotation": 5
    },
    {
      "x": -5,
      "y": 16,
      "z": -4,
      "name": "*Rock_Stone_Brick_Stairs_State_Definitions_Inverted_Corner_Left",
      "rotation": 11
    },
    {
      "x": -5,
      "y": 17,
      "z": -4,
      "name": "*Rock_Stone_Brick_Wall_State_Definitions_Corner",
      "rotation": 1
    },
    {
      "x": -5,
      "y": 22,
      "z": -4,
      "name": "*Rock_Stone_Brick_Stairs_State_Definitions_Inverted_Corner_Left",
      "rotation": 33
    },
    {
      "x": -5,
      "y": 8,
      "z": -3,
      "name": "*Rock_Stone_Brick_Stairs_State_Definitions_Corner_Left",
      "rotation": 11
    },
    {
      "x": -5,
      "y": 9,
      "z": -3,
      "name": "*Rock_Stone_Brick_Wall_State_Definitions_Corner",
      "rotation": 3
    },
    {
      "x": -5,
      "y": 14,
      "z": -3,
      "name": "*Rock_Stone_Brick_Stairs_State_Definitions_Corner_Left",
      "rotation": 11
    },
    {
      "x": -5,
      "y": 16,
      "z": -3,
      "name": "*Rock_Stone_Brick_Stairs_State_Definitions_Corner_Right",
      "rotation": 10
    },
    {
      "x": -5,
      "y": 17,
      "z": -3,
      "name": "*Rock_Stone_Brick_Wall_State_Definitions_Corner",
      "rotation": 3
    },
    {
      "x": -5,
      "y": 22,
      "z": -3,
      "name": "*Rock_Stone_Brick_Stairs_State_Definitions_Corner_Left",
      "rotation": 33
    },
    {
      "x": -5,
      "y": 7,
      "z": 3,
      "name": "*Rock_Stone_Brick_Stairs_State_Definitions_Corner_Right",
      "rotation": 11
    },
    {
      "x": -5,
      "y": 8,
      "z": 3,
      "name": "Custom_Stone_Bricks_Wall3"
    },
    {
      "x": -5,
      "y": 13,
      "z": 3,
      "name": "*Rock_Stone_Brick_Stairs_State_Definitions_Corner_Right",
      "rotation": 11
    },
    {
      "x": -5,
      "y": 16,
