{
  "version": 8,
  "blockIdVersion": 11,
  "anchorX": 0,
  "anchorY": 9,
  "anchorZ": 0,
  "blocks": [
    {
      "x": -16,
      "y": 13,
      "z": -16,
      "name": "Cloth_Block_Wool_Green"
    },
    {
      "x": -16,
      "y": 13,
      "z": -15,
      "name": "Cloth_Block_Wool_Green"
    },
    {
      "x": -16,
      "y": 13,
      "z": -14,
      "name": "Cloth_Block_Wool_Green"
    },
    {
      "x": -16,
      "y": 13,
      "z": -13,
      "name": "Cloth_Block_Wool_Green"
    },
    {
      "x": -16,
      "y": 13,
      "z": -12,
      "name": "Cloth_Block_Wool_Green"
    },
    {
      "x": -16,
      "y": 13,
      "z": -11,
      "name": "Cloth_Block_Wool_Green"
    },
    {
      "x": -16,
      "y": 13,
      "z": -10,
      "name": "Cloth_Block_Wool_Green"
    },
    {
      "x": -16,
      "y": 13,
      "z": -9,
      "name": "Cloth_Block_Wool_Green"
    },
    {
      "x": -16,
      "y": 13,
      "z": -8,
      "name": "Cloth_Block_Wool_Green"
    },
    {
      "x": -16,
      "y": 13,
      "z": -7,
      "name": "Cloth_Block_Wool_Green"
    },
    {
      "x": -16,
      "y": 13,
      "z": -6,
      "name": "Cloth_Block_Wool_Green"
    },
    {
      "x": -16,
      "y": 13,
      "z": -5,
      "name": "Cloth_Block_Wool_Pink",
      "rotation": 3
    },
    {
      "x": -16,
      "y": 13,
      "z": -4,
      "name": "Cloth_Block_Wool_Pink",
      "rotation": 3
    },
    {
      "x": -16,
      "y": 13,
      "z": -3,
      "name": "Cloth_Block_Wool_Pink",
      "rotation": 3
    },
    {
      "x": -16,
      "y": 13,
      "z": -2,
      "name": "Cloth_Block_Wool_Pink",
      "rotation": 3
    },
    {
      "x": -16,
      "y": 13,
      "z": -1,
      "name": "Cloth_Block_Wool_Pink",
      "rotation": 3
    },
    {
      "x": -16,
      "y": 13,
      "z": 0,
      "name": "Cloth_Block_Wool_Pink"
    },
    {
      "x": -16,
      "y": 13,
      "z": 1,
      "name": "Cloth_Block_Wool_Pink",
      "rotation": 3
    },
    {
      "x": -16,
      "y": 13,
      "z": 2,
      "name": "Cloth_Block_Wool_Pink",
      "rotation": 3
    },
    {
      "x": -16,
      "y": 13,
      "z": 3,
      "name": "Cloth_Block_Wool_Pink",
      "rotation": 3
    },
    {
      "x": -16,
      "y": 13,
      "z": 4,
      "name": "Cloth_Block_Wool_Pink",
      "rotation": 3
    },
    {
      "x": -16,
      "y": 13,
      "z": 5,
      "name": "Cloth_Block_Wool_Pink",
      "rotation": 3
    },
    {
      "x": -16,
      "y": 13,
      "z": 6,
      "name": "Cloth_Block_Wool_Green",
      "rotation": 1
    },
    {
      "x": -16,
      "y": 13,
      "z": 7,
      "name": "Cloth_Block_Wool_Green",
      "rotation": 1
    },
    {
      "x": -16,
      "y": 13,
      "z": 8,
      "name": "Cloth_Block_Wool_Green",
      "rotation": 1
    },
    {
      "x": -16,
      "y": 13,
      "z": 9,
      "name": "Cloth_Block_Wool_Green",
      "rotation": 1
    },
    {
      "x": -16,
      "y": 13,
      "z": 10,
      "name": "Cloth_Block_Wool_Green",
      "rotation": 1
    },
    {
      "x": -16,
      "y": 13,
      "z": 11,
      "name": "Cloth_Block_Wool_Green",
      "rotation": 1
    },
    {
      "x": -16,
      "y": 13,
      "z": 12,
      "name": "Cloth_Block_Wool_Green",
      "rotation": 1
    },
    {
      "x": -16,
      "y": 13,
      "z": 13,
      "name": "Cloth_Block_Wool_Green",
      "rotation": 1
    },
    {
      "x": -16,
      "y": 13,
      "z": 14,
      "name": "Cloth_Block_Wool_Green",
      "rotation": 1
    },
    {
      "x": -16,
      "y": 13,
      "z": 15,
      "name": "Cloth_Block_Wool_Green",
      "rotation": 1
    },
    {
      "x": -16,
      "y": 13,
      "z": 16,
      "name": "Cloth_Block_Wool_Green",
      "rotation": 1
    },
    {
      "x": -15,
      "y": 13,
      "z": -16,
      "name": "Cloth_Block_Wool_Green"
    },
    {
      "x": -15,
      "y": 13,
      "z": -6,
      "name": "Cloth_Block_Wool_Green"
    },
    {
      "x": -15,
      "y": 13,
      "z": -5,
      "name": "Cloth_Block_Wool_Pink",
      "rotation": 3
    },
    {
      "x": -15,
      "y": 13,
      "z": 5,
      "name": "Cloth_Block_Wool_Pink",
      "rotation": 3
    },
    {
      "x": -15,
      "y": 13,
      "z": 6,
      "name": "Cloth_Block_Wool_Green",
      "rotation": 1
    },
    {
      "x": -15,
      "y": 13,
      "z": 16,
      "name": "Cloth_Block_Wool_Green",
      "rotation": 1
    },
    {
      "x": -14,
      "y": 13,
      "z": -16,
      "name": "Cloth_Block_Wool_Green"
    },
    {
      "x": -14,
      "y": 13,
      "z": -6,
      "name": "Cloth_Block_Wool_Green"
    },
    {
      "x": -14,
      "y": 13,
      "z": -5,
      "name": "Cloth_Block_Wool_Pink",
      "rotation": 3
    },
    {
      "x": -14,
      "y": 13,
      "z": 5,
      "name": "Cloth_Block_Wool_Pink",
      "rotation": 3
    },
    {
      "x": -14,
      "y": 13,
      "z": 6,
      "name": "Cloth_Block_Wool_Green",
      "rotation": 1
    },
    {
      "x": -14,
      "y": 13,
      "z": 16,
      "name": "Cloth_Block_Wool_Green",
      "rotation": 1
    },
    {
      "x": -13,
      "y": 13,
      "z": -16,
      "name": "Cloth_Block_Wool_Green"
    },
    {
      "x": -13,
      "y": 13,
      "z": -6,
      "name": "Cloth_Block_Wool_Green"
    },
    {
      "x": -13,
      "y": 13,
      "z": -5,
      "name": "Cloth_Block_Wool_Pink",
      "rotation": 3
    },
    {
      "x": -13,
      "y": 3,
      "z": -1,
      "name": "Rock_Stone_Brick_Decorative"
    },
    {
      "x": -13,
      "y": 4,
      "z": -1,
      "name": "Soil_Gravel",
      "support": 15
    },
    {
      "x": -13,
      "y": 5,
      "z": -1,
      "name": "Soil_Gravel",
      "support": 15
    },
    {
      "x": -13,
      "y": 6,
      "z": -1,
      "name": "Soil_Gravel",
      "support": 15
    },
    {
      "x": -13,
      "y": 7,
      "z": -1,
      "name": "Soil_Gravel",
      "support": 15
    },
    {
      "x": -13,
      "y": 8,
      "z": -1,
      "name": "Soil_Gravel",
      "support": 15
    },
    {
      "x": -13,
      "y": 3,
      "z": 0,
      "name": "Rock_Stone_Brick_Decorative"
    },
    {
      "x": -13,
      "y": 4,
      "z": 0,
      "name": "Soil_Gravel",
      "support": 15
    },
    {
      "x": -13,
      "y": 5,
      "z": 0,
      "name": "Soil_Gravel",
      "support": 15
    },
    {
      "x": -13,
      "y": 6,
      "z": 0,
      "name": "Soil_Gravel",
      "support": 15
    },
    {
      "x": -13,
      "y": 7,
      "z": 0,
      "name": "Soil_Gravel",
      "support": 15
    },
    {
      "x": -13,
      "y": 8,
      "z": 0,
      "name": "Soil_Gravel",
      "support": 15
    },
    {
      "x": -13,
      "y": 3,
      "z": 1,
      "name": "Rock_Stone_Brick_Decorative"
    },
    {
      "x": -13,
      "y": 4,
      "z": 1,
      "name": "Soil_Gravel",
      "support": 15
    },
    {
      "x": -13,
      "y": 5,
      "z": 1,
      "name": "Soil_Gravel",
      "support": 15
    },
    {
      "x": -13,
      "y": 6,
      "z": 1,
      "name": "Soil_Gravel",
      "support": 15
    },
    {
      "x": -13,
      "y": 7,
      "z": 1,
      "name": "Soil_Gravel",
      "support": 15
    },
    {
      "x": -13,
      "y": 8,
      "z": 1,
      "name": "Soil_Gravel",
      "support": 15
    },
    {
      "x": -13,
      "y": 13,
      "z": 5,
      "name": "Cloth_Block_Wool_Pink",
      "rotation": 3
    },
    {
      "x": -13,
      "y": 13,
      "z": 6,
      "name": "Cloth_Block_Wool_Green",
      "rotation": 1
    },
    {
      "x": -13,
      "y": 13,
      "z": 16,
      "name": "Cloth_Block_Wool_Green",
      "rotation": 1
    },
    {
      "x": -12,
      "y": 13,
      "z": -16,
      "name": "Cloth_Block_Wool_Green"
    },
    {
      "x": -12,
      "y": 13,
      "z": -6,
      "name": "Cloth_Block_Wool_Green"
    },
    {
      "x": -12,
      "y": 13,
      "z": -5,
      "name": "Cloth_Block_Wool_Pink",
      "rotation": 3
    },
    {
      "x": -12,
      "y": 4,
      "z": -2,
      "name": "Rock_Stone_Brick_Decorative",
      "rotation": 1
    },
    {
      "x": -12,
      "y": 5,
      "z": -2,
      "name": "Rock_Stone_Brick",
      "rotation": 1
    },
    {
      "x": -12,
      "y": 6,
      "z": -2,
      "name": "Rock_Stone_Brick",
      "rotation": 1
    },
    {
      "x": -12,
      "y": 7,
      "z": -2,
      "name": "Rock_Stone_Brick",
      "rotation": 1
    },
    {
      "x": -12,
      "y": 8,
      "z": -2,
      "name": "Rock_Stone_Brick",
      "rotation": 1
    },
    {
      "x": -12,
      "y": 9,
      "z": -2,
      "name": "Rock_Stone_Brick"
    },
    {
      "x": -12,
      "y": 3,
      "z": -1,
      "name": "Rock_Stone_Brick_Smooth"
    },
    {
      "x": -12,
      "y": 4,
      "z": -1,
      "name": "Rock_Stone_Brick_Smooth_Half",
      "rotation": 4
    },
    {
      "x": -12,
      "y": 5,
      "z": -1,
      "name": "Rock_Stone_Brick_Smooth_Half",
      "rotation": 4
    },
    {
      "x": -12,
      "y": 6,
      "z": -1,
      "name": "Rock_Stone_Brick_Smooth_Half",
      "rotation": 4
    },
    {
      "x": -12,
      "y": 7,
      "z": -1,
      "name": "Rock_Stone_Brick_Stairs",
      "rotation": 10
    },
    {
      "x": -12,
      "y": 8,
      "z": -1,
      "name": "Rock_Stone_Brick_Decorative",
      "rotation": 1
    },
    {
      "x": -12,
      "y": 9,
      "z": -1,
      "name": "Rock_Stone_Brick"
    },
    {
      "x": -12,
      "y": 3,
      "z": 0,
      "name": "Rock_Stone_Brick_Smooth"
    },
    {
      "x": -12,
      "y": 7,
      "z": 0,
      "name": "Rock_Stone_Brick_Smooth_Half",
      "rotation": 8
    },
    {
      "x": -12,
      "y": 8,
      "z": 0,
      "name": "Rock_Stone_Brick_Decorative",
      "rotation": 1
    },
    {
      "x": -12,
      "y": 9,
      "z": 0,
      "name": "Rock_Stone_Brick"
    },
    {
      "x": -12,
      "y": 3,
      "z": 1,
      "name": "Rock_Stone_Brick_Smooth"
    },
    {
      "x": -12,
      "y": 4,
      "z": 1,
      "name": "Rock_Stone_Brick_Smooth_Half",
      "rotation": 6
    },
    {
      "x": -12,
      "y": 5,
      "z": 1,
      "name": "Rock_Stone_Brick_Smooth_Half",
      "rotation": 6
    },
    {
      "x": -12,
      "y": 6,
      "z": 1,
      "name": "Rock_Stone_Brick_Smooth_Half",
      "rotation": 6
    },
    {
      "x": -12,
      "y": 7,
      "z": 1,
      "name": "Rock_Stone_Brick_Stairs",
      "rotation": 8
    },
    {
      "x": -12,
      "y": 8,
      "z": 1,
      "name": "Rock_Stone_Brick_Decorative",
      "rotation": 1
    },
    {
      "x": -12,
      "y": 9,
      "z": 1,
      "name": "Rock_Stone_Brick"
    },
    {
      "x": -12,
      "y": 4,
      "z": 2,
      "name": "Rock_Stone_Brick_Decorative",
      "rotation": 1
    },
    {
      "x": -12,
      "y": 5,
      "z": 2,
      "name": "Rock_Stone_Brick",
      "rotation": 1
    },
    {
      "x": -12,
      "y": 6,
      "z": 2,
      "name": "Rock_Stone_Brick",
      "rotation": 1
    },
    {
      "x": -12,
      "y": 7,
      "z": 2,
      "name": "Rock_Stone_Brick",
      "rotation": 1
    },
    {
      "x": -12,
      "y": 8,
      "z": 2,
      "name": "Rock_Stone_Brick",
      "rotation": 1
    },
    {
      "x": -12,
      "y": 9,
      "z": 2,
      "name": "Rock_Stone_Brick"
    },
    {
      "x": -12,
      "y": 13,
      "z": 5,
      "name": "Cloth_Block_Wool_Pink",
      "rotation": 3
    },
    {
      "x": -12,
      "y": 13,
      "z": 6,
      "name": "Cloth_Block_Wool_Green",
      "rotation": 1
    },
    {
      "x": -12,
      "y": 13,
      "z": 16,
      "name": "Cloth_Block_Wool_Green",
      "rotation": 1
    },
    {
      "x": -11,
      "y": 13,
      "z": -16,
      "name": "Cloth_Block_Wool_Green"
    },
    {
      "x": -11,
      "y": 13,
      "z": -6,
      "name": "Cloth_Block_Wool_Green"
    },
    {
      "x": -11,
      "y": 13,
      "z": -5,
      "name": "Cloth_Block_Wool_Pink"
    },
    {
      "x": -11,
      "y": 4,
      "z": -3,
      "name": "Rock_Stone_Brick_Smooth"
    },
    {
      "x": -11,
      "y": 5,
      "z": -3,
      "name": "Soil_Gravel",
      "support": 15
    },
    {
      "x": -11,
      "y": 6,
      "z": -3,
      "name": "Soil_Gravel",
      "support": 15
    },
    {
      "x": -11,
      "y": 7,
      "z": -3,
      "name": "Soil_Gravel",
      "support": 15
    },
    {
      "x": -11,
      "y": 8,
      "z": -3,
      "name": "Soil_Gravel",
      "support": 15
    },
    {
      "x": -11,
      "y": 4,
      "z": -2,
      "name": "Rock_Stone_Brick_Smooth"
    },
    {
      "x": -11,
      "y": 5,
      "z": -2,
      "name": "Rock_Stone_Brick_Pillar_Base",
      "rotation": 3
    },
    {
      "x": -11,
      "y": 6,
      "z": -2,
      "name": "Rock_Stone_Brick_Pillar_Middle",
      "rotation": 3
    },
    {
      "x": -11,
      "y": 7,
      "z": -2,
      "name": "Rock_Stone_Brick_Pillar_Middle",
      "rotation": 3
    },
    {
      "x": -11,
      "y": 8,
      "z": -2,
      "name": "Rock_Stone_Brick_Pillar_Base",
      "rotation": 33
    },
    {
      "x": -11,
      "y": 9,
      "z": -2,
      "name": "Rock_Stone_Brick"
    },
    {
      "x": -11,
      "y": 3,
      "z": -1,
      "name": "Rock_Stone_Brick_Smooth"
    },
    {
      "x": -11,
      "y": 9,
      "z": -1,
      "name": "Rock_Stone_Brick_Smooth",
      "rotation": 2
    },
    {
      "x": -11,
      "y": 3,
      "z": 0,
      "name": "Rock_Stone_Brick_Smooth"
    },
    {
      "x": -11,
      "y": 9,
      "z": 0,
      "name": "Rock_Stone_Brick_Smooth",
      "rotation": 2
    },
    {
      "x": -11,
      "y": 3,
      "z": 1,
      "name": "Rock_Stone_Brick_Smooth"
    },
    {
      "x": -11,
      "y": 9,
      "z": 1,
      "name": "Rock_Stone_Brick_Smooth",
      "rotation": 2
    },
    {
      "x": -11,
      "y": 4,
      "z": 2,
      "name": "Rock_Stone_Brick_Smooth"
    },
    {
      "x": -11,
      "y": 5,
      "z": 2,
      "name": "Rock_Stone_Brick_Pillar_Base",
      "rotation": 1
    },
    {
      "x": -11,
      "y": 6,
      "z": 2,
      "name": "Rock_Stone_Brick_Pillar_Middle",
      "rotation": 1
    },
    {
      "x": -11,
      "y": 7,
      "z": 2,
      "name": "Rock_Stone_Brick_Pillar_Middle",
      "rotation": 1
    },
    {
      "x": -11,
      "y": 8,
      "z": 2,
      "name": "Rock_Stone_Brick_Pillar_Base",
      "rotation": 35
    },
    {
      "x": -11,
      "y": 9,
      "z": 2,
      "name": "Rock_Stone_Brick"
    },
    {
      "x": -11,
      "y": 4,
      "z": 3,
      "name": "Rock_Stone_Brick_Smooth"
    },
    {
      "x": -11,
      "y": 5,
      "z": 3,
      "name": "Soil_Gravel",
      "support": 15
    },
    {
      "x": -11,
      "y": 6,
      "z": 3,
      "name": "Soil_Gravel",
      "support": 15
    },
    {
      "x": -11,
      "y": 7,
      "z": 3,
      "name": "Soil_Gravel",
      "support": 15
    },
    {
      "x": -11,
      "y": 8,
      "z": 3,
      "name": "Soil_Gravel",
      "support": 15
    },
    {
      "x": -11,
      "y": 13,
      "z": 5,
      "name": "Cloth_Block_Wool_Pink",
      "rotation": 3
    },
    {
      "x": -11,
      "y": 13,
      "z": 6,
      "name": "Cloth_Block_Wool_Green",
      "rotation": 1
    },
    {
      "x": -11,
      "y": 13,
      "z": 16,
      "name": "Cloth_Block_Wool_Green",
      "rotation": 1
    },
    {
      "x": -10,
      "y": 13,
      "z": -16,
      "name": "Cloth_Block_Wool_Green"
    },
    {
      "x": -10,
      "y": 13,
      "z": -6,
      "name": "Cloth_Block_Wool_Green"
    },
    {
      "x": -10,
      "y": 13,
      "z": -5,
      "name": "Cloth_Block_Wool_Pink",
      "rotation": 3
    },
    {
      "x": -10,
      "y": 4,
      "z": -2,
      "name": "Rock_Stone_Brick_Decorative",
      "rotation": 3
    },
    {
      "x": -10,
      "y": 5,
      "z": -2,
      "name": "Soil_Gravel_Half",
      "support": 15,
      "rotation": 4
    },
    {
      "x": -10,
      "y": 6,
      "z": -2,
      "name": "Soil_Gravel_Half",
      "support": 15,
      "rotation": 4
    },
    {
      "x": -10,
      "y": 7,
      "z": -2,
      "name": "Soil_Gravel_Half",
      "support": 15,
      "rotation": 4
    },
    {
      "x": -10,
      "y": 8,
      "z": -2,
      "name": "Soil_Gravel_Half",
      "support": 15,
      "rotation": 4
    },
    {
      "x": -10,
      "y": 9,
      "z": -2,
      "name": "Rock_Stone_Brick"
    },
    {
      "x": -10,
      "y": 3,
      "z": -1,
      "name": "Rock_Stone_Brick_Smooth"
    },
    {
      "x": -10,
      "y": 9,
      "z": -1,
      "name": "Rock_Stone_Brick_Smooth",
      "rotation": 2
    },
    {
      "x": -10,
      "y": 3,
      "z": 0,
      "name": "Rock_Stone_Brick_Smooth"
    },
    {
      "x": -10,
      "y": 9,
      "z": 0,
      "name": "Rock_Stone_Brick_Smooth",
      "rotation": 2
    },
    {
      "x": -10,
      "y": 3,
      "z": 1,
      "name": "Rock_Stone_Brick_Smooth"
    },
    {
      "x": -10,
      "y": 9,
      "z": 1,
      "name": "Rock_Stone_Brick_Smooth",
      "rotation": 2
    },
    {
      "x": -10,
      "y": 4,
      "z": 2,
      "name": "Rock_Stone_Brick_Decorative",
      "rotation": 1
    },
    {
      "x": -10,
      "y": 5,
      "z": 2,
      "name": "Soil_Gravel_Half",
      "support": 15,
      "rotation": 6
    },
    {
      "x": -10,
      "y": 6,
      "z": 2,
      "name": "Soil_Gravel_Half",
      "support": 15,
      "rotation": 6
    },
    {
      "x": -10,
      "y": 7,
      "z": 2,
      "name": "Soil_Gravel_Half",
      "support": 15,
      "rotation": 6
    },
    {
      "x": -10,
      "y": 8,
      "z": 2,
      "name": "Soil_Gravel_Half",
      "support": 15,
      "rotation": 6
    },
    {
      "x": -10,
      "y": 9,
      "z": 2,
      "name": "Rock_Stone_Brick"
    },
    {
      "x": -10,
      "y": 13,
      "z": 5,
      "name": "Cloth_Block_Wool_Pink",
      "rotation": 3
    },
    {
      "x": -10,
      "y": 13,
      "z": 6,
      "name": "Cloth_Block_Wool_Green",
      "rotation": 1
    },
    {
      "x": -10,
      "y": 13,
      "z": 16,
      "name": "Cloth_Block_Wool_Green",
      "rotation": 1
    },
    {
      "x": -9,
      "y": 13,
      "z": -16,
      "name": "Cloth_Block_Wool_Green"
    },
    {
      "x": -9,
      "y": 13,
      "z": -6,
      "name": "Cloth_Block_Wool_Green"
    },
    {
      "x": -9,
      "y": 13,
      "z": -5,
      "name": "Cloth_Block_Wool_Pink",
      "rotation": 3
    },
    {
      "x": -9,
      "y": 4,
      "z": -2,
      "name": "Rock_Stone_Brick_Decorative",
      "rotation": 3
    },
    {
      "x": -9,
      "y": 5,
      "z": -2,
      "name": "Soil_Gravel_Half",
      "support": 15,
      "rotation": 4
    },
    {
      "x": -9,
      "y": 6,
      "z": -2,
      "name": "Soil_Gravel_Half",
      "support": 15,
      "rotation": 4
    },
    {
      "x": -9,
      "y": 7,
      "z": -2,
      "name": "Soil_Gravel_Half",
      "support": 15,
      "rotation": 4
    },
    {
      "x": -9,
      "y": 8,
      "z": -2,
      "name": "Soil_Gravel_Half",
      "support": 15,
      "rotation": 4
    },
    {
      "x": -9,
      "y": 9,
      "z": -2,
      "name": "Rock_Stone_Brick"
    },
    {
      "x": -9,
      "y": 3,
      "z": -1,
      "name": "Rock_Stone_Brick_Smooth"
    },
    {
      "x": -9,
      "y": 9,
      "z": -1,
      "name": "Rock_Stone_Brick_Smooth",
      "rotation": 2
    },
    {
      "x": -9,
      "y": 3,
      "z": 0,
      "name": "Rock_Stone_Brick_Smooth"
    },
    {
      "x": -9,
      "y": 9,
      "z": 0,
      "name": "Rock_Stone_Brick_Smooth",
      "rotation": 2
    },
    {
      "x": -9,
      "y": 3,
      "z": 1,
      "name": "Rock_Stone_Brick_Smooth"
    },
    {
      "x": -9,
      "y": 9,
      "z": 1,
      "name": "Rock_Stone_Brick_Smooth",
      "rotation": 2
    },
    {
      "x": -9,
      "y": 4,
      "z": 2,
      "name": "Rock_Stone_Brick_Decorative",
      "rotation": 1
    },
    {
      "x": -9,
      "y": 5,
      "z": 2,
      "name": "Soil_Gravel_Half",
      "support": 15,
      "rotation": 6
    },
    {
      "x": -9,
      "y": 6,
      "z": 2,
      "name": "Soil_Gravel_Half",
      "support": 15,
      "rotation": 6
    },
    {
      "x": -9,
      "y": 7,
      "z": 2,
      "name": "Soil_Gravel_Half",
      "support": 15,
      "rotation": 6
    },
    {
      "x": -9,
      "y": 8,
      "z": 2,
      "name": "Soil_Gravel_Half",
      "support": 15,
      "rotation": 6
    },
    {
      "x": -9,
      "y": 9,
      "z": 2,
      "name": "Rock_Stone_Brick"
    },
    {
      "x": -9,
      "y": 13,
      "z": 5,
      "name": "Cloth_Block_Wool_Pink",
      "rotation": 3
    },
    {
      "x": -9,
      "y": 13,
      "z": 6,
      "name": "Cloth_Block_Wool_Green",
      "rotation": 1
    },
    {
      "x": -9,
      "y": 13,
      "z": 16,
      "name": "Cloth_Block_Wool_Green",
      "rotation": 1
    },
    {
      "x": -8,
      "y": 13,
      "z": -16,
      "name": "Cloth_Block_Wool_Green"
    },
    {
      "x": -8,
      "y": 4,
      "z": -6,
      "name": "Rock_Stone_Brick_Smooth"
    },
    {
      "x": -8,
      "y": 5,
      "z": -6,
      "name": "Soil_Gravel",
      "support": 15
    },
    {
      "x": -8,
      "y": 6,
      "z": -6,
      "name": "Soil_Gravel",
      "support": 15
    },
    {
      "x": -8,
      "y": 7,
      "z": -6,
      "name": "Soil_Gravel",
      "support": 15
    },
    {
      "x": -8,
      "y": 8,
      "z": -6,
      "name": "Soil_Gravel",
      "support": 15
    },
    {
      "x": -8,
      "y": 13,
      "z": -6,
      "name": "Cloth_Block_Wool_Green"
    },
    {
      "x": -8,
      "y": 13,
      "z": -5,
      "name": "Cloth_Block_Wool_Pink",
      "rotation": 3
    },
    {
      "x": -8,
      "y": 4,
      "z": -2,
      "name": "Rock_Stone_Brick_Decorative",
      "rotation": 3
    },
    {
      "x": -8,
      "y": 5,
      "z": -2,
      "name": "Soil_Gravel_Half",
      "support": 15,
      "rotation": 4
    },
    {
      "x": -8,
      "y": 6,
      "z": -2,
      "name": "Soil_Gravel_Half",
      "support": 15,
      "rotation": 4
    },
    {
      "x": -8,
      "y": 7,
      "z": -2,
      "name": "Soil_Gravel_Half",
      "support": 15,
      "rotation": 4
    },
    {
      "x": -8,
      "y": 8,
      "z": -2,
      "name": "Soil_Gravel_Half",
      "support": 15,
      "rotation": 4
    },
    {
      "x": -8,
      "y": 9,
      "z": -2,
      "name": "Rock_Stone_Brick"
    },
    {
      "x": -8,
      "y": 3,
      "z": -1,
      "name": "Rock_Stone_Brick_Smooth"
    },
    {
      "x": -8,
      "y": 9,
      "z": -1,
      "name": "Rock_Stone_Brick_Smooth",
      "rotation": 2
    },
    {
      "x": -8,
      "y": 3,
      "z": 0,
      "name": "Rock_Stone_Brick_Smooth"
    },
    {
      "x": -8,
      "y": 9,
      "z": 0,
      "name": "Rock_Stone_Brick_Smooth",
      "rotation": 2
    },
    {
      "x": -8,
      "y": 3,
      "z": 1,
      "name": "Rock_Stone_Brick_Smooth"
    },
    {
      "x": -8,
      "y": 9,
      "z": 1,
      "name": "Rock_Stone_Brick_Smooth",
      "rotation": 2
    },
    {
      "x": -8,
      "y": 4,
      "z": 2,
      "name": "Rock_Stone_Brick_Decorative",
      "rotation": 1
    },
    {
      "x": -8,
      "y": 5,
      "z": 2,
      "name": "Soil_Gravel_Half",
      "support": 15,
      "rotation": 6
    },
    {
      "x": -8,
      "y": 6,
      "z": 2,
      "name": "Soil_Gravel_Half",
      "support": 15,
      "rotation": 6
    },
    {
      "x": -8,
      "y": 7,
      "z": 2,
      "name": "Soil_Gravel_Half",
      "support": 15,
      "rotation": 6
    },
    {
      "x": -8,
      "y": 8,
      "z": 2,
      "name": "Soil_Gravel_Half",
      "support": 15,
      "rotation": 6
    },
    {
      "x": -8,
      "y": 9,
      "z": 2,
      "name": "Rock_Stone_Brick"
    },
    {
      "x": -8,
      "y": 13,
      "z": 5,
      "name": "Cloth_Block_Wool_Pink",
      "rotation": 3
    },
    {
      "x": -8,
      "y": 4,
      "z": 6,
      "name": "Rock_Stone_Brick_Smooth"
    },
    {
      "x": -8,
      "y": 5,
      "z": 6,
      "name": "Soil_Gravel",
      "support": 15
    },
    {
      "x": -8,
      "y": 6,
      "z": 6,
      "name": "Soil_Gravel",
      "support": 15
    },
    {
      "x": -8,
      "y": 7,
      "z": 6,
      "name": "Soil_Gravel",
      "support": 15
    },
    {
      "x": -8,
      "y": 8,
      "z": 6,
      "name": "Soil_Gravel",
      "support": 15
    },
    {
      "x": -8,
      "y": 13,
      "z": 6,
      "name": "Cloth_Block_Wool_Green",
      "rotation": 1
    },
    {
      "x": -8,
      "y": 13,
      "z": 16,
      "name": "Cloth_Block_Wool_Green",
      "rotation": 1
    },
    {
      "x": -7,
      "y": 13,
      "z": -16,
      "name": "Cloth_Block_Wool_Green"
    },
    {
      "x": -7,
      "y": 4,
      "z": -7,
      "name": "Rock_Stone_Brick"
    },
    {
      "x": -7,
      "y": 5,
      "z": -7,
      "name": "Rock_Stone_Brick"
    },
    {
      "x": -7,
      "y": 6,
      "z": -7,
      "name": "Rock_Stone_Brick"
    },
    {
      "x": -7,
      "y": 7,
      "z": -7,
      "name": "Rock_Stone_Brick"
    },
    {
      "x": -7,
      "y": 8,
      "z": -7,
      "name": "Rock_Stone_Brick"
    },
    {
      "x": -7,
      "y": 9,
      "z": -7,
      "name": "Rock_Stone_Brick"
    },
    {
      "x": -7,
      "y": 4,
      "z": -6,
      "name": "Rock_Stone_Brick_Smooth"
    },
    {
      "x": -7,
      "y": 5,
      "z": -6,
      "name": "Rock_Stone_Brick_Pillar_Base"
    },
    {
      "x": -7,
      "y": 6,
      "z": -6,
      "name": "Rock_Stone_Brick_Pillar_Middle"
    },
    {
      "x": -7,
      "y": 7,
      "z": -6,
      "name": "Rock_Stone_Brick_Pillar_Middle"
    },
    {
      "x": -7,
      "y": 8,
      "z": -6,
      "name": "Rock_Stone_Brick_Pillar_Base",
      "rotation": 34
    },
    {
      "x": -7,
      "y": 9,
      "z": -6,
      "name": "Rock_Stone_Brick"
    },
    {
      "x": -7,
      "y": 13,
      "z": -6,
      "name": "Cloth_Block_Wool_Green"
    },
    {
      "x": -7,
      "y": 4,
      "z": -5,
      "name": "Rock_Stone_Brick_Decorative"
    },
    {
      "x": -7,
      "y": 5,
      "z": -5,
      "name": "Soil_Gravel_Half",
      "support": 15,
      "rotation": 5
    },
    {
      "x": -7,
      "y": 6,
      "z": -5,
      "name": "Soil_Gravel_Half",
      "support": 15,
      "rotation": 5
    },
    {
      "x": -7,
      "y": 7,
      "z": -5,
      "name": "Soil_Gravel_Half",
      "support": 15,
      "rotation": 5
    },
    {
      "x": -7,
      "y": 8,
      "z": -5,
      "name": "Soil_Gravel_Half",
      "support": 15,
      "rotation": 5
    },
    {
      "x": -7,
      "y": 9,
      "z": -5,
      "name": "Rock_Stone_Brick"
    },
    {
      "x": -7,
      "y": 13,
      "z": -5,
      "name": "Cloth_Block_Wool_Pink",
      "rotation": 3
    },
    {
      "x": -7,
      "y": 4,
      "z": -4,
      "name": "Rock_Stone_Brick_Decorative"
    },
    {
      "x": -7,
      "y": 5,
      "z": -4,
      "name": "Soil_Gravel_Half",
      "support": 15,
      "rotation": 5
    },
    {
      "x": -7,
      "y": 6,
      "z": -4,
      "name": "Soil_Gravel_Half",
      "support": 15,
      "rotation": 5
    },
    {
      "x": -7,
      "y": 7,
      "z": -4,
      "name": "Soil_Gravel_Half",
      "support": 15,
      "rotation": 5
    },
    {
      "x": -7,
      "y": 8,
      "z": -4,
      "name": "Soil_Gravel_Half",
      "support": 15,
      "rotation": 5
    },
    {
      "x": -7,
      "y": 9,
      "z": -4,
      "name": "Rock_Stone_Brick"
    },
    {
      "x": -7,
      "y": 4,
      "z": -3,
      "name": "Rock_Stone_Brick_Decorative"
    },
    {
      "x": -7,
      "y": 5,
      "z": -3,
      "name": "Soil_Gravel_Half",
      "support": 15,
      "rotation": 5
    },
    {
      "x": -7,
      "y": 6,
      "z": -3,
      "name": "Soil_Gravel_Half",
      "support": 15,
      "rotation": 5
    },
    {
      "x": -7,
      "y": 7,
      "z": -3,
      "name": "Soil_Gravel_Half",
      "support": 15,
      "rotation": 5
    },
    {
      "x": -7,
      "y": 8,
      "z": -3,
      "name": "Soil_Gravel_Half",
      "support": 15,
      "rotation": 5
    },
    {
      "x": -7,
      "y": 9,
      "z": -3,
      "name": "Rock_Stone_Brick"
    },
    {
      "x": -7,
      "y": 4,
      "z": -2,
      "name": "Rock_Stone_Brick_Smooth"
    },
    {
      "x": -7,
      "y": 5,
      "z": -2,
      "name": "Rock_Stone_Brick_Pillar_Base"
    },
    {
      "x": -7,
      "y": 6,
      "z": -2,
      "name": "Rock_Stone_Brick_Pillar_Middle"
    },
    {
      "x": -7,
      "y": 7,
      "z": -2,
      "name": "Rock_Stone_Brick_Pillar_Middle"
    },
    {
      "x": -7,
      "y": 8,
      "z": -2,
      "name": "Rock_Stone_Brick_Pillar_Base",
      "rotation": 34
    },
    {
      "x": -7,
      "y": 9,
      "z": -2,
      "name": "Rock_Stone_Brick_Decorative"
    },
    {
      "x": -7,
      "y": 3,
      "z": -1,
      "name": "Rock_Stone_Brick_Smooth"
    },
    {
      "x": -7,
      "y": 9,
      "z": -1,
      "name": "Rock_Stone_Brick_Smooth",
      "rotation": 2
    },
    {
      "x": -7,
      "y": 3,
      "z": 0,
      "name": "Rock_Stone_Brick_Smooth"
    },
    {
      "x": -7,
      "y": 9,
      "z": 0,
      "name": "Rock_Stone_Brick_Smooth",
      "rotation": 2
    },
    {
      "x": -7,
      "y": 3,
      "z": 1,
      "name": "Rock_Stone_Brick_Smooth"
    },
    {
      "x": -7,
      "y": 9,
      "z": 1,
      "name": "Rock_Stone_Brick_Smooth",
      "rotation": 2
    },
    {
      "x": -7,
      "y": 4,
      "z": 2,
      "name": "Rock_Stone_Brick_Smooth"
    },
    {
      "x": -7,
      "y": 5,
      "z": 2,
      "name": "Rock_Stone_Brick_Pillar_Base"
    },
    {
      "x": -7,
      "y": 6,
      "z": 2,
      "name": "Rock_Stone_Brick_Pillar_Middle"
    },
    {
      "x": -7,
      "y": 7,
      "z": 2,
      "name": "Rock_Stone_Brick_Pillar_Middle"
    },
    {
      "x": -7,
      "y": 8,
      "z": 2,
      "name": "Rock_Stone_Brick_Pillar_Base",
      "rotation": 34
    },
    {
      "x": -7,
      "y": 9,
      "z": 2,
      "name": "Rock_Stone_Brick_Decorative"
    },
    {
      "x": -7,
      "y": 4,
      "z": 3,
      "name": "Rock_Stone_Brick_Decorative"
    },
    {
      "x": -7,
      "y": 5,
      "z": 3,
      "name": "Soil_Gravel_Half",
      "support": 15,
      "rotation": 5
    },
    {
      "x": -7,
      "y": 6,
      "z": 3,
      "name": "Soil_Gravel_Half",
      "support": 15,
      "rotation": 5
    },
    {
      "x": -7,
      "y": 7,
      "z": 3,
      "name": "Soil_Gravel_Half",
      "support": 15,
      "rotation": 5
    },
    {
      "x": -7,
      "y": 8,
      "z": 3,
      "name": "Soil_Gravel_Half",
      "support": 15,
      "rotation": 5
    },
    {
      "x": -7,
      "y": 9,
      "z": 3,
      "name": "Rock_Stone_Brick"
    },
    {
      "x": -7,
      "y": 4,
      "z": 4,
      "name": "Rock_Stone_Brick_Decorative"
    },
    {
      "x": -7,
      "y": 5,
      "z": 4,
      "name": "Soil_Gravel_Half",
      "support": 15,
      "rotation": 5
    },
    {
      "x": -7,
      "y": 6,
      "z": 4,
      "name": "Soil_Gravel_Half",
      "support": 15,
      "rotation": 5
    },
    {
      "x": -7,
      "y": 7,
      "z": 4,
      "name": "Soil_Gravel_Half",
      "support": 15,
      "rotation": 5
    },
    {
      "x": -7,
      "y": 8,
      "z": 4,
      "name": "Soil_Gravel_Half",
      "support": 15,
      "rotation": 5
    },
    {
      "x": -7,
      "y": 9,
      "z": 4,
      "name": "Rock_Stone_Brick"
    },
    {
      "x": -7,
      "y": 4,
      "z": 5,
      "name": "Rock_Stone_Brick_Decorative"
    },
    {
      "x": -7,
      "y": 5,
      "z": 5,
      "name": "Soil_Gravel_Half",
      "support": 15,
      "rotation": 5
    },
    {
      "x": -7,
      "y": 6,
      "z": 5,
      "name": "Soil_Gravel_Half",
      "support": 15,
      "rotation": 5
    },
    {
      "x": -7,
      "y": 7,
      "z": 5,
      "name": "Soil_Gravel_Half",
      "support": 15,
      "rotation": 5
    },
    {
      "x": -7,
      "y": 8,
      "z": 5,
      "name": "Soil_Gravel_Half",
      "support": 15,
      "rotation": 5
    },
    {
      "x": -7,
      "y": 9,
      "z": 5,
      "name": "Rock_Stone_Brick"
    },
    {
      "x": -7,
      "y": 13,
      "z": 5,
      "name": "Cloth_Block_Wool_Pink",
      "rotation": 3
    },
    {
      "x": -7,
      "y": 4,
      "z": 6,
      "name": "Rock_Stone_Brick_Smooth"
    },
    {
      "x": -7,
      "y": 5,
      "z": 6,
      "name": "Rock_Stone_Brick_Pillar_Base"
    },
    {
      "x": -7,
      "y": 6,
      "z": 6,
      "name": "Rock_Stone_Brick_Pillar_Middle"
    },
    {
      "x": -7,
      "y": 7,
      "z": 6,
      "name": "Rock_Stone_Brick_Pillar_Middle"
    },
    {
      "x": -7,
      "y": 8,
      "z": 6,
      "name": "Rock_Stone_Brick_Pillar_Base",
      "rotation": 34
    },
    {
      "x": -7,
      "y": 9,
      "z": 6,
      "name": "Rock_Stone_Brick"
    },
    {
      "x": -7,
      "y": 13,
      "z": 6,
      "name": "Cloth_Block_Wool_Green",
      "rotation": 1
    },
    {
      "x": -7,
      "y": 4,
      "z": 7,
      "name": "Rock_Stone_Brick"
    },
    {
      "x": -7,
      "y": 5,
      "z": 7,
      "name": "Rock_Stone_Brick"
    },
    {
      "x": -7,
      "y": 6,
      "z": 7,
      "name": "Rock_Stone_Brick"
    },
    {
      "x": -7,
      "y": 7,
      "z": 7,
      "name": "Rock_Stone_Brick"
    },
    {
      "x": -7,
      "y": 8,
      "z": 7,
      "name": "Rock_Stone_Brick"
    },
    {
      "x": -7,
      "y": 9,
      "z": 7,
      "name": "Rock_Stone_Brick"
    },
    {
      "x": -7,
      "y": 13,
      "z": 16,
      "name": "Cloth_Block_Wool_Green",
      "rotation": 1
    },
    {
      "x": -6,
      "y": 13,
      "z": -16,
      "name": "Cloth_Block_Wool_Green"
    },
    {
      "x": -6,
      "y": 13,
      "z": -15,
      "name": "Cloth_Block_Wool_Green"
    },
    {
      "x": -6,
      "y": 13,
      "z": -14,
      "name": "Cloth_Block_Wool_Green"
    },
    {
      "x": -6,
      "y": 13,
      "z": -13,
      "name": "Cloth_Block_Wool_Green"
    },
    {
      "x": -6,
      "y": 13,
      "z": -12,
      "name": "Cloth_Block_Wool_Green"
    },
    {
      "x": -6,
      "y": 13,
      "z": -11,
      "name": "Cloth_Block_Wool_Green"
    },
    {
      "x": -6,
      "y": 13,
      "z": -10,
      "name": "Cloth_Block_Wool_Green"
    },
    {
      "x": -6,
      "y": 13,
      "z": -9,
      "name": "Cloth_Block_Wool_Green"
    },
    {
      "x": -6,
      "y": 4,
      "z": -8,
      "name": "Rock_Stone_Brick_Smooth"
    },
    {
      "x": -6,
      "y": 5,
      "z": -8,
      "name": "Soil_Gravel",
      "support": 15
    },
    {
      "x": -6,
      "y": 6,
      "z": -8,
      "name": "Soil_Gravel",
      "support": 15
    },
    {
      "x": -6,
      "y": 7,
      "z": -8,
      "name": "Soil_Gravel",
      "support": 15
    },
    {
      "x": -6,
      "y": 8,
      "z": -8,
      "name": "Soil_Gravel",
      "support": 15
    },
    {
      "x": -6,
      "y": 13,
      "z": -8,
      "name": "Cloth_Block_Wool_Green"
    },
    {
      "x": -6,
      "y": 4,
      "z": -7,
      "name": "Rock_Stone_Brick_Smooth"
    },
    {
      "x": -6,
      "y": 5,
      "z": -7,
      "name": "Rock_Stone_Brick_Pillar_Base",
      "rotation": 3
    },
    {
      "x": -6,
      "y": 6,
      "z": -7,
      "name": "Rock_Stone_Brick_Pillar_Middle",
      "rotation": 3
    },
    {
      "x": -6,
      "y": 7,
      "z": -7,
      "name": "Rock_Stone_Brick_Pillar_Middle",
      "rotation": 3
    },
    {
      "x": -6,
      "y": 8,
      "z": -7,
      "name": "Rock_Stone_Brick_Pillar_Base",
      "rotation": 33
    },
    {
      "x": -6,
      "y": 9,
      "z": -7,
      "name": "Rock_Stone_Brick"
    },
    {
      "x": -6,
      "y": 13,
      "z": -7,
      "name": "Cloth_Block_Wool_Green"
    },
    {
      "x": -6,
      "y": 3,
      "z": -6,
      "name": "Rock_Stone_Brick_Smooth"
    },
    {
      "x": -6,
      "y": 4,
      "z": -6,
      "name": "Furniture_Temple_Dark_Candle"
    },
    {
      "x": -6,
      "y": 5,
      "z": -6,
      "name": "Furniture_Temple_Dark_Candle",
      "filler": 1024
    },
    {
      "x": -6,
      "y": 9,
      "z": -6,
      "name": "Rock_Stone_Brick_Smooth_Half",
      "rotation": 35
    },
    {
      "x": -6,
      "y": 13,
      "z": -6,
      "name": "Cloth_Block_Wool_Green"
    },
    {
      "x": -6,
      "y": 3,
      "z": -5,
      "name": "Rock_Stone_Brick_Smooth"
    },
    {
      "x": -6,
      "y": 9,
      "z": -5,
      "name": "Rock_Stone_Brick_Smooth_Half",
      "rotation": 35
    },
    {
      "x": -6,
      "y": 13,
      "z": -5,
      "name": "Cloth_Block_Wool_Pink",
      "rotation": 3
    },
    {
      "x": -6,
      "y": 3,
      "z": -4,
      "name": "Rock_Stone_Brick_Smooth"
    },
    {
      "x": -6,
      "y": 9,
      "z": -4,
      "name": "Rock_Stone_Brick_Smooth_Half",
      "rotation": 35
    },
    {
      "x": -6,
      "y": 13,
      "z": -4,
      "name": "Cloth_Block_Wool_Pink",
      "rotation": 3
    },
    {
      "x": -6,
      "y": 3,
      "z": -3,
      "name": "Rock_Stone_Brick_Smooth"
    },
    {
      "x": -6,
      "y": 9,
      "z": -3,
      "name": "Rock_Stone_Brick_Smooth_Half",
      "rotation": 35
    },
    {
      "x": -6,
      "y": 10,
      "z": -3,
      "name": "Rock_Stone_Brick_Smooth",
      "rotation": 1
    },
    {
      "x": -6,
      "y": 13,
      "z": -3,
      "name": "Cloth_Block_Wool_Pink",
      "rotation": 3
    },
    {
      "x": -6,
      "y": 3,
      "z": -2,
      "name": "Rock_Stone_Brick_Smooth"
    },
    {
      "x": -6,
      "y": 9,
      "z": -2,
      "name": "Rock_Stone_Brick"
    },
    {
      "x": -6,
      "y": 13,
      "z": -2,
      "name": "Cloth_Block_Wool_Pink",
      "rotation": 3
    },
    {
      "x": -6,
      "y": 3,
      "z": -1,
      "name": "Rock_Stone_Brick_Smooth"
    },
    {
      "x": -6,
      "y": 9,
      "z": -1,
      "name": "Rock_Stone_Brick_Smooth_Half",
      "rotation": 32
    },
    {
      "x": -6,
      "y": 10,
      "z": -1,
      "name": "Rock_Stone_Brick_Smooth",
      "rotation": 2
    },
    {
      "x": -6,
      "y": 13,
      "z": -1,
      "name": "Cloth_Block_Wool_Pink",
      "rotation": 3
    },
    {
      "x": -6,
      "y": 3,
      "z": 0,
      "name": "Rock_Stone_Brick_Smooth"
    },
    {
      "x": -6,
      "y": 9,
      "z": 0,
      "name": "Rock_Stone_Brick_Smooth_Half",
      "rotation": 32
    },
    {
      "x": -6,
      "y": 10,
      "z": 0,
      "name": "Rock_Stone_Brick_Smooth",
      "rotation": 2
    },
    {
      "x": -6,
      "y": 13,
      "z": 0,
      "name": "Cloth_Block_Wool_Pink"
    },
    {
      "x": -6,
      "y": 3,
      "z": 1,
      "name": "Rock_Stone_Brick_Smooth"
    },
    {
      "x": -6,
      "y": 9,
      "z": 1,
      "name": "Rock_Stone_Brick_Smooth_Half",
      "rotation": 32
    },
    {
      "x": -6,
      "y": 10,
      "z": 1,
      "name": "Rock_Stone_Brick_Smooth",
      "rotation": 2
    },
    {
      "x": -6,
      "y": 13,
      "z": 1,
      "name": "Cloth_Block_Wool_Pink",
      "rotation": 3
    },
    {
      "x": -6,
      "y": 3,
      "z": 2,
      "name": "Rock_Stone_Brick_Smooth"
    },
    {
      "x": -6,
      "y": 9,
      "z": 2,
      "name": "Rock_Stone_Brick"
    },
    {
      "x": -6,
      "y": 13,
      "z": 2,
      "name": "Cloth_Block_Wool_Pink",
      "rotation": 3
    },
    {
      "x": -6,
      "y": 3,
      "z": 3,
      "name": "Rock_Stone_Brick_Smooth"
    },
    {
      "x": -6,
      "y": 9,
      "z": 3,
      "name": "Rock_Stone_Brick_Smooth_Half",
      "rotation": 32
    },
    {
      "x": -6,
      "y": 10,
      "z": 3,
      "name": "Rock_Stone_Brick_Smooth",
      "rotation": 2
    },
    {
      "x": -6,
      "y": 13,
      "z": 3,
      "name": "Cloth_Block_Wool_Pink",
      "rotation": 3
    },
    {
      "x": -6,
      "y": 3,
      "z": 4,
      "name": "Rock_Stone_Brick_Smooth"
    },
    {
      "x": -6,
      "y": 9,
      "z": 4,
      "name": "Rock_Stone_Brick_Smooth_Half",
      "rotation": 32
    },
    {
      "x": -6,
      "y": 13,
      "z": 4,
      "name": "Cloth_Block_Wool_Pink",
      "rotation": 3
    },
    {
      "x": -6,
      "y": 3,
      "z": 5,
      "name": "Rock_Stone_Brick_Smooth"
    },
    {
      "x": -6,
      "y": 9,
      "z": 5,
      "name": "Rock_Stone_Brick_Smooth_Half",
      "rotation": 32
    },
    {
      "x": -6,
      "y": 13,
      "z": 5,
      "name": "Cloth_Block_Wool_Pink",
      "rotation": 3
    },
    {
      "x": -6,
      "y": 3,
      "z": 6,
      "name": "Rock_Stone_Brick_Smooth"
    },
    {
      "x": -6,
      "y": 4,
      "z": 6,
      "name": "Furniture_Temple_Dark_Candle"
    },
    {
      "x": -6,
      "y": 5,
      "z": 6,
      "name": "Furniture_Temple_Dark_Candle",
      "filler": 1024
    },
    {
      "x": -6,
      "y": 9,
      "z": 6,
      "name": "Rock_Stone_Brick_Smooth_Half",
      "rotation": 32
    },
    {
      "x": -6,
      "y": 13,
      "z": 6,
      "name": "Cloth_Block_Wool_Green",
      "rotation": 1
    },
    {
      "x": -6,
      "y": 4,
      "z": 7,
      "name": "Rock_Stone_Brick_Smooth"
    },
    {
      "x": -6,
      "y": 5,
      "z": 7,
      "name": "Rock_Stone_Brick_Pillar_Base"
    },
    {
      "x": -6,
      "y": 6,
      "z": 7,
      "name": "Rock_Stone_Brick_Pillar_Middle"
    },
    {
      "x": -6,
      "y": 7,
      "z": 7,
      "name": "Rock_Stone_Brick_Pillar_Middle"
    },
    {
      "x": -6,
      "y": 8,
      "z": 7,
      "name": "Rock_Stone_Brick_Pillar_Base",
      "rotation": 8
    },
    {
      "x": -6,
      "y": 9,
      "z": 7,
      "name": "Rock_Stone_Brick"
    },
    {
      "x": -6,
      "y": 13,
      "z": 7,
      "name": "Cloth_Block_Wool_Green",
      "rotation": 1
    },
    {
      "x": -6,
      "y": 4,
      "z": 8,
      "name": "Rock_Stone_Brick_Smooth"
    },
    {
      "x": -6,
      "y": 5,
      "z": 8,
      "name": "Soil_Gravel",
      "support": 15
    },
    {
      "x": -6,
      "y": 6,
      "z": 8,
      "name": "Soil_Gravel",
      "support": 15
    },
    {
      "x": -6,
      "y": 7,
      "z": 8,
      "name": "Soil_Gravel",
      "support": 15
    },
    {
      "x": -6,
      "y": 8,
      "z": 8,
      "name": "Soil_Gravel",
      "support": 15
    },
    {
      "x": -6,
      "y": 13,
      "z": 8,
      "name": "Cloth_Block_Wool_Green",
      "rotation": 1
    },
    {
      "x": -6,
      "y": 13,
      "z": 9,
      "name": "Cloth_Block_Wool_Green",
      "rotation": 1
    },
    {
      "x": -6,
      "y": 13,
      "z": 10,
      "name": "Cloth_Block_Wool_Green",
      "rotation": 1
    },
    {
      "x": -6,
      "y": 13,
      "z": 11,
      "name": "Cloth_Block_Wool_Green"
    },
    {
      "x": -6,
      "y": 13,
      "z": 12,
      "name": "Cloth_Block_Wool_Green",
      "rotation": 1
    },
    {
      "x": -6,
      "y": 13,
      "z": 13,
      "name": "Cloth_Block_Wool_Green",
      "rotation": 1
    },
    {
      "x": -6,
      "y": 13,
      "z": 14,
      "name": "Cloth_Block_Wool_Green",
      "rotation": 1
    },
    {
      "x": -6,
      "y": 13,
      "z": 15,
      "name": "Cloth_Block_Wool_Green",
      "rotation": 1
    },
    {
      "x": -6,
      "y": 13,
      "z": 16,
      "name": "Cloth_Block_Wool_Green",
      "rotation": 1
    },
    {
      "x": -5,
      "y": 13,
      "z": -16,
      "name": "Cloth_Block_Wool_Pink",
      "rotation": 3
    },
    {
      "x": -5,
      "y": 13,
      "z": -15,
      "name": "Cloth_Block_Wool_Pink",
      "rotation": 3
    },
    {
      "x": -5,
      "y": 13,
      "z": -14,
      "name": "Cloth_Block_Wool_Pink",
      "rotation": 3
    },
    {
      "x": -5,
      "y": 13,
      "z": -13,
      "name": "Cloth_Block_Wool_Pink",
      "rotation": 3
    },
    {
      "x": -5,
      "y": 13,
      "z": -12,
      "name": "Cloth_Block_Wool_Pink",
      "rotation": 3
    },
    {
      "x": -5,
      "y": 13,
      "z": -11,
      "name": "Cloth_Block_Wool_Pink"
    },
    {
      "x": -5,
      "y": 13,
      "z": -10,
      "name": "Cloth_Block_Wool_Pink",
      "rotation": 3
    },
    {
      "x": -5,
      "y": 13,
      "z": -9,
      "name": "Cloth_Block_Wool_Pink",
      "rotation": 3
    },
    {
      "x": -5,
      "y": 13,
      "z": -8,
      "name": "Cloth_Block_Wool_Pink",
      "rotation": 3
    },
    {
      "x": -5,
      "y": 4,
      "z": -7,
      "name": "Rock_Stone_Brick_Decorative",
      "rotation": 3
    },
    {
      "x": -5,
      "y": 5,
      "z": -7,
      "name": "Soil_Gravel_Half",
      "support": 15,
      "rotation": 4
    },
    {
      "x": -5,
      "y": 6,
      "z": -7,
      "name": "Soil_Gravel_Half",
      "support": 15,
      "rotation": 4
    },
    {
      "x": -5,
      "y": 7,
      "z": -7,
      "name": "Soil_Gravel_Half",
      "support": 15,
      "rotation": 4
    },
    {
      "x": -5,
      "y": 8,
      "z": -7,
      "name": "Soil_Gravel_Half",
      "support": 15,
      "rotation": 4
    },
    {
      "x": -5,
      "y": 9,
      "z": -7,
      "name": "Rock_Stone_Brick"
    },
    {
      "x": -5,
      "y": 13,
      "z": -7,
      "name": "Cloth_Block_Wool_Pink",
      "rotation": 3
    },
    {
      "x": -5,
      "y": 3,
      "z": -6,
      "name": "Rock_Stone_Brick_Smooth"
    },
    {
      "x": -5,
      "y": 9,
      "z": -6,
      "name": "Rock_Stone_Brick_Smooth_Half",
      "rotation": 35
    },
    {
      "x": -5,
      "y": 13,
      "z": -6,
      "name": "Cloth_Block_Wool_Pink",
      "rotation": 3
    },
    {
      "x": -5,
      "y": 3,
      "z": -5,
      "name": "Rock_Stone_Brick_Smooth"
    },
    {
      "x": -5,
      "y": 9,
      "z": -5,
      "name": "Rock_Stone_Brick_Smooth_Half",
      "rotation": 35
    },
    {
      "x": -5,
      "y": 13,
      "z": -5,
      "name": "Cloth_Block_Wool_Green",
      "rotation": 2
    },
    {
      "x": -5,
      "y": 3,
      "z": -4,
      "name": "Rock_Stone_Brick_Smooth"
    },
    {
      "x": -5,
      "y": 10,
      "z": -4,
      "name": "Rock_Stone_Brick_Smooth",
      "rotation": 1
    },
    {
      "x": -5,
      "y": 13,
      "z": -4,
      "name": "Cloth_Block_Wool_Green",
      "rotation": 2
    },
    {
      "x": -5,
      "y": 3,
      "z": -3,
      "name": "Rock_Stone_Brick_Smooth"
    },
    {
      "x": -5,
      "y": 10,
      "z": -3,
      "name": "Rock_Stone_Brick_Smooth_Half",
      "rotation": 35
    },
    {
      "x": -5,
      "y": 11,
      "z": -3,
      "name": "Rock_Stone_Brick_Smooth",
      "rotation": 1
    },
    {
      "x": -5,
      "y": 13,
      "z": -3,
      "name": "Cloth_Block_Wool_Green",
      "rotation": 2
    },
    {
      "x": -5,
      "y": 3,
      "z": -2,
      "name": "Rock_Stone_Brick_Smooth"
    },
    {
      "x": -5,
      "y": 10,
      "z": -2,
      "name": "Rock_Stone_Brick"
    },
    {
      "x": -5,
      "y": 13,
      "z": -2,
      "name": "Cloth_Block_Wool_Green",
      "rotation": 2
    },
    {
      "x": -5,
      "y": 3,
      "z": -1,
      "name": "Rock_Stone_Brick_Smooth"
    },
    {
      "x": -5,
      "y": 10,
      "z": -1,
      "name": "Rock_Stone_Brick_Smooth_Half",
      "rotation": 32
    },
    {
      "x": -5,
      "y": 11,
      "z": -1,
      "name": "Rock_Stone_Brick_Smooth",
      "rotation": 2
    },
    {
      "x": -5,
      "y": 13,
      "z": -1,
      "name": "Cloth_Block_Wool_Green",
      "rotation": 2
    },
    {
      "x": -5,
      "y": 3,
      "z": 0,
      "name": "Rock_Stone_Brick_Smooth"
    },
    {
      "x": -5,
      "y": 10,
      "z": 0,
      "name": "Rock_Stone_Brick_Smooth_Half",
      "rotation": 32
    },
    {
      "x": -5,
      "y": 11,
      "z": 0,
      "name": "Rock_Stone_Brick_Smooth",
      "rotation": 2
    },
    {
      "x": -5,
      "y": 13,
      "z": 0,
      "name": "Cloth_Block_Wool_Green"
    },
    {
      "x": -5,
      "y": 3,
      "z": 1,
      "name": "Rock_Stone_Brick_Smooth"
    },
    {
      "x": -5,
      "y": 10,
      "z": 1,
      "name": "Rock_Stone_Brick_Smooth_Half",
      "rotation": 32
    },
    {
      "x": -5,
      "y": 11,
      "z": 1,
      "name": "Rock_Stone_Brick_Smooth",
      "rotation": 2
    },
    {
      "x": -5,
      "y": 13,
      "z": 1,
      "name": "Cloth_Block_Wool_Green",
      "rotation": 2
    },
    {
      "x": -5,
      "y": 3,
      "z": 2,
      "name": "Rock_Stone_Brick_Smooth"
    },
    {
      "x": -5,
      "y": 10,
      "z": 2,
      "name": "Rock_Stone_Brick"
    },
    {
      "x": -5,
      "y": 13,
      "z": 2,
      "name": "Cloth_Block_Wool_Green",
      "rotation": 2
    },
    {
      "x": -5,
      "y": 3,
      "z": 3,
      "name": "Rock_Stone_Brick_Smooth"
    },
    {
      "x": -5,
      "y": 10,
      "z": 3,
      "name": "Rock_Stone_Brick_Smooth_Half",
      "rotation": 32
    },
    {
      "x": -5,
      "y": 11,
      "z": 3,
      "name": "Rock_Stone_Brick_Smooth",
      "rotation": 2
    },
    {
      "x": -5,
      "y": 13,
      "z": 3,
      "name": "Cloth_Block_Wool_Green",
      "rotation": 2
    },
    {
      "x": -5,
      "y": 3,
      "z": 4,
      "name": "Rock_Stone_Brick_Smooth"
    },
    {
      "x": -5,
      "y": 10,
      "z": 4,
      "name": "Rock_Stone_Brick_Smooth",
      "rotation": 2
    },
    {
      "x": -5,
      "y": 13,
      "z": 4,
      "name": "Cloth_Block_Wool_Green",
      "rotation": 2
    },
    {
      "x": -5,
      "y": 3,
      "z": 5,
      "name": "Rock_Stone_Brick_Smooth"
    },
    {
      "x": -5,
      "y": 9,
      "z": 5,
      "name": "Rock_Stone_Brick_Smooth_Half",
      "rotation": 32
    },
    {
      "x": -5,
      "y": 13,
      "z": 5,
      "name": "Cloth_Block_Wool_Green",
      "rotation": 2
    },
    {
      "x": -5,
      "y": 3,
      "z": 6,
      "name": "Rock_Stone_Brick_Smooth"
    },
    {
      "x": -5,
      "y": 9,
      "z": 6,
      "name": "Rock_Stone_Brick_Smooth_Half",
      "rotation": 32
    },
    {
      "x": -5,
      "y": 13,
      "z": 6,
      "name": "Cloth_Block_Wool_Pink"
    },
    {
      "x": -5,
      "y": 4,
      "z": 7,
      "name": "Rock_Stone_Brick_Decorative",
      "rotation": 1
    },
    {
      "x": -5,
      "y": 5,
      "z": 7,
      "name": "Soil_Gravel_Half",
      "support": 15,
      "rotation": 6
    },
    {
      "x": -5,
      "y": 6,
      "z": 7,
      "name": "Soil_Gravel_Half",
      "support": 15,
      "rotation": 6
    },
    {
      "x": -5,
      "y": 7,
      "z": 7,
      "name": "Soil_Gravel_Half",
      "support": 15,
      "rotation": 6
    },
    {
      "x": -5,
      "y": 8,
      "z": 7,
      "name": "Soil_Gravel_Half",
      "support": 15,
      "rotation": 6
    },
    {
      "x": -5,
      "y": 9,
      "z": 7,
      "name": "Rock_Stone_Brick"
    },
    {
      "x": -5,
      "y": 13,
      "z": 7,
      "name": "Cloth_Block_Wool_Pink"
    },
    {
      "x": -5,
      "y": 13,
      "z": 8,
      "name": "Cloth_Block_Wool_Pink"
    },
    {
      "x": -5,
      "y": 13,
      "z": 9,
      "name": "Cloth_Block_Wool_Pink"
    },
    {
      "x": -5,
      "y": 13,
      "z": 10,
      "name": "Cloth_Block_Wool_Pink"
    },
    {
      "x": -5,
      "y": 13,
      "z": 11,
      "name": "Cloth_Block_Wool_Pink"
    },
    {
      "x": -5,
      "y": 13,
      "z": 12,
      "name": "Cloth_Block_Wool_Pink"
    },
    {
      "x": -5,
      "y": 13,
      "z": 13,
      "name": "Cloth_Block_Wool_Pink"
    },
    {
      "x": -5,
      "y": 13,
      "z": 14,
      "name": "Cloth_Block_Wool_Pink"
    },
    {
      "x": -5,
      "y": 13,
      "z": 15,
      "name": "Cloth_Block_Wool_Pink"
    },
    {
      "x": -5,
      "y": 13,
      "z": 16,
      "name": "Cloth_Block_Wool_Pink"
    },
    {
      "x": -4,
      "y": 13,
      "z": -16,
      "name": "Cloth_Block_Wool_Pink",
      "rotation": 3
    },
    {
      "x": -4,
      "y": 4,
      "z": -7,
      "name": "Rock_Stone_Brick_Decorative",
      "rotation": 3
    },
    {
      "x": -4,
      "y": 5,
      "z": -7,
      "name": "Soil_Gravel_Half",
      "support": 15,
      "rotation": 4
    },
    {
      "x": -4,
      "y": 6,
      "z": -7,
      "name": "Soil_Gravel_Half",
      "support": 15,
      "rotation": 4
    },
    {
      "x": -4,
      "y": 7,
      "z": -7,
      "name": "Soil_Gravel_Half",
      "support": 15,
      "rotation": 4
    },
    {
      "x": -4,
      "y": 8,
      "z": -7,
      "name": "Soil_Gravel_Half",
      "support": 15,
      "rotation": 4
    },
    {
      "x": -4,
      "y": 9,
      "z": -7,
      "name": "Rock_Stone_Brick"
    },
    {
      "x": -4,
      "y": 3,
      "z": -6,
      "name": "Rock_Stone_Brick_Smooth"
    },
    {
      "x": -4,
      "y": 9,
      "z": -6,
      "name": "Rock_Stone_Brick_Smooth_Half",
      "rotation": 35
    },
    {
      "x": -4,
      "y": 13,
      "z": -6,
      "name": "Cloth_Block_Wool_Pink",
      "rotation": 3
    },
    {
      "x": -4,
      "y": 3,
      "z": -5,
      "name": "Rock_Stone_Brick_Smooth"
    },
    {
      "x": -4,
      "y": 10,
      "z": -5,
      "name": "Rock_Stone_Brick_Smooth",
      "rotation": 1
    },
    {
      "x": -4,
      "y": 13,
      "z": -5,
      "name": "Cloth_Block_Wool_Green",
      "rotation": 2
    },
    {
      "x": -4,
      "y": 3,
      "z": -4,
      "name": "Rock_Stone_Brick_Smooth"
    },
    {
      "x": -4,
      "y": 10,
      "z": -4,
      "name": "Rock_Stone_Brick_Smooth_Half",
      "rotation": 35
    },
    {
      "x": -4,
      "y": 11,
      "z": -4,
      "name": "Rock_Stone_Brick_Smooth",
      "rotation": 1
    },
    {
      "x": -4,
      "y": 3,
      "z": -3,
      "name": "Rock_Stone_Brick_Smooth"
    },
    {
      "x": -4,
      "y": 11,
      "z": -3,
      "name": "Rock_Stone_Brick_Smooth_Half",
      "rotation": 35
    },
    {
      "x": -4,
      "y": 3,
      "z": -2,
      "name": "Rock_Stone_Brick_Smooth"
    },
    {
      "x": -4,
      "y": 11,
      "z": -2,
      "name": "Rock_Stone_Brick"
    },
    {
      "x": -4,
      "y": 3,
      "z": -1,
      "name": "Rock_Stone_Brick_Smooth"
    },
    {
      "x": -4,
      "y": 11,
      "z": -1,
      "name": "Rock_Stone_Brick_Smooth_Half",
      "rotation": 32
    },
    {
      "x": -4,
      "y": 3,
      "z": 0,
      "name": "Rock_Stone_Brick_Smooth"
    },
    {
      "x": -4,
      "y": 11,
      "z": 0,
      "name": "Rock_Stone_Brick_Smooth_Half",
      "rotation": 32
    },
    {
      "x": -4,
      "y": 3,
      "z": 1,
      "name": "Rock_Stone_Brick_Smooth"
    },
    {
      "x": -4,
      "y": 11,
      "z": 1,
      "name": "Rock_Stone_Brick_Smooth_Half",
      "rotation": 32
    },
    {
      "x": -4,
      "y": 3,
      "z": 2,
      "name": "Rock_Stone_Brick_Smooth"
    },
    {
      "x": -4,
      "y": 11,
      "z": 2,
      "name": "Rock_Stone_Brick"
    },
    {
      "x": -4,
      "y": 3,
      "z": 3,
      "name": "Rock_Stone_Brick_Smooth"
    },
    {
      "x": -4,
      "y": 11,
      "z": 3,
      "name": "Rock_Stone_Brick_Smooth_Half",
      "rotation": 32
    },
    {
      "x": -4,
      "y": 3,
      "z": 4,
      "name": "Rock_Stone_Brick_Smooth"
    },
    {
      "x": -4,
      "y": 10,
      "z": 4,
      "name": "Rock_Stone_Brick_Smooth_Half",
      "rotation": 32
    },
    {
      "x": -4,
      "y": 11,
      "z": 4,
      "name": "Rock_Stone_Brick_Smooth",
      "rotation": 2
    },
    {
      "x": -4,
      "y": 3,
      "z": 5,
      "name": "Rock_Stone_Brick_Smooth"
    },
    {
      "x": -4,
      "y": 10,
      "z": 5,
      "name": "Rock_Stone_Brick_Smooth",
      "rotation": 2
    },
    {
      "x": -4,
      "y": 13,
      "z": 5,
      "name": "Cloth_Block_Wool_Green",
      "rotation": 2
    },
    {
      "x": -4,
      "y": 3,
      "z": 6,
      "name": "Rock_Stone_Brick_Smooth"
    },
    {
      "x": -4,
      "y": 9,
      "z": 6,
      "name": "Rock_Stone_Brick_Smooth_Half",
      "rotation": 32
    },
    {
      "x": -4,
      "y": 13,
      "z": 6,
      "name": "Cloth_Block_Wool_Pink"
    },
    {
      "x": -4,
      "y": 4,
      "z": 7,
      "name": "Rock_Stone_Brick_Decorative",
      "rotation": 1
    },
    {
      "x": -4,
      "y": 5,
      "z": 7,
      "name": "Soil_Gravel_Half",
      "support": 15,
      "rotation": 6
    },
    {
      "x": -4,
      "y": 6,
      "z": 7,
      "name": "Soil_Gravel_Half",
      "support": 15,
      "rotation": 6
    },
    {
      "x": -4,
      "y": 7,
      "z": 7,
      "name": "Soil_Gravel_Half",
      "support": 15,
      "rotation": 6
    },
    {
      "x": -4,
      "y": 8,
      "z": 7,
      "name": "Soil_Gravel_Half",
      "support": 15,
      "rotation": 6
    },
    {
      "x": -4,
      "y": 9,
      "z": 7,
      "name": "Rock_Stone_Brick"
    },
    {
      "x": -4,
      "y": 13,
      "z": 16,
      "name": "Cloth_Block_Wool_Pink"
    },
    {
      "x": -3,
      "y": 13,
      "z": -16,
      "name": "Cloth_Block_Wool_Pink",
      "rotation": 3
    },
    {
      "x": -3,
      "y": 4,
      "z": -11,
      "name": "Rock_Stone_Brick_Smooth"
    },
    {
      "x": -3,
      "y": 5,
      "z": -11,
      "name": "Soil_Gravel",
      "support": 15
    },
    {
      "x": -3,
      "y": 6,
      "z": -11,
      "name": "Soil_Gravel",
      "support": 15
    },
    {
      "x": -3,
      "y": 7,
      "z": -11,
      "name": "Soil_Gravel",
      "support": 15
    },
    {
      "x": -3,
      "y": 8,
      "z": -11,
      "name": "Soil_Gravel",
      "support": 15
    },
    {
      "x": -3,
      "y": 4,
      "z": -7,
      "name": "Rock_Stone_Brick_Decorative",
      "rotation": 3
    },
    {
      "x": -3,
      "y": 5,
      "z": -7,
      "name": "Soil_Gravel_Half",
      "support": 15,
      "rotation": 4
    },
    {
      "x": -3,
      "y": 6,
      "z": -7,
      "name": "Soil_Gravel_Half",
      "support": 15,
      "rotation": 4
    },
    {
      "x": -3,
      "y": 7,
      "z": -7,
      "name": "Soil_Gravel_Half",
      "support": 15,
      "rotation": 4
    },
    {
      "x": -3,
      "y": 8,
      "z": -7,
      "name": "Soil_Gravel_Half",
      "support": 15,
      "rotation": 4
    },
    {
      "x": -3,
      "y": 9,
      "z": -7,
      "name": "Rock_Stone_Brick"
    },
    {
      "x": -3,
      "y": 3,
      "z": -6,
      "name": "Rock_Stone_Brick_Smooth"
    },
    {
      "x": -3,
      "y": 9,
      "z": -6,
      "name": "Rock_Stone_Brick_Smooth_Half",
      "rotation": 35
    },
    {
      "x": -3,
      "y": 10,
      "z": -6,
      "name": "Rock_Stone_Brick_Smooth",
      "rotation": 1
    },
    {
      "x": -3,
      "y": 13,
      "z": -6,
      "name": "Cloth_Block_Wool_Pink",
      "rotation": 3
    },
    {
      "x": -3,
      "y": 3,
      "z": -5,
      "name": "Rock_Stone_Brick_Smooth"
    },
    {
      "x": -3,
      "y": 10,
      "z": -5,
      "name": "Rock_Stone_Brick_Smooth_Half",
      "rotation": 35
    },
    {
      "x": -3,
      "y": 11,
      "z": -5,
      "name": "Rock_Stone_Brick_Smooth",
      "rotation": 1
    },
    {
      "x": -3,
      "y": 13,
      "z": -5,
      "name": "Cloth_Block_Wool_Green",
      "rotation": 2
    },
    {
      "x": -3,
      "y": 3,
      "z": -4,
      "name": "Rock_Stone_Brick_Smooth"
    },
    {
      "x": -3,
      "y": 11,
      "z": -4,
      "name": "Rock_Stone_Brick_Smooth_Half",
      "rotation": 35
    },
    {
      "x": -3,
      "y": 3,
      "z": -3,
      "name": "Rock_Stone_Brick_Smooth"
    },
    {
      "x": -3,
      "y": 11,
      "z": -3,
      "name": "Rock_Stone_Brick_Smooth_Half",
      "rotation": 35
    },
    {
      "x": -3,
      "y": 3,
      "z": -2,
      "name": "Rock_Stone_Brick_Smooth"
    },
    {
      "x": -3,
      "y": 11,
      "z": -2,
      "name": "Rock_Stone_Brick"
    },
    {
      "x": -3,
      "y": 3,
      "z": -1,
      "name": "Rock_Stone_Brick_Smooth"
    },
    {
      "x": -3,
      "y": 11,
      "z": -1,
      "name": "Rock_Stone_Brick_Smooth_Half",
      "rotation": 32
    },
    {
      "x": -3,
      "y": 3,
      "z": 0,
      "name": "Rock_Stone_Brick_Smooth"
    },
    {
      "x": -3,
      "y": 11,
      "z": 0,
      "name": "Rock_Stone_Brick_Smooth_Half",
      "rotation": 32
    },
    {
      "x": -3,
      "y": 3,
      "z": 1,
      "name": "Rock_Stone_Brick_Smooth"
    },
    {
      "x": -3,
      "y": 11,
      "z": 1,
      "name": "Rock_Stone_Brick_Smooth_Half",
      "rotation": 32
    },
    {
      "x": -3,
      "y": 3,
      "z": 2,
      "name": "Rock_Stone_Brick_Smooth"
    },
    {
      "x": -3,
      "y": 11,
      "z": 2,
      "name": "Rock_Stone_Brick"
    },
    {
      "x": -3,
      "y": 3,
      "z": 3,
      "name": "Rock_Stone_Brick_Smooth"
    },
    {
      "x": -3,
      "y": 11,
      "z": 3,
      "name": "Rock_Stone_Brick_Smooth_Half",
      "rotation": 32
    },
    {
      "x": -3,
      "y": 3,
      "z": 4,
      "name": "Rock_Stone_Brick_Smooth"
    },
    {
      "x": -3,
      "y": 11,
      "z": 4,
      "name": "Rock_Stone_Brick_Smooth_Half",
      "rotation": 32
    },
    {
      "x": -3,
      "y": 3,
      "z": 5,
      "name": "Rock_Stone_Brick_Smooth"
    },
    {
      "x": -3,
      "y": 10,
      "z": 5,
      "name": "Rock_Stone_Brick_Smooth_Half",
      "rotation": 32
    },
    {
      "x": -3,
      "y": 11,
      "z": 5,
      "name": "Rock_Stone_Brick_Smooth",
      "rotation": 2
    },
    {
      "x": -3,
      "y": 13,
      "z": 5,
      "name": "Cloth_Block_Wool_Green",
      "rotation": 2
    },
    {
      "x": -3,
      "y": 3,
      "z": 6,
      "name": "Rock_Stone_Brick_Smooth"
    },
    {
      "x": -3,
      "y": 9,
      "z": 6,
      "name": "Rock_Stone_Brick_Smooth_Half",
      "rotation": 32
    },
    {
      "x": -3,
      "y": 10,
      "z": 6,
      "name": "Rock_Stone_Brick_Smooth",
      "rotation": 2
    },
    {
      "x": -3,
      "y": 13,
      "z": 6,
      "name": "Cloth_Block_Wool_Pink"
    },
    {
      "x": -3,
      "y": 4,
      "z": 7,
      "name": "Rock_Stone_Brick_Decorative",
      "rotation": 1
    },
    {
      "x": -3,
      "y": 5,
      "z": 7,
      "name": "Soil_Gravel_Half",
      "support": 15,
      "rotation": 6
    },
    {
      "x": -3,
      "y": 6,
      "z": 7,
      "name": "Soil_Gravel_Half",
      "support": 15,
      "rotation": 6
    },
    {
      "x": -3,
      "y": 7,
      "z": 7,
      "name": "Soil_Gravel_Half",
      "support": 15,
      "rotation": 6
    },
    {
      "x": -3,
      "y": 8,
      "z": 7,
      "name": "Soil_Gravel_Half",
      "support": 15,
      "rotation": 6
    },
    {
      "x": -3,
      "y": 9,
      "z": 7,
      "name": "Rock_Stone_Brick"
    },
    {
      "x": -3,
      "y": 13,
      "z": 16,
      "name": "Cloth_Block_Wool_Pink"
    },
    {
      "x": -2,
      "y": 3,
      "z": -16,
      "name": "Rock_Stone_Brick"
    },
    {
      "x": -2,
      "y": 4,
      "z": -16,
      "name": "Rock_Stone_Brick_Decorative"
    },
    {
      "x": -2,
      "y": 5,
      "z": -16,
      "name": "Rock_Stone_Brick"
    },
    {
      "x": -2,
      "y": 6,
      "z": -16,
      "name": "Rock_Stone_Brick"
    },
    {
      "x": -2,
      "y": 7,
      "z": -16,
      "name": "Rock_Stone_Brick"
    },
    {
      "x": -2,
      "y": 8,
      "z": -16,
      "name": "Rock_Stone_Brick"
    },
    {
      "x": -2,
      "y": 9,
      "z": -16,
      "name": "Rock_Stone_Brick"
    },
    {
      "x": -2,
      "y": 13,
      "z": -16,
      "name": "Cloth_Block_Wool_Pink",
      "rotation": 3
    },
    {
      "x": -2,
      "y": 4,
      "z": -15,
      "name": "Rock_Stone_Brick"
    },
    {
      "x": -2,
      "y": 5,
      "z": -15,
      "name": "Rock_Stone_Brick"
    },
    {
      "x": -2,
      "y": 6,
      "z": -15,
      "name": "Rock_Stone_Brick"
    },
    {
      "x": -2,
      "y": 7,
      "z": -15,
      "name": "Rock_Stone_Brick"
    },
    {
      "x": -2,
      "y": 8,
      "z": -15,
      "name": "Rock_Stone_Brick"
    },
    {
      "x": -2,
      "y": 9,
      "z": -15,
      "name": "Rock_Stone_Brick"
    },
    {
      "x": -2,
      "y": 4,
      "z": -14,
      "name": "Rock_Stone_Brick_Decorative"
    },
    {
      "x": -2,
      "y": 5,
      "z": -14,
      "name": "Soil_Gravel_Half",
      "support": 15,
      "rotation": 5
    },
    {
      "x": -2,
      "y": 6,
      "z": -14,
      "name": "Soil_Gravel_Half",
      "support": 15,
      "rotation": 5
    },
    {
      "x": -2,
      "y": 7,
      "z": -14,
      "name": "Soil_Gravel_Half",
      "support": 15,
      "rotation": 5
    },
    {
      "x": -2,
      "y": 8,
      "z": -14,
      "name": "Soil_Gravel_Half",
      "support": 15,
      "rotation": 5
    },
    {
      "x": -2,
      "y": 9,
      "z": -14,
      "name": "Rock_Stone_Brick"
    },
    {
      "x": -2,
      "y": 4,
      "z": -13,
      "name": "Rock_Stone_Brick_Decorative"
    },
    {
      "x": -2,
      "y": 5,
      "z": -13,
      "name": "Soil_Gravel_Half",
      "support": 15,
      "rotation": 5
    },
    {
      "x": -2,
      "y": 6,
      "z": -13,
      "name": "Soil_Gravel_Half",
      "support": 15,
      "rotation": 5
    },
    {
      "x": -2,
      "y": 7,
      "z": -13,
      "name": "Soil_Gravel_Half",
      "support": 15,
      "rotation": 5
    },
    {
      "x": -2,
      "y": 8,
      "z": -13,
      "name": "Soil_Gravel_Half",
      "support": 15,
      "rotation": 5
    },
    {
      "x": -2,
      "y": 9,
      "z": -13,
      "name": "Rock_Stone_Brick"
    },
    {
      "x": -2,
      "y": 4,
      "z": -12,
      "name": "Rock_Stone_Brick_Decorative"
    },
    {
      "x": -2,
      "y": 5,
      "z": -12,
      "name": "Soil_Gravel_Half",
      "support": 15,
      "rotation": 5
    },
    {
      "x": -2,
      "y": 6,
      "z": -12,
      "name": "Soil_Gravel_Half",
      "support": 15,
      "rotation": 5
    },
    {
      "x": -2,
      "y": 7,
      "z": -12,
      "name": "Soil_Gravel_Half",
      "support": 15,
      "rotation": 5
    },
    {
      "x": -2,
      "y": 8,
      "z": -12,
      "name": "Soil_Gravel_Half",
      "support": 15,
      "rotation": 5
    },
    {
      "x": -2,
      "y": 9,
      "z": -12,
      "name": "Rock_Stone_Brick"
    },
    {
      "x": -2,
      "y": 4,
      "z": -11,
      "name": "Rock_Stone_Brick_Smooth"
    },
    {
      "x": -2,
      "y": 5,
      "z": -11,
      "name": "Rock_Stone_Brick_Pillar_Base"
    },
    {
      "x": -2,
      "y": 6,
      "z": -11,
      "name": "Rock_Stone_Brick_Pillar_Middle"
    },
    {
      "x": -2,
      "y": 7,
      "z": -11,
      "name": "Rock_Stone_Brick_Pillar_Middle"
    },
    {
      "x": -2,
      "y": 8,
      "z": -11,
      "name": "Rock_Stone_Brick_Pillar_Base",
      "rotation": 34
    },
    {
      "x": -2,
      "y": 9,
      "z": -11,
      "name": "Rock_Stone_Brick"
    },
    {
      "x": -2,
      "y": 4,
      "z": -10,
      "name": "Rock_Stone_Brick_Decorative"
    },
    {
      "x": -2,
      "y": 5,
      "z": -10,
      "name": "Soil_Gravel_Half",
      "support": 15,
      "rotation": 5
    },
    {
      "x": -2,
      "y": 6,
      "z": -10,
      "name": "Soil_Gravel_Half",
      "support": 15,
      "rotation": 5
    },
    {
      "x": -2,
      "y": 7,
      "z": -10,
      "name": "Soil_Gravel_Half",
      "support": 15,
      "rotation": 5
    },
    {
      "x": -2,
      "y": 8,
      "z": -10,
      "name": "Soil_Gravel_Half",
      "support": 15,
      "rotation": 5
    },
    {
      "x": -2,
      "y": 9,
      "z": -10,
      "name": "Rock_Stone_Brick"
    },
    {
      "x": -2,
      "y": 4,
      "z": -9,
      "name": "Rock_Stone_Brick_Decorative"
    },
    {
      "x": -2,
      "y": 5,
      "z": -9,
      "name": "Soil_Gravel_Half",
      "support": 15,
      "rotation": 5
    },
    {
      "x": -2,
      "y": 6,
      "z": -9,
      "name": "Soil_Gravel_Half",
      "support": 15,
      "rotation": 5
    },
    {
      "x": -2,
      "y": 7,
      "z": -9,
      "name": "Soil_Gravel_Half",
      "support": 15,
      "rotation": 5
    },
    {
      "x": -2,
      "y": 8,
      "z": -9,
      "name": "Soil_Gravel_Half",
      "support": 15,
      "rotation": 5
    },
    {
      "x": -2,
      "y": 9,
      "z": -9,
      "name": "Rock_Stone_Brick"
    },
    {
      "x": -2,
      "y": 4,
      "z": -8,
      "name": "Rock_Stone_Brick_Decorative"
    },
    {
      "x": -2,
      "y": 5,
      "z": -8,
      "name": "Soil_Gravel_Half",
      "support": 15,
      "rotation": 5
    },
    {
      "x": -2,
      "y": 6,
      "z": -8,
      "name": "Soil_Gravel_Half",
      "support": 15,
      "rotation": 5
    },
    {
      "x": -2,
      "y": 7,
      "z": -8,
      "name": "Soil_Gravel_Half",
      "support": 15,
      "rotation": 5
    },
    {
      "x": -2,
      "y": 8,
      "z": -8,
      "name": "Soil_Gravel_Half",
      "support": 15,
      "rotation": 5
    },
    {
      "x": -2,
      "y": 9,
      "z": -8,
      "name": "Rock_Stone_Brick"
    },
    {
      "x": -2,
      "y": 4,
      "z": -7,
      "name": "Rock_Stone_Brick_Smooth"
    },
    {
      "x": -2,
      "y": 5,
      "z": -7,
      "name": "Rock_Stone_Brick_Pillar_Base",
      "rotation": 3
    },
    {
      "x": -2,
      "y": 6,
      "z": -7,
      "name": "Rock_Stone_Brick_Pillar_Middle",
      "rotation": 3
    },
    {
      "x": -2,
      "y": 7,
      "z": -7,
      "name": "Rock_Stone_Brick_Pillar_Middle",
      "rotation": 3
    },
    {
      "x": -2,
      "y": 8,
      "z": -7,
      "name": "Rock_Stone_Brick_Pillar_Base",
      "rotation": 33
    },
    {
      "x": -2,
      "y": 9,
      "z": -7,
      "name": "Rock_Stone_Brick_Decorative"
    },
    {
      "x": -2,
      "y": 3,
      "z": -6,
      "name": "Rock_Stone_Brick_Smooth"
    },
    {
      "x": -2,
      "y": 9,
      "z": -6,
      "name": "Rock_Stone_Brick"
    },
    {
      "x": -2,
      "y": 13,
      "z": -6,
      "name": "Cloth_Block_Wool_Pink",
      "rotation": 3
    },
    {
      "x": -2,
      "y": 3,
      "z": -5,
      "name": "Rock_Stone_Brick_Smooth"
    },
    {
      "x": -2,
      "y": 10,
      "z": -5,
      "name": "Rock_Stone_Brick"
    },
    {
      "x": -2,
      "y": 13,
      "z": -5,
      "name": "Cloth_Block_Wool_Green",
      "rotation": 2
    },
    {
      "x": -2,
      "y": 3,
      "z": -4,
      "name": "Rock_Stone_Brick_Smooth"
    },
    {
      "x": -2,
      "y": 11,
      "z": -4,
      "name": "Rock_Stone_Brick"
    },
    {
      "x": -2,
      "y": 3,
      "z": -3,
      "name": "Rock_Stone_Brick_Smooth"
    },
    {
      "x": -2,
      "y": 11,
      "z": -3,
      "name": "Rock_Stone_Brick"
    },
    {
      "x": -2,
      "y": 3,
      "z": -2,
      "name": "Rock_Stone_Brick_Smooth"
    },
    {
      "x": -2,
      "y": 4,
      "z": -2,
      "name": "Rock_Stone_Brick_Smooth"
    },
    {
      "x": -2,
      "y": 5,
      "z": -2,
      "name": "Rock_Stone_Brick_Pillar_Base"
    },
    {
      "x": -2,
      "y": 6,
      "z": -2,
      "name": "Rock_Stone_Brick_Pillar_Middle"
    },
    {
      "x": -2,
      "y": 7,
      "z": -2,
      "name": "Rock_Stone_Brick_Pillar_Middle"
    },
    {
      "x": -2,
      "y": 8,
      "z": -2,
      "name": "Rock_Stone_Brick_Pillar_Middle",
      "rotation": 8
    },
    {
      "x": -2,
      "y": 9,
      "z": -2,
      "name": "Rock_Stone_Brick_Pillar_Middle",
      "rotation": 8
    },
    {
      "x": -2,
      "y": 10,
      "z": -2,
      "name": "Rock_Stone_Brick_Pillar_Base",
      "rotation": 8
    },
    {
      "x": -2,
      "y": 11,
      "z": -2,
      "name": "Rock_Stone_Brick_Decorative"
    },
    {
      "x": -2,
      "y": 3,
      "z": -1,
      "name": "Rock_Stone_Brick_Smooth"
    },
    {
      "x": -2,
      "y": 4,
      "z": -1,
      "name": "Rock_Stone_Brick_Smooth_Stairs",
      "rotation": 3
    },
    {
      "x": -2,
      "y": 11,
      "z": -1,
      "name": "Rock_Stone_Brick"
    },
    {
      "x": -2,
      "y": 3,
      "z": 0,
      "name": "Rock_Stone_Brick_Smooth"
    },
    {
      "x": -2,
      "y": 4,
      "z": 0,
      "name": "Rock_Stone_Brick_Smooth_Stairs",
      "rotation": 3
    },
    {
      "x": -2,
      "y": 11,
      "z": 0,
      "name": "Rock_Stone_Brick"
    },
    {
      "x": -2,
      "y": 3,
      "z": 1,
      "name": "Rock_Stone_Brick_Smooth"
    },
    {
      "x": -2,
      "y": 4,
      "z": 1,
      "name": "Rock_Stone_Brick_Smooth_Stairs",
      "rotation": 3
    },
    {
      "x": -2,
      "y": 11,
      "z": 1,
      "name": "Rock_Stone_Brick"
    },
    {
      "x": -2,
      "y": 3,
      "z": 2,
      "name": "Rock_Stone_Brick_Smooth"
    },
    {
      "x": -2,
      "y": 4,
      "z": 2,
      "name": "Rock_Stone_Brick_Smooth"
    },
    {
      "x": -2,
      "y": 5,
      "z": 2,
      "name": "Rock_Stone_Brick_Pillar_Base"
    },
    {
      "x": -2,
      "y": 6,
      "z": 2,
      "name": "Rock_Stone_Brick_Pillar_Middle"
    },
    {
      "x": -2,
      "y": 7,
      "z": 2,
      "name": "Rock_Stone_Brick_Pillar_Middle"
    },
    {
      "x": -2,
      "y": 8,
      "z": 2,
      "name": "Rock_Stone_Brick_Pillar_Middle",
      "rotation": 8
    },
    {
      "x": -2,
      "y": 9,
      "z": 2,
      "name": "Rock_Stone_Brick_Pillar_Middle",
      "rotation": 8
    },
    {
      "x": -2,
      "y": 10,
      "z": 2,
      "name": "Rock_Stone_Brick_Pillar_Base",
      "rotation": 8
    },
    {
      "x": -2,
      "y": 11,
      "z": 2,
      "name": "Rock_Stone_Brick_Decorative"
    },
    {
      "x": -2,
      "y": 3,
      "z": 3,
      "name": "Rock_Stone_Brick_Smooth"
    },
    {
      "x": -2,
      "y": 11,
      "z": 3,
      "name": "Rock_Stone_Brick"
    },
    {
      "x": -2,
      "y": 3,
      "z": 4,
      "name": "Rock_Stone_Brick_Smooth"
    },
    {
      "x": -2,
      "y": 10,
      "z": 4,
      "name": "Rock_Stone_Brick"
    },
    {
      "x": -2,
      "y": 11,
      "z": 4,
      "name": "Rock_Stone_Brick_Smooth"
    },
    {
      "x": -2,
      "y": 3,
      "z": 5,
      "name": "Rock_Stone_Brick_Smooth"
    },
    {
      "x": -2,
      "y": 9,
      "z": 5,
      "name": "Rock_Stone_Brick"
    },
    {
      "x": -2,
      "y": 10,
      "z": 5,
      "name": "Rock_Stone_Brick_Smooth"
    },
    {
      "x": -2,
      "y": 13,
      "z": 5,
      "name": "Cloth_Block_Wool_Green",
      "rotation": 2
    },
    {
      "x": -2,
      "y": 3,
      "z": 6,
      "name": "Rock_Stone_Brick_Smooth"
    },
    {
      "x": -2,
      "y": 9,
      "z": 6,
      "name": "Rock_Stone_Brick_Decorative"
    },
    {
      "x": -2,
      "y": 13,
      "z": 6,
      "name": "Cloth_Block_Wool_Pink"
    },
    {
      "x": -2,
      "y": 4,
      "z": 7,
      "name": "Rock_Stone_Brick_Smooth"
    },
    {
      "x": -2,
      "y": 5,
      "z": 7,
      "name": "Rock_Stone_Brick_Pillar_Base",
      "rotation": 1
    },
    {
      "x": -2,
      "y": 6,
      "z": 7,
      "name": "Rock_Stone_Brick_Pillar_Middle",
      "rotation": 1
    },
    {
      "x": -2,
      "y": 7,
      "z": 7,
      "name": "Rock_Stone_Brick_Pillar_Middle",
      "rotation": 1
    },
    {
      "x": -2,
      "y": 8,
      "z": 7,
      "name": "Rock_Stone_Brick_Pillar_Base",
      "rotation": 35
    },
    {
      "x": -2,
      "y": 9,
      "z": 7,
      "name": "Rock_Stone_Brick_Decorative"
    },
    {
      "x": -2,
      "y": 4,
      "z": 8,
      "name": "Rock_Stone_Brick_Smooth"
    },
    {
      "x": -2,
      "y": 5,
      "z": 8,
      "name": "Soil_Gravel",
      "support": 15
    },
    {
      "x": -2,
      "y": 6,
      "z": 8,
      "name": "Soil_Gravel",
      "support": 15
    },
    {
      "x": -2,
      "y": 7,
      "z": 8,
      "name": "Soil_Gravel",
      "support": 15
    },
    {
      "x": -2,
      "y": 8,
      "z": 8,
      "name": "Soil_Gravel",
      "support": 15
    },
    {
      "x": -2,
      "y": 13,
      "z": 16,
      "name": "Cloth_Block_Wool_Pink"
    },
    {
      "x": -1,
      "y": 3,
      "z": -16,
      "name": "Rock_Stone_Brick_Smooth"
    },
    {
      "x": -1,
      "y": 4,
      "z": -16,
      "name": "Rock_Stone_Brick_Smooth_Half",
      "rotation": 5
    },
    {
      "x": -1,
      "y": 5,
      "z": -16,
      "name": "Rock_Stone_Brick_Smooth_Half",
      "rotation": 5
    },
    {
      "x": -1,
      "y": 6,
      "z": -16,
      "name": "Rock_Stone_Brick_Smooth_Half",
      "rotation": 5
    },
    {
      "x": -1,
      "y": 7,
      "z": -16,
      "name": "*Rock_Stone_Brick_Stairs_State_Definitions_Inverted_Corner_Left",
      "rotation": 11
    },
    {
      "x": -1,
      "y": 8,
      "z": -16,
      "name": "Rock_Stone_Brick_Decorative"
    },
    {
      "x": -1,
      "y": 9,
      "z": -16,
      "name": "Rock_Stone_Brick"
    },
    {
      "x": -1,
      "y": 13,
      "z": -16,
      "name": "Cloth_Block_Wool_Pink",
      "rotation": 3
    },
    {
      "x": -1,
      "y": 3,
      "z": -15,
      "name": "Rock_Stone_Brick_Smooth"
    },
    {
      "x": -1,
      "y": 9,
      "z": -15,
      "name": "Rock_Stone_Brick_Smooth"
    },
    {
      "x": -1,
      "y": 3,
      "z": -14,
      "name": "Rock_Stone_Brick_Smooth"
    },
    {
      "x": -1,
      "y": 9,
      "z": -14,
      "name": "Rock_Stone_Brick_Smooth"
    },
    {
      "x": -1,
      "y": 3,
      "z": -13,
      "name": "Rock_Stone_Brick_Smooth"
    },
    {
      "x": -1,
      "y": 9,
      "z": -13,
      "name": "Rock_Stone_Brick_Smooth"
    },
    {
      "x": -1,
      "y": 3,
      "z": -12,
      "name": "Rock_Stone_Brick_Smooth"
    },
    {
      "x": -1,
      "y": 9,
      "z": -12,
      "name": "Rock_Stone_Brick_Smooth"
    },
    {
      "x": -1,
      "y": 3,
      "z": -11,
      "name": "Rock_Stone_Brick_Smooth"
    },
    {
      "x": -1,
      "y": 9,
      "z": -11,
      "name": "Rock_Stone_Brick_Smooth"
    },
    {
      "x": -1,
      "y": 3,
      "z": -10,
      "name": "Rock_Stone_Brick_Smooth"
    },
    {
      "x": -1,
      "y": 9,
      "z": -10,
      "name": "Rock_Stone_Brick_Smooth"
    },
    {
      "x": -1,
      "y": 3,
      "z": -9,
      "name": "Rock_Stone_Brick_Smooth"
    },
    {
      "x": -1,
      "y": 9,
      "z": -9,
      "name": "Rock_Stone_Brick_Smooth"
    },
    {
      "x": -1,
      "y": 3,
      "z": -8,
      "name": "Rock_Stone_Brick_Smooth"
    },
    {
      "x": -1,
      "y": 9,
      "z": -8,
      "name": "Rock_Stone_Brick_Smooth"
    },
    {
      "x": -1,
      "y": 3,
      "z": -7,
      "name": "Rock_Stone_Brick_Smooth"
    },
    {
      "x": -1,
      "y": 9,
      "z": -7,
      "name": "Rock_Stone_Brick_Smooth"
    },
    {
      "x": -1,
      "y": 3,
      "z": -6,
      "name": "Rock_Stone_Brick_Smooth"
    },
    {
      "x": -1,
      "y": 9,
      "z": -6,
      "name": "Rock_Stone_Brick_Smooth_Half",
      "rotation": 8
    },
    {
      "x": -1,
      "y": 10,
      "z": -6,
      "name": "Rock_Stone_Brick_Smooth"
    },
    {
      "x": -1,
      "y": 13,
      "z": -6,
      "name": "Cloth_Block_Wool_Pink",
      "rotation": 3
    },
    {
      "x": -1,
      "y": 3,
      "z": -5,
      "name": "Rock_Stone_Brick_Smooth"
    },
    {
      "x": -1,
      "y": 10,
      "z": -5,
      "name": "Rock_Stone_Brick_Smooth_Half",
      "rotation": 8
    },
    {
      "x": -1,
      "y": 11,
      "z": -5,
      "name": "Rock_Stone_Brick_Smooth"
    },
    {
      "x": -1,
      "y": 13,
      "z": -5,
      "name": "Cloth_Block_Wool_Green",
      "rotation": 2
    },
    {
      "x": -1,
      "y": 3,
      "z": -4,
      "name": "Rock_Stone_Brick_Smooth"
    },
    {
      "x": -1,
      "y": 11,
      "z": -4,
      "name": "Rock_Stone_Brick_Smooth_Half",
      "rotation": 8
    },
    {
      "x": -1,
      "y": 3,
      "z": -3,
      "name": "Rock_Stone_Brick_Smooth"
    },
    {
      "x": -1,
      "y": 11,
      "z": -3,
      "name": "Rock_Stone_Brick_Smooth_Half",
      "rotation": 8
    },
    {
      "x": -1,
      "y": 3,
      "z": -2,
      "name": "Rock_Stone_Brick_Smooth"
    },
    {
      "x": -1,
      "y": 4,
      "z": -2,
      "name": "Rock_Stone_Brick_Smooth_Stairs",
      "rotation": 2
    },
    {
      "x": -1,
      "y": 11,
      "z": -2,
      "name": "Rock_Stone_Brick"
    },
    {
      "x": -1,
      "y": 3,
      "z": -1,
      "name": "Rock_Stone_Brick_Smooth"
    },
    {
      "x": -1,
      "y": 4,
      "z": -1,
      "name": "Rock_Stone_Brick_Smooth"
    },
    {
      "x": -1,
      "y": 11,
      "z": -1,
      "name": "Rock_Stone_Brick_Smooth_Half",
      "rotation": 8
    },
    {
      "x": -1,
      "y": 3,
      "z": 0,
      "name": "Rock_Stone_Brick_Smooth"
    },
    {
      "x": -1,
      "y": 4,
      "z": 0,
      "name": "Rock_Stone_Brick_Smooth"
    },
    {
      "x": -1,
      "y": 5,
      "z": 0,
      "name": "Furniture_Ancient_Statue",
      "filler": 31,
      "rotation": 2
    },
    {
      "x": -1,
      "y": 6,
      "z": 0,
      "name": "Furniture_Ancient_Statue",
      "filler": 1055,
      "rotation": 2
    },
    {
      "x": -1,
      "y": 7,
      "z": 0,
      "name": "Furniture_Ancient_Statue",
      "filler": 2079,
      "rotation": 2
    },
    {
      "x": -1,
      "y": 11,
      "z": 0,
      "name": "Rock_Stone_Brick_Smooth_Half",
      "rotation": 8
    },
    {
      "x": -1,
      "y": 3,
      "z": 1,
      "name": "Rock_Stone_Brick_Smooth"
    },
    {
      "x": -1,
      "y": 4,
      "z": 1,
      "name": "Rock_Stone_Brick_Smooth"
    },
    {
      "x": -1,
      "y": 11,
      "z": 1,
      "name": "Rock_Stone_Brick_Smooth_Half",
      "rotation": 8
    },
    {
      "x": -1,
      "y": 3,
      "z": 2,
      "name": "Rock_Stone_Brick_Smooth"
    },
    {
      "x": -1,
      "y": 4,
      "z": 2,
      "name": "Rock_Stone_Brick_Smooth_Stairs"
    },
    {
      "x": -1,
      "y": 11,
      "z": 2,
      "name": "Rock_Stone_Brick"
    },
    {
      "x": -1,
      "y": 3,
      "z": 3,
      "name": "Rock_Stone_Brick_Smooth"
    },
    {
      "x": -1,
      "y": 11,
      "z": 3,
      "name": "Rock_Stone_Brick_Smooth_Half",
      "rotation": 8
    },
    {
      "x": -1,
      "y": 3,
      "z": 4,
      "name": "Rock_Stone_Brick_Smooth"
    },
    {
      "x": -1,
      "y": 10,
      "z": 4,
      "name": "Rock_Stone_Brick_Smooth_Half",
      "rotation": 8
    },
    {
      "x": -1,
      "y": 11,
      "z": 4,
      "name": "Rock_Stone_Brick_Smooth"
    },
    {
      "x": -1,
      "y": 3,
      "z": 5,
      "name": "Rock_Stone_Brick_Smooth"
    },
    {
      "x": -1,
      "y": 9,
      "z": 5,
      "name": "Rock_Stone_Brick_Smooth_Half",
      "rotation": 8
    },
    {
      "x": -1,
      "y": 10,
      "z": 5,
      "name": "Rock_Stone_Brick_Smooth"
    },
    {
      "x": -1,
      "y": 13,
      "z": 5,
      "name": "Cloth_Block_Wool_Green",
      "rotation": 2
    },
    {
      "x": -1,
      "y": 3,
      "z": 6,
      "name": "Rock_Stone_Brick_Smooth"
    },
    {
      "x": -1,
      "y": 9,
      "z": 6,
      "name": "Rock_Stone_Brick_Smooth"
    },
    {
      "x": -1,
      "y": 13,
      "z": 6,
      "name": "Cloth_Block_Wool_Pink"
    },
    {
      "x": -1,
      "y": 4,
      "z": 7,
      "name": "Rock_Stone_Brick_Decorative",
      "rotation": 1
    },
    {
      "x": -1,
      "y": 5,
      "z": 7,
      "name": "Soil_Gravel_Half",
      "support": 15,
      "rotation": 6
    },
    {
      "x": -1,
      "y": 6,
      "z": 7,
      "name": "Soil_Gravel_Half",
      "support": 15,
      "rotation": 6
    },
    {
      "x": -1,
      "y": 7,
      "z": 7,
      "name": "Soil_Gravel_Half",
      "support": 15,
      "rotation": 6
    },
    {
      "x": -1,
      "y": 8,
      "z": 7,
      "name": "Soil_Gravel_Half",
      "support": 15,
      "rotation": 6
    },
    {
      "x": -1,
      "y": 9,
      "z": 7,
      "name": "Rock_Stone_Brick"
    },
    {
      "x": -1,
      "y": 13,
      "z": 16,
      "name": "Cloth_Block_Wool_Pink"
    },
    {
      "x": 0,
      "y": 3,
      "z": -16,
      "name": "Rock_Stone_Brick_Smooth"
    },
    {
      "x": 0,
      "y": 7,
      "z": -16,
      "name": "Rock_Stone_Brick_Stairs",
      "rotation": 10
    },
    {
      "x": 0,
      "y": 8,
      "z": -16,
      "name": "Rock_Stone_Brick_Decorative"
    },
    {
      "x": 0,
      "y": 9,
      "z": -16,
      "name": "Rock_Stone_Brick"
    },
    {
      "x": 0,
      "y": 13,
      "z": -16,
      "name": "Cloth_Block_Wool_Cyan_Light"
    },
    {
      "x": 0,
      "y": 3,
      "z": -15,
      "name": "Rock_Stone_Brick_Smooth"
    },
    {
      "x": 0,
      "y": 9,
      "z": -15,
      "name": "Rock_Stone_Brick_Smooth"
    },
    {
      "x": 0,
      "y": 13,
      "z": -15,
      "name": "Cloth_Block_Wool_Cyan_Light"
    },
    {
      "x": 0,
      "y": 3,
      "z": -14,
      "name": "Rock_Stone_Brick_Smooth"
    },
    {
      "x": 0,
      "y": 9,
      "z": -14,
      "name": "Rock_Stone_Brick_Smooth"
    },
    {
      "x": 0,
      "y": 13,
      "z": -14,
      "name": "Cloth_Block_Wool_Cyan_Light"
    },
    {
      "x": 0,
      "y": 3,
      "z": -13,
      "name": "Rock_Stone_Brick_Smooth"
    },
    {
      "x": 0,
      "y": 9,
      "z": -13,
      "name": "Rock_Stone_Brick_Smooth"
    },
    {
      "x": 0,
      "y": 3,
      "z": -12,
      "name": "Rock_Stone_Brick_Smooth"
    },
    {
      "x": 0,
      "y": 9,
      "z": -12,
      "name": "Rock_Stone_Brick_Smooth"
    },
    {
      "x": 0,
      "y": 3,
      "z": -11,
      "name": "Rock_Stone_Brick_Smooth"
    },
    {
      "x": 0,
      "y": 9,
      "z": -11,
      "name": "Rock_Stone_Brick_Smooth"
    },
    {
      "x": 0,
      "y": 3,
      "z": -10,
      "name": "Rock_Stone_Brick_Smooth"
    },
    {
      "x": 0,
      "y": 9,
      "z": -10,
      "name": "Rock_Stone_Brick_Smooth"
    },
    {
      "x": 0,
      "y": 3,
      "z": -9,
      "name": "Rock_Stone_Brick_Smooth"
    },
    {
      "x": 0,
      "y": 9,
      "z": -9,
      "name": "Rock_Stone_Brick_Smooth"
    },
    {
      "x": 0,
      "y": 3,
      "z": -8,
      "name": "Rock_Stone_Brick_Smooth"
    },
    {
      "x": 0,
      "y": 9,
      "z": -8,
      "name": "Rock_Stone_Brick_Smooth"
    },
    {
      "x": 0,
      "y": 3,
      "z": -7,
      "name": "Rock_Stone_Brick_Smooth"
    },
    {
      "x": 0,
      "y": 9,
      "z": -7,
      "name": "Rock_Stone_Brick_Smooth"
    },
    {
      "x": 0,
      "y": 3,
      "z": -6,
      "name": "Rock_Stone_Brick_Smooth"
    },
    {
      "x": 0,
      "y": 9,
      "z": -6,
      "name": "Rock_Stone_Brick_Smooth_Half",
      "rotation": 8
    },
    {
      "x": 0,
      "y": 10,
      "z": -6,
      "name": "Rock_Stone_Brick_Smooth"
    },
    {
      "x": 0,
      "y": 13,
      "z": -6,
      "name": "Cloth_Block_Wool_Pink",
      "rotation": 3
    },
    {
      "x": 0,
      "y": 3,
      "z": -5,
      "name": "Rock_Stone_Brick_Smooth"
    },
    {
      "x": 0,
      "y": 10,
      "z": -5,
      "name": "Rock_Stone_Brick_Smooth_Half",
      "rotation": 8
    },
    {
      "x": 0,
      "y": 11,
      "z": -5,
      "name": "Rock_Stone_Brick_Smooth"
    },
    {
      "x": 0,
      "y": 13,
      "z": -5,
      "name": "Cloth_Block_Wool_Green"
    },
    {
      "x": 0,
      "y": 3,
      "z": -4,
      "name": "Rock_Stone_Brick_Smooth"
    },
    {
      "x": 0,
      "y": 11,
      "z": -4,
      "name": "Rock_Stone_Brick_Smooth_Half",
      "rotation": 8
    },
    {
      "x": 0,
      "y": 3,
      "z": -3,
      "name": "Rock_Stone_Brick_Smooth"
    },
    {
      "x": 0,
      "y": 11,
      "z": -3,
      "name": "Rock_Stone_Brick_Smooth_Half",
      "rotation": 8
    },
    {
      "x": 0,
      "y": 3,
      "z": -2,
      "name": "Rock_Stone_Brick_Smooth"
    },
    {
      "x": 0,
      "y": 4,
      "z": -2,
      "name": "Rock_Stone_Brick_Smooth_Stairs",
      "rotation": 2
    },
    {
      "x": 0,
      "y": 11,
      "z": -2,
      "name": "Rock_Stone_Brick"
    },
    {
      "x": 0,
      "y": 3,
      "z": -1,
      "name": "Rock_Stone_Brick_Smooth"
    },
    {
      "x": 0,
      "y": 4,
      "z": -1,
      "name": "Rock_Stone_Brick_Smooth"
    },
    {
      "x": 0,
      "y": 11,
      "z": -1,
      "name": "Rock_Stone_Brick_Smooth_Half",
      "rotation": 8
    },
    {
      "x": 0,
      "y": 3,
      "z": 0,
      "name": "Rock_Stone_Brick_Smooth"
    },
    {
      "x": 0,
      "y": 4,
      "z": 0,
      "name": "Rock_Stone_Brick_Smooth"
    },
    {
      "x": 0,
      "y": 5,
      "z": 0,
      "name": "Furniture_Ancient_Statue",
      "rotation": 2
    },
    {
      "x": 0,
      "y": 6,
      "z": 0,
      "name": "Furniture_Ancient_Statue",
      "filler": 1024,
      "rotation": 2
    },
    {
      "x": 0,
      "y": 7,
      "z": 0,
      "name": "Furniture_Ancient_Statue",
      "filler": 2048,
      "rotation": 2
    },
    {
      "x": 0,
      "y": 11,
      "z": 0,
      "name": "Rock_Stone_Brick_Smooth_Half",
      "rotation": 8
    },
    {
      "x": 0,
      "y": 3,
      "z": 1,
      "name": "Rock_Stone_Brick_Smooth"
    },
    {
      "x": 0,
      "y": 4,
      "z": 1,
      "name": "Rock_Stone_Brick_Smooth"
    },
    {
      "x": 0,
      "y": 11,
      "z": 1,
      "name": "Rock_Stone_Brick_Smooth_Half",
      "rotation": 8
    },
    {
      "x": 0,
      "y": 3,
      "z": 2,
      "name": "Rock_Stone_Brick_Smooth"
    },
    {
      "x": 0,
      "y": 4,
      "z": 2,
      "name": "Rock_Stone_Brick_Smooth_Stairs"
    },
    {
      "x": 0,
      "y": 11,
      "z": 2,
      "name": "Rock_Stone_Brick"
    },
    {
      "x": 0,
      "y": 3,
      "z": 3,
      "name": "Rock_Stone_Brick_Smooth"
    },
    {
      "x": 0,
      "y": 11,
      "z": 3,
      "name": "Rock_Stone_Brick_Smooth_Half",
      "rotation": 8
    },
    {
      "x": 0,
      "y": 3,
      "z": 4,
      "name": "Rock_Stone_Brick_Smooth"
    },
    {
      "x": 0,
      "y": 10,
      "z": 4,
      "name": "Rock_Stone_Brick_Smooth_Half",
      "rotation": 8
    },
    {
      "x": 0,
      "y": 11,
      "z": 4,
      "name": "Rock_Stone_Brick_Smooth"
    },
    {
      "x": 0,
      "y": 3,
      "z": 5,
      "name": "Rock_Stone_Brick_Smooth"
    },
    {
      "x": 0,
      "y": 9,
      "z": 5,
      "name": "Rock_Stone_Brick_Smooth_Half",
      "rotation": 8
    },
    {
      "x": 0,
      "y": 10,
      "z": 5,
      "name": "Rock_Stone_Brick_Smooth"
    },
    {
      "x": 0,
      "y": 13,
      "z": 5,
      "name": "Cloth_Block_Wool_Green",
      "rotation": 2
    },
    {
      "x": 0,
      "y": 3,
      "z": 6,
      "name": "Rock_Stone_Brick_Smooth"
    },
    {
      "x": 0,
      "y": 4,
      "z": 6,
      "name": "Furniture_Dungeon_Chest_Epic",
      "components": {
        "Components": {
          "PlacedByInteraction": {
            "WhoPlacedUuid": {
              "$binary": "qGU++b12Sz+P6LLmzedq3Q==",
              "$type": "04"
            }
          },
          "ItemContainerBlock": {
            "ItemContainer": {
              "Capacity": 18,
              "Items": {}
            },
            "Capacity": 18
          }
        }
      },
      "rotation": 2
    },
    {
      "x": 0,
      "y": 9,
      "z": 6,
      "name": "Rock_Stone_Brick_Smooth"
    },
    {
      "x": 0,
      "y": 13,
      "z": 6,
      "name": "Cloth_Block_Wool_Pink",
      "rotation": 2
    },
    {
      "x": 0,
      "y": 4,
      "z": 7,
      "name": "Rock_Stone_Brick_Decorative",
      "rotation": 1
    },
    {
      "x": 0,
      "y": 5,
      "z": 7,
      "name": "Soil_Gravel_Half",
      "support": 15,
      "rotation": 6
    },
    {
      "x": 0,
      "y": 6,
      "z": 7,
      "name": "Soil_Gravel_Half",
      "support": 15,
      "rotation": 6
    },
    {
      "x": 0,
      "y": 7,
      "z": 7,
      "name": "Soil_Gravel_Half",
      "support": 15,
      "rotation": 6
    },
    {
      "x": 0,
      "y": 8,
      "z": 7,
      "name": "Soil_Gravel_Half",
      "support": 15,
      "rotation": 6
    },
    {
      "x": 0,
      "y": 9,
      "z": 7,
      "name": "Rock_Stone_Brick"
    },
    {
      "x": 0,
      "y": 13,
      "z": 16,
      "name": "Cloth_Block_Wool_Pink"
    },
    {
      "x": 1,
      "y": 3,
      "z": -16,
      "name": "Rock_Stone_Brick_Smooth"
    },
    {
      "x": 1,
      "y": 4,
      "z": -16,
      "name": "Rock_Stone_Brick_Smooth_Half",
      "rotation": 7
    },
    {
      "x": 1,
      "y": 5,
      "z": -16,
      "name": "Rock_Stone_Brick_Smooth_Half",
      "rotation": 7
    },
    {
      "x": 1,
      "y": 6,
      "z": -16,
      "name": "Rock_Stone_Brick_Smooth_Half",
      "rotation": 7
    },
    {
      "x": 1,
      "y": 7,
      "z": -16,
      "name": "*Rock_Stone_Brick_Stairs_State_Definitions_Inverted_Corner_Right",
      "rotation": 9
    },
    {
      "x": 1,
      "y": 8,
      "z": -16,
      "name": "Rock_Stone_Brick_Decorative"
    },
    {
      "x": 1,
      "y": 9,
      "z": -16,
      "name": "Rock_Stone_Brick"
    },
    {
      "x": 1,
      "y": 13,
      "z": -16,
      "name": "Cloth_Block_Wool_Pink",
      "rotation": 3
    },
    {
      "x": 1,
      "y": 3,
      "z": -15,
      "name": "Rock_Stone_Brick_Smooth"
    },
    {
      "x": 1,
      "y": 9,
      "z": -15,
      "name": "Rock_Stone_Brick_Smooth"
    },
    {
      "x": 1,
      "y": 3,
      "z": -14,
      "name": "Rock_Stone_Brick_Smooth"
    },
    {
      "x": 1,
      "y": 9,
      "z": -14,
      "name": "Rock_Stone_Brick_Smooth"
    },
    {
      "x": 1,
      "y": 3,
      "z": -13,
      "name": "Rock_Stone_Brick_Smooth"
    },
    {
      "x": 1,
      "y": 9,
      "z": -13,
      "name": "Rock_Stone_Brick_Smooth"
    },
    {
      "x": 1,
      "y": 3,
      "z": -12,
      "name": "Rock_Stone_Brick_Smooth"
    },
    {
      "x": 1,
      "y": 9,
      "z": -12,
      "name": "Rock_Stone_Brick_Smooth"
    },
    {
      "x": 1,
      "y": 3,
      "z": -11,
      "name": "Rock_Stone_Brick_Smooth"
    },
    {
      "x": 1,
      "y": 9,
      "z": -11,
      "name": "Rock_Stone_Brick_Smooth"
    },
    {
      "x": 1,
      "y": 3,
      "z": -10,
      "name": "Rock_Stone_Brick_Smooth"
    },
    {
      "x": 1,
      "y": 9,
      "z": -10,
      "name": "Rock_Stone_Brick_Smooth"
    },
    {
      "x": 1,
      "y": 3,
      "z": -9,
      "name": "Rock_Stone_Brick_Smooth"
    },
    {
      "x": 1,
      "y": 9,
      "z": -9,
      "name": "Rock_Stone_Brick_Smooth"
    },
    {
      "x": 1,
      "y": 3,
      "z": -8,
      "name": "Rock_Stone_Brick_Smooth"
    },
    {
      "x": 1,
      "y": 9,
      "z": -8,
      "name": "Rock_Stone_Brick_Smooth"
    },
    {
      "x": 1,
      "y": 3,
      "z": -7,
      "name": "Rock_Stone_Brick_Smooth"
    },
    {
      "x": 1,
      "y": 9,
      "z": -7,
      "name": "Rock_Stone_Brick_Smooth"
    },
    {
      "x": 1,
      "y": 3,
      "z": -6,
      "name": "Rock_Stone_Brick_Smooth"
    },
    {
      "x": 1,
      "y": 9,
      "z": -6,
      "name": "Rock_Stone_Brick_Smooth_Half",
      "rotation": 8
    },
    {
      "x": 1,
      "y": 10,
      "z": -6,
      "name": "Rock_Stone_Brick_Smooth"
    },
    {
      "x": 1,
      "y": 13,
      "z": -6,
      "name": "Cloth_Block_Wool_Pink",
      "rotation": 3
    },
    {
      "x": 1,
      "y": 3,
      "z": -5,
      "name": "Rock_Stone_Brick_Smooth"
    },
    {
      "x": 1,
      "y": 10,
      "z": -5,
      "name": "Rock_Stone_Brick_Smooth_Half",
      "rotation": 8
    },
    {
      "x": 1,
      "y": 11,
      "z": -5,
      "name": "Rock_Stone_Brick_Smooth"
    },
    {
      "x": 1,
      "y": 13,
      "z": -5,
      "name": "Cloth_Block_Wool_Green",
      "rotation": 2
    },
    {
      "x": 1,
      "y": 3,
      "z": -4,
      "name": "Rock_Stone_Brick_Smooth"
    },
    {
      "x": 1,
      "y": 11,
      "z": -4,
      "name": "Rock_Stone_Brick_Smooth_Half",
      "rotation": 8
    },
    {
      "x": 1,
      "y": 3,
      "z": -3,
      "name": "Rock_Stone_Brick_Smooth"
    },
    {
      "x": 1,
      "y": 11,
      "z": -3,
      "name": "Rock_Stone_Brick_Smooth_Half",
      "rotation": 8
    },
    {
      "x": 1,
      "y": 3,
      "z": -2,
      "name": "Rock_Stone_Brick_Smooth"
    },
    {
      "x": 1,
      "y": 4,
      "z": -2,
      "name": "Rock_Stone_Brick_Smooth_Stairs",
      "rotation": 2
    },
    {
      "x": 1,
      "y": 11,
      "z": -2,
      "name": "Rock_Stone_Brick"
    },
    {
      "x": 1,
      "y": 3,
      "z": -1,
      "name": "Rock_Stone_Brick_Smooth"
    },
    {
      "x": 1,
      "y": 4,
      "z": -1,
      "name": "Rock_Stone_Brick_Smooth"
    },
    {
      "x": 1,
      "y": 11,
      "z": -1,
      "name": "Rock_Stone_Brick_Smooth_Half",
      "rotation": 8
    },
    {
      "x": 1,
      "y": 3,
      "z": 0,
      "name": "Rock_Stone_Brick_Smooth"
    },
    {
      "x": 1,
      "y": 4,
      "z": 0,
      "name": "Rock_Stone_Brick_Smooth"
    },
    {
      "x": 1,
      "y": 5,
      "z": 0,
      "name": "Furniture_Ancient_Statue",
      "filler": 1,
      "rotation": 2
    },
    {
      "x": 1,
      "y": 6,
      "z": 0,
      "name": "Furniture_Ancient_Statue",
      "filler": 1025,
      "rotation": 2
    },
    {
      "x": 1,
      "y": 7,
      "z": 0,
      "name": "Furniture_Ancient_Statue",
      "filler": 2049,
      "rotation": 2
    },
    {
      "x": 1,
      "y": 11,
      "z": 0,
      "name": "Rock_Stone_Brick_Smooth_Half",
      "rotation": 8
    },
    {
      "x": 1,
      "y": 3,
      "z": 1,
      "name": "Rock_Stone_Brick_Smooth"
    },
    {
      "x": 1,
      "y": 4,
      "z": 1,
      "name": "Rock_Stone_Brick_Smooth"
    },
    {
      "x": 1,
      "y": 11,
      "z": 1,
      "name": "Rock_Stone_Brick_Smooth_Half",
      "rotation": 8
    },
    {
      "x": 1,
      "y": 3,
      "z": 2,
      "name": "Rock_Stone_Brick_Smooth"
    },
    {
      "x": 1,
      "y": 4,
      "z": 2,
      "name": "Rock_Stone_Brick_Smooth_Stairs"
    },
    {
      "x": 1,
      "y": 11,
      "z": 2,
      "name": "Rock_Stone_Brick"
    },
    {
      "x": 1,
      "y": 3,
      "z": 3,
      "name": "Rock_Stone_Brick_Smooth"
    },
    {
      "x": 1,
      "y": 11,
      "z": 3,
      "name": "Rock_Stone_Brick_Smooth_Half",
      "rotation": 8
    },
    {
      "x": 1,
      "y": 3,
      "z": 4,
      "name": "Rock_Stone_Brick_Smooth"
    },
    {
      "x": 1,
      "y": 10,
      "z": 4,
      "name": "Rock_Stone_Brick_Smooth_Half",
      "rotation": 8
    },
    {
      "x": 1,
      "y": 11,
      "z": 4,
      "name": "Rock_Stone_Brick_Smooth"
    },
    {
      "x": 1,
      "y": 3,
      "z": 5,
      "name": "Rock_Stone_Brick_Smooth"
    },
    {
      "x": 1,
      "y": 9,
      "z": 5,
      "name": "Rock_Stone_Brick_Smooth_Half",
      "rotation": 8
    },
    {
      "x": 1,
      "y": 10,
      "z": 5,
      "name": "Rock_Stone_Brick_Smooth"
    },
    {
      "x": 1,
      "y": 13,
      "z": 5,
      "name": "Cloth_Block_Wool_Green",
      "rotation": 2
    },
    {
      "x": 1,
      "y": 3,
      "z": 6,
      "name": "Rock_Stone_Brick_Smooth"
    },
    {
      "x": 1,
      "y": 9,
      "z": 6,
