{
  "version": 8,
  "blockIdVersion": 11,
  "anchorX": -1,
  "anchorY": 15,
  "anchorZ": 0,
  "blocks": [
    {
      "x": -17,
      "y": 2,
      "z": -2,
      "name": "Rock_Stone"
    },
    {
      "x": -17,
      "y": 3,
      "z": -2,
      "name": "Rock_Stone_Brick"
    },
    {
      "x": -17,
      "y": 4,
      "z": -2,
      "name": "Rock_Stone_Brick"
    },
    {
      "x": -17,
      "y": 5,
      "z": -2,
      "name": "Rock_Stone_Brick"
    },
    {
      "x": -17,
      "y": 6,
      "z": -2,
      "name": "Rock_Stone_Brick"
    },
    {
      "x": -17,
      "y": 7,
      "z": -2,
      "name": "Rock_Stone_Brick"
    },
    {
      "x": -17,
      "y": 8,
      "z": -2,
      "name": "Rock_Stone_Brick"
    },
    {
      "x": -17,
      "y": 2,
      "z": -1,
      "name": "Rock_Stone"
    },
    {
      "x": -17,
      "y": 3,
      "z": -1,
      "name": "Rock_Stone"
    },
    {
      "x": -17,
      "y": 4,
      "z": -1,
      "name": "Rock_Stone"
    },
    {
      "x": -17,
      "y": 5,
      "z": -1,
      "name": "Rock_Stone"
    },
    {
      "x": -17,
      "y": 6,
      "z": -1,
      "name": "Rock_Stone"
    },
    {
      "x": -17,
      "y": 7,
      "z": -1,
      "name": "Rock_Stone"
    },
    {
      "x": -17,
      "y": 8,
      "z": -1,
      "name": "Rock_Stone"
    },
    {
      "x": -17,
      "y": 9,
      "z": -1,
      "name": "Rock_Stone_Brick_Smooth"
    },
    {
      "x": -17,
      "y": 2,
      "z": 0,
      "name": "Rock_Stone"
    },
    {
      "x": -17,
      "y": 3,
      "z": 0,
      "name": "Rock_Stone"
    },
    {
      "x": -17,
      "y": 4,
      "z": 0,
      "name": "Rock_Stone"
    },
    {
      "x": -17,
      "y": 5,
      "z": 0,
      "name": "Rock_Stone"
    },
    {
      "x": -17,
      "y": 6,
      "z": 0,
      "name": "Rock_Stone"
    },
    {
      "x": -17,
      "y": 7,
      "z": 0,
      "name": "Rock_Stone"
    },
    {
      "x": -17,
      "y": 8,
      "z": 0,
      "name": "Rock_Stone"
    },
    {
      "x": -17,
      "y": 9,
      "z": 0,
      "name": "Rock_Stone_Brick_Smooth"
    },
    {
      "x": -17,
      "y": 2,
      "z": 1,
      "name": "Rock_Stone"
    },
    {
      "x": -17,
      "y": 3,
      "z": 1,
      "name": "Rock_Stone"
    },
    {
      "x": -17,
      "y": 4,
      "z": 1,
      "name": "Rock_Stone"
    },
    {
      "x": -17,
      "y": 5,
      "z": 1,
      "name": "Rock_Stone"
    },
    {
      "x": -17,
      "y": 6,
      "z": 1,
      "name": "Rock_Stone"
    },
    {
      "x": -17,
      "y": 7,
      "z": 1,
      "name": "Rock_Stone"
    },
    {
      "x": -17,
      "y": 8,
      "z": 1,
      "name": "Rock_Stone"
    },
    {
      "x": -17,
      "y": 9,
      "z": 1,
      "name": "Rock_Stone_Brick"
    },
    {
      "x": -17,
      "y": 2,
      "z": 2,
      "name": "Rock_Stone"
    },
    {
      "x": -17,
      "y": 3,
      "z": 2,
      "name": "Rock_Stone_Brick"
    },
    {
      "x": -17,
      "y": 4,
      "z": 2,
      "name": "Rock_Stone_Brick"
    },
    {
      "x": -17,
      "y": 5,
      "z": 2,
      "name": "Rock_Stone_Brick"
    },
    {
      "x": -17,
      "y": 6,
      "z": 2,
      "name": "Rock_Stone_Brick"
    },
    {
      "x": -17,
      "y": 7,
      "z": 2,
      "name": "Rock_Stone_Brick"
    },
    {
      "x": -17,
      "y": 8,
      "z": 2,
      "name": "Rock_Stone_Brick"
    },
    {
      "x": -16,
      "y": 2,
      "z": -2,
      "name": "Rock_Stone"
    },
    {
      "x": -16,
      "y": 3,
      "z": -2,
      "name": "Rock_Stone_Brick"
    },
    {
      "x": -16,
      "y": 4,
      "z": -2,
      "name": "Rock_Stone_Brick"
    },
    {
      "x": -16,
      "y": 5,
      "z": -2,
      "name": "Rock_Stone_Brick"
    },
    {
      "x": -16,
      "y": 6,
      "z": -2,
      "name": "Rock_Stone_Brick"
    },
    {
      "x": -16,
      "y": 7,
      "z": -2,
      "name": "Rock_Stone_Brick"
    },
    {
      "x": -16,
      "y": 8,
      "z": -2,
      "name": "Rock_Stone_Brick"
    },
    {
      "x": -16,
      "y": 2,
      "z": -1,
      "name": "Rock_Stone"
    },
    {
      "x": -16,
      "y": 5,
      "z": -1,
      "name": "Rock_Stone_Brick"
    },
    {
      "x": -16,
      "y": 8,
      "z": -1,
      "name": "Rock_Stone_Brick_Stairs",
      "rotation": 10
    },
    {
      "x": -16,
      "y": 9,
      "z": -1,
      "name": "Rock_Stone_Brick"
    },
    {
      "x": -16,
      "y": 2,
      "z": 0,
      "name": "Rock_Stone"
    },
    {
      "x": -16,
      "y": 5,
      "z": 0,
      "name": "Rock_Stone_Brick"
    },
    {
      "x": -16,
      "y": 9,
      "z": 0,
      "name": "Rock_Stone_Brick_Smooth"
    },
    {
      "x": -16,
      "y": 2,
      "z": 1,
      "name": "Rock_Stone"
    },
    {
      "x": -16,
      "y": 5,
      "z": 1,
      "name": "Rock_Stone_Brick"
    },
    {
      "x": -16,
      "y": 8,
      "z": 1,
      "name": "Rock_Stone_Brick_Stairs",
      "rotation": 8
    },
    {
      "x": -16,
      "y": 9,
      "z": 1,
      "name": "Rock_Stone_Brick"
    },
    {
      "x": -16,
      "y": 2,
      "z": 2,
      "name": "Rock_Stone"
    },
    {
      "x": -16,
      "y": 3,
      "z": 2,
      "name": "Rock_Stone_Brick"
    },
    {
      "x": -16,
      "y": 4,
      "z": 2,
      "name": "Rock_Stone_Brick"
    },
    {
      "x": -16,
      "y": 5,
      "z": 2,
      "name": "Rock_Stone_Brick"
    },
    {
      "x": -16,
      "y": 6,
      "z": 2,
      "name": "Rock_Stone_Brick"
    },
    {
      "x": -16,
      "y": 7,
      "z": 2,
      "name": "Rock_Stone_Brick"
    },
    {
      "x": -16,
      "y": 8,
      "z": 2,
      "name": "Rock_Stone_Brick"
    },
    {
      "x": -15,
      "y": 2,
      "z": -2,
      "name": "Rock_Stone"
    },
    {
      "x": -15,
      "y": 3,
      "z": -2,
      "name": "Rock_Stone_Brick"
    },
    {
      "x": -15,
      "y": 4,
      "z": -2,
      "name": "Rock_Stone_Brick"
    },
    {
      "x": -15,
      "y": 5,
      "z": -2,
      "name": "Rock_Stone_Brick"
    },
    {
      "x": -15,
      "y": 6,
      "z": -2,
      "name": "Rock_Stone_Brick"
    },
    {
      "x": -15,
      "y": 7,
      "z": -2,
      "name": "Rock_Stone_Brick"
    },
    {
      "x": -15,
      "y": 8,
      "z": -2,
      "name": "Rock_Stone_Brick"
    },
    {
      "x": -15,
      "y": 2,
      "z": -1,
      "name": "Rock_Stone"
    },
    {
      "x": -15,
      "y": 3,
      "z": -1,
      "name": "Rock_Stone_Brick"
    },
    {
      "x": -15,
      "y": 4,
      "z": -1,
      "name": "Rock_Stone_Brick"
    },
    {
      "x": -15,
      "y": 5,
      "z": -1,
      "name": "Rock_Stone_Brick"
    },
    {
      "x": -15,
      "y": 8,
      "z": -1,
      "name": "Rock_Stone_Brick_Stairs",
      "rotation": 10
    },
    {
      "x": -15,
      "y": 9,
      "z": -1,
      "name": "Rock_Stone_Brick"
    },
    {
      "x": -15,
      "y": 2,
      "z": 0,
      "name": "Rock_Stone"
    },
    {
      "x": -15,
      "y": 3,
      "z": 0,
      "name": "Rock_Stone_Brick"
    },
    {
      "x": -15,
      "y": 4,
      "z": 0,
      "name": "Rock_Stone_Brick"
    },
    {
      "x": -15,
      "y": 5,
      "z": 0,
      "name": "Rock_Stone_Brick"
    },
    {
      "x": -15,
      "y": 9,
      "z": 0,
      "name": "Rock_Stone_Brick_Smooth"
    },
    {
      "x": -15,
      "y": 2,
      "z": 1,
      "name": "Rock_Stone"
    },
    {
      "x": -15,
      "y": 3,
      "z": 1,
      "name": "Rock_Stone_Brick"
    },
    {
      "x": -15,
      "y": 4,
      "z": 1,
      "name": "Rock_Stone_Brick"
    },
    {
      "x": -15,
      "y": 5,
      "z": 1,
      "name": "Rock_Stone_Brick"
    },
    {
      "x": -15,
      "y": 8,
      "z": 1,
      "name": "Rock_Stone_Brick_Stairs",
      "rotation": 8
    },
    {
      "x": -15,
      "y": 9,
      "z": 1,
      "name": "Rock_Stone_Brick"
    },
    {
      "x": -15,
      "y": 2,
      "z": 2,
      "name": "Rock_Stone"
    },
    {
      "x": -15,
      "y": 3,
      "z": 2,
      "name": "Rock_Stone_Brick"
    },
    {
      "x": -15,
      "y": 4,
      "z": 2,
      "name": "Rock_Stone_Brick"
    },
    {
      "x": -15,
      "y": 5,
      "z": 2,
      "name": "Rock_Stone_Brick"
    },
    {
      "x": -15,
      "y": 6,
      "z": 2,
      "name": "Rock_Stone_Brick"
    },
    {
      "x": -15,
      "y": 7,
      "z": 2,
      "name": "Rock_Stone_Brick"
    },
    {
      "x": -15,
      "y": 8,
      "z": 2,
      "name": "Rock_Stone_Brick"
    },
    {
      "x": -14,
      "y": 2,
      "z": -2,
      "name": "Rock_Stone"
    },
    {
      "x": -14,
      "y": 3,
      "z": -2,
      "name": "Rock_Stone_Brick"
    },
    {
      "x": -14,
      "y": 4,
      "z": -2,
      "name": "Rock_Stone_Brick"
    },
    {
      "x": -14,
      "y": 5,
      "z": -2,
      "name": "Rock_Stone_Brick"
    },
    {
      "x": -14,
      "y": 6,
      "z": -2,
      "name": "Rock_Stone_Brick"
    },
    {
      "x": -14,
      "y": 7,
      "z": -2,
      "name": "Rock_Stone_Brick"
    },
    {
      "x": -14,
      "y": 8,
      "z": -2,
      "name": "Rock_Stone_Brick"
    },
    {
      "x": -14,
      "y": 2,
      "z": -1,
      "name": "Rock_Stone"
    },
    {
      "x": -14,
      "y": 8,
      "z": -1,
      "name": "Rock_Stone_Brick_Stairs",
      "rotation": 10
    },
    {
      "x": -14,
      "y": 9,
      "z": -1,
      "name": "Rock_Stone_Brick"
    },
    {
      "x": -14,
      "y": 2,
      "z": 0,
      "name": "Rock_Stone"
    },
    {
      "x": -14,
      "y": 9,
      "z": 0,
      "name": "Rock_Stone_Brick_Smooth"
    },
    {
      "x": -14,
      "y": 2,
      "z": 1,
      "name": "Rock_Stone"
    },
    {
      "x": -14,
      "y": 8,
      "z": 1,
      "name": "Rock_Stone_Brick_Stairs",
      "rotation": 8
    },
    {
      "x": -14,
      "y": 9,
      "z": 1,
      "name": "Rock_Stone_Brick"
    },
    {
      "x": -14,
      "y": 2,
      "z": 2,
      "name": "Rock_Stone"
    },
    {
      "x": -14,
      "y": 3,
      "z": 2,
      "name": "Rock_Stone_Brick"
    },
    {
      "x": -14,
      "y": 4,
      "z": 2,
      "name": "Rock_Stone_Brick"
    },
    {
      "x": -14,
      "y": 5,
      "z": 2,
      "name": "Rock_Stone_Brick"
    },
    {
      "x": -14,
      "y": 6,
      "z": 2,
      "name": "Rock_Stone_Brick"
    },
    {
      "x": -14,
      "y": 7,
      "z": 2,
      "name": "Rock_Stone_Brick"
    },
    {
      "x": -14,
      "y": 8,
      "z": 2,
      "name": "Rock_Stone_Brick"
    },
    {
      "x": -13,
      "y": 10,
      "z": -6,
      "name": "Rock_Stone_Brick_Decorative"
    },
    {
      "x": -13,
      "y": 11,
      "z": -6,
      "name": "Soil_Gravel",
      "support": 15
    },
    {
      "x": -13,
      "y": 12,
      "z": -6,
      "name": "Soil_Gravel",
      "support": 15
    },
    {
      "x": -13,
      "y": 13,
      "z": -6,
      "name": "Soil_Gravel",
      "support": 15
    },
    {
      "x": -13,
      "y": 14,
      "z": -6,
      "name": "Soil_Gravel",
      "support": 15
    },
    {
      "x": -13,
      "y": 2,
      "z": -2,
      "name": "Rock_Stone"
    },
    {
      "x": -13,
      "y": 3,
      "z": -2,
      "name": "Rock_Stone_Brick"
    },
    {
      "x": -13,
      "y": 4,
      "z": -2,
      "name": "Rock_Stone_Brick"
    },
    {
      "x": -13,
      "y": 5,
      "z": -2,
      "name": "Rock_Stone_Brick"
    },
    {
      "x": -13,
      "y": 6,
      "z": -2,
      "name": "Rock_Stone_Brick"
    },
    {
      "x": -13,
      "y": 7,
      "z": -2,
      "name": "Rock_Stone_Brick"
    },
    {
      "x": -13,
      "y": 8,
      "z": -2,
      "name": "Rock_Stone_Brick"
    },
    {
      "x": -13,
      "y": 10,
      "z": -2,
      "name": "Rock_Stone_Brick_Decorative"
    },
    {
      "x": -13,
      "y": 11,
      "z": -2,
      "name": "Soil_Gravel",
      "support": 15
    },
    {
      "x": -13,
      "y": 12,
      "z": -2,
      "name": "Soil_Gravel",
      "support": 15
    },
    {
      "x": -13,
      "y": 13,
      "z": -2,
      "name": "Soil_Gravel",
      "support": 15
    },
    {
      "x": -13,
      "y": 14,
      "z": -2,
      "name": "Soil_Gravel",
      "support": 15
    },
    {
      "x": -13,
      "y": 2,
      "z": -1,
      "name": "Rock_Stone"
    },
    {
      "x": -13,
      "y": 8,
      "z": -1,
      "name": "Rock_Stone_Brick_Stairs",
      "rotation": 10
    },
    {
      "x": -13,
      "y": 9,
      "z": -1,
      "name": "Rock_Stone_Brick"
    },
    {
      "x": -13,
      "y": 2,
      "z": 0,
      "name": "Rock_Stone"
    },
    {
      "x": -13,
      "y": 9,
      "z": 0,
      "name": "Rock_Stone_Brick_Smooth"
    },
    {
      "x": -13,
      "y": 2,
      "z": 1,
      "name": "Rock_Stone"
    },
    {
      "x": -13,
      "y": 8,
      "z": 1,
      "name": "Rock_Stone_Brick_Stairs",
      "rotation": 8
    },
    {
      "x": -13,
      "y": 9,
      "z": 1,
      "name": "Rock_Stone_Brick"
    },
    {
      "x": -13,
      "y": 2,
      "z": 2,
      "name": "Rock_Stone"
    },
    {
      "x": -13,
      "y": 3,
      "z": 2,
      "name": "Rock_Stone_Brick"
    },
    {
      "x": -13,
      "y": 4,
      "z": 2,
      "name": "Rock_Stone_Brick"
    },
    {
      "x": -13,
      "y": 5,
      "z": 2,
      "name": "Rock_Stone_Brick"
    },
    {
      "x": -13,
      "y": 6,
      "z": 2,
      "name": "Rock_Stone_Brick"
    },
    {
      "x": -13,
      "y": 7,
      "z": 2,
      "name": "Rock_Stone_Brick"
    },
    {
      "x": -13,
      "y": 8,
      "z": 2,
      "name": "Rock_Stone_Brick"
    },
    {
      "x": -13,
      "y": 10,
      "z": 2,
      "name": "Rock_Stone_Brick_Decorative"
    },
    {
      "x": -13,
      "y": 11,
      "z": 2,
      "name": "Soil_Gravel",
      "support": 15
    },
    {
      "x": -13,
      "y": 12,
      "z": 2,
      "name": "Soil_Gravel",
      "support": 15
    },
    {
      "x": -13,
      "y": 13,
      "z": 2,
      "name": "Soil_Gravel",
      "support": 15
    },
    {
      "x": -13,
      "y": 14,
      "z": 2,
      "name": "Soil_Gravel",
      "support": 15
    },
    {
      "x": -13,
      "y": 10,
      "z": 6,
      "name": "Rock_Stone_Brick_Decorative"
    },
    {
      "x": -13,
      "y": 11,
      "z": 6,
      "name": "Soil_Gravel",
      "support": 15
    },
    {
      "x": -13,
      "y": 12,
      "z": 6,
      "name": "Soil_Gravel",
      "support": 15
    },
    {
      "x": -13,
      "y": 13,
      "z": 6,
      "name": "Soil_Gravel",
      "support": 15
    },
    {
      "x": -13,
      "y": 14,
      "z": 6,
      "name": "Soil_Gravel",
      "support": 15
    },
    {
      "x": -12,
      "y": 10,
      "z": -11,
      "name": "Rock_Stone_Brick_Decorative"
    },
    {
      "x": -12,
      "y": 11,
      "z": -11,
      "name": "Rock_Stone_Brick"
    },
    {
      "x": -12,
      "y": 12,
      "z": -11,
      "name": "Rock_Stone_Brick"
    },
    {
      "x": -12,
      "y": 13,
      "z": -11,
      "name": "Rock_Stone_Brick"
    },
    {
      "x": -12,
      "y": 14,
      "z": -11,
      "name": "Rock_Stone_Brick"
    },
    {
      "x": -12,
      "y": 15,
      "z": -11,
      "name": "Rock_Stone_Brick_Smooth"
    },
    {
      "x": -12,
      "y": 10,
      "z": -10,
      "name": "Rock_Stone_Brick_Decorative"
    },
    {
      "x": -12,
      "y": 11,
      "z": -10,
      "name": "Soil_Gravel_Half",
      "support": 15,
      "rotation": 5
    },
    {
      "x": -12,
      "y": 12,
      "z": -10,
      "name": "Soil_Gravel_Half",
      "support": 15,
      "rotation": 5
    },
    {
      "x": -12,
      "y": 13,
      "z": -10,
      "name": "Soil_Gravel_Half",
      "support": 15,
      "rotation": 5
    },
    {
      "x": -12,
      "y": 14,
      "z": -10,
      "name": "Soil_Gravel_Half",
      "support": 15,
      "rotation": 5
    },
    {
      "x": -12,
      "y": 15,
      "z": -10,
      "name": "Rock_Stone_Brick"
    },
    {
      "x": -12,
      "y": 10,
      "z": -9,
      "name": "Rock_Stone_Brick_Decorative"
    },
    {
      "x": -12,
      "y": 11,
      "z": -9,
      "name": "Soil_Gravel_Half",
      "support": 15,
      "rotation": 5
    },
    {
      "x": -12,
      "y": 12,
      "z": -9,
      "name": "Soil_Gravel_Half",
      "support": 15,
      "rotation": 5
    },
    {
      "x": -12,
      "y": 13,
      "z": -9,
      "name": "Soil_Gravel_Half",
      "support": 15,
      "rotation": 5
    },
    {
      "x": -12,
      "y": 14,
      "z": -9,
      "name": "Soil_Gravel_Half",
      "support": 15,
      "rotation": 5
    },
    {
      "x": -12,
      "y": 15,
      "z": -9,
      "name": "Rock_Stone_Brick"
    },
    {
      "x": -12,
      "y": 10,
      "z": -8,
      "name": "Rock_Stone_Brick_Decorative"
    },
    {
      "x": -12,
      "y": 11,
      "z": -8,
      "name": "Soil_Gravel_Half",
      "support": 15,
      "rotation": 5
    },
    {
      "x": -12,
      "y": 12,
      "z": -8,
      "name": "Soil_Gravel_Half",
      "support": 15,
      "rotation": 5
    },
    {
      "x": -12,
      "y": 13,
      "z": -8,
      "name": "Soil_Gravel_Half",
      "support": 15,
      "rotation": 5
    },
    {
      "x": -12,
      "y": 14,
      "z": -8,
      "name": "Soil_Gravel_Half",
      "support": 15,
      "rotation": 5
    },
    {
      "x": -12,
      "y": 15,
      "z": -8,
      "name": "Rock_Stone_Brick"
    },
    {
      "x": -12,
      "y": 9,
      "z": -7,
      "name": "Rock_Stone_Brick_Smooth"
    },
    {
      "x": -12,
      "y": 10,
      "z": -7,
      "name": "Rock_Stone_Brick_Decorative"
    },
    {
      "x": -12,
      "y": 11,
      "z": -7,
      "name": "Soil_Gravel_Half",
      "support": 15,
      "rotation": 5
    },
    {
      "x": -12,
      "y": 12,
      "z": -7,
      "name": "Soil_Gravel_Half",
      "support": 15,
      "rotation": 5
    },
    {
      "x": -12,
      "y": 13,
      "z": -7,
      "name": "Soil_Gravel_Half",
      "support": 15,
      "rotation": 5
    },
    {
      "x": -12,
      "y": 14,
      "z": -7,
      "name": "Soil_Gravel_Half",
      "support": 15,
      "rotation": 5
    },
    {
      "x": -12,
      "y": 15,
      "z": -7,
      "name": "Rock_Stone_Brick"
    },
    {
      "x": -12,
      "y": 9,
      "z": -6,
      "name": "Rock_Stone_Brick_Smooth"
    },
    {
      "x": -12,
      "y": 10,
      "z": -6,
      "name": "Rock_Stone_Brick_Smooth"
    },
    {
      "x": -12,
      "y": 11,
      "z": -6,
      "name": "Rock_Stone_Brick_Pillar_Base"
    },
    {
      "x": -12,
      "y": 12,
      "z": -6,
      "name": "Rock_Stone_Brick_Pillar_Middle"
    },
    {
      "x": -12,
      "y": 13,
      "z": -6,
      "name": "Rock_Stone_Brick_Pillar_Middle"
    },
    {
      "x": -12,
      "y": 14,
      "z": -6,
      "name": "Rock_Stone_Brick_Pillar_Base",
      "rotation": 8
    },
    {
      "x": -12,
      "y": 15,
      "z": -6,
      "name": "Rock_Stone_Brick"
    },
    {
      "x": -12,
      "y": 9,
      "z": -5,
      "name": "Rock_Stone_Brick_Smooth"
    },
    {
      "x": -12,
      "y": 10,
      "z": -5,
      "name": "Rock_Stone_Brick_Decorative"
    },
    {
      "x": -12,
      "y": 11,
      "z": -5,
      "name": "Soil_Gravel_Half",
      "support": 15,
      "rotation": 5
    },
    {
      "x": -12,
      "y": 12,
      "z": -5,
      "name": "Soil_Gravel_Half",
      "support": 15,
      "rotation": 5
    },
    {
      "x": -12,
      "y": 13,
      "z": -5,
      "name": "Soil_Gravel_Half",
      "support": 15,
      "rotation": 5
    },
    {
      "x": -12,
      "y": 14,
      "z": -5,
      "name": "Soil_Gravel_Half",
      "support": 15,
      "rotation": 5
    },
    {
      "x": -12,
      "y": 15,
      "z": -5,
      "name": "Rock_Stone_Brick"
    },
    {
      "x": -12,
      "y": 9,
      "z": -4,
      "name": "Rock_Stone_Brick_Smooth"
    },
    {
      "x": -12,
      "y": 10,
      "z": -4,
      "name": "Rock_Stone_Brick_Decorative"
    },
    {
      "x": -12,
      "y": 11,
      "z": -4,
      "name": "Soil_Gravel_Half",
      "support": 15,
      "rotation": 5
    },
    {
      "x": -12,
      "y": 12,
      "z": -4,
      "name": "Soil_Gravel_Half",
      "support": 15,
      "rotation": 5
    },
    {
      "x": -12,
      "y": 13,
      "z": -4,
      "name": "Soil_Gravel_Half",
      "support": 15,
      "rotation": 5
    },
    {
      "x": -12,
      "y": 14,
      "z": -4,
      "name": "Soil_Gravel_Half",
      "support": 15,
      "rotation": 5
    },
    {
      "x": -12,
      "y": 15,
      "z": -4,
      "name": "Rock_Stone_Brick"
    },
    {
      "x": -12,
      "y": 9,
      "z": -3,
      "name": "Rock_Stone_Brick_Smooth"
    },
    {
      "x": -12,
      "y": 10,
      "z": -3,
      "name": "Rock_Stone_Brick_Decorative"
    },
    {
      "x": -12,
      "y": 11,
      "z": -3,
      "name": "Soil_Gravel_Half",
      "support": 15,
      "rotation": 5
    },
    {
      "x": -12,
      "y": 12,
      "z": -3,
      "name": "Soil_Gravel_Half",
      "support": 15,
      "rotation": 5
    },
    {
      "x": -12,
      "y": 13,
      "z": -3,
      "name": "Soil_Gravel_Half",
      "support": 15,
      "rotation": 5
    },
    {
      "x": -12,
      "y": 14,
      "z": -3,
      "name": "Soil_Gravel_Half",
      "support": 15,
      "rotation": 5
    },
    {
      "x": -12,
      "y": 15,
      "z": -3,
      "name": "Rock_Stone_Brick"
    },
    {
      "x": -12,
      "y": 2,
      "z": -2,
      "name": "Rock_Stone"
    },
    {
      "x": -12,
      "y": 3,
      "z": -2,
      "name": "Rock_Stone_Brick"
    },
    {
      "x": -12,
      "y": 4,
      "z": -2,
      "name": "Rock_Stone_Brick"
    },
    {
      "x": -12,
      "y": 5,
      "z": -2,
      "name": "Rock_Stone_Brick"
    },
    {
      "x": -12,
      "y": 6,
      "z": -2,
      "name": "Rock_Stone_Brick"
    },
    {
      "x": -12,
      "y": 7,
      "z": -2,
      "name": "Rock_Stone_Brick"
    },
    {
      "x": -12,
      "y": 8,
      "z": -2,
      "name": "Rock_Stone_Brick"
    },
    {
      "x": -12,
      "y": 9,
      "z": -2,
      "name": "Rock_Stone_Brick_Smooth"
    },
    {
      "x": -12,
      "y": 10,
      "z": -2,
      "name": "Rock_Stone_Brick_Smooth"
    },
    {
      "x": -12,
      "y": 11,
      "z": -2,
      "name": "Rock_Stone_Brick_Pillar_Base"
    },
    {
      "x": -12,
      "y": 12,
      "z": -2,
      "name": "Rock_Stone_Brick_Pillar_Middle"
    },
    {
      "x": -12,
      "y": 13,
      "z": -2,
      "name": "Rock_Stone_Brick_Pillar_Middle"
    },
    {
      "x": -12,
      "y": 14,
      "z": -2,
      "name": "Rock_Stone_Brick_Pillar_Base",
      "rotation": 8
    },
    {
      "x": -12,
      "y": 15,
      "z": -2,
      "name": "Rock_Stone_Brick"
    },
    {
      "x": -12,
      "y": 2,
      "z": -1,
      "name": "Rock_Stone"
    },
    {
      "x": -12,
      "y": 8,
      "z": -1,
      "name": "Rock_Stone_Brick_Stairs",
      "rotation": 10
    },
    {
      "x": -12,
      "y": 9,
      "z": -1,
      "name": "Rock_Stone_Brick_Smooth"
    },
    {
      "x": -12,
      "y": 10,
      "z": -1,
      "name": "Rock_Stone_Brick_Decorative"
    },
    {
      "x": -12,
      "y": 11,
      "z": -1,
      "name": "Soil_Gravel_Half",
      "support": 15,
      "rotation": 5
    },
    {
      "x": -12,
      "y": 12,
      "z": -1,
      "name": "Soil_Gravel_Half",
      "support": 15,
      "rotation": 5
    },
    {
      "x": -12,
      "y": 13,
      "z": -1,
      "name": "Soil_Gravel_Half",
      "support": 15,
      "rotation": 5
    },
    {
      "x": -12,
      "y": 14,
      "z": -1,
      "name": "Soil_Gravel_Half",
      "support": 15,
      "rotation": 5
    },
    {
      "x": -12,
      "y": 15,
      "z": -1,
      "name": "Rock_Stone_Brick"
    },
    {
      "x": -12,
      "y": 2,
      "z": 0,
      "name": "Rock_Stone"
    },
    {
      "x": -12,
      "y": 9,
      "z": 0,
      "name": "Rock_Stone_Brick_Smooth"
    },
    {
      "x": -12,
      "y": 10,
      "z": 0,
      "name": "Rock_Stone_Brick_Decorative"
    },
    {
      "x": -12,
      "y": 11,
      "z": 0,
      "name": "Soil_Gravel_Half",
      "support": 15,
      "rotation": 5
    },
    {
      "x": -12,
      "y": 12,
      "z": 0,
      "name": "Soil_Gravel_Half",
      "support": 15,
      "rotation": 5
    },
    {
      "x": -12,
      "y": 13,
      "z": 0,
      "name": "Soil_Gravel_Half",
      "support": 15,
      "rotation": 5
    },
    {
      "x": -12,
      "y": 14,
      "z": 0,
      "name": "Soil_Gravel_Half",
      "support": 15,
      "rotation": 5
    },
    {
      "x": -12,
      "y": 15,
      "z": 0,
      "name": "Rock_Stone_Brick"
    },
    {
      "x": -12,
      "y": 2,
      "z": 1,
      "name": "Rock_Stone"
    },
    {
      "x": -12,
      "y": 8,
      "z": 1,
      "name": "Rock_Stone_Brick_Stairs",
      "rotation": 8
    },
    {
      "x": -12,
      "y": 9,
      "z": 1,
      "name": "Rock_Stone_Brick_Smooth"
    },
    {
      "x": -12,
      "y": 10,
      "z": 1,
      "name": "Rock_Stone_Brick_Decorative"
    },
    {
      "x": -12,
      "y": 11,
      "z": 1,
      "name": "Soil_Gravel_Half",
      "support": 15,
      "rotation": 5
    },
    {
      "x": -12,
      "y": 12,
      "z": 1,
      "name": "Soil_Gravel_Half",
      "support": 15,
      "rotation": 5
    },
    {
      "x": -12,
      "y": 13,
      "z": 1,
      "name": "Soil_Gravel_Half",
      "support": 15,
      "rotation": 5
    },
    {
      "x": -12,
      "y": 14,
      "z": 1,
      "name": "Soil_Gravel_Half",
      "support": 15,
      "rotation": 5
    },
    {
      "x": -12,
      "y": 15,
      "z": 1,
      "name": "Rock_Stone_Brick"
    },
    {
      "x": -12,
      "y": 2,
      "z": 2,
      "name": "Rock_Stone"
    },
    {
      "x": -12,
      "y": 3,
      "z": 2,
      "name": "Rock_Stone_Brick"
    },
    {
      "x": -12,
      "y": 4,
      "z": 2,
      "name": "Rock_Stone_Brick"
    },
    {
      "x": -12,
      "y": 5,
      "z": 2,
      "name": "Rock_Stone_Brick"
    },
    {
      "x": -12,
      "y": 6,
      "z": 2,
      "name": "Rock_Stone_Brick"
    },
    {
      "x": -12,
      "y": 7,
      "z": 2,
      "name": "Rock_Stone_Brick"
    },
    {
      "x": -12,
      "y": 8,
      "z": 2,
      "name": "Rock_Stone_Brick"
    },
    {
      "x": -12,
      "y": 9,
      "z": 2,
      "name": "Rock_Stone_Brick_Smooth"
    },
    {
      "x": -12,
      "y": 10,
      "z": 2,
      "name": "Rock_Stone_Brick_Smooth"
    },
    {
      "x": -12,
      "y": 11,
      "z": 2,
      "name": "Rock_Stone_Brick_Pillar_Base"
    },
    {
      "x": -12,
      "y": 12,
      "z": 2,
      "name": "Rock_Stone_Brick_Pillar_Middle"
    },
    {
      "x": -12,
      "y": 13,
      "z": 2,
      "name": "Rock_Stone_Brick_Pillar_Middle"
    },
    {
      "x": -12,
      "y": 14,
      "z": 2,
      "name": "Rock_Stone_Brick_Pillar_Base",
      "rotation": 8
    },
    {
      "x": -12,
      "y": 15,
      "z": 2,
      "name": "Rock_Stone_Brick"
    },
    {
      "x": -12,
      "y": 10,
      "z": 3,
      "name": "Rock_Stone_Brick_Decorative"
    },
    {
      "x": -12,
      "y": 11,
      "z": 3,
      "name": "Soil_Gravel_Half",
      "support": 15,
      "rotation": 5
    },
    {
      "x": -12,
      "y": 12,
      "z": 3,
      "name": "Soil_Gravel_Half",
      "support": 15,
      "rotation": 5
    },
    {
      "x": -12,
      "y": 13,
      "z": 3,
      "name": "Soil_Gravel_Half",
      "support": 15,
      "rotation": 5
    },
    {
      "x": -12,
      "y": 14,
      "z": 3,
      "name": "Soil_Gravel_Half",
      "support": 15,
      "rotation": 5
    },
    {
      "x": -12,
      "y": 15,
      "z": 3,
      "name": "Rock_Stone_Brick"
    },
    {
      "x": -12,
      "y": 10,
      "z": 4,
      "name": "Rock_Stone_Brick_Decorative"
    },
    {
      "x": -12,
      "y": 11,
      "z": 4,
      "name": "Soil_Gravel_Half",
      "support": 15,
      "rotation": 5
    },
    {
      "x": -12,
      "y": 12,
      "z": 4,
      "name": "Soil_Gravel_Half",
      "support": 15,
      "rotation": 5
    },
    {
      "x": -12,
      "y": 13,
      "z": 4,
      "name": "Soil_Gravel_Half",
      "support": 15,
      "rotation": 5
    },
    {
      "x": -12,
      "y": 14,
      "z": 4,
      "name": "Soil_Gravel_Half",
      "support": 15,
      "rotation": 5
    },
    {
      "x": -12,
      "y": 15,
      "z": 4,
      "name": "Rock_Stone_Brick"
    },
    {
      "x": -12,
      "y": 10,
      "z": 5,
      "name": "Rock_Stone_Brick_Decorative"
    },
    {
      "x": -12,
      "y": 11,
      "z": 5,
      "name": "Soil_Gravel_Half",
      "support": 15,
      "rotation": 5
    },
    {
      "x": -12,
      "y": 12,
      "z": 5,
      "name": "Soil_Gravel_Half",
      "support": 15,
      "rotation": 5
    },
    {
      "x": -12,
      "y": 13,
      "z": 5,
      "name": "Soil_Gravel_Half",
      "support": 15,
      "rotation": 5
    },
    {
      "x": -12,
      "y": 14,
      "z": 5,
      "name": "Soil_Gravel_Half",
      "support": 15,
      "rotation": 5
    },
    {
      "x": -12,
      "y": 15,
      "z": 5,
      "name": "Rock_Stone_Brick"
    },
    {
      "x": -12,
      "y": 10,
      "z": 6,
      "name": "Rock_Stone_Brick_Smooth"
    },
    {
      "x": -12,
      "y": 11,
      "z": 6,
      "name": "Rock_Stone_Brick_Pillar_Base"
    },
    {
      "x": -12,
      "y": 12,
      "z": 6,
      "name": "Rock_Stone_Brick_Pillar_Middle"
    },
    {
      "x": -12,
      "y": 13,
      "z": 6,
      "name": "Rock_Stone_Brick_Pillar_Middle"
    },
    {
      "x": -12,
      "y": 14,
      "z": 6,
      "name": "Rock_Stone_Brick_Pillar_Base",
      "rotation": 8
    },
    {
      "x": -12,
      "y": 15,
      "z": 6,
      "name": "Rock_Stone_Brick"
    },
    {
      "x": -12,
      "y": 10,
      "z": 7,
      "name": "Rock_Stone_Brick_Decorative"
    },
    {
      "x": -12,
      "y": 11,
      "z": 7,
      "name": "Soil_Gravel_Half",
      "support": 15,
      "rotation": 5
    },
    {
      "x": -12,
      "y": 12,
      "z": 7,
      "name": "Soil_Gravel_Half",
      "support": 15,
      "rotation": 5
    },
    {
      "x": -12,
      "y": 13,
      "z": 7,
      "name": "Soil_Gravel_Half",
      "support": 15,
      "rotation": 5
    },
    {
      "x": -12,
      "y": 14,
      "z": 7,
      "name": "Soil_Gravel_Half",
      "support": 15,
      "rotation": 5
    },
    {
      "x": -12,
      "y": 15,
      "z": 7,
      "name": "Rock_Stone_Brick"
    },
    {
      "x": -12,
      "y": 10,
      "z": 8,
      "name": "Rock_Stone_Brick_Decorative"
    },
    {
      "x": -12,
      "y": 11,
      "z": 8,
      "name": "Rock_Stone_Brick"
    },
    {
      "x": -12,
      "y": 12,
      "z": 8,
      "name": "Rock_Stone_Brick"
    },
    {
      "x": -12,
      "y": 13,
      "z": 8,
      "name": "Rock_Stone_Brick"
    },
    {
      "x": -12,
      "y": 14,
      "z": 8,
      "name": "Rock_Stone_Brick"
    },
    {
      "x": -12,
      "y": 15,
      "z": 8,
      "name": "Rock_Stone_Brick"
    },
    {
      "x": -11,
      "y": 10,
      "z": -11,
      "name": "Rock_Stone_Brick_Decorative"
    },
    {
      "x": -11,
      "y": 11,
      "z": -11,
      "name": "Soil_Gravel_Half",
      "support": 15,
      "rotation": 4
    },
    {
      "x": -11,
      "y": 12,
      "z": -11,
      "name": "Soil_Gravel_Half",
      "support": 15,
      "rotation": 4
    },
    {
      "x": -11,
      "y": 13,
      "z": -11,
      "name": "Soil_Gravel_Half",
      "support": 15,
      "rotation": 4
    },
    {
      "x": -11,
      "y": 14,
      "z": -11,
      "name": "Soil_Gravel_Half",
      "support": 15,
      "rotation": 4
    },
    {
      "x": -11,
      "y": 15,
      "z": -11,
      "name": "Rock_Stone_Brick"
    },
    {
      "x": -11,
      "y": 9,
      "z": -10,
      "name": "Rock_Stone_Brick_Smooth"
    },
    {
      "x": -11,
      "y": 15,
      "z": -10,
      "name": "Rock_Stone_Brick_Smooth"
    },
    {
      "x": -11,
      "y": 9,
      "z": -9,
      "name": "Rock_Stone_Brick_Smooth"
    },
    {
      "x": -11,
      "y": 15,
      "z": -9,
      "name": "Rock_Stone_Brick_Smooth"
    },
    {
      "x": -11,
      "y": 9,
      "z": -8,
      "name": "Rock_Stone_Brick_Smooth"
    },
    {
      "x": -11,
      "y": 15,
      "z": -8,
      "name": "Rock_Stone_Brick_Smooth"
    },
    {
      "x": -11,
      "y": 9,
      "z": -7,
      "name": "Rock_Stone_Brick_Smooth"
    },
    {
      "x": -11,
      "y": 15,
      "z": -7,
      "name": "Rock_Stone_Brick_Smooth"
    },
    {
      "x": -11,
      "y": 9,
      "z": -6,
      "name": "Rock_Stone_Brick_Smooth"
    },
    {
      "x": -11,
      "y": 15,
      "z": -6,
      "name": "Rock_Stone_Brick_Decorative"
    },
    {
      "x": -11,
      "y": 9,
      "z": -5,
      "name": "Rock_Stone_Brick_Smooth"
    },
    {
      "x": -11,
      "y": 15,
      "z": -5,
      "name": "Rock_Stone_Brick_Smooth"
    },
    {
      "x": -11,
      "y": 9,
      "z": -4,
      "name": "Rock_Stone_Brick_Smooth"
    },
    {
      "x": -11,
      "y": 15,
      "z": -4,
      "name": "Rock_Stone_Brick_Smooth"
    },
    {
      "x": -11,
      "y": 9,
      "z": -3,
      "name": "Rock_Stone_Brick_Smooth"
    },
    {
      "x": -11,
      "y": 15,
      "z": -3,
      "name": "Rock_Stone_Brick_Smooth"
    },
    {
      "x": -11,
      "y": 2,
      "z": -2,
      "name": "Rock_Stone"
    },
    {
      "x": -11,
      "y": 3,
      "z": -2,
      "name": "Rock_Stone_Brick"
    },
    {
      "x": -11,
      "y": 4,
      "z": -2,
      "name": "Rock_Stone_Brick"
    },
    {
      "x": -11,
      "y": 5,
      "z": -2,
      "name": "Rock_Stone_Brick"
    },
    {
      "x": -11,
      "y": 6,
      "z": -2,
      "name": "Rock_Stone_Brick"
    },
    {
      "x": -11,
      "y": 7,
      "z": -2,
      "name": "Rock_Stone_Brick"
    },
    {
      "x": -11,
      "y": 8,
      "z": -2,
      "name": "Rock_Stone_Brick"
    },
    {
      "x": -11,
      "y": 9,
      "z": -2,
      "name": "Rock_Stone_Brick_Smooth"
    },
    {
      "x": -11,
      "y": 15,
      "z": -2,
      "name": "Rock_Stone_Brick_Smooth"
    },
    {
      "x": -11,
      "y": 2,
      "z": -1,
      "name": "Rock_Stone"
    },
    {
      "x": -11,
      "y": 8,
      "z": -1,
      "name": "Rock_Stone_Brick_Stairs",
      "rotation": 10
    },
    {
      "x": -11,
      "y": 9,
      "z": -1,
      "name": "Rock_Stone_Brick_Smooth"
    },
    {
      "x": -11,
      "y": 15,
      "z": -1,
      "name": "Rock_Stone_Brick_Smooth"
    },
    {
      "x": -11,
      "y": 2,
      "z": 0,
      "name": "Rock_Stone"
    },
    {
      "x": -11,
      "y": 9,
      "z": 0,
      "name": "Rock_Stone_Brick_Smooth"
    },
    {
      "x": -11,
      "y": 15,
      "z": 0,
      "name": "Rock_Stone_Brick_Smooth"
    },
    {
      "x": -11,
      "y": 2,
      "z": 1,
      "name": "Rock_Stone"
    },
    {
      "x": -11,
      "y": 8,
      "z": 1,
      "name": "Rock_Stone_Brick_Stairs",
      "rotation": 8
    },
    {
      "x": -11,
      "y": 9,
      "z": 1,
      "name": "Rock_Stone_Brick_Smooth"
    },
    {
      "x": -11,
      "y": 15,
      "z": 1,
      "name": "Rock_Stone_Brick_Smooth"
    },
    {
      "x": -11,
      "y": 2,
      "z": 2,
      "name": "Rock_Stone"
    },
    {
      "x": -11,
      "y": 3,
      "z": 2,
      "name": "Rock_Stone_Brick"
    },
    {
      "x": -11,
      "y": 4,
      "z": 2,
      "name": "Rock_Stone_Brick"
    },
    {
      "x": -11,
      "y": 5,
      "z": 2,
      "name": "Rock_Stone_Brick"
    },
    {
      "x": -11,
      "y": 6,
      "z": 2,
      "name": "Rock_Stone_Brick"
    },
    {
      "x": -11,
      "y": 7,
      "z": 2,
      "name": "Rock_Stone_Brick"
    },
    {
      "x": -11,
      "y": 8,
      "z": 2,
      "name": "Rock_Stone_Brick"
    },
    {
      "x": -11,
      "y": 9,
      "z": 2,
      "name": "Rock_Stone_Brick_Smooth"
    },
    {
      "x": -11,
      "y": 15,
      "z": 2,
      "name": "Rock_Stone_Brick_Smooth"
    },
    {
      "x": -11,
      "y": 9,
      "z": 3,
      "name": "Rock_Stone_Brick_Smooth"
    },
    {
      "x": -11,
      "y": 15,
      "z": 3,
      "name": "Rock_Stone_Brick_Smooth"
    },
    {
      "x": -11,
      "y": 9,
      "z": 4,
      "name": "Rock_Stone_Brick_Smooth"
    },
    {
      "x": -11,
      "y": 15,
      "z": 4,
      "name": "Rock_Stone_Brick_Smooth"
    },
    {
      "x": -11,
      "y": 9,
      "z": 5,
      "name": "Rock_Stone_Brick_Smooth"
    },
    {
      "x": -11,
      "y": 15,
      "z": 5,
      "name": "Rock_Stone_Brick_Smooth"
    },
    {
      "x": -11,
      "y": 9,
      "z": 6,
      "name": "Rock_Stone_Brick_Smooth"
    },
    {
      "x": -11,
      "y": 15,
      "z": 6,
      "name": "Rock_Stone_Brick_Smooth"
    },
    {
      "x": -11,
      "y": 9,
      "z": 7,
      "name": "Rock_Stone_Brick_Smooth"
    },
    {
      "x": -11,
      "y": 15,
      "z": 7,
      "name": "Rock_Stone_Brick_Smooth"
    },
    {
      "x": -11,
      "y": 10,
      "z": 8,
      "name": "Rock_Stone_Brick_Decorative"
    },
    {
      "x": -11,
      "y": 11,
      "z": 8,
      "name": "Soil_Gravel_Half",
      "support": 15,
      "rotation": 6
    },
    {
      "x": -11,
      "y": 12,
      "z": 8,
      "name": "Soil_Gravel_Half",
      "support": 15,
      "rotation": 6
    },
    {
      "x": -11,
      "y": 13,
      "z": 8,
      "name": "Soil_Gravel_Half",
      "support": 15,
      "rotation": 6
    },
    {
      "x": -11,
      "y": 14,
      "z": 8,
      "name": "Soil_Gravel_Half",
      "support": 15,
      "rotation": 6
    },
    {
      "x": -11,
      "y": 15,
      "z": 8,
      "name": "Rock_Stone_Brick"
    },
    {
      "x": -10,
      "y": 10,
      "z": -11,
      "name": "Rock_Stone_Brick_Decorative"
    },
    {
      "x": -10,
      "y": 11,
      "z": -11,
      "name": "Soil_Gravel_Half",
      "support": 15,
      "rotation": 4
    },
    {
      "x": -10,
      "y": 12,
      "z": -11,
      "name": "Soil_Gravel_Half",
      "support": 15,
      "rotation": 4
    },
    {
      "x": -10,
      "y": 13,
      "z": -11,
      "name": "Soil_Gravel_Half",
      "support": 15,
      "rotation": 4
    },
    {
      "x": -10,
      "y": 14,
      "z": -11,
      "name": "Soil_Gravel_Half",
      "support": 15,
      "rotation": 4
    },
    {
      "x": -10,
      "y": 15,
      "z": -11,
      "name": "Rock_Stone_Brick"
    },
    {
      "x": -10,
      "y": 9,
      "z": -10,
      "name": "Rock_Stone_Brick_Smooth"
    },
    {
      "x": -10,
      "y": 15,
      "z": -10,
      "name": "Rock_Stone_Brick_Smooth"
    },
    {
      "x": -10,
      "y": 9,
      "z": -9,
      "name": "Rock_Stone_Brick_Smooth"
    },
    {
      "x": -10,
      "y": 15,
      "z": -9,
      "name": "Rock_Stone_Brick_Smooth"
    },
    {
      "x": -10,
      "y": 9,
      "z": -8,
      "name": "Rock_Stone_Brick_Smooth"
    },
    {
      "x": -10,
      "y": 15,
      "z": -8,
      "name": "Rock_Stone_Brick_Smooth"
    },
    {
      "x": -10,
      "y": 9,
      "z": -7,
      "name": "Rock_Stone_Brick_Smooth"
    },
    {
      "x": -10,
      "y": 15,
      "z": -7,
      "name": "Rock_Stone_Brick_Smooth"
    },
    {
      "x": -10,
      "y": 9,
      "z": -6,
      "name": "Rock_Stone_Brick_Smooth"
    },
    {
      "x": -10,
      "y": 15,
      "z": -6,
      "name": "Rock_Stone_Brick_Decorative"
    },
    {
      "x": -10,
      "y": 9,
      "z": -5,
      "name": "Rock_Stone_Brick_Smooth"
    },
    {
      "x": -10,
      "y": 15,
      "z": -5,
      "name": "Rock_Stone_Brick_Smooth"
    },
    {
      "x": -10,
      "y": 9,
      "z": -4,
      "name": "Rock_Stone_Brick_Smooth"
    },
    {
      "x": -10,
      "y": 15,
      "z": -4,
      "name": "Rock_Stone_Brick_Smooth"
    },
    {
      "x": -10,
      "y": 9,
      "z": -3,
      "name": "Rock_Stone_Brick_Smooth"
    },
    {
      "x": -10,
      "y": 15,
      "z": -3,
      "name": "Rock_Stone_Brick_Smooth"
    },
    {
      "x": -10,
      "y": 2,
      "z": -2,
      "name": "Rock_Stone"
    },
    {
      "x": -10,
      "y": 3,
      "z": -2,
      "name": "Rock_Stone_Brick"
    },
    {
      "x": -10,
      "y": 4,
      "z": -2,
      "name": "Rock_Stone_Brick"
    },
    {
      "x": -10,
      "y": 5,
      "z": -2,
      "name": "Rock_Stone_Brick"
    },
    {
      "x": -10,
      "y": 6,
      "z": -2,
      "name": "Rock_Stone_Brick"
    },
    {
      "x": -10,
      "y": 7,
      "z": -2,
      "name": "Rock_Stone_Brick"
    },
    {
      "x": -10,
      "y": 8,
      "z": -2,
      "name": "Rock_Stone_Brick"
    },
    {
      "x": -10,
      "y": 9,
      "z": -2,
      "name": "Rock_Stone_Brick_Smooth"
    },
    {
      "x": -10,
      "y": 15,
      "z": -2,
      "name": "Rock_Stone_Brick_Smooth"
    },
    {
      "x": -10,
      "y": 2,
      "z": -1,
      "name": "Rock_Stone"
    },
    {
      "x": -10,
      "y": 8,
      "z": -1,
      "name": "Rock_Stone_Brick_Stairs",
      "rotation": 10
    },
    {
      "x": -10,
      "y": 9,
      "z": -1,
      "name": "Rock_Stone_Brick_Smooth"
    },
    {
      "x": -10,
      "y": 15,
      "z": -1,
      "name": "Rock_Stone_Brick_Smooth"
    },
    {
      "x": -10,
      "y": 2,
      "z": 0,
      "name": "Rock_Stone"
    },
    {
      "x": -10,
      "y": 9,
      "z": 0,
      "name": "Rock_Stone_Brick_Smooth"
    },
    {
      "x": -10,
      "y": 15,
      "z": 0,
      "name": "Rock_Stone_Brick_Smooth"
    },
    {
      "x": -10,
      "y": 2,
      "z": 1,
      "name": "Rock_Stone"
    },
    {
      "x": -10,
      "y": 8,
      "z": 1,
      "name": "Rock_Stone_Brick_Stairs",
      "rotation": 8
    },
    {
      "x": -10,
      "y": 9,
      "z": 1,
      "name": "Rock_Stone_Brick_Smooth"
    },
    {
      "x": -10,
      "y": 15,
      "z": 1,
      "name": "Rock_Stone_Brick_Smooth"
    },
    {
      "x": -10,
      "y": 2,
      "z": 2,
      "name": "Rock_Stone"
    },
    {
      "x": -10,
      "y": 3,
      "z": 2,
      "name": "Rock_Stone_Brick"
    },
    {
      "x": -10,
      "y": 4,
      "z": 2,
      "name": "Rock_Stone_Brick"
    },
    {
      "x": -10,
      "y": 5,
      "z": 2,
      "name": "Rock_Stone_Brick"
    },
    {
      "x": -10,
      "y": 6,
      "z": 2,
      "name": "Rock_Stone_Brick"
    },
    {
      "x": -10,
      "y": 7,
      "z": 2,
      "name": "Rock_Stone_Brick"
    },
    {
      "x": -10,
      "y": 8,
      "z": 2,
      "name": "Rock_Stone_Brick"
    },
    {
      "x": -10,
      "y": 9,
      "z": 2,
      "name": "Rock_Stone_Brick_Smooth"
    },
    {
      "x": -10,
      "y": 15,
      "z": 2,
      "name": "Rock_Stone_Brick_Smooth"
    },
    {
      "x": -10,
      "y": 9,
      "z": 3,
      "name": "Rock_Stone_Brick_Smooth"
    },
    {
      "x": -10,
      "y": 15,
      "z": 3,
      "name": "Rock_Stone_Brick_Smooth"
    },
    {
      "x": -10,
      "y": 9,
      "z": 4,
      "name": "Rock_Stone_Brick_Smooth"
    },
    {
      "x": -10,
      "y": 15,
      "z": 4,
      "name": "Rock_Stone_Brick_Smooth"
    },
    {
      "x": -10,
      "y": 9,
      "z": 5,
      "name": "Rock_Stone_Brick_Smooth"
    },
    {
      "x": -10,
      "y": 15,
      "z": 5,
      "name": "Rock_Stone_Brick_Smooth"
    },
    {
      "x": -10,
      "y": 9,
      "z": 6,
      "name": "Rock_Stone_Brick_Smooth"
    },
    {
      "x": -10,
      "y": 15,
      "z": 6,
      "name": "Rock_Stone_Brick_Smooth"
    },
    {
      "x": -10,
      "y": 9,
      "z": 7,
      "name": "Rock_Stone_Brick_Smooth"
    },
    {
      "x": -10,
      "y": 15,
      "z": 7,
      "name": "Rock_Stone_Brick_Smooth"
    },
    {
      "x": -10,
      "y": 10,
      "z": 8,
      "name": "Rock_Stone_Brick_Smooth"
    },
    {
      "x": -10,
      "y": 11,
      "z": 8,
      "name": "Rock_Stone_Brick_Pillar_Base"
    },
    {
      "x": -10,
      "y": 12,
      "z": 8,
      "name": "Rock_Stone_Brick_Pillar_Middle"
    },
    {
      "x": -10,
      "y": 13,
      "z": 8,
      "name": "Rock_Stone_Brick_Pillar_Middle"
    },
    {
      "x": -10,
      "y": 14,
      "z": 8,
      "name": "Rock_Stone_Brick_Pillar_Base",
      "rotation": 8
    },
    {
      "x": -10,
      "y": 15,
      "z": 8,
      "name": "Rock_Stone_Brick"
    },
    {
      "x": -10,
      "y": 10,
      "z": 9,
      "name": "Rock_Stone_Brick_Decorative"
    },
    {
      "x": -10,
      "y": 11,
      "z": 9,
      "name": "Soil_Gravel",
      "support": 15
    },
    {
      "x": -10,
      "y": 12,
      "z": 9,
      "name": "Soil_Gravel",
      "support": 15
    },
    {
      "x": -10,
      "y": 13,
      "z": 9,
      "name": "Soil_Gravel",
      "support": 15
    },
    {
      "x": -10,
      "y": 14,
      "z": 9,
      "name": "Soil_Gravel",
      "support": 15
    },
    {
      "x": -9,
      "y": 10,
      "z": -11,
      "name": "Rock_Stone_Brick_Decorative"
    },
    {
      "x": -9,
      "y": 11,
      "z": -11,
      "name": "Soil_Gravel_Half",
      "support": 15,
      "rotation": 4
    },
    {
      "x": -9,
      "y": 12,
      "z": -11,
      "name": "Soil_Gravel_Half",
      "support": 15,
      "rotation": 4
    },
    {
      "x": -9,
      "y": 13,
      "z": -11,
      "name": "Soil_Gravel_Half",
      "support": 15,
      "rotation": 4
    },
    {
      "x": -9,
      "y": 14,
      "z": -11,
      "name": "Soil_Gravel_Half",
      "support": 15,
      "rotation": 4
    },
    {
      "x": -9,
      "y": 15,
      "z": -11,
      "name": "Rock_Stone_Brick"
    },
    {
      "x": -9,
      "y": 9,
      "z": -10,
      "name": "Rock_Stone_Brick_Smooth"
    },
    {
      "x": -9,
      "y": 15,
      "z": -10,
      "name": "Rock_Stone_Brick_Smooth"
    },
    {
      "x": -9,
      "y": 9,
      "z": -9,
      "name": "Rock_Stone_Brick_Smooth"
    },
    {
      "x": -9,
      "y": 15,
      "z": -9,
      "name": "Rock_Stone_Brick_Smooth"
    },
    {
      "x": -9,
      "y": 9,
      "z": -8,
      "name": "Rock_Stone_Brick_Smooth"
    },
    {
      "x": -9,
      "y": 15,
      "z": -8,
      "name": "Rock_Stone_Brick_Smooth"
    },
    {
      "x": -9,
      "y": 9,
      "z": -7,
      "name": "Rock_Stone_Brick_Smooth"
    },
    {
      "x": -9,
      "y": 15,
      "z": -7,
      "name": "Rock_Stone_Brick_Smooth"
    },
    {
      "x": -9,
      "y": 9,
      "z": -6,
      "name": "Rock_Stone_Brick_Smooth"
    },
    {
      "x": -9,
      "y": 15,
      "z": -6,
      "name": "Rock_Stone_Brick_Decorative"
    },
    {
      "x": -9,
      "y": 9,
      "z": -5,
      "name": "Rock_Stone_Brick_Smooth"
    },
    {
      "x": -9,
      "y": 15,
      "z": -5,
      "name": "Rock_Stone_Brick_Smooth"
    },
    {
      "x": -9,
      "y": 9,
      "z": -4,
      "name": "Rock_Stone_Brick_Smooth"
    },
    {
      "x": -9,
      "y": 15,
      "z": -4,
      "name": "Rock_Stone_Brick_Smooth"
    },
    {
      "x": -9,
      "y": 9,
      "z": -3,
      "name": "Rock_Stone_Brick_Smooth"
    },
    {
      "x": -9,
      "y": 15,
      "z": -3,
      "name": "Rock_Stone_Brick_Smooth"
    },
    {
      "x": -9,
      "y": 2,
      "z": -2,
      "name": "Rock_Stone"
    },
    {
      "x": -9,
      "y": 3,
      "z": -2,
      "name": "Rock_Stone_Brick"
    },
    {
      "x": -9,
      "y": 4,
      "z": -2,
      "name": "Rock_Stone_Brick"
    },
    {
      "x": -9,
      "y": 5,
      "z": -2,
      "name": "Rock_Stone_Brick"
    },
    {
      "x": -9,
      "y": 6,
      "z": -2,
      "name": "Rock_Stone_Brick"
    },
    {
      "x": -9,
      "y": 7,
      "z": -2,
      "name": "Rock_Stone_Brick"
    },
    {
      "x": -9,
      "y": 8,
      "z": -2,
      "name": "Rock_Stone_Brick"
    },
    {
      "x": -9,
      "y": 9,
      "z": -2,
      "name": "Rock_Stone_Brick_Smooth"
    },
    {
      "x": -9,
      "y": 15,
      "z": -2,
      "name": "Rock_Stone_Brick_Smooth"
    },
    {
      "x": -9,
      "y": 2,
      "z": -1,
      "name": "Rock_Stone"
    },
    {
      "x": -9,
      "y": 8,
      "z": -1,
      "name": "Rock_Stone_Brick_Stairs",
      "rotation": 10
    },
    {
      "x": -9,
      "y": 9,
      "z": -1,
      "name": "Rock_Stone_Brick_Smooth"
    },
    {
      "x": -9,
      "y": 15,
      "z": -1,
      "name": "Rock_Stone_Brick_Smooth"
    },
    {
      "x": -9,
      "y": 2,
      "z": 0,
      "name": "Rock_Stone"
    },
    {
      "x": -9,
      "y": 9,
      "z": 0,
      "name": "Rock_Stone_Brick_Smooth"
    },
    {
      "x": -9,
      "y": 15,
      "z": 0,
      "name": "Rock_Stone_Brick_Smooth"
    },
    {
      "x": -9,
      "y": 2,
      "z": 1,
      "name": "Rock_Stone"
    },
    {
      "x": -9,
      "y": 8,
      "z": 1,
      "name": "Rock_Stone_Brick_Stairs",
      "rotation": 8
    },
    {
      "x": -9,
      "y": 9,
      "z": 1,
      "name": "Rock_Stone_Brick_Smooth"
    },
    {
      "x": -9,
      "y": 15,
      "z": 1,
      "name": "Rock_Stone_Brick_Smooth"
    },
    {
      "x": -9,
      "y": 2,
      "z": 2,
      "name": "Rock_Stone"
    },
    {
      "x": -9,
      "y": 3,
      "z": 2,
      "name": "Rock_Stone_Brick"
    },
    {
      "x": -9,
      "y": 4,
      "z": 2,
      "name": "Rock_Stone_Brick"
    },
    {
      "x": -9,
      "y": 5,
      "z": 2,
      "name": "Rock_Stone_Brick"
    },
    {
      "x": -9,
      "y": 6,
      "z": 2,
      "name": "Rock_Stone_Brick"
    },
    {
      "x": -9,
      "y": 7,
      "z": 2,
      "name": "Rock_Stone_Brick"
    },
    {
      "x": -9,
      "y": 8,
      "z": 2,
      "name": "Rock_Stone_Brick"
    },
    {
      "x": -9,
      "y": 9,
      "z": 2,
      "name": "Rock_Stone_Brick_Smooth"
    },
    {
      "x": -9,
      "y": 15,
      "z": 2,
      "name": "Rock_Stone_Brick_Smooth"
    },
    {
      "x": -9,
      "y": 9,
      "z": 3,
      "name": "Rock_Stone_Brick_Smooth"
    },
    {
      "x": -9,
      "y": 15,
      "z": 3,
      "name": "Rock_Stone_Brick_Smooth"
    },
    {
      "x": -9,
      "y": 9,
      "z": 4,
      "name": "Rock_Stone_Brick_Smooth"
    },
    {
      "x": -9,
      "y": 15,
      "z": 4,
      "name": "Rock_Stone_Brick_Smooth"
    },
    {
      "x": -9,
      "y": 9,
      "z": 5,
      "name": "Rock_Stone_Brick_Smooth"
    },
    {
      "x": -9,
      "y": 15,
      "z": 5,
      "name": "Rock_Stone_Brick_Smooth"
    },
    {
      "x": -9,
      "y": 9,
      "z": 6,
      "name": "Rock_Stone_Brick_Smooth"
    },
    {
      "x": -9,
      "y": 15,
      "z": 6,
      "name": "Rock_Stone_Brick_Smooth"
    },
    {
      "x": -9,
      "y": 9,
      "z": 7,
      "name": "Rock_Stone_Brick_Smooth"
    },
    {
      "x": -9,
      "y": 15,
      "z": 7,
      "name": "Rock_Stone_Brick_Smooth"
    },
    {
      "x": -9,
      "y": 10,
      "z": 8,
      "name": "Rock_Stone_Brick_Decorative"
    },
    {
      "x": -9,
      "y": 11,
      "z": 8,
      "name": "Soil_Gravel_Half",
      "support": 15,
      "rotation": 6
    },
    {
      "x": -9,
      "y": 12,
      "z": 8,
      "name": "Soil_Gravel_Half",
      "support": 15,
      "rotation": 6
    },
    {
      "x": -9,
      "y": 13,
      "z": 8,
      "name": "Soil_Gravel_Half",
      "support": 15,
      "rotation": 6
    },
    {
      "x": -9,
      "y": 14,
      "z": 8,
      "name": "Soil_Gravel_Half",
      "support": 15,
      "rotation": 6
    },
    {
      "x": -9,
      "y": 15,
      "z": 8,
      "name": "Rock_Stone_Brick"
    },
    {
      "x": -8,
      "y": 10,
      "z": -12,
      "name": "Rock_Stone_Brick_Decorative"
    },
    {
      "x": -8,
      "y": 11,
      "z": -12,
      "name": "Soil_Gravel",
      "support": 15
    },
    {
      "x": -8,
      "y": 12,
      "z": -12,
      "name": "Soil_Gravel",
      "support": 15
    },
    {
      "x": -8,
      "y": 13,
      "z": -12,
      "name": "Soil_Gravel",
      "support": 15
    },
    {
      "x": -8,
      "y": 14,
      "z": -12,
      "name": "Soil_Gravel",
      "support": 15
    },
    {
      "x": -8,
      "y": 10,
      "z": -11,
      "name": "Rock_Stone_Brick_Smooth"
    },
    {
      "x": -8,
      "y": 11,
      "z": -11,
      "name": "Rock_Stone_Brick_Pillar_Base"
    },
    {
      "x": -8,
      "y": 12,
      "z": -11,
      "name": "Rock_Stone_Brick_Pillar_Middle"
    },
    {
      "x": -8,
      "y": 13,
      "z": -11,
      "name": "Rock_Stone_Brick_Pillar_Middle"
    },
    {
      "x": -8,
      "y": 14,
      "z": -11,
      "name": "Rock_Stone_Brick_Pillar_Base",
      "rotation": 8
    },
    {
      "x": -8,
      "y": 15,
      "z": -11,
      "name": "Rock_Stone_Brick_Smooth"
    },
    {
      "x": -8,
      "y": 9,
      "z": -10,
      "name": "Rock_Stone_Brick_Smooth"
    },
    {
      "x": -8,
      "y": 15,
      "z": -10,
      "name": "Rock_Stone_Brick_Smooth"
    },
    {
      "x": -8,
      "y": 9,
      "z": -9,
      "name": "Rock_Stone_Brick_Smooth"
    },
    {
      "x": -8,
      "y": 15,
      "z": -9,
      "name": "Rock_Stone_Brick_Smooth"
    },
    {
      "x": -8,
      "y": 9,
      "z": -8,
      "name": "Rock_Stone_Brick_Smooth"
    },
    {
      "x": -8,
      "y": 15,
      "z": -8,
      "name": "Rock_Stone_Brick_Smooth"
    },
    {
      "x": -8,
      "y": 9,
      "z": -7,
      "name": "Rock_Stone_Brick_Smooth"
    },
    {
      "x": -8,
      "y": 15,
      "z": -7,
      "name": "Rock_Stone_Brick_Smooth"
    },
    {
      "x": -8,
      "y": 9,
      "z": -6,
      "name": "Rock_Stone_Brick_Smooth"
    },
    {
      "x": -8,
      "y": 10,
      "z": -6,
      "name": "Rock_Stone_Brick_Smooth"
    },
    {
      "x": -8,
      "y": 11,
      "z": -6,
      "name": "Rock_Stone_Brick_Pillar_Base"
    },
    {
      "x": -8,
      "y": 12,
      "z": -6,
      "name": "Rock_Stone_Brick_Pillar_Middle"
    },
    {
      "x": -8,
      "y": 13,
      "z": -6,
      "name": "Rock_Stone_Brick_Pillar_Middle"
    },
    {
      "x": -8,
      "y": 14,
      "z": -6,
      "name": "Rock_Stone_Brick_Pillar_Base",
      "rotation": 8
    },
    {
      "x": -8,
      "y": 15,
      "z": -6,
      "name": "Rock_Stone_Brick_Smooth"
    },
    {
      "x": -8,
      "y": 16,
      "z": -6,
      "name": "Rock_Stone_Brick_Smooth"
    },
    {
      "x": -8,
      "y": 9,
      "z": -5,
      "name": "Rock_Stone_Brick_Smooth"
    },
    {
      "x": -8,
      "y": 10,
      "z": -5,
      "name": "Rock_Stone_Brick_Wall",
      "rotation": 1
    },
    {
      "x": -8,
      "y": 15,
      "z": -5,
      "name": "Rock_Stone_Brick_Decorative"
    },
    {
      "x": -8,
      "y": 16,
      "z": -5,
      "name": "Rock_Stone_Brick"
    },
    {
      "x": -8,
      "y": 9,
      "z": -4,
      "name": "Rock_Stone_Brick_Smooth"
    },
    {
      "x": -8,
      "y": 10,
      "z": -4,
      "name": "Rock_Stone_Brick_Wall",
      "rotation": 1
    },
    {
      "x": -8,
      "y": 15,
      "z": -4,
      "name": "Rock_Stone_Brick_Decorative"
    },
    {
      "x": -8,
      "y": 16,
      "z": -4,
      "name": "Rock_Stone_Brick"
    },
    {
      "x": -8,
      "y": 5,
      "z": -3,
      "name": "Rock_Stone_Brick"
    },
    {
      "x": -8,
      "y": 6,
      "z": -3,
      "name": "Rock_Stone_Brick"
    },
    {
      "x": -8,
      "y": 7,
      "z": -3,
      "name": "Rock_Stone_Brick_Smooth"
    },
    {
      "x": -8,
      "y": 8,
      "z": -3,
      "name": "Rock_Stone_Brick_Smooth"
    },
    {
      "x": -8,
      "y": 9,
      "z": -3,
      "name": "Rock_Stone_Brick_Decorative"
    },
    {
      "x": -8,
      "y": 10,
      "z": -3,
      "name": "Rock_Stone_Brick_Wall",
      "rotation": 1
    },
    {
      "x": -8,
      "y": 15,
      "z": -3,
      "name": "Rock_Stone_Brick_Decorative"
    },
    {
      "x": -8,
      "y": 16,
      "z": -3,
      "name": "Rock_Stone_Brick"
    },
    {
      "x": -8,
      "y": 2,
      "z": -2,
      "name": "Rock_Stone"
    },
    {
      "x": -8,
      "y": 3,
      "z": -2,
      "name": "Rock_Stone_Brick"
    },
    {
      "x": -8,
      "y": 4,
      "z": -2,
      "name": "Rock_Stone_Brick"
    },
    {
      "x": -8,
      "y": 5,
      "z": -2,
      "name": "Rock_Stone_Brick"
    },
    {
      "x": -8,
      "y": 6,
      "z": -2,
      "name": "Rock_Stone_Brick"
    },
    {
      "x": -8,
      "y": 7,
      "z": -2,
      "name": "Rock_Stone_Brick"
    },
    {
      "x": -8,
      "y": 8,
      "z": -2,
      "name": "Rock_Stone_Brick"
    },
    {
      "x": -8,
      "y": 9,
      "z": -2,
      "name": "Rock_Stone_Brick_Decorative"
    },
    {
      "x": -8,
      "y": 10,
      "z": -2,
      "name": "Rock_Stone_Brick_Smooth"
    },
    {
      "x": -8,
      "y": 11,
      "z": -2,
      "name": "Rock_Stone_Brick_Pillar_Base"
    },
    {
      "x": -8,
      "y": 12,
      "z": -2,
      "name": "Rock_Stone_Brick_Pillar_Middle"
    },
    {
      "x": -8,
      "y": 13,
      "z": -2,
      "name": "Rock_Stone_Brick_Pillar_Middle"
    },
    {
      "x": -8,
      "y": 14,
      "z": -2,
      "name": "Rock_Stone_Brick_Pillar_Base",
      "rotation": 8
    },
    {
      "x": -8,
      "y": 15,
      "z": -2,
      "name": "Rock_Stone_Brick_Smooth"
    },
    {
      "x": -8,
      "y": 16,
      "z": -2,
      "name": "Rock_Stone_Brick_Smooth"
    },
    {
      "x": -8,
      "y": 2,
      "z": -1,
      "name": "Rock_Stone"
    },
    {
      "x": -8,
      "y": 3,
      "z": -1,
      "name": "Rock_Stone_Brick_Smooth_Half",
      "rotation": 4
    },
    {
      "x": -8,
      "y": 4,
      "z": -1,
      "name": "Rock_Stone_Brick_Smooth_Half",
      "rotation": 4
    },
    {
      "x": -8,
      "y": 5,
      "z": -1,
      "name": "Rock_Stone_Brick_Smooth_Half",
      "rotation": 4
    },
    {
      "x": -8,
      "y": 6,
      "z": -1,
      "name": "Rock_Stone_Brick_Smooth_Half",
      "rotation": 4
    },
    {
      "x": -8,
      "y": 7,
      "z": -1,
      "name": "Rock_Stone_Brick_Smooth_Half",
      "rotation": 4
    },
    {
      "x": -8,
      "y": 8,
      "z": -1,
      "name": "Rock_Stone_Brick_Stairs",
      "rotation": 10
    },
    {
      "x": -8,
      "y": 9,
      "z": -1,
      "name": "Rock_Stone_Brick_Decorative"
    },
    {
      "x": -8,
      "y": 10,
      "z": -1,
      "name": "Rock_Stone_Brick_Wall",
      "rotation": 1
    },
    {
      "x": -8,
      "y": 15,
      "z": -1,
      "name": "Rock_Stone_Brick_Decorative"
    },
    {
      "x": -8,
      "y": 16,
      "z": -1,
      "name": "Rock_Stone_Brick"
    },
    {
      "x": -8,
      "y": 2,
      "z": 0,
      "name": "Rock_Stone"
    },
    {
      "x": -8,
      "y": 9,
      "z": 0,
      "name": "Rock_Stone_Brick_Decorative"
    },
    {
      "x": -8,
      "y": 10,
      "z": 0,
      "name": "Rock_Stone_Brick_Wall",
      "rotation": 1
    },
    {
      "x": -8,
      "y": 15,
      "z": 0,
      "name": "Rock_Stone_Brick_Decorative"
    },
    {
      "x": -8,
      "y": 16,
      "z": 0,
      "name": "Rock_Stone_Brick"
    },
    {
      "x": -8,
      "y": 2,
      "z": 1,
      "name": "Rock_Stone"
    },
    {
      "x": -8,
      "y": 3,
      "z": 1,
      "name": "Rock_Stone_Brick_Smooth_Half",
      "rotation": 6
    },
    {
      "x": -8,
      "y": 4,
      "z": 1,
      "name": "Rock_Stone_Brick_Smooth_Half",
      "rotation": 6
    },
    {
      "x": -8,
      "y": 5,
      "z": 1,
      "name": "Rock_Stone_Brick_Smooth_Half",
      "rotation": 6
    },
    {
      "x": -8,
      "y": 6,
      "z": 1,
      "name": "Rock_Stone_Brick_Smooth_Half",
      "rotation": 6
    },
    {
      "x": -8,
      "y": 7,
      "z": 1,
      "name": "Rock_Stone_Brick_Smooth_Half",
      "rotation": 6
    },
    {
      "x": -8,
      "y": 8,
      "z": 1,
      "name": "Rock_Stone_Brick_Stairs",
      "rotation": 8
    },
    {
      "x": -8,
      "y": 9,
      "z": 1,
      "name": "Rock_Stone_Brick_Decorative"
    },
    {
      "x": -8,
      "y": 10,
      "z": 1,
      "name": "Rock_Stone_Brick_Wall",
      "rotation": 1
    },
    {
      "x": -8,
      "y": 15,
      "z": 1,
      "name": "Rock_Stone_Brick_Decorative"
    },
    {
      "x": -8,
      "y": 16,
      "z": 1,
      "name": "Rock_Stone_Brick"
    },
    {
      "x": -8,
      "y": 2,
      "z": 2,
      "name": "Rock_Stone"
    },
    {
      "x": -8,
      "y": 3,
      "z": 2,
      "name": "Rock_Stone_Brick"
    },
    {
      "x": -8,
      "y": 4,
      "z": 2,
      "name": "Rock_Stone_Brick"
    },
    {
      "x": -8,
      "y": 5,
      "z": 2,
      "name": "Rock_Stone_Brick"
    },
    {
      "x": -8,
      "y": 6,
      "z": 2,
      "name": "Rock_Stone_Brick"
    },
    {
      "x": -8,
      "y": 7,
      "z": 2,
      "name": "Rock_Stone_Brick"
    },
    {
      "x": -8,
      "y": 8,
      "z": 2,
      "name": "Rock_Stone_Brick"
    },
    {
      "x": -8,
      "y": 9,
      "z": 2,
      "name": "Rock_Stone_Brick_Decorative"
    },
    {
      "x": -8,
      "y": 10,
      "z": 2,
      "name": "Rock_Stone_Brick_Smooth"
    },
    {
      "x": -8,
      "y": 11,
      "z": 2,
      "name": "Rock_Stone_Brick_Pillar_Base"
    },
    {
      "x": -8,
      "y": 12,
      "z": 2,
      "name": "Rock_Stone_Brick_Pillar_Middle"
    },
    {
      "x": -8,
      "y": 13,
      "z": 2,
      "name": "Rock_Stone_Brick_Pillar_Middle"
    },
    {
      "x": -8,
      "y": 14,
      "z": 2,
      "name": "Rock_Stone_Brick_Pillar_Base",
      "rotation": 8
    },
    {
      "x": -8,
      "y": 15,
      "z": 2,
      "name": "Rock_Stone_Brick_Smooth"
    },
    {
      "x": -8,
      "y": 16,
      "z": 2,
      "name": "Rock_Stone_Brick_Smooth"
    },
    {
      "x": -8,
      "y": 2,
      "z": 3,
      "name": "Rock_Stone"
    },
    {
      "x": -8,
      "y": 3,
      "z": 3,
      "name": "Rock_Stone_Brick"
    },
    {
      "x": -8,
      "y": 4,
      "z": 3,
      "name": "Rock_Stone_Brick"
    },
    {
      "x": -8,
      "y": 5,
      "z": 3,
      "name": "Rock_Stone_Brick"
    },
    {
      "x": -8,
      "y": 6,
      "z": 3,
      "name": "Rock_Stone_Brick_Smooth"
    },
    {
      "x": -8,
      "y": 7,
      "z": 3,
      "name": "Rock_Stone_Brick_Smooth"
    },
    {
      "x": -8,
      "y": 8,
      "z": 3,
      "name": "Rock_Stone_Brick_Smooth"
    },
    {
      "x": -8,
      "y": 9,
      "z": 3,
      "name": "Rock_Stone_Brick_Decorative"
    },
    {
      "x": -8,
      "y": 10,
      "z": 3,
      "name": "Rock_Stone_Brick"
    },
    {
      "x": -8,
      "y": 11,
      "z": 3,
      "name": "Rock_Stone_Brick"
    },
    {
      "x": -8,
      "y": 12,
      "z": 3,
      "name": "Rock_Stone_Brick"
    },
    {
      "x": -8,
      "y": 13,
      "z": 3,
      "name": "Rock_Stone_Brick"
    },
    {
      "x": -8,
      "y": 14,
      "z": 3,
      "name": "Rock_Stone_Brick"
    },
    {
      "x": -8,
      "y": 15,
      "z": 3,
      "name": "Rock_Stone_Brick_Decorative"
    },
    {
      "x": -8,
      "y": 16,
      "z": 3,
      "name": "Rock_Stone_Brick"
    },
    {
      "x": -8,
      "y": 2,
      "z": 4,
      "name": "Rock_Stone"
    },
    {
      "x": -8,
      "y": 3,
      "z": 4,
      "name": "Rock_Stone_Brick"
    },
    {
      "x": -8,
      "y": 4,
      "z": 4,
      "name": "Rock_Stone_Brick"
    },
    {
      "x": -8,
      "y": 5,
      "z": 4,
      "name": "Rock_Stone_Brick"
    },
    {
      "x": -8,
      "y": 6,
      "z": 4,
      "name": "Rock_Stone_Brick_Smooth"
    },
    {
      "x": -8,
      "y": 7,
      "z": 4,
      "name": "Rock_Stone_Brick_Smooth"
    },
    {
      "x": -8,
      "y": 8,
      "z": 4,
      "name": "Rock_Stone_Brick_Smooth"
    },
    {
      "x": -8,
      "y": 9,
      "z": 4,
      "name": "Rock_Stone_Brick_Decorative"
    },
    {
      "x": -8,
      "y": 10,
      "z": 4,
      "name": "Rock_Stone_Brick"
    },
    {
      "x": -8,
      "y": 11,
      "z": 4,
      "name": "Rock_Stone_Brick"
    },
    {
      "x": -8,
      "y": 12,
      "z": 4,
      "name": "Rock_Stone_Brick"
    },
    {
      "x": -8,
      "y": 13,
      "z": 4,
      "name": "Rock_Stone_Brick"
    },
    {
      "x": -8,
      "y": 14,
      "z": 4,
      "name": "Rock_Stone_Brick"
    },
    {
      "x": -8,
      "y": 15,
      "z": 4,
      "name": "Rock_Stone_Brick_Decorative"
    },
    {
      "x": -8,
      "y": 16,
      "z": 4,
      "name": "Rock_Stone_Brick_Smooth"
    },
    {
      "x": -8,
      "y": 9,
      "z": 5,
      "name": "Rock_Stone_Brick_Smooth"
    },
    {
      "x": -8,
      "y": 15,
      "z": 5,
      "name": "Rock_Stone_Brick_Smooth"
    },
    {
      "x": -8,
      "y": 9,
      "z": 6,
      "name": "Rock_Stone_Brick_Smooth"
    },
    {
      "x": -8,
      "y": 15,
      "z": 6,
      "name": "Rock_Stone_Brick_Smooth"
    },
    {
      "x": -8,
      "y": 9,
      "z": 7,
      "name": "Rock_Stone_Brick_Smooth"
    },
    {
      "x": -8,
      "y": 15,
      "z": 7,
      "name": "Rock_Stone_Brick_Smooth"
    },
    {
      "x": -8,
      "y": 10,
      "z": 8,
      "name": "Rock_Stone_Brick_Decorative"
    },
    {
      "x": -8,
      "y": 11,
      "z": 8,
      "name": "Soil_Gravel_Half",
      "support": 15,
      "rotation": 6
    },
    {
      "x": -8,
      "y": 12,
      "z": 8,
      "name": "Soil_Gravel_Half",
      "support": 15,
      "rotation": 6
    },
    {
      "x": -8,
      "y": 13,
      "z": 8,
      "name": "Soil_Gravel_Half",
      "support": 15,
      "rotation": 6
    },
    {
      "x": -8,
      "y": 14,
      "z": 8,
      "name": "Soil_Gravel_Half",
      "support": 15,
      "rotation": 6
    },
    {
      "x": -8,
      "y": 15,
      "z": 8,
      "name": "Rock_Stone_Brick"
    },
    {
      "x": -7,
      "y": 10,
      "z": -11,
      "name": "Rock_Stone_Brick_Decorative"
    },
    {
      "x": -7,
      "y": 11,
      "z": -11,
      "name": "Soil_Gravel_Half",
      "support": 15,
      "rotation": 4
    },
    {
      "x": -7,
      "y": 12,
      "z": -11,
      "name": "Soil_Gravel_Half",
      "support": 15,
      "rotation": 4
    },
    {
      "x": -7,
      "y": 13,
      "z": -11,
      "name": "Soil_Gravel_Half",
      "support": 15,
      "rotation": 4
    },
    {
      "x": -7,
      "y": 14,
      "z": -11,
      "name": "Soil_Gravel_Half",
      "support": 15,
      "rotation": 4
    },
    {
      "x": -7,
      "y": 15,
      "z": -11,
      "name": "Rock_Stone_Brick"
    },
    {
      "x": -7,
      "y": 9,
      "z": -10,
      "name": "Rock_Stone_Brick_Smooth"
    },
    {
      "x": -7,
      "y": 15,
      "z": -10,
      "name": "Rock_Stone_Brick_Smooth"
    },
    {
      "x": -7,
      "y": 18,
      "z": -10,
      "name": "Rock_Stone_Brick"
    },
    {
      "x": -7,
      "y": 9,
      "z": -9,
      "name": "Rock_Stone_Brick_Smooth"
    },
    {
      "x": -7,
      "y": 15,
      "z": -9,
      "name": "Rock_Stone_Brick_Smooth"
    },
    {
      "x": -7,
      "y": 9,
      "z": -8,
      "name": "Rock_Stone_Brick_Smooth"
    },
    {
      "x": -7,
      "y": 15,
      "z": -8,
      "name": "Rock_Stone_Brick_Smooth"
    },
    {
      "x": -7,
      "y": 9,
      "z": -7,
      "name": "Rock_Stone_Brick_Smooth"
    },
    {
      "x": -7,
      "y": 15,
      "z": -7,
      "name": "Rock_Stone_Brick_Smooth"
    },
    {
      "x": -7,
      "y": 9,
      "z": -6,
      "name": "Rock_Stone_Brick_Smooth"
    },
    {
      "x": -7,
      "y": 15,
      "z": -6,
      "name": "Rock_Stone_Brick_Decorative"
    },
    {
      "x": -7,
      "y": 16,
      "z": -6,
      "name": "Rock_Stone_Brick"
    },
    {
      "x": -7,
      "y": 9,
      "z": -5,
      "name": "Rock_Stone_Brick_Smooth"
    },
    {
      "x": -7,
      "y": 16,
      "z": -5,
      "name": "Rock_Stone_Half",
      "rotation": 8
    },
    {
      "x": -7,
      "y": 7,
      "z": -4,
      "name": "Rock_Stone_Brick_Smooth"
    },
    {
      "x": -7,
      "y": 8,
      "z": -4,
      "name": "Rock_Stone_Brick_Smooth"
    },
    {
      "x": -7,
      "y": 9,
      "z": -4,
      "name": "Rock_Stone_Brick_Smooth"
    },
    {
      "x": -7,
      "y": 16,
      "z": -4,
      "name": "Rock_Stone_Half",
      "rotation": 8
    },
    {
      "x": -7,
      "y": 5,
      "z": -3,
      "name": "Rock_Stone_Brick"
    },
    {
      "x": -7,
      "y": 6,
      "z": -3,
      "name": "Rock_Stone_Brick_Smooth"
    },
    {
      "x": -7,
      "y": 16,
      "z": -3,
      "name": "Rock_Stone_Half",
      "rotation": 8
    },
    {
      "x": -7,
      "y": 2,
      "z": -2,
      "name": "Rock_Stone"
    },
    {
      "x": -7,
      "y": 3,
      "z": -2,
      "name": "Rock_Stone_Brick"
    },
    {
      "x": -7,
      "y": 4,
      "z": -2,
      "name": "Rock_Stone_Brick"
    },
    {
      "x": -7,
      "y": 5,
      "z": -2,
      "name": "Rock_Stone_Brick"
    },
    {
      "x": -7,
      "y": 6,
      "z": -2,
      "name": "Rock_Stone_Brick_Smooth"
    },
    {
      "x": -7,
      "y": 16,
      "z": -2,
      "name": "Rock_Stone_Brick"
    },
    {
      "x": -7,
      "y": 2,
      "z": -1,
      "name": "Rock_Stone"
    },
    {
      "x": -7,
      "y": 16,
      "z": -1,
      "name": "Rock_Stone_Half",
      "rotation": 8
    },
    {
      "x": -7,
      "y": 2,
      "z": 0,
      "name": "Rock_Stone"
    },
    {
      "x": -7,
      "y": 16,
      "z": 0,
      "name": "Rock_Stone_Half",
      "rotation": 8
    },
    {
      "x": -7,
      "y": 2,
      "z": 1,
      "name": "Rock_Stone"
    },
    {
      "x": -7,
      "y": 16,
      "z": 1,
      "name": "Rock_Stone_Half",
      "rotation": 8
    },
    {
      "x": -7,
      "y": 2,
      "z": 2,
      "name": "Rock_Stone"
    },
    {
      "x": -7,
      "y": 16,
      "z": 2,
      "name": "Rock_Stone_Brick"
    },
    {
      "x": -7,
      "y": 2,
      "z": 3,
      "name": "Rock_Stone"
    },
    {
      "x": -7,
      "y": 16,
      "z": 3,
      "name": "Rock_Stone_Half",
      "rotation": 8
    },
    {
      "x": -7,
      "y": 2,
      "z": 4,
      "name": "Rock_Stone"
    },
    {
      "x": -7,
      "y": 3,
      "z": 4,
      "name": "Rock_Stone_Brick"
    },
    {
      "x": -7,
      "y": 4,
      "z": 4,
      "name": "Rock_Stone_Brick"
    },
    {
      "x": -7,
      "y": 5,
      "z": 4,
      "name": "Rock_Stone_Brick"
    },
    {
      "x": -7,
      "y": 6,
      "z": 4,
      "name": "Rock_Stone_Brick_Smooth"
    },
    {
      "x": -7,
      "y": 7,
      "z": 4,
      "name": "Rock_Stone_Brick_Smooth"
    },
    {
      "x": -7,
      "y": 8,
      "z": 4,
      "name": "Rock_Stone_Brick_Smooth"
    },
    {
      "x": -7,
      "y": 9,
      "z": 4,
      "name": "Rock_Stone_Brick_Decorative"
    },
    {
      "x": -7,
      "y": 10,
      "z": 4,
      "name": "Rock_Stone_Brick"
    },
    {
      "x": -7,
      "y": 11,
      "z": 4,
      "name": "Rock_Stone_Brick"
    },
    {
      "x": -7,
      "y": 12,
      "z": 4,
      "name": "Rock_Stone_Brick"
    },
    {
      "x": -7,
      "y": 13,
      "z": 4,
      "name": "Rock_Stone_Brick"
    },
    {
      "x": -7,
      "y": 14,
      "z": 4,
      "name": "Rock_Stone_Brick"
    },
    {
      "x": -7,
      "y": 15,
      "z": 4,
      "name": "Rock_Stone_Brick_Decorative"
    },
    {
      "x": -7,
      "y": 16,
      "z": 4,
      "name": "Rock_Stone_Brick"
    },
    {
      "x": -7,
      "y": 9,
      "z": 5,
      "name": "Rock_Stone_Brick_Smooth"
    },
    {
      "x": -7,
      "y": 15,
      "z": 5,
      "name": "Rock_Stone_Brick_Smooth"
    },
    {
      "x": -7,
      "y": 9,
      "z": 6,
      "name": "Rock_Stone_Brick_Smooth"
    },
    {
      "x": -7,
      "y": 15,
      "z": 6,
      "name": "Rock_Stone_Brick_Smooth"
    },
    {
      "x": -7,
      "y": 9,
      "z": 7,
      "name": "Rock_Stone_Brick_Smooth"
    },
    {
      "x": -7,
      "y": 15,
      "z": 7,
      "name": "Rock_Stone_Brick_Smooth"
    },
    {
      "x": -7,
      "y": 10,
      "z": 8,
      "name": "Rock_Stone_Brick_Decorative"
    },
    {
      "x": -7,
      "y": 11,
      "z": 8,
      "name": "Soil_Gravel_Half",
      "support": 15,
      "rotation": 6
    },
    {
      "x": -7,
      "y": 12,
      "z": 8,
      "name": "Soil_Gravel_Half",
      "support": 15,
      "rotation": 6
    },
    {
      "x": -7,
      "y": 13,
      "z": 8,
      "name": "Soil_Gravel_Half",
      "support": 15,
      "rotation": 6
    },
    {
      "x": -7,
      "y": 14,
      "z": 8,
      "name": "Soil_Gravel_Half",
      "support": 15,
      "rotation": 6
    },
    {
      "x": -7,
      "y": 15,
      "z": 8,
      "name": "Rock_Stone_Brick"
    },
    {
      "x": -6,
      "y": 10,
      "z": -11,
      "name": "Rock_Stone_Brick_Decorative"
    },
    {
      "x": -6,
      "y": 11,
      "z": -11,
      "name": "Soil_Gravel_Half",
      "support": 15,
      "rotation": 4
    },
    {
      "x": -6,
      "y": 12,
      "z": -11,
      "name": "Soil_Gravel_Half",
      "support": 15,
      "rotation": 4
    },
    {
      "x": -6,
      "y": 13,
      "z": -11,
      "name": "Soil_Gravel_Half",
      "support": 15,
      "rotation": 4
    },
    {
      "x": -6,
      "y": 14,
      "z": -11,
      "name": "Soil_Gravel_Half",
      "support": 15,
      "rotation": 4
    },
    {
      "x": -6,
      "y": 15,
      "z": -11,
      "name": "Rock_Stone_Brick"
    },
    {
      "x": -6,
      "y": 9,
      "z": -10,
      "name": "Rock_Stone_Brick_Smooth"
    },
    {
      "x": -6,
      "y": 15,
      "z": -10,
      "name": "Rock_Stone_Brick_Smooth"
    },
    {
      "x": -6,
      "y": 9,
      "z": -9,
      "name": "Rock_Stone_Brick_Smooth"
    },
    {
      "x": -6,
      "y": 15,
      "z": -9,
      "name": "Rock_Stone_Brick_Smooth"
    },
    {
      "x": -6,
      "y": 9,
      "z": -8,
      "name": "Rock_Stone_Brick_Smooth"
    },
    {
      "x": -6,
      "y": 15,
      "z": -8,
      "name": "Rock_Stone_Brick_Smooth"
    },
    {
      "x": -6,
      "y": 9,
      "z": -7,
      "name": "Rock_Stone_Brick_Smooth"
    },
    {
      "x": -6,
      "y": 15,
      "z": -7,
      "name": "Rock_Stone_Brick_Smooth"
    },
    {
      "x": -6,
      "y": 9,
      "z": -6,
      "name": "Rock_Stone_Brick_Smooth"
    },
    {
      "x": -6,
      "y": 15,
      "z": -6,
      "name": "Rock_Stone_Brick_Decorative"
    },
    {
      "x": -6,
      "y": 16,
      "z": -6,
      "name": "Rock_Stone_Brick_Smooth"
    },
    {
      "x": -6,
      "y": 9,
      "z": -5,
      "name": "Rock_Stone_Brick_Smooth"
    },
    {
      "x": -6,
      "y": 16,
      "z": -5,
      "name": "Rock_Stone_Brick"
    },
    {
      "x": -6,
      "y": 7,
      "z": -4,
      "name": "Rock_Stone_Brick_Smooth"
    },
    {
      "x": -6,
      "y": 8,
      "z": -4,
      "name": "Rock_Stone_Brick_Smooth"
    },
    {
      "x": -6,
      "y": 9,
      "z": -4,
      "name": "Rock_Stone_Brick_Smooth"
    },
    {
      "x": -6,
      "y": 16,
      "z": -4,
      "name": "Rock_Stone_Brick"
    },
    {
      "x": -6,
      "y": 5,
      "z": -3,
      "name": "Rock_Stone_Brick"
    },
    {
      "x": -6,
      "y": 6,
      "z": -3,
      "name": "Rock_Stone_Brick_Smooth"
    },
    {
      "x": -6,
      "y": 16,
      "z": -3,
      "name": "Rock_Stone_Brick"
    },
    {
      "x": -6,
      "y": 2,
      "z": -2,
      "name": "Rock_Stone"
    },
    {
      "x": -6,
      "y": 3,
      "z": -2,
      "name": "Rock_Stone_Brick"
    },
    {
      "x": -6,
      "y": 4,
      "z": -2,
      "name": "Rock_Stone_Brick"
    },
    {
      "x": -6,
      "y": 5,
      "z": -2,
      "name": "Rock_Stone_Brick"
    },
    {
      "x": -6,
      "y": 6,
      "z": -2,
      "name": "Rock_Stone_Brick_Smooth"
    },
    {
      "x": -6,
      "y": 16,
      "z": -2,
      "name": "Rock_Stone_Brick"
    },
    {
      "x": -6,
      "y": 2,
      "z": -1,
      "name": "Rock_Stone"
    },
    {
      "x": -6,
      "y": 16,
      "z": -1,
      "name": "Rock_Stone_Brick"
    },
    {
      "x": -6,
      "y": 2,
      "z": 0,
      "name": "Rock_Stone"
    },
    {
      "x": -6,
      "y": 16,
      "z": 0,
      "name": "Rock_Stone_Brick"
    },
    {
      "x": -6,
      "y": 2,
      "z": 1,
      "name": "Rock_Stone"
    },
    {
      "x": -6,
      "y": 16,
      "z": 1,
      "name": "Rock_Stone_Brick"
    },
    {
      "x": -6,
      "y": 2,
      "z": 2,
      "name": "Rock_Stone"
    },
    {
      "x": -6,
      "y": 16,
      "z": 2,
      "name": "Rock_Stone_Brick"
    },
    {
      "x": -6,
      "y": 2,
      "z": 3,
      "name": "Rock_Stone"
    },
    {
      "x": -6,
      "y": 16,
      "z": 3,
      "name": "Rock_Stone_Brick"
    },
    {
      "x": -6,
      "y": 2,
      "z": 4,
      "name": "Rock_Stone"
    },
    {
      "x": -6,
      "y": 3,
      "z": 4,
      "name": "Rock_Stone_Brick"
    },
    {
      "x": -6,
      "y": 4,
      "z": 4,
      "name": "Rock_Stone_Brick"
    },
    {
      "x": -6,
      "y": 5,
      "z": 4,
      "name": "Rock_Stone_Brick"
    },
    {
      "x": -6,
      "y": 6,
      "z": 4,
      "name": "Rock_Stone_Brick"
    },
    {
      "x": -6,
      "y": 7,
      "z": 4,
      "name": "Rock_Stone_Brick"
    },
    {
      "x": -6,
      "y": 8,
      "z": 4,
      "name": "Rock_Stone_Brick"
    },
    {
      "x": -6,
      "y": 9,
      "z": 4,
      "name": "Rock_Stone_Brick_Decorative"
    },
    {
      "x": -6,
      "y": 10,
      "z": 4,
      "name": "Rock_Stone_Brick_Smooth"
    },
    {
      "x": -6,
      "y": 11,
      "z": 4,
      "name": "Rock_Stone_Brick_Pillar_Base"
    },
    {
      "x": -6,
      "y": 12,
      "z": 4,
      "name": "Rock_Stone_Brick_Pillar_Middle"
    },
    {
      "x": -6,
      "y": 13,
      "z": 4,
      "name": "Rock_Stone_Brick_Pillar_Middle"
    },
    {
      "x": -6,
      "y": 14,
      "z": 4,
      "name": "Rock_Stone_Brick_Pillar_Base",
      "rotation": 8
    },
    {
      "x": -6,
      "y": 15,
      "z": 4,
      "name": "Rock_Stone_Brick_Smooth"
    },
    {
      "x": -6,
      "y": 16,
      "z": 4,
      "name": "Rock_Stone_Brick_Smooth"
    },
    {
      "x": -6,
      "y": 9,
      "z": 5,
      "name": "Rock_Stone_Brick_Smooth"
    },
    {
      "x": -6,
      "y": 15,
      "z": 5,
      "name": "Rock_Stone_Brick_Smooth"
    },
    {
      "x": -6,
      "y": 9,
      "z": 6,
      "name": "Rock_Stone_Brick_Smooth"
    },
    {
      "x": -6,
      "y": 15,
      "z": 6,
      "name": "Rock_Stone_Brick_Smooth"
    },
    {
      "x": -6,
      "y": 9,
      "z": 7,
      "name": "Rock_Stone_Brick_Smooth"
    },
    {
      "x": -6,
      "y": 15,
      "z": 7,
      "name": "Rock_Stone_Brick_Smooth"
    },
    {
      "x": -6,
      "y": 10,
      "z": 8,
      "name": "Rock_Stone_Brick_Smooth"
    },
    {
      "x": -6,
      "y": 11,
      "z": 8,
      "name": "Rock_Stone_Brick_Pillar_Base"
    },
    {
      "x": -6,
      "y": 12,
      "z": 8,
      "name": "Rock_Stone_Brick_Pillar_Middle"
    },
    {
      "x": -6,
      "y": 13,
      "z": 8,
      "name": "Rock_Stone_Brick_Pillar_Middle"
    },
    {
      "x": -6,
      "y": 14,
      "z": 8,
      "name": "Rock_Stone_Brick_Pillar_Base",
      "rotation": 8
    },
    {
      "x": -6,
      "y": 15,
      "z": 8,
      "name": "Rock_Stone_Brick"
    },
    {
      "x": -6,
      "y": 10,
      "z": 9,
      "name": "Rock_Stone_Brick_Decorative"
    },
    {
      "x": -6,
      "y": 11,
      "z": 9,
      "name": "Soil_Gravel_Half",
      "support": 15,
      "rotation": 5
    },
    {
      "x": -6,
      "y": 12,
      "z": 9,
      "name": "Soil_Gravel_Half",
      "support": 15,
      "rotation": 5
    },
    {
      "x": -6,
      "y": 13,
      "z": 9,
      "name": "Soil_Gravel_Half",
      "support": 15,
      "rotation": 5
    },
    {
      "x": -6,
      "y": 14,
      "z": 9,
      "name": "Soil_Gravel_Half",
      "support": 15,
      "rotation": 5
    },
    {
      "x": -6,
      "y": 15,
      "z": 9,
      "name": "Rock_Stone_Brick"
    },
    {
      "x": -6,
      "y": 10,
      "z": 10,
      "name": "Rock_Stone_Brick"
    },
    {
      "x": -6,
      "y": 11,
      "z": 10,
      "name": "Rock_Stone_Brick"
    },
    {
      "x": -6,
      "y": 12,
      "z": 10,
      "name": "Rock_Stone_Brick"
    },
    {
      "x": -6,
      "y": 13,
      "z": 10,
      "name": "Rock_Stone_Brick"
    },
    {
      "x": -6,
      "y": 14,
      "z": 10,
      "name": "Rock_Stone_Brick"
    },
    {
      "x": -6,
      "y": 15,
      "z": 10,
      "name": "Rock_Stone_Brick"
    },
    {
      "x": -5,
      "y": 10,
      "z": -11,
      "name": "Rock_Stone_Brick_Decorative"
    },
    {
      "x": -5,
      "y": 11,
      "z": -11,
      "name": "Soil_Gravel_Half",
      "support": 15,
      "rotation": 4
    },
    {
      "x": -5,
      "y": 12,
      "z": -11,
      "name": "Soil_Gravel_Half",
      "support": 15,
      "rotation": 4
    },
    {
      "x": -5,
      "y": 13,
      "z": -11,
      "name": "Soil_Gravel_Half",
      "support": 15,
      "rotation": 4
    },
    {
      "x": -5,
      "y": 14,
      "z": -11,
      "name": "Soil_Gravel_Half",
      "support": 15,
      "rotation": 4
    },
    {
      "x": -5,
      "y": 15,
      "z": -11,
      "name": "Rock_Stone_Brick"
    },
    {
      "x": -5,
      "y": 9,
      "z": -10,
      "name": "Rock_Stone_Brick_Smooth"
    },
    {
      "x": -5,
      "y": 15,
      "z": -10,
      "name": "Rock_Stone_Brick_Smooth"
    },
    {
      "x": -5,
      "y": 9,
      "z": -9,
      "name": "Rock_Stone_Brick_Smooth"
    },
    {
      "x": -5,
      "y": 15,
      "z": -9,
      "name": "Rock_Stone_Brick_Smooth"
    },
    {
      "x": -5,
      "y": 9,
      "z": -8,
      "name": "Rock_Stone_Brick_Smooth"
    },
    {
      "x": -5,
      "y": 15,
      "z": -8,
      "name": "Rock_Stone_Brick_Smooth"
    },
    {
      "x": -5,
      "y": 9,
      "z": -7,
      "name": "Rock_Stone_Brick_Smooth"
    },
    {
      "x": -5,
      "y": 15,
      "z": -7,
      "name": "Rock_Stone_Brick_Smooth"
    },
    {
      "x": -5,
      "y": 8,
      "z": -6,
      "name": "Rock_Stone_Brick_Smooth"
    },
    {
      "x": -5,
      "y": 9,
      "z": -6,
      "name": "Rock_Stone_Brick_Decorative"
    },
    {
      "x": -5,
      "y": 15,
      "z": -6,
      "name": "Rock_Stone_Brick_Decorative"
    },
    {
      "x": -5,
      "y": 16,
      "z": -6,
      "name": "Rock_Stone_Brick"
    },
    {
      "x": -5,
      "y": 9,
      "z": -5,
      "name": "Rock_Stone_Brick_Stairs",
      "rotation": 1
    },
    {
      "x": -5,
      "y": 16,
      "z": -5,
      "name": "Rock_Stone_Half",
      "rotation": 8
    },
    {
      "x": -5,
      "y": 7,
      "z": -4,
      "name": "Rock_Stone_Brick_Smooth"
    },
    {
      "x": -5,
      "y": 8,
      "z": -4,
      "name": "Rock_Stone_Brick_Smooth"
    },
    {
      "x": -5,
      "y": 9,
      "z": -4,
      "name": "Rock_Stone_Brick_Stairs",
      "rotation": 1
    },
    {
      "x": -5,
      "y": 16,
      "z": -4,
      "name": "Rock_Stone_Half",
      "rotation": 8
    },
    {
      "x": -5,
      "y": 5,
      "z": -3,
      "name": "Rock_Stone_Brick"
    },
    {
      "x": -5,
      "y": 6,
      "z": -3,
      "name": "Rock_Stone_Brick_Smooth"
    },
    {
      "x": -5,
      "y": 16,
      "z": -3,
      "name": "Rock_Stone_Half",
      "rotation": 8
    },
    {
      "x": -5,
      "y": 2,
      "z": -2,
      "name": "Rock_Stone"
    },
    {
      "x": -5,
      "y": 3,
      "z": -2,
      "name": "Rock_Stone_Brick"
    },
    {
      "x": -5,
      "y": 4,
      "z": -2,
      "name": "Rock_Stone_Brick"
    },
    {
      "x": -5,
      "y": 5,
      "z": -2,
      "name": "Rock_Stone_Brick"
    },
    {
      "x": -5,
      "y": 6,
      "z": -2,
      "name": "Rock_Stone_Brick_Smooth"
    },
    {
      "x": -5,
      "y": 7,
      "z": -2,
      "name": "Rock_Stone_Brick_Wall"
    },
    {
      "x": -5,
      "y": 16,
      "z": -2,
      "name": "Rock_Stone_Brick"
    },
    {
      "x": -5,
      "y": 2,
      "z": -1,
      "name": "Rock_Stone"
    },
    {
      "x": -5,
      "y": 16,
      "z": -1,
      "name": "Rock_Stone_Half",
      "rotation": 8
    },
    {
      "x": -5,
      "y": 2,
      "z": 0,
      "name": "Rock_Stone"
    },
    {
      "x": -5,
      "y": 16,
      "z": 0,
      "name": "Rock_Stone_Half",
      "rotation": 8
    },
    {
      "x": -5,
      "y": 2,
      "z": 1,
      "name": "Rock_Stone"
    },
    {
      "x": -5,
      "y": 16,
      "z": 1,
      "name": "Rock_Stone_Half",
      "rotation": 8
    },
    {
      "x": -5,
      "y": 2,
      "z": 2,
      "name": "Rock_Stone"
    },
    {
      "x": -5,
      "y": 16,
      "z": 2,
      "name": "Rock_Stone_Brick"
    },
    {
      "x": -5,
      "y": 2,
      "z": 3,
      "name": "Rock_Stone"
    },
    {
      "x": -5,
      "y": 16,
      "z": 3,
      "name": "Rock_Stone_Half",
      "rotation": 8
    },
    {
      "x": -5,
      "y": 2,
      "z": 4,
      "name": "Rock_Stone"
    },
    {
      "x": -5,
      "y": 3,
      "z": 4,
      "name": "Rock_Stone_Brick"
    },
    {
      "x": -5,
      "y": 4,
      "z": 4,
      "name": "Rock_Stone_Brick"
    },
    {
      "x": -5,
      "y": 5,
      "z": 4,
      "name": "Rock_Stone_Brick"
    },
    {
      "x": -5,
      "y": 6,
      "z": 4,
      "name": "Rock_Stone_Brick_Smooth"
    },
    {
      "x": -5,
      "y": 7,
      "z": 4,
      "name": "Rock_Stone_Brick_Smooth"
    },
    {
      "x": -5,
      "y": 8,
      "z": 4,
      "name": "Rock_Stone_Brick_Smooth"
    },
    {
      "x": -5,
      "y": 9,
      "z": 4,
      "name": "Rock_Stone_Brick_Decorative"
    },
    {
      "x": -5,
      "y": 10,
      "z": 4,
      "name": "Rock_Stone_Brick_Wall"
    },
    {
      "x": -5,
      "y": 15,
      "z": 4,
      "name": "Rock_Stone_Brick_Decorative"
    },
    {
      "x": -5,
      "y": 16,
      "z": 4,
      "name": "Rock_Stone_Brick"
    },
    {
      "x": -5,
      "y": 9,
      "z": 5,
      "name": "Rock_Stone_Brick_Smooth"
    },
    {
      "x": -5,
      "y": 15,
      "z": 5,
      "name": "Rock_Stone_Brick_Smooth"
    },
    {
      "x": -5,
      "y": 9,
      "z": 6,
      "name": "Rock_Stone_Brick_Smooth"
    },
    {
      "x": -5,
      "y": 15,
      "z": 6,
      "name": "Rock_Stone_Brick_Smooth"
    },
    {
      "x": -5,
      "y": 9,
      "z": 7,
      "name": "Rock_Stone_Brick_Smooth"
    },
    {
      "x": -5,
      "y": 15,
      "z": 7,
      "name": "Rock_Stone_Brick_Smooth"
    },
    {
      "x": -5,
      "y": 9,
      "z": 8,
      "name": "Rock_Stone_Brick_Smooth"
    },
    {
      "x": -5,
      "y": 15,
      "z": 8,
      "name": "Rock_Stone_Brick_Smooth"
    },
    {
      "x": -5,
      "y": 9,
      "z": 9,
      "name": "Rock_Stone_Brick_Smooth"
    },
    {
      "x": -5,
      "y": 15,
      "z": 9,
      "name": "Rock_Stone_Brick_Smooth"
    },
    {
      "x": -5,
      "y": 10,
      "z": 10,
      "name": "Rock_Stone_Brick_Decorative"
    },
    {
      "x": -5,
      "y": 11,
      "z": 10,
      "name": "Soil_Gravel_Half",
      "support": 15,
      "rotation": 6
    },
    {
      "x": -5,
      "y": 12,
      "z": 10,
      "name": "Soil_Gravel_Half",
      "support": 15,
      "rotation": 6
    },
    {
      "x": -5,
      "y": 13,
      "z": 10,
      "name": "Soil_Gravel_Half",
      "support": 15,
      "rotation": 6
    },
    {
      "x": -5,
      "y": 14,
      "z": 10,
      "name": "Soil_Gravel_Half",
      "support": 15,
      "rotation": 6
    },
    {
      "x": -5,
      "y": 15,
      "z": 10,
      "name": "Rock_Stone_Brick"
    },
    {
      "x": -4,
      "y": 10,
      "z": -11,
      "name": "Rock_Stone_Brick_Decorative"
    },
    {
      "x": -4,
      "y": 11,
      "z": -11,
      "name": "Soil_Gravel_Half",
      "support": 15,
      "rotation": 4
    },
    {
      "x": -4,
      "y": 12,
      "z": -11,
      "name": "Soil_Gravel_Half",
      "support": 15,
      "rotation": 4
    },
    {
      "x": -4,
      "y": 13,
      "z": -11,
      "name": "Soil_Gravel_Half",
      "support": 15,
      "rotation": 4
    },
    {
      "x": -4,
      "y": 14,
      "z": -11,
      "name": "Soil_Gravel_Half",
      "support": 15,
      "rotation": 4
    },
    {
      "x": -4,
      "y": 15,
      "z": -11,
      "name": "Rock_Stone_Brick"
    },
    {
      "x": -4,
      "y": 9,
      "z": -10,
      "name": "Rock_Stone_Brick_Smooth"
    },
    {
      "x": -4,
      "y": 15,
      "z": -10,
      "name": "Rock_Stone_Brick_Smooth"
    },
    {
      "x": -4,
      "y": 9,
      "z": -9,
      "name": "Rock_Stone_Brick_Smooth"
    },
    {
      "x": -4,
      "y": 15,
      "z": -9,
      "name": "Rock_Stone_Brick_Smooth"
    },
    {
      "x": -4,
      "y": 9,
      "z": -8,
      "name": "Rock_Stone_Brick_Smooth"
    },
    {
      "x": -4,
      "y": 15,
      "z": -8,
      "name": "Rock_Stone_Brick_Smooth"
    },
    {
      "x": -4,
      "y": 9,
      "z": -7,
      "name": "Rock_Stone_Brick_Smooth"
    },
    {
      "x": -4,
      "y": 15,
      "z": -7,
      "name": "Rock_Stone_Brick_Smooth"
    },
    {
      "x": -4,
      "y": 7,
      "z": -6,
      "name": "Rock_Stone_Brick_Smooth"
    },
    {
      "x": -4,
      "y": 8,
      "z": -6,
      "name": "Rock_Stone_Brick_Smooth"
    },
    {
      "x": -4,
      "y": 9,
      "z": -6,
      "name": "Rock_Stone_Brick_Decorative"
    },
    {
      "x": -4,
      "y": 15,
      "z": -6,
      "name": "Rock_Stone_Brick_Decorative"
    },
    {
      "x": -4,
      "y": 16,
      "z": -6,
      "name": "Rock_Stone_Brick"
    },
    {
      "x": -4,
      "y": 8,
      "z": -5,
      "name": "Rock_Stone_Brick_Stairs",
      "rotation": 1
    },
    {
      "x": -4,
      "y": 16,
      "z": -5,
      "name": "Rock_Stone_Half",
      "rotation": 8
    },
    {
      "x": -4,
      "y": 7,
      "z": -4,
      "name": "Rock_Stone_Brick_Smooth"
    },
    {
      "x": -4,
      "y": 8,
      "z": -4,
      "name": "Rock_Stone_Brick_Stairs",
      "rotation": 1
    },
    {
      "x": -4,
      "y": 16,
      "z": -4,
      "name": "Rock_Stone_Half",
      "rotation": 8
    },
    {
      "x": -4,
      "y": 5,
      "z": -3,
      "name": "Rock_Stone_Brick"
    },
    {
      "x": -4,
      "y": 6,
      "z": -3,
      "name": "Rock_Stone_Brick_Smooth"
    },
    {
      "x": -4,
      "y": 16,
      "z": -3,
      "name": "Rock_Stone_Half",
      "rotation": 8
    },
    {
      "x": -4,
      "y": 2,
      "z": -2,
      "name": "Rock_Stone"
    },
    {
      "x": -4,
      "y": 3,
      "z": -2,
      "name": "Rock_Stone_Brick"
    },
    {
      "x": -4,
      "y": 4,
      "z": -2,
      "name": "Rock_Stone_Brick"
    },
    {
      "x": -4,
      "y": 5,
      "z": -2,
      "name": "Rock_Stone_Brick"
    },
    {
      "x": -4,
      "y": 6,
      "z": -2,
      "name": "Rock_Stone_Brick_Smooth"
    },
    {
      "x": -4,
      "y": 16,
      "z": -2,
      "name": "Rock_Stone_Brick"
    },
    {
      "x": -4,
      "y": 2,
      "z": -1,
      "name": "Rock_Stone"
    },
    {
      "x": -4,
      "y": 16,
      "z": -1,
      "name": "Rock_Stone_Half",
      "rotation": 8
    },
    {
      "x": -4,
      "y": 2,
      "z": 0,
      "name": "Rock_Stone"
    },
    {
      "x": -4,
      "y": 16,
      "z": 0,
      "name": "Rock_Stone_Half",
      "rotation": 8
    },
    {
      "x": -4,
      "y": 2,
      "z": 1,
      "name": "Rock_Stone"
    },
    {
      "x": -4,
      "y": 16,
      "z": 1,
      "name": "Rock_Stone_Half",
      "rotation": 8
    },
    {
      "x": -4,
      "y": 2,
      "z": 2,
      "name": "Rock_Stone"
    },
    {
      "x": -4,
      "y": 16,
      "z": 2,
      "name": "Rock_Stone_Brick"
    },
    {
      "x": -4,
      "y": 2,
      "z": 3,
      "name": "Rock_Stone"
    },
    {
      "x": -4,
      "y": 16,
      "z": 3,
      "name": "Rock_Stone_Half",
      "rotation": 8
    },
    {
      "x": -4,
      "y": 2,
      "z": 4,
      "name": "Rock_Stone"
    },
    {
      "x": -4,
      "y": 3,
      "z": 4,
      "name": "Rock_Stone_Brick"
    },
    {
      "x": -4,
      "y": 4,
      "z": 4,
      "name": "Rock_Stone_Brick"
    },
    {
      "x": -4,
      "y": 5,
      "z": 4,
      "name": "Rock_Stone_Brick"
    },
    {
      "x": -4,
      "y": 6,
      "z": 4,
      "name": "Rock_Stone_Brick_Smooth"
    },
    {
      "x": -4,
      "y": 7,
      "z": 4,
      "name": "Rock_Stone_Brick_Smooth"
    },
    {
      "x": -4,
      "y": 8,
      "z": 4,
      "name": "Rock_Stone_Brick_Smooth"
    },
    {
      "x": -4,
      "y": 9,
      "z": 4,
      "name": "Rock_Stone_Brick_Decorative"
    },
    {
      "x": -4,
      "y": 10,
      "z": 4,
      "name": "Rock_Stone_Brick_Wall"
    },
    {
      "x": -4,
      "y": 15,
      "z": 4,
      "name": "Rock_Stone_Brick_Decorative"
    },
    {
      "x": -4,
      "y": 16,
      "z": 4,
      "name": "Rock_Stone_Brick"
    },
    {
      "x": -4,
      "y": 9,
      "z": 5,
      "name": "Rock_Stone_Brick_Smooth"
    },
    {
      "x": -4,
      "y": 15,
      "z": 5,
      "name": "Rock_Stone_Brick_Smooth"
    },
    {
      "x": -4,
      "y": 9,
      "z": 6,
      "name": "Rock_Stone_Brick_Smooth"
    },
    {
      "x": -4,
      "y": 15,
      "z": 6,
      "name": "Rock_Stone_Brick_Smooth"
    },
    {
      "x": -4,
      "y": 9,
      "z": 7,
      "name": "Rock_Stone_Brick_Smooth"
    },
    {
      "x": -4,
      "y": 15,
      "z": 7,
      "name": "Rock_Stone_Brick_Smooth"
    },
    {
      "x": -4,
      "y": 9,
      "z": 8,
      "name": "Rock_Stone_Brick_Smooth"
    },
    {
      "x": -4,
      "y": 15,
      "z": 8,
      "name": "Rock_Stone_Brick_Smooth"
    },
    {
      "x": -4,
      "y": 9,
      "z": 9,
      "name": "Rock_Stone_Brick_Smooth"
    },
    {
      "x": -4,
      "y": 15,
      "z": 9,
      "name": "Rock_Stone_Brick_Smooth"
    },
    {
      "x": -4,
      "y": 10,
      "z": 10,
      "name": "Rock_Stone_Brick_Smooth"
    },
    {
      "x": -4,
      "y": 11,
      "z": 10,
      "name": "Rock_Stone_Brick_Pillar_Base"
    },
    {
      "x": -4,
      "y": 12,
      "z": 10,
      "name": "Rock_Stone_Brick_Pillar_Middle"
    },
    {
      "x": -4,
      "y": 13,
      "z": 10,
      "name": "Rock_Stone_Brick_Pillar_Middle"
    },
    {
      "x": -4,
      "y": 14,
      "z": 10,
      "name": "Rock_Stone_Brick_Pillar_Base",
      "rotation": 8
    },
    {
      "x": -4,
      "y": 15,
      "z": 10,
      "name": "Rock_Stone_Brick"
    },
    {
      "x": -4,
      "y": 10,
      "z": 11,
      "name": "Rock_Stone_Brick_Decorative"
    },
    {
      "x": -4,
      "y": 11,
      "z": 11,
      "name": "Soil_Gravel_Half",
      "support": 15,
      "rotation": 5
    },
    {
      "x": -4,
      "y": 12,
      "z": 11,
      "name": "Soil_Gravel_Half",
      "support": 15,
      "rotation": 5
    },
    {
      "x": -4,
      "y": 13,
      "z": 11,
      "name": "Soil_Gravel_Half",
      "support": 15,
      "rotation": 5
    },
    {
      "x": -4,
      "y": 14,
      "z": 11,
      "name": "Soil_Gravel_Half",
      "support": 15,
      "rotation": 5
    },
    {
      "x": -4,
      "y": 15,
      "z": 11,
      "name": "Rock_Stone_Brick"
    },
    {
      "x": -4,
      "y": 10,
      "z": 12,
      "name": "Rock_Stone_Brick_Decorative"
    },
    {
      "x": -4,
      "y": 11,
      "z": 12,
      "name": "Soil_Gravel_Half",
      "support": 15,
      "rotation": 5
    },
    {
      "x": -4,
      "y": 12,
      "z": 12,
      "name": "Soil_Gravel_Half",
      "support": 15,
      "rotation": 5
    },
    {
      "x": -4,
      "y": 13,
      "z": 12,
      "name": "Soil_Gravel_Half",
      "support": 15,
      "rotation": 5
    },
    {
      "x": -4,
      "y": 14,
      "z": 12,
      "name": "Soil_Gravel_Half",
      "support": 15,
      "rotation": 5
    },
    {
      "x": -4,
      "y": 15,
      "z": 12,
      "name": "Rock_Stone_Brick"
    },
    {
      "x": -4,
      "y": 10,
      "z": 13,
      "name": "Rock_Stone_Brick_Decorative"
    },
    {
      "x": -4,
      "y": 11,
      "z": 13,
      "name": "Soil_Gravel_Half",
      "support": 15,
      "rotation": 5
    },
    {
      "x": -4,
      "y": 12,
      "z": 13,
      "name": "Soil_Gravel_Half",
      "support": 15,
      "rotation": 5
    },
    {
      "x": -4,
      "y": 13,
      "z": 13,
      "name": "Soil_Gravel_Half",
      "support": 15,
      "rotation": 5
    },
    {
      "x": -4,
      "y": 14,
      "z": 13,
      "name": "Soil_Gravel_Half",
      "support": 15,
      "rotation": 5
    },
    {
      "x": -4,
      "y": 15,
      "z": 13,
      "name": "Rock_Stone_Brick"
    },
    {
      "x": -4,
      "y": 10,
      "z": 14,
      "name": "Rock_Stone_Brick_Decorative"
    },
    {
      "x": -4,
      "y": 11,
      "z": 14,
      "name": "Rock_Stone_Brick"
    },
    {
      "x": -4,
      "y": 12,
      "z": 14,
      "name": "Rock_Stone_Brick"
    },
    {
      "x": -4,
      "y": 13,
      "z": 14,
      "name": "Rock_Stone_Brick"
    },
    {
      "x": -4,
      "y": 14,
      "z": 14,
      "name": "Rock_Stone_Brick"
    },
    {
      "x": -4,
      "y": 15,
      "z": 14,
      "name": "Rock_Stone_Brick"
    },
    {
      "x": -3,
      "y": 9,
      "z": -16,
      "name": "Rock_Stone_Brick"
    },
    {
      "x": -3,
      "y": 10,
      "z": -16,
      "name": "Rock_Stone_Brick_Decorative"
    },
    {
      "x": -3,
      "y": 11,
      "z": -16,
      "name": "Rock_Stone_Brick"
    },
    {
      "x": -3,
      "y": 12,
      "z": -16,
      "name": "Rock_Stone_Brick"
    },
    {
      "x": -3,
      "y": 13,
      "z": -16,
      "name": "Rock_Stone_Brick"
    },
    {
      "x": -3,
      "y": 14,
      "z": -16,
      "name": "Rock_Stone_Brick"
    },
    {
      "x": -3,
      "y": 15,
      "z": -16,
      "name": "Rock_Stone_Brick"
    },
    {
      "x": -3,
      "y": 10,
      "z": -15,
      "name": "Rock_Stone_Brick_Decorative"
    },
    {
      "x": -3,
      "y": 11,
      "z": -15,
      "name": "Soil_Gravel_Half",
      "support": 15,
      "rotation": 5
    },
    {
      "x": -3,
      "y": 12,
      "z": -15,
      "name": "Soil_Gravel_Half",
      "support": 15,
      "rotation": 5
    },
    {
      "x": -3,
      "y": 13,
      "z": -15,
      "name": "Soil_Gravel_Half",
      "support": 15,
      "rotation": 5
    },
    {
      "x": -3,
      "y": 14,
      "z": -15,
      "name": "Soil_Gravel_Half",
      "support": 15,
      "rotation": 5
    },
    {
      "x": -3,
      "y": 15,
      "z": -15,
      "name": "Rock_Stone_Brick"
    },
    {
      "x": -3,
      "y": 10,
      "z": -14,
      "name": "Rock_Stone_Brick_Decorative"
    },
    {
      "x": -3,
      "y": 11,
      "z": -14,
      "name": "Soil_Gravel_Half",
      "support": 15,
      "rotation": 5
    },
    {
      "x": -3,
      "y": 12,
      "z": -14,
      "name": "Soil_Gravel_Half",
      "support": 15,
      "rotation": 5
    },
    {
      "x": -3,
      "y": 13,
      "z": -14,
      "name": "Soil_Gravel_Half",
      "support": 15,
      "rotation": 5
    },
    {
      "x": -3,
      "y": 14,
      "z": -14,
      "name": "Soil_Gravel_Half",
      "support": 15,
      "rotation": 5
    },
    {
