{
  "version": 8,
  "blockIdVersion": 11,
  "anchorX": 0,
  "anchorY": 0,
  "anchorZ": 0,
  "blocks": [
    {
      "x": -9,
      "y": 4,
      "z": -7,
      "name": "Rock_Sandstone_Cobble"
    },
    {
      "x": -9,
      "y": 5,
      "z": -7,
      "name": "Rock_Sandstone_Cobble"
    },
    {
      "x": -9,
      "y": 6,
      "z": -7,
      "name": "Rock_Sandstone_Cobble"
    },
    {
      "x": -9,
      "y": 7,
      "z": -7,
      "name": "Rock_Sandstone_Cobble"
    },
    {
      "x": -9,
      "y": 3,
      "z": -6,
      "name": "Rock_Sandstone_Cobble"
    },
    {
      "x": -9,
      "y": 4,
      "z": -6,
      "name": "Rock_Sandstone_Cobble"
    },
    {
      "x": -9,
      "y": 5,
      "z": -6,
      "name": "Rock_Sandstone_Cobble"
    },
    {
      "x": -9,
      "y": 6,
      "z": -6,
      "name": "Rock_Sandstone_Cobble"
    },
    {
      "x": -9,
      "y": 7,
      "z": -6,
      "name": "Rock_Sandstone_Cobble"
    },
    {
      "x": -9,
      "y": 8,
      "z": -6,
      "name": "Rock_Sandstone_Cobble"
    },
    {
      "x": -9,
      "y": 9,
      "z": -6,
      "name": "Rock_Sandstone_Cobble"
    },
    {
      "x": -9,
      "y": 2,
      "z": -5,
      "name": "Rock_Sandstone_Cobble"
    },
    {
      "x": -9,
      "y": 3,
      "z": -5,
      "name": "Rock_Sandstone_Cobble"
    },
    {
      "x": -9,
      "y": 4,
      "z": -5,
      "name": "Rock_Sandstone_Cobble"
    },
    {
      "x": -9,
      "y": 5,
      "z": -5,
      "name": "Rock_Sandstone_Cobble"
    },
    {
      "x": -9,
      "y": 6,
      "z": -5,
      "name": "Rock_Sandstone_Cobble"
    },
    {
      "x": -9,
      "y": 7,
      "z": -5,
      "name": "Rock_Sandstone_Cobble"
    },
    {
      "x": -9,
      "y": 8,
      "z": -5,
      "name": "Rock_Sandstone_Cobble"
    },
    {
      "x": -9,
      "y": 9,
      "z": -5,
      "name": "Rock_Sandstone_Cobble"
    },
    {
      "x": -9,
      "y": 10,
      "z": -5,
      "name": "Rock_Sandstone_Brick"
    },
    {
      "x": -9,
      "y": 11,
      "z": -5,
      "name": "Rock_Sandstone_Brick"
    },
    {
      "x": -9,
      "y": 12,
      "z": -5,
      "name": "Rock_Sandstone_Brick"
    },
    {
      "x": -9,
      "y": 13,
      "z": -5,
      "name": "Rock_Sandstone_Brick"
    },
    {
      "x": -9,
      "y": 14,
      "z": -5,
      "name": "Rock_Sandstone_Brick"
    },
    {
      "x": -9,
      "y": 15,
      "z": -5,
      "name": "Rock_Sandstone_Brick"
    },
    {
      "x": -9,
      "y": 16,
      "z": -5,
      "name": "Rock_Sandstone_Brick"
    },
    {
      "x": -9,
      "y": 17,
      "z": -5,
      "name": "Rock_Sandstone_Brick"
    },
    {
      "x": -9,
      "y": 18,
      "z": -5,
      "name": "Rock_Sandstone_Brick"
    },
    {
      "x": -9,
      "y": 19,
      "z": -5,
      "name": "Rock_Sandstone_Brick"
    },
    {
      "x": -9,
      "y": 20,
      "z": -5,
      "name": "Rock_Sandstone_Brick"
    },
    {
      "x": -9,
      "y": 21,
      "z": -5,
      "name": "Rock_Sandstone_Brick"
    },
    {
      "x": -9,
      "y": 22,
      "z": -5,
      "name": "Rock_Sandstone_Brick"
    },
    {
      "x": -9,
      "y": 1,
      "z": -4,
      "name": "Rock_Sandstone_Cobble"
    },
    {
      "x": -9,
      "y": 2,
      "z": -4,
      "name": "Rock_Sandstone_Cobble"
    },
    {
      "x": -9,
      "y": 3,
      "z": -4,
      "name": "Rock_Sandstone_Cobble"
    },
    {
      "x": -9,
      "y": 4,
      "z": -4,
      "name": "Rock_Sandstone_Cobble"
    },
    {
      "x": -9,
      "y": 5,
      "z": -4,
      "name": "Rock_Sandstone_Cobble"
    },
    {
      "x": -9,
      "y": 6,
      "z": -4,
      "name": "Rock_Sandstone_Cobble"
    },
    {
      "x": -9,
      "y": 7,
      "z": -4,
      "name": "Rock_Sandstone_Cobble"
    },
    {
      "x": -9,
      "y": 8,
      "z": -4,
      "name": "Rock_Sandstone_Cobble"
    },
    {
      "x": -9,
      "y": 9,
      "z": -4,
      "name": "Rock_Sandstone_Cobble"
    },
    {
      "x": -9,
      "y": 10,
      "z": -4,
      "name": "Rock_Sandstone_Cobble"
    },
    {
      "x": -9,
      "y": 11,
      "z": -4,
      "name": "Rock_Sandstone_Cobble"
    },
    {
      "x": -9,
      "y": 12,
      "z": -4,
      "name": "Rock_Sandstone_Cobble"
    },
    {
      "x": -9,
      "y": 13,
      "z": -4,
      "name": "Rock_Sandstone_Cobble"
    },
    {
      "x": -9,
      "y": 14,
      "z": -4,
      "name": "Rock_Sandstone_Cobble"
    },
    {
      "x": -9,
      "y": 15,
      "z": -4,
      "name": "Rock_Sandstone_Cobble"
    },
    {
      "x": -9,
      "y": 16,
      "z": -4,
      "name": "Rock_Sandstone_Cobble"
    },
    {
      "x": -9,
      "y": 17,
      "z": -4,
      "name": "Rock_Sandstone_Cobble"
    },
    {
      "x": -9,
      "y": 18,
      "z": -4,
      "name": "Rock_Sandstone_Cobble"
    },
    {
      "x": -9,
      "y": 19,
      "z": -4,
      "name": "Rock_Sandstone_Cobble"
    },
    {
      "x": -9,
      "y": 20,
      "z": -4,
      "name": "Rock_Sandstone_Cobble"
    },
    {
      "x": -9,
      "y": 21,
      "z": -4,
      "name": "Rock_Sandstone_Cobble"
    },
    {
      "x": -9,
      "y": 1,
      "z": -3,
      "name": "Rock_Sandstone_Cobble"
    },
    {
      "x": -9,
      "y": 2,
      "z": -3,
      "name": "Rock_Sandstone_Cobble"
    },
    {
      "x": -9,
      "y": 3,
      "z": -3,
      "name": "Rock_Sandstone_Cobble"
    },
    {
      "x": -9,
      "y": 4,
      "z": -3,
      "name": "Rock_Sandstone_Cobble"
    },
    {
      "x": -9,
      "y": 5,
      "z": -3,
      "name": "Rock_Sandstone_Cobble"
    },
    {
      "x": -9,
      "y": 6,
      "z": -3,
      "name": "Rock_Sandstone_Cobble"
    },
    {
      "x": -9,
      "y": 7,
      "z": -3,
      "name": "Rock_Sandstone_Cobble"
    },
    {
      "x": -9,
      "y": 8,
      "z": -3,
      "name": "Rock_Sandstone_Cobble"
    },
    {
      "x": -9,
      "y": 9,
      "z": -3,
      "name": "Rock_Sandstone_Cobble"
    },
    {
      "x": -9,
      "y": 10,
      "z": -3,
      "name": "Rock_Sandstone_Cobble"
    },
    {
      "x": -9,
      "y": 11,
      "z": -3,
      "name": "Rock_Sandstone_Cobble"
    },
    {
      "x": -9,
      "y": 12,
      "z": -3,
      "name": "Rock_Sandstone_Cobble"
    },
    {
      "x": -9,
      "y": 13,
      "z": -3,
      "name": "Rock_Sandstone_Cobble"
    },
    {
      "x": -9,
      "y": 14,
      "z": -3,
      "name": "Rock_Sandstone_Cobble"
    },
    {
      "x": -9,
      "y": 15,
      "z": -3,
      "name": "Rock_Sandstone_Cobble"
    },
    {
      "x": -9,
      "y": 16,
      "z": -3,
      "name": "Rock_Sandstone_Cobble"
    },
    {
      "x": -9,
      "y": 17,
      "z": -3,
      "name": "Rock_Sandstone_Cobble"
    },
    {
      "x": -9,
      "y": 18,
      "z": -3,
      "name": "Rock_Sandstone_Cobble"
    },
    {
      "x": -9,
      "y": 19,
      "z": -3,
      "name": "Rock_Sandstone_Cobble"
    },
    {
      "x": -9,
      "y": 20,
      "z": -3,
      "name": "Rock_Sandstone_Cobble"
    },
    {
      "x": -9,
      "y": 21,
      "z": -3,
      "name": "Rock_Sandstone_Cobble"
    },
    {
      "x": -9,
      "y": 0,
      "z": -2,
      "name": "Rock_Sandstone_Cobble"
    },
    {
      "x": -9,
      "y": 1,
      "z": -2,
      "name": "Rock_Sandstone_Cobble"
    },
    {
      "x": -9,
      "y": 2,
      "z": -2,
      "name": "Rock_Sandstone_Cobble"
    },
    {
      "x": -9,
      "y": 3,
      "z": -2,
      "name": "Rock_Sandstone_Cobble"
    },
    {
      "x": -9,
      "y": 4,
      "z": -2,
      "name": "Rock_Sandstone_Cobble"
    },
    {
      "x": -9,
      "y": 5,
      "z": -2,
      "name": "Rock_Sandstone_Cobble"
    },
    {
      "x": -9,
      "y": 6,
      "z": -2,
      "name": "Rock_Sandstone_Cobble"
    },
    {
      "x": -9,
      "y": 7,
      "z": -2,
      "name": "Rock_Sandstone_Cobble"
    },
    {
      "x": -9,
      "y": 8,
      "z": -2,
      "name": "Rock_Sandstone_Cobble"
    },
    {
      "x": -9,
      "y": 9,
      "z": -2,
      "name": "Rock_Sandstone_Cobble"
    },
    {
      "x": -9,
      "y": 10,
      "z": -2,
      "name": "Rock_Sandstone_Cobble"
    },
    {
      "x": -9,
      "y": 11,
      "z": -2,
      "name": "Rock_Sandstone_Cobble"
    },
    {
      "x": -9,
      "y": 12,
      "z": -2,
      "name": "Rock_Sandstone_Cobble"
    },
    {
      "x": -9,
      "y": 13,
      "z": -2,
      "name": "Rock_Sandstone_Cobble"
    },
    {
      "x": -9,
      "y": 14,
      "z": -2,
      "name": "Rock_Sandstone_Cobble"
    },
    {
      "x": -9,
      "y": 15,
      "z": -2,
      "name": "Rock_Sandstone_Cobble"
    },
    {
      "x": -9,
      "y": 16,
      "z": -2,
      "name": "Rock_Sandstone_Cobble"
    },
    {
      "x": -9,
      "y": 17,
      "z": -2,
      "name": "Rock_Sandstone_Cobble"
    },
    {
      "x": -9,
      "y": 18,
      "z": -2,
      "name": "Rock_Sandstone_Cobble"
    },
    {
      "x": -9,
      "y": 19,
      "z": -2,
      "name": "Rock_Sandstone_Cobble"
    },
    {
      "x": -9,
      "y": 20,
      "z": -2,
      "name": "Rock_Sandstone_Cobble"
    },
    {
      "x": -9,
      "y": 21,
      "z": -2,
      "name": "Rock_Sandstone_Cobble"
    },
    {
      "x": -9,
      "y": 0,
      "z": -1,
      "name": "Rock_Sandstone_Cobble"
    },
    {
      "x": -9,
      "y": 1,
      "z": -1,
      "name": "Rock_Sandstone_Cobble"
    },
    {
      "x": -9,
      "y": 2,
      "z": -1,
      "name": "Rock_Sandstone_Cobble"
    },
    {
      "x": -9,
      "y": 3,
      "z": -1,
      "name": "Rock_Sandstone_Cobble"
    },
    {
      "x": -9,
      "y": 4,
      "z": -1,
      "name": "Rock_Sandstone_Cobble"
    },
    {
      "x": -9,
      "y": 5,
      "z": -1,
      "name": "Rock_Sandstone_Cobble"
    },
    {
      "x": -9,
      "y": 6,
      "z": -1,
      "name": "Rock_Sandstone_Cobble"
    },
    {
      "x": -9,
      "y": 7,
      "z": -1,
      "name": "Rock_Sandstone_Cobble"
    },
    {
      "x": -9,
      "y": 8,
      "z": -1,
      "name": "Rock_Sandstone_Cobble"
    },
    {
      "x": -9,
      "y": 9,
      "z": -1,
      "name": "Rock_Sandstone_Cobble"
    },
    {
      "x": -9,
      "y": 10,
      "z": -1,
      "name": "Rock_Sandstone_Cobble"
    },
    {
      "x": -9,
      "y": 11,
      "z": -1,
      "name": "Rock_Sandstone_Cobble"
    },
    {
      "x": -9,
      "y": 12,
      "z": -1,
      "name": "Rock_Sandstone_Cobble"
    },
    {
      "x": -9,
      "y": 13,
      "z": -1,
      "name": "Rock_Sandstone_Cobble"
    },
    {
      "x": -9,
      "y": 14,
      "z": -1,
      "name": "Rock_Sandstone_Cobble"
    },
    {
      "x": -9,
      "y": 15,
      "z": -1,
      "name": "Rock_Sandstone_Cobble"
    },
    {
      "x": -9,
      "y": 16,
      "z": -1,
      "name": "Rock_Sandstone_Cobble"
    },
    {
      "x": -9,
      "y": 17,
      "z": -1,
      "name": "Rock_Sandstone_Cobble"
    },
    {
      "x": -9,
      "y": 18,
      "z": -1,
      "name": "Rock_Sandstone_Cobble"
    },
    {
      "x": -9,
      "y": 19,
      "z": -1,
      "name": "Rock_Sandstone_Cobble"
    },
    {
      "x": -9,
      "y": 20,
      "z": -1,
      "name": "Rock_Sandstone_Cobble"
    },
    {
      "x": -9,
      "y": 21,
      "z": -1,
      "name": "Rock_Sandstone_Cobble"
    },
    {
      "x": -9,
      "y": 0,
      "z": 0,
      "name": "Rock_Sandstone_Cobble"
    },
    {
      "x": -9,
      "y": 1,
      "z": 0,
      "name": "Rock_Sandstone_Cobble"
    },
    {
      "x": -9,
      "y": 2,
      "z": 0,
      "name": "Rock_Sandstone_Cobble"
    },
    {
      "x": -9,
      "y": 3,
      "z": 0,
      "name": "Rock_Sandstone_Cobble"
    },
    {
      "x": -9,
      "y": 4,
      "z": 0,
      "name": "Rock_Sandstone_Cobble"
    },
    {
      "x": -9,
      "y": 5,
      "z": 0,
      "name": "Rock_Sandstone_Cobble"
    },
    {
      "x": -9,
      "y": 6,
      "z": 0,
      "name": "Rock_Sandstone_Cobble"
    },
    {
      "x": -9,
      "y": 7,
      "z": 0,
      "name": "Rock_Sandstone_Cobble"
    },
    {
      "x": -9,
      "y": 8,
      "z": 0,
      "name": "Rock_Sandstone_Cobble"
    },
    {
      "x": -9,
      "y": 9,
      "z": 0,
      "name": "Rock_Sandstone_Cobble"
    },
    {
      "x": -9,
      "y": 10,
      "z": 0,
      "name": "Rock_Sandstone_Cobble"
    },
    {
      "x": -9,
      "y": 11,
      "z": 0,
      "name": "Rock_Sandstone_Cobble"
    },
    {
      "x": -9,
      "y": 12,
      "z": 0,
      "name": "Rock_Sandstone_Cobble"
    },
    {
      "x": -9,
      "y": 13,
      "z": 0,
      "name": "Rock_Sandstone_Cobble"
    },
    {
      "x": -9,
      "y": 14,
      "z": 0,
      "name": "Rock_Sandstone_Cobble"
    },
    {
      "x": -9,
      "y": 15,
      "z": 0,
      "name": "Rock_Sandstone_Cobble"
    },
    {
      "x": -9,
      "y": 16,
      "z": 0,
      "name": "Rock_Sandstone_Cobble"
    },
    {
      "x": -9,
      "y": 17,
      "z": 0,
      "name": "Rock_Sandstone_Cobble"
    },
    {
      "x": -9,
      "y": 18,
      "z": 0,
      "name": "Rock_Sandstone_Cobble"
    },
    {
      "x": -9,
      "y": 19,
      "z": 0,
      "name": "Rock_Sandstone_Cobble"
    },
    {
      "x": -9,
      "y": 20,
      "z": 0,
      "name": "Rock_Sandstone_Cobble"
    },
    {
      "x": -9,
      "y": 21,
      "z": 0,
      "name": "Rock_Sandstone_Cobble"
    },
    {
      "x": -9,
      "y": 0,
      "z": 1,
      "name": "Rock_Sandstone_Cobble"
    },
    {
      "x": -9,
      "y": 1,
      "z": 1,
      "name": "Rock_Sandstone_Cobble"
    },
    {
      "x": -9,
      "y": 2,
      "z": 1,
      "name": "Rock_Sandstone_Cobble"
    },
    {
      "x": -9,
      "y": 3,
      "z": 1,
      "name": "Rock_Sandstone_Cobble"
    },
    {
      "x": -9,
      "y": 4,
      "z": 1,
      "name": "Rock_Sandstone_Cobble"
    },
    {
      "x": -9,
      "y": 5,
      "z": 1,
      "name": "Rock_Sandstone_Cobble"
    },
    {
      "x": -9,
      "y": 6,
      "z": 1,
      "name": "Rock_Sandstone_Cobble"
    },
    {
      "x": -9,
      "y": 7,
      "z": 1,
      "name": "Rock_Sandstone_Cobble"
    },
    {
      "x": -9,
      "y": 8,
      "z": 1,
      "name": "Rock_Sandstone_Cobble"
    },
    {
      "x": -9,
      "y": 9,
      "z": 1,
      "name": "Rock_Sandstone_Cobble"
    },
    {
      "x": -9,
      "y": 10,
      "z": 1,
      "name": "Rock_Sandstone_Cobble"
    },
    {
      "x": -9,
      "y": 11,
      "z": 1,
      "name": "Rock_Sandstone_Cobble"
    },
    {
      "x": -9,
      "y": 12,
      "z": 1,
      "name": "Rock_Sandstone_Cobble"
    },
    {
      "x": -9,
      "y": 13,
      "z": 1,
      "name": "Rock_Sandstone_Cobble"
    },
    {
      "x": -9,
      "y": 14,
      "z": 1,
      "name": "Rock_Sandstone_Cobble"
    },
    {
      "x": -9,
      "y": 15,
      "z": 1,
      "name": "Rock_Sandstone_Cobble"
    },
    {
      "x": -9,
      "y": 16,
      "z": 1,
      "name": "Rock_Sandstone_Cobble"
    },
    {
      "x": -9,
      "y": 17,
      "z": 1,
      "name": "Rock_Sandstone_Cobble"
    },
    {
      "x": -9,
      "y": 18,
      "z": 1,
      "name": "Rock_Sandstone_Cobble"
    },
    {
      "x": -9,
      "y": 19,
      "z": 1,
      "name": "Rock_Sandstone_Cobble"
    },
    {
      "x": -9,
      "y": 20,
      "z": 1,
      "name": "Rock_Sandstone_Cobble"
    },
    {
      "x": -9,
      "y": 21,
      "z": 1,
      "name": "Rock_Sandstone_Cobble"
    },
    {
      "x": -9,
      "y": 0,
      "z": 2,
      "name": "Rock_Sandstone_Cobble"
    },
    {
      "x": -9,
      "y": 1,
      "z": 2,
      "name": "Rock_Sandstone_Cobble"
    },
    {
      "x": -9,
      "y": 2,
      "z": 2,
      "name": "Rock_Sandstone_Cobble"
    },
    {
      "x": -9,
      "y": 3,
      "z": 2,
      "name": "Rock_Sandstone_Cobble"
    },
    {
      "x": -9,
      "y": 4,
      "z": 2,
      "name": "Rock_Sandstone_Cobble"
    },
    {
      "x": -9,
      "y": 5,
      "z": 2,
      "name": "Rock_Sandstone_Cobble"
    },
    {
      "x": -9,
      "y": 6,
      "z": 2,
      "name": "Rock_Sandstone_Cobble"
    },
    {
      "x": -9,
      "y": 7,
      "z": 2,
      "name": "Rock_Sandstone_Cobble"
    },
    {
      "x": -9,
      "y": 8,
      "z": 2,
      "name": "Rock_Sandstone_Cobble"
    },
    {
      "x": -9,
      "y": 9,
      "z": 2,
      "name": "Rock_Sandstone_Cobble"
    },
    {
      "x": -9,
      "y": 10,
      "z": 2,
      "name": "Rock_Sandstone_Cobble"
    },
    {
      "x": -9,
      "y": 11,
      "z": 2,
      "name": "Rock_Sandstone_Cobble"
    },
    {
      "x": -9,
      "y": 12,
      "z": 2,
      "name": "Rock_Sandstone_Cobble"
    },
    {
      "x": -9,
      "y": 13,
      "z": 2,
      "name": "Rock_Sandstone_Cobble"
    },
    {
      "x": -9,
      "y": 14,
      "z": 2,
      "name": "Rock_Sandstone_Cobble"
    },
    {
      "x": -9,
      "y": 15,
      "z": 2,
      "name": "Rock_Sandstone_Cobble"
    },
    {
      "x": -9,
      "y": 16,
      "z": 2,
      "name": "Rock_Sandstone_Cobble"
    },
    {
      "x": -9,
      "y": 17,
      "z": 2,
      "name": "Rock_Sandstone_Cobble"
    },
    {
      "x": -9,
      "y": 18,
      "z": 2,
      "name": "Rock_Sandstone_Cobble"
    },
    {
      "x": -9,
      "y": 19,
      "z": 2,
      "name": "Rock_Sandstone_Cobble"
    },
    {
      "x": -9,
      "y": 20,
      "z": 2,
      "name": "Rock_Sandstone_Cobble"
    },
    {
      "x": -9,
      "y": 21,
      "z": 2,
      "name": "Rock_Sandstone_Cobble"
    },
    {
      "x": -9,
      "y": 0,
      "z": 3,
      "name": "Rock_Sandstone_Cobble"
    },
    {
      "x": -9,
      "y": 1,
      "z": 3,
      "name": "Rock_Sandstone_Cobble"
    },
    {
      "x": -9,
      "y": 2,
      "z": 3,
      "name": "Rock_Sandstone_Cobble"
    },
    {
      "x": -9,
      "y": 3,
      "z": 3,
      "name": "Rock_Sandstone_Cobble"
    },
    {
      "x": -9,
      "y": 4,
      "z": 3,
      "name": "Rock_Sandstone_Cobble"
    },
    {
      "x": -9,
      "y": 5,
      "z": 3,
      "name": "Rock_Sandstone_Cobble"
    },
    {
      "x": -9,
      "y": 6,
      "z": 3,
      "name": "Rock_Sandstone_Cobble"
    },
    {
      "x": -9,
      "y": 7,
      "z": 3,
      "name": "Rock_Sandstone_Cobble"
    },
    {
      "x": -9,
      "y": 8,
      "z": 3,
      "name": "Rock_Sandstone_Cobble"
    },
    {
      "x": -9,
      "y": 9,
      "z": 3,
      "name": "Rock_Sandstone_Cobble"
    },
    {
      "x": -9,
      "y": 10,
      "z": 3,
      "name": "Rock_Sandstone_Cobble"
    },
    {
      "x": -9,
      "y": 11,
      "z": 3,
      "name": "Rock_Sandstone_Cobble"
    },
    {
      "x": -9,
      "y": 12,
      "z": 3,
      "name": "Rock_Sandstone_Cobble"
    },
    {
      "x": -9,
      "y": 13,
      "z": 3,
      "name": "Rock_Sandstone_Cobble"
    },
    {
      "x": -9,
      "y": 14,
      "z": 3,
      "name": "Rock_Sandstone_Cobble"
    },
    {
      "x": -9,
      "y": 15,
      "z": 3,
      "name": "Rock_Sandstone_Cobble"
    },
    {
      "x": -9,
      "y": 16,
      "z": 3,
      "name": "Rock_Sandstone_Cobble"
    },
    {
      "x": -9,
      "y": 17,
      "z": 3,
      "name": "Rock_Sandstone_Cobble"
    },
    {
      "x": -9,
      "y": 18,
      "z": 3,
      "name": "Rock_Sandstone_Cobble"
    },
    {
      "x": -9,
      "y": 19,
      "z": 3,
      "name": "Rock_Sandstone_Cobble"
    },
    {
      "x": -9,
      "y": 20,
      "z": 3,
      "name": "Rock_Sandstone_Cobble"
    },
    {
      "x": -9,
      "y": 21,
      "z": 3,
      "name": "Rock_Sandstone_Cobble"
    },
    {
      "x": -9,
      "y": 0,
      "z": 4,
      "name": "Rock_Sandstone_Cobble"
    },
    {
      "x": -9,
      "y": 1,
      "z": 4,
      "name": "Rock_Sandstone_Cobble"
    },
    {
      "x": -9,
      "y": 2,
      "z": 4,
      "name": "Rock_Sandstone_Cobble"
    },
    {
      "x": -9,
      "y": 3,
      "z": 4,
      "name": "Rock_Sandstone_Cobble"
    },
    {
      "x": -9,
      "y": 4,
      "z": 4,
      "name": "Rock_Sandstone_Cobble"
    },
    {
      "x": -9,
      "y": 5,
      "z": 4,
      "name": "Rock_Sandstone_Cobble"
    },
    {
      "x": -9,
      "y": 6,
      "z": 4,
      "name": "Rock_Sandstone_Cobble"
    },
    {
      "x": -9,
      "y": 7,
      "z": 4,
      "name": "Rock_Sandstone_Cobble"
    },
    {
      "x": -9,
      "y": 8,
      "z": 4,
      "name": "Rock_Sandstone_Cobble"
    },
    {
      "x": -9,
      "y": 9,
      "z": 4,
      "name": "Rock_Sandstone_Cobble"
    },
    {
      "x": -9,
      "y": 10,
      "z": 4,
      "name": "Rock_Sandstone_Cobble"
    },
    {
      "x": -9,
      "y": 11,
      "z": 4,
      "name": "Rock_Sandstone_Cobble"
    },
    {
      "x": -9,
      "y": 12,
      "z": 4,
      "name": "Rock_Sandstone_Cobble"
    },
    {
      "x": -9,
      "y": 13,
      "z": 4,
      "name": "Rock_Sandstone_Cobble"
    },
    {
      "x": -9,
      "y": 14,
      "z": 4,
      "name": "Rock_Sandstone_Cobble"
    },
    {
      "x": -9,
      "y": 15,
      "z": 4,
      "name": "Rock_Sandstone_Cobble"
    },
    {
      "x": -9,
      "y": 16,
      "z": 4,
      "name": "Rock_Sandstone_Cobble"
    },
    {
      "x": -9,
      "y": 17,
      "z": 4,
      "name": "Rock_Sandstone_Cobble"
    },
    {
      "x": -9,
      "y": 18,
      "z": 4,
      "name": "Rock_Sandstone_Cobble"
    },
    {
      "x": -9,
      "y": 19,
      "z": 4,
      "name": "Rock_Sandstone_Cobble"
    },
    {
      "x": -9,
      "y": 0,
      "z": 5,
      "name": "Rock_Sandstone_Cobble"
    },
    {
      "x": -9,
      "y": 1,
      "z": 5,
      "name": "Rock_Sandstone_Cobble"
    },
    {
      "x": -9,
      "y": 2,
      "z": 5,
      "name": "Rock_Sandstone_Cobble"
    },
    {
      "x": -9,
      "y": 3,
      "z": 5,
      "name": "Rock_Sandstone_Cobble"
    },
    {
      "x": -9,
      "y": 4,
      "z": 5,
      "name": "Rock_Sandstone_Cobble"
    },
    {
      "x": -9,
      "y": 5,
      "z": 5,
      "name": "Rock_Sandstone_Cobble"
    },
    {
      "x": -9,
      "y": 6,
      "z": 5,
      "name": "Rock_Sandstone_Cobble"
    },
    {
      "x": -9,
      "y": 7,
      "z": 5,
      "name": "Rock_Sandstone_Cobble"
    },
    {
      "x": -9,
      "y": 8,
      "z": 5,
      "name": "Rock_Sandstone_Cobble"
    },
    {
      "x": -9,
      "y": 9,
      "z": 5,
      "name": "Rock_Sandstone_Cobble"
    },
    {
      "x": -9,
      "y": 10,
      "z": 5,
      "name": "Rock_Sandstone_Cobble"
    },
    {
      "x": -9,
      "y": 11,
      "z": 5,
      "name": "Rock_Sandstone_Cobble"
    },
    {
      "x": -9,
      "y": 12,
      "z": 5,
      "name": "Rock_Sandstone_Cobble"
    },
    {
      "x": -9,
      "y": 13,
      "z": 5,
      "name": "Rock_Sandstone_Cobble"
    },
    {
      "x": -9,
      "y": 14,
      "z": 5,
      "name": "Rock_Sandstone_Cobble"
    },
    {
      "x": -9,
      "y": 15,
      "z": 5,
      "name": "Rock_Sandstone_Cobble"
    },
    {
      "x": -9,
      "y": 16,
      "z": 5,
      "name": "Rock_Sandstone_Cobble"
    },
    {
      "x": -9,
      "y": 17,
      "z": 5,
      "name": "Rock_Sandstone_Cobble"
    },
    {
      "x": -9,
      "y": 18,
      "z": 5,
      "name": "Rock_Sandstone_Cobble"
    },
    {
      "x": -9,
      "y": 19,
      "z": 5,
      "name": "Rock_Sandstone_Cobble"
    },
    {
      "x": -9,
      "y": 0,
      "z": 6,
      "name": "Rock_Sandstone_Cobble"
    },
    {
      "x": -9,
      "y": 1,
      "z": 6,
      "name": "Rock_Sandstone_Cobble"
    },
    {
      "x": -9,
      "y": 2,
      "z": 6,
      "name": "Rock_Sandstone_Cobble"
    },
    {
      "x": -9,
      "y": 3,
      "z": 6,
      "name": "Rock_Sandstone_Cobble"
    },
    {
      "x": -9,
      "y": 4,
      "z": 6,
      "name": "Rock_Sandstone_Cobble"
    },
    {
      "x": -9,
      "y": 5,
      "z": 6,
      "name": "Rock_Sandstone_Cobble"
    },
    {
      "x": -9,
      "y": 6,
      "z": 6,
      "name": "Rock_Sandstone_Cobble"
    },
    {
      "x": -9,
      "y": 7,
      "z": 6,
      "name": "Rock_Sandstone_Cobble"
    },
    {
      "x": -9,
      "y": 8,
      "z": 6,
      "name": "Rock_Sandstone_Cobble"
    },
    {
      "x": -9,
      "y": 9,
      "z": 6,
      "name": "Rock_Sandstone_Cobble"
    },
    {
      "x": -9,
      "y": 10,
      "z": 6,
      "name": "Rock_Sandstone_Cobble"
    },
    {
      "x": -9,
      "y": 11,
      "z": 6,
      "name": "Rock_Sandstone_Cobble"
    },
    {
      "x": -9,
      "y": 0,
      "z": 7,
      "name": "Rock_Sandstone_Cobble"
    },
    {
      "x": -9,
      "y": 1,
      "z": 7,
      "name": "Rock_Sandstone_Cobble"
    },
    {
      "x": -9,
      "y": 2,
      "z": 7,
      "name": "Rock_Sandstone_Cobble"
    },
    {
      "x": -9,
      "y": 3,
      "z": 7,
      "name": "Rock_Sandstone_Cobble"
    },
    {
      "x": -9,
      "y": 4,
      "z": 7,
      "name": "Rock_Sandstone_Cobble"
    },
    {
      "x": -9,
      "y": 5,
      "z": 7,
      "name": "Rock_Sandstone_Cobble"
    },
    {
      "x": -9,
      "y": 6,
      "z": 7,
      "name": "Rock_Sandstone_Cobble"
    },
    {
      "x": -9,
      "y": 7,
      "z": 7,
      "name": "Rock_Sandstone_Cobble"
    },
    {
      "x": -9,
      "y": 8,
      "z": 7,
      "name": "Rock_Sandstone_Cobble"
    },
    {
      "x": -9,
      "y": 9,
      "z": 7,
      "name": "Rock_Sandstone_Cobble"
    },
    {
      "x": -9,
      "y": 10,
      "z": 7,
      "name": "Rock_Sandstone_Cobble"
    },
    {
      "x": -9,
      "y": 11,
      "z": 7,
      "name": "Rock_Sandstone_Cobble"
    },
    {
      "x": -9,
      "y": 0,
      "z": 8,
      "name": "Rock_Sandstone_Cobble"
    },
    {
      "x": -9,
      "y": 1,
      "z": 8,
      "name": "Rock_Sandstone_Cobble"
    },
    {
      "x": -9,
      "y": 2,
      "z": 8,
      "name": "Rock_Sandstone_Cobble"
    },
    {
      "x": -9,
      "y": 3,
      "z": 8,
      "name": "Rock_Sandstone_Cobble"
    },
    {
      "x": -9,
      "y": 4,
      "z": 8,
      "name": "Rock_Sandstone_Cobble"
    },
    {
      "x": -9,
      "y": 5,
      "z": 8,
      "name": "Rock_Sandstone_Cobble"
    },
    {
      "x": -9,
      "y": 6,
      "z": 8,
      "name": "Rock_Sandstone_Cobble"
    },
    {
      "x": -9,
      "y": 7,
      "z": 8,
      "name": "Rock_Sandstone_Cobble"
    },
    {
      "x": -9,
      "y": 8,
      "z": 8,
      "name": "Rock_Sandstone_Cobble"
    },
    {
      "x": -9,
      "y": 9,
      "z": 8,
      "name": "Rock_Sandstone_Cobble"
    },
    {
      "x": -9,
      "y": 10,
      "z": 8,
      "name": "Rock_Sandstone_Cobble"
    },
    {
      "x": -9,
      "y": 11,
      "z": 8,
      "name": "Rock_Sandstone_Cobble"
    },
    {
      "x": -9,
      "y": 0,
      "z": 9,
      "name": "Rock_Sandstone_Cobble"
    },
    {
      "x": -9,
      "y": 1,
      "z": 9,
      "name": "Rock_Sandstone_Cobble"
    },
    {
      "x": -9,
      "y": 2,
      "z": 9,
      "name": "Rock_Sandstone_Cobble"
    },
    {
      "x": -9,
      "y": 3,
      "z": 9,
      "name": "Rock_Sandstone_Cobble"
    },
    {
      "x": -9,
      "y": 4,
      "z": 9,
      "name": "Rock_Sandstone_Cobble"
    },
    {
      "x": -9,
      "y": 5,
      "z": 9,
      "name": "Rock_Sandstone_Cobble"
    },
    {
      "x": -9,
      "y": 6,
      "z": 9,
      "name": "Rock_Sandstone_Cobble"
    },
    {
      "x": -9,
      "y": 7,
      "z": 9,
      "name": "Rock_Sandstone_Cobble"
    },
    {
      "x": -9,
      "y": 8,
      "z": 9,
      "name": "Rock_Sandstone_Cobble"
    },
    {
      "x": -9,
      "y": 9,
      "z": 9,
      "name": "Rock_Sandstone_Cobble"
    },
    {
      "x": -9,
      "y": 10,
      "z": 9,
      "name": "Rock_Sandstone_Cobble"
    },
    {
      "x": -9,
      "y": 11,
      "z": 9,
      "name": "Rock_Sandstone_Cobble"
    },
    {
      "x": -9,
      "y": 12,
      "z": 9,
      "name": "Rock_Sandstone_Cobble"
    },
    {
      "x": -9,
      "y": 13,
      "z": 9,
      "name": "Rock_Sandstone_Cobble"
    },
    {
      "x": -9,
      "y": 14,
      "z": 9,
      "name": "Rock_Sandstone_Cobble"
    },
    {
      "x": -9,
      "y": 15,
      "z": 9,
      "name": "Rock_Sandstone_Cobble"
    },
    {
      "x": -9,
      "y": 16,
      "z": 9,
      "name": "Rock_Sandstone_Cobble"
    },
    {
      "x": -9,
      "y": 17,
      "z": 9,
      "name": "Rock_Sandstone_Cobble"
    },
    {
      "x": -9,
      "y": 18,
      "z": 9,
      "name": "Rock_Sandstone_Cobble"
    },
    {
      "x": -9,
      "y": 19,
      "z": 9,
      "name": "Rock_Sandstone_Cobble"
    },
    {
      "x": -9,
      "y": 20,
      "z": 9,
      "name": "Rock_Sandstone_Cobble"
    },
    {
      "x": -9,
      "y": 21,
      "z": 9,
      "name": "Rock_Sandstone_Cobble"
    },
    {
      "x": -8,
      "y": 21,
      "z": -8,
      "name": "Rock_Sandstone_Brick"
    },
    {
      "x": -8,
      "y": 22,
      "z": -8,
      "name": "Rock_Sandstone_Brick"
    },
    {
      "x": -8,
      "y": 18,
      "z": -7,
      "name": "Rock_Sandstone_Brick_Half",
      "rotation": 8
    },
    {
      "x": -8,
      "y": 19,
      "z": -7,
      "name": "Rock_Sandstone_Brick"
    },
    {
      "x": -8,
      "y": 20,
      "z": -7,
      "name": "Rock_Sandstone_Brick"
    },
    {
      "x": -8,
      "y": 21,
      "z": -7,
      "name": "Rock_Sandstone_Brick"
    },
    {
      "x": -8,
      "y": 22,
      "z": -7,
      "name": "Rock_Sandstone_Brick"
    },
    {
      "x": -8,
      "y": 4,
      "z": -6,
      "name": "Rock_Sandstone_Cobble"
    },
    {
      "x": -8,
      "y": 5,
      "z": -6,
      "name": "Rock_Sandstone_Cobble"
    },
    {
      "x": -8,
      "y": 6,
      "z": -6,
      "name": "Rock_Sandstone_Cobble"
    },
    {
      "x": -8,
      "y": 7,
      "z": -6,
      "name": "Rock_Sandstone_Cobble"
    },
    {
      "x": -8,
      "y": 8,
      "z": -6,
      "name": "Rock_Sandstone_Cobble"
    },
    {
      "x": -8,
      "y": 13,
      "z": -6,
      "name": "Rock_Sandstone_Brick_Half",
      "rotation": 6
    },
    {
      "x": -8,
      "y": 14,
      "z": -6,
      "name": "Rock_Sandstone_Brick"
    },
    {
      "x": -8,
      "y": 15,
      "z": -6,
      "name": "Rock_Sandstone_Brick"
    },
    {
      "x": -8,
      "y": 16,
      "z": -6,
      "name": "Rock_Sandstone_Brick"
    },
    {
      "x": -8,
      "y": 17,
      "z": -6,
      "name": "Rock_Sandstone_Brick"
    },
    {
      "x": -8,
      "y": 18,
      "z": -6,
      "name": "Rock_Sandstone_Brick"
    },
    {
      "x": -8,
      "y": 19,
      "z": -6,
      "name": "Rock_Sandstone_Brick"
    },
    {
      "x": -8,
      "y": 20,
      "z": -6,
      "name": "Rock_Sandstone_Brick"
    },
    {
      "x": -8,
      "y": 21,
      "z": -6,
      "name": "Rock_Sandstone_Brick"
    },
    {
      "x": -8,
      "y": 22,
      "z": -6,
      "name": "Rock_Sandstone_Brick"
    },
    {
      "x": -8,
      "y": 3,
      "z": -5,
      "name": "Rock_Sandstone_Cobble"
    },
    {
      "x": -8,
      "y": 4,
      "z": -5,
      "name": "Rock_Sandstone_Cobble"
    },
    {
      "x": -8,
      "y": 5,
      "z": -5,
      "name": "Rock_Sandstone_Cobble"
    },
    {
      "x": -8,
      "y": 6,
      "z": -5,
      "name": "Rock_Sandstone_Cobble"
    },
    {
      "x": -8,
      "y": 7,
      "z": -5,
      "name": "Rock_Sandstone_Cobble"
    },
    {
      "x": -8,
      "y": 8,
      "z": -5,
      "name": "Rock_Sandstone_Cobble"
    },
    {
      "x": -8,
      "y": 9,
      "z": -5,
      "name": "Rock_Sandstone_Cobble"
    },
    {
      "x": -8,
      "y": 10,
      "z": -5,
      "name": "Rock_Sandstone_Brick"
    },
    {
      "x": -8,
      "y": 11,
      "z": -5,
      "name": "Rock_Sandstone_Brick"
    },
    {
      "x": -8,
      "y": 12,
      "z": -5,
      "name": "Rock_Sandstone_Brick"
    },
    {
      "x": -8,
      "y": 13,
      "z": -5,
      "name": "Rock_Sandstone_Brick"
    },
    {
      "x": -8,
      "y": 14,
      "z": -5,
      "name": "Rock_Sandstone_Brick"
    },
    {
      "x": -8,
      "y": 15,
      "z": -5,
      "name": "Rock_Sandstone_Brick"
    },
    {
      "x": -8,
      "y": 16,
      "z": -5,
      "name": "Rock_Sandstone_Brick"
    },
    {
      "x": -8,
      "y": 17,
      "z": -5,
      "name": "Rock_Sandstone_Brick"
    },
    {
      "x": -8,
      "y": 18,
      "z": -5,
      "name": "Rock_Sandstone_Brick"
    },
    {
      "x": -8,
      "y": 19,
      "z": -5,
      "name": "Rock_Sandstone_Brick"
    },
    {
      "x": -8,
      "y": 20,
      "z": -5,
      "name": "Rock_Sandstone_Brick"
    },
    {
      "x": -8,
      "y": 21,
      "z": -5,
      "name": "Rock_Sandstone_Brick"
    },
    {
      "x": -8,
      "y": 22,
      "z": -5,
      "name": "Rock_Sandstone_Brick"
    },
    {
      "x": -8,
      "y": 2,
      "z": -4,
      "name": "Rock_Sandstone_Cobble"
    },
    {
      "x": -8,
      "y": 3,
      "z": -4,
      "name": "Rock_Sandstone_Cobble"
    },
    {
      "x": -8,
      "y": 4,
      "z": -4,
      "name": "Rock_Sandstone_Cobble"
    },
    {
      "x": -8,
      "y": 5,
      "z": -4,
      "name": "Rock_Sandstone_Cobble"
    },
    {
      "x": -8,
      "y": 6,
      "z": -4,
      "name": "Rock_Sandstone_Cobble"
    },
    {
      "x": -8,
      "y": 7,
      "z": -4,
      "name": "Rock_Sandstone_Cobble"
    },
    {
      "x": -8,
      "y": 8,
      "z": -4,
      "name": "Rock_Sandstone_Cobble"
    },
    {
      "x": -8,
      "y": 9,
      "z": -4,
      "name": "Rock_Sandstone_Cobble"
    },
    {
      "x": -8,
      "y": 10,
      "z": -4,
      "name": "Rock_Sandstone_Cobble"
    },
    {
      "x": -8,
      "y": 11,
      "z": -4,
      "name": "Rock_Sandstone_Cobble"
    },
    {
      "x": -8,
      "y": 12,
      "z": -4,
      "name": "Rock_Sandstone_Cobble"
    },
    {
      "x": -8,
      "y": 13,
      "z": -4,
      "name": "Rock_Sandstone_Cobble"
    },
    {
      "x": -8,
      "y": 14,
      "z": -4,
      "name": "Rock_Sandstone_Cobble"
    },
    {
      "x": -8,
      "y": 15,
      "z": -4,
      "name": "Rock_Sandstone_Cobble"
    },
    {
      "x": -8,
      "y": 16,
      "z": -4,
      "name": "Rock_Sandstone_Cobble"
    },
    {
      "x": -8,
      "y": 17,
      "z": -4,
      "name": "Rock_Sandstone_Cobble"
    },
    {
      "x": -8,
      "y": 18,
      "z": -4,
      "name": "Rock_Sandstone_Cobble"
    },
    {
      "x": -8,
      "y": 19,
      "z": -4,
      "name": "Rock_Sandstone_Cobble"
    },
    {
      "x": -8,
      "y": 20,
      "z": -4,
      "name": "Rock_Sandstone_Cobble"
    },
    {
      "x": -8,
      "y": 21,
      "z": -4,
      "name": "Rock_Sandstone_Cobble"
    },
    {
      "x": -8,
      "y": 22,
      "z": -4,
      "name": "Rock_Sandstone_Brick_Half"
    },
    {
      "x": -8,
      "y": 1,
      "z": -3,
      "name": "Rock_Sandstone_Cobble"
    },
    {
      "x": -8,
      "y": 2,
      "z": -3,
      "name": "Rock_Sandstone_Cobble"
    },
    {
      "x": -8,
      "y": 3,
      "z": -3,
      "name": "Rock_Sandstone_Cobble"
    },
    {
      "x": -8,
      "y": 4,
      "z": -3,
      "name": "Rock_Sandstone_Cobble"
    },
    {
      "x": -8,
      "y": 5,
      "z": -3,
      "name": "Rock_Sandstone_Cobble"
    },
    {
      "x": -8,
      "y": 6,
      "z": -3,
      "name": "Rock_Sandstone_Cobble"
    },
    {
      "x": -8,
      "y": 7,
      "z": -3,
      "name": "Rock_Sandstone_Cobble"
    },
    {
      "x": -8,
      "y": 8,
      "z": -3,
      "name": "Rock_Sandstone_Cobble"
    },
    {
      "x": -8,
      "y": 9,
      "z": -3,
      "name": "Rock_Sandstone_Cobble"
    },
    {
      "x": -8,
      "y": 10,
      "z": -3,
      "name": "Rock_Sandstone_Cobble"
    },
    {
      "x": -8,
      "y": 11,
      "z": -3,
      "name": "Rock_Sandstone_Cobble"
    },
    {
      "x": -8,
      "y": 12,
      "z": -3,
      "name": "Rock_Sandstone_Cobble"
    },
    {
      "x": -8,
      "y": 13,
      "z": -3,
      "name": "Rock_Sandstone_Cobble"
    },
    {
      "x": -8,
      "y": 14,
      "z": -3,
      "name": "Rock_Sandstone_Cobble"
    },
    {
      "x": -8,
      "y": 15,
      "z": -3,
      "name": "Rock_Sandstone_Cobble"
    },
    {
      "x": -8,
      "y": 16,
      "z": -3,
      "name": "Rock_Sandstone_Cobble"
    },
    {
      "x": -8,
      "y": 17,
      "z": -3,
      "name": "Rock_Sandstone_Cobble"
    },
    {
      "x": -8,
      "y": 18,
      "z": -3,
      "name": "Rock_Sandstone_Cobble"
    },
    {
      "x": -8,
      "y": 19,
      "z": -3,
      "name": "Rock_Sandstone_Cobble"
    },
    {
      "x": -8,
      "y": 20,
      "z": -3,
      "name": "Rock_Sandstone_Cobble"
    },
    {
      "x": -8,
      "y": 21,
      "z": -3,
      "name": "Rock_Sandstone_Cobble"
    },
    {
      "x": -8,
      "y": 22,
      "z": -3,
      "name": "Rock_Sandstone_Brick_Half"
    },
    {
      "x": -8,
      "y": 1,
      "z": -2,
      "name": "Rock_Sandstone_Cobble"
    },
    {
      "x": -8,
      "y": 2,
      "z": -2,
      "name": "Rock_Sandstone_Cobble"
    },
    {
      "x": -8,
      "y": 3,
      "z": -2,
      "name": "Rock_Sandstone_Cobble"
    },
    {
      "x": -8,
      "y": 4,
      "z": -2,
      "name": "Rock_Sandstone_Cobble"
    },
    {
      "x": -8,
      "y": 5,
      "z": -2,
      "name": "Rock_Sandstone_Cobble"
    },
    {
      "x": -8,
      "y": 6,
      "z": -2,
      "name": "Rock_Sandstone_Cobble"
    },
    {
      "x": -8,
      "y": 7,
      "z": -2,
      "name": "Rock_Sandstone_Cobble"
    },
    {
      "x": -8,
      "y": 8,
      "z": -2,
      "name": "Rock_Sandstone_Cobble"
    },
    {
      "x": -8,
      "y": 9,
      "z": -2,
      "name": "Rock_Sandstone_Cobble"
    },
    {
      "x": -8,
      "y": 10,
      "z": -2,
      "name": "Rock_Sandstone_Cobble"
    },
    {
      "x": -8,
      "y": 11,
      "z": -2,
      "name": "Rock_Sandstone_Cobble"
    },
    {
      "x": -8,
      "y": 12,
      "z": -2,
      "name": "Rock_Sandstone_Cobble"
    },
    {
      "x": -8,
      "y": 13,
      "z": -2,
      "name": "Rock_Sandstone_Cobble"
    },
    {
      "x": -8,
      "y": 14,
      "z": -2,
      "name": "Rock_Sandstone_Cobble"
    },
    {
      "x": -8,
      "y": 15,
      "z": -2,
      "name": "Rock_Sandstone_Cobble"
    },
    {
      "x": -8,
      "y": 16,
      "z": -2,
      "name": "Rock_Sandstone_Cobble"
    },
    {
      "x": -8,
      "y": 17,
      "z": -2,
      "name": "Rock_Sandstone_Cobble"
    },
    {
      "x": -8,
      "y": 18,
      "z": -2,
      "name": "Rock_Sandstone_Cobble"
    },
    {
      "x": -8,
      "y": 19,
      "z": -2,
      "name": "Rock_Sandstone_Cobble"
    },
    {
      "x": -8,
      "y": 20,
      "z": -2,
      "name": "Rock_Sandstone_Cobble"
    },
    {
      "x": -8,
      "y": 21,
      "z": -2,
      "name": "Rock_Sandstone_Cobble"
    },
    {
      "x": -8,
      "y": 22,
      "z": -2,
      "name": "Rock_Sandstone_Brick_Half"
    },
    {
      "x": -8,
      "y": 0,
      "z": -1,
      "name": "Rock_Sandstone_Cobble"
    },
    {
      "x": -8,
      "y": 1,
      "z": -1,
      "name": "Rock_Sandstone_Cobble"
    },
    {
      "x": -8,
      "y": 2,
      "z": -1,
      "name": "Rock_Sandstone_Cobble"
    },
    {
      "x": -8,
      "y": 3,
      "z": -1,
      "name": "Rock_Sandstone_Cobble"
    },
    {
      "x": -8,
      "y": 4,
      "z": -1,
      "name": "Rock_Sandstone_Cobble"
    },
    {
      "x": -8,
      "y": 5,
      "z": -1,
      "name": "Rock_Sandstone_Cobble"
    },
    {
      "x": -8,
      "y": 6,
      "z": -1,
      "name": "Rock_Sandstone_Cobble"
    },
    {
      "x": -8,
      "y": 7,
      "z": -1,
      "name": "Rock_Sandstone_Cobble"
    },
    {
      "x": -8,
      "y": 8,
      "z": -1,
      "name": "Rock_Sandstone_Cobble"
    },
    {
      "x": -8,
      "y": 9,
      "z": -1,
      "name": "Rock_Sandstone_Cobble"
    },
    {
      "x": -8,
      "y": 10,
      "z": -1,
      "name": "Rock_Sandstone_Cobble"
    },
    {
      "x": -8,
      "y": 11,
      "z": -1,
      "name": "Rock_Sandstone_Cobble"
    },
    {
      "x": -8,
      "y": 12,
      "z": -1,
      "name": "Rock_Sandstone_Cobble"
    },
    {
      "x": -8,
      "y": 13,
      "z": -1,
      "name": "Rock_Sandstone_Cobble"
    },
    {
      "x": -8,
      "y": 14,
      "z": -1,
      "name": "Rock_Sandstone_Cobble"
    },
    {
      "x": -8,
      "y": 15,
      "z": -1,
      "name": "Rock_Sandstone_Cobble"
    },
    {
      "x": -8,
      "y": 16,
      "z": -1,
      "name": "Rock_Sandstone_Cobble"
    },
    {
      "x": -8,
      "y": 17,
      "z": -1,
      "name": "Rock_Sandstone_Cobble"
    },
    {
      "x": -8,
      "y": 18,
      "z": -1,
      "name": "Rock_Sandstone_Cobble"
    },
    {
      "x": -8,
      "y": 19,
      "z": -1,
      "name": "Rock_Sandstone_Cobble"
    },
    {
      "x": -8,
      "y": 20,
      "z": -1,
      "name": "Rock_Sandstone_Cobble"
    },
    {
      "x": -8,
      "y": 21,
      "z": -1,
      "name": "Rock_Sandstone_Cobble"
    },
    {
      "x": -8,
      "y": 22,
      "z": -1,
      "name": "Rock_Sandstone_Brick_Half"
    },
    {
      "x": -8,
      "y": 0,
      "z": 0,
      "name": "Rock_Sandstone_Cobble"
    },
    {
      "x": -8,
      "y": 1,
      "z": 0,
      "name": "Rock_Sandstone_Cobble"
    },
    {
      "x": -8,
      "y": 2,
      "z": 0,
      "name": "Rock_Sandstone_Cobble"
    },
    {
      "x": -8,
      "y": 3,
      "z": 0,
      "name": "Rock_Sandstone_Cobble"
    },
    {
      "x": -8,
      "y": 4,
      "z": 0,
      "name": "Rock_Sandstone_Cobble"
    },
    {
      "x": -8,
      "y": 5,
      "z": 0,
      "name": "Rock_Sandstone_Cobble"
    },
    {
      "x": -8,
      "y": 6,
      "z": 0,
      "name": "Rock_Sandstone_Cobble"
    },
    {
      "x": -8,
      "y": 7,
      "z": 0,
      "name": "Rock_Sandstone_Cobble"
    },
    {
      "x": -8,
      "y": 8,
      "z": 0,
      "name": "Rock_Sandstone_Cobble"
    },
    {
      "x": -8,
      "y": 9,
      "z": 0,
      "name": "Rock_Sandstone_Cobble"
    },
    {
      "x": -8,
      "y": 10,
      "z": 0,
      "name": "Rock_Sandstone_Cobble"
    },
    {
      "x": -8,
      "y": 11,
      "z": 0,
      "name": "Rock_Sandstone_Cobble"
    },
    {
      "x": -8,
      "y": 12,
      "z": 0,
      "name": "Rock_Sandstone_Cobble"
    },
    {
      "x": -8,
      "y": 13,
      "z": 0,
      "name": "Rock_Sandstone_Cobble"
    },
    {
      "x": -8,
      "y": 14,
      "z": 0,
      "name": "Rock_Sandstone_Cobble"
    },
    {
      "x": -8,
      "y": 15,
      "z": 0,
      "name": "Rock_Sandstone_Cobble"
    },
    {
      "x": -8,
      "y": 16,
      "z": 0,
      "name": "Rock_Sandstone_Cobble"
    },
    {
      "x": -8,
      "y": 17,
      "z": 0,
      "name": "Rock_Sandstone_Cobble"
    },
    {
      "x": -8,
      "y": 18,
      "z": 0,
      "name": "Rock_Sandstone_Cobble"
    },
    {
      "x": -8,
      "y": 19,
      "z": 0,
      "name": "Rock_Sandstone_Cobble"
    },
    {
      "x": -8,
      "y": 20,
      "z": 0,
      "name": "Rock_Sandstone_Cobble"
    },
    {
      "x": -8,
      "y": 21,
      "z": 0,
      "name": "Rock_Sandstone_Cobble"
    },
    {
      "x": -8,
      "y": 22,
      "z": 0,
      "name": "Rock_Sandstone_Brick_Half"
    },
    {
      "x": -8,
      "y": 0,
      "z": 1,
      "name": "Rock_Sandstone_Cobble"
    },
    {
      "x": -8,
      "y": 1,
      "z": 1,
      "name": "Rock_Sandstone_Cobble"
    },
    {
      "x": -8,
      "y": 2,
      "z": 1,
      "name": "Rock_Sandstone_Cobble"
    },
    {
      "x": -8,
      "y": 3,
      "z": 1,
      "name": "Rock_Sandstone_Cobble"
    },
    {
      "x": -8,
      "y": 4,
      "z": 1,
      "name": "Rock_Sandstone_Cobble"
    },
    {
      "x": -8,
      "y": 5,
      "z": 1,
      "name": "Rock_Sandstone_Cobble"
    },
    {
      "x": -8,
      "y": 6,
      "z": 1,
      "name": "Rock_Sandstone_Cobble"
    },
    {
      "x": -8,
      "y": 7,
      "z": 1,
      "name": "Rock_Sandstone_Cobble"
    },
    {
      "x": -8,
      "y": 8,
      "z": 1,
      "name": "Rock_Sandstone_Cobble"
    },
    {
      "x": -8,
      "y": 9,
      "z": 1,
      "name": "Rock_Sandstone_Cobble"
    },
    {
      "x": -8,
      "y": 10,
      "z": 1,
      "name": "Rock_Sandstone_Cobble"
    },
    {
      "x": -8,
      "y": 11,
      "z": 1,
      "name": "Rock_Sandstone_Cobble"
    },
    {
      "x": -8,
      "y": 12,
      "z": 1,
      "name": "Rock_Sandstone_Cobble"
    },
    {
      "x": -8,
      "y": 13,
      "z": 1,
      "name": "Rock_Sandstone_Cobble"
    },
    {
      "x": -8,
      "y": 14,
      "z": 1,
      "name": "Rock_Sandstone_Cobble"
    },
    {
      "x": -8,
      "y": 15,
      "z": 1,
      "name": "Rock_Sandstone_Cobble"
    },
    {
      "x": -8,
      "y": 16,
      "z": 1,
      "name": "Rock_Sandstone_Cobble"
    },
    {
      "x": -8,
      "y": 17,
      "z": 1,
      "name": "Rock_Sandstone_Cobble"
    },
    {
      "x": -8,
      "y": 18,
      "z": 1,
      "name": "Rock_Sandstone_Cobble"
    },
    {
      "x": -8,
      "y": 19,
      "z": 1,
      "name": "Rock_Sandstone_Cobble"
    },
    {
      "x": -8,
      "y": 20,
      "z": 1,
      "name": "Rock_Sandstone_Cobble"
    },
    {
      "x": -8,
      "y": 21,
      "z": 1,
      "name": "Rock_Sandstone_Cobble"
    },
    {
      "x": -8,
      "y": 22,
      "z": 1,
      "name": "Rock_Sandstone_Brick_Half"
    },
    {
      "x": -8,
      "y": 0,
      "z": 2,
      "name": "Rock_Sandstone_Cobble"
    },
    {
      "x": -8,
      "y": 1,
      "z": 2,
      "name": "Rock_Sandstone_Cobble"
    },
    {
      "x": -8,
      "y": 2,
      "z": 2,
      "name": "Rock_Sandstone_Cobble"
    },
    {
      "x": -8,
      "y": 3,
      "z": 2,
      "name": "Rock_Sandstone_Cobble"
    },
    {
      "x": -8,
      "y": 4,
      "z": 2,
      "name": "Rock_Sandstone_Cobble"
    },
    {
      "x": -8,
      "y": 5,
      "z": 2,
      "name": "Rock_Sandstone_Cobble"
    },
    {
      "x": -8,
      "y": 6,
      "z": 2,
      "name": "Rock_Sandstone_Cobble"
    },
    {
      "x": -8,
      "y": 7,
      "z": 2,
      "name": "Rock_Sandstone_Cobble"
    },
    {
      "x": -8,
      "y": 8,
      "z": 2,
      "name": "Rock_Sandstone_Cobble"
    },
    {
      "x": -8,
      "y": 9,
      "z": 2,
      "name": "Rock_Sandstone_Cobble"
    },
    {
      "x": -8,
      "y": 10,
      "z": 2,
      "name": "Rock_Sandstone_Cobble"
    },
    {
      "x": -8,
      "y": 11,
      "z": 2,
      "name": "Rock_Sandstone_Cobble"
    },
    {
      "x": -8,
      "y": 12,
      "z": 2,
      "name": "Rock_Sandstone_Cobble"
    },
    {
      "x": -8,
      "y": 13,
      "z": 2,
      "name": "Rock_Sandstone_Cobble"
    },
    {
      "x": -8,
      "y": 14,
      "z": 2,
      "name": "Rock_Sandstone_Cobble"
    },
    {
      "x": -8,
      "y": 15,
      "z": 2,
      "name": "Rock_Sandstone_Cobble"
    },
    {
      "x": -8,
      "y": 16,
      "z": 2,
      "name": "Rock_Sandstone_Cobble"
    },
    {
      "x": -8,
      "y": 17,
      "z": 2,
      "name": "Rock_Sandstone_Cobble"
    },
    {
      "x": -8,
      "y": 18,
      "z": 2,
      "name": "Rock_Sandstone_Cobble"
    },
    {
      "x": -8,
      "y": 19,
      "z": 2,
      "name": "Rock_Sandstone_Cobble"
    },
    {
      "x": -8,
      "y": 20,
      "z": 2,
      "name": "Rock_Sandstone_Cobble"
    },
    {
      "x": -8,
      "y": 21,
      "z": 2,
      "name": "Rock_Sandstone_Cobble"
    },
    {
      "x": -8,
      "y": 22,
      "z": 2,
      "name": "Rock_Sandstone_Brick_Half"
    },
    {
      "x": -8,
      "y": 0,
      "z": 3,
      "name": "Rock_Sandstone_Cobble"
    },
    {
      "x": -8,
      "y": 1,
      "z": 3,
      "name": "Rock_Sandstone_Cobble"
    },
    {
      "x": -8,
      "y": 2,
      "z": 3,
      "name": "Rock_Sandstone_Cobble"
    },
    {
      "x": -8,
      "y": 3,
      "z": 3,
      "name": "Rock_Sandstone_Cobble"
    },
    {
      "x": -8,
      "y": 4,
      "z": 3,
      "name": "Rock_Sandstone_Cobble"
    },
    {
      "x": -8,
      "y": 5,
      "z": 3,
      "name": "Rock_Sandstone_Cobble"
    },
    {
      "x": -8,
      "y": 6,
      "z": 3,
      "name": "Rock_Sandstone_Cobble"
    },
    {
      "x": -8,
      "y": 7,
      "z": 3,
      "name": "Rock_Sandstone_Cobble"
    },
    {
      "x": -8,
      "y": 8,
      "z": 3,
      "name": "Rock_Sandstone_Cobble"
    },
    {
      "x": -8,
      "y": 9,
      "z": 3,
      "name": "Rock_Sandstone_Cobble"
    },
    {
      "x": -8,
      "y": 10,
      "z": 3,
      "name": "Rock_Sandstone_Cobble"
    },
    {
      "x": -8,
      "y": 11,
      "z": 3,
      "name": "Rock_Sandstone_Cobble"
    },
    {
      "x": -8,
      "y": 12,
      "z": 3,
      "name": "Rock_Sandstone_Cobble"
    },
    {
      "x": -8,
      "y": 13,
      "z": 3,
      "name": "Rock_Sandstone_Cobble"
    },
    {
      "x": -8,
      "y": 14,
      "z": 3,
      "name": "Rock_Sandstone_Cobble"
    },
    {
      "x": -8,
      "y": 15,
      "z": 3,
      "name": "Rock_Sandstone_Cobble"
    },
    {
      "x": -8,
      "y": 16,
      "z": 3,
      "name": "Rock_Sandstone_Cobble"
    },
    {
      "x": -8,
      "y": 17,
      "z": 3,
      "name": "Rock_Sandstone_Cobble"
    },
    {
      "x": -8,
      "y": 18,
      "z": 3,
      "name": "Rock_Sandstone_Cobble"
    },
    {
      "x": -8,
      "y": 19,
      "z": 3,
      "name": "Rock_Sandstone_Cobble"
    },
    {
      "x": -8,
      "y": 20,
      "z": 3,
      "name": "Rock_Sandstone_Cobble"
    },
    {
      "x": -8,
      "y": 21,
      "z": 3,
      "name": "Rock_Sandstone_Cobble"
    },
    {
      "x": -8,
      "y": 22,
      "z": 3,
      "name": "Rock_Sandstone_Brick_Half"
    },
    {
      "x": -8,
      "y": 0,
      "z": 4,
      "name": "Rock_Sandstone_Cobble"
    },
    {
      "x": -8,
      "y": 1,
      "z": 4,
      "name": "Rock_Sandstone_Cobble"
    },
    {
      "x": -8,
      "y": 2,
      "z": 4,
      "name": "Rock_Sandstone_Cobble"
    },
    {
      "x": -8,
      "y": 3,
      "z": 4,
      "name": "Rock_Sandstone_Cobble"
    },
    {
      "x": -8,
      "y": 4,
      "z": 4,
      "name": "Rock_Sandstone_Cobble"
    },
    {
      "x": -8,
      "y": 5,
      "z": 4,
      "name": "Rock_Sandstone_Cobble"
    },
    {
      "x": -8,
      "y": 6,
      "z": 4,
      "name": "Rock_Sandstone_Cobble"
    },
    {
      "x": -8,
      "y": 7,
      "z": 4,
      "name": "Rock_Sandstone_Cobble"
    },
    {
      "x": -8,
      "y": 8,
      "z": 4,
      "name": "Rock_Sandstone_Cobble"
    },
    {
      "x": -8,
      "y": 9,
      "z": 4,
      "name": "Rock_Sandstone_Cobble"
    },
    {
      "x": -8,
      "y": 10,
      "z": 4,
      "name": "Rock_Sandstone_Cobble"
    },
    {
      "x": -8,
      "y": 11,
      "z": 4,
      "name": "Rock_Sandstone_Cobble"
    },
    {
      "x": -8,
      "y": 12,
      "z": 4,
      "name": "Rock_Sandstone_Cobble"
    },
    {
      "x": -8,
      "y": 13,
      "z": 4,
      "name": "Rock_Sandstone_Cobble"
    },
    {
      "x": -8,
      "y": 14,
      "z": 4,
      "name": "Rock_Sandstone_Cobble"
    },
    {
      "x": -8,
      "y": 15,
      "z": 4,
      "name": "Rock_Sandstone_Cobble"
    },
    {
      "x": -8,
      "y": 16,
      "z": 4,
      "name": "Rock_Sandstone_Cobble"
    },
    {
      "x": -8,
      "y": 17,
      "z": 4,
      "name": "Rock_Sandstone_Cobble"
    },
    {
      "x": -8,
      "y": 18,
      "z": 4,
      "name": "Rock_Sandstone_Cobble"
    },
    {
      "x": -8,
      "y": 19,
      "z": 4,
      "name": "Rock_Sandstone_Cobble"
    },
    {
      "x": -8,
      "y": 20,
      "z": 4,
      "name": "Rock_Sandstone_Cobble"
    },
    {
      "x": -8,
      "y": 21,
      "z": 4,
      "name": "Rock_Sandstone_Cobble"
    },
    {
      "x": -8,
      "y": 22,
      "z": 4,
      "name": "Rock_Sandstone_Brick_Half"
    },
    {
      "x": -8,
      "y": 0,
      "z": 5,
      "name": "Rock_Sandstone_Cobble"
    },
    {
      "x": -8,
      "y": 1,
      "z": 5,
      "name": "Rock_Sandstone_Cobble"
    },
    {
      "x": -8,
      "y": 2,
      "z": 5,
      "name": "Rock_Sandstone_Cobble"
    },
    {
      "x": -8,
      "y": 3,
      "z": 5,
      "name": "Rock_Sandstone_Cobble"
    },
    {
      "x": -8,
      "y": 4,
      "z": 5,
      "name": "Rock_Sandstone_Cobble"
    },
    {
      "x": -8,
      "y": 5,
      "z": 5,
      "name": "Rock_Sandstone_Cobble"
    },
    {
      "x": -8,
      "y": 6,
      "z": 5,
      "name": "Rock_Sandstone_Cobble"
    },
    {
      "x": -8,
      "y": 7,
      "z": 5,
      "name": "Rock_Sandstone_Cobble"
    },
    {
      "x": -8,
      "y": 8,
      "z": 5,
      "name": "Rock_Sandstone_Cobble"
    },
    {
      "x": -8,
      "y": 9,
      "z": 5,
      "name": "Rock_Sandstone_Cobble"
    },
    {
      "x": -8,
      "y": 10,
      "z": 5,
      "name": "Rock_Sandstone_Cobble"
    },
    {
      "x": -8,
      "y": 11,
      "z": 5,
      "name": "Rock_Sandstone_Cobble"
    },
    {
      "x": -8,
      "y": 12,
      "z": 5,
      "name": "Rock_Sandstone_Cobble"
    },
    {
      "x": -8,
      "y": 13,
      "z": 5,
      "name": "Rock_Sandstone_Cobble"
    },
    {
      "x": -8,
      "y": 14,
      "z": 5,
      "name": "Rock_Sandstone_Cobble"
    },
    {
      "x": -8,
      "y": 15,
      "z": 5,
      "name": "Rock_Sandstone_Cobble"
    },
    {
      "x": -8,
      "y": 16,
      "z": 5,
      "name": "Rock_Sandstone_Cobble"
    },
    {
      "x": -8,
      "y": 17,
      "z": 5,
      "name": "Rock_Sandstone_Cobble"
    },
    {
      "x": -8,
      "y": 18,
      "z": 5,
      "name": "Rock_Sandstone_Cobble"
    },
    {
      "x": -8,
      "y": 19,
      "z": 5,
      "name": "Rock_Sandstone_Cobble"
    },
    {
      "x": -8,
      "y": 20,
      "z": 5,
      "name": "Rock_Sandstone_Cobble"
    },
    {
      "x": -8,
      "y": 21,
      "z": 5,
      "name": "Rock_Sandstone_Cobble"
    },
    {
      "x": -8,
      "y": 22,
      "z": 5,
      "name": "Rock_Sandstone_Brick_Half"
    },
    {
      "x": -8,
      "y": 0,
      "z": 6,
      "name": "Rock_Sandstone_Cobble"
    },
    {
      "x": -8,
      "y": 1,
      "z": 6,
      "name": "Rock_Sandstone_Cobble"
    },
    {
      "x": -8,
      "y": 2,
      "z": 6,
      "name": "Rock_Sandstone_Cobble"
    },
    {
      "x": -8,
      "y": 3,
      "z": 6,
      "name": "Rock_Sandstone_Cobble"
    },
    {
      "x": -8,
      "y": 4,
      "z": 6,
      "name": "Rock_Sandstone_Cobble"
    },
    {
      "x": -8,
      "y": 5,
      "z": 6,
      "name": "Rock_Sandstone_Cobble"
    },
    {
      "x": -8,
      "y": 6,
      "z": 6,
      "name": "Rock_Sandstone_Cobble"
    },
    {
      "x": -8,
      "y": 7,
      "z": 6,
      "name": "Rock_Sandstone_Cobble"
    },
    {
      "x": -8,
      "y": 8,
      "z": 6,
      "name": "Rock_Sandstone_Cobble"
    },
    {
      "x": -8,
      "y": 9,
      "z": 6,
      "name": "Rock_Sandstone_Cobble"
    },
    {
      "x": -8,
      "y": 10,
      "z": 6,
      "name": "Rock_Sandstone_Cobble"
    },
    {
      "x": -8,
      "y": 11,
      "z": 6,
      "name": "Rock_Sandstone_Cobble"
    },
    {
      "x": -8,
      "y": 0,
      "z": 7,
      "name": "Rock_Sandstone_Cobble"
    },
    {
      "x": -8,
      "y": 1,
      "z": 7,
      "name": "Rock_Sandstone_Cobble"
    },
    {
      "x": -8,
      "y": 2,
      "z": 7,
      "name": "Rock_Sandstone_Cobble"
    },
    {
      "x": -8,
      "y": 3,
      "z": 7,
      "name": "Rock_Sandstone_Cobble"
    },
    {
      "x": -8,
      "y": 4,
      "z": 7,
      "name": "Rock_Sandstone_Cobble"
    },
    {
      "x": -8,
      "y": 5,
      "z": 7,
      "name": "Rock_Sandstone_Cobble"
    },
    {
      "x": -8,
      "y": 6,
      "z": 7,
      "name": "Rock_Sandstone_Cobble"
    },
    {
      "x": -8,
      "y": 7,
      "z": 7,
      "name": "Rock_Sandstone_Cobble"
    },
    {
      "x": -8,
      "y": 8,
      "z": 7,
      "name": "Rock_Sandstone_Cobble"
    },
    {
      "x": -8,
      "y": 9,
      "z": 7,
      "name": "Rock_Sandstone_Cobble"
    },
    {
      "x": -8,
      "y": 10,
      "z": 7,
      "name": "Rock_Sandstone_Cobble"
    },
    {
      "x": -8,
      "y": 11,
      "z": 7,
      "name": "Rock_Sandstone_Cobble"
    },
    {
      "x": -8,
      "y": 0,
      "z": 8,
      "name": "Rock_Sandstone_Cobble"
    },
    {
      "x": -8,
      "y": 1,
      "z": 8,
      "name": "Rock_Sandstone_Cobble"
    },
    {
      "x": -8,
      "y": 2,
      "z": 8,
      "name": "Rock_Sandstone_Cobble"
    },
    {
      "x": -8,
      "y": 3,
      "z": 8,
      "name": "Rock_Sandstone_Cobble"
    },
    {
      "x": -8,
      "y": 4,
      "z": 8,
      "name": "Rock_Sandstone_Cobble"
    },
    {
      "x": -8,
      "y": 5,
      "z": 8,
      "name": "Rock_Sandstone_Cobble"
    },
    {
      "x": -8,
      "y": 6,
      "z": 8,
      "name": "Rock_Sandstone_Cobble"
    },
    {
      "x": -8,
      "y": 7,
      "z": 8,
      "name": "Rock_Sandstone_Cobble"
    },
    {
      "x": -8,
      "y": 8,
      "z": 8,
      "name": "Rock_Sandstone_Cobble"
    },
    {
      "x": -8,
      "y": 9,
      "z": 8,
      "name": "Rock_Sandstone_Cobble"
    },
    {
      "x": -8,
      "y": 10,
      "z": 8,
      "name": "Rock_Sandstone_Cobble"
    },
    {
      "x": -8,
      "y": 11,
      "z": 8,
      "name": "Rock_Sandstone_Cobble"
    },
    {
      "x": -8,
      "y": 0,
      "z": 9,
      "name": "Rock_Sandstone_Cobble"
    },
    {
      "x": -8,
      "y": 1,
      "z": 9,
      "name": "Rock_Sandstone_Cobble"
    },
    {
      "x": -8,
      "y": 2,
      "z": 9,
      "name": "Rock_Sandstone_Cobble"
    },
    {
      "x": -8,
      "y": 3,
      "z": 9,
      "name": "Rock_Sandstone_Cobble"
    },
    {
      "x": -8,
      "y": 4,
      "z": 9,
      "name": "Rock_Sandstone_Cobble"
    },
    {
      "x": -8,
      "y": 5,
      "z": 9,
      "name": "Rock_Sandstone_Cobble"
    },
    {
      "x": -8,
      "y": 6,
      "z": 9,
      "name": "Rock_Sandstone_Cobble"
    },
    {
      "x": -8,
      "y": 7,
      "z": 9,
      "name": "Rock_Sandstone_Cobble"
    },
    {
      "x": -8,
      "y": 8,
      "z": 9,
      "name": "Rock_Sandstone_Cobble"
    },
    {
      "x": -8,
      "y": 9,
      "z": 9,
      "name": "Rock_Sandstone_Cobble"
    },
    {
      "x": -8,
      "y": 10,
      "z": 9,
      "name": "Rock_Sandstone_Cobble"
    },
    {
      "x": -8,
      "y": 11,
      "z": 9,
      "name": "Rock_Sandstone_Cobble"
    },
    {
      "x": -8,
      "y": 12,
      "z": 9,
      "name": "Rock_Sandstone_Cobble"
    },
    {
      "x": -8,
      "y": 13,
      "z": 9,
      "name": "Rock_Sandstone_Cobble"
    },
    {
      "x": -8,
      "y": 14,
      "z": 9,
      "name": "Rock_Sandstone_Cobble"
    },
    {
      "x": -8,
      "y": 15,
      "z": 9,
      "name": "Rock_Sandstone_Cobble"
    },
    {
      "x": -8,
      "y": 16,
      "z": 9,
      "name": "Rock_Sandstone_Cobble"
    },
    {
      "x": -8,
      "y": 17,
      "z": 9,
      "name": "Rock_Sandstone_Cobble"
    },
    {
      "x": -8,
      "y": 18,
      "z": 9,
      "name": "Rock_Sandstone_Cobble"
    },
    {
      "x": -8,
      "y": 19,
      "z": 9,
      "name": "Rock_Sandstone_Cobble"
    },
    {
      "x": -8,
      "y": 20,
      "z": 9,
      "name": "Rock_Sandstone_Cobble"
    },
    {
      "x": -8,
      "y": 21,
      "z": 9,
      "name": "Rock_Sandstone_Cobble"
    },
    {
      "x": -7,
      "y": 21,
      "z": -8,
      "name": "Rock_Sandstone_Brick_Half",
      "rotation": 8
    },
    {
      "x": -7,
      "y": 22,
      "z": -8,
      "name": "Rock_Sandstone_Brick"
    },
    {
      "x": -7,
      "y": 19,
      "z": -7,
      "name": "Rock_Sandstone_Cobble"
    },
    {
      "x": -7,
      "y": 20,
      "z": -7,
      "name": "Rock_Sandstone_Cobble"
    },
    {
      "x": -7,
      "y": 21,
      "z": -7,
      "name": "Soil_Grass_Dry"
    },
    {
      "x": -7,
      "y": 6,
      "z": -6,
      "name": "Rock_Sandstone_Cobble"
    },
    {
      "x": -7,
      "y": 14,
      "z": -6,
      "name": "Rock_Sandstone_Cobble"
    },
    {
      "x": -7,
      "y": 15,
      "z": -6,
      "name": "Rock_Sandstone_Cobble"
    },
    {
      "x": -7,
      "y": 16,
      "z": -6,
      "name": "Rock_Sandstone_Cobble"
    },
    {
      "x": -7,
      "y": 17,
      "z": -6,
      "name": "Rock_Sandstone_Cobble"
    },
    {
      "x": -7,
      "y": 18,
      "z": -6,
      "name": "Rock_Sandstone_Cobble"
    },
    {
      "x": -7,
      "y": 19,
      "z": -6,
      "name": "Rock_Sandstone_Cobble"
    },
    {
      "x": -7,
      "y": 20,
      "z": -6,
      "name": "Rock_Sandstone_Cobble"
    },
    {
      "x": -7,
      "y": 21,
      "z": -6,
      "name": "Soil_Grass_Dry"
    },
    {
      "x": -7,
      "y": 3,
      "z": -5,
      "name": "Rock_Sandstone_Cobble"
    },
    {
      "x": -7,
      "y": 4,
      "z": -5,
      "name": "Rock_Sandstone_Cobble"
    },
    {
      "x": -7,
      "y": 5,
      "z": -5,
      "name": "Rock_Sandstone_Cobble"
    },
    {
      "x": -7,
      "y": 6,
      "z": -5,
      "name": "Rock_Sandstone_Cobble"
    },
    {
      "x": -7,
      "y": 7,
      "z": -5,
      "name": "Rock_Sandstone_Cobble"
    },
    {
      "x": -7,
      "y": 8,
      "z": -5,
      "name": "Rock_Sandstone_Cobble"
    },
    {
      "x": -7,
      "y": 9,
      "z": -5,
      "name": "Rock_Sandstone_Cobble"
    },
    {
      "x": -7,
      "y": 10,
      "z": -5,
      "name": "Rock_Sandstone_Cobble"
    },
    {
      "x": -7,
      "y": 11,
      "z": -5,
      "name": "Rock_Sandstone_Cobble"
    },
    {
      "x": -7,
      "y": 12,
      "z": -5,
      "name": "Rock_Sandstone_Cobble"
    },
    {
      "x": -7,
      "y": 13,
      "z": -5,
      "name": "Rock_Sandstone_Cobble"
    },
    {
      "x": -7,
      "y": 14,
      "z": -5,
      "name": "Rock_Sandstone_Cobble"
    },
    {
      "x": -7,
      "y": 15,
      "z": -5,
      "name": "Rock_Sandstone_Cobble"
    },
    {
      "x": -7,
      "y": 16,
      "z": -5,
      "name": "Rock_Sandstone_Cobble"
    },
    {
      "x": -7,
      "y": 17,
      "z": -5,
      "name": "Rock_Sandstone_Cobble"
    },
    {
      "x": -7,
      "y": 18,
      "z": -5,
      "name": "Rock_Sandstone_Cobble"
    },
    {
      "x": -7,
      "y": 19,
      "z": -5,
      "name": "Rock_Sandstone_Cobble"
    },
    {
      "x": -7,
      "y": 20,
      "z": -5,
      "name": "Rock_Sandstone_Cobble"
    },
    {
      "x": -7,
      "y": 21,
      "z": -5,
      "name": "Soil_Grass_Dry"
    },
    {
      "x": -7,
      "y": 2,
      "z": -4,
      "name": "Rock_Sandstone_Cobble"
    },
    {
      "x": -7,
      "y": 3,
      "z": -4,
      "name": "Rock_Sandstone_Cobble"
    },
    {
      "x": -7,
      "y": 4,
      "z": -4,
      "name": "Rock_Sandstone_Cobble"
    },
    {
      "x": -7,
      "y": 5,
      "z": -4,
      "name": "Rock_Sandstone_Cobble"
    },
    {
      "x": -7,
      "y": 6,
      "z": -4,
      "name": "Rock_Sandstone_Cobble"
    },
    {
      "x": -7,
      "y": 7,
      "z": -4,
      "name": "Rock_Sandstone_Cobble"
    },
    {
      "x": -7,
      "y": 8,
      "z": -4,
      "name": "Rock_Sandstone_Cobble"
    },
    {
      "x": -7,
      "y": 9,
      "z": -4,
      "name": "Rock_Sandstone_Cobble"
    },
    {
      "x": -7,
      "y": 10,
      "z": -4,
      "name": "Rock_Sandstone_Cobble"
    },
    {
      "x": -7,
      "y": 11,
      "z": -4,
      "name": "Rock_Sandstone_Cobble"
    },
    {
      "x": -7,
      "y": 12,
      "z": -4,
      "name": "Rock_Sandstone_Cobble"
    },
    {
      "x": -7,
      "y": 13,
      "z": -4,
      "name": "Rock_Sandstone_Cobble"
    },
    {
      "x": -7,
      "y": 14,
      "z": -4,
      "name": "Rock_Sandstone_Cobble"
    },
    {
      "x": -7,
      "y": 15,
      "z": -4,
      "name": "Rock_Sandstone_Cobble"
    },
    {
      "x": -7,
      "y": 16,
      "z": -4,
      "name": "Rock_Sandstone_Cobble"
    },
    {
      "x": -7,
      "y": 17,
      "z": -4,
      "name": "Rock_Sandstone_Cobble"
    },
    {
      "x": -7,
      "y": 18,
      "z": -4,
      "name": "Rock_Sandstone_Cobble"
    },
    {
      "x": -7,
      "y": 19,
      "z": -4,
      "name": "Rock_Sandstone_Cobble"
    },
    {
      "x": -7,
      "y": 20,
      "z": -4,
      "name": "Rock_Sandstone_Cobble"
    },
    {
      "x": -7,
      "y": 21,
      "z": -4,
      "name": "Soil_Grass_Dry"
    },
    {
      "x": -7,
      "y": 1,
      "z": -3,
      "name": "Rock_Sandstone_Cobble"
    },
    {
      "x": -7,
      "y": 2,
      "z": -3,
      "name": "Rock_Sandstone_Cobble"
    },
    {
      "x": -7,
      "y": 3,
      "z": -3,
      "name": "Rock_Sandstone_Cobble"
    },
    {
      "x": -7,
      "y": 4,
      "z": -3,
      "name": "Rock_Sandstone_Cobble"
    },
    {
      "x": -7,
      "y": 5,
      "z": -3,
      "name": "Rock_Sandstone_Cobble"
    },
    {
      "x": -7,
      "y": 6,
      "z": -3,
      "name": "Rock_Sandstone_Cobble"
    },
    {
      "x": -7,
      "y": 7,
      "z": -3,
      "name": "Rock_Sandstone_Cobble"
    },
    {
      "x": -7,
      "y": 8,
      "z": -3,
      "name": "Rock_Sandstone_Cobble"
    },
    {
      "x": -7,
      "y": 9,
      "z": -3,
      "name": "Rock_Sandstone_Cobble"
    },
    {
      "x": -7,
      "y": 10,
      "z": -3,
      "name": "Rock_Sandstone_Cobble"
    },
    {
      "x": -7,
      "y": 11,
      "z": -3,
      "name": "Rock_Sandstone_Cobble"
    },
    {
      "x": -7,
      "y": 12,
      "z": -3,
      "name": "Rock_Sandstone_Cobble"
    },
    {
      "x": -7,
      "y": 13,
      "z": -3,
      "name": "Rock_Sandstone_Cobble"
    },
    {
      "x": -7,
      "y": 14,
      "z": -3,
      "name": "Rock_Sandstone_Cobble"
    },
    {
      "x": -7,
      "y": 15,
      "z": -3,
      "name": "Rock_Sandstone_Cobble"
    },
    {
      "x": -7,
      "y": 16,
      "z": -3,
      "name": "Rock_Sandstone_Cobble"
    },
    {
      "x": -7,
      "y": 17,
      "z": -3,
      "name": "Rock_Sandstone_Cobble"
    },
    {
      "x": -7,
      "y": 18,
      "z": -3,
      "name": "Rock_Sandstone_Cobble"
    },
    {
      "x": -7,
      "y": 19,
      "z": -3,
      "name": "Rock_Sandstone_Cobble"
    },
    {
      "x": -7,
      "y": 20,
      "z": -3,
      "name": "Rock_Sandstone_Cobble"
    },
    {
      "x": -7,
      "y": 21,
      "z": -3,
      "name": "Soil_Grass_Dry"
    },
    {
      "x": -7,
      "y": 1,
      "z": -2,
      "name": "Rock_Sandstone_Cobble"
    },
    {
      "x": -7,
      "y": 2,
      "z": -2,
      "name": "Rock_Sandstone_Cobble"
    },
    {
      "x": -7,
      "y": 3,
      "z": -2,
      "name": "Rock_Sandstone_Cobble"
    },
    {
      "x": -7,
      "y": 4,
      "z": -2,
      "name": "Rock_Sandstone_Cobble"
    },
    {
      "x": -7,
      "y": 5,
      "z": -2,
      "name": "Rock_Sandstone_Cobble"
    },
    {
      "x": -7,
      "y": 6,
      "z": -2,
      "name": "Rock_Sandstone_Cobble"
    },
    {
      "x": -7,
      "y": 7,
      "z": -2,
      "name": "Rock_Sandstone_Cobble"
    },
    {
      "x": -7,
      "y": 8,
      "z": -2,
      "name": "Rock_Sandstone_Cobble"
    },
    {
      "x": -7,
      "y": 9,
      "z": -2,
      "name": "Rock_Sandstone_Cobble"
    },
    {
      "x": -7,
      "y": 10,
      "z": -2,
      "name": "Rock_Sandstone_Cobble"
    },
    {
      "x": -7,
      "y": 11,
      "z": -2,
      "name": "Rock_Sandstone_Cobble"
    },
    {
      "x": -7,
      "y": 12,
      "z": -2,
      "name": "Rock_Sandstone_Cobble"
    },
    {
      "x": -7,
      "y": 13,
      "z": -2,
      "name": "Rock_Sandstone_Cobble"
    },
    {
      "x": -7,
      "y": 14,
      "z": -2,
      "name": "Rock_Sandstone_Cobble"
    },
    {
      "x": -7,
      "y": 15,
      "z": -2,
      "name": "Rock_Sandstone_Cobble"
    },
    {
      "x": -7,
      "y": 16,
      "z": -2,
      "name": "Rock_Sandstone_Cobble"
    },
    {
      "x": -7,
      "y": 17,
      "z": -2,
      "name": "Rock_Sandstone_Cobble"
    },
    {
      "x": -7,
      "y": 18,
      "z": -2,
      "name": "Rock_Sandstone_Cobble"
    },
    {
      "x": -7,
      "y": 19,
      "z": -2,
      "name": "Rock_Sandstone_Cobble"
    },
    {
      "x": -7,
      "y": 20,
      "z": -2,
      "name": "Rock_Sandstone_Cobble"
    },
    {
      "x": -7,
      "y": 21,
      "z": -2,
      "name": "Soil_Grass_Dry"
    },
    {
      "x": -7,
      "y": 0,
      "z": -1,
      "name": "Rock_Sandstone_Cobble"
    },
    {
      "x": -7,
      "y": 1,
      "z": -1,
      "name": "Rock_Sandstone_Cobble"
    },
    {
      "x": -7,
      "y": 2,
      "z": -1,
      "name": "Rock_Sandstone_Cobble"
    },
    {
      "x": -7,
      "y": 3,
      "z": -1,
      "name": "Rock_Sandstone_Cobble"
    },
    {
      "x": -7,
      "y": 4,
      "z": -1,
      "name": "Rock_Sandstone_Cobble"
    },
    {
      "x": -7,
      "y": 5,
      "z": -1,
      "name": "Rock_Sandstone_Cobble"
    },
    {
      "x": -7,
      "y": 6,
      "z": -1,
      "name": "Rock_Sandstone_Cobble"
    },
    {
      "x": -7,
      "y": 7,
      "z": -1,
      "name": "Rock_Sandstone_Cobble"
    },
    {
      "x": -7,
      "y": 8,
      "z": -1,
      "name": "Rock_Sandstone_Cobble"
    },
    {
      "x": -7,
      "y": 9,
      "z": -1,
      "name": "Rock_Sandstone_Cobble"
    },
    {
      "x": -7,
      "y": 10,
      "z": -1,
      "name": "Rock_Sandstone_Cobble"
    },
    {
      "x": -7,
      "y": 11,
      "z": -1,
      "name": "Rock_Sandstone_Cobble"
    },
    {
      "x": -7,
      "y": 12,
      "z": -1,
      "name": "Rock_Sandstone_Cobble"
    },
    {
      "x": -7,
      "y": 13,
      "z": -1,
      "name": "Rock_Sandstone_Cobble"
    },
    {
      "x": -7,
      "y": 14,
      "z": -1,
      "name": "Rock_Sandstone_Cobble"
    },
    {
      "x": -7,
      "y": 15,
      "z": -1,
      "name": "Rock_Sandstone_Cobble"
    },
    {
      "x": -7,
      "y": 16,
      "z": -1,
      "name": "Rock_Sandstone_Cobble"
    },
    {
      "x": -7,
      "y": 17,
      "z": -1,
      "name": "Rock_Sandstone_Cobble"
    },
    {
      "x": -7,
      "y": 18,
      "z": -1,
      "name": "Rock_Sandstone_Cobble"
    },
    {
      "x": -7,
      "y": 19,
      "z": -1,
      "name": "Rock_Sandstone_Cobble"
    },
    {
      "x": -7,
      "y": 20,
      "z": -1,
      "name": "Rock_Sandstone_Cobble"
    },
    {
      "x": -7,
      "y": 21,
      "z": -1,
      "name": "Soil_Grass_Dry"
    },
    {
      "x": -7,
      "y": 0,
      "z": 0,
      "name": "Rock_Sandstone_Cobble"
    },
    {
      "x": -7,
      "y": 1,
      "z": 0,
      "name": "Rock_Sandstone_Cobble"
    },
    {
      "x": -7,
      "y": 2,
      "z": 0,
      "name": "Rock_Sandstone_Cobble"
    },
    {
      "x": -7,
      "y": 3,
      "z": 0,
      "name": "Rock_Sandstone_Cobble"
    },
    {
      "x": -7,
      "y": 4,
      "z": 0,
      "name": "Rock_Sandstone_Cobble"
    },
    {
      "x": -7,
      "y": 5,
      "z": 0,
      "name": "Rock_Sandstone_Cobble"
    },
    {
      "x": -7,
      "y": 6,
      "z": 0,
      "name": "Rock_Sandstone_Cobble"
    },
    {
      "x": -7,
      "y": 7,
      "z": 0,
      "name": "Rock_Sandstone_Cobble"
    },
    {
      "x": -7,
      "y": 8,
      "z": 0,
      "name": "Rock_Sandstone_Cobble"
    },
    {
      "x": -7,
      "y": 9,
      "z": 0,
      "name": "Rock_Sandstone_Cobble"
    },
    {
      "x": -7,
      "y": 10,
      "z": 0,
      "name": "Rock_Sandstone_Cobble"
    },
    {
      "x": -7,
      "y": 11,
      "z": 0,
      "name": "Rock_Sandstone_Cobble"
    },
    {
      "x": -7,
      "y": 12,
      "z": 0,
      "name": "Rock_Sandstone_Cobble"
    },
    {
      "x": -7,
      "y": 13,
      "z": 0,
      "name": "Rock_Sandstone_Cobble"
    },
    {
      "x": -7,
      "y": 14,
      "z": 0,
      "name": "Rock_Sandstone_Cobble"
    },
    {
      "x": -7,
      "y": 15,
      "z": 0,
      "name": "Rock_Sandstone_Cobble"
    },
    {
      "x": -7,
      "y": 16,
      "z": 0,
      "name": "Rock_Sandstone_Cobble"
    },
    {
      "x": -7,
      "y": 17,
      "z": 0,
      "name": "Rock_Sandstone_Cobble"
    },
    {
      "x": -7,
      "y": 18,
      "z": 0,
      "name": "Rock_Sandstone_Cobble"
    },
    {
      "x": -7,
      "y": 19,
      "z": 0,
      "name": "Rock_Sandstone_Cobble"
    },
    {
      "x": -7,
      "y": 20,
      "z": 0,
      "name": "Rock_Sandstone_Cobble"
    },
    {
      "x": -7,
      "y": 21,
      "z": 0,
      "name": "Soil_Grass_Dry"
    },
    {
      "x": -7,
      "y": 0,
      "z": 1,
      "name": "Rock_Sandstone_Cobble"
    },
    {
      "x": -7,
      "y": 1,
      "z": 1,
      "name": "Rock_Sandstone_Cobble"
    },
    {
      "x": -7,
      "y": 2,
      "z": 1,
      "name": "Rock_Sandstone_Cobble"
    },
    {
      "x": -7,
      "y": 3,
      "z": 1,
      "name": "Rock_Sandstone_Cobble"
    },
    {
      "x": -7,
      "y": 4,
      "z": 1,
      "name": "Rock_Sandstone_Cobble"
    },
    {
      "x": -7,
      "y": 5,
      "z": 1,
      "name": "Rock_Sandstone_Cobble"
    },
    {
      "x": -7,
      "y": 6,
      "z": 1,
      "name": "Rock_Sandstone_Cobble"
    },
    {
      "x": -7,
      "y": 7,
      "z": 1,
      "name": "Rock_Sandstone_Cobble"
    },
    {
      "x": -7,
      "y": 8,
      "z": 1,
      "name": "Rock_Sandstone_Cobble"
    },
    {
      "x": -7,
      "y": 9,
      "z": 1,
      "name": "Rock_Sandstone_Cobble"
    },
    {
      "x": -7,
      "y": 10,
      "z": 1,
      "name": "Rock_Sandstone_Cobble"
    },
    {
      "x": -7,
      "y": 11,
      "z": 1,
      "name": "Rock_Sandstone_Cobble"
    },
    {
      "x": -7,
      "y": 12,
      "z": 1,
      "name": "Rock_Sandstone_Cobble"
    },
    {
      "x": -7,
      "y": 13,
      "z": 1,
      "name": "Rock_Sandstone_Cobble"
    },
    {
      "x": -7,
      "y": 14,
      "z": 1,
      "name": "Rock_Sandstone_Cobble"
    },
    {
      "x": -7,
      "y": 15,
      "z": 1,
      "name": "Rock_Sandstone_Cobble"
    },
    {
      "x": -7,
      "y": 16,
      "z": 1,
      "name": "Rock_Sandstone_Cobble"
    },
    {
      "x": -7,
      "y": 17,
      "z": 1,
      "name": "Rock_Sandstone_Cobble"
    },
    {
      "x": -7,
      "y": 18,
      "z": 1,
      "name": "Rock_Sandstone_Cobble"
    },
    {
      "x": -7,
      "y": 19,
      "z": 1,
      "name": "Rock_Sandstone_Cobble"
    },
    {
      "x": -7,
      "y": 20,
      "z": 1,
      "name": "Rock_Sandstone_Cobble"
    },
    {
      "x": -7,
      "y": 21,
      "z": 1,
      "name": "Soil_Grass_Dry"
    },
    {
      "x": -7,
      "y": 0,
      "z": 2,
      "name": "Rock_Sandstone_Cobble"
    },
    {
      "x": -7,
      "y": 1,
      "z": 2,
      "name": "Rock_Sandstone_Cobble"
    },
    {
      "x": -7,
      "y": 2,
      "z": 2,
      "name": "Rock_Sandstone_Cobble"
    },
    {
      "x": -7,
      "y": 3,
      "z": 2,
      "name": "Rock_Sandstone_Cobble"
    },
    {
      "x": -7,
      "y": 4,
      "z": 2,
      "name": "Rock_Sandstone_Cobble"
    },
    {
      "x": -7,
      "y": 5,
      "z": 2,
      "name": "Rock_Sandstone_Cobble"
    },
    {
      "x": -7,
      "y": 6,
      "z": 2,
      "name": "Rock_Sandstone_Cobble"
    },
    {
      "x": -7,
      "y": 7,
      "z": 2,
      "name": "Rock_Sandstone_Cobble"
    },
    {
      "x": -7,
      "y": 8,
      "z": 2,
      "name": "Rock_Sandstone_Cobble"
    },
    {
      "x": -7,
      "y": 9,
      "z": 2,
      "name": "Rock_Sandstone_Cobble"
    },
    {
      "x": -7,
      "y": 10,
      "z": 2,
      "name": "Rock_Sandstone_Cobble"
    },
    {
      "x": -7,
      "y": 11,
      "z": 2,
      "name": "Rock_Sandstone_Cobble"
    },
    {
      "x": -7,
      "y": 12,
      "z": 2,
      "name": "Rock_Sandstone_Cobble"
    },
    {
      "x": -7,
      "y": 13,
      "z": 2,
      "name": "Rock_Sandstone_Cobble"
    },
    {
      "x": -7,
      "y": 14,
      "z": 2,
      "name": "Rock_Sandstone_Cobble"
    },
    {
      "x": -7,
      "y": 15,
      "z": 2,
      "name": "Rock_Sandstone_Cobble"
    },
    {
      "x": -7,
      "y": 16,
      "z": 2,
      "name": "Rock_Sandstone_Cobble"
    },
    {
      "x": -7,
      "y": 17,
      "z": 2,
      "name": "Rock_Sandstone_Cobble"
    },
    {
      "x": -7,
      "y": 18,
      "z": 2,
      "name": "Rock_Sandstone_Cobble"
    },
    {
      "x": -7,
      "y": 19,
      "z": 2,
      "name": "Rock_Sandstone_Cobble"
    },
    {
      "x": -7,
      "y": 20,
      "z": 2,
      "name": "Rock_Sandstone_Cobble"
    },
    {
      "x": -7,
      "y": 21,
      "z": 2,
      "name": "Soil_Grass_Dry"
    },
    {
      "x": -7,
      "y": 22,
      "z": 2,
      "name": "Plant_Grass_Arid"
    },
    {
      "x": -7,
      "y": 0,
      "z": 3,
      "name": "Rock_Sandstone_Cobble"
    },
    {
      "x": -7,
      "y": 1,
      "z": 3,
      "name": "Rock_Sandstone_Cobble"
    },
    {
      "x": -7,
      "y": 2,
      "z": 3,
      "name": "Rock_Sandstone_Cobble"
    },
    {
      "x": -7,
      "y": 3,
      "z": 3,
      "name": "Rock_Sandstone_Cobble"
    },
    {
      "x": -7,
      "y": 4,
      "z": 3,
      "name": "Rock_Sandstone_Cobble"
    },
    {
      "x": -7,
      "y": 5,
      "z": 3,
      "name": "Rock_Sandstone_Cobble"
    },
    {
      "x": -7,
      "y": 6,
      "z": 3,
      "name": "Rock_Sandstone_Cobble"
    },
    {
      "x": -7,
      "y": 7,
      "z": 3,
      "name": "Rock_Sandstone_Cobble"
    },
    {
      "x": -7,
      "y": 8,
      "z": 3,
      "name": "Rock_Sandstone_Cobble"
    },
    {
      "x": -7,
      "y": 9,
      "z": 3,
      "name": "Rock_Sandstone_Cobble"
    },
    {
      "x": -7,
      "y": 10,
      "z": 3,
      "name": "Rock_Sandstone_Cobble"
    },
    {
      "x": -7,
      "y": 11,
      "z": 3,
      "name": "Rock_Sandstone_Cobble"
    },
    {
      "x": -7,
      "y": 12,
      "z": 3,
      "name": "Rock_Sandstone_Cobble"
    },
    {
      "x": -7,
      "y": 13,
      "z": 3,
      "name": "Rock_Sandstone_Cobble"
    },
    {
      "x": -7,
      "y": 14,
      "z": 3,
      "name": "Rock_Sandstone_Cobble"
    },
    {
      "x": -7,
      "y": 15,
      "z": 3,
      "name": "Rock_Sandstone_Cobble"
    },
    {
      "x": -7,
      "y": 16,
      "z": 3,
      "name": "Rock_Sandstone_Cobble"
    },
    {
      "x": -7,
      "y": 17,
      "z": 3,
      "name": "Rock_Sandstone_Cobble"
    },
    {
      "x": -7,
      "y": 18,
      "z": 3,
      "name": "Rock_Sandstone_Cobble"
    },
    {
      "x": -7,
      "y": 19,
      "z": 3,
      "name": "Rock_Sandstone_Cobble"
    },
    {
      "x": -7,
      "y": 20,
      "z": 3,
      "name": "Rock_Sandstone_Cobble"
    },
    {
      "x": -7,
      "y": 21,
      "z": 3,
      "name": "Soil_Grass_Dry"
    },
    {
      "x": -7,
      "y": 0,
      "z": 4,
      "name": "Rock_Sandstone_Cobble"
    },
    {
      "x": -7,
      "y": 1,
      "z": 4,
      "name": "Rock_Sandstone_Cobble"
    },
    {
      "x": -7,
      "y": 2,
      "z": 4,
      "name": "Rock_Sandstone_Cobble"
    },
    {
      "x": -7,
      "y": 3,
      "z": 4,
      "name": "Rock_Sandstone_Cobble"
    },
    {
      "x": -7,
      "y": 4,
      "z": 4,
      "name": "Rock_Sandstone_Cobble"
    },
    {
      "x": -7,
      "y": 5,
      "z": 4,
      "name": "Rock_Sandstone_Cobble"
    },
    {
      "x": -7,
      "y": 6,
      "z": 4,
      "name": "Rock_Sandstone_Cobble"
    },
    {
      "x": -7,
      "y": 7,
      "z": 4,
      "name": "Rock_Sandstone_Cobble"
    },
    {
      "x": -7,
      "y": 8,
      "z": 4,
      "name": "Rock_Sandstone_Cobble"
    },
    {
      "x": -7,
      "y": 9,
      "z": 4,
      "name": "Rock_Sandstone_Cobble"
    },
    {
      "x": -7,
      "y": 10,
      "z": 4,
      "name": "Rock_Sandstone_Cobble"
    },
    {
      "x": -7,
      "y": 11,
      "z": 4,
      "name": "Rock_Sandstone_Cobble"
    },
    {
      "x": -7,
      "y": 12,
      "z": 4,
      "name": "Rock_Sandstone_Cobble"
    },
    {
      "x": -7,
      "y": 13,
      "z": 4,
      "name": "Rock_Sandstone_Cobble"
    },
    {
      "x": -7,
      "y": 14,
      "z": 4,
      "name": "Rock_Sandstone_Cobble"
    },
    {
      "x": -7,
      "y": 15,
      "z": 4,
      "name": "Rock_Sandstone_Cobble"
    },
    {
      "x": -7,
      "y": 16,
      "z": 4,
      "name": "Rock_Sandstone_Cobble"
    },
    {
      "x": -7,
      "y": 17,
      "z": 4,
      "name": "Rock_Sandstone_Cobble"
    },
    {
      "x": -7,
      "y": 18,
      "z": 4,
      "name": "Rock_Sandstone_Cobble"
    },
    {
      "x": -7,
      "y": 19,
      "z": 4,
      "name": "Rock_Sandstone_Cobble"
    },
    {
      "x": -7,
      "y": 20,
      "z": 4,
      "name": "Rock_Sandstone_Cobble"
    },
    {
      "x": -7,
      "y": 21,
      "z": 4,
      "name": "Soil_Grass_Dry"
    },
    {
      "x": -7,
      "y": 0,
      "z": 5,
      "name": "Rock_Sandstone_Cobble"
    },
    {
      "x": -7,
      "y": 1,
      "z": 5,
      "name": "Rock_Sandstone_Cobble"
    },
    {
      "x": -7,
      "y": 2,
      "z": 5,
      "name": "Rock_Sandstone_Cobble"
    },
    {
      "x": -7,
      "y": 3,
      "z": 5,
      "name": "Rock_Sandstone_Cobble"
    },
    {
      "x": -7,
      "y": 4,
      "z": 5,
      "name": "Rock_Sandstone_Cobble"
    },
    {
      "x": -7,
      "y": 5,
      "z": 5,
      "name": "Rock_Sandstone_Cobble"
    },
    {
      "x": -7,
      "y": 6,
      "z": 5,
      "name": "Rock_Sandstone_Cobble"
    },
    {
      "x": -7,
      "y": 7,
      "z": 5,
      "name": "Rock_Sandstone_Cobble"
    },
    {
      "x": -7,
      "y": 8,
      "z": 5,
      "name": "Rock_Sandstone_Cobble"
    },
    {
      "x": -7,
      "y": 9,
      "z": 5,
      "name": "Rock_Sandstone_Cobble"
    },
    {
      "x": -7,
      "y": 10,
      "z": 5,
      "name": "Rock_Sandstone_Cobble"
    },
    {
      "x": -7,
      "y": 11,
      "z": 5,
      "name": "Rock_Sandstone_Cobble"
    },
    {
      "x": -7,
      "y": 12,
      "z": 5,
      "name": "Rock_Sandstone_Cobble"
    },
    {
      "x": -7,
      "y": 13,
      "z": 5,
      "name": "Rock_Sandstone_Cobble"
    },
    {
      "x": -7,
      "y": 14,
      "z": 5,
      "name": "Rock_Sandstone_Cobble"
    },
    {
      "x": -7,
      "y": 15,
      "z": 5,
      "name": "Rock_Sandstone_Cobble"
    },
    {
      "x": -7,
      "y": 16,
      "z": 5,
      "name": "Rock_Sandstone_Cobble"
    },
    {
      "x": -7,
      "y": 17,
      "z": 5,
      "name": "Rock_Sandstone_Cobble"
    },
    {
      "x": -7,
      "y": 18,
      "z": 5,
      "name": "Rock_Sandstone_Cobble"
    },
    {
      "x": -7,
      "y": 19,
      "z": 5,
      "name": "Rock_Sandstone_Cobble"
    },
    {
      "x": -7,
      "y": 20,
      "z": 5,
      "name": "Rock_Sandstone_Cobble"
    },
    {
      "x": -7,
      "y": 21,
      "z": 5,
      "name": "Rock_Sandstone_Cobble"
    },
    {
      "x": -7,
      "y": 22,
      "z": 5,
      "name": "Rock_Sandstone_Brick_Half"
    },
    {
      "x": -7,
      "y": 0,
      "z": 6,
      "name": "Rock_Sandstone_Cobble"
    },
    {
      "x": -7,
      "y": 1,
      "z": 6,
      "name": "Rock_Sandstone_Cobble"
    },
    {
      "x": -7,
      "y": 2,
      "z": 6,
      "name": "Rock_Sandstone_Cobble"
    },
    {
      "x": -7,
      "y": 3,
      "z": 6,
      "name": "Rock_Sandstone_Cobble"
    },
    {
      "x": -7,
      "y": 4,
      "z": 6,
      "name": "Rock_Sandstone_Cobble"
    },
    {
      "x": -7,
      "y": 5,
      "z": 6,
      "name": "Rock_Sandstone_Cobble"
    },
    {
      "x": -7,
      "y": 6,
      "z": 6,
      "name": "Rock_Sandstone_Cobble"
    },
    {
      "x": -7,
      "y": 7,
      "z": 6,
      "name": "Rock_Sandstone_Cobble"
    },
    {
      "x": -7,
      "y": 8,
      "z": 6,
      "name": "Rock_Sandstone_Cobble"
    },
    {
      "x": -7,
      "y": 9,
      "z": 6,
      "name": "Rock_Sandstone_Cobble"
    },
    {
      "x": -7,
      "y": 10,
      "z": 6,
      "name": "Rock_Sandstone_Cobble"
    },
    {
      "x": -7,
      "y": 11,
      "z": 6,
      "name": "Rock_Sandstone_Cobble"
    },
    {
      "x": -7,
      "y": 0,
      "z": 7,
      "name": "Rock_Sandstone_Cobble"
    },
    {
      "x": -7,
      "y": 1,
      "z": 7,
      "name": "Rock_Sandstone_Cobble"
    },
    {
      "x": -7,
      "y": 2,
      "z": 7,
      "name": "Rock_Sandstone_Cobble"
    },
    {
      "x": -7,
      "y": 3,
      "z": 7,
      "name": "Rock_Sandstone_Cobble"
    },
    {
      "x": -7,
      "y": 4,
      "z": 7,
      "name": "Rock_Sandstone_Cobble"
    },
    {
      "x": -7,
      "y": 5,
      "z": 7,
      "name": "Rock_Sandstone_Cobble"
    },
    {
      "x": -7,
      "y": 6,
      "z": 7,
      "name": "Rock_Sandstone_Cobble"
    },
    {
      "x": -7,
      "y": 7,
      "z": 7,
      "name": "Rock_Sandstone_Cobble"
    },
    {
      "x": -7,
      "y": 8,
      "z": 7,
      "name": "Rock_Sandstone_Cobble"
    },
    {
      "x": -7,
      "y": 9,
      "z": 7,
      "name": "Rock_Sandstone_Cobble"
    },
    {
      "x": -7,
      "y": 10,
      "z": 7,
      "name": "Rock_Sandstone_Cobble"
    },
    {
      "x": -7,
      "y": 11,
      "z": 7,
      "name": "Rock_Sandstone_Cobble"
    },
    {
      "x": -7,
      "y": 0,
      "z": 8,
      "name": "Rock_Sandstone_Cobble"
    },
    {
      "x": -7,
      "y": 1,
      "z": 8,
      "name": "Rock_Sandstone_Cobble"
    },
    {
      "x": -7,
      "y": 2,
      "z": 8,
      "name": "Rock_Sandstone_Cobble"
    },
    {
      "x": -7,
      "y": 3,
      "z": 8,
      "name": "Rock_Sandstone_Cobble"
    },
    {
      "x": -7,
      "y": 4,
      "z": 8,
      "name": "Rock_Sandstone_Cobble"
    },
    {
      "x": -7,
      "y": 5,
      "z": 8,
      "name": "Rock_Sandstone_Cobble"
    },
    {
      "x": -7,
      "y": 6,
      "z": 8,
      "name": "Rock_Sandstone_Cobble"
    },
    {
      "x": -7,
      "y": 7,
      "z": 8,
      "name": "Rock_Sandstone_Cobble"
    },
    {
      "x": -7,
      "y": 8,
      "z": 8,
      "name": "Rock_Sandstone_Cobble"
    },
    {
      "x": -7,
      "y": 9,
      "z": 8,
      "name": "Rock_Sandstone_Cobble"
    },
    {
      "x": -7,
      "y": 10,
      "z": 8,
      "name": "Rock_Sandstone_Cobble"
    },
    {
      "x": -7,
      "y": 11,
      "z": 8,
      "name": "Rock_Sandstone_Cobble"
    },
    {
      "x": -7,
      "y": 0,
      "z": 9,
      "name": "Rock_Sandstone_Cobble"
    },
    {
      "x": -7,
      "y": 1,
      "z": 9,
      "name": "Rock_Sandstone_Cobble"
    },
    {
      "x": -7,
      "y": 2,
      "z": 9,
      "name": "Rock_Sandstone_Cobble"
    },
    {
      "x": -7,
      "y": 3,
      "z": 9,
      "name": "Rock_Sandstone_Cobble"
    },
    {
      "x": -7,
      "y": 4,
      "z": 9,
      "name": "Rock_Sandstone_Cobble"
    },
    {
      "x": -7,
      "y": 5,
      "z": 9,
      "name": "Rock_Sandstone_Cobble"
    },
    {
      "x": -7,
      "y": 6,
      "z": 9,
      "name": "Rock_Sandstone_Cobble"
    },
    {
      "x": -7,
      "y": 7,
      "z": 9,
      "name": "Rock_Sandstone_Cobble"
    },
    {
      "x": -7,
      "y": 8,
      "z": 9,
      "name": "Rock_Sandstone_Cobble"
    },
    {
      "x": -7,
      "y": 9,
      "z": 9,
      "name": "Rock_Sandstone_Cobble"
    },
    {
      "x": -7,
      "y": 10,
      "z": 9,
      "name": "Rock_Sandstone_Cobble"
    },
    {
      "x": -7,
      "y": 11,
      "z": 9,
      "name": "Rock_Sandstone_Cobble"
    },
    {
      "x": -7,
      "y": 12,
      "z": 9,
      "name": "Rock_Sandstone_Cobble"
    },
    {
      "x": -7,
      "y": 13,
      "z": 9,
      "name": "Rock_Sandstone_Cobble"
    },
    {
      "x": -7,
      "y": 14,
      "z": 9,
      "name": "Rock_Sandstone_Cobble"
    },
    {
      "x": -7,
      "y": 15,
      "z": 9,
      "name": "Rock_Sandstone_Cobble"
    },
    {
      "x": -7,
      "y": 16,
      "z": 9,
      "name": "Rock_Sandstone_Cobble"
    },
    {
      "x": -7,
      "y": 17,
      "z": 9,
      "name": "Rock_Sandstone_Cobble"
    },
    {
      "x": -7,
      "y": 18,
      "z": 9,
      "name": "Rock_Sandstone_Cobble"
    },
    {
      "x": -7,
      "y": 19,
      "z": 9,
      "name": "Rock_Sandstone_Cobble"
    },
    {
      "x": -7,
      "y": 20,
      "z": 9,
      "name": "Wood_Dry_Trunk_Full",
      "rotation": 5
    },
    {
      "x": -6,
      "y": 22,
      "z": -8,
      "name": "Rock_Sandstone_Brick"
    },
    {
      "x": -6,
      "y": 19,
      "z": -7,
      "name": "Rock_Sandstone_Cobble"
    },
    {
      "x": -6,
      "y": 20,
      "z": -7,
      "name": "Rock_Sandstone_Cobble"
    },
    {
      "x": -6,
      "y": 21,
      "z": -7,
      "name": "Soil_Grass_Dry"
    },
    {
      "x": -6,
      "y": 14,
      "z": -6,
      "name": "Rock_Sandstone_Cobble"
    },
    {
      "x": -6,
      "y": 15,
      "z": -6,
      "name": "Rock_Sandstone_Cobble"
    },
    {
      "x": -6,
      "y": 16,
      "z": -6,
      "name": "Rock_Sandstone_Cobble"
    },
    {
      "x": -6,
      "y": 17,
      "z": -6,
      "name": "Rock_Sandstone_Cobble"
    },
    {
      "x": -6,
      "y": 18,
      "z": -6,
      "name": "Rock_Sandstone_Cobble"
    },
    {
      "x": -6,
      "y": 19,
      "z": -6,
      "name": "Rock_Sandstone_Cobble"
    },
    {
      "x": -6,
      "y": 20,
      "z": -6,
      "name": "Rock_Sandstone_Cobble"
    },
    {
      "x": -6,
      "y": 21,
      "z": -6,
      "name": "Soil_Grass_Dry"
    },
    {
      "x": -6,
      "y": 22,
      "z": -6,
      "name": "Deco_Target"
    },
    {
      "x": -6,
      "y": 4,
      "z": -5,
      "name": "Rock_Sandstone_Cobble"
    },
    {
      "x": -6,
      "y": 5,
      "z": -5,
      "name": "Rock_Sandstone_Cobble"
    },
    {
      "x": -6,
      "y": 6,
      "z": -5,
      "name": "Rock_Sandstone_Cobble"
    },
    {
      "x": -6,
      "y": 7,
      "z": -5,
      "name": "Rock_Sandstone_Cobble"
    },
    {
      "x": -6,
      "y": 8,
      "z": -5,
      "name": "Rock_Sandstone_Cobble"
    },
    {
      "x": -6,
      "y": 9,
      "z": -5,
      "name": "Rock_Sandstone_Cobble"
    },
    {
      "x": -6,
      "y": 10,
      "z": -5,
      "name": "Rock_Sandstone_Cobble"
    },
    {
      "x": -6,
      "y": 11,
      "z": -5,
      "name": "Rock_Sandstone_Cobble"
    },
    {
      "x": -6,
      "y": 12,
      "z": -5,
      "name": "Rock_Sandstone_Cobble"
    },
    {
      "x": -6,
      "y": 13,
      "z": -5,
      "name": "Rock_Sandstone_Cobble"
    },
    {
      "x": -6,
      "y": 14,
      "z": -5,
      "name": "Rock_Sandstone_Cobble"
    },
    {
      "x": -6,
      "y": 15,
      "z": -5,
      "name": "Rock_Sandstone_Cobble"
    },
    {
      "x": -6,
      "y": 16,
      "z": -5,
      "name": "Rock_Sandstone_Cobble"
    },
    {
      "x": -6,
      "y": 17,
      "z": -5,
      "name": "Rock_Sandstone_Cobble"
    },
    {
      "x": -6,
      "y": 18,
      "z": -5,
      "name": "Rock_Sandstone_Cobble"
    },
    {
      "x": -6,
      "y": 19,
      "z": -5,
      "name": "Rock_Sandstone_Cobble"
    },
    {
      "x": -6,
      "y": 20,
      "z": -5,
      "name": "Rock_Sandstone_Cobble"
    },
    {
      "x": -6,
      "y": 21,
      "z": -5,
      "name": "Soil_Grass_Dry"
    },
    {
      "x": -6,
      "y": 3,
      "z": -4,
      "name": "Rock_Sandstone_Cobble"
    },
    {
      "x": -6,
      "y": 4,
      "z": -4,
      "name": "Rock_Sandstone_Cobble"
    },
    {
      "x": -6,
      "y": 5,
      "z": -4,
      "name": "Rock_Sandstone_Cobble"
    },
    {
      "x": -6,
      "y": 6,
      "z": -4,
      "name": "Rock_Sandstone_Cobble"
    },
    {
      "x": -6,
      "y": 7,
      "z": -4,
      "name": "Rock_Sandstone_Cobble"
    },
    {
      "x": -6,
      "y": 8,
      "z": -4,
      "name": "Rock_Sandstone_Cobble"
    },
    {
      "x": -6,
      "y": 9,
      "z": -4,
      "name": "Rock_Sandstone_Cobble"
    },
    {
      "x": -6,
      "y": 10,
      "z": -4,
      "name": "Rock_Sandstone_Cobble"
    },
    {
      "x": -6,
      "y": 11,
      "z": -4,
      "name": "Rock_Sandstone_Cobble"
    },
    {
      "x": -6,
      "y": 12,
      "z": -4,
      "name": "Rock_Sandstone_Cobble"
    },
    {
      "x": -6,
      "y": 13,
      "z": -4,
      "name": "Rock_Sandstone_Cobble"
    },
    {
      "x": -6,
      "y": 14,
      "z": -4,
      "name": "Rock_Sandstone_Cobble"
    },
    {
      "x": -6,
      "y": 15,
      "z": -4,
      "name": "Rock_Sandstone_Cobble"
    },
    {
      "x": -6,
      "y": 16,
      "z": -4,
      "name": "Rock_Sandstone_Cobble"
    },
    {
      "x": -6,
      "y": 17,
      "z": -4,
      "name": "Rock_Sandstone_Cobble"
    },
    {
      "x": -6,
      "y": 18,
      "z": -4,
      "name": "Rock_Sandstone_Cobble"
    },
    {
      "x": -6,
      "y": 19,
      "z": -4,
      "name": "Rock_Sandstone_Cobble"
    },
    {
      "x": -6,
      "y": 20,
      "z": -4,
      "name": "Rock_Sandstone_Cobble"
    },
    {
      "x": -6,
      "y": 21,
      "z": -4,
      "name": "Soil_Grass_Dry"
    },
    {
      "x": -6,
      "y": 2,
      "z": -3,
      "name": "Rock_Sandstone_Cobble"
    },
    {
      "x": -6,
      "y": 3,
      "z": -3,
      "name": "Rock_Sandstone_Cobble"
    },
    {
      "x": -6,
      "y": 4,
      "z": -3,
      "name": "Rock_Sandstone_Cobble"
    },
    {
      "x": -6,
      "y": 5,
      "z": -3,
      "name": "Rock_Sandstone_Cobble"
    },
    {
      "x": -6,
      "y": 6,
      "z": -3,
      "name": "Rock_Sandstone_Cobble"
    },
    {
      "x": -6,
      "y": 7,
      "z": -3,
      "name": "Rock_Sandstone_Cobble"
    },
    {
      "x": -6,
      "y": 8,
      "z": -3,
      "name": "Rock_Sandstone_Cobble"
    },
    {
      "x": -6,
      "y": 9,
      "z": -3,
      "name": "Rock_Sandstone_Cobble"
    },
    {
      "x": -6,
      "y": 10,
      "z": -3,
      "name": "Rock_Sandstone_Cobble"
    },
    {
      "x": -6,
      "y": 11,
      "z": -3,
      "name": "Rock_Sandstone_Cobble"
    },
    {
      "x": -6,
      "y": 12,
      "z": -3,
      "name": "Rock_Sandstone_Cobble"
    },
    {
      "x": -6,
      "y": 13,
      "z": -3,
      "name": "Rock_Sandstone_Cobble"
    },
    {
      "x": -6,
      "y": 14,
      "z": -3,
      "name": "Rock_Sandstone_Cobble"
    },
    {
      "x": -6,
      "y": 15,
      "z": -3,
      "name": "Rock_Sandstone_Cobble"
    },
    {
      "x": -6,
      "y": 16,
      "z": -3,
      "name": "Rock_Sandstone_Cobble"
    },
    {
      "x": -6,
      "y": 17,
      "z": -3,
      "name": "Rock_Sandstone_Cobble"
    },
    {
      "x": -6,
      "y": 18,
      "z": -3,
      "name": "Rock_Sandstone_Cobble"
    },
    {
      "x": -6,
      "y": 19,
      "z": -3,
      "name": "Rock_Sandstone_Cobble"
    },
    {
      "x": -6,
      "y": 20,
      "z": -3,
      "name": "Rock_Sandstone_Cobble"
    },
    {
      "x": -6,
      "y": 21,
      "z": -3,
      "name": "Soil_Grass_Dry"
    },
    {
      "x": -6,
      "y": 1,
      "z": -2,
      "name": "Rock_Sandstone_Cobble"
    },
    {
      "x": -6,
      "y": 2,
      "z": -2,
      "name": "Rock_Sandstone_Cobble"
    },
    {
      "x": -6,
      "y": 3,
      "z": -2,
      "name": "Rock_Sandstone_Cobble"
    },
    {
      "x": -6,
      "y": 4,
      "z": -2,
      "name": "Rock_Sandstone_Cobble"
    },
    {
      "x": -6,
      "y": 5,
      "z": -2,
      "name": "Rock_Sandstone_Cobble"
    },
    {
      "x": -6,
      "y": 6,
      "z": -2,
      "name": "Rock_Sandstone_Cobble"
    },
    {
      "x": -6,
      "y": 7,
      "z": -2,
      "name": "Rock_Sandstone_Cobble"
    },
    {
      "x": -6,
      "y": 8,
      "z": -2,
      "name": "Rock_Sandstone_Cobble"
    },
    {
      "x": -6,
      "y": 9,
      "z": -2,
      "name": "Rock_Sandstone_Cobble"
    },
    {
      "x": -6,
      "y": 10,
      "z": -2,
      "name": "Rock_Sandstone_Cobble"
    },
    {
      "x": -6,
      "y": 11,
      "z": -2,
      "name": "Rock_Sandstone_Cobble"
    },
    {
      "x": -6,
      "y": 12,
      "z": -2,
      "name": "Rock_Sandstone_Cobble"
    },
    {
      "x": -6,
      "y": 13,
      "z": -2,
      "name": "Rock_Sandstone_Cobble"
    },
    {
      "x": -6,
      "y": 14,
      "z": -2,
      "name": "Rock_Sandstone_Cobble"
    },
    {
      "x": -6,
      "y": 15,
      "z": -2,
      "name": "Rock_Sandstone_Cobble"
    },
    {
      "x": -6,
      "y": 16,
      "z": -2,
      "name": "Rock_Sandstone_Cobble"
    },
    {
      "x": -6,
      "y": 17,
      "z": -2,
      "name": "Rock_Sandstone_Cobble"
    },
    {
      "x": -6,
      "y": 18,
      "z": -2,
      "name": "Rock_Sandstone_Cobble"
    },
    {
      "x": -6,
      "y": 19,
      "z": -2,
      "name": "Rock_Sandstone_Cobble"
    },
    {
      "x": -6,
      "y": 20,
      "z": -2,
      "name": "Rock_Sandstone_Cobble"
    },
    {
      "x": -6,
      "y": 21,
      "z": -2,
      "name": "Soil_Grass_Dry"
    },
    {
      "x": -6,
      "y": 1,
      "z": -1,
      "name": "Rock_Sandstone_Cobble"
    },
    {
      "x": -6,
      "y": 2,
      "z": -1,
      "name": "Rock_Sandstone_Cobble"
    },
    {
      "x": -6,
      "y": 3,
      "z": -1,
      "name": "Rock_Sandstone_Cobble"
    },
    {
      "x": -6,
      "y": 4,
      "z": -1,
      "name": "Rock_Sandstone_Cobble"
    },
    {
      "x": -6,
      "y": 5,
      "z": -1,
      "name": "Rock_Sandstone_Cobble"
    },
    {
      "x": -6,
      "y": 6,
      "z": -1,
      "name": "Rock_Sandstone_Cobble"
    },
    {
      "x": -6,
      "y": 7,
      "z": -1,
      "name": "Rock_Sandstone_Cobble"
    },
    {
      "x": -6,
      "y": 8,
      "z": -1,
      "name": "Rock_Sandstone_Cobble"
    },
    {
      "x": -6,
      "y": 9,
      "z": -1,
      "name": "Rock_Sandstone_Cobble"
    },
    {
      "x": -6,
      "y": 10,
      "z": -1,
      "name": "Rock_Sandstone_Cobble"
    },
    {
      "x": -6,
      "y": 11,
      "z": -1,
      "name": "Rock_Sandstone_Cobble"
    },
    {
      "x": -6,
      "y": 12,
      "z": -1,
      "name": "Rock_Sandstone_Cobble"
    },
    {
      "x": -6,
      "y": 13,
      "z": -1,
      "name": "Rock_Sandstone_Cobble"
    },
    {
      "x": -6,
      "y": 14,
      "z": -1,
      "name": "Rock_Sandstone_Cobble"
    },
    {
      "x": -6,
      "y": 15,
      "z": -1,
      "name": "Rock_Sandstone_Cobble"
    },
    {
      "x": -6,
      "y": 16,
      "z": -1,
      "name": "Rock_Sandstone_Cobble"
    },
    {
      "x": -6,
      "y": 17,
      "z": -1,
      "name": "Rock_Sandstone_Cobble"
    },
    {
      "x": -6,
      "y": 18,
      "z": -1,
      "name": "Rock_Sandstone_Cobble"
    },
    {
      "x": -6,
      "y": 19,
      "z": -1,
      "name": "Rock_Sandstone_Cobble"
    },
    {
      "x": -6,
      "y": 20,
      "z": -1,
      "name": "Rock_Sandstone_Cobble"
    },
    {
      "x": -6,
      "y": 21,
      "z": -1,
      "name": "Soil_Grass_Dry"
    },
    {
      "x": -6,
      "y": 0,
      "z": 0,
      "name": "Rock_Sandstone_Cobble"
    },
    {
      "x": -6,
      "y": 1,
      "z": 0,
      "name": "Rock_Sandstone_Cobble"
    },
    {
      "x": -6,
