{
  "version": 8,
  "blockIdVersion": 11,
  "anchorX": 0,
  "anchorY": 0,
  "anchorZ": 0,
  "blocks": [
    {
      "x": -3,
      "y": 0,
      "z": -3,
      "name": "Ore_Iron_Basalt_Cracked"
    },
    {
      "x": -3,
      "y": 1,
      "z": -3,
      "name": "Empty"
    },
    {
      "x": -3,
      "y": 2,
      "z": -3,
      "name": "Empty"
    },
    {
      "x": -3,
      "y": 3,
      "z": -3,
      "name": "Empty"
    },
    {
      "x": -3,
      "y": 0,
      "z": -2,
      "name": "Rock_Basalt"
    },
    {
      "x": -3,
      "y": 1,
      "z": -2,
      "name": "Empty"
    },
    {
      "x": -3,
      "y": 2,
      "z": -2,
      "name": "Empty"
    },
    {
      "x": -3,
      "y": 3,
      "z": -2,
      "name": "Empty"
    },
    {
      "x": -3,
      "y": 0,
      "z": -1,
      "name": "Ore_Iron_Basalt_Cracked"
    },
    {
      "x": -3,
      "y": 1,
      "z": -1,
      "name": "Empty"
    },
    {
      "x": -3,
      "y": 2,
      "z": -1,
      "name": "Empty"
    },
    {
      "x": -3,
      "y": 3,
      "z": -1,
      "name": "Empty"
    },
    {
      "x": -3,
      "y": 0,
      "z": 0,
      "name": "Rock_Basalt_Cobble"
    },
    {
      "x": -3,
      "y": 1,
      "z": 0,
      "name": "Rock_Basalt"
    },
    {
      "x": -3,
      "y": 2,
      "z": 0,
      "name": "Empty"
    },
    {
      "x": -3,
      "y": 3,
      "z": 0,
      "name": "Empty"
    },
    {
      "x": -3,
      "y": 0,
      "z": 1,
      "name": "Rock_Basalt"
    },
    {
      "x": -3,
      "y": 1,
      "z": 1,
      "name": "Rock_Basalt"
    },
    {
      "x": -3,
      "y": 2,
      "z": 1,
      "name": "Rock_Basalt"
    },
    {
      "x": -3,
      "y": 3,
      "z": 1,
      "name": "Rock_Basalt"
    },
    {
      "x": -3,
      "y": 4,
      "z": 1,
      "name": "Rock_Stone"
    },
    {
      "x": -3,
      "y": 5,
      "z": 1,
      "name": "Rock_Stone"
    },
    {
      "x": -3,
      "y": 0,
      "z": 2,
      "name": "Rock_Basalt"
    },
    {
      "x": -3,
      "y": 1,
      "z": 2,
      "name": "Rock_Basalt"
    },
    {
      "x": -3,
      "y": 2,
      "z": 2,
      "name": "Rock_Basalt"
    },
    {
      "x": -3,
      "y": 3,
      "z": 2,
      "name": "Rock_Basalt"
    },
    {
      "x": -3,
      "y": 4,
      "z": 2,
      "name": "Rock_Stone"
    },
    {
      "x": -3,
      "y": 5,
      "z": 2,
      "name": "Rock_Stone"
    },
    {
      "x": -3,
      "y": 6,
      "z": 2,
      "name": "Rock_Stone"
    },
    {
      "x": -3,
      "y": 7,
      "z": 2,
      "name": "Rock_Stone_Stairs",
      "rotation": 2
    },
    {
      "x": -3,
      "y": 0,
      "z": 3,
      "name": "Rock_Basalt"
    },
    {
      "x": -3,
      "y": 1,
      "z": 3,
      "name": "Rock_Basalt"
    },
    {
      "x": -3,
      "y": 2,
      "z": 3,
      "name": "Rock_Basalt"
    },
    {
      "x": -3,
      "y": 3,
      "z": 3,
      "name": "Rock_Basalt"
    },
    {
      "x": -3,
      "y": 4,
      "z": 3,
      "name": "Rock_Stone"
    },
    {
      "x": -3,
      "y": 5,
      "z": 3,
      "name": "Rock_Stone"
    },
    {
      "x": -3,
      "y": 6,
      "z": 3,
      "name": "Rock_Stone"
    },
    {
      "x": -3,
      "y": 7,
      "z": 3,
      "name": "Rock_Stone"
    },
    {
      "x": -3,
      "y": 8,
      "z": 3,
      "name": "Rock_Stone_Stairs",
      "rotation": 2
    },
    {
      "x": -2,
      "y": 0,
      "z": -3,
      "name": "Rock_Basalt"
    },
    {
      "x": -2,
      "y": 1,
      "z": -3,
      "name": "Empty"
    },
    {
      "x": -2,
      "y": 2,
      "z": -3,
      "name": "Empty"
    },
    {
      "x": -2,
      "y": 3,
      "z": -3,
      "name": "Empty"
    },
    {
      "x": -2,
      "y": 0,
      "z": -2,
      "name": "Plant_Crop_Mushroom_Block_Green"
    },
    {
      "x": -2,
      "y": 1,
      "z": -2,
      "name": "Plant_Coral_Model_Grey"
    },
    {
      "x": -2,
      "y": 2,
      "z": -2,
      "name": "Empty"
    },
    {
      "x": -2,
      "y": 3,
      "z": -2,
      "name": "Empty",
      "rotation": 3
    },
    {
      "x": -2,
      "y": 0,
      "z": -1,
      "name": "Plant_Crop_Mushroom_Block_Green"
    },
    {
      "x": -2,
      "y": 1,
      "z": -1,
      "name": "Plant_Seaweed_Grass_Short"
    },
    {
      "x": -2,
      "y": 2,
      "z": -1,
      "name": "Empty"
    },
    {
      "x": -2,
      "y": 3,
      "z": -1,
      "name": "Empty",
      "rotation": 3
    },
    {
      "x": -2,
      "y": 0,
      "z": 0,
      "name": "Rock_Basalt"
    },
    {
      "x": -2,
      "y": 1,
      "z": 0,
      "name": "Rock_Basalt"
    },
    {
      "x": -2,
      "y": 2,
      "z": 0,
      "name": "Rock_Basalt"
    },
    {
      "x": -2,
      "y": 3,
      "z": 0,
      "name": "Empty",
      "rotation": 3
    },
    {
      "x": -2,
      "y": 0,
      "z": 1,
      "name": "Rock_Basalt"
    },
    {
      "x": -2,
      "y": 1,
      "z": 1,
      "name": "Rock_Basalt",
      "rotation": 3
    },
    {
      "x": -2,
      "y": 2,
      "z": 1,
      "name": "Rock_Basalt"
    },
    {
      "x": -2,
      "y": 3,
      "z": 1,
      "name": "Rock_Basalt"
    },
    {
      "x": -2,
      "y": 4,
      "z": 1,
      "name": "Rock_Stone"
    },
    {
      "x": -2,
      "y": 5,
      "z": 1,
      "name": "Rock_Stone"
    },
    {
      "x": -2,
      "y": 6,
      "z": 1,
      "name": "Rock_Stone"
    },
    {
      "x": -2,
      "y": 0,
      "z": 2,
      "name": "Rock_Basalt"
    },
    {
      "x": -2,
      "y": 1,
      "z": 2,
      "name": "Rock_Basalt",
      "rotation": 3
    },
    {
      "x": -2,
      "y": 2,
      "z": 2,
      "name": "Rock_Basalt",
      "rotation": 3
    },
    {
      "x": -2,
      "y": 3,
      "z": 2,
      "name": "Rock_Basalt",
      "rotation": 3
    },
    {
      "x": -2,
      "y": 4,
      "z": 2,
      "name": "Rock_Stone",
      "rotation": 3
    },
    {
      "x": -2,
      "y": 5,
      "z": 2,
      "name": "Rock_Stone",
      "rotation": 3
    },
    {
      "x": -2,
      "y": 6,
      "z": 2,
      "name": "Rock_Stone",
      "rotation": 3
    },
    {
      "x": -2,
      "y": 7,
      "z": 2,
      "name": "Rock_Stone",
      "rotation": 3
    },
    {
      "x": -2,
      "y": 0,
      "z": 3,
      "name": "Rock_Basalt"
    },
    {
      "x": -2,
      "y": 1,
      "z": 3,
      "name": "Rock_Basalt",
      "rotation": 3
    },
    {
      "x": -2,
      "y": 2,
      "z": 3,
      "name": "Rock_Basalt",
      "rotation": 3
    },
    {
      "x": -2,
      "y": 3,
      "z": 3,
      "name": "Rock_Basalt",
      "rotation": 3
    },
    {
      "x": -2,
      "y": 4,
      "z": 3,
      "name": "Rock_Stone",
      "rotation": 3
    },
    {
      "x": -2,
      "y": 5,
      "z": 3,
      "name": "Rock_Stone",
      "rotation": 3
    },
    {
      "x": -2,
      "y": 6,
      "z": 3,
      "name": "Rock_Stone",
      "rotation": 3
    },
    {
      "x": -2,
      "y": 7,
      "z": 3,
      "name": "Rock_Stone",
      "rotation": 3
    },
    {
      "x": -2,
      "y": 8,
      "z": 3,
      "name": "Rock_Stone",
      "rotation": 3
    },
    {
      "x": -1,
      "y": 0,
      "z": -3,
      "name": "Rock_Basalt"
    },
    {
      "x": -1,
      "y": 1,
      "z": -3,
      "name": "Empty"
    },
    {
      "x": -1,
      "y": 2,
      "z": -3,
      "name": "Empty"
    },
    {
      "x": -1,
      "y": 3,
      "z": -3,
      "name": "Empty"
    },
    {
      "x": -1,
      "y": 0,
      "z": -2,
      "name": "Plant_Crop_Mushroom_Block_Green"
    },
    {
      "x": -1,
      "y": 1,
      "z": -2,
      "name": "Empty"
    },
    {
      "x": -1,
      "y": 2,
      "z": -2,
      "name": "Empty"
    },
    {
      "x": -1,
      "y": 3,
      "z": -2,
      "name": "Empty",
      "rotation": 3
    },
    {
      "x": -1,
      "y": 0,
      "z": -1,
      "name": "Plant_Crop_Mushroom_Block_Green"
    },
    {
      "x": -1,
      "y": 1,
      "z": -1,
      "name": "Plant_Crop_Mushroom_Block_Green"
    },
    {
      "x": -1,
      "y": 2,
      "z": -1,
      "name": "Plant_Seaweed_Grass_Short"
    },
    {
      "x": -1,
      "y": 3,
      "z": -1,
      "name": "Empty",
      "rotation": 3
    },
    {
      "x": -1,
      "y": 0,
      "z": 0,
      "name": "Rock_Basalt"
    },
    {
      "x": -1,
      "y": 1,
      "z": 0,
      "name": "Ore_Iron_Basalt_Cracked"
    },
    {
      "x": -1,
      "y": 2,
      "z": 0,
      "name": "Rock_Basalt"
    },
    {
      "x": -1,
      "y": 3,
      "z": 0,
      "name": "Empty"
    },
    {
      "x": -1,
      "y": 0,
      "z": 1,
      "name": "Rock_Basalt"
    },
    {
      "x": -1,
      "y": 1,
      "z": 1,
      "name": "Rock_Basalt",
      "rotation": 3
    },
    {
      "x": -1,
      "y": 2,
      "z": 1,
      "name": "Rock_Basalt",
      "rotation": 3
    },
    {
      "x": -1,
      "y": 3,
      "z": 1,
      "name": "Rock_Basalt"
    },
    {
      "x": -1,
      "y": 4,
      "z": 1,
      "name": "Rock_Stone"
    },
    {
      "x": -1,
      "y": 5,
      "z": 1,
      "name": "Rock_Stone"
    },
    {
      "x": -1,
      "y": 6,
      "z": 1,
      "name": "Rubble_Stone",
      "support": 15
    },
    {
      "x": -1,
      "y": 0,
      "z": 2,
      "name": "Rock_Basalt"
    },
    {
      "x": -1,
      "y": 1,
      "z": 2,
      "name": "Rock_Basalt",
      "rotation": 3
    },
    {
      "x": -1,
      "y": 2,
      "z": 2,
      "name": "Rock_Basalt",
      "rotation": 3
    },
    {
      "x": -1,
      "y": 3,
      "z": 2,
      "name": "Rock_Basalt",
      "rotation": 3
    },
    {
      "x": -1,
      "y": 4,
      "z": 2,
      "name": "Rock_Stone",
      "rotation": 3
    },
    {
      "x": -1,
      "y": 5,
      "z": 2,
      "name": "Rock_Stone_Mossy",
      "rotation": 3
    },
    {
      "x": -1,
      "y": 6,
      "z": 2,
      "name": "Rock_Stone",
      "rotation": 3
    },
    {
      "x": -1,
      "y": 7,
      "z": 2,
      "name": "Rock_Stone_Stairs",
      "rotation": 2
    },
    {
      "x": -1,
      "y": 0,
      "z": 3,
      "name": "Rock_Basalt"
    },
    {
      "x": -1,
      "y": 1,
      "z": 3,
      "name": "Rock_Basalt",
      "rotation": 3
    },
    {
      "x": -1,
      "y": 2,
      "z": 3,
      "name": "Rock_Basalt",
      "rotation": 3
    },
    {
      "x": -1,
      "y": 3,
      "z": 3,
      "name": "Rock_Basalt",
      "rotation": 3
    },
    {
      "x": -1,
      "y": 4,
      "z": 3,
      "name": "Rock_Stone",
      "rotation": 3
    },
    {
      "x": -1,
      "y": 5,
      "z": 3,
      "name": "Rock_Stone",
      "rotation": 3
    },
    {
      "x": -1,
      "y": 6,
      "z": 3,
      "name": "Rock_Stone",
      "rotation": 3
    },
    {
      "x": -1,
      "y": 7,
      "z": 3,
      "name": "Rock_Stone",
      "rotation": 3
    },
    {
      "x": -1,
      "y": 8,
      "z": 3,
      "name": "Rock_Stone",
      "rotation": 3
    },
    {
      "x": 0,
      "y": 0,
      "z": -3,
      "name": "Rock_Basalt"
    },
    {
      "x": 0,
      "y": 1,
      "z": -3,
      "name": "Empty"
    },
    {
      "x": 0,
      "y": 2,
      "z": -3,
      "name": "Empty"
    },
    {
      "x": 0,
      "y": 3,
      "z": -3,
      "name": "Empty"
    },
    {
      "x": 0,
      "y": 0,
      "z": -2,
      "name": "Plant_Crop_Mushroom_Block_Green"
    },
    {
      "x": 0,
      "y": 1,
      "z": -2,
      "name": "Rock_Basalt"
    },
    {
      "x": 0,
      "y": 2,
      "z": -2,
      "name": "Empty"
    },
    {
      "x": 0,
      "y": 3,
      "z": -2,
      "name": "Empty"
    },
    {
      "x": 0,
      "y": 0,
      "z": -1,
      "name": "Ore_Iron_Basalt_Cracked"
    },
    {
      "x": 0,
      "y": 1,
      "z": -1,
      "name": "Ore_Iron_Basalt_Cracked"
    },
    {
      "x": 0,
      "y": 2,
      "z": -1,
      "name": "Rock_Basalt"
    },
    {
      "x": 0,
      "y": 3,
      "z": -1,
      "name": "Empty"
    },
    {
      "x": 0,
      "y": 0,
      "z": 0,
      "name": "Plant_Crop_Mushroom_Block_Green"
    },
    {
      "x": 0,
      "y": 1,
      "z": 0,
      "name": "Plant_Crop_Mushroom_Block_Green"
    },
    {
      "x": 0,
      "y": 2,
      "z": 0,
      "name": "Rock_Basalt"
    },
    {
      "x": 0,
      "y": 3,
      "z": 0,
      "name": "Rock_Basalt"
    },
    {
      "x": 0,
      "y": 4,
      "z": 0,
      "name": "Rock_Stone_Mossy"
    },
    {
      "x": 0,
      "y": 0,
      "z": 1,
      "name": "Rock_Basalt"
    },
    {
      "x": 0,
      "y": 1,
      "z": 1,
      "name": "Rock_Basalt",
      "rotation": 3
    },
    {
      "x": 0,
      "y": 2,
      "z": 1,
      "name": "Rock_Basalt",
      "rotation": 3
    },
    {
      "x": 0,
      "y": 3,
      "z": 1,
      "name": "Rock_Basalt",
      "rotation": 3
    },
    {
      "x": 0,
      "y": 4,
      "z": 1,
      "name": "Rock_Stone",
      "rotation": 3
    },
    {
      "x": 0,
      "y": 5,
      "z": 1,
      "name": "Rock_Stone_Mossy"
    },
    {
      "x": 0,
      "y": 6,
      "z": 1,
      "name": "Plant_Moss_Rug_Green",
      "support": 15
    },
    {
      "x": 0,
      "y": 0,
      "z": 2,
      "name": "Rock_Basalt"
    },
    {
      "x": 0,
      "y": 1,
      "z": 2,
      "name": "Rock_Basalt",
      "rotation": 3
    },
    {
      "x": 0,
      "y": 2,
      "z": 2,
      "name": "Rock_Basalt",
      "rotation": 3
    },
    {
      "x": 0,
      "y": 3,
      "z": 2,
      "name": "Rock_Basalt",
      "rotation": 3
    },
    {
      "x": 0,
      "y": 4,
      "z": 2,
      "name": "Rock_Stone",
      "rotation": 3
    },
    {
      "x": 0,
      "y": 5,
      "z": 2,
      "name": "Rock_Stone",
      "rotation": 3
    },
    {
      "x": 0,
      "y": 6,
      "z": 2,
      "name": "Rock_Stone",
      "rotation": 3
    },
    {
      "x": 0,
      "y": 7,
      "z": 2,
      "name": "Rock_Stone_Mossy",
      "rotation": 3
    },
    {
      "x": 0,
      "y": 0,
      "z": 3,
      "name": "Rock_Basalt"
    },
    {
      "x": 0,
      "y": 1,
      "z": 3,
      "name": "Rock_Basalt",
      "rotation": 3
    },
    {
      "x": 0,
      "y": 2,
      "z": 3,
      "name": "Rock_Basalt",
      "rotation": 3
    },
    {
      "x": 0,
      "y": 3,
      "z": 3,
      "name": "Rock_Basalt",
      "rotation": 3
    },
    {
      "x": 0,
      "y": 4,
      "z": 3,
      "name": "Rock_Stone",
      "rotation": 3
    },
    {
      "x": 0,
      "y": 5,
      "z": 3,
      "name": "Rock_Stone",
      "rotation": 3
    },
    {
      "x": 0,
      "y": 6,
      "z": 3,
      "name": "Rock_Stone",
      "rotation": 3
    },
    {
      "x": 0,
      "y": 7,
      "z": 3,
      "name": "Rock_Stone",
      "rotation": 3
    },
    {
      "x": 0,
      "y": 8,
      "z": 3,
      "name": "Rock_Stone_Half",
      "rotation": 3
    },
    {
      "x": 1,
      "y": 0,
      "z": -3,
      "name": "Rock_Basalt_Cobble"
    },
    {
      "x": 1,
      "y": 1,
      "z": -3,
      "name": "Rock_Basalt"
    },
    {
      "x": 1,
      "y": 2,
      "z": -3,
      "name": "Rock_Basalt"
    },
    {
      "x": 1,
      "y": 3,
      "z": -3,
      "name": "Rock_Basalt"
    },
    {
      "x": 1,
      "y": 4,
      "z": -3,
      "name": "Rock_Stone"
    },
    {
      "x": 1,
      "y": 5,
      "z": -3,
      "name": "Rock_Stone"
    },
    {
      "x": 1,
      "y": 6,
      "z": -3,
      "name": "Rubble_Stone",
      "support": 15
    },
    {
      "x": 1,
      "y": 0,
      "z": -2,
      "name": "Rock_Basalt_Cobble"
    },
    {
      "x": 1,
      "y": 1,
      "z": -2,
      "name": "Ore_Iron_Basalt_Cracked"
    },
    {
      "x": 1,
      "y": 2,
      "z": -2,
      "name": "Rock_Basalt"
    },
    {
      "x": 1,
      "y": 3,
      "z": -2,
      "name": "Empty"
    },
    {
      "x": 1,
      "y": 0,
      "z": -1,
      "name": "Rock_Basalt"
    },
    {
      "x": 1,
      "y": 1,
      "z": -1,
      "name": "Rock_Basalt"
    },
    {
      "x": 1,
      "y": 2,
      "z": -1,
      "name": "Rock_Basalt"
    },
    {
      "x": 1,
      "y": 3,
      "z": -1,
      "name": "Rock_Basalt"
    },
    {
      "x": 1,
      "y": 4,
      "z": -1,
      "name": "Rock_Stone_Mossy"
    },
    {
      "x": 1,
      "y": 5,
      "z": -1,
      "name": "Plant_Moss_Rug_Green",
      "support": 15
    },
    {
      "x": 1,
      "y": 0,
      "z": 0,
      "name": "Rock_Basalt"
    },
    {
      "x": 1,
      "y": 1,
      "z": 0,
      "name": "Ore_Iron_Basalt_Cracked"
    },
    {
      "x": 1,
      "y": 2,
      "z": 0,
      "name": "Rock_Basalt"
    },
    {
      "x": 1,
      "y": 3,
      "z": 0,
      "name": "Rock_Basalt"
    },
    {
      "x": 1,
      "y": 4,
      "z": 0,
      "name": "Rock_Stone"
    },
    {
      "x": 1,
      "y": 5,
      "z": 0,
      "name": "Rock_Stone"
    },
    {
      "x": 1,
      "y": 0,
      "z": 1,
      "name": "Rock_Basalt"
    },
    {
      "x": 1,
      "y": 1,
      "z": 1,
      "name": "Rock_Basalt",
      "rotation": 3
    },
    {
      "x": 1,
      "y": 2,
      "z": 1,
      "name": "Rock_Basalt",
      "rotation": 3
    },
    {
      "x": 1,
      "y": 3,
      "z": 1,
      "name": "Rock_Basalt",
      "rotation": 3
    },
    {
      "x": 1,
      "y": 4,
      "z": 1,
      "name": "Rock_Stone",
      "rotation": 3
    },
    {
      "x": 1,
      "y": 5,
      "z": 1,
      "name": "Rock_Stone_Mossy",
      "rotation": 3
    },
    {
      "x": 1,
      "y": 6,
      "z": 1,
      "name": "Rock_Stone"
    },
    {
      "x": 1,
      "y": 0,
      "z": 2,
      "name": "Rock_Basalt"
    },
    {
      "x": 1,
      "y": 1,
      "z": 2,
      "name": "Rock_Basalt",
      "rotation": 3
    },
    {
      "x": 1,
      "y": 2,
      "z": 2,
      "name": "Rock_Basalt",
      "rotation": 3
    },
    {
      "x": 1,
      "y": 3,
      "z": 2,
      "name": "Rock_Basalt",
      "rotation": 3
    },
    {
      "x": 1,
      "y": 4,
      "z": 2,
      "name": "Rock_Stone",
      "rotation": 3
    },
    {
      "x": 1,
      "y": 5,
      "z": 2,
      "name": "Rock_Stone",
      "rotation": 3
    },
    {
      "x": 1,
      "y": 6,
      "z": 2,
      "name": "Rock_Stone",
      "rotation": 3
    },
    {
      "x": 1,
      "y": 7,
      "z": 2,
      "name": "Rock_Stone_Mossy",
      "rotation": 3
    },
    {
      "x": 1,
      "y": 0,
      "z": 3,
      "name": "Rock_Basalt"
    },
    {
      "x": 1,
      "y": 1,
      "z": 3,
      "name": "Rock_Basalt",
      "rotation": 3
    },
    {
      "x": 1,
      "y": 2,
      "z": 3,
      "name": "Rock_Basalt",
      "rotation": 3
    },
    {
      "x": 1,
      "y": 3,
      "z": 3,
      "name": "Rock_Basalt",
      "rotation": 3
    },
    {
      "x": 1,
      "y": 4,
      "z": 3,
      "name": "Rock_Stone",
      "rotation": 3
    },
    {
      "x": 1,
      "y": 5,
      "z": 3,
      "name": "Rock_Stone",
      "rotation": 3
    },
    {
      "x": 1,
      "y": 6,
      "z": 3,
      "name": "Rock_Stone",
      "rotation": 3
    },
    {
      "x": 1,
      "y": 7,
      "z": 3,
      "name": "Rock_Stone",
      "rotation": 3
    },
    {
      "x": 1,
      "y": 8,
      "z": 3,
      "name": "Rock_Stone_Half",
      "rotation": 3
    },
    {
      "x": 2,
      "y": 0,
      "z": -3,
      "name": "Rock_Basalt"
    },
    {
      "x": 2,
      "y": 1,
      "z": -3,
      "name": "Rock_Basalt"
    },
    {
      "x": 2,
      "y": 2,
      "z": -3,
      "name": "Rock_Basalt"
    },
    {
      "x": 2,
      "y": 3,
      "z": -3,
      "name": "Rock_Basalt"
    },
    {
      "x": 2,
      "y": 4,
      "z": -3,
      "name": "Rock_Stone"
    },
    {
      "x": 2,
      "y": 5,
      "z": -3,
      "name": "Rock_Stone"
    },
    {
      "x": 2,
      "y": 6,
      "z": -3,
      "name": "Rock_Stone"
    },
    {
      "x": 2,
      "y": 7,
      "z": -3,
      "name": "Rock_Stone_Stairs",
      "rotation": 3
    },
    {
      "x": 2,
      "y": 0,
      "z": -2,
      "name": "Plant_Crop_Mushroom_Block_Green"
    },
    {
      "x": 2,
      "y": 1,
      "z": -2,
      "name": "Rock_Basalt"
    },
    {
      "x": 2,
      "y": 2,
      "z": -2,
      "name": "Rock_Basalt"
    },
    {
      "x": 2,
      "y": 3,
      "z": -2,
      "name": "Rock_Basalt"
    },
    {
      "x": 2,
      "y": 4,
      "z": -2,
      "name": "Rock_Stone"
    },
    {
      "x": 2,
      "y": 5,
      "z": -2,
      "name": "Rock_Stone_Mossy"
    },
    {
      "x": 2,
      "y": 6,
      "z": -2,
      "name": "Rock_Stone_Mossy"
    },
    {
      "x": 2,
      "y": 7,
      "z": -2,
      "name": "Rock_Stone"
    },
    {
      "x": 2,
      "y": 0,
      "z": -1,
      "name": "Rock_Basalt"
    },
    {
      "x": 2,
      "y": 1,
      "z": -1,
      "name": "Rock_Basalt"
    },
    {
      "x": 2,
      "y": 2,
      "z": -1,
      "name": "Rock_Basalt"
    },
    {
      "x": 2,
      "y": 3,
      "z": -1,
      "name": "Rock_Basalt"
    },
    {
      "x": 2,
      "y": 4,
      "z": -1,
      "name": "Rock_Stone"
    },
    {
      "x": 2,
      "y": 5,
      "z": -1,
      "name": "Rock_Stone"
    },
    {
      "x": 2,
      "y": 6,
      "z": -1,
      "name": "Rock_Stone"
    },
    {
      "x": 2,
      "y": 7,
      "z": -1,
      "name": "Rock_Stone_Mossy"
    },
    {
      "x": 2,
      "y": 8,
      "z": -1,
      "name": "Plant_Moss_Rug_Green",
      "support": 15
    },
    {
      "x": 2,
      "y": 0,
      "z": 0,
      "name": "Rock_Basalt"
    },
    {
      "x": 2,
      "y": 1,
      "z": 0,
      "name": "Rock_Basalt",
      "rotation": 3
    },
    {
      "x": 2,
      "y": 2,
      "z": 0,
      "name": "Rock_Basalt"
    },
    {
      "x": 2,
      "y": 3,
      "z": 0,
      "name": "Rock_Basalt"
    },
    {
      "x": 2,
      "y": 4,
      "z": 0,
      "name": "Rock_Stone"
    },
    {
      "x": 2,
      "y": 5,
      "z": 0,
      "name": "Rock_Stone"
    },
    {
      "x": 2,
      "y": 6,
      "z": 0,
      "name": "Rock_Stone_Mossy"
    },
    {
      "x": 2,
      "y": 7,
      "z": 0,
      "name": "Rock_Stone_Stairs",
      "rotation": 3
    },
    {
      "x": 2,
      "y": 0,
      "z": 1,
      "name": "Rock_Basalt"
    },
    {
      "x": 2,
      "y": 1,
      "z": 1,
      "name": "Rock_Basalt",
      "rotation": 3
    },
    {
      "x": 2,
      "y": 2,
      "z": 1,
      "name": "Rock_Basalt",
      "rotation": 3
    },
    {
      "x": 2,
      "y": 3,
      "z": 1,
      "name": "Rock_Basalt"
    },
    {
      "x": 2,
      "y": 4,
      "z": 1,
      "name": "Rock_Stone"
    },
    {
      "x": 2,
      "y": 5,
      "z": 1,
      "name": "Rock_Stone_Mossy"
    },
    {
      "x": 2,
      "y": 6,
      "z": 1,
      "name": "Rock_Stone_Mossy"
    },
    {
      "x": 2,
      "y": 7,
      "z": 1,
      "name": "Rock_Stone"
    },
    {
      "x": 2,
      "y": 0,
      "z": 2,
      "name": "Rock_Basalt"
    },
    {
      "x": 2,
      "y": 1,
      "z": 2,
      "name": "Rock_Basalt",
      "rotation": 3
    },
    {
      "x": 2,
      "y": 2,
      "z": 2,
      "name": "Rock_Basalt",
      "rotation": 3
    },
    {
      "x": 2,
      "y": 3,
      "z": 2,
      "name": "Rock_Basalt",
      "rotation": 3
    },
    {
      "x": 2,
      "y": 4,
      "z": 2,
      "name": "Rock_Stone",
      "rotation": 3
    },
    {
      "x": 2,
      "y": 5,
      "z": 2,
      "name": "Rock_Stone_Mossy",
      "rotation": 3
    },
    {
      "x": 2,
      "y": 6,
      "z": 2,
      "name": "Rock_Stone_Mossy",
      "rotation": 3
    },
    {
      "x": 2,
      "y": 7,
      "z": 2,
      "name": "Rock_Stone",
      "rotation": 3
    },
    {
      "x": 2,
      "y": 0,
      "z": 3,
      "name": "Rock_Basalt"
    },
    {
      "x": 2,
      "y": 1,
      "z": 3,
      "name": "Rock_Basalt",
      "rotation": 3
    },
    {
      "x": 2,
      "y": 2,
      "z": 3,
      "name": "Rock_Basalt",
      "rotation": 3
    },
    {
      "x": 2,
      "y": 3,
      "z": 3,
      "name": "Rock_Basalt",
      "rotation": 3
    },
    {
      "x": 2,
      "y": 4,
      "z": 3,
      "name": "Rock_Stone",
      "rotation": 3
    },
    {
      "x": 2,
      "y": 5,
      "z": 3,
      "name": "Rock_Stone",
      "rotation": 3
    },
    {
      "x": 2,
      "y": 6,
      "z": 3,
      "name": "Rock_Stone",
      "rotation": 3
    },
    {
      "x": 2,
      "y": 7,
      "z": 3,
      "name": "Rock_Stone",
      "rotation": 3
    },
    {
      "x": 2,
      "y": 8,
      "z": 3,
      "name": "Rock_Stone_Stairs",
      "rotation": 3
    },
    {
      "x": 3,
      "y": 0,
      "z": -3,
      "name": "Rock_Basalt"
    },
    {
      "x": 3,
      "y": 1,
      "z": -3,
      "name": "Rock_Basalt"
    },
    {
      "x": 3,
      "y": 2,
      "z": -3,
      "name": "Rock_Basalt"
    },
    {
      "x": 3,
      "y": 3,
      "z": -3,
      "name": "Rock_Basalt"
    },
    {
      "x": 3,
      "y": 4,
      "z": -3,
      "name": "Rock_Stone"
    },
    {
      "x": 3,
      "y": 5,
      "z": -3,
      "name": "Rock_Stone"
    },
    {
      "x": 3,
      "y": 6,
      "z": -3,
      "name": "Rock_Stone"
    },
    {
      "x": 3,
      "y": 7,
      "z": -3,
      "name": "Rock_Stone"
    },
    {
      "x": 3,
      "y": 8,
      "z": -3,
      "name": "Rock_Stone"
    },
    {
      "x": 3,
      "y": 0,
      "z": -2,
      "name": "Rock_Basalt"
    },
    {
      "x": 3,
      "y": 1,
      "z": -2,
      "name": "Rock_Basalt"
    },
    {
      "x": 3,
      "y": 2,
      "z": -2,
      "name": "Rock_Basalt"
    },
    {
      "x": 3,
      "y": 3,
      "z": -2,
      "name": "Rock_Basalt"
    },
    {
      "x": 3,
      "y": 4,
      "z": -2,
      "name": "Rock_Stone"
    },
    {
      "x": 3,
      "y": 5,
      "z": -2,
      "name": "Rock_Stone"
    },
    {
      "x": 3,
      "y": 6,
      "z": -2,
      "name": "Rock_Stone"
    },
    {
      "x": 3,
      "y": 7,
      "z": -2,
      "name": "Rock_Stone"
    },
    {
      "x": 3,
      "y": 8,
      "z": -2,
      "name": "Rock_Stone"
    },
    {
      "x": 3,
      "y": 0,
      "z": -1,
      "name": "Rock_Basalt"
    },
    {
      "x": 3,
      "y": 1,
      "z": -1,
      "name": "Rock_Basalt"
    },
    {
      "x": 3,
      "y": 2,
      "z": -1,
      "name": "Rock_Basalt"
    },
    {
      "x": 3,
      "y": 3,
      "z": -1,
      "name": "Rock_Basalt"
    },
    {
      "x": 3,
      "y": 4,
      "z": -1,
      "name": "Rock_Stone"
    },
    {
      "x": 3,
      "y": 5,
      "z": -1,
      "name": "Rock_Stone"
    },
    {
      "x": 3,
      "y": 6,
      "z": -1,
      "name": "Rock_Stone"
    },
    {
      "x": 3,
      "y": 7,
      "z": -1,
      "name": "Rock_Stone"
    },
    {
      "x": 3,
      "y": 8,
      "z": -1,
      "name": "Rock_Stone_Stairs",
      "rotation": 3
    },
    {
      "x": 3,
      "y": 0,
      "z": 0,
      "name": "Rock_Basalt"
    },
    {
      "x": 3,
      "y": 1,
      "z": 0,
      "name": "Rock_Basalt",
      "rotation": 3
    },
    {
      "x": 3,
      "y": 2,
      "z": 0,
      "name": "Rock_Basalt",
      "rotation": 3
    },
    {
      "x": 3,
      "y": 3,
      "z": 0,
      "name": "Rock_Basalt",
      "rotation": 3
    },
    {
      "x": 3,
      "y": 4,
      "z": 0,
      "name": "Rock_Stone",
      "rotation": 3
    },
    {
      "x": 3,
      "y": 5,
      "z": 0,
      "name": "Rock_Stone",
      "rotation": 3
    },
    {
      "x": 3,
      "y": 6,
      "z": 0,
      "name": "Rock_Stone"
    },
    {
      "x": 3,
      "y": 7,
      "z": 0,
      "name": "Rock_Stone"
    },
    {
      "x": 3,
      "y": 8,
      "z": 0,
      "name": "Rock_Stone"
    },
    {
      "x": 3,
      "y": 9,
      "z": 0,
      "name": "Rubble_Stone",
      "support": 15
    },
    {
      "x": 3,
      "y": 0,
      "z": 1,
      "name": "Rock_Basalt"
    },
    {
      "x": 3,
      "y": 1,
      "z": 1,
      "name": "Rock_Basalt",
      "rotation": 3
    },
    {
      "x": 3,
      "y": 2,
      "z": 1,
      "name": "Rock_Basalt",
      "rotation": 3
    },
    {
      "x": 3,
      "y": 3,
      "z": 1,
      "name": "Rock_Basalt",
      "rotation": 3
    },
    {
      "x": 3,
      "y": 4,
      "z": 1,
      "name": "Rock_Stone",
      "rotation": 3
    },
    {
      "x": 3,
      "y": 5,
      "z": 1,
      "name": "Rock_Stone",
      "rotation": 3
    },
    {
      "x": 3,
      "y": 6,
      "z": 1,
      "name": "Rock_Stone"
    },
    {
      "x": 3,
      "y": 7,
      "z": 1,
      "name": "Rock_Stone"
    },
    {
      "x": 3,
      "y": 8,
      "z": 1,
      "name": "Rock_Stone_Stairs"
    },
    {
      "x": 3,
      "y": 0,
      "z": 2,
      "name": "Rock_Basalt"
    },
    {
      "x": 3,
      "y": 1,
      "z": 2,
      "name": "Rock_Basalt",
      "rotation": 3
    },
    {
      "x": 3,
      "y": 2,
      "z": 2,
      "name": "Rock_Basalt",
      "rotation": 3
    },
    {
      "x": 3,
      "y": 3,
      "z": 2,
      "name": "Rock_Basalt",
      "rotation": 3
    },
    {
      "x": 3,
      "y": 4,
      "z": 2,
      "name": "Rock_Stone",
      "rotation": 3
    },
    {
      "x": 3,
      "y": 5,
      "z": 2,
      "name": "Rock_Stone",
      "rotation": 3
    },
    {
      "x": 3,
      "y": 6,
      "z": 2,
      "name": "Rock_Stone_Mossy",
      "rotation": 3
    },
    {
      "x": 3,
      "y": 7,
      "z": 2,
      "name": "Rock_Stone_Stairs",
      "rotation": 2
    },
    {
      "x": 3,
      "y": 8,
      "z": 2,
      "name": "Rock_Stone_Half"
    },
    {
      "x": 3,
      "y": 0,
      "z": 3,
      "name": "Rock_Basalt"
    },
    {
      "x": 3,
      "y": 1,
      "z": 3,
      "name": "Rock_Basalt",
      "rotation": 3
    },
    {
      "x": 3,
      "y": 2,
      "z": 3,
      "name": "Rock_Basalt",
      "rotation": 3
    },
    {
      "x": 3,
      "y": 3,
      "z": 3,
      "name": "Rock_Basalt",
      "rotation": 3
    },
    {
      "x": 3,
      "y": 4,
      "z": 3,
      "name": "Rock_Stone",
      "rotation": 3
    },
    {
      "x": 3,
      "y": 5,
      "z": 3,
      "name": "Rock_Stone",
      "rotation": 3
    },
    {
      "x": 3,
      "y": 6,
      "z": 3,
      "name": "Rock_Stone",
      "rotation": 3
    },
    {
      "x": 3,
      "y": 7,
      "z": 3,
      "name": "Rock_Stone",
      "rotation": 3
    },
    {
      "x": 3,
      "y": 8,
      "z": 3,
      "name": "Rock_Stone",
      "rotation": 3
    }
  ],
  "fluids": [
    {
      "x": -3,
      "y": 0,
      "z": -3,
      "name": "Water_Source",
      "level": 1
    },
    {
      "x": -3,
      "y": 1,
      "z": -3,
      "name": "Water_Source",
      "level": 1
    },
    {
      "x": -3,
      "y": 2,
      "z": -3,
      "name": "Water_Source",
      "level": 1
    },
    {
      "x": -3,
      "y": 3,
      "z": -3,
      "name": "Water_Source",
      "level": 1
    },
    {
      "x": -3,
      "y": 0,
      "z": -2,
      "name": "Water_Source",
      "level": 1
    },
    {
      "x": -3,
      "y": 1,
      "z": -2,
      "name": "Water_Source",
      "level": 1
    },
    {
      "x": -3,
      "y": 2,
      "z": -2,
      "name": "Water_Source",
      "level": 1
    },
    {
      "x": -3,
      "y": 3,
      "z": -2,
      "name": "Water_Source",
      "level": 1
    },
    {
      "x": -3,
      "y": 0,
      "z": -1,
      "name": "Water_Source",
      "level": 1
    },
    {
      "x": -3,
      "y": 1,
      "z": -1,
      "name": "Water_Source",
      "level": 1
    },
    {
      "x": -3,
      "y": 2,
      "z": -1,
      "name": "Water_Source",
      "level": 1
    },
    {
      "x": -3,
      "y": 3,
      "z": -1,
      "name": "Water_Source",
      "level": 1
    },
    {
      "x": -3,
      "y": 0,
      "z": 0,
      "name": "Water_Source",
      "level": 1
    },
    {
      "x": -3,
      "y": 1,
      "z": 0,
      "name": "Water_Source",
      "level": 1
    },
    {
      "x": -3,
      "y": 2,
      "z": 0,
      "name": "Water_Source",
      "level": 1
    },
    {
      "x": -3,
      "y": 3,
      "z": 0,
      "name": "Water_Source",
      "level": 1
    },
    {
      "x": -3,
      "y": 0,
      "z": 1,
      "name": "Water_Source",
      "level": 1
    },
    {
      "x": -3,
      "y": 1,
      "z": 1,
      "name": "Water_Source",
      "level": 1
    },
    {
      "x": -3,
      "y": 2,
      "z": 1,
      "name": "Water_Source",
      "level": 1
    },
    {
      "x": -3,
      "y": 3,
      "z": 1,
      "name": "Water_Source",
      "level": 1
    },
    {
      "x": -3,
      "y": 4,
      "z": 1,
      "name": "Empty",
      "level": 0
    },
    {
      "x": -3,
      "y": 5,
      "z": 1,
      "name": "Empty",
      "level": 0
    },
    {
      "x": -3,
      "y": 0,
      "z": 2,
      "name": "Water_Source",
      "level": 1
    },
    {
      "x": -3,
      "y": 1,
      "z": 2,
      "name": "Water_Source",
      "level": 1
    },
    {
      "x": -3,
      "y": 2,
      "z": 2,
      "name": "Water_Source",
      "level": 1
    },
    {
      "x": -3,
      "y": 3,
      "z": 2,
      "name": "Water_Source",
      "level": 1
    },
    {
      "x": -3,
      "y": 4,
      "z": 2,
      "name": "Empty",
      "level": 0
    },
    {
      "x": -3,
      "y": 5,
      "z": 2,
      "name": "Empty",
      "level": 0
    },
    {
      "x": -3,
      "y": 6,
      "z": 2,
      "name": "Empty",
      "level": 0
    },
    {
      "x": -3,
      "y": 7,
      "z": 2,
      "name": "Empty",
      "level": 0
    },
    {
      "x": -3,
      "y": 0,
      "z": 3,
      "name": "Water_Source",
      "level": 1
    },
    {
      "x": -3,
      "y": 1,
      "z": 3,
      "name": "Water_Source",
      "level": 1
    },
    {
      "x": -3,
      "y": 2,
      "z": 3,
      "name": "Water_Source",
      "level": 1
    },
    {
      "x": -3,
      "y": 3,
      "z": 3,
      "name": "Water_Source",
      "level": 1
    },
    {
      "x": -3,
      "y": 4,
      "z": 3,
      "name": "Empty",
      "level": 0
    },
    {
      "x": -3,
      "y": 5,
      "z": 3,
      "name": "Empty",
      "level": 0
    },
    {
      "x": -3,
      "y": 6,
      "z": 3,
      "name": "Empty",
      "level": 0
    },
    {
      "x": -3,
      "y": 7,
      "z": 3,
      "name": "Empty",
      "level": 0
    },
    {
      "x": -3,
      "y": 8,
      "z": 3,
      "name": "Empty",
      "level": 0
    },
    {
      "x": -2,
      "y": 0,
      "z": -3,
      "name": "Water_Source",
      "level": 1
    },
    {
      "x": -2,
      "y": 1,
      "z": -3,
      "name": "Water_Source",
      "level": 1
    },
    {
      "x": -2,
      "y": 2,
      "z": -3,
      "name": "Water_Source",
      "level": 1
    },
    {
      "x": -2,
      "y": 3,
      "z": -3,
      "name": "Water_Source",
      "level": 1
    },
    {
      "x": -2,
      "y": 0,
      "z": -2,
      "name": "Water_Source",
      "level": 1
    },
    {
      "x": -2,
      "y": 1,
      "z": -2,
      "name": "Water_Source",
      "level": 1
    },
    {
      "x": -2,
      "y": 2,
      "z": -2,
      "name": "Water_Source",
      "level": 1
    },
    {
      "x": -2,
      "y": 3,
      "z": -2,
      "name": "Water_Source",
      "level": 1
    },
    {
      "x": -2,
      "y": 0,
      "z": -1,
      "name": "Water_Source",
      "level": 1
    },
    {
      "x": -2,
      "y": 1,
      "z": -1,
      "name": "Water_Source",
      "level": 1
    },
    {
      "x": -2,
      "y": 2,
      "z": -1,
      "name": "Water_Source",
      "level": 1
    },
    {
      "x": -2,
      "y": 3,
      "z": -1,
      "name": "Water_Source",
      "level": 1
    },
    {
      "x": -2,
      "y": 0,
      "z": 0,
      "name": "Water_Source",
      "level": 1
    },
    {
      "x": -2,
      "y": 1,
      "z": 0,
      "name": "Water_Source",
      "level": 1
    },
    {
      "x": -2,
      "y": 2,
      "z": 0,
      "name": "Water_Source",
      "level": 1
    },
    {
      "x": -2,
      "y": 3,
      "z": 0,
      "name": "Water_Source",
      "level": 1
    },
    {
      "x": -2,
      "y": 0,
      "z": 1,
      "name": "Water_Source",
      "level": 1
    },
    {
      "x": -2,
      "y": 1,
      "z": 1,
      "name": "Water_Source",
      "level": 1
    },
    {
      "x": -2,
      "y": 2,
      "z": 1,
      "name": "Water_Source",
      "level": 1
    },
    {
      "x": -2,
      "y": 3,
      "z": 1,
      "name": "Water_Source",
      "level": 1
    },
    {
      "x": -2,
      "y": 4,
      "z": 1,
      "name": "Empty",
      "level": 0
    },
    {
      "x": -2,
      "y": 5,
      "z": 1,
      "name": "Empty",
      "level": 0
    },
    {
      "x": -2,
      "y": 6,
      "z": 1,
      "name": "Empty",
      "level": 0
    },
    {
      "x": -2,
      "y": 0,
      "z": 2,
      "name": "Water_Source",
      "level": 1
    },
    {
      "x": -2,
      "y": 1,
      "z": 2,
      "name": "Water_Source",
      "level": 1
    },
    {
      "x": -2,
      "y": 2,
      "z": 2,
      "name": "Water_Source",
      "level": 1
    },
    {
      "x": -2,
      "y": 3,
      "z": 2,
      "name": "Water_Source",
      "level": 1
    },
    {
      "x": -2,
      "y": 4,
      "z": 2,
      "name": "Empty",
      "level": 0
    },
    {
      "x": -2,
      "y": 5,
      "z": 2,
      "name": "Empty",
      "level": 0
    },
    {
      "x": -2,
      "y": 6,
      "z": 2,
      "name": "Empty",
      "level": 0
    },
    {
      "x": -2,
      "y": 7,
      "z": 2,
      "name": "Empty",
      "level": 0
    },
    {
      "x": -2,
      "y": 0,
      "z": 3,
      "name": "Water_Source",
      "level": 1
    },
    {
      "x": -2,
      "y": 1,
      "z": 3,
      "name": "Water_Source",
      "level": 1
    },
    {
      "x": -2,
      "y": 2,
      "z": 3,
      "name": "Water_Source",
      "level": 1
    },
    {
      "x": -2,
      "y": 3,
      "z": 3,
      "name": "Water_Source",
      "level": 1
    },
    {
      "x": -2,
      "y": 4,
      "z": 3,
      "name": "Empty",
      "level": 0
    },
    {
      "x": -2,
      "y": 5,
      "z": 3,
      "name": "Empty",
      "level": 0
    },
    {
      "x": -2,
      "y": 6,
      "z": 3,
      "name": "Empty",
      "level": 0
    },
    {
      "x": -2,
      "y": 7,
      "z": 3,
      "name": "Empty",
      "level": 0
    },
    {
      "x": -2,
      "y": 8,
      "z": 3,
      "name": "Empty",
      "level": 0
    },
    {
      "x": -1,
      "y": 0,
      "z": -3,
      "name": "Water_Source",
      "level": 1
    },
    {
      "x": -1,
      "y": 1,
      "z": -3,
      "name": "Water_Source",
      "level": 1
    },
    {
      "x": -1,
      "y": 2,
      "z": -3,
      "name": "Water_Source",
      "level": 1
    },
    {
      "x": -1,
      "y": 3,
      "z": -3,
      "name": "Water_Source",
      "level": 1
    },
    {
      "x": -1,
      "y": 0,
      "z": -2,
      "name": "Water_Source",
      "level": 1
    },
    {
      "x": -1,
      "y": 1,
      "z": -2,
      "name": "Water_Source",
      "level": 1
    },
    {
      "x": -1,
      "y": 2,
      "z": -2,
      "name": "Water_Source",
      "level": 1
    },
    {
      "x": -1,
      "y": 3,
      "z": -2,
      "name": "Water_Source",
      "level": 1
    },
    {
      "x": -1,
      "y": 0,
      "z": -1,
      "name": "Water_Source",
      "level": 1
    },
    {
      "x": -1,
      "y": 1,
      "z": -1,
      "name": "Water_Source",
      "level": 1
    },
    {
      "x": -1,
      "y": 2,
      "z": -1,
      "name": "Water_Source",
      "level": 1
    },
    {
      "x": -1,
      "y": 3,
      "z": -1,
      "name": "Water_Source",
      "level": 1
    },
    {
      "x": -1,
      "y": 0,
      "z": 0,
      "name": "Water_Source",
      "level": 1
    },
    {
      "x": -1,
      "y": 1,
      "z": 0,
      "name": "Water_Source",
      "level": 1
    },
    {
      "x": -1,
      "y": 2,
      "z": 0,
      "name": "Water_Source",
      "level": 1
    },
    {
      "x": -1,
      "y": 3,
      "z": 0,
      "name": "Water_Source",
      "level": 1
    },
    {
      "x": -1,
      "y": 0,
      "z": 1,
      "name": "Water_Source",
      "level": 1
    },
    {
      "x": -1,
      "y": 1,
      "z": 1,
      "name": "Water_Source",
      "level": 1
    },
    {
      "x": -1,
      "y": 2,
      "z": 1,
      "name": "Water_Source",
      "level": 1
    },
    {
      "x": -1,
      "y": 3,
      "z": 1,
      "name": "Water_Source",
      "level": 1
    },
    {
      "x": -1,
      "y": 4,
      "z": 1,
      "name": "Empty",
      "level": 0
    },
    {
      "x": -1,
      "y": 5,
      "z": 1,
      "name": "Empty",
      "level": 0
    },
    {
      "x": -1,
      "y": 6,
      "z": 1,
      "name": "Empty",
      "level": 0
    },
    {
      "x": -1,
      "y": 0,
      "z": 2,
      "name": "Water_Source",
      "level": 1
    },
    {
      "x": -1,
      "y": 1,
      "z": 2,
      "name": "Water_Source",
      "level": 1
    },
    {
      "x": -1,
      "y": 2,
      "z": 2,
      "name": "Water_Source",
      "level": 1
    },
    {
      "x": -1,
      "y": 3,
      "z": 2,
      "name": "Water_Source",
      "level": 1
    },
    {
      "x": -1,
      "y": 4,
      "z": 2,
      "name": "Empty",
      "level": 0
    },
    {
      "x": -1,
      "y": 5,
      "z": 2,
      "name": "Empty",
      "level": 0
    },
    {
      "x": -1,
      "y": 6,
      "z": 2,
      "name": "Empty",
      "level": 0
    },
    {
      "x": -1,
      "y": 7,
      "z": 2,
      "name": "Empty",
      "level": 0
    },
    {
      "x": -1,
      "y": 0,
      "z": 3,
      "name": "Water_Source",
      "level": 1
    },
    {
      "x": -1,
      "y": 1,
      "z": 3,
      "name": "Water_Source",
      "level": 1
    },
    {
      "x": -1,
      "y": 2,
      "z": 3,
      "name": "Water_Source",
      "level": 1
    },
    {
      "x": -1,
      "y": 3,
      "z": 3,
      "name": "Water_Source",
      "level": 1
    },
    {
      "x": -1,
      "y": 4,
      "z": 3,
      "name": "Empty",
      "level": 0
    },
    {
      "x": -1,
      "y": 5,
      "z": 3,
      "name": "Empty",
      "level": 0
    },
    {
      "x": -1,
      "y": 6,
      "z": 3,
      "name": "Empty",
      "level": 0
    },
    {
      "x": -1,
      "y": 7,
      "z": 3,
      "name": "Empty",
      "level": 0
    },
    {
      "x": -1,
      "y": 8,
      "z": 3,
      "name": "Empty",
      "level": 0
    },
    {
      "x": 0,
      "y": 0,
      "z": -3,
      "name": "Water_Source",
      "level": 1
    },
    {
      "x": 0,
      "y": 1,
      "z": -3,
      "name": "Water_Source",
      "level": 1
    },
    {
      "x": 0,
      "y": 2,
      "z": -3,
      "name": "Water_Source",
      "level": 1
    },
    {
      "x": 0,
      "y": 3,
      "z": -3,
      "name": "Water_Source",
      "level": 1
    },
    {
      "x": 0,
      "y": 0,
      "z": -2,
      "name": "Water_Source",
      "level": 1
    },
    {
      "x": 0,
      "y": 1,
      "z": -2,
      "name": "Water_Source",
      "level": 1
    },
    {
      "x": 0,
      "y": 2,
      "z": -2,
      "name": "Water_Source",
      "level": 1
    },
    {
      "x": 0,
      "y": 3,
      "z": -2,
      "name": "Water_Source",
      "level": 1
    },
    {
      "x": 0,
      "y": 0,
      "z": -1,
      "name": "Water_Source",
      "level": 1
    },
    {
      "x": 0,
      "y": 1,
      "z": -1,
      "name": "Water_Source",
      "level": 1
    },
    {
      "x": 0,
      "y": 2,
      "z": -1,
      "name": "Water_Source",
      "level": 1
    },
    {
      "x": 0,
      "y": 3,
      "z": -1,
      "name": "Water_Source",
      "level": 1
    },
    {
      "x": 0,
      "y": 0,
      "z": 0,
      "name": "Water_Source",
      "level": 1
    },
    {
      "x": 0,
      "y": 1,
      "z": 0,
      "name": "Water_Source",
      "level": 1
    },
    {
      "x": 0,
      "y": 2,
      "z": 0,
      "name": "Water_Source",
      "level": 1
    },
    {
      "x": 0,
      "y": 3,
      "z": 0,
      "name": "Water_Source",
      "level": 1
    },
    {
      "x": 0,
      "y": 4,
      "z": 0,
      "name": "Empty",
      "level": 0
    },
    {
      "x": 0,
      "y": 0,
      "z": 1,
      "name": "Water_Source",
      "level": 1
    },
    {
      "x": 0,
      "y": 1,
      "z": 1,
      "name": "Water_Source",
      "level": 1
    },
    {
      "x": 0,
      "y": 2,
      "z": 1,
      "name": "Water_Source",
      "level": 1
    },
    {
      "x": 0,
      "y": 3,
      "z": 1,
      "name": "Water_Source",
      "level": 1
    },
    {
      "x": 0,
      "y": 4,
      "z": 1,
      "name": "Empty",
      "level": 0
    },
    {
      "x": 0,
      "y": 5,
      "z": 1,
      "name": "Empty",
      "level": 0
    },
    {
      "x": 0,
      "y": 6,
      "z": 1,
      "name": "Empty",
      "level": 0
    },
    {
      "x": 0,
      "y": 0,
      "z": 2,
      "name": "Water_Source",
      "level": 1
    },
    {
      "x": 0,
      "y": 1,
      "z": 2,
      "name": "Water_Source",
      "level": 1
    },
    {
      "x": 0,
      "y": 2,
      "z": 2,
      "name": "Water_Source",
      "level": 1
    },
    {
      "x": 0,
      "y": 3,
      "z": 2,
      "name": "Water_Source",
      "level": 1
    },
    {
      "x": 0,
      "y": 4,
      "z": 2,
      "name": "Empty",
      "level": 0
    },
    {
      "x": 0,
      "y": 5,
      "z": 2,
      "name": "Empty",
      "level": 0
    },
    {
      "x": 0,
      "y": 6,
      "z": 2,
      "name": "Empty",
      "level": 0
    },
    {
      "x": 0,
      "y": 7,
      "z": 2,
      "name": "Empty",
      "level": 0
    },
    {
      "x": 0,
      "y": 0,
      "z": 3,
      "name": "Water_Source",
      "level": 1
    },
    {
      "x": 0,
      "y": 1,
      "z": 3,
      "name": "Water_Source",
      "level": 1
    },
    {
      "x": 0,
      "y": 2,
      "z": 3,
      "name": "Water_Source",
      "level": 1
    },
    {
      "x": 0,
      "y": 3,
      "z": 3,
      "name": "Water_Source",
      "level": 1
    },
    {
      "x": 0,
      "y": 4,
      "z": 3,
      "name": "Empty",
      "level": 0
    },
    {
      "x": 0,
      "y": 5,
      "z": 3,
      "name": "Empty",
      "level": 0
    },
    {
      "x": 0,
      "y": 6,
      "z": 3,
      "name": "Empty",
      "level": 0
    },
    {
      "x": 0,
      "y": 7,
      "z": 3,
      "name": "Empty",
      "level": 0
    },
    {
      "x": 0,
      "y": 8,
      "z": 3,
      "name": "Empty",
      "level": 0
    },
    {
      "x": 1,
      "y": 0,
      "z": -3,
      "name": "Water_Source",
      "level": 1
    },
    {
      "x": 1,
      "y": 1,
      "z": -3,
      "name": "Water_Source",
      "level": 1
    },
    {
      "x": 1,
      "y": 2,
      "z": -3,
      "name": "Water_Source",
      "level": 1
    },
    {
      "x": 1,
      "y": 3,
      "z": -3,
      "name": "Water_Source",
      "level": 1
    },
    {
      "x": 1,
      "y": 4,
      "z": -3,
      "name": "Empty",
      "level": 0
    },
    {
      "x": 1,
      "y": 5,
      "z": -3,
      "name": "Empty",
      "level": 0
    },
    {
      "x": 1,
      "y": 6,
      "z": -3,
      "name": "Empty",
      "level": 0
    },
    {
      "x": 1,
      "y": 0,
      "z": -2,
      "name": "Water_Source",
      "level": 1
    },
    {
      "x": 1,
      "y": 1,
      "z": -2,
      "name": "Water_Source",
      "level": 1
    },
    {
      "x": 1,
      "y": 2,
      "z": -2,
      "name": "Water_Source",
      "level": 1
    },
    {
      "x": 1,
      "y": 3,
      "z": -2,
      "name": "Water_Source",
      "level": 1
    },
    {
      "x": 1,
      "y": 0,
      "z": -1,
      "name": "Water_Source",
      "level": 1
    },
    {
      "x": 1,
      "y": 1,
      "z": -1,
      "name": "Water_Source",
      "level": 1
    },
    {
      "x": 1,
      "y": 2,
      "z": -1,
      "name": "Water_Source",
      "level": 1
    },
    {
      "x": 1,
      "y": 3,
      "z": -1,
      "name": "Water_Source",
      "level": 1
    },
    {
      "x": 1,
      "y": 4,
      "z": -1,
      "name": "Empty",
      "level": 0
    },
    {
      "x": 1,
      "y": 5,
      "z": -1,
      "name": "Empty",
      "level": 0
    },
    {
      "x": 1,
      "y": 0,
      "z": 0,
      "name": "Water_Source",
      "level": 1
    },
    {
      "x": 1,
      "y": 1,
      "z": 0,
      "name": "Water_Source",
      "level": 1
    },
    {
      "x": 1,
      "y": 2,
      "z": 0,
      "name": "Water_Source",
      "level": 1
    },
    {
      "x": 1,
      "y": 3,
      "z": 0,
      "name": "Water_Source",
      "level": 1
    },
    {
      "x": 1,
      "y": 4,
      "z": 0,
      "name": "Empty",
      "level": 0
    },
    {
      "x": 1,
      "y": 5,
      "z": 0,
      "name": "Empty",
      "level": 0
    },
    {
      "x": 1,
      "y": 0,
      "z": 1,
      "name": "Water_Source",
      "level": 1
    },
    {
      "x": 1,
      "y": 1,
      "z": 1,
      "name": "Water_Source",
      "level": 1
    },
    {
      "x": 1,
      "y": 2,
      "z": 1,
      "name": "Water_Source",
      "level": 1
    },
    {
      "x": 1,
      "y": 3,
      "z": 1,
      "name": "Water_Source",
      "level": 1
    },
    {
      "x": 1,
      "y": 4,
      "z": 1,
      "name": "Empty",
      "level": 0
    },
    {
      "x": 1,
      "y": 5,
      "z": 1,
      "name": "Empty",
      "level": 0
    },
    {
      "x": 1,
      "y": 6,
      "z": 1,
      "name": "Empty",
      "level": 0
    },
    {
      "x": 1,
      "y": 0,
      "z": 2,
      "name": "Water_Source",
      "level": 1
    },
    {
      "x": 1,
      "y": 1,
      "z": 2,
      "name": "Water_Source",
      "level": 1
    },
    {
      "x": 1,
      "y": 2,
      "z": 2,
      "name": "Water_Source",
      "level": 1
    },
    {
      "x": 1,
      "y": 3,
      "z": 2,
      "name": "Water_Source",
      "level": 1
    },
    {
      "x": 1,
      "y": 4,
      "z": 2,
      "name": "Empty",
      "level": 0
    },
    {
      "x": 1,
      "y": 5,
      "z": 2,
      "name": "Empty",
      "level": 0
    },
    {
      "x": 1,
      "y": 6,
      "z": 2,
      "name": "Empty",
      "level": 0
    },
    {
      "x": 1,
      "y": 7,
      "z": 2,
      "name": "Empty",
      "level": 0
    },
    {
      "x": 1,
      "y": 0,
      "z": 3,
      "name": "Water_Source",
      "level": 1
    },
    {
      "x": 1,
      "y": 1,
      "z": 3,
      "name": "Water_Source",
      "level": 1
    },
    {
      "x": 1,
      "y": 2,
      "z": 3,
      "name": "Water_Source",
      "level": 1
    },
    {
      "x": 1,
      "y": 3,
      "z": 3,
      "name": "Water_Source",
      "level": 1
    },
    {
      "x": 1,
      "y": 4,
      "z": 3,
      "name": "Empty",
      "level": 0
    },
    {
      "x": 1,
      "y": 5,
      "z": 3,
      "name": "Empty",
      "level": 0
    },
    {
      "x": 1,
      "y": 6,
      "z": 3,
      "name": "Empty",
      "level": 0
    },
    {
      "x": 1,
      "y": 7,
      "z": 3,
      "name": "Empty",
      "level": 0
    },
    {
      "x": 1,
      "y": 8,
      "z": 3,
      "name": "Empty",
      "level": 0
    },
    {
      "x": 2,
      "y": 0,
      "z": -3,
      "name": "Water_Source",
      "level": 1
    },
    {
      "x": 2,
      "y": 1,
      "z": -3,
      "name": "Water_Source",
      "level": 1
    },
    {
      "x": 2,
      "y": 2,
      "z": -3,
      "name": "Water_Source",
      "level": 1
    },
    {
      "x": 2,
      "y": 3,
      "z": -3,
      "name": "Water_Source",
      "level": 1
    },
    {
      "x": 2,
      "y": 4,
      "z": -3,
      "name": "Empty",
      "level": 0
    },
    {
      "x": 2,
      "y": 5,
      "z": -3,
      "name": "Empty",
      "level": 0
    },
    {
      "x": 2,
      "y": 6,
      "z": -3,
      "name": "Empty",
      "level": 0
    },
    {
      "x": 2,
      "y": 7,
      "z": -3,
      "name": "Empty",
      "level": 0
    },
    {
      "x": 2,
      "y": 0,
      "z": -2,
      "name": "Water_Source",
      "level": 1
    },
    {
      "x": 2,
      "y": 1,
      "z": -2,
      "name": "Water_Source",
      "level": 1
    },
    {
      "x": 2,
      "y": 2,
      "z": -2,
      "name": "Water_Source",
      "level": 1
    },
    {
      "x": 2,
      "y": 3,
      "z": -2,
      "name": "Water_Source",
      "level": 1
    },
    {
      "x": 2,
      "y": 4,
      "z": -2,
      "name": "Empty",
      "level": 0
    },
    {
      "x": 2,
      "y": 5,
      "z": -2,
      "name": "Empty",
      "level": 0
    },
    {
      "x": 2,
      "y": 6,
      "z": -2,
      "name": "Empty",
      "level": 0
    },
    {
      "x": 2,
      "y": 7,
      "z": -2,
      "name": "Empty",
      "level": 0
    },
    {
      "x": 2,
      "y": 0,
      "z": -1,
      "name": "Water_Source",
      "level": 1
    },
    {
      "x": 2,
      "y": 1,
      "z": -1,
      "name": "Water_Source",
      "level": 1
    },
    {
      "x": 2,
      "y": 2,
      "z": -1,
      "name": "Water_Source",
      "level": 1
    },
    {
      "x": 2,
      "y": 3,
      "z": -1,
      "name": "Water_Source",
      "level": 1
    },
    {
      "x": 2,
      "y": 4,
      "z": -1,
      "name": "Empty",
      "level": 0
    },
    {
      "x": 2,
      "y": 5,
      "z": -1,
      "name": "Empty",
      "level": 0
    },
    {
      "x": 2,
      "y": 6,
      "z": -1,
      "name": "Empty",
      "level": 0
    },
    {
      "x": 2,
      "y": 7,
      "z": -1,
      "name": "Empty",
      "level": 0
    },
    {
      "x": 2,
      "y": 8,
      "z": -1,
      "name": "Empty",
      "level": 0
    },
    {
      "x": 2,
      "y": 0,
      "z": 0,
      "name": "Water_Source",
      "level": 1
    },
    {
      "x": 2,
      "y": 1,
      "z": 0,
      "name": "Water_Source",
      "level": 1
    },
    {
      "x": 2,
      "y": 2,
      "z": 0,
      "name": "Water_Source",
      "level": 1
    },
    {
      "x": 2,
      "y": 3,
      "z": 0,
      "name": "Water_Source",
      "level": 1
    },
    {
      "x": 2,
      "y": 4,
      "z": 0,
      "name": "Empty",
      "level": 0
    },
    {
      "x": 2,
      "y": 5,
      "z": 0,
      "name": "Empty",
      "level": 0
    },
    {
      "x": 2,
      "y": 6,
      "z": 0,
      "name": "Empty",
      "level": 0
    },
    {
      "x": 2,
      "y": 7,
      "z": 0,
      "name": "Empty",
      "level": 0
    },
    {
      "x": 2,
      "y": 0,
      "z": 1,
      "name": "Water_Source",
      "level": 1
    },
    {
      "x": 2,
      "y": 1,
      "z": 1,
      "name": "Water_Source",
      "level": 1
    },
    {
      "x": 2,
      "y": 2,
      "z": 1,
      "name": "Water_Source",
      "level": 1
    },
    {
      "x": 2,
      "y": 3,
      "z": 1,
      "name": "Water_Source",
      "level": 1
    },
    {
      "x": 2,
      "y": 4,
      "z": 1,
      "name": "Empty",
      "level": 0
    },
    {
      "x": 2,
      "y": 5,
      "z": 1,
      "name": "Empty",
      "level": 0
    },
    {
      "x": 2,
      "y": 6,
      "z": 1,
      "name": "Empty",
      "level": 0
    },
    {
      "x": 2,
      "y": 7,
      "z": 1,
      "name": "Empty",
      "level": 0
    },
    {
      "x": 2,
      "y": 0,
      "z": 2,
      "name": "Water_Source",
      "level": 1
    },
    {
      "x": 2,
      "y": 1,
      "z": 2,
      "name": "Water_Source",
      "level": 1
    },
    {
      "x": 2,
      "y": 2,
      "z": 2,
      "name": "Water_Source",
      "level": 1
    },
    {
      "x": 2,
      "y": 3,
      "z": 2,
      "name": "Water_Source",
      "level": 1
    },
    {
      "x": 2,
      "y": 4,
      "z": 2,
      "name": "Empty",
      "level": 0
    },
    {
      "x": 2,
      "y": 5,
      "z": 2,
      "name": "Empty",
      "level": 0
    },
    {
      "x": 2,
      "y": 6,
      "z": 2,
      "name": "Empty",
      "level": 0
    },
    {
      "x": 2,
      "y": 7,
      "z": 2,
      "name": "Empty",
      "level": 0
    },
    {
      "x": 2,
      "y": 0,
      "z": 3,
      "name": "Water_Source",
      "level": 1
    },
    {
      "x": 2,
      "y": 1,
      "z": 3,
      "name": "Water_Source",
      "level": 1
    },
    {
      "x": 2,
      "y": 2,
      "z": 3,
      "name": "Water_Source",
      "level": 1
    },
    {
      "x": 2,
      "y": 3,
      "z": 3,
      "name": "Water_Source",
      "level": 1
    },
    {
      "x": 2,
      "y": 4,
      "z": 3,
      "name": "Empty",
      "level": 0
    },
    {
      "x": 2,
      "y": 5,
      "z": 3,
      "name": "Empty",
      "level": 0
    },
    {
      "x": 2,
      "y": 6,
      "z": 3,
      "name": "Empty",
      "level": 0
    },
    {
      "x": 2,
      "y": 7,
      "z": 3,
      "name": "Empty",
      "level": 0
    },
    {
      "x": 2,
      "y": 8,
      "z": 3,
      "name": "Empty",
      "level": 0
    },
    {
      "x": 3,
      "y": 0,
      "z": -3,
      "name": "Water_Source",
      "level": 1
    },
    {
      "x": 3,
      "y": 1,
      "z": -3,
      "name": "Water_Source",
      "level": 1
    },
    {
      "x": 3,
      "y": 2,
      "z": -3,
      "name": "Water_Source",
      "level": 1
    },
    {
      "x": 3,
      "y": 3,
      "z": -3,
      "name": "Water_Source",
      "level": 1
    },
    {
      "x": 3,
      "y": 4,
      "z": -3,
      "name": "Empty",
      "level": 0
    },
    {
      "x": 3,
      "y": 5,
      "z": -3,
      "name": "Empty",
      "level": 0
    },
    {
      "x": 3,
      "y": 6,
      "z": -3,
      "name": "Empty",
      "level": 0
    },
    {
      "x": 3,
      "y": 7,
      "z": -3,
      "name": "Empty",
      "level": 0
    },
    {
      "x": 3,
      "y": 8,
      "z": -3,
      "name": "Empty",
      "level": 0
    },
    {
      "x": 3,
      "y": 0,
      "z": -2,
      "name": "Water_Source",
      "level": 1
    },
    {
      "x": 3,
      "y": 1,
      "z": -2,
      "name": "Water_Source",
      "level": 1
    },
    {
      "x": 3,
      "y": 2,
      "z": -2,
      "name": "Water_Source",
      "level": 1
    },
    {
      "x": 3,
      "y": 3,
      "z": -2,
      "name": "Water_Source",
      "level": 1
    },
    {
      "x": 3,
      "y": 4,
      "z": -2,
      "name": "Empty",
      "level": 0
    },
    {
      "x": 3,
      "y": 5,
      "z": -2,
      "name": "Empty",
      "level": 0
    },
    {
      "x": 3,
      "y": 6,
      "z": -2,
      "name": "Empty",
      "level": 0
    },
    {
      "x": 3,
      "y": 7,
      "z": -2,
      "name": "Empty",
      "level": 0
    },
    {
      "x": 3,
      "y": 8,
      "z": -2,
      "name": "Empty",
      "level": 0
    },
    {
      "x": 3,
      "y": 0,
      "z": -1,
      "name": "Water_Source",
      "level": 1
    },
    {
      "x": 3,
      "y": 1,
      "z": -1,
      "name": "Water_Source",
      "level": 1
    },
    {
      "x": 3,
      "y": 2,
      "z": -1,
      "name": "Water_Source",
      "level": 1
    },
    {
      "x": 3,
      "y": 3,
      "z": -1,
      "name": "Water_Source",
      "level": 1
    },
    {
      "x": 3,
      "y": 4,
      "z": -1,
      "name": "Empty",
      "level": 0
    },
    {
      "x": 3,
      "y": 5,
      "z": -1,
      "name": "Empty",
      "level": 0
    },
    {
      "x": 3,
      "y": 6,
      "z": -1,
      "name": "Empty",
      "level": 0
    },
    {
      "x": 3,
      "y": 7,
      "z": -1,
      "name": "Empty",
      "level": 0
    },
    {
      "x": 3,
      "y": 8,
      "z": -1,
      "name": "Empty",
      "level": 0
    },
    {
      "x": 3,
      "y": 0,
      "z": 0,
      "name": "Water_Source",
      "level": 1
    },
    {
      "x": 3,
      "y": 1,
      "z": 0,
      "name": "Water_Source",
      "level": 1
    },
    {
      "x": 3,
      "y": 2,
      "z": 0,
      "name": "Water_Source",
      "level": 1
    },
    {
      "x": 3,
      "y": 3,
      "z": 0,
      "name": "Water_Source",
      "level": 1
    },
    {
      "x": 3,
      "y": 4,
      "z": 0,
      "name": "Empty",
      "level": 0
    },
    {
      "x": 3,
      "y": 5,
      "z": 0,
      "name": "Empty",
      "level": 0
    },
    {
      "x": 3,
      "y": 6,
      "z": 0,
      "name": "Empty",
      "level": 0
    },
    {
      "x": 3,
      "y": 7,
      "z": 0,
      "name": "Empty",
      "level": 0
    },
    {
      "x": 3,
      "y": 8,
      "z": 0,
      "name": "Empty",
      "level": 0
    },
    {
      "x": 3,
      "y": 9,
      "z": 0,
      "name": "Empty",
      "level": 0
    },
    {
      "x": 3,
      "y": 0,
      "z": 1,
      "name": "Water_Source",
      "level": 1
    },
    {
      "x": 3,
      "y": 1,
      "z": 1,
      "name": "Water_Source",
      "level": 1
    },
    {
      "x": 3,
      "y": 2,
      "z": 1,
      "name": "Water_Source",
      "level": 1
    },
    {
      "x": 3,
      "y": 3,
      "z": 1,
      "name": "Water_Source",
      "level": 1
    },
    {
      "x": 3,
      "y": 4,
      "z": 1,
      "name": "Empty",
      "level": 0
    },
    {
      "x": 3,
      "y": 5,
      "z": 1,
      "name": "Empty",
      "level": 0
    },
    {
      "x": 3,
      "y": 6,
      "z": 1,
      "name": "Empty",
      "level": 0
    },
    {
      "x": 3,
      "y": 7,
      "z": 1,
      "name": "Empty",
      "level": 0
    },
    {
      "x": 3,
      "y": 8,
      "z": 1,
      "name": "Empty",
      "level": 0
    },
    {
      "x": 3,
      "y": 0,
      "z": 2,
      "name": "Water_Source",
      "level": 1
    },
    {
      "x": 3,
      "y": 1,
      "z": 2,
      "name": "Water_Source",
      "level": 1
    },
    {
      "x": 3,
      "y": 2,
      "z": 2,
      "name": "Water_Source",
      "level": 1
    },
    {
      "x": 3,
      "y": 3,
      "z": 2,
      "name": "Water_Source",
      "level": 1
    },
    {
      "x": 3,
      "y": 4,
      "z": 2,
      "name": "Empty",
      "level": 0
    },
    {
      "x": 3,
      "y": 5,
      "z": 2,
      "name": "Empty",
      "level": 0
    },
    {
      "x": 3,
      "y": 6,
      "z": 2,
      "name": "Empty",
      "level": 0
    },
    {
      "x": 3,
      "y": 7,
      "z": 2,
      "name": "Empty",
      "level": 0
    },
    {
      "x": 3,
      "y": 8,
      "z": 2,
      "name": "Empty",
      "level": 0
    },
    {
      "x": 3,
      "y": 0,
      "z": 3,
      "name": "Water_Source",
      "level": 1
    },
    {
      "x": 3,
      "y": 1,
      "z": 3,
      "name": "Water_Source",
      "level": 1
    },
    {
      "x": 3,
      "y": 2,
      "z": 3,
      "name": "Water_Source",
      "level": 1
    },
    {
      "x": 3,
      "y": 3,
      "z": 3,
      "name": "Water_Source",
      "level": 1
    },
    {
      "x": 3,
      "y": 4,
      "z": 3,
      "name": "Empty",
      "level": 0
    },
    {
      "x": 3,
      "y": 5,
      "z": 3,
      "name": "Empty",
      "level": 0
    },
    {
      "x": 3,
      "y": 6,
      "z": 3,
      "name": "Empty",
      "level": 0
    },
    {
      "x": 3,
      "y": 7,
      "z": 3,
      "name": "Empty",
      "level": 0
    },
    {
      "x": 3,
      "y": 8,
      "z": 3,
      "name": "Empty",
      "level": 0
    }
  ]
}