{
  "version": 8,
  "blockIdVersion": 11,
  "anchorX": 0,
  "anchorY": 0,
  "anchorZ": 0,
  "blocks": [
    {
      "x": -3,
      "y": 0,
      "z": -1,
      "name": "Rock_Stone_Stairs",
      "rotation": 3
    },
    {
      "x": -3,
      "y": 0,
      "z": 0,
      "name": "Rock_Stone"
    },
    {
      "x": -3,
      "y": 0,
      "z": 1,
      "name": "Rock_Stone"
    },
    {
      "x": -3,
      "y": 0,
      "z": 2,
      "name": "Rock_Stone_Stairs",
      "rotation": 3
    },
    {
      "x": -3,
      "y": 0,
      "z": 3,
      "name": "Rock_Stone"
    },
    {
      "x": -3,
      "y": 0,
      "z": 4,
      "name": "Rock_Stone"
    },
    {
      "x": -2,
      "y": 0,
      "z": -1,
      "name": "Rock_Stone",
      "rotation": 2
    },
    {
      "x": -2,
      "y": 0,
      "z": 0,
      "name": "Rock_Stone",
      "rotation": 2
    },
    {
      "x": -2,
      "y": 0,
      "z": 1,
      "name": "Rock_Stone",
      "rotation": 2
    },
    {
      "x": -2,
      "y": 1,
      "z": 1,
      "name": "Soil_Clay_Grey",
      "rotation": 2
    },
    {
      "x": -2,
      "y": 2,
      "z": 1,
      "name": "Soil_Clay_Grey",
      "rotation": 2
    },
    {
      "x": -2,
      "y": 3,
      "z": 1,
      "name": "Soil_Clay_Grey",
      "rotation": 2
    },
    {
      "x": -2,
      "y": 4,
      "z": 1,
      "name": "Soil_Clay_Grey",
      "rotation": 2
    },
    {
      "x": -2,
      "y": 5,
      "z": 1,
      "name": "Soil_Clay_White",
      "rotation": 2
    },
    {
      "x": -2,
      "y": 0,
      "z": 2,
      "name": "Rock_Stone",
      "rotation": 2
    },
    {
      "x": -2,
      "y": 1,
      "z": 2,
      "name": "Soil_Clay_Smooth_Grey_Stairs",
      "rotation": 3
    },
    {
      "x": -2,
      "y": 2,
      "z": 2,
      "name": "Soil_Clay_Smooth_Grey_Half",
      "rotation": 7
    },
    {
      "x": -2,
      "y": 3,
      "z": 2,
      "name": "Soil_Clay_Smooth_Grey_Half",
      "rotation": 7
    },
    {
      "x": -2,
      "y": 4,
      "z": 2,
      "name": "Soil_Clay_Smooth_Grey_Stairs",
      "rotation": 9
    },
    {
      "x": -2,
      "y": 5,
      "z": 2,
      "name": "Soil_Clay_White",
      "rotation": 2
    },
    {
      "x": -2,
      "y": 0,
      "z": 3,
      "name": "Rock_Stone",
      "rotation": 2
    },
    {
      "x": -2,
      "y": 1,
      "z": 3,
      "name": "Soil_Clay_Grey",
      "rotation": 2
    },
    {
      "x": -2,
      "y": 2,
      "z": 3,
      "name": "Soil_Clay_Grey",
      "rotation": 2
    },
    {
      "x": -2,
      "y": 3,
      "z": 3,
      "name": "Soil_Clay_Grey",
      "rotation": 2
    },
    {
      "x": -2,
      "y": 4,
      "z": 3,
      "name": "Soil_Clay_Grey",
      "rotation": 2
    },
    {
      "x": -2,
      "y": 5,
      "z": 3,
      "name": "Soil_Clay_White",
      "rotation": 2
    },
    {
      "x": -2,
      "y": 0,
      "z": 4,
      "name": "Rock_Stone",
      "rotation": 2
    },
    {
      "x": -1,
      "y": 0,
      "z": -2,
      "name": "Rock_Stone",
      "rotation": 3
    },
    {
      "x": -1,
      "y": 0,
      "z": -1,
      "name": "Rock_Stone",
      "rotation": 2
    },
    {
      "x": -1,
      "y": 0,
      "z": 0,
      "name": "Rock_Stone",
      "rotation": 2
    },
    {
      "x": -1,
      "y": 1,
      "z": 0,
      "name": "Soil_Clay_Grey",
      "rotation": 2
    },
    {
      "x": -1,
      "y": 2,
      "z": 0,
      "name": "Soil_Clay_Grey",
      "rotation": 2
    },
    {
      "x": -1,
      "y": 3,
      "z": 0,
      "name": "Soil_Clay_Grey",
      "rotation": 2
    },
    {
      "x": -1,
      "y": 4,
      "z": 0,
      "name": "Soil_Clay_Grey",
      "rotation": 2
    },
    {
      "x": -1,
      "y": 5,
      "z": 0,
      "name": "Soil_Clay_White",
      "rotation": 2
    },
    {
      "x": -1,
      "y": 0,
      "z": 1,
      "name": "Rock_Stone",
      "rotation": 2
    },
    {
      "x": -1,
      "y": 0,
      "z": 2,
      "name": "Rock_Stone",
      "rotation": 2
    },
    {
      "x": -1,
      "y": 0,
      "z": 3,
      "name": "Rock_Stone",
      "rotation": 2
    },
    {
      "x": -1,
      "y": 0,
      "z": 4,
      "name": "Rock_Stone",
      "rotation": 2
    },
    {
      "x": -1,
      "y": 1,
      "z": 4,
      "name": "Soil_Clay_Grey",
      "rotation": 2
    },
    {
      "x": -1,
      "y": 2,
      "z": 4,
      "name": "Soil_Clay_Grey",
      "rotation": 2
    },
    {
      "x": -1,
      "y": 3,
      "z": 4,
      "name": "Soil_Clay_Grey",
      "rotation": 2
    },
    {
      "x": -1,
      "y": 4,
      "z": 4,
      "name": "Soil_Clay_Grey",
      "rotation": 2
    },
    {
      "x": -1,
      "y": 5,
      "z": 4,
      "name": "Soil_Clay_White",
      "rotation": 2
    },
    {
      "x": 0,
      "y": 0,
      "z": -2,
      "name": "Rock_Stone"
    },
    {
      "x": 0,
      "y": 0,
      "z": -1,
      "name": "Rock_Stone",
      "rotation": 2
    },
    {
      "x": 0,
      "y": 1,
      "z": -1,
      "name": "Soil_Clay_Grey",
      "rotation": 2
    },
    {
      "x": 0,
      "y": 2,
      "z": -1,
      "name": "Soil_Clay_Grey",
      "rotation": 2
    },
    {
      "x": 0,
      "y": 3,
      "z": -1,
      "name": "Soil_Clay_Grey",
      "rotation": 2
    },
    {
      "x": 0,
      "y": 4,
      "z": -1,
      "name": "Soil_Clay_Grey",
      "rotation": 2
    },
    {
      "x": 0,
      "y": 5,
      "z": -1,
      "name": "Soil_Clay_White",
      "rotation": 2
    },
    {
      "x": 0,
      "y": 0,
      "z": 0,
      "name": "Rock_Stone",
      "rotation": 2
    },
    {
      "x": 0,
      "y": 0,
      "z": 1,
      "name": "Rock_Stone",
      "rotation": 2
    },
    {
      "x": 0,
      "y": 0,
      "z": 2,
      "name": "Rock_Stone",
      "rotation": 2
    },
    {
      "x": 0,
      "y": 0,
      "z": 3,
      "name": "Rock_Stone",
      "rotation": 2
    },
    {
      "x": 0,
      "y": 0,
      "z": 4,
      "name": "Rock_Stone",
      "rotation": 2
    },
    {
      "x": 1,
      "y": 0,
      "z": -2,
      "name": "Rock_Stone"
    },
    {
      "x": 1,
      "y": 0,
      "z": -1,
      "name": "Rock_Stone",
      "rotation": 2
    },
    {
      "x": 1,
      "y": 1,
      "z": -1,
      "name": "Soil_Clay_Smooth_Grey_Stairs",
      "rotation": 2
    },
    {
      "x": 1,
      "y": 2,
      "z": -1,
      "name": "Soil_Clay_Smooth_Grey_Half",
      "rotation": 6
    },
    {
      "x": 1,
      "y": 3,
      "z": -1,
      "name": "Soil_Clay_Smooth_Grey_Half",
      "rotation": 6
    },
    {
      "x": 1,
      "y": 4,
      "z": -1,
      "name": "Soil_Clay_Smooth_Grey_Stairs",
      "rotation": 8
    },
    {
      "x": 1,
      "y": 5,
      "z": -1,
      "name": "Soil_Clay_White",
      "rotation": 2
    },
    {
      "x": 1,
      "y": 0,
      "z": 0,
      "name": "Rock_Stone",
      "rotation": 2
    },
    {
      "x": 1,
      "y": 0,
      "z": 1,
      "name": "Rock_Stone",
      "rotation": 2
    },
    {
      "x": 1,
      "y": 0,
      "z": 2,
      "name": "Rock_Stone",
      "rotation": 2
    },
    {
      "x": 1,
      "y": 0,
      "z": 3,
      "name": "Rock_Stone",
      "rotation": 2
    },
    {
      "x": 1,
      "y": 0,
      "z": 4,
      "name": "Rock_Stone",
      "rotation": 2
    },
    {
      "x": 2,
      "y": 0,
      "z": -3,
      "name": "Rock_Stone_Stairs",
      "rotation": 2
    },
    {
      "x": 2,
      "y": 0,
      "z": -2,
      "name": "Rock_Stone"
    },
    {
      "x": 2,
      "y": 0,
      "z": -1,
      "name": "Rock_Stone",
      "rotation": 2
    },
    {
      "x": 2,
      "y": 1,
      "z": -1,
      "name": "Soil_Clay_Grey",
      "rotation": 2
    },
    {
      "x": 2,
      "y": 2,
      "z": -1,
      "name": "Soil_Clay_Grey",
      "rotation": 2
    },
    {
      "x": 2,
      "y": 3,
      "z": -1,
      "name": "Soil_Clay_Grey",
      "rotation": 2
    },
    {
      "x": 2,
      "y": 4,
      "z": -1,
      "name": "Soil_Clay_Grey",
      "rotation": 2
    },
    {
      "x": 2,
      "y": 5,
      "z": -1,
      "name": "Soil_Clay_White",
      "rotation": 2
    },
    {
      "x": 2,
      "y": 0,
      "z": 0,
      "name": "Rock_Stone",
      "rotation": 2
    },
    {
      "x": 2,
      "y": 0,
      "z": 1,
      "name": "Rock_Stone",
      "rotation": 2
    },
    {
      "x": 2,
      "y": 0,
      "z": 2,
      "name": "Rock_Stone",
      "rotation": 2
    },
    {
      "x": 2,
      "y": 0,
      "z": 3,
      "name": "Rock_Stone",
      "rotation": 2
    },
    {
      "x": 2,
      "y": 0,
      "z": 4,
      "name": "Rock_Stone",
      "rotation": 2
    },
    {
      "x": 3,
      "y": 0,
      "z": -2,
      "name": "Rock_Stone",
      "rotation": 3
    },
    {
      "x": 3,
      "y": 0,
      "z": -1,
      "name": "Rock_Stone",
      "rotation": 2
    },
    {
      "x": 3,
      "y": 0,
      "z": 0,
      "name": "Rock_Stone",
      "rotation": 2
    },
    {
      "x": 3,
      "y": 1,
      "z": 0,
      "name": "Soil_Clay_Grey",
      "rotation": 2
    },
    {
      "x": 3,
      "y": 2,
      "z": 0,
      "name": "Soil_Clay_Grey",
      "rotation": 2
    },
    {
      "x": 3,
      "y": 3,
      "z": 0,
      "name": "Soil_Clay_Grey",
      "rotation": 2
    },
    {
      "x": 3,
      "y": 4,
      "z": 0,
      "name": "Soil_Clay_Grey",
      "rotation": 2
    },
    {
      "x": 3,
      "y": 5,
      "z": 0,
      "name": "Soil_Clay_White",
      "rotation": 2
    },
    {
      "x": 3,
      "y": 0,
      "z": 1,
      "name": "Rock_Stone",
      "rotation": 2
    },
    {
      "x": 3,
      "y": 0,
      "z": 2,
      "name": "Rock_Stone",
      "rotation": 2
    },
    {
      "x": 3,
      "y": 1,
      "z": 2,
      "name": "Soil_Clay_Smooth_Black",
      "rotation": 2
    },
    {
      "x": 3,
      "y": 2,
      "z": 2,
      "name": "Soil_Clay_Smooth_Black",
      "rotation": 2
    },
    {
      "x": 3,
      "y": 3,
      "z": 2,
      "name": "Soil_Clay_Smooth_Black",
      "rotation": 2
    },
    {
      "x": 3,
      "y": 0,
      "z": 3,
      "name": "Rock_Stone",
      "rotation": 2
    },
    {
      "x": 3,
      "y": 0,
      "z": 4,
      "name": "Rock_Stone",
      "rotation": 2
    },
    {
      "x": 3,
      "y": 1,
      "z": 4,
      "name": "Soil_Clay_Grey",
      "rotation": 2
    },
    {
      "x": 3,
      "y": 2,
      "z": 4,
      "name": "Soil_Clay_Grey",
      "rotation": 2
    },
    {
      "x": 3,
      "y": 3,
      "z": 4,
      "name": "Soil_Clay_Grey",
      "rotation": 2
    },
    {
      "x": 3,
      "y": 4,
      "z": 4,
      "name": "Soil_Clay_Grey",
      "rotation": 2
    },
    {
      "x": 3,
      "y": 5,
      "z": 4,
      "name": "Soil_Clay_White",
      "rotation": 2
    },
    {
      "x": 4,
      "y": 0,
      "z": -2,
      "name": "Rock_Stone_Stairs",
      "rotation": 2
    },
    {
      "x": 4,
      "y": 0,
      "z": -1,
      "name": "Rock_Stone"
    },
    {
      "x": 4,
      "y": 1,
      "z": -1,
      "name": "Rubble_Stone",
      "support": 15
    },
    {
      "x": 4,
      "y": 0,
      "z": 0,
      "name": "Rock_Stone"
    },
    {
      "x": 4,
      "y": 0,
      "z": 1,
      "name": "Rock_Stone"
    },
    {
      "x": 4,
      "y": 1,
      "z": 1,
      "name": "Soil_Clay_Grey",
      "rotation": 2
    },
    {
      "x": 4,
      "y": 2,
      "z": 1,
      "name": "Soil_Clay_Grey",
      "rotation": 2
    },
    {
      "x": 4,
      "y": 3,
      "z": 1,
      "name": "Soil_Clay_Grey",
      "rotation": 2
    },
    {
      "x": 4,
      "y": 4,
      "z": 1,
      "name": "Soil_Clay_Grey",
      "rotation": 2
    },
    {
      "x": 4,
      "y": 5,
      "z": 1,
      "name": "Soil_Clay_White",
      "rotation": 2
    },
    {
      "x": 4,
      "y": 0,
      "z": 2,
      "name": "Rock_Stone"
    },
    {
      "x": 4,
      "y": 3,
      "z": 2,
      "name": "Soil_Clay_Smooth_Grey_Half",
      "rotation": 5
    },
    {
      "x": 4,
      "y": 4,
      "z": 2,
      "name": "Soil_Clay_Smooth_Grey_Stairs",
      "rotation": 11
    },
    {
      "x": 4,
      "y": 5,
      "z": 2,
      "name": "Soil_Clay_White",
      "rotation": 2
    },
    {
      "x": 4,
      "y": 0,
      "z": 3,
      "name": "Rock_Stone_Mossy"
    },
    {
      "x": 4,
      "y": 1,
      "z": 3,
      "name": "Soil_Clay_Grey",
      "rotation": 2
    },
    {
      "x": 4,
      "y": 2,
      "z": 3,
      "name": "Soil_Clay_Grey",
      "rotation": 2
    },
    {
      "x": 4,
      "y": 3,
      "z": 3,
      "name": "Soil_Clay_Grey",
      "rotation": 2
    },
    {
      "x": 4,
      "y": 4,
      "z": 3,
      "name": "Soil_Clay_Grey",
      "rotation": 2
    },
    {
      "x": 4,
      "y": 5,
      "z": 3,
      "name": "Soil_Clay_White",
      "rotation": 2
    },
    {
      "x": 4,
      "y": 0,
      "z": 4,
      "name": "Rock_Stone_Mossy"
    }
  ],
  "fluids": [
    {
      "x": -3,
      "y": 0,
      "z": -1,
      "name": "Empty",
      "level": 0
    },
    {
      "x": -3,
      "y": 0,
      "z": 0,
      "name": "Empty",
      "level": 0
    },
    {
      "x": -3,
      "y": 0,
      "z": 1,
      "name": "Empty",
      "level": 0
    },
    {
      "x": -3,
      "y": 0,
      "z": 2,
      "name": "Empty",
      "level": 0
    },
    {
      "x": -3,
      "y": 0,
      "z": 3,
      "name": "Empty",
      "level": 0
    },
    {
      "x": -3,
      "y": 0,
      "z": 4,
      "name": "Empty",
      "level": 0
    },
    {
      "x": -2,
      "y": 0,
      "z": -1,
      "name": "Empty",
      "level": 0
    },
    {
      "x": -2,
      "y": 0,
      "z": 0,
      "name": "Empty",
      "level": 0
    },
    {
      "x": -2,
      "y": 0,
      "z": 1,
      "name": "Empty",
      "level": 0
    },
    {
      "x": -2,
      "y": 1,
      "z": 1,
      "name": "Empty",
      "level": 0
    },
    {
      "x": -2,
      "y": 2,
      "z": 1,
      "name": "Empty",
      "level": 0
    },
    {
      "x": -2,
      "y": 3,
      "z": 1,
      "name": "Empty",
      "level": 0
    },
    {
      "x": -2,
      "y": 4,
      "z": 1,
      "name": "Empty",
      "level": 0
    },
    {
      "x": -2,
      "y": 5,
      "z": 1,
      "name": "Empty",
      "level": 0
    },
    {
      "x": -2,
      "y": 0,
      "z": 2,
      "name": "Empty",
      "level": 0
    },
    {
      "x": -2,
      "y": 1,
      "z": 2,
      "name": "Empty",
      "level": 0
    },
    {
      "x": -2,
      "y": 2,
      "z": 2,
      "name": "Empty",
      "level": 0
    },
    {
      "x": -2,
      "y": 3,
      "z": 2,
      "name": "Empty",
      "level": 0
    },
    {
      "x": -2,
      "y": 4,
      "z": 2,
      "name": "Empty",
      "level": 0
    },
    {
      "x": -2,
      "y": 5,
      "z": 2,
      "name": "Empty",
      "level": 0
    },
    {
      "x": -2,
      "y": 0,
      "z": 3,
      "name": "Empty",
      "level": 0
    },
    {
      "x": -2,
      "y": 1,
      "z": 3,
      "name": "Empty",
      "level": 0
    },
    {
      "x": -2,
      "y": 2,
      "z": 3,
      "name": "Empty",
      "level": 0
    },
    {
      "x": -2,
      "y": 3,
      "z": 3,
      "name": "Empty",
      "level": 0
    },
    {
      "x": -2,
      "y": 4,
      "z": 3,
      "name": "Empty",
      "level": 0
    },
    {
      "x": -2,
      "y": 5,
      "z": 3,
      "name": "Empty",
      "level": 0
    },
    {
      "x": -2,
      "y": 0,
      "z": 4,
      "name": "Empty",
      "level": 0
    },
    {
      "x": -1,
      "y": 0,
      "z": -2,
      "name": "Empty",
      "level": 0
    },
    {
      "x": -1,
      "y": 0,
      "z": -1,
      "name": "Empty",
      "level": 0
    },
    {
      "x": -1,
      "y": 0,
      "z": 0,
      "name": "Empty",
      "level": 0
    },
    {
      "x": -1,
      "y": 1,
      "z": 0,
      "name": "Empty",
      "level": 0
    },
    {
      "x": -1,
      "y": 2,
      "z": 0,
      "name": "Empty",
      "level": 0
    },
    {
      "x": -1,
      "y": 3,
      "z": 0,
      "name": "Empty",
      "level": 0
    },
    {
      "x": -1,
      "y": 4,
      "z": 0,
      "name": "Empty",
      "level": 0
    },
    {
      "x": -1,
      "y": 5,
      "z": 0,
      "name": "Empty",
      "level": 0
    },
    {
      "x": -1,
      "y": 0,
      "z": 1,
      "name": "Empty",
      "level": 0
    },
    {
      "x": -1,
      "y": 0,
      "z": 2,
      "name": "Empty",
      "level": 0
    },
    {
      "x": -1,
      "y": 0,
      "z": 3,
      "name": "Empty",
      "level": 0
    },
    {
      "x": -1,
      "y": 0,
      "z": 4,
      "name": "Empty",
      "level": 0
    },
    {
      "x": -1,
      "y": 1,
      "z": 4,
      "name": "Empty",
      "level": 0
    },
    {
      "x": -1,
      "y": 2,
      "z": 4,
      "name": "Empty",
      "level": 0
    },
    {
      "x": -1,
      "y": 3,
      "z": 4,
      "name": "Empty",
      "level": 0
    },
    {
      "x": -1,
      "y": 4,
      "z": 4,
      "name": "Empty",
      "level": 0
    },
    {
      "x": -1,
      "y": 5,
      "z": 4,
      "name": "Empty",
      "level": 0
    },
    {
      "x": 0,
      "y": 0,
      "z": -2,
      "name": "Empty",
      "level": 0
    },
    {
      "x": 0,
      "y": 0,
      "z": -1,
      "name": "Empty",
      "level": 0
    },
    {
      "x": 0,
      "y": 1,
      "z": -1,
      "name": "Empty",
      "level": 0
    },
    {
      "x": 0,
      "y": 2,
      "z": -1,
      "name": "Empty",
      "level": 0
    },
    {
      "x": 0,
      "y": 3,
      "z": -1,
      "name": "Empty",
      "level": 0
    },
    {
      "x": 0,
      "y": 4,
      "z": -1,
      "name": "Empty",
      "level": 0
    },
    {
      "x": 0,
      "y": 5,
      "z": -1,
      "name": "Empty",
      "level": 0
    },
    {
      "x": 0,
      "y": 0,
      "z": 0,
      "name": "Empty",
      "level": 0
    },
    {
      "x": 0,
      "y": 0,
      "z": 1,
      "name": "Empty",
      "level": 0
    },
    {
      "x": 0,
      "y": 0,
      "z": 2,
      "name": "Empty",
      "level": 0
    },
    {
      "x": 0,
      "y": 0,
      "z": 3,
      "name": "Empty",
      "level": 0
    },
    {
      "x": 0,
      "y": 0,
      "z": 4,
      "name": "Empty",
      "level": 0
    },
    {
      "x": 1,
      "y": 0,
      "z": -2,
      "name": "Empty",
      "level": 0
    },
    {
      "x": 1,
      "y": 0,
      "z": -1,
      "name": "Empty",
      "level": 0
    },
    {
      "x": 1,
      "y": 1,
      "z": -1,
      "name": "Empty",
      "level": 0
    },
    {
      "x": 1,
      "y": 2,
      "z": -1,
      "name": "Empty",
      "level": 0
    },
    {
      "x": 1,
      "y": 3,
      "z": -1,
      "name": "Empty",
      "level": 0
    },
    {
      "x": 1,
      "y": 4,
      "z": -1,
      "name": "Empty",
      "level": 0
    },
    {
      "x": 1,
      "y": 5,
      "z": -1,
      "name": "Empty",
      "level": 0
    },
    {
      "x": 1,
      "y": 0,
      "z": 0,
      "name": "Empty",
      "level": 0
    },
    {
      "x": 1,
      "y": 0,
      "z": 1,
      "name": "Empty",
      "level": 0
    },
    {
      "x": 1,
      "y": 0,
      "z": 2,
      "name": "Empty",
      "level": 0
    },
    {
      "x": 1,
      "y": 0,
      "z": 3,
      "name": "Empty",
      "level": 0
    },
    {
      "x": 1,
      "y": 0,
      "z": 4,
      "name": "Empty",
      "level": 0
    },
    {
      "x": 2,
      "y": 0,
      "z": -3,
      "name": "Empty",
      "level": 0
    },
    {
      "x": 2,
      "y": 0,
      "z": -2,
      "name": "Empty",
      "level": 0
    },
    {
      "x": 2,
      "y": 0,
      "z": -1,
      "name": "Empty",
      "level": 0
    },
    {
      "x": 2,
      "y": 1,
      "z": -1,
      "name": "Empty",
      "level": 0
    },
    {
      "x": 2,
      "y": 2,
      "z": -1,
      "name": "Empty",
      "level": 0
    },
    {
      "x": 2,
      "y": 3,
      "z": -1,
      "name": "Empty",
      "level": 0
    },
    {
      "x": 2,
      "y": 4,
      "z": -1,
      "name": "Empty",
      "level": 0
    },
    {
      "x": 2,
      "y": 5,
      "z": -1,
      "name": "Empty",
      "level": 0
    },
    {
      "x": 2,
      "y": 0,
      "z": 0,
      "name": "Empty",
      "level": 0
    },
    {
      "x": 2,
      "y": 0,
      "z": 1,
      "name": "Empty",
      "level": 0
    },
    {
      "x": 2,
      "y": 0,
      "z": 2,
      "name": "Empty",
      "level": 0
    },
    {
      "x": 2,
      "y": 0,
      "z": 3,
      "name": "Empty",
      "level": 0
    },
    {
      "x": 2,
      "y": 0,
      "z": 4,
      "name": "Empty",
      "level": 0
    },
    {
      "x": 3,
      "y": 0,
      "z": -2,
      "name": "Empty",
      "level": 0
    },
    {
      "x": 3,
      "y": 0,
      "z": -1,
      "name": "Empty",
      "level": 0
    },
    {
      "x": 3,
      "y": 0,
      "z": 0,
      "name": "Empty",
      "level": 0
    },
    {
      "x": 3,
      "y": 1,
      "z": 0,
      "name": "Empty",
      "level": 0
    },
    {
      "x": 3,
      "y": 2,
      "z": 0,
      "name": "Empty",
      "level": 0
    },
    {
      "x": 3,
      "y": 3,
      "z": 0,
      "name": "Empty",
      "level": 0
    },
    {
      "x": 3,
      "y": 4,
      "z": 0,
      "name": "Empty",
      "level": 0
    },
    {
      "x": 3,
      "y": 5,
      "z": 0,
      "name": "Empty",
      "level": 0
    },
    {
      "x": 3,
      "y": 0,
      "z": 1,
      "name": "Empty",
      "level": 0
    },
    {
      "x": 3,
      "y": 0,
      "z": 2,
      "name": "Empty",
      "level": 0
    },
    {
      "x": 3,
      "y": 1,
      "z": 2,
      "name": "Empty",
      "level": 0
    },
    {
      "x": 3,
      "y": 2,
      "z": 2,
      "name": "Empty",
      "level": 0
    },
    {
      "x": 3,
      "y": 3,
      "z": 2,
      "name": "Empty",
      "level": 0
    },
    {
      "x": 3,
      "y": 0,
      "z": 3,
      "name": "Empty",
      "level": 0
    },
    {
      "x": 3,
      "y": 0,
      "z": 4,
      "name": "Empty",
      "level": 0
    },
    {
      "x": 3,
      "y": 1,
      "z": 4,
      "name": "Empty",
      "level": 0
    },
    {
      "x": 3,
      "y": 2,
      "z": 4,
      "name": "Empty",
      "level": 0
    },
    {
      "x": 3,
      "y": 3,
      "z": 4,
      "name": "Empty",
      "level": 0
    },
    {
      "x": 3,
      "y": 4,
      "z": 4,
      "name": "Empty",
      "level": 0
    },
    {
      "x": 3,
      "y": 5,
      "z": 4,
      "name": "Empty",
      "level": 0
    },
    {
      "x": 4,
      "y": 0,
      "z": -2,
      "name": "Empty",
      "level": 0
    },
    {
      "x": 4,
      "y": 0,
      "z": -1,
      "name": "Empty",
      "level": 0
    },
    {
      "x": 4,
      "y": 1,
      "z": -1,
      "name": "Empty",
      "level": 0
    },
    {
      "x": 4,
      "y": 0,
      "z": 0,
      "name": "Empty",
      "level": 0
    },
    {
      "x": 4,
      "y": 0,
      "z": 1,
      "name": "Empty",
      "level": 0
    },
    {
      "x": 4,
      "y": 1,
      "z": 1,
      "name": "Empty",
      "level": 0
    },
    {
      "x": 4,
      "y": 2,
      "z": 1,
      "name": "Empty",
      "level": 0
    },
    {
      "x": 4,
      "y": 3,
      "z": 1,
      "name": "Empty",
      "level": 0
    },
    {
      "x": 4,
      "y": 4,
      "z": 1,
      "name": "Empty",
      "level": 0
    },
    {
      "x": 4,
      "y": 5,
      "z": 1,
      "name": "Empty",
      "level": 0
    },
    {
      "x": 4,
      "y": 0,
      "z": 2,
      "name": "Empty",
      "level": 0
    },
    {
      "x": 4,
      "y": 3,
      "z": 2,
      "name": "Empty",
      "level": 0
    },
    {
      "x": 4,
      "y": 4,
      "z": 2,
      "name": "Empty",
      "level": 0
    },
    {
      "x": 4,
      "y": 5,
      "z": 2,
      "name": "Empty",
      "level": 0
    },
    {
      "x": 4,
      "y": 0,
      "z": 3,
      "name": "Empty",
      "level": 0
    },
    {
      "x": 4,
      "y": 1,
      "z": 3,
      "name": "Empty",
      "level": 0
    },
    {
      "x": 4,
      "y": 2,
      "z": 3,
      "name": "Empty",
      "level": 0
    },
    {
      "x": 4,
      "y": 3,
      "z": 3,
      "name": "Empty",
      "level": 0
    },
    {
      "x": 4,
      "y": 4,
      "z": 3,
      "name": "Empty",
      "level": 0
    },
    {
      "x": 4,
      "y": 5,
      "z": 3,
      "name": "Empty",
      "level": 0
    },
    {
      "x": 4,
      "y": 0,
      "z": 4,
      "name": "Empty",
      "level": 0
    }
  ]
}