{
  "version": 8,
  "blockIdVersion": 11,
  "anchorX": 1,
  "anchorY": 21,
  "anchorZ": 0,
  "blocks": [
    {
      "x": -10,
      "y": 22,
      "z": -16,
      "name": "Cloth_Block_Wool_Pink",
      "rotation": 3
    },
    {
      "x": -10,
      "y": 22,
      "z": -15,
      "name": "Cloth_Block_Wool_Pink",
      "rotation": 3
    },
    {
      "x": -10,
      "y": 22,
      "z": -14,
      "name": "Cloth_Block_Wool_Pink",
      "rotation": 3
    },
    {
      "x": -10,
      "y": 22,
      "z": -13,
      "name": "Cloth_Block_Wool_Pink",
      "rotation": 3
    },
    {
      "x": -10,
      "y": 22,
      "z": -12,
      "name": "Cloth_Block_Wool_Pink",
      "rotation": 3
    },
    {
      "x": -10,
      "y": 22,
      "z": -11,
      "name": "Cloth_Block_Wool_Pink"
    },
    {
      "x": -10,
      "y": 22,
      "z": -10,
      "name": "Cloth_Block_Wool_Pink",
      "rotation": 3
    },
    {
      "x": -10,
      "y": 22,
      "z": -9,
      "name": "Cloth_Block_Wool_Pink",
      "rotation": 3
    },
    {
      "x": -10,
      "y": 22,
      "z": -8,
      "name": "Cloth_Block_Wool_Pink",
      "rotation": 3
    },
    {
      "x": -10,
      "y": 22,
      "z": -7,
      "name": "Cloth_Block_Wool_Pink",
      "rotation": 3
    },
    {
      "x": -10,
      "y": 22,
      "z": -6,
      "name": "Cloth_Block_Wool_Pink",
      "rotation": 3
    },
    {
      "x": -10,
      "y": 22,
      "z": -5,
      "name": "Cloth_Block_Wool_Green",
      "rotation": 2
    },
    {
      "x": -10,
      "y": 22,
      "z": -4,
      "name": "Cloth_Block_Wool_Green",
      "rotation": 2
    },
    {
      "x": -10,
      "y": 13,
      "z": -3,
      "name": "Rock_Stone_Brick_Decorative"
    },
    {
      "x": -10,
      "y": 14,
      "z": -3,
      "name": "Soil_Gravel",
      "support": 15
    },
    {
      "x": -10,
      "y": 15,
      "z": -3,
      "name": "Soil_Gravel",
      "support": 15
    },
    {
      "x": -10,
      "y": 16,
      "z": -3,
      "name": "Soil_Gravel",
      "support": 15
    },
    {
      "x": -10,
      "y": 17,
      "z": -3,
      "name": "Soil_Gravel",
      "support": 15
    },
    {
      "x": -10,
      "y": 22,
      "z": -3,
      "name": "Cloth_Block_Wool_Green",
      "rotation": 2
    },
    {
      "x": -10,
      "y": 22,
      "z": -2,
      "name": "Cloth_Block_Wool_Green",
      "rotation": 2
    },
    {
      "x": -10,
      "y": 22,
      "z": -1,
      "name": "Cloth_Block_Wool_Green",
      "rotation": 2
    },
    {
      "x": -10,
      "y": 22,
      "z": 0,
      "name": "Cloth_Block_Wool_Green"
    },
    {
      "x": -10,
      "y": 12,
      "z": 1,
      "name": "Rock_Stone_Brick_Smooth"
    },
    {
      "x": -10,
      "y": 13,
      "z": 1,
      "name": "Soil_Gravel",
      "support": 15
    },
    {
      "x": -10,
      "y": 14,
      "z": 1,
      "name": "Soil_Gravel",
      "support": 15
    },
    {
      "x": -10,
      "y": 15,
      "z": 1,
      "name": "Soil_Gravel",
      "support": 15
    },
    {
      "x": -10,
      "y": 16,
      "z": 1,
      "name": "Soil_Gravel",
      "support": 15
    },
    {
      "x": -10,
      "y": 17,
      "z": 1,
      "name": "Soil_Gravel",
      "support": 15
    },
    {
      "x": -10,
      "y": 22,
      "z": 1,
      "name": "Cloth_Block_Wool_Green",
      "rotation": 2
    },
    {
      "x": -10,
      "y": 22,
      "z": 2,
      "name": "Cloth_Block_Wool_Green",
      "rotation": 2
    },
    {
      "x": -10,
      "y": 22,
      "z": 3,
      "name": "Cloth_Block_Wool_Green",
      "rotation": 2
    },
    {
      "x": -10,
      "y": 22,
      "z": 4,
      "name": "Cloth_Block_Wool_Green",
      "rotation": 2
    },
    {
      "x": -10,
      "y": 13,
      "z": 5,
      "name": "Rock_Stone_Brick_Decorative"
    },
    {
      "x": -10,
      "y": 14,
      "z": 5,
      "name": "Soil_Gravel",
      "support": 15
    },
    {
      "x": -10,
      "y": 15,
      "z": 5,
      "name": "Soil_Gravel",
      "support": 15
    },
    {
      "x": -10,
      "y": 16,
      "z": 5,
      "name": "Soil_Gravel",
      "support": 15
    },
    {
      "x": -10,
      "y": 17,
      "z": 5,
      "name": "Soil_Gravel",
      "support": 15
    },
    {
      "x": -10,
      "y": 22,
      "z": 5,
      "name": "Cloth_Block_Wool_Green",
      "rotation": 2
    },
    {
      "x": -10,
      "y": 22,
      "z": 6,
      "name": "Cloth_Block_Wool_Pink"
    },
    {
      "x": -10,
      "y": 22,
      "z": 7,
      "name": "Cloth_Block_Wool_Pink"
    },
    {
      "x": -10,
      "y": 22,
      "z": 8,
      "name": "Cloth_Block_Wool_Pink"
    },
    {
      "x": -10,
      "y": 22,
      "z": 9,
      "name": "Cloth_Block_Wool_Pink"
    },
    {
      "x": -10,
      "y": 22,
      "z": 10,
      "name": "Cloth_Block_Wool_Pink"
    },
    {
      "x": -10,
      "y": 22,
      "z": 11,
      "name": "Cloth_Block_Wool_Pink"
    },
    {
      "x": -10,
      "y": 22,
      "z": 12,
      "name": "Cloth_Block_Wool_Pink"
    },
    {
      "x": -10,
      "y": 22,
      "z": 13,
      "name": "Cloth_Block_Wool_Pink"
    },
    {
      "x": -10,
      "y": 22,
      "z": 14,
      "name": "Cloth_Block_Wool_Pink"
    },
    {
      "x": -10,
      "y": 22,
      "z": 15,
      "name": "Cloth_Block_Wool_Pink"
    },
    {
      "x": -10,
      "y": 22,
      "z": 16,
      "name": "Cloth_Block_Wool_Pink"
    },
    {
      "x": -9,
      "y": 22,
      "z": -16,
      "name": "Cloth_Block_Wool_Pink",
      "rotation": 3
    },
    {
      "x": -9,
      "y": 12,
      "z": -7,
      "name": "Rock_Stone_Brick_Smooth"
    },
    {
      "x": -9,
      "y": 13,
      "z": -7,
      "name": "Rock_Stone_Brick_Smooth"
    },
    {
      "x": -9,
      "y": 14,
      "z": -7,
      "name": "Rock_Stone_Brick"
    },
    {
      "x": -9,
      "y": 15,
      "z": -7,
      "name": "Rock_Stone_Brick"
    },
    {
      "x": -9,
      "y": 16,
      "z": -7,
      "name": "Rock_Stone_Brick"
    },
    {
      "x": -9,
      "y": 17,
      "z": -7,
      "name": "Rock_Stone_Brick"
    },
    {
      "x": -9,
      "y": 18,
      "z": -7,
      "name": "Rock_Stone_Brick"
    },
    {
      "x": -9,
      "y": 13,
      "z": -6,
      "name": "Rock_Stone_Brick_Decorative"
    },
    {
      "x": -9,
      "y": 14,
      "z": -6,
      "name": "Soil_Gravel_Half",
      "support": 15,
      "rotation": 5
    },
    {
      "x": -9,
      "y": 15,
      "z": -6,
      "name": "Soil_Gravel_Half",
      "support": 15,
      "rotation": 5
    },
    {
      "x": -9,
      "y": 16,
      "z": -6,
      "name": "Soil_Gravel_Half",
      "support": 15,
      "rotation": 5
    },
    {
      "x": -9,
      "y": 17,
      "z": -6,
      "name": "Soil_Gravel_Half",
      "support": 15,
      "rotation": 5
    },
    {
      "x": -9,
      "y": 18,
      "z": -6,
      "name": "Rock_Stone_Brick"
    },
    {
      "x": -9,
      "y": 22,
      "z": -6,
      "name": "Cloth_Block_Wool_Pink",
      "rotation": 3
    },
    {
      "x": -9,
      "y": 12,
      "z": -5,
      "name": "Rock_Stone_Brick_Smooth"
    },
    {
      "x": -9,
      "y": 13,
      "z": -5,
      "name": "Rock_Stone_Brick_Decorative"
    },
    {
      "x": -9,
      "y": 14,
      "z": -5,
      "name": "Soil_Gravel_Half",
      "support": 15,
      "rotation": 5
    },
    {
      "x": -9,
      "y": 15,
      "z": -5,
      "name": "Soil_Gravel_Half",
      "support": 15,
      "rotation": 5
    },
    {
      "x": -9,
      "y": 16,
      "z": -5,
      "name": "Soil_Gravel_Half",
      "support": 15,
      "rotation": 5
    },
    {
      "x": -9,
      "y": 17,
      "z": -5,
      "name": "Soil_Gravel_Half",
      "support": 15,
      "rotation": 5
    },
    {
      "x": -9,
      "y": 18,
      "z": -5,
      "name": "Rock_Stone_Brick"
    },
    {
      "x": -9,
      "y": 22,
      "z": -5,
      "name": "Cloth_Block_Wool_Green",
      "rotation": 2
    },
    {
      "x": -9,
      "y": 12,
      "z": -4,
      "name": "Rock_Stone_Brick_Smooth"
    },
    {
      "x": -9,
      "y": 13,
      "z": -4,
      "name": "Rock_Stone_Brick_Decorative"
    },
    {
      "x": -9,
      "y": 14,
      "z": -4,
      "name": "Soil_Gravel_Half",
      "support": 15,
      "rotation": 5
    },
    {
      "x": -9,
      "y": 15,
      "z": -4,
      "name": "Soil_Gravel_Half",
      "support": 15,
      "rotation": 5
    },
    {
      "x": -9,
      "y": 16,
      "z": -4,
      "name": "Soil_Gravel_Half",
      "support": 15,
      "rotation": 5
    },
    {
      "x": -9,
      "y": 17,
      "z": -4,
      "name": "Soil_Gravel_Half",
      "support": 15,
      "rotation": 5
    },
    {
      "x": -9,
      "y": 18,
      "z": -4,
      "name": "Rock_Stone_Brick"
    },
    {
      "x": -9,
      "y": 12,
      "z": -3,
      "name": "Rock_Stone_Brick_Smooth"
    },
    {
      "x": -9,
      "y": 13,
      "z": -3,
      "name": "Rock_Stone_Brick_Smooth"
    },
    {
      "x": -9,
      "y": 14,
      "z": -3,
      "name": "Rock_Stone_Brick_Pillar_Base"
    },
    {
      "x": -9,
      "y": 15,
      "z": -3,
      "name": "Rock_Stone_Brick_Pillar_Middle"
    },
    {
      "x": -9,
      "y": 16,
      "z": -3,
      "name": "Rock_Stone_Brick_Pillar_Middle"
    },
    {
      "x": -9,
      "y": 17,
      "z": -3,
      "name": "Rock_Stone_Brick_Pillar_Base",
      "rotation": 8
    },
    {
      "x": -9,
      "y": 18,
      "z": -3,
      "name": "Rock_Stone_Brick"
    },
    {
      "x": -9,
      "y": 12,
      "z": -2,
      "name": "Rock_Stone_Brick_Smooth"
    },
    {
      "x": -9,
      "y": 13,
      "z": -2,
      "name": "Rock_Stone_Brick_Decorative"
    },
    {
      "x": -9,
      "y": 14,
      "z": -2,
      "name": "Soil_Gravel_Half",
      "support": 15,
      "rotation": 5
    },
    {
      "x": -9,
      "y": 15,
      "z": -2,
      "name": "Soil_Gravel_Half",
      "support": 15,
      "rotation": 5
    },
    {
      "x": -9,
      "y": 16,
      "z": -2,
      "name": "Soil_Gravel_Half",
      "support": 15,
      "rotation": 5
    },
    {
      "x": -9,
      "y": 17,
      "z": -2,
      "name": "Soil_Gravel_Half",
      "support": 15,
      "rotation": 5
    },
    {
      "x": -9,
      "y": 18,
      "z": -2,
      "name": "Rock_Stone_Brick"
    },
    {
      "x": -9,
      "y": 12,
      "z": -1,
      "name": "Rock_Stone_Brick_Smooth"
    },
    {
      "x": -9,
      "y": 13,
      "z": -1,
      "name": "Rock_Stone_Brick_Decorative"
    },
    {
      "x": -9,
      "y": 14,
      "z": -1,
      "name": "Soil_Gravel_Half",
      "support": 15,
      "rotation": 5
    },
    {
      "x": -9,
      "y": 15,
      "z": -1,
      "name": "Soil_Gravel_Half",
      "support": 15,
      "rotation": 5
    },
    {
      "x": -9,
      "y": 16,
      "z": -1,
      "name": "Soil_Gravel_Half",
      "support": 15,
      "rotation": 5
    },
    {
      "x": -9,
      "y": 17,
      "z": -1,
      "name": "Soil_Gravel_Half",
      "support": 15,
      "rotation": 5
    },
    {
      "x": -9,
      "y": 18,
      "z": -1,
      "name": "Rock_Stone_Brick"
    },
    {
      "x": -9,
      "y": 12,
      "z": 0,
      "name": "Rock_Stone_Brick_Smooth"
    },
    {
      "x": -9,
      "y": 13,
      "z": 0,
      "name": "Rock_Stone_Brick_Decorative"
    },
    {
      "x": -9,
      "y": 14,
      "z": 0,
      "name": "Soil_Gravel_Half",
      "support": 15,
      "rotation": 5
    },
    {
      "x": -9,
      "y": 15,
      "z": 0,
      "name": "Soil_Gravel_Half",
      "support": 15,
      "rotation": 5
    },
    {
      "x": -9,
      "y": 16,
      "z": 0,
      "name": "Soil_Gravel_Half",
      "support": 15,
      "rotation": 5
    },
    {
      "x": -9,
      "y": 17,
      "z": 0,
      "name": "Soil_Gravel_Half",
      "support": 15,
      "rotation": 5
    },
    {
      "x": -9,
      "y": 18,
      "z": 0,
      "name": "Rock_Stone_Brick"
    },
    {
      "x": -9,
      "y": 12,
      "z": 1,
      "name": "Rock_Stone_Brick_Smooth"
    },
    {
      "x": -9,
      "y": 13,
      "z": 1,
      "name": "Rock_Stone_Brick_Smooth"
    },
    {
      "x": -9,
      "y": 14,
      "z": 1,
      "name": "Rock_Stone_Brick_Pillar_Base"
    },
    {
      "x": -9,
      "y": 15,
      "z": 1,
      "name": "Rock_Stone_Brick_Pillar_Middle"
    },
    {
      "x": -9,
      "y": 16,
      "z": 1,
      "name": "Rock_Stone_Brick_Pillar_Middle"
    },
    {
      "x": -9,
      "y": 17,
      "z": 1,
      "name": "Rock_Stone_Brick_Pillar_Base",
      "rotation": 8
    },
    {
      "x": -9,
      "y": 18,
      "z": 1,
      "name": "Rock_Stone_Brick"
    },
    {
      "x": -9,
      "y": 12,
      "z": 2,
      "name": "Rock_Stone_Brick_Smooth"
    },
    {
      "x": -9,
      "y": 13,
      "z": 2,
      "name": "Rock_Stone_Brick_Decorative"
    },
    {
      "x": -9,
      "y": 14,
      "z": 2,
      "name": "Soil_Gravel_Half",
      "support": 15,
      "rotation": 5
    },
    {
      "x": -9,
      "y": 15,
      "z": 2,
      "name": "Soil_Gravel_Half",
      "support": 15,
      "rotation": 5
    },
    {
      "x": -9,
      "y": 16,
      "z": 2,
      "name": "Soil_Gravel_Half",
      "support": 15,
      "rotation": 5
    },
    {
      "x": -9,
      "y": 17,
      "z": 2,
      "name": "Soil_Gravel_Half",
      "support": 15,
      "rotation": 5
    },
    {
      "x": -9,
      "y": 18,
      "z": 2,
      "name": "Rock_Stone_Brick"
    },
    {
      "x": -9,
      "y": 12,
      "z": 3,
      "name": "Rock_Stone_Brick_Smooth"
    },
    {
      "x": -9,
      "y": 13,
      "z": 3,
      "name": "Rock_Stone_Brick_Decorative"
    },
    {
      "x": -9,
      "y": 14,
      "z": 3,
      "name": "Soil_Gravel_Half",
      "support": 15,
      "rotation": 5
    },
    {
      "x": -9,
      "y": 15,
      "z": 3,
      "name": "Soil_Gravel_Half",
      "support": 15,
      "rotation": 5
    },
    {
      "x": -9,
      "y": 16,
      "z": 3,
      "name": "Soil_Gravel_Half",
      "support": 15,
      "rotation": 5
    },
    {
      "x": -9,
      "y": 17,
      "z": 3,
      "name": "Soil_Gravel_Half",
      "support": 15,
      "rotation": 5
    },
    {
      "x": -9,
      "y": 18,
      "z": 3,
      "name": "Rock_Stone_Brick"
    },
    {
      "x": -9,
      "y": 12,
      "z": 4,
      "name": "Rock_Stone_Brick_Smooth"
    },
    {
      "x": -9,
      "y": 13,
      "z": 4,
      "name": "Rock_Stone_Brick_Decorative"
    },
    {
      "x": -9,
      "y": 14,
      "z": 4,
      "name": "Soil_Gravel_Half",
      "support": 15,
      "rotation": 5
    },
    {
      "x": -9,
      "y": 15,
      "z": 4,
      "name": "Soil_Gravel_Half",
      "support": 15,
      "rotation": 5
    },
    {
      "x": -9,
      "y": 16,
      "z": 4,
      "name": "Soil_Gravel_Half",
      "support": 15,
      "rotation": 5
    },
    {
      "x": -9,
      "y": 17,
      "z": 4,
      "name": "Soil_Gravel_Half",
      "support": 15,
      "rotation": 5
    },
    {
      "x": -9,
      "y": 18,
      "z": 4,
      "name": "Rock_Stone_Brick"
    },
    {
      "x": -9,
      "y": 12,
      "z": 5,
      "name": "Rock_Stone_Brick_Smooth"
    },
    {
      "x": -9,
      "y": 13,
      "z": 5,
      "name": "Rock_Stone_Brick_Smooth"
    },
    {
      "x": -9,
      "y": 14,
      "z": 5,
      "name": "Rock_Stone_Brick_Pillar_Base"
    },
    {
      "x": -9,
      "y": 15,
      "z": 5,
      "name": "Rock_Stone_Brick_Pillar_Middle"
    },
    {
      "x": -9,
      "y": 16,
      "z": 5,
      "name": "Rock_Stone_Brick_Pillar_Middle"
    },
    {
      "x": -9,
      "y": 17,
      "z": 5,
      "name": "Rock_Stone_Brick_Pillar_Base",
      "rotation": 8
    },
    {
      "x": -9,
      "y": 18,
      "z": 5,
      "name": "Rock_Stone_Brick"
    },
    {
      "x": -9,
      "y": 22,
      "z": 5,
      "name": "Cloth_Block_Wool_Green",
      "rotation": 2
    },
    {
      "x": -9,
      "y": 12,
      "z": 6,
      "name": "Rock_Stone_Brick_Smooth"
    },
    {
      "x": -9,
      "y": 13,
      "z": 6,
      "name": "Rock_Stone_Brick_Decorative"
    },
    {
      "x": -9,
      "y": 14,
      "z": 6,
      "name": "Rock_Stone_Brick"
    },
    {
      "x": -9,
      "y": 15,
      "z": 6,
      "name": "Rock_Stone_Brick"
    },
    {
      "x": -9,
      "y": 16,
      "z": 6,
      "name": "Rock_Stone_Brick"
    },
    {
      "x": -9,
      "y": 17,
      "z": 6,
      "name": "Rock_Stone_Brick"
    },
    {
      "x": -9,
      "y": 22,
      "z": 6,
      "name": "Cloth_Block_Wool_Pink"
    },
    {
      "x": -9,
      "y": 12,
      "z": 7,
      "name": "Rock_Stone_Brick_Smooth"
    },
    {
      "x": -9,
      "y": 14,
      "z": 9,
      "name": "Rock_Stone_Brick"
    },
    {
      "x": -9,
      "y": 15,
      "z": 9,
      "name": "Rock_Stone_Brick"
    },
    {
      "x": -9,
      "y": 16,
      "z": 9,
      "name": "Rock_Stone_Brick"
    },
    {
      "x": -9,
      "y": 17,
      "z": 9,
      "name": "Rock_Stone_Brick"
    },
    {
      "x": -9,
      "y": 18,
      "z": 9,
      "name": "Rock_Stone_Brick"
    },
    {
      "x": -9,
      "y": 14,
      "z": 13,
      "name": "Rock_Stone_Brick"
    },
    {
      "x": -9,
      "y": 15,
      "z": 13,
      "name": "Rock_Stone_Brick"
    },
    {
      "x": -9,
      "y": 16,
      "z": 13,
      "name": "Rock_Stone_Brick"
    },
    {
      "x": -9,
      "y": 17,
      "z": 13,
      "name": "Rock_Stone_Brick"
    },
    {
      "x": -9,
      "y": 18,
      "z": 13,
      "name": "Rock_Stone_Brick"
    },
    {
      "x": -9,
      "y": 22,
      "z": 16,
      "name": "Cloth_Block_Wool_Pink"
    },
    {
      "x": -8,
      "y": 15,
      "z": -16,
      "name": "Rock_Stone_Brick",
      "rotation": 1
    },
    {
      "x": -8,
      "y": 16,
      "z": -16,
      "name": "Rock_Stone_Brick_Decorative",
      "rotation": 1
    },
    {
      "x": -8,
      "y": 17,
      "z": -16,
      "name": "Soil_Gravel",
      "rotation": 1
    },
    {
      "x": -8,
      "y": 18,
      "z": -16,
      "name": "Soil_Gravel",
      "rotation": 1
    },
    {
      "x": -8,
      "y": 19,
      "z": -16,
      "name": "Soil_Gravel",
      "rotation": 1
    },
    {
      "x": -8,
      "y": 20,
      "z": -16,
      "name": "Soil_Gravel",
      "rotation": 1
    },
    {
      "x": -8,
      "y": 21,
      "z": -16,
      "name": "Rock_Stone_Brick_Smooth",
      "rotation": 1
    },
    {
      "x": -8,
      "y": 22,
      "z": -16,
      "name": "Cloth_Block_Wool_Pink",
      "rotation": 3
    },
    {
      "x": -8,
      "y": 15,
      "z": -15,
      "name": "Rock_Stone_Brick",
      "rotation": 1
    },
    {
      "x": -8,
      "y": 16,
      "z": -15,
      "name": "Rock_Stone_Brick_Decorative",
      "rotation": 2
    },
    {
      "x": -8,
      "y": 17,
      "z": -15,
      "name": "Soil_Gravel",
      "rotation": 2
    },
    {
      "x": -8,
      "y": 18,
      "z": -15,
      "name": "Soil_Gravel",
      "rotation": 2
    },
    {
      "x": -8,
      "y": 19,
      "z": -15,
      "name": "Soil_Gravel",
      "rotation": 2
    },
    {
      "x": -8,
      "y": 20,
      "z": -15,
      "name": "Soil_Gravel",
      "rotation": 2
    },
    {
      "x": -8,
      "y": 21,
      "z": -15,
      "name": "Rock_Stone_Brick_Smooth",
      "rotation": 2
    },
    {
      "x": -8,
      "y": 15,
      "z": -14,
      "name": "Rock_Stone_Brick",
      "rotation": 1
    },
    {
      "x": -8,
      "y": 16,
      "z": -14,
      "name": "Rock_Stone_Brick_Decorative"
    },
    {
      "x": -8,
      "y": 17,
      "z": -14,
      "name": "Soil_Gravel"
    },
    {
      "x": -8,
      "y": 18,
      "z": -14,
      "name": "Soil_Gravel"
    },
    {
      "x": -8,
      "y": 19,
      "z": -14,
      "name": "Soil_Gravel"
    },
    {
      "x": -8,
      "y": 20,
      "z": -14,
      "name": "Soil_Gravel"
    },
    {
      "x": -8,
      "y": 21,
      "z": -14,
      "name": "Rock_Stone_Brick_Smooth"
    },
    {
      "x": -8,
      "y": 15,
      "z": -13,
      "name": "Rock_Stone_Brick",
      "rotation": 1
    },
    {
      "x": -8,
      "y": 16,
      "z": -13,
      "name": "Rock_Stone_Brick_Decorative"
    },
    {
      "x": -8,
      "y": 17,
      "z": -13,
      "name": "Soil_Gravel",
      "rotation": 3
    },
    {
      "x": -8,
      "y": 18,
      "z": -13,
      "name": "Soil_Gravel",
      "rotation": 3
    },
    {
      "x": -8,
      "y": 19,
      "z": -13,
      "name": "Soil_Gravel",
      "rotation": 3
    },
    {
      "x": -8,
      "y": 20,
      "z": -13,
      "name": "Soil_Gravel",
      "rotation": 3
    },
    {
      "x": -8,
      "y": 21,
      "z": -13,
      "name": "Rock_Stone_Brick_Smooth"
    },
    {
      "x": -8,
      "y": 15,
      "z": -12,
      "name": "Rock_Stone_Brick",
      "rotation": 1
    },
    {
      "x": -8,
      "y": 16,
      "z": -12,
      "name": "Rock_Stone_Brick_Decorative",
      "rotation": 3
    },
    {
      "x": -8,
      "y": 17,
      "z": -12,
      "name": "Soil_Gravel",
      "rotation": 3
    },
    {
      "x": -8,
      "y": 18,
      "z": -12,
      "name": "Soil_Gravel",
      "rotation": 3
    },
    {
      "x": -8,
      "y": 19,
      "z": -12,
      "name": "Soil_Gravel",
      "rotation": 3
    },
    {
      "x": -8,
      "y": 20,
      "z": -12,
      "name": "Soil_Gravel",
      "rotation": 3
    },
    {
      "x": -8,
      "y": 21,
      "z": -12,
      "name": "Rock_Stone_Brick_Smooth"
    },
    {
      "x": -8,
      "y": 15,
      "z": -11,
      "name": "Rock_Stone_Brick",
      "rotation": 1
    },
    {
      "x": -8,
      "y": 16,
      "z": -11,
      "name": "Rock_Stone_Brick_Decorative",
      "rotation": 3
    },
    {
      "x": -8,
      "y": 17,
      "z": -11,
      "name": "Soil_Gravel",
      "rotation": 3
    },
    {
      "x": -8,
      "y": 18,
      "z": -11,
      "name": "Soil_Gravel",
      "rotation": 3
    },
    {
      "x": -8,
      "y": 19,
      "z": -11,
      "name": "Soil_Gravel",
      "rotation": 3
    },
    {
      "x": -8,
      "y": 20,
      "z": -11,
      "name": "Soil_Gravel",
      "rotation": 3
    },
    {
      "x": -8,
      "y": 21,
      "z": -11,
      "name": "Rock_Stone_Brick_Smooth"
    },
    {
      "x": -8,
      "y": 15,
      "z": -10,
      "name": "Rock_Stone_Brick",
      "rotation": 1
    },
    {
      "x": -8,
      "y": 16,
      "z": -10,
      "name": "Rock_Stone_Brick_Decorative",
      "rotation": 3
    },
    {
      "x": -8,
      "y": 17,
      "z": -10,
      "name": "Soil_Gravel",
      "rotation": 3
    },
    {
      "x": -8,
      "y": 18,
      "z": -10,
      "name": "Soil_Gravel",
      "rotation": 3
    },
    {
      "x": -8,
      "y": 19,
      "z": -10,
      "name": "Soil_Gravel",
      "rotation": 3
    },
    {
      "x": -8,
      "y": 20,
      "z": -10,
      "name": "Soil_Gravel",
      "rotation": 3
    },
    {
      "x": -8,
      "y": 21,
      "z": -10,
      "name": "Rock_Stone_Brick_Smooth",
      "rotation": 2
    },
    {
      "x": -8,
      "y": 12,
      "z": -9,
      "name": "Rock_Stone_Brick",
      "rotation": 1
    },
    {
      "x": -8,
      "y": 13,
      "z": -9,
      "name": "Rock_Stone_Brick_Decorative",
      "rotation": 3
    },
    {
      "x": -8,
      "y": 14,
      "z": -9,
      "name": "Soil_Gravel",
      "rotation": 3
    },
    {
      "x": -8,
      "y": 15,
      "z": -9,
      "name": "Soil_Gravel",
      "rotation": 3
    },
    {
      "x": -8,
      "y": 16,
      "z": -9,
      "name": "Soil_Gravel",
      "rotation": 3
    },
    {
      "x": -8,
      "y": 17,
      "z": -9,
      "name": "Soil_Gravel",
      "rotation": 3
    },
    {
      "x": -8,
      "y": 18,
      "z": -9,
      "name": "Rock_Stone_Brick_Smooth",
      "rotation": 2
    },
    {
      "x": -8,
      "y": 12,
      "z": -7,
      "name": "Rock_Stone_Brick_Smooth"
    },
    {
      "x": -8,
      "y": 13,
      "z": -7,
      "name": "Rock_Stone_Brick_Decorative"
    },
    {
      "x": -8,
      "y": 14,
      "z": -7,
      "name": "Soil_Gravel_Half",
      "rotation": 4
    },
    {
      "x": -8,
      "y": 15,
      "z": -7,
      "name": "Soil_Gravel_Half",
      "rotation": 4
    },
    {
      "x": -8,
      "y": 16,
      "z": -7,
      "name": "Soil_Gravel_Half",
      "rotation": 4
    },
    {
      "x": -8,
      "y": 17,
      "z": -7,
      "name": "Soil_Gravel_Half",
      "rotation": 4
    },
    {
      "x": -8,
      "y": 18,
      "z": -7,
      "name": "Rock_Stone_Brick"
    },
    {
      "x": -8,
      "y": 12,
      "z": -6,
      "name": "Rock_Stone_Brick_Smooth"
    },
    {
      "x": -8,
      "y": 18,
      "z": -6,
      "name": "Rock_Stone_Brick_Smooth_Half",
      "rotation": 8
    },
    {
      "x": -8,
      "y": 22,
      "z": -6,
      "name": "Cloth_Block_Wool_Pink",
      "rotation": 3
    },
    {
      "x": -8,
      "y": 12,
      "z": -5,
      "name": "Rock_Stone_Brick_Smooth"
    },
    {
      "x": -8,
      "y": 18,
      "z": -5,
      "name": "Rock_Stone_Brick_Smooth_Half",
      "rotation": 8
    },
    {
      "x": -8,
      "y": 22,
      "z": -5,
      "name": "Cloth_Block_Wool_Green",
      "rotation": 2
    },
    {
      "x": -8,
      "y": 12,
      "z": -4,
      "name": "Rock_Stone_Brick_Smooth"
    },
    {
      "x": -8,
      "y": 18,
      "z": -4,
      "name": "Rock_Stone_Brick_Smooth_Half",
      "rotation": 8
    },
    {
      "x": -8,
      "y": 12,
      "z": -3,
      "name": "Rock_Stone_Brick_Smooth"
    },
    {
      "x": -8,
      "y": 18,
      "z": -3,
      "name": "Rock_Stone_Brick"
    },
    {
      "x": -8,
      "y": 12,
      "z": -2,
      "name": "Rock_Stone_Brick_Smooth"
    },
    {
      "x": -8,
      "y": 18,
      "z": -2,
      "name": "Rock_Stone_Brick_Smooth_Half",
      "rotation": 8
    },
    {
      "x": -8,
      "y": 12,
      "z": -1,
      "name": "Rock_Stone_Brick_Smooth"
    },
    {
      "x": -8,
      "y": 18,
      "z": -1,
      "name": "Rock_Stone_Brick_Smooth_Half",
      "rotation": 8
    },
    {
      "x": -8,
      "y": 12,
      "z": 0,
      "name": "Rock_Stone_Brick_Smooth"
    },
    {
      "x": -8,
      "y": 18,
      "z": 0,
      "name": "Rock_Stone_Brick_Smooth_Half",
      "rotation": 8
    },
    {
      "x": -8,
      "y": 12,
      "z": 1,
      "name": "Rock_Stone_Brick_Smooth"
    },
    {
      "x": -8,
      "y": 18,
      "z": 1,
      "name": "Rock_Stone_Brick"
    },
    {
      "x": -8,
      "y": 12,
      "z": 2,
      "name": "Rock_Stone_Brick_Smooth"
    },
    {
      "x": -8,
      "y": 18,
      "z": 2,
      "name": "Rock_Stone_Brick_Smooth_Half",
      "rotation": 8
    },
    {
      "x": -8,
      "y": 12,
      "z": 3,
      "name": "Rock_Stone_Brick_Smooth"
    },
    {
      "x": -8,
      "y": 18,
      "z": 3,
      "name": "Rock_Stone_Brick_Smooth_Half",
      "rotation": 8
    },
    {
      "x": -8,
      "y": 12,
      "z": 4,
      "name": "Rock_Stone_Brick_Smooth"
    },
    {
      "x": -8,
      "y": 18,
      "z": 4,
      "name": "Rock_Stone_Brick_Smooth_Half",
      "rotation": 8
    },
    {
      "x": -8,
      "y": 12,
      "z": 5,
      "name": "Rock_Stone_Brick_Smooth"
    },
    {
      "x": -8,
      "y": 18,
      "z": 5,
      "name": "Rock_Stone_Brick"
    },
    {
      "x": -8,
      "y": 22,
      "z": 5,
      "name": "Cloth_Block_Wool_Green",
      "rotation": 2
    },
    {
      "x": -8,
      "y": 12,
      "z": 6,
      "name": "Rock_Stone_Brick_Smooth"
    },
    {
      "x": -8,
      "y": 13,
      "z": 6,
      "name": "Rock_Stone_Brick_Decorative"
    },
    {
      "x": -8,
      "y": 14,
      "z": 6,
      "name": "Soil_Gravel_Half",
      "support": 15,
      "rotation": 6
    },
    {
      "x": -8,
      "y": 15,
      "z": 6,
      "name": "Soil_Gravel_Half",
      "support": 15,
      "rotation": 6
    },
    {
      "x": -8,
      "y": 16,
      "z": 6,
      "name": "Soil_Gravel_Half",
      "support": 15,
      "rotation": 6
    },
    {
      "x": -8,
      "y": 17,
      "z": 6,
      "name": "Soil_Gravel_Half",
      "support": 15,
      "rotation": 6
    },
    {
      "x": -8,
      "y": 18,
      "z": 6,
      "name": "Rock_Stone_Brick"
    },
    {
      "x": -8,
      "y": 22,
      "z": 6,
      "name": "Cloth_Block_Wool_Pink"
    },
    {
      "x": -8,
      "y": 12,
      "z": 7,
      "name": "Rock_Stone_Brick_Smooth"
    },
    {
      "x": -8,
      "y": 14,
      "z": 8,
      "name": "Rock_Stone_Brick"
    },
    {
      "x": -8,
      "y": 15,
      "z": 8,
      "name": "Rock_Stone_Brick"
    },
    {
      "x": -8,
      "y": 16,
      "z": 8,
      "name": "Rock_Stone_Brick"
    },
    {
      "x": -8,
      "y": 17,
      "z": 8,
      "name": "Rock_Stone_Brick"
    },
    {
      "x": -8,
      "y": 18,
      "z": 8,
      "name": "Rock_Stone_Brick"
    },
    {
      "x": -8,
      "y": 14,
      "z": 9,
      "name": "Rock_Stone_Brick_Smooth"
    },
    {
      "x": -8,
      "y": 15,
      "z": 9,
      "name": "Rock_Stone_Brick_Pillar_Base"
    },
    {
      "x": -8,
      "y": 16,
      "z": 9,
      "name": "Rock_Stone_Brick_Pillar_Middle"
    },
    {
      "x": -8,
      "y": 17,
      "z": 9,
      "name": "Rock_Stone_Brick_Pillar_Middle"
    },
    {
      "x": -8,
      "y": 18,
      "z": 9,
      "name": "Rock_Stone_Brick_Pillar_Base",
      "rotation": 8
    },
    {
      "x": -8,
      "y": 19,
      "z": 9,
      "name": "Rock_Stone_Brick"
    },
    {
      "x": -8,
      "y": 14,
      "z": 10,
      "name": "Rock_Stone_Brick_Decorative"
    },
    {
      "x": -8,
      "y": 15,
      "z": 10,
      "name": "Soil_Gravel_Half",
      "support": 15,
      "rotation": 5
    },
    {
      "x": -8,
      "y": 16,
      "z": 10,
      "name": "Soil_Gravel_Half",
      "support": 15,
      "rotation": 5
    },
    {
      "x": -8,
      "y": 17,
      "z": 10,
      "name": "Soil_Gravel_Half",
      "support": 15,
      "rotation": 5
    },
    {
      "x": -8,
      "y": 18,
      "z": 10,
      "name": "Soil_Gravel_Half",
      "support": 15,
      "rotation": 5
    },
    {
      "x": -8,
      "y": 19,
      "z": 10,
      "name": "Rock_Stone_Brick"
    },
    {
      "x": -8,
      "y": 14,
      "z": 11,
      "name": "Rock_Stone_Brick_Decorative"
    },
    {
      "x": -8,
      "y": 15,
      "z": 11,
      "name": "Soil_Gravel_Half",
      "support": 15,
      "rotation": 5
    },
    {
      "x": -8,
      "y": 16,
      "z": 11,
      "name": "Soil_Gravel_Half",
      "support": 15,
      "rotation": 5
    },
    {
      "x": -8,
      "y": 17,
      "z": 11,
      "name": "Soil_Gravel_Half",
      "support": 15,
      "rotation": 5
    },
    {
      "x": -8,
      "y": 18,
      "z": 11,
      "name": "Soil_Gravel_Half",
      "support": 15,
      "rotation": 5
    },
    {
      "x": -8,
      "y": 19,
      "z": 11,
      "name": "Rock_Stone_Brick"
    },
    {
      "x": -8,
      "y": 14,
      "z": 12,
      "name": "Rock_Stone_Brick_Decorative"
    },
    {
      "x": -8,
      "y": 15,
      "z": 12,
      "name": "Soil_Gravel_Half",
      "support": 15,
      "rotation": 5
    },
    {
      "x": -8,
      "y": 16,
      "z": 12,
      "name": "Soil_Gravel_Half",
      "support": 15,
      "rotation": 5
    },
    {
      "x": -8,
      "y": 17,
      "z": 12,
      "name": "Soil_Gravel_Half",
      "support": 15,
      "rotation": 5
    },
    {
      "x": -8,
      "y": 18,
      "z": 12,
      "name": "Soil_Gravel_Half",
      "support": 15,
      "rotation": 5
    },
    {
      "x": -8,
      "y": 19,
      "z": 12,
      "name": "Rock_Stone_Brick"
    },
    {
      "x": -8,
      "y": 14,
      "z": 13,
      "name": "Rock_Stone_Brick_Smooth"
    },
    {
      "x": -8,
      "y": 15,
      "z": 13,
      "name": "Rock_Stone_Brick_Pillar_Base"
    },
    {
      "x": -8,
      "y": 16,
      "z": 13,
      "name": "Rock_Stone_Brick_Pillar_Middle"
    },
    {
      "x": -8,
      "y": 17,
      "z": 13,
      "name": "Rock_Stone_Brick_Pillar_Middle",
      "rotation": 8
    },
    {
      "x": -8,
      "y": 18,
      "z": 13,
      "name": "Rock_Stone_Brick_Pillar_Base",
      "rotation": 8
    },
    {
      "x": -8,
      "y": 19,
      "z": 13,
      "name": "Rock_Stone_Brick"
    },
    {
      "x": -8,
      "y": 15,
      "z": 14,
      "name": "Rock_Stone_Brick"
    },
    {
      "x": -8,
      "y": 16,
      "z": 14,
      "name": "Rock_Stone_Brick"
    },
    {
      "x": -8,
      "y": 17,
      "z": 14,
      "name": "Rock_Stone_Brick"
    },
    {
      "x": -8,
      "y": 18,
      "z": 14,
      "name": "Rock_Stone_Brick"
    },
    {
      "x": -8,
      "y": 19,
      "z": 14,
      "name": "Rock_Stone_Brick"
    },
    {
      "x": -8,
      "y": 22,
      "z": 16,
      "name": "Cloth_Block_Wool_Pink"
    },
    {
      "x": -7,
      "y": 15,
      "z": -16,
      "name": "Rock_Stone_Brick",
      "rotation": 2
    },
    {
      "x": -7,
      "y": 16,
      "z": -16,
      "name": "Rock_Stone_Brick"
    },
    {
      "x": -7,
      "y": 17,
      "z": -16,
      "name": "Rock_Stone_Brick"
    },
    {
      "x": -7,
      "y": 18,
      "z": -16,
      "name": "Rock_Stone_Brick"
    },
    {
      "x": -7,
      "y": 19,
      "z": -16,
      "name": "Rock_Stone_Brick"
    },
    {
      "x": -7,
      "y": 20,
      "z": -16,
      "name": "Rock_Stone_Brick_Decorative"
    },
    {
      "x": -7,
      "y": 21,
      "z": -16,
      "name": "Rock_Stone_Brick",
      "rotation": 1
    },
    {
      "x": -7,
      "y": 22,
      "z": -16,
      "name": "Cloth_Block_Wool_Pink",
      "rotation": 3
    },
    {
      "x": -7,
      "y": 15,
      "z": -15,
      "name": "Rock_Stone_Brick",
      "rotation": 2
    },
    {
      "x": -7,
      "y": 16,
      "z": -15,
      "name": "Rock_Stone_Brick_Decorative"
    },
    {
      "x": -7,
      "y": 17,
      "z": -15,
      "name": "Soil_Gravel_Half",
      "support": 15,
      "rotation": 5
    },
    {
      "x": -7,
      "y": 18,
      "z": -15,
      "name": "Soil_Gravel_Half",
      "rotation": 5
    },
    {
      "x": -7,
      "y": 19,
      "z": -15,
      "name": "Soil_Gravel_Half",
      "rotation": 5
    },
    {
      "x": -7,
      "y": 20,
      "z": -15,
      "name": "Soil_Gravel_Half",
      "rotation": 5
    },
    {
      "x": -7,
      "y": 21,
      "z": -15,
      "name": "Rock_Stone_Brick",
      "rotation": 2
    },
    {
      "x": -7,
      "y": 15,
      "z": -14,
      "name": "Rock_Stone_Brick",
      "rotation": 2
    },
    {
      "x": -7,
      "y": 16,
      "z": -14,
      "name": "Rock_Stone_Brick_Decorative",
      "rotation": 1
    },
    {
      "x": -7,
      "y": 17,
      "z": -14,
      "name": "Soil_Gravel_Half",
      "rotation": 5
    },
    {
      "x": -7,
      "y": 18,
      "z": -14,
      "name": "Soil_Gravel_Half",
      "rotation": 5
    },
    {
      "x": -7,
      "y": 19,
      "z": -14,
      "name": "Soil_Gravel_Half",
      "rotation": 5
    },
    {
      "x": -7,
      "y": 20,
      "z": -14,
      "name": "Soil_Gravel_Half",
      "rotation": 5
    },
    {
      "x": -7,
      "y": 21,
      "z": -14,
      "name": "Rock_Stone_Brick",
      "rotation": 2
    },
    {
      "x": -7,
      "y": 15,
      "z": -13,
      "name": "Rock_Stone_Brick",
      "rotation": 1
    },
    {
      "x": -7,
      "y": 16,
      "z": -13,
      "name": "Rock_Stone_Brick_Decorative",
      "rotation": 1
    },
    {
      "x": -7,
      "y": 17,
      "z": -13,
      "name": "Soil_Gravel_Half",
      "rotation": 5
    },
    {
      "x": -7,
      "y": 18,
      "z": -13,
      "name": "Soil_Gravel_Half",
      "rotation": 5
    },
    {
      "x": -7,
      "y": 19,
      "z": -13,
      "name": "Soil_Gravel_Half",
      "rotation": 5
    },
    {
      "x": -7,
      "y": 20,
      "z": -13,
      "name": "Soil_Gravel_Half",
      "rotation": 5
    },
    {
      "x": -7,
      "y": 21,
      "z": -13,
      "name": "Rock_Stone_Brick",
      "rotation": 2
    },
    {
      "x": -7,
      "y": 15,
      "z": -12,
      "name": "Rock_Stone_Brick_Decorative",
      "rotation": 2
    },
    {
      "x": -7,
      "y": 16,
      "z": -12,
      "name": "Rock_Stone_Brick_Smooth"
    },
    {
      "x": -7,
      "y": 17,
      "z": -12,
      "name": "Rock_Stone_Brick_Pillar_Base",
      "rotation": 1
    },
    {
      "x": -7,
      "y": 18,
      "z": -12,
      "name": "Rock_Stone_Brick_Pillar_Middle",
      "rotation": 1
    },
    {
      "x": -7,
      "y": 19,
      "z": -12,
      "name": "Rock_Stone_Brick_Pillar_Middle",
      "rotation": 1
    },
    {
      "x": -7,
      "y": 20,
      "z": -12,
      "name": "Rock_Stone_Brick_Pillar_Base",
      "rotation": 9
    },
    {
      "x": -7,
      "y": 21,
      "z": -12,
      "name": "Rock_Stone_Brick",
      "rotation": 3
    },
    {
      "x": -7,
      "y": 14,
      "z": -11,
      "name": "Rock_Stone_Brick_Decorative"
    },
    {
      "x": -7,
      "y": 15,
      "z": -11,
      "name": "Rock_Stone_Brick_Decorative",
      "rotation": 2
    },
    {
      "x": -7,
      "y": 16,
      "z": -11,
      "name": "Soil_Gravel_Half",
      "rotation": 5
    },
    {
      "x": -7,
      "y": 17,
      "z": -11,
      "name": "Soil_Gravel_Half",
      "rotation": 5
    },
    {
      "x": -7,
      "y": 18,
      "z": -11,
      "name": "Soil_Gravel_Half",
      "rotation": 5
    },
    {
      "x": -7,
      "y": 19,
      "z": -11,
      "name": "Soil_Gravel_Half",
      "rotation": 5
    },
    {
      "x": -7,
      "y": 20,
      "z": -11,
      "name": "*Rock_Stone_Brick_Stairs_State_Definitions_Inverted_Corner_Right",
      "rotation": 11
    },
    {
      "x": -7,
      "y": 21,
      "z": -11,
      "name": "Rock_Stone_Brick",
      "rotation": 2
    },
    {
      "x": -7,
      "y": 13,
      "z": -10,
      "name": "Rock_Stone_Brick_Decorative",
      "rotation": 2
    },
    {
      "x": -7,
      "y": 14,
      "z": -10,
      "name": "Rock_Stone_Brick_Decorative",
      "rotation": 2
    },
    {
      "x": -7,
      "y": 15,
      "z": -10,
      "name": "Soil_Gravel_Half",
      "rotation": 5
    },
    {
      "x": -7,
      "y": 16,
      "z": -10,
      "name": "Soil_Gravel_Half",
      "rotation": 5
    },
    {
      "x": -7,
      "y": 17,
      "z": -10,
      "name": "Soil_Gravel_Half",
      "rotation": 5
    },
    {
      "x": -7,
      "y": 18,
      "z": -10,
      "name": "Soil_Gravel_Half",
      "rotation": 5
    },
    {
      "x": -7,
      "y": 19,
      "z": -10,
      "name": "*Rock_Stone_Brick_Stairs_State_Definitions_Inverted_Corner_Right",
      "rotation": 11
    },
    {
      "x": -7,
      "y": 20,
      "z": -10,
      "name": "Rock_Stone_Brick",
      "rotation": 2
    },
    {
      "x": -7,
      "y": 21,
      "z": -10,
      "name": "Rock_Stone_Brick",
      "rotation": 2
    },
    {
      "x": -7,
      "y": 12,
      "z": -9,
      "name": "Rock_Stone_Brick",
      "rotation": 2
    },
    {
      "x": -7,
      "y": 13,
      "z": -9,
      "name": "Rock_Stone_Brick_Smooth"
    },
    {
      "x": -7,
      "y": 14,
      "z": -9,
      "name": "Rock_Stone_Brick_Pillar_Base",
      "rotation": 2
    },
    {
      "x": -7,
      "y": 15,
      "z": -9,
      "name": "Rock_Stone_Brick_Pillar_Middle",
      "rotation": 10
    },
    {
      "x": -7,
      "y": 16,
      "z": -9,
      "name": "Rock_Stone_Brick_Pillar_Middle",
      "rotation": 10
    },
    {
      "x": -7,
      "y": 17,
      "z": -9,
      "name": "Rock_Stone_Brick_Pillar_Base",
      "rotation": 10
    },
    {
      "x": -7,
      "y": 18,
      "z": -9,
      "name": "Rock_Stone_Brick_Smooth",
      "rotation": 2
    },
    {
      "x": -7,
      "y": 13,
      "z": -8,
      "name": "Rock_Stone_Brick_Decorative"
    },
    {
      "x": -7,
      "y": 14,
      "z": -8,
      "name": "Soil_Gravel_Half",
      "rotation": 5
    },
    {
      "x": -7,
      "y": 15,
      "z": -8,
      "name": "Soil_Gravel_Half",
      "rotation": 5
    },
    {
      "x": -7,
      "y": 16,
      "z": -8,
      "name": "Soil_Gravel_Half",
      "rotation": 5
    },
    {
      "x": -7,
      "y": 17,
      "z": -8,
      "name": "Rock_Stone_Brick_Stairs",
      "rotation": 11
    },
    {
      "x": -7,
      "y": 18,
      "z": -8,
      "name": "Rock_Stone_Brick"
    },
    {
      "x": -7,
      "y": 12,
      "z": -7,
      "name": "Rock_Stone_Brick_Smooth"
    },
    {
      "x": -7,
      "y": 13,
      "z": -7,
      "name": "Rock_Stone_Brick_Decorative"
    },
    {
      "x": -7,
      "y": 14,
      "z": -7,
      "name": "Rock_Stone_Brick"
    },
    {
      "x": -7,
      "y": 15,
      "z": -7,
      "name": "Rock_Stone_Brick"
    },
    {
      "x": -7,
      "y": 16,
      "z": -7,
      "name": "Rock_Stone_Brick"
    },
    {
      "x": -7,
      "y": 17,
      "z": -7,
      "name": "Rock_Stone_Brick"
    },
    {
      "x": -7,
      "y": 18,
      "z": -7,
      "name": "Rock_Stone_Brick"
    },
    {
      "x": -7,
      "y": 12,
      "z": -6,
      "name": "Rock_Stone_Brick_Smooth"
    },
    {
      "x": -7,
      "y": 18,
      "z": -6,
      "name": "Rock_Stone_Brick_Smooth_Half",
      "rotation": 8
    },
    {
      "x": -7,
      "y": 22,
      "z": -6,
      "name": "Cloth_Block_Wool_Pink",
      "rotation": 3
    },
    {
      "x": -7,
      "y": 7,
      "z": -5,
      "name": "Rock_Stone_Brick_Smooth"
    },
    {
      "x": -7,
      "y": 8,
      "z": -5,
      "name": "Rock_Stone_Brick_Smooth"
    },
    {
      "x": -7,
      "y": 9,
      "z": -5,
      "name": "Rock_Stone_Brick_Smooth"
    },
    {
      "x": -7,
      "y": 10,
      "z": -5,
      "name": "Rock_Stone_Brick_Smooth"
    },
    {
      "x": -7,
      "y": 11,
      "z": -5,
      "name": "Rock_Stone_Brick_Smooth"
    },
    {
      "x": -7,
      "y": 12,
      "z": -5,
      "name": "Rock_Stone_Brick_Smooth"
    },
    {
      "x": -7,
      "y": 18,
      "z": -5,
      "name": "Rock_Stone_Brick_Smooth_Half",
      "rotation": 8
    },
    {
      "x": -7,
      "y": 22,
      "z": -5,
      "name": "Cloth_Block_Wool_Green",
      "rotation": 2
    },
    {
      "x": -7,
      "y": 6,
      "z": -4,
      "name": "Rock_Stone_Brick_Smooth"
    },
    {
      "x": -7,
      "y": 7,
      "z": -4,
      "name": "Rock_Stone_Brick_Smooth"
    },
    {
      "x": -7,
      "y": 8,
      "z": -4,
      "name": "Rock_Stone_Brick_Smooth"
    },
    {
      "x": -7,
      "y": 9,
      "z": -4,
      "name": "Rock_Stone_Brick_Smooth"
    },
    {
      "x": -7,
      "y": 10,
      "z": -4,
      "name": "Rock_Stone_Brick_Smooth"
    },
    {
      "x": -7,
      "y": 11,
      "z": -4,
      "name": "Rock_Stone_Brick_Smooth"
    },
    {
      "x": -7,
      "y": 12,
      "z": -4,
      "name": "Rock_Stone_Brick_Smooth"
    },
    {
      "x": -7,
      "y": 18,
      "z": -4,
      "name": "Rock_Stone_Brick_Smooth_Half",
      "rotation": 8
    },
    {
      "x": -7,
      "y": 6,
      "z": -3,
      "name": "Rock_Stone_Brick_Smooth"
    },
    {
      "x": -7,
      "y": 7,
      "z": -3,
      "name": "Rock_Stone_Brick_Smooth"
    },
    {
      "x": -7,
      "y": 8,
      "z": -3,
      "name": "Rock_Stone_Brick_Smooth"
    },
    {
      "x": -7,
      "y": 9,
      "z": -3,
      "name": "Rock_Stone_Brick_Smooth"
    },
    {
      "x": -7,
      "y": 10,
      "z": -3,
      "name": "Rock_Stone_Brick_Smooth"
    },
    {
      "x": -7,
      "y": 11,
      "z": -3,
      "name": "Rock_Stone_Brick_Smooth"
    },
    {
      "x": -7,
      "y": 12,
      "z": -3,
      "name": "Rock_Stone_Brick_Smooth"
    },
    {
      "x": -7,
      "y": 18,
      "z": -3,
      "name": "Rock_Stone_Brick"
    },
    {
      "x": -7,
      "y": 6,
      "z": -2,
      "name": "Rock_Stone_Brick_Smooth"
    },
    {
      "x": -7,
      "y": 7,
      "z": -2,
      "name": "Rock_Stone_Brick_Smooth"
    },
    {
      "x": -7,
      "y": 8,
      "z": -2,
      "name": "Rock_Stone_Brick_Smooth"
    },
    {
      "x": -7,
      "y": 9,
      "z": -2,
      "name": "Rock_Stone_Brick_Smooth"
    },
    {
      "x": -7,
      "y": 10,
      "z": -2,
      "name": "Rock_Stone_Brick_Smooth"
    },
    {
      "x": -7,
      "y": 11,
      "z": -2,
      "name": "Rock_Stone_Brick_Smooth"
    },
    {
      "x": -7,
      "y": 12,
      "z": -2,
      "name": "Rock_Stone_Brick_Smooth"
    },
    {
      "x": -7,
      "y": 18,
      "z": -2,
      "name": "Rock_Stone_Brick_Smooth_Half",
      "rotation": 8
    },
    {
      "x": -7,
      "y": 6,
      "z": -1,
      "name": "Rock_Stone_Brick_Smooth"
    },
    {
      "x": -7,
      "y": 7,
      "z": -1,
      "name": "Rock_Stone_Brick_Smooth"
    },
    {
      "x": -7,
      "y": 8,
      "z": -1,
      "name": "Rock_Stone_Brick_Smooth"
    },
    {
      "x": -7,
      "y": 9,
      "z": -1,
      "name": "Rock_Stone_Brick_Smooth"
    },
    {
      "x": -7,
      "y": 10,
      "z": -1,
      "name": "Rock_Stone_Brick_Smooth"
    },
    {
      "x": -7,
      "y": 11,
      "z": -1,
      "name": "Rock_Stone_Brick_Smooth"
    },
    {
      "x": -7,
      "y": 12,
      "z": -1,
      "name": "Rock_Stone_Brick_Smooth"
    },
    {
      "x": -7,
      "y": 18,
      "z": -1,
      "name": "Rock_Stone_Brick_Smooth_Half",
      "rotation": 8
    },
    {
      "x": -7,
      "y": 6,
      "z": 0,
      "name": "Rock_Stone_Brick_Smooth"
    },
    {
      "x": -7,
      "y": 7,
      "z": 0,
      "name": "Rock_Stone_Brick_Smooth"
    },
    {
      "x": -7,
      "y": 8,
      "z": 0,
      "name": "Rock_Stone_Brick_Smooth"
    },
    {
      "x": -7,
      "y": 9,
      "z": 0,
      "name": "Rock_Stone_Brick_Smooth"
    },
    {
      "x": -7,
      "y": 10,
      "z": 0,
      "name": "Rock_Stone_Brick_Smooth"
    },
    {
      "x": -7,
      "y": 11,
      "z": 0,
      "name": "Rock_Stone_Brick_Smooth"
    },
    {
      "x": -7,
      "y": 12,
      "z": 0,
      "name": "Rock_Stone_Brick_Smooth"
    },
    {
      "x": -7,
      "y": 18,
      "z": 0,
      "name": "Rock_Stone_Brick_Smooth_Half",
      "rotation": 8
    },
    {
      "x": -7,
      "y": 6,
      "z": 1,
      "name": "Rock_Stone_Brick_Smooth"
    },
    {
      "x": -7,
      "y": 7,
      "z": 1,
      "name": "Rock_Stone_Brick_Smooth"
    },
    {
      "x": -7,
      "y": 8,
      "z": 1,
      "name": "Rock_Stone_Brick_Smooth"
    },
    {
      "x": -7,
      "y": 9,
      "z": 1,
      "name": "Rock_Stone_Brick_Smooth"
    },
    {
      "x": -7,
      "y": 10,
      "z": 1,
      "name": "Rock_Stone_Brick_Smooth"
    },
    {
      "x": -7,
      "y": 11,
      "z": 1,
      "name": "Rock_Stone_Brick_Smooth"
    },
    {
      "x": -7,
      "y": 12,
      "z": 1,
      "name": "Rock_Stone_Brick_Smooth"
    },
    {
      "x": -7,
      "y": 18,
      "z": 1,
      "name": "Rock_Stone_Brick"
    },
    {
      "x": -7,
      "y": 6,
      "z": 2,
      "name": "Rock_Stone_Brick_Smooth"
    },
    {
      "x": -7,
      "y": 7,
      "z": 2,
      "name": "Rock_Stone_Brick_Smooth"
    },
    {
      "x": -7,
      "y": 8,
      "z": 2,
      "name": "Rock_Stone_Brick_Smooth"
    },
    {
      "x": -7,
      "y": 9,
      "z": 2,
      "name": "Rock_Stone_Brick_Smooth"
    },
    {
      "x": -7,
      "y": 10,
      "z": 2,
      "name": "Rock_Stone_Brick_Smooth"
    },
    {
      "x": -7,
      "y": 11,
      "z": 2,
      "name": "Rock_Stone_Brick_Smooth"
    },
    {
      "x": -7,
      "y": 12,
      "z": 2,
      "name": "Rock_Stone_Brick_Smooth"
    },
    {
      "x": -7,
      "y": 18,
      "z": 2,
      "name": "Rock_Stone_Brick_Smooth_Half",
      "rotation": 8
    },
    {
      "x": -7,
      "y": 6,
      "z": 3,
      "name": "Rock_Stone_Brick_Smooth"
    },
    {
      "x": -7,
      "y": 7,
      "z": 3,
      "name": "Rock_Stone_Brick_Smooth"
    },
    {
      "x": -7,
      "y": 8,
      "z": 3,
      "name": "Rock_Stone_Brick_Smooth"
    },
    {
      "x": -7,
      "y": 9,
      "z": 3,
      "name": "Rock_Stone_Brick_Smooth"
    },
    {
      "x": -7,
      "y": 10,
      "z": 3,
      "name": "Rock_Stone_Brick_Smooth"
    },
    {
      "x": -7,
      "y": 11,
      "z": 3,
      "name": "Rock_Stone_Brick_Smooth"
    },
    {
      "x": -7,
      "y": 12,
      "z": 3,
      "name": "Rock_Stone_Brick_Smooth"
    },
    {
      "x": -7,
      "y": 18,
      "z": 3,
      "name": "Rock_Stone_Brick_Smooth_Half",
      "rotation": 8
    },
    {
      "x": -7,
      "y": 6,
      "z": 4,
      "name": "Rock_Stone_Brick_Smooth"
    },
    {
      "x": -7,
      "y": 7,
      "z": 4,
      "name": "Rock_Stone_Brick_Smooth"
    },
    {
      "x": -7,
      "y": 8,
      "z": 4,
      "name": "Rock_Stone_Brick_Smooth"
    },
    {
      "x": -7,
      "y": 9,
      "z": 4,
      "name": "Rock_Stone_Brick_Smooth"
    },
    {
      "x": -7,
      "y": 10,
      "z": 4,
      "name": "Rock_Stone_Brick_Smooth"
    },
    {
      "x": -7,
      "y": 11,
      "z": 4,
      "name": "Rock_Stone_Brick_Smooth"
    },
    {
      "x": -7,
      "y": 12,
      "z": 4,
      "name": "Rock_Stone_Brick_Smooth"
    },
    {
      "x": -7,
      "y": 18,
      "z": 4,
      "name": "Rock_Stone_Brick_Smooth_Half",
      "rotation": 8
    },
    {
      "x": -7,
      "y": 6,
      "z": 5,
      "name": "Rock_Stone_Brick_Smooth"
    },
    {
      "x": -7,
      "y": 7,
      "z": 5,
      "name": "Rock_Stone_Brick_Smooth"
    },
    {
      "x": -7,
      "y": 8,
      "z": 5,
      "name": "Rock_Stone_Brick_Smooth"
    },
    {
      "x": -7,
      "y": 9,
      "z": 5,
      "name": "Rock_Stone_Brick_Smooth"
    },
    {
      "x": -7,
      "y": 10,
      "z": 5,
      "name": "Rock_Stone_Brick_Smooth"
    },
    {
      "x": -7,
      "y": 11,
      "z": 5,
      "name": "Rock_Stone_Brick_Smooth"
    },
    {
      "x": -7,
      "y": 12,
      "z": 5,
      "name": "Rock_Stone_Brick_Smooth"
    },
    {
      "x": -7,
      "y": 18,
      "z": 5,
      "name": "Rock_Stone_Brick"
    },
    {
      "x": -7,
      "y": 22,
      "z": 5,
      "name": "Cloth_Block_Wool_Green",
      "rotation": 2
    },
    {
      "x": -7,
      "y": 12,
      "z": 6,
      "name": "Rock_Stone_Brick_Smooth"
    },
    {
      "x": -7,
      "y": 13,
      "z": 6,
      "name": "Rock_Stone_Brick_Decorative"
    },
    {
      "x": -7,
      "y": 14,
      "z": 6,
      "name": "Rock_Stone_Brick"
    },
    {
      "x": -7,
      "y": 15,
      "z": 6,
      "name": "Rock_Stone_Brick"
    },
    {
      "x": -7,
      "y": 16,
      "z": 6,
      "name": "Rock_Stone_Brick"
    },
    {
      "x": -7,
      "y": 17,
      "z": 6,
      "name": "Rock_Stone_Brick"
    },
    {
      "x": -7,
      "y": 18,
      "z": 6,
      "name": "Rock_Stone_Brick"
    },
    {
      "x": -7,
      "y": 22,
      "z": 6,
      "name": "Cloth_Block_Wool_Pink"
    },
    {
      "x": -7,
      "y": 12,
      "z": 7,
      "name": "Rock_Stone_Brick_Smooth"
    },
    {
      "x": -7,
      "y": 13,
      "z": 7,
      "name": "Rock_Stone_Brick_Decorative"
    },
    {
      "x": -7,
      "y": 14,
      "z": 7,
      "name": "Soil_Gravel_Half",
      "support": 15,
      "rotation": 5
    },
    {
      "x": -7,
      "y": 15,
      "z": 7,
      "name": "Soil_Gravel_Half",
      "support": 15,
      "rotation": 5
    },
    {
      "x": -7,
      "y": 16,
      "z": 7,
      "name": "Soil_Gravel_Half",
      "support": 15,
      "rotation": 5
    },
    {
      "x": -7,
      "y": 17,
      "z": 7,
      "name": "Soil_Gravel_Half",
      "support": 15,
      "rotation": 5
    },
    {
      "x": -7,
      "y": 18,
      "z": 7,
      "name": "Rock_Stone_Brick"
    },
    {
      "x": -7,
      "y": 13,
      "z": 8,
      "name": "Rock_Stone_Brick_Decorative"
    },
    {
      "x": -7,
      "y": 14,
      "z": 8,
      "name": "Rock_Stone_Brick"
    },
    {
      "x": -7,
      "y": 15,
      "z": 8,
      "name": "Rock_Stone_Brick"
    },
    {
      "x": -7,
      "y": 16,
      "z": 8,
      "name": "Rock_Stone_Brick"
    },
    {
      "x": -7,
      "y": 17,
      "z": 8,
      "name": "Rock_Stone_Brick"
    },
    {
      "x": -7,
      "y": 18,
      "z": 8,
      "name": "Rock_Stone_Brick"
    },
    {
      "x": -7,
      "y": 19,
      "z": 8,
      "name": "Rock_Stone_Brick"
    },
    {
      "x": -7,
      "y": 13,
      "z": 9,
      "name": "Rock_Stone_Brick_Smooth"
    },
    {
      "x": -7,
      "y": 19,
      "z": 9,
      "name": "Rock_Stone_Brick"
    },
    {
      "x": -7,
      "y": 13,
      "z": 10,
      "name": "Rock_Stone_Brick_Smooth"
    },
    {
      "x": -7,
      "y": 19,
      "z": 10,
      "name": "Rock_Stone_Brick"
    },
    {
      "x": -7,
      "y": 13,
      "z": 11,
      "name": "Rock_Stone_Brick_Smooth"
    },
    {
      "x": -7,
      "y": 19,
      "z": 11,
      "name": "Rock_Stone_Brick"
    },
    {
      "x": -7,
      "y": 13,
      "z": 12,
      "name": "Rock_Stone_Brick_Smooth"
    },
    {
      "x": -7,
      "y": 19,
      "z": 12,
      "name": "Rock_Stone_Brick"
    },
    {
      "x": -7,
      "y": 13,
      "z": 13,
      "name": "Rock_Stone_Brick_Smooth"
    },
    {
      "x": -7,
      "y": 19,
      "z": 13,
      "name": "Rock_Stone_Brick"
    },
    {
      "x": -7,
      "y": 13,
      "z": 14,
      "name": "Rock_Stone_Brick_Decorative"
    },
    {
      "x": -7,
      "y": 14,
      "z": 14,
      "name": "Rock_Stone_Brick_Smooth",
      "rotation": 2
    },
    {
      "x": -7,
      "y": 15,
      "z": 14,
      "name": "Rock_Stone_Brick"
    },
    {
      "x": -7,
      "y": 16,
      "z": 14,
      "name": "Rock_Stone_Brick"
    },
    {
      "x": -7,
      "y": 17,
      "z": 14,
      "name": "Rock_Stone_Brick"
    },
    {
      "x": -7,
      "y": 18,
      "z": 14,
      "name": "Rock_Stone_Brick"
    },
    {
      "x": -7,
      "y": 19,
      "z": 14,
      "name": "Rock_Stone_Brick"
    },
    {
      "x": -7,
      "y": 22,
      "z": 16,
      "name": "Cloth_Block_Wool_Pink"
    },
    {
      "x": -6,
      "y": 15,
      "z": -16,
      "name": "Rock_Stone_Brick_Smooth"
    },
    {
      "x": -6,
      "y": 16,
      "z": -16,
      "name": "Rock_Stone_Brick_Smooth_Half",
      "rotation": 5
    },
    {
      "x": -6,
      "y": 17,
      "z": -16,
      "name": "Rock_Stone_Brick_Smooth_Half",
      "rotation": 5
    },
    {
      "x": -6,
      "y": 18,
      "z": -16,
      "name": "Rock_Stone_Brick_Smooth_Half",
      "rotation": 5
    },
    {
      "x": -6,
      "y": 19,
      "z": -16,
      "name": "*Rock_Stone_Brick_Stairs_State_Definitions_Inverted_Corner_Left",
      "rotation": 11
    },
    {
      "x": -6,
      "y": 20,
      "z": -16,
      "name": "Rock_Stone_Brick_Decorative"
    },
    {
      "x": -6,
      "y": 21,
      "z": -16,
      "name": "Rock_Stone_Brick_Smooth"
    },
    {
      "x": -6,
      "y": 22,
      "z": -16,
      "name": "Cloth_Block_Wool_Pink",
      "rotation": 3
    },
    {
      "x": -6,
      "y": 15,
      "z": -15,
      "name": "Rock_Stone_Brick_Smooth"
    },
    {
      "x": -6,
      "y": 21,
      "z": -15,
      "name": "Rock_Stone_Brick_Smooth"
    },
    {
      "x": -6,
      "y": 15,
      "z": -14,
      "name": "Rock_Stone_Brick_Smooth"
    },
    {
      "x": -6,
      "y": 21,
      "z": -14,
      "name": "Rock_Stone_Brick_Smooth",
      "rotation": 1
    },
    {
      "x": -6,
      "y": 15,
      "z": -13,
      "name": "Rock_Stone_Brick_Smooth"
    },
    {
      "x": -6,
      "y": 21,
      "z": -13,
      "name": "Rock_Stone_Brick_Smooth",
      "rotation": 1
    },
    {
      "x": -6,
      "y": 15,
      "z": -12,
      "name": "Rock_Stone_Brick_Stairs"
    },
    {
      "x": -6,
      "y": 21,
      "z": -12,
      "name": "Rock_Stone_Brick_Smooth",
      "rotation": 1
    },
    {
      "x": -6,
      "y": 14,
      "z": -11,
      "name": "Rock_Stone_Brick_Stairs"
    },
    {
      "x": -6,
      "y": 20,
      "z": -11,
      "name": "Rock_Stone_Brick_Stairs",
      "rotation": 8
    },
    {
      "x": -6,
      "y": 21,
      "z": -11,
      "name": "Rock_Stone_Brick_Smooth",
      "rotation": 1
    },
    {
      "x": -6,
      "y": 12,
      "z": -10,
      "name": "Rock_Stone_Brick_Smooth"
    },
    {
      "x": -6,
      "y": 13,
      "z": -10,
      "name": "Rock_Stone_Brick_Stairs"
    },
    {
      "x": -6,
      "y": 19,
      "z": -10,
      "name": "Rock_Stone_Brick_Stairs",
      "rotation": 8
    },
    {
      "x": -6,
      "y": 20,
      "z": -10,
      "name": "Rock_Stone_Brick",
      "rotation": 2
    },
    {
      "x": -6,
      "y": 21,
      "z": -10,
      "name": "Rock_Stone_Brick_Smooth",
      "rotation": 2
    },
    {
      "x": -6,
      "y": 12,
      "z": -9,
      "name": "Rock_Stone_Brick_Smooth",
      "rotation": 2
    },
    {
      "x": -6,
      "y": 18,
      "z": -9,
      "name": "Rock_Stone_Brick_Stairs",
      "rotation": 8
    },
    {
      "x": -6,
      "y": 12,
      "z": -8,
      "name": "Rock_Stone_Brick_Smooth"
    },
    {
      "x": -6,
      "y": 18,
      "z": -8,
      "name": "Rock_Stone_Brick_Smooth_Half"
    },
    {
      "x": -6,
      "y": 12,
      "z": -7,
      "name": "Rock_Stone_Brick_Smooth"
    },
    {
      "x": -6,
      "y": 18,
      "z": -7,
      "name": "Rock_Stone_Brick"
    },
    {
      "x": -6,
      "y": 12,
      "z": -6,
      "name": "Rock_Stone_Brick_Smooth"
    },
    {
      "x": -6,
      "y": 18,
      "z": -6,
      "name": "Rock_Stone_Brick_Smooth_Half",
      "rotation": 8
    },
    {
      "x": -6,
      "y": 22,
      "z": -6,
      "name": "Cloth_Block_Wool_Pink",
      "rotation": 3
    },
    {
      "x": -6,
      "y": 7,
      "z": -5,
      "name": "Rock_Stone_Brick_Smooth"
    },
    {
      "x": -6,
      "y": 8,
      "z": -5,
      "name": "Rock_Stone_Brick_Smooth"
    },
    {
      "x": -6,
      "y": 9,
      "z": -5,
      "name": "Rock_Stone_Brick_Smooth"
    },
    {
      "x": -6,
      "y": 10,
      "z": -5,
      "name": "Rock_Stone_Brick_Smooth"
    },
    {
      "x": -6,
      "y": 11,
      "z": -5,
      "name": "Rock_Stone_Brick_Smooth"
    },
    {
      "x": -6,
      "y": 12,
      "z": -5,
      "name": "Rock_Stone_Brick_Smooth"
    },
    {
      "x": -6,
      "y": 18,
      "z": -5,
      "name": "Rock_Stone_Brick_Smooth_Half",
      "rotation": 8
    },
    {
      "x": -6,
      "y": 22,
      "z": -5,
      "name": "Cloth_Block_Wool_Green",
      "rotation": 2
    },
    {
      "x": -6,
      "y": 6,
      "z": -4,
      "name": "Rock_Stone_Brick_Smooth"
    },
    {
      "x": -6,
      "y": 12,
      "z": -4,
      "name": "Rock_Stone_Brick_Smooth"
    },
    {
      "x": -6,
      "y": 18,
      "z": -4,
      "name": "Rock_Stone_Brick_Smooth_Half",
      "rotation": 8
    },
    {
      "x": -6,
      "y": 6,
      "z": -3,
      "name": "Rock_Stone_Brick_Smooth"
    },
    {
      "x": -6,
      "y": 12,
      "z": -3,
      "name": "Rock_Stone_Brick_Smooth"
    },
    {
      "x": -6,
      "y": 18,
      "z": -3,
      "name": "Rock_Stone_Brick"
    },
    {
      "x": -6,
      "y": 6,
      "z": -2,
      "name": "Rock_Stone_Brick_Smooth"
    },
    {
      "x": -6,
      "y": 12,
      "z": -2,
      "name": "Rock_Stone_Brick_Smooth"
    },
    {
      "x": -6,
      "y": 18,
      "z": -2,
      "name": "Rock_Stone_Brick_Smooth_Half",
      "rotation": 8
    },
    {
      "x": -6,
      "y": 6,
      "z": -1,
      "name": "Rock_Stone_Brick_Smooth"
    },
    {
      "x": -6,
      "y": 12,
      "z": -1,
      "name": "Rock_Stone_Brick_Smooth"
    },
    {
      "x": -6,
      "y": 18,
      "z": -1,
      "name": "Rock_Stone_Brick_Smooth_Half",
      "rotation": 8
    },
    {
      "x": -6,
      "y": 6,
      "z": 0,
      "name": "Rock_Stone_Brick_Smooth"
    },
    {
      "x": -6,
      "y": 12,
      "z": 0,
      "name": "Rock_Stone_Brick_Smooth"
    },
    {
      "x": -6,
      "y": 18,
      "z": 0,
      "name": "Rock_Stone_Brick_Smooth_Half",
      "rotation": 8
    },
    {
      "x": -6,
      "y": 6,
      "z": 1,
      "name": "Rock_Stone_Brick_Smooth"
    },
    {
      "x": -6,
      "y": 12,
      "z": 1,
      "name": "Rock_Stone_Brick_Smooth"
    },
    {
      "x": -6,
      "y": 18,
      "z": 1,
      "name": "Rock_Stone_Brick"
    },
    {
      "x": -6,
      "y": 6,
      "z": 2,
      "name": "Rock_Stone_Brick_Smooth"
    },
    {
      "x": -6,
      "y": 12,
      "z": 2,
      "name": "Rock_Stone_Brick_Smooth"
    },
    {
      "x": -6,
      "y": 18,
      "z": 2,
      "name": "Rock_Stone_Brick_Smooth_Half",
      "rotation": 8
    },
    {
      "x": -6,
      "y": 6,
      "z": 3,
      "name": "Rock_Stone_Brick_Smooth"
    },
    {
      "x": -6,
      "y": 12,
      "z": 3,
      "name": "Rock_Stone_Brick_Smooth"
    },
    {
      "x": -6,
      "y": 18,
      "z": 3,
      "name": "Rock_Stone_Brick_Smooth_Half",
      "rotation": 8
    },
    {
      "x": -6,
      "y": 6,
      "z": 4,
      "name": "Rock_Stone_Brick_Smooth"
    },
    {
      "x": -6,
      "y": 12,
      "z": 4,
      "name": "Rock_Stone_Brick_Smooth"
    },
    {
      "x": -6,
      "y": 18,
      "z": 4,
      "name": "Rock_Stone_Brick_Smooth_Half",
      "rotation": 8
    },
    {
      "x": -6,
      "y": 6,
      "z": 5,
      "name": "Rock_Stone_Brick_Smooth"
    },
    {
      "x": -6,
      "y": 7,
      "z": 5,
      "name": "Rock_Stone_Brick_Smooth"
    },
    {
      "x": -6,
      "y": 8,
      "z": 5,
      "name": "Rock_Stone_Brick_Smooth"
    },
    {
      "x": -6,
      "y": 9,
      "z": 5,
      "name": "Rock_Stone_Brick_Smooth"
    },
    {
      "x": -6,
      "y": 10,
      "z": 5,
      "name": "Rock_Stone_Brick_Smooth"
    },
    {
      "x": -6,
      "y": 11,
      "z": 5,
      "name": "Rock_Stone_Brick_Smooth"
    },
    {
      "x": -6,
      "y": 12,
      "z": 5,
      "name": "Rock_Stone_Brick_Smooth"
    },
    {
      "x": -6,
      "y": 18,
      "z": 5,
      "name": "Rock_Stone_Brick"
    },
    {
      "x": -6,
      "y": 22,
      "z": 5,
      "name": "Cloth_Block_Wool_Green",
      "rotation": 2
    },
    {
      "x": -6,
      "y": 12,
      "z": 6,
      "name": "Rock_Stone_Brick_Smooth"
    },
    {
      "x": -6,
      "y": 18,
      "z": 6,
      "name": "Rock_Stone_Brick_Stairs",
      "rotation": 8
    },
    {
      "x": -6,
      "y": 22,
      "z": 6,
      "name": "Cloth_Block_Wool_Pink"
    },
    {
      "x": -6,
      "y": 12,
      "z": 7,
      "name": "Rock_Stone_Brick_Smooth"
    },
    {
      "x": -6,
      "y": 18,
      "z": 7,
      "name": "Rock_Stone_Brick_Stairs",
      "rotation": 10
    },
    {
      "x": -6,
      "y": 13,
      "z": 8,
      "name": "Rock_Stone_Brick_Stairs",
      "rotation": 2
    },
    {
      "x": -6,
      "y": 19,
      "z": 8,
      "name": "Rock_Stone_Brick"
    },
    {
      "x": -6,
      "y": 13,
      "z": 9,
      "name": "Rock_Stone_Brick_Smooth"
    },
    {
      "x": -6,
      "y": 19,
      "z": 9,
      "name": "Rock_Stone_Brick_Smooth_Half",
      "rotation": 8
    },
    {
      "x": -6,
      "y": 13,
      "z": 10,
      "name": "Rock_Stone_Brick_Smooth"
    },
    {
      "x": -6,
      "y": 19,
      "z": 10,
      "name": "Rock_Stone_Brick_Smooth_Half",
      "rotation": 8
    },
    {
      "x": -6,
      "y": 13,
      "z": 11,
      "name": "Rock_Stone_Brick_Smooth"
    },
    {
      "x": -6,
      "y": 19,
      "z": 11,
      "name": "Rock_Stone_Brick_Smooth_Half",
      "rotation": 8
    },
    {
      "x": -6,
      "y": 13,
      "z": 12,
      "name": "Rock_Stone_Brick_Smooth"
    },
    {
      "x": -6,
      "y": 19,
      "z": 12,
      "name": "Rock_Stone_Brick_Smooth_Half",
      "rotation": 8
    },
    {
      "x": -6,
      "y": 13,
      "z": 13,
      "name": "Rock_Stone_Brick_Smooth"
    },
    {
      "x": -6,
      "y": 19,
      "z": 13,
      "name": "Rock_Stone_Brick_Smooth_Half",
      "rotation": 8
    },
    {
      "x": -6,
      "y": 13,
      "z": 14,
      "name": "Rock_Stone_Brick_Smooth"
    },
    {
      "x": -6,
      "y": 14,
      "z": 14,
      "name": "Rock_Stone_Brick_Decorative",
      "rotation": 2
    },
    {
      "x": -6,
      "y": 15,
      "z": 14,
      "name": "Soil_Gravel_Half",
      "rotation": 6
    },
    {
      "x": -6,
      "y": 16,
      "z": 14,
      "name": "Soil_Gravel_Half",
      "rotation": 6
    },
    {
      "x": -6,
      "y": 17,
      "z": 14,
      "name": "Soil_Gravel_Half",
      "rotation": 6
    },
    {
      "x": -6,
      "y": 18,
      "z": 14,
      "name": "Soil_Gravel_Half",
      "rotation": 6
    },
    {
      "x": -6,
      "y": 19,
      "z": 14,
      "name": "Rock_Stone_Brick"
    },
    {
      "x": -6,
      "y": 22,
      "z": 16,
      "name": "Cloth_Block_Wool_Pink"
    },
    {
      "x": -5,
      "y": 15,
      "z": -16,
      "name": "Rock_Stone_Brick_Smooth"
    },
    {
      "x": -5,
      "y": 19,
      "z": -16,
      "name": "Rock_Stone_Brick_Stairs",
      "rotation": 10
    },
    {
      "x": -5,
      "y": 20,
      "z": -16,
      "name": "Rock_Stone_Brick_Decorative"
    },
    {
      "x": -5,
      "y": 21,
      "z": -16,
      "name": "Rock_Stone_Brick_Smooth"
    },
    {
      "x": -5,
      "y": 22,
      "z": -16,
      "name": "Cloth_Block_Wool_Cyan_Light"
    },
    {
      "x": -5,
      "y": 15,
      "z": -15,
      "name": "Rock_Stone_Brick_Smooth"
    },
    {
      "x": -5,
      "y": 21,
      "z": -15,
      "name": "Rock_Stone_Brick_Smooth"
    },
    {
      "x": -5,
      "y": 22,
      "z": -15,
      "name": "Cloth_Block_Wool_Cyan_Light"
    },
    {
      "x": -5,
      "y": 15,
      "z": -14,
      "name": "Rock_Stone_Brick_Smooth",
      "rotation": 3
    },
    {
      "x": -5,
      "y": 21,
      "z": -14,
      "name": "Rock_Stone_Brick_Smooth",
      "rotation": 3
    },
    {
      "x": -5,
      "y": 22,
      "z": -14,
      "name": "Cloth_Block_Wool_Cyan_Light"
    },
    {
      "x": -5,
      "y": 15,
      "z": -13,
      "name": "Rock_Stone_Brick_Smooth"
    },
    {
      "x": -5,
      "y": 21,
      "z": -13,
      "name": "Rock_Stone_Brick_Smooth"
    },
    {
      "x": -5,
      "y": 15,
      "z": -12,
      "name": "Rock_Stone_Brick_Stairs"
    },
    {
      "x": -5,
      "y": 21,
      "z": -12,
      "name": "Rock_Stone_Brick_Smooth"
    },
    {
      "x": -5,
      "y": 14,
      "z": -11,
      "name": "Rock_Stone_Brick_Stairs"
    },
    {
      "x": -5,
      "y": 20,
      "z": -11,
      "name": "Rock_Stone_Brick_Stairs",
      "rotation": 8
    },
    {
      "x": -5,
      "y": 21,
      "z": -11,
      "name": "Rock_Stone_Brick_Smooth"
    },
    {
      "x": -5,
      "y": 12,
      "z": -10,
      "name": "Rock_Stone_Brick_Smooth"
    },
    {
      "x": -5,
      "y": 13,
      "z": -10,
      "name": "Rock_Stone_Brick_Stairs"
    },
    {
      "x": -5,
      "y": 19,
      "z": -10,
      "name": "Rock_Stone_Brick_Stairs",
      "rotation": 8
    },
    {
      "x": -5,
      "y": 20,
      "z": -10,
      "name": "Rock_Stone_Brick",
      "rotation": 2
    },
    {
      "x": -5,
      "y": 21,
      "z": -10,
      "name": "Rock_Stone_Brick_Smooth",
      "rotation": 3
    },
    {
      "x": -5,
      "y": 12,
      "z": -9,
      "name": "Rock_Stone_Brick_Smooth"
    },
    {
      "x": -5,
      "y": 18,
      "z": -9,
      "name": "Rock_Stone_Brick_Stairs",
      "rotation": 8
    },
    {
      "x": -5,
      "y": 12,
      "z": -8,
      "name": "Rock_Stone_Brick_Smooth"
    },
    {
      "x": -5,
      "y": 18,
      "z": -8,
      "name": "Rock_Stone_Brick_Smooth_Half"
    },
    {
      "x": -5,
      "y": 12,
      "z": -7,
      "name": "Rock_Stone_Brick_Smooth"
    },
    {
      "x": -5,
      "y": 18,
      "z": -7,
      "name": "Rock_Stone_Brick"
    },
    {
      "x": -5,
      "y": 12,
      "z": -6,
      "name": "Rock_Stone_Brick_Smooth"
    },
    {
      "x": -5,
      "y": 18,
      "z": -6,
      "name": "Rock_Stone_Brick"
    },
    {
      "x": -5,
      "y": 22,
      "z": -6,
      "name": "Cloth_Block_Wool_Pink",
      "rotation": 3
    },
    {
      "x": -5,
      "y": 7,
      "z": -5,
      "name": "Rock_Stone_Brick_Smooth"
    },
    {
      "x": -5,
      "y": 8,
      "z": -5,
      "name": "Rock_Stone_Brick_Smooth"
    },
    {
      "x": -5,
      "y": 9,
      "z": -5,
      "name": "Rock_Stone_Brick_Smooth"
    },
    {
      "x": -5,
      "y": 10,
      "z": -5,
      "name": "Rock_Stone_Brick_Smooth"
    },
    {
      "x": -5,
      "y": 11,
      "z": -5,
      "name": "Rock_Stone_Brick_Smooth"
    },
    {
      "x": -5,
      "y": 12,
      "z": -5,
      "name": "Rock_Stone_Brick_Smooth"
    },
    {
      "x": -5,
      "y": 18,
      "z": -5,
      "name": "Rock_Stone_Brick"
    },
    {
      "x": -5,
      "y": 22,
      "z": -5,
      "name": "Cloth_Block_Wool_Green"
    },
    {
      "x": -5,
      "y": 6,
      "z": -4,
      "name": "Rock_Stone_Brick_Smooth"
    },
    {
      "x": -5,
      "y": 12,
      "z": -4,
      "name": "Rock_Stone_Brick_Smooth"
    },
    {
      "x": -5,
      "y": 18,
      "z": -4,
      "name": "Rock_Stone_Brick"
    },
    {
      "x": -5,
      "y": 6,
      "z": -3,
      "name": "Rock_Stone_Brick_Smooth"
    },
    {
      "x": -5,
      "y": 12,
      "z": -3,
      "name": "Rock_Stone_Brick_Smooth"
    },
    {
      "x": -5,
      "y": 18,
      "z": -3,
      "name": "Rock_Stone_Brick"
    },
    {
      "x": -5,
      "y": 6,
      "z": -2,
      "name": "Rock_Stone_Brick_Smooth"
    },
    {
      "x": -5,
      "y": 12,
      "z": -2,
      "name": "Rock_Stone_Brick_Smooth"
    },
    {
      "x": -5,
      "y": 18,
      "z": -2,
      "name": "Rock_Stone_Brick"
    },
    {
      "x": -5,
      "y": 6,
      "z": -1,
      "name": "Rock_Stone_Brick_Smooth"
    },
    {
      "x": -5,
      "y": 12,
      "z": -1,
      "name": "Rock_Stone_Brick_Smooth"
    },
    {
      "x": -5,
      "y": 18,
      "z": -1,
      "name": "Rock_Stone_Brick"
    },
    {
      "x": -5,
      "y": 6,
      "z": 0,
      "name": "Rock_Stone_Brick_Smooth"
    },
    {
      "x": -5,
      "y": 12,
      "z": 0,
      "name": "Rock_Stone_Brick_Smooth"
    },
    {
      "x": -5,
      "y": 18,
      "z": 0,
      "name": "Rock_Stone_Brick"
    },
    {
      "x": -5,
      "y": 6,
      "z": 1,
      "name": "Rock_Stone_Brick_Smooth"
    },
    {
      "x": -5,
      "y": 12,
      "z": 1,
      "name": "Rock_Stone_Brick_Smooth"
    },
    {
      "x": -5,
      "y": 18,
      "z": 1,
      "name": "Rock_Stone_Brick"
    },
    {
      "x": -5,
      "y": 6,
      "z": 2,
      "name": "Rock_Stone_Brick_Smooth"
    },
    {
      "x": -5,
      "y": 12,
      "z": 2,
      "name": "Rock_Stone_Brick_Smooth"
    },
    {
      "x": -5,
      "y": 18,
      "z": 2,
      "name": "Rock_Stone_Brick"
    },
    {
      "x": -5,
      "y": 6,
      "z": 3,
      "name": "Rock_Stone_Brick_Smooth"
    },
    {
      "x": -5,
      "y": 12,
      "z": 3,
      "name": "Rock_Stone_Brick_Smooth"
    },
    {
      "x": -5,
      "y": 18,
      "z": 3,
      "name": "Rock_Stone_Brick"
    },
    {
      "x": -5,
      "y": 6,
      "z": 4,
      "name": "Rock_Stone_Brick_Smooth"
    },
    {
      "x": -5,
      "y": 12,
      "z": 4,
      "name": "Rock_Stone_Brick_Smooth"
    },
    {
      "x": -5,
      "y": 18,
      "z": 4,
      "name": "Rock_Stone_Brick"
    },
    {
      "x": -5,
      "y": 6,
      "z": 5,
      "name": "Rock_Stone_Brick_Smooth"
    },
    {
      "x": -5,
      "y": 7,
      "z": 5,
      "name": "Rock_Stone_Brick_Smooth"
    },
    {
      "x": -5,
      "y": 8,
      "z": 5,
      "name": "Rock_Stone_Brick_Smooth"
    },
    {
      "x": -5,
      "y": 9,
      "z": 5,
      "name": "Rock_Stone_Brick_Smooth"
    },
    {
      "x": -5,
      "y": 10,
      "z": 5,
      "name": "Rock_Stone_Brick_Smooth"
    },
    {
      "x": -5,
      "y": 11,
      "z": 5,
      "name": "Rock_Stone_Brick_Smooth"
    },
    {
      "x": -5,
      "y": 12,
      "z": 5,
      "name": "Rock_Stone_Brick_Smooth"
    },
    {
      "x": -5,
      "y": 18,
      "z": 5,
      "name": "Rock_Stone_Brick"
    },
    {
      "x": -5,
      "y": 22,
      "z": 5,
      "name": "Cloth_Block_Wool_Green",
      "rotation": 2
    },
    {
      "x": -5,
      "y": 12,
      "z": 6,
      "name": "Rock_Stone_Brick_Smooth"
    },
    {
      "x": -5,
      "y": 18,
      "z": 6,
      "name": "Rock_Stone_Brick_Stairs",
      "rotation": 8
    },
    {
      "x": -5,
      "y": 22,
      "z": 6,
      "name": "Cloth_Block_Wool_Pink",
      "rotation": 2
    },
    {
      "x": -5,
      "y": 12,
      "z": 7,
      "name": "Rock_Stone_Brick_Smooth"
    },
    {
      "x": -5,
      "y": 18,
      "z": 7,
      "name": "Rock_Stone_Brick_Stairs",
      "rotation": 10
    },
    {
      "x": -5,
      "y": 13,
      "z": 8,
      "name": "Rock_Stone_Brick_Stairs",
      "rotation": 2
    },
    {
      "x": -5,
      "y": 19,
      "z": 8,
      "name": "Rock_Stone_Brick"
    },
    {
      "x": -5,
      "y": 13,
      "z": 9,
      "name": "Rock_Stone_Brick_Smooth"
    },
    {
      "x": -5,
      "y": 19,
      "z": 9,
      "name": "Rock_Stone_Brick_Smooth_Half",
      "rotation": 8
    },
    {
      "x": -5,
      "y": 13,
      "z": 10,
      "name": "Rock_Stone_Brick_Smooth"
    },
    {
      "x": -5,
      "y": 19,
      "z": 10,
      "name": "Rock_Stone_Brick_Smooth_Half",
      "rotation": 8
    },
    {
      "x": -5,
      "y": 13,
      "z": 11,
      "name": "Rock_Stone_Brick_Smooth"
    },
    {
      "x": -5,
      "y": 19,
      "z": 11,
      "name": "Rock_Stone_Brick_Smooth_Half",
      "rotation": 8
    },
    {
      "x": -5,
      "y": 13,
      "z": 12,
      "name": "Rock_Stone_Brick_Smooth"
    },
    {
      "x": -5,
      "y": 19,
      "z": 12,
      "name": "Rock_Stone_Brick_Smooth_Half",
      "rotation": 8
    },
    {
      "x": -5,
      "y": 13,
      "z": 13,
      "name": "Rock_Stone_Brick_Smooth"
    },
    {
      "x": -5,
      "y": 19,
      "z": 13,
      "name": "Rock_Stone_Brick_Smooth_Half",
      "rotation": 8
    },
    {
      "x": -5,
      "y": 13,
      "z": 14,
      "name": "Rock_Stone_Brick_Smooth"
    },
    {
      "x": -5,
      "y": 14,
      "z": 14,
      "name": "Rock_Stone_Brick_Decorative",
      "rotation": 2
    },
    {
      "x": -5,
      "y": 15,
      "z": 14,
      "name": "Soil_Gravel_Half",
      "rotation": 6
    },
    {
      "x": -5,
      "y": 16,
      "z": 14,
      "name": "Soil_Gravel_Half",
      "rotation": 6
    },
    {
      "x": -5,
      "y": 17,
      "z": 14,
      "name": "Soil_Gravel_Half",
      "rotation": 6
    },
    {
      "x": -5,
      "y": 18,
      "z": 14,
      "name": "Soil_Gravel_Half",
      "rotation": 6
    },
    {
      "x": -5,
      "y": 19,
      "z": 14,
      "name": "Rock_Stone_Brick"
    },
    {
      "x": -5,
      "y": 22,
      "z": 16,
      "name": "Cloth_Block_Wool_Pink"
    },
    {
      "x": -4,
      "y": 15,
      "z": -16,
      "name": "Rock_Stone_Brick_Smooth"
    },
    {
      "x": -4,
      "y": 16,
      "z": -16,
      "name": "Rock_Stone_Brick_Smooth_Half",
      "rotation": 7
    },
    {
      "x": -4,
      "y": 17,
      "z": -16,
      "name": "Rock_Stone_Brick_Smooth_Half",
      "rotation": 7
    },
    {
      "x": -4,
      "y": 18,
      "z": -16,
      "name": "Rock_Stone_Brick_Smooth_Half",
      "rotation": 7
    },
    {
      "x": -4,
      "y": 19,
      "z": -16,
      "name": "*Rock_Stone_Brick_Stairs_State_Definitions_Inverted_Corner_Right",
      "rotation": 9
    },
    {
      "x": -4,
      "y": 20,
      "z": -16,
      "name": "Rock_Stone_Brick_Decorative"
    },
    {
      "x": -4,
      "y": 21,
      "z": -16,
      "name": "Rock_Stone_Brick_Smooth"
    },
    {
      "x": -4,
      "y": 22,
      "z": -16,
      "name": "Cloth_Block_Wool_Pink",
      "rotation": 3
    },
    {
      "x": -4,
      "y": 15,
      "z": -15,
      "name": "Rock_Stone_Brick_Smooth"
    },
    {
      "x": -4,
      "y": 21,
      "z": -15,
      "name": "Rock_Stone_Brick_Smooth"
    },
    {
      "x": -4,
      "y": 15,
      "z": -14,
      "name": "Rock_Stone_Brick_Smooth",
      "rotation": 3
    },
    {
      "x": -4,
      "y": 21,
      "z": -14,
      "name": "Rock_Stone_Brick_Smooth",
      "rotation": 3
    },
    {
      "x": -4,
      "y": 15,
      "z": -13,
      "name": "Rock_Stone_Brick_Smooth"
    },
    {
      "x": -4,
      "y": 21,
      "z": -13,
      "name": "Rock_Stone_Brick_Smooth"
    },
    {
      "x": -4,
      "y": 15,
      "z": -12,
      "name": "Rock_Stone_Brick_Stairs"
    },
    {
      "x": -4,
      "y": 21,
      "z": -12,
      "name": "Rock_Stone_Brick_Smooth"
    },
    {
      "x": -4,
      "y": 14,
      "z": -11,
      "name": "Rock_Stone_Brick_Stairs"
    },
    {
      "x": -4,
      "y": 20,
      "z": -11,
      "name": "Rock_Stone_Brick_Stairs",
      "rotation": 8
    },
    {
      "x": -4,
      "y": 21,
      "z": -11,
      "name": "Rock_Stone_Brick_Smooth",
      "rotation": 3
    },
    {
      "x": -4,
      "y": 12,
      "z": -10,
      "name": "Rock_Stone_Brick_Smooth"
    },
    {
      "x": -4,
      "y": 13,
      "z": -10,
      "name": "Rock_Stone_Brick_Stairs"
    },
    {
      "x": -4,
      "y": 19,
      "z": -10,
      "name": "Rock_Stone_Brick_Stairs",
      "rotation": 8
    },
    {
      "x": -4,
      "y": 20,
      "z": -10,
      "name": "Rock_Stone_Brick",
      "rotation": 2
    },
    {
      "x": -4,
      "y": 21,
      "z": -10,
      "name": "Rock_Stone_Brick_Smooth",
      "rotation": 3
    },
    {
      "x": -4,
      "y": 12,
      "z": -9,
      "name": "Rock_Stone_Brick_Smooth",
      "rotation": 2
    },
    {
      "x": -4,
      "y": 18,
      "z": -9,
      "name": "Rock_Stone_Brick_Stairs",
      "rotation": 8
    },
    {
      "x": -4,
      "y": 12,
      "z": -8,
      "name": "Rock_Stone_Brick_Smooth"
    },
    {
      "x": -4,
      "y": 18,
      "z": -8,
      "name": "Rock_Stone_Brick_Smooth_Half"
    },
    {
      "x": -4,
      "y": 12,
      "z": -7,
      "name": "Rock_Stone_Brick_Smooth"
    },
    {
      "x": -4,
      "y": 18,
      "z": -7,
      "name": "Rock_Stone_Brick"
    },
    {
      "x": -4,
      "y": 12,
      "z": -6,
      "name": "Rock_Stone_Brick_Smooth"
    },
    {
      "x": -4,
      "y": 18,
      "z": -6,
      "name": "Rock_Stone_Brick_Smooth_Half",
      "rotation": 8
    },
    {
      "x": -4,
      "y": 22,
      "z": -6,
      "name": "Cloth_Block_Wool_Pink",
      "rotation": 3
    },
    {
      "x": -4,
      "y": 7,
      "z": -5,
      "name": "Rock_Stone_Brick_Smooth"
    },
    {
      "x": -4,
      "y": 8,
      "z": -5,
      "name": "Rock_Stone_Brick_Smooth"
    },
    {
      "x": -4,
      "y": 9,
      "z": -5,
      "name": "Rock_Stone_Brick_Smooth"
    },
    {
      "x": -4,
      "y": 10,
      "z": -5,
      "name": "Rock_Stone_Brick_Smooth"
    },
    {
      "x": -4,
      "y": 11,
      "z": -5,
      "name": "Rock_Stone_Brick_Smooth"
    },
    {
      "x": -4,
      "y": 12,
      "z": -5,
      "name": "Rock_Stone_Brick_Smooth"
    },
    {
      "x": -4,
      "y": 18,
      "z": -5,
      "name": "Rock_Stone_Brick_Smooth_Half",
      "rotation": 8
    },
    {
      "x": -4,
      "y": 22,
      "z": -5,
      "name": "Cloth_Block_Wool_Green",
      "rotation": 2
    },
    {
      "x": -4,
      "y": 6,
      "z": -4,
      "name": "Rock_Stone_Brick_Smooth"
    },
    {
      "x": -4,
      "y": 12,
      "z": -4,
      "name": "Rock_Stone_Brick_Smooth"
    },
    {
      "x": -4,
      "y": 18,
      "z": -4,
      "name": "Rock_Stone_Brick_Smooth_Half",
      "rotation": 8
    },
    {
      "x": -4,
      "y": 6,
      "z": -3,
      "name": "Rock_Stone_Brick_Smooth"
    },
    {
      "x": -4,
      "y": 12,
      "z": -3,
      "name": "Rock_Stone_Brick_Smooth"
    },
    {
      "x": -4,
      "y": 18,
      "z": -3,
      "name": "Rock_Stone_Brick"
    },
    {
      "x": -4,
      "y": 6,
      "z": -2,
      "name": "Rock_Stone_Brick_Smooth"
    },
    {
      "x": -4,
      "y": 12,
      "z": -2,
      "name": "Rock_Stone_Brick_Smooth"
    },
    {
      "x": -4,
      "y": 18,
      "z": -2,
      "name": "Rock_Stone_Brick_Smooth_Half",
      "rotation": 8
    },
    {
      "x": -4,
      "y": 6,
      "z": -1,
      "name": "Rock_Stone_Brick_Smooth"
    },
    {
      "x": -4,
      "y": 12,
      "z": -1,
      "name": "Rock_Stone_Brick_Smooth"
    },
    {
      "x": -4,
      "y": 18,
      "z": -1,
      "name": "Rock_Stone_Brick_Smooth_Half",
      "rotation": 8
    },
    {
      "x": -4,
      "y": 6,
      "z": 0,
      "name": "Rock_Stone_Brick_Smooth"
    },
    {
      "x": -4,
      "y": 12,
      "z": 0,
      "name": "Rock_Stone_Brick_Smooth"
    },
    {
      "x": -4,
      "y": 18,
      "z": 0,
      "name": "Rock_Stone_Brick_Smooth_Half",
      "rotation": 8
    },
    {
      "x": -4,
      "y": 6,
      "z": 1,
      "name": "Rock_Stone_Brick_Smooth"
    },
    {
      "x": -4,
      "y": 12,
      "z": 1,
      "name": "Rock_Stone_Brick_Smooth"
    },
    {
      "x": -4,
      "y": 18,
      "z": 1,
      "name": "Rock_Stone_Brick"
    },
    {
      "x": -4,
      "y": 6,
      "z": 2,
      "name": "Rock_Stone_Brick_Smooth"
    },
    {
      "x": -4,
      "y": 12,
      "z": 2,
      "name": "Rock_Stone_Brick_Smooth"
    },
    {
      "x": -4,
      "y": 18,
      "z": 2,
      "name": "Rock_Stone_Brick_Smooth_Half",
      "rotation": 8
    },
    {
      "x": -4,
      "y": 6,
      "z": 3,
      "name": "Rock_Stone_Brick_Smooth"
    },
    {
      "x": -4,
      "y": 12,
      "z": 3,
      "name": "Rock_Stone_Brick_Smooth"
    },
    {
      "x": -4,
      "y": 18,
      "z": 3,
      "name": "Rock_Stone_Brick_Smooth_Half",
      "rotation": 8
    },
    {
      "x": -4,
      "y": 6,
      "z": 4,
      "name": "Rock_Stone_Brick_Smooth"
    },
    {
      "x": -4,
      "y": 12,
      "z": 4,
      "name": "Rock_Stone_Brick_Smooth"
    },
    {
      "x": -4,
      "y": 18,
      "z": 4,
      "name": "Rock_Stone_Brick_Smooth_Half",
      "rotation": 8
    },
    {
      "x": -4,
      "y": 6,
      "z": 5,
      "name": "Rock_Stone_Brick_Smooth"
    },
    {
      "x": -4,
      "y": 7,
      "z": 5,
      "name": "Rock_Stone_Brick_Smooth"
    },
    {
      "x": -4,
      "y": 8,
      "z": 5,
      "name": "Rock_Stone_Brick_Smooth"
    },
    {
      "x": -4,
      "y": 9,
      "z": 5,
      "name": "Rock_Stone_Brick_Smooth"
    },
    {
      "x": -4,
      "y": 10,
      "z": 5,
      "name": "Rock_Stone_Brick_Smooth"
    },
    {
      "x": -4,
      "y": 11,
      "z": 5,
      "name": "Rock_Stone_Brick_Smooth"
    },
    {
      "x": -4,
      "y": 12,
      "z": 5,
      "name": "Rock_Stone_Brick_Smooth"
    },
    {
      "x": -4,
      "y": 18,
      "z": 5,
      "name": "Rock_Stone_Brick"
    },
    {
      "x": -4,
      "y": 22,
      "z": 5,
      "name": "Cloth_Block_Wool_Green",
      "rotation": 2
    },
    {
      "x": -4,
      "y": 12,
      "z": 6,
      "name": "Rock_Stone_Brick_Smooth"
    },
    {
      "x": -4,
      "y": 18,
      "z": 6,
      "name": "Rock_Stone_Brick_Stairs",
      "rotation": 8
    },
    {
      "x": -4,
      "y": 22,
      "z": 6,
      "name": "Cloth_Block_Wool_Pink"
    },
    {
      "x": -4,
      "y": 12,
      "z": 7,
      "name": "Rock_Stone_Brick_Smooth"
    },
    {
      "x": -4,
      "y": 18,
      "z": 7,
      "name": "Rock_Stone_Brick_Stairs",
      "rotation": 10
    },
    {
      "x": -4,
      "y": 13,
      "z": 8,
      "name": "Rock_Stone_Brick_Stairs",
      "rotation": 2
    },
    {
      "x": -4,
      "y": 19,
      "z": 8,
      "name": "Rock_Stone_Brick"
    },
    {
      "x": -4,
      "y": 13,
      "z": 9,
      "name": "Rock_Stone_Brick_Smooth"
    },
    {
      "x": -4,
      "y": 19,
      "z": 9,
      "name": "Rock_Stone_Brick_Smooth_Half",
      "rotation": 8
    },
    {
      "x": -4,
      "y": 13,
      "z": 10,
      "name": "Rock_Stone_Brick_Smooth"
    },
    {
      "x": -4,
      "y": 19,
      "z": 10,
      "name": "Rock_Stone_Brick_Smooth_Half",
      "rotation": 8
    },
    {
      "x": -4,
      "y": 13,
      "z": 11,
      "name": "Rock_Stone_Brick_Smooth"
    },
    {
      "x": -4,
      "y": 19,
      "z": 11,
      "name": "Rock_Stone_Brick_Smooth_Half",
      "rotation": 8
    },
    {
      "x": -4,
      "y": 13,
      "z": 12,
      "name": "Rock_Stone_Brick_Smooth"
    },
    {
      "x": -4,
      "y": 19,
      "z": 12,
      "name": "Rock_Stone_Brick_Smooth_Half",
      "rotation": 8
    },
    {
      "x": -4,
      "y": 13,
      "z": 13,
      "name": "Rock_Stone_Brick_Smooth"
    },
    {
      "x": -4,
      "y": 19,
      "z": 13,
      "name": "Rock_Stone_Brick_Smooth_Half",
      "rotation": 8
    },
    {
      "x": -4,
      "y": 13,
      "z": 14,
      "name": "Rock_Stone_Brick_Smooth"
    },
    {
      "x": -4,
      "y": 14,
      "z": 14,
      "name": "Rock_Stone_Brick_Decorative",
      "rotation": 2
    },
    {
      "x": -4,
      "y": 15,
      "z": 14,
      "name": "Soil_Gravel_Half",
      "rotation": 6
    },
    {
      "x": -4,
      "y": 16,
      "z": 14,
      "name": "Soil_Gravel_Half",
      "rotation": 6
    },
    {
      "x": -4,
      "y": 17,
      "z": 14,
      "name": "Soil_Gravel_Half",
      "rotation": 6
    },
    {
      "x": -4,
      "y": 18,
      "z": 14,
      "name": "Soil_Gravel_Half",
      "rotation": 6
    },
    {
      "x": -4,
      "y": 19,
      "z": 14,
      "name": "Rock_Stone_Brick"
    },
    {
      "x": -4,
      "y": 22,
      "z": 16,
      "name": "Cloth_Block_Wool_Pink"
    },
    {
      "x": -3,
      "y": 15,
      "z": -16,
      "name": "Rock_Stone_Brick"
    },
    {
      "x": -3,
      "y": 16,
      "z": -16,
      "name": "Rock_Stone_Brick_Decorative"
    },
    {
      "x": -3,
      "y": 17,
      "z": -16,
      "name": "Rock_Stone_Brick",
      "rotation": 1
    },
    {
      "x": -3,
      "y": 18,
      "z": -16,
      "name": "Rock_Stone_Brick",
      "rotation": 1
    },
    {
      "x": -3,
      "y": 19,
      "z": -16,
      "name": "Rock_Stone_Brick",
      "rotation": 1
    },
    {
      "x": -3,
      "y": 20,
      "z": -16,
      "name": "Rock_Stone_Brick_Decorative",
      "rotation": 1
    },
    {
      "x": -3,
      "y": 21,
      "z": -16,
      "name": "Rock_Stone_Brick",
      "rotation": 1
    },
    {
      "x": -3,
      "y": 22,
      "z": -16,
      "name": "Cloth_Block_Wool_Pink",
      "rotation": 3
    },
    {
      "x": -3,
      "y": 15,
      "z": -15,
      "name": "Rock_Stone_Brick"
    },
    {
      "x": -3,
      "y": 16,
      "z": -15,
      "name": "Rock_Stone_Brick_Decorative"
    },
    {
      "x": -3,
      "y": 17,
      "z": -15,
      "name": "Soil_Gravel_Half",
      "support": 15,
      "rotation": 7
    },
    {
      "x": -3,
      "y": 18,
      "z": -15,
      "name": "Soil_Gravel_Half",
      "rotation": 7
    },
    {
      "x": -3,
      "y": 19,
      "z": -15,
      "name": "Soil_Gravel_Half",
      "rotation": 7
    },
    {
      "x": -3,
      "y": 20,
      "z": -15,
      "name": "Soil_Gravel_Half",
      "rotation": 7
    },
    {
      "x": -3,
      "y": 21,
      "z": -15,
      "name": "Rock_Stone_Brick",
      "rotation": 1
    },
    {
      "x": -3,
      "y": 15,
      "z": -14,
      "name": "Rock_Stone_Brick",
      "rotation": 3
    },
    {
      "x": -3,
      "y": 16,
      "z": -14,
      "name": "Rock_Stone_Brick_Decorative",
      "rotation": 3
    },
    {
      "x": -3,
      "y": 17,
      "z": -14,
      "name": "Soil_Gravel_Half",
      "rotation": 7
    },
    {
      "x": -3,
      "y": 18,
      "z": -14,
      "name": "Soil_Gravel_Half",
      "rotation": 7
    },
    {
      "x": -3,
      "y": 19,
      "z": -14,
      "name": "Soil_Gravel_Half",
      "rotation": 7
    },
    {
      "x": -3,
      "y": 20,
      "z": -14,
      "name": "Soil_Gravel_Half",
      "rotation": 7
    },
    {
      "x": -3,
      "y": 21,
      "z": -14,
      "name": "Rock_Stone_Brick",
      "rotation": 1
    },
    {
      "x": -3,
      "y": 15,
      "z": -13,
      "name": "Rock_Stone_Brick"
    },
    {
      "x": -3,
      "y": 16,
      "z": -13,
      "name": "Rock_Stone_Brick_Decorative"
    },
    {
      "x": -3,
      "y": 17,
      "z": -13,
      "name": "Soil_Gravel_Half",
      "rotation": 7
    },
    {
      "x": -3,
      "y": 18,
      "z": -13,
      "name": "Soil_Gravel_Half",
      "rotation": 7
    },
    {
      "x": -3,
      "y": 19,
      "z": -13,
      "name": "Soil_Gravel_Half",
      "rotation": 7
    },
    {
      "x": -3,
      "y": 20,
      "z": -13,
      "name": "Soil_Gravel_Half",
      "rotation": 7
    },
    {
      "x": -3,
      "y": 21,
      "z": -13,
      "name": "Rock_Stone_Brick",
      "rotation": 1
    },
    {
      "x": -3,
      "y": 15,
      "z": -12,
      "name": "Rock_Stone_Brick_Decorative",
      "rotation": 2
    },
    {
      "x": -3,
      "y": 16,
      "z": -12,
      "name": "Rock_Stone_Brick_Smooth"
    },
    {
      "x": -3,
      "y": 17,
      "z": -12,
      "name": "Rock_Stone_Brick_Pillar_Base"
    },
    {
      "x": -3,
      "y": 18,
      "z": -12,
      "name": "Rock_Stone_Brick_Pillar_Middle"
    },
    {
      "x": -3,
      "y": 19,
      "z": -12,
      "name": "Rock_Stone_Brick_Pillar_Middle"
    },
    {
      "x": -3,
      "y": 20,
      "z": -12,
      "name": "Rock_Stone_Brick_Pillar_Base",
      "rotation": 8
    },
    {
      "x": -3,
      "y": 21,
      "z": -12,
      "name": "Rock_Stone_Brick",
      "rotation": 1
    },
    {
      "x": -3,
      "y": 14,
      "z": -11,
      "name": "Rock_Stone_Brick_Decorative"
    },
    {
      "x": -3,
      "y": 15,
      "z": -11,
      "name": "Rock_Stone_Brick_Decorative",
      "rotation": 2
    },
    {
      "x": -3,
      "y": 16,
      "z": -11,
      "name": "Soil_Gravel_Half",
      "rotation": 7
    },
    {
      "x": -3,
      "y": 17,
      "z": -11,
      "name": "Soil_Gravel_Half",
      "rotation": 7
    },
    {
      "x": -3,
      "y": 18,
      "z": -11,
      "name": "Soil_Gravel_Half",
      "rotation": 7
    },
    {
      "x": -3,
      "y": 19,
      "z": -11,
      "name": "Soil_Gravel_Half",
      "rotation": 7
    },
    {
      "x": -3,
      "y": 20,
      "z": -11,
      "name": "*Rock_Stone_Brick_Stairs_State_Definitions_Inverted_Corner_Left",
      "rotation": 9
    },
    {
      "x": -3,
      "y": 21,
      "z": -11,
      "name": "Rock_Stone_Brick",
      "rotation": 1
    },
    {
      "x": -3,
      "y": 12,
      "z": -10,
      "name": "Rock_Stone_Brick_Smooth"
    },
    {
      "x": -3,
      "y": 13,
      "z": -10,
      "name": "Rock_Stone_Brick_Decorative",
      "rotation": 2
    },
    {
      "x": -3,
      "y": 14,
      "z": -10,
      "name": "Rock_Stone_Brick_Decorative",
      "rotation": 2
    },
    {
      "x": -3,
      "y": 15,
      "z": -10,
      "name": "Soil_Gravel_Half",
      "rotation": 7
    },
    {
      "x": -3,
      "y": 16,
      "z": -10,
      "name": "Soil_Gravel_Half",
      "rotation": 7
    },
    {
      "x": -3,
      "y": 17,
      "z": -10,
      "name": "Soil_Gravel_Half",
      "rotation": 7
    },
    {
      "x": -3,
      "y": 18,
      "z": -10,
      "name": "Soil_Gravel_Half",
      "rotation": 7
    },
    {
      "x": -3,
      "y": 19,
      "z": -10,
      "name": "*Rock_Stone_Brick_Stairs_State_Definitions_Inverted_Corner_Left",
      "rotation": 9
    },
    {
      "x": -3,
      "y": 20,
      "z": -10,
      "name": "Rock_Stone_Brick",
      "rotation": 2
    },
    {
      "x": -3,
      "y": 21,
      "z": -10,
      "name": "Rock_Stone_Brick",
      "rotation": 1
    },
    {
      "x": -3,
      "y": 12,
      "z": -9,
      "name": "Rock_Stone_Brick_Smooth"
    },
    {
      "x": -3,
      "y": 13,
      "z": -9,
      "name": "Rock_Stone_Brick_Smooth"
    },
    {
      "x": -3,
      "y": 14,
      "z": -9,
      "name": "Rock_Stone_Brick_Pillar_Base",
      "rotation": 2
    },
    {
      "x": -3,
      "y": 15,
      "z": -9,
      "name": "Rock_Stone_Brick_Pillar_Middle",
      "rotation": 10
    },
    {
      "x": -3,
      "y": 16,
      "z": -9,
      "name": "Rock_Stone_Brick_Pillar_Middle",
      "rotation": 10
    },
    {
      "x": -3,
      "y": 17,
      "z": -9,
      "name": "Rock_Stone_Brick_Pillar_Base",
      "rotation": 10
    },
    {
      "x": -3,
      "y": 18,
      "z": -9,
      "name": "Rock_Stone_Brick_Smooth",
      "rotation": 2
    },
    {
      "x": -3,
      "y": 13,
      "z": -8,
      "name": "Rock_Stone_Brick_Decorative"
    },
    {
      "x": -3,
      "y": 14,
      "z": -8,
      "name": "Soil_Gravel_Half",
      "rotation": 7
    },
    {
      "x": -3,
      "y": 15,
      "z": -8,
      "name": "Soil_Gravel_Half",
      "rotation": 7
    },
    {
      "x": -3,
      "y": 16,
      "z": -8,
      "name": "Soil_Gravel_Half",
      "rotation": 7
    },
    {
      "x": -3,
      "y": 17,
      "z": -8,
      "name": "Rock_Stone_Brick_Stairs",
      "rotation": 9
    },
    {
      "x": -3,
      "y": 12,
      "z": -7,
      "name": "Rock_Stone_Brick_Smooth"
    },
    {
      "x": -3,
      "y": 13,
      "z": -7,
      "name": "Rock_Stone_Brick_Decorative"
    },
    {
      "x": -3,
      "y": 14,
      "z": -7,
      "name": "Rock_Stone_Brick"
    },
    {
      "x": -3,
      "y": 15,
      "z": -7,
      "name": "Rock_Stone_Brick"
    },
    {
      "x": -3,
      "y": 16,
      "z": -7,
      "name": "Rock_Stone_Brick"
    },
    {
      "x": -3,
      "y": 17,
      "z": -7,
      "name": "Rock_Stone_Brick"
    },
    {
      "x": -3,
      "y": 18,
      "z": -7,
      "name": "Rock_Stone_Brick"
    },
    {
      "x": -3,
      "y": 12,
      "z": -6,
      "name": "Rock_Stone_Brick_Smooth"
    },
    {
      "x": -3,
      "y": 18,
      "z": -6,
      "name": "Rock_Stone_Brick_Smooth_Half",
      "rotation": 8
    },
    {
      "x": -3,
      "y": 22,
      "z": -6,
      "name": "Cloth_Block_Wool_Pink",
      "rotation": 3
    },
    {
      "x": -3,
      "y": 7,
      "z": -5,
      "name": "Rock_Stone_Brick_Smooth"
    },
    {
      "x": -3,
      "y": 8,
      "z": -5,
      "name": "Rock_Stone_Brick_Smooth"
    },
    {
      "x": -3,
      "y": 9,
      "z": -5,
      "name": "Rock_Stone_Brick_Smooth"
    },
    {
      "x": -3,
      "y": 10,
      "z": -5,
      "name": "Rock_Stone_Brick_Smooth"
    },
    {
      "x": -3,
      "y": 11,
      "z": -5,
      "name": "Rock_Stone_Brick_Smooth"
    },
    {
      "x": -3,
      "y": 12,
      "z": -5,
      "name": "Rock_Stone_Brick_Smooth"
    },
    {
      "x": -3,
      "y": 18,
      "z": -5,
      "name": "Rock_Stone_Brick_Smooth_Half",
      "rotation": 8
    },
    {
      "x": -3,
      "y": 22,
      "z": -5,
      "name": "Cloth_Block_Wool_Green",
      "rotation": 2
    },
    {
      "x": -3,
      "y": 6,
      "z": -4,
      "name": "Rock_Stone_Brick_Smooth"
    },
    {
      "x": -3,
      "y": 12,
      "z": -4,
      "name": "Rock_Stone_Brick_Smooth"
    },
    {
      "x": -3,
      "y": 18,
      "z": -4,
      "name": "Rock_Stone_Brick_Smooth_Half",
      "rotation": 8
    },
    {
      "x": -3,
      "y": 6,
      "z": -3,
      "name": "Rock_Stone_Brick_Smooth"
    },
    {
      "x": -3,
      "y": 12,
      "z": -3,
      "name": "Rock_Stone_Brick_Smooth"
    },
    {
      "x": -3,
      "y": 18,
      "z": -3,
      "name": "Rock_Stone_Brick"
    },
    {
      "x": -3,
      "y": 6,
      "z": -2,
      "name": "Rock_Stone_Brick_Smooth"
    },
    {
      "x": -3,
      "y": 12,
      "z": -2,
      "name": "Rock_Stone_Brick_Smooth"
    },
    {
      "x": -3,
      "y": 18,
      "z": -2,
      "name": "Rock_Stone_Brick_Smooth_Half",
      "rotation": 8
    },
    {
      "x": -3,
      "y": 6,
      "z": -1,
      "name": "Rock_Stone_Brick_Smooth"
    },
    {
      "x": -3,
      "y": 12,
      "z": -1,
      "name": "Rock_Stone_Brick_Smooth"
    },
    {
      "x": -3,
      "y": 18,
      "z": -1,
      "name": "Rock_Stone_Brick_Smooth_Half",
      "rotation": 8
    },
    {
      "x": -3,
      "y": 6,
      "z": 0,
      "name": "Rock_Stone_Brick_Smooth"
    },
    {
      "x": -3,
      "y": 12,
      "z": 0,
      "name": "Rock_Stone_Brick_Smooth"
    },
    {
      "x": -3,
      "y": 18,
      "z": 0,
      "name": "Rock_Stone_Brick_Smooth_Half",
      "rotation": 8
    },
    {
      "x": -3,
      "y": 6,
      "z": 1,
      "name": "Rock_Stone_Brick_Smooth"
    },
    {
      "x": -3,
      "y": 12,
      "z": 1,
      "name": "Rock_Stone_Brick_Smooth"
    },
    {
      "x": -3,
      "y": 18,
      "z": 1,
      "name": "Rock_Stone_Brick"
    },
    {
      "x": -3,
      "y": 6,
      "z": 2,
      "name": "Rock_Stone_Brick_Smooth"
    },
    {
      "x": -3,
      "y": 12,
      "z": 2,
      "name": "Rock_Stone_Brick_Smooth"
    },
    {
      "x": -3,
      "y": 18,
      "z": 2,
      "name": "Rock_Stone_Brick_Smooth_Half",
      "rotation": 8
    },
    {
      "x": -3,
      "y": 6,
      "z": 3,
      "name": "Rock_Stone_Brick_Smooth"
    },
    {
      "x": -3,
      "y": 12,
      "z": 3,
      "name": "Rock_Stone_Brick_Smooth"
    },
    {
      "x": -3,
      "y": 18,
      "z": 3,
      "name": "Rock_Stone_Brick_Smooth_Half",
      "rotation": 8
    },
    {
      "x": -3,
      "y": 6,
      "z": 4,
      "name": "Rock_Stone_Brick_Smooth"
    },
    {
      "x": -3,
      "y": 12,
      "z": 4,
      "name": "Rock_Stone_Brick_Smooth"
    },
    {
      "x": -3,
      "y": 18,
      "z": 4,
      "name": "Rock_Stone_Brick_Smooth_Half",
      "rotation": 8
    },
    {
      "x": -3,
      "y": 6,
      "z": 5,
      "name": "Rock_Stone_Brick_Smooth"
    },
    {
      "x": -3,
      "y": 7,
      "z": 5,
      "name": "Rock_Stone_Brick_Smooth"
    },
    {
      "x": -3,
      "y": 8,
      "z": 5,
      "name": "Rock_Stone_Brick_Smooth"
    },
    {
      "x": -3,
      "y": 9,
      "z": 5,
      "name": "Rock_Stone_Brick_Smooth"
    },
    {
      "x": -3,
      "y": 10,
      "z": 5,
      "name": "Rock_Stone_Brick_Smooth"
    },
    {
      "x": -3,
      "y": 11,
      "z": 5,
      "name": "Rock_Stone_Brick_Smooth"
    },
    {
      "x": -3,
      "y": 12,
      "z": 5,
      "name": "Rock_Stone_Brick_Smooth"
    },
    {
      "x": -3,
      "y": 18,
      "z": 5,
      "name": "Rock_Stone_Brick"
    },
    {
      "x": -3,
      "y": 22,
      "z": 5,
      "name": "Cloth_Block_Wool_Green",
      "rotation": 2
    },
    {
      "x": -3,
      "y": 12,
      "z": 6,
      "name": "Rock_Stone_Brick_Smooth"
    },
    {
      "x": -3,
      "y": 13,
      "z": 6,
      "name": "Rock_Stone_Brick_Decorative"
    },
    {
      "x": -3,
      "y": 14,
      "z": 6,
      "name": "Rock_Stone_Brick"
    },
    {
      "x": -3,
      "y": 15,
      "z": 6,
      "name": "Rock_Stone_Brick"
    },
    {
      "x": -3,
      "y": 16,
      "z": 6,
      "name": "Rock_Stone_Brick"
    },
    {
      "x": -3,
      "y": 17,
      "z": 6,
      "name": "Rock_Stone_Brick"
    },
    {
      "x": -3,
      "y": 18,
