{
  "version": 8,
  "blockIdVersion": 11,
  "anchorX": 1,
  "anchorY": 7,
  "anchorZ": 0,
  "blocks": [
    {
      "x": -8,
      "y": 1,
      "z": -5,
      "name": "Rock_Stone_Brick"
    },
    {
      "x": -8,
      "y": 2,
      "z": -5,
      "name": "Rock_Stone_Brick_Decorative",
      "rotation": 1
    },
    {
      "x": -8,
      "y": 3,
      "z": -5,
      "name": "Soil_Gravel",
      "support": 15,
      "rotation": 1
    },
    {
      "x": -8,
      "y": 4,
      "z": -5,
      "name": "Soil_Gravel",
      "support": 15,
      "rotation": 1
    },
    {
      "x": -8,
      "y": 5,
      "z": -5,
      "name": "Soil_Gravel",
      "support": 15,
      "rotation": 1
    },
    {
      "x": -8,
      "y": 6,
      "z": -5,
      "name": "Soil_Gravel",
      "support": 15,
      "rotation": 1
    },
    {
      "x": -8,
      "y": 7,
      "z": -5,
      "name": "Rock_Stone_Brick_Smooth",
      "rotation": 1
    },
    {
      "x": -8,
      "y": 1,
      "z": -4,
      "name": "Rock_Stone_Brick"
    },
    {
      "x": -8,
      "y": 2,
      "z": -4,
      "name": "Rock_Stone_Brick_Decorative",
      "rotation": 1
    },
    {
      "x": -8,
      "y": 3,
      "z": -4,
      "name": "Soil_Gravel",
      "support": 15,
      "rotation": 1
    },
    {
      "x": -8,
      "y": 4,
      "z": -4,
      "name": "Soil_Gravel",
      "support": 15,
      "rotation": 1
    },
    {
      "x": -8,
      "y": 5,
      "z": -4,
      "name": "Soil_Gravel",
      "support": 15,
      "rotation": 1
    },
    {
      "x": -8,
      "y": 6,
      "z": -4,
      "name": "Soil_Gravel",
      "support": 15,
      "rotation": 1
    },
    {
      "x": -8,
      "y": 7,
      "z": -4,
      "name": "Rock_Stone_Brick_Smooth",
      "rotation": 1
    },
    {
      "x": -8,
      "y": 1,
      "z": -3,
      "name": "Rock_Stone_Brick"
    },
    {
      "x": -8,
      "y": 2,
      "z": -3,
      "name": "Rock_Stone_Brick_Decorative",
      "rotation": 1
    },
    {
      "x": -8,
      "y": 3,
      "z": -3,
      "name": "Soil_Gravel",
      "support": 15,
      "rotation": 1
    },
    {
      "x": -8,
      "y": 4,
      "z": -3,
      "name": "Soil_Gravel",
      "support": 15,
      "rotation": 1
    },
    {
      "x": -8,
      "y": 5,
      "z": -3,
      "name": "Soil_Gravel",
      "support": 15,
      "rotation": 1
    },
    {
      "x": -8,
      "y": 6,
      "z": -3,
      "name": "Soil_Gravel",
      "support": 15,
      "rotation": 1
    },
    {
      "x": -8,
      "y": 7,
      "z": -3,
      "name": "Rock_Stone_Brick_Smooth",
      "rotation": 1
    },
    {
      "x": -8,
      "y": 1,
      "z": -2,
      "name": "Rock_Stone_Brick"
    },
    {
      "x": -8,
      "y": 2,
      "z": -2,
      "name": "Rock_Stone_Brick_Decorative",
      "rotation": 1
    },
    {
      "x": -8,
      "y": 3,
      "z": -2,
      "name": "Soil_Gravel",
      "support": 15,
      "rotation": 1
    },
    {
      "x": -8,
      "y": 4,
      "z": -2,
      "name": "Soil_Gravel",
      "support": 15,
      "rotation": 1
    },
    {
      "x": -8,
      "y": 5,
      "z": -2,
      "name": "Soil_Gravel",
      "support": 15,
      "rotation": 1
    },
    {
      "x": -8,
      "y": 6,
      "z": -2,
      "name": "Soil_Gravel",
      "support": 15,
      "rotation": 1
    },
    {
      "x": -8,
      "y": 7,
      "z": -2,
      "name": "Rock_Stone_Brick_Smooth",
      "rotation": 1
    },
    {
      "x": -8,
      "y": 1,
      "z": -1,
      "name": "Rock_Stone_Brick"
    },
    {
      "x": -8,
      "y": 2,
      "z": -1,
      "name": "Rock_Stone_Brick_Decorative",
      "rotation": 1
    },
    {
      "x": -8,
      "y": 3,
      "z": -1,
      "name": "Soil_Gravel",
      "support": 15,
      "rotation": 1
    },
    {
      "x": -8,
      "y": 4,
      "z": -1,
      "name": "Soil_Gravel",
      "support": 15,
      "rotation": 1
    },
    {
      "x": -8,
      "y": 5,
      "z": -1,
      "name": "Soil_Gravel",
      "support": 15,
      "rotation": 1
    },
    {
      "x": -8,
      "y": 6,
      "z": -1,
      "name": "Soil_Gravel",
      "support": 15,
      "rotation": 1
    },
    {
      "x": -8,
      "y": 7,
      "z": -1,
      "name": "Rock_Stone_Brick_Smooth",
      "rotation": 1
    },
    {
      "x": -8,
      "y": 1,
      "z": 0,
      "name": "Rock_Stone_Brick"
    },
    {
      "x": -8,
      "y": 2,
      "z": 0,
      "name": "Rock_Stone_Brick_Decorative"
    },
    {
      "x": -8,
      "y": 3,
      "z": 0,
      "name": "Soil_Gravel",
      "support": 15
    },
    {
      "x": -8,
      "y": 4,
      "z": 0,
      "name": "Soil_Gravel",
      "support": 15
    },
    {
      "x": -8,
      "y": 5,
      "z": 0,
      "name": "Soil_Gravel",
      "support": 15
    },
    {
      "x": -8,
      "y": 6,
      "z": 0,
      "name": "Soil_Gravel",
      "support": 15
    },
    {
      "x": -8,
      "y": 7,
      "z": 0,
      "name": "Rock_Stone_Brick_Smooth"
    },
    {
      "x": -8,
      "y": 1,
      "z": 1,
      "name": "Rock_Stone_Brick",
      "rotation": 1
    },
    {
      "x": -8,
      "y": 2,
      "z": 1,
      "name": "Rock_Stone_Brick_Decorative",
      "rotation": 2
    },
    {
      "x": -8,
      "y": 3,
      "z": 1,
      "name": "Soil_Gravel",
      "support": 15,
      "rotation": 2
    },
    {
      "x": -8,
      "y": 4,
      "z": 1,
      "name": "Soil_Gravel",
      "support": 15,
      "rotation": 2
    },
    {
      "x": -8,
      "y": 5,
      "z": 1,
      "name": "Soil_Gravel",
      "support": 15,
      "rotation": 2
    },
    {
      "x": -8,
      "y": 6,
      "z": 1,
      "name": "Soil_Gravel",
      "support": 15,
      "rotation": 2
    },
    {
      "x": -8,
      "y": 7,
      "z": 1,
      "name": "Rock_Stone_Brick_Smooth",
      "rotation": 2
    },
    {
      "x": -8,
      "y": 1,
      "z": 2,
      "name": "Rock_Stone_Brick",
      "rotation": 1
    },
    {
      "x": -8,
      "y": 2,
      "z": 2,
      "name": "Rock_Stone_Brick_Decorative",
      "rotation": 2
    },
    {
      "x": -8,
      "y": 3,
      "z": 2,
      "name": "Soil_Gravel",
      "support": 15,
      "rotation": 2
    },
    {
      "x": -8,
      "y": 4,
      "z": 2,
      "name": "Soil_Gravel",
      "support": 15,
      "rotation": 2
    },
    {
      "x": -8,
      "y": 5,
      "z": 2,
      "name": "Soil_Gravel",
      "support": 15,
      "rotation": 2
    },
    {
      "x": -8,
      "y": 6,
      "z": 2,
      "name": "Soil_Gravel",
      "support": 15,
      "rotation": 2
    },
    {
      "x": -8,
      "y": 7,
      "z": 2,
      "name": "Rock_Stone_Brick_Smooth",
      "rotation": 2
    },
    {
      "x": -8,
      "y": 1,
      "z": 3,
      "name": "Rock_Stone_Brick",
      "rotation": 1
    },
    {
      "x": -8,
      "y": 2,
      "z": 3,
      "name": "Rock_Stone_Brick_Decorative",
      "rotation": 2
    },
    {
      "x": -8,
      "y": 3,
      "z": 3,
      "name": "Soil_Gravel",
      "support": 15,
      "rotation": 2
    },
    {
      "x": -8,
      "y": 4,
      "z": 3,
      "name": "Soil_Gravel",
      "support": 15,
      "rotation": 2
    },
    {
      "x": -8,
      "y": 5,
      "z": 3,
      "name": "Soil_Gravel",
      "support": 15,
      "rotation": 2
    },
    {
      "x": -8,
      "y": 6,
      "z": 3,
      "name": "Soil_Gravel",
      "support": 15,
      "rotation": 2
    },
    {
      "x": -8,
      "y": 7,
      "z": 3,
      "name": "Rock_Stone_Brick_Smooth",
      "rotation": 2
    },
    {
      "x": -8,
      "y": 1,
      "z": 4,
      "name": "Rock_Stone_Brick",
      "rotation": 1
    },
    {
      "x": -8,
      "y": 2,
      "z": 4,
      "name": "Rock_Stone_Brick_Decorative",
      "rotation": 2
    },
    {
      "x": -8,
      "y": 3,
      "z": 4,
      "name": "Soil_Gravel",
      "support": 15,
      "rotation": 2
    },
    {
      "x": -8,
      "y": 4,
      "z": 4,
      "name": "Soil_Gravel",
      "support": 15,
      "rotation": 2
    },
    {
      "x": -8,
      "y": 5,
      "z": 4,
      "name": "Soil_Gravel",
      "support": 15,
      "rotation": 2
    },
    {
      "x": -8,
      "y": 6,
      "z": 4,
      "name": "Soil_Gravel",
      "support": 15,
      "rotation": 2
    },
    {
      "x": -8,
      "y": 7,
      "z": 4,
      "name": "Rock_Stone_Brick_Smooth",
      "rotation": 2
    },
    {
      "x": -8,
      "y": 1,
      "z": 5,
      "name": "Rock_Stone_Brick",
      "rotation": 1
    },
    {
      "x": -8,
      "y": 2,
      "z": 5,
      "name": "Rock_Stone_Brick_Decorative",
      "rotation": 1
    },
    {
      "x": -8,
      "y": 3,
      "z": 5,
      "name": "*Soil_Gravel_Half_State_Definitions_Block",
      "rotation": 7
    },
    {
      "x": -8,
      "y": 4,
      "z": 5,
      "name": "*Soil_Gravel_Half_State_Definitions_Block",
      "rotation": 7
    },
    {
      "x": -8,
      "y": 5,
      "z": 5,
      "name": "*Soil_Gravel_Half_State_Definitions_Block",
      "rotation": 7
    },
    {
      "x": -8,
      "y": 6,
      "z": 5,
      "name": "*Soil_Gravel_Half_State_Definitions_Block",
      "rotation": 7
    },
    {
      "x": -8,
      "y": 7,
      "z": 5,
      "name": "Rock_Stone_Brick_Smooth",
      "rotation": 1
    },
    {
      "x": -7,
      "y": 1,
      "z": -7,
      "name": "Rock_Stone_Brick"
    },
    {
      "x": -7,
      "y": 2,
      "z": -7,
      "name": "Rock_Stone_Brick_Decorative",
      "rotation": 1
    },
    {
      "x": -7,
      "y": 3,
      "z": -7,
      "name": "Soil_Gravel",
      "support": 15,
      "rotation": 1
    },
    {
      "x": -7,
      "y": 4,
      "z": -7,
      "name": "Soil_Gravel",
      "support": 15,
      "rotation": 1
    },
    {
      "x": -7,
      "y": 5,
      "z": -7,
      "name": "Soil_Gravel",
      "support": 15,
      "rotation": 1
    },
    {
      "x": -7,
      "y": 6,
      "z": -7,
      "name": "Soil_Gravel",
      "support": 15,
      "rotation": 1
    },
    {
      "x": -7,
      "y": 7,
      "z": -7,
      "name": "Rock_Stone_Brick_Smooth",
      "rotation": 1
    },
    {
      "x": -7,
      "y": 1,
      "z": -6,
      "name": "Rock_Stone_Brick"
    },
    {
      "x": -7,
      "y": 2,
      "z": -6,
      "name": "Rock_Stone_Brick_Decorative",
      "rotation": 1
    },
    {
      "x": -7,
      "y": 3,
      "z": -6,
      "name": "Soil_Gravel",
      "support": 15,
      "rotation": 1
    },
    {
      "x": -7,
      "y": 4,
      "z": -6,
      "name": "Soil_Gravel",
      "support": 15,
      "rotation": 1
    },
    {
      "x": -7,
      "y": 5,
      "z": -6,
      "name": "Soil_Gravel",
      "support": 15,
      "rotation": 1
    },
    {
      "x": -7,
      "y": 6,
      "z": -6,
      "name": "Soil_Gravel",
      "support": 15,
      "rotation": 1
    },
    {
      "x": -7,
      "y": 7,
      "z": -6,
      "name": "Rock_Stone_Brick_Smooth",
      "rotation": 1
    },
    {
      "x": -7,
      "y": 1,
      "z": -5,
      "name": "Rock_Stone_Brick_Smooth"
    },
    {
      "x": -7,
      "y": 2,
      "z": -5,
      "name": "Rock_Stone_Brick_Decorative",
      "rotation": 1
    },
    {
      "x": -7,
      "y": 3,
      "z": -5,
      "name": "Soil_Gravel_Half",
      "support": 15,
      "rotation": 5
    },
    {
      "x": -7,
      "y": 4,
      "z": -5,
      "name": "Soil_Gravel_Half",
      "support": 15,
      "rotation": 5
    },
    {
      "x": -7,
      "y": 5,
      "z": -5,
      "name": "Soil_Gravel_Half",
      "support": 15,
      "rotation": 5
    },
    {
      "x": -7,
      "y": 6,
      "z": -5,
      "name": "Soil_Gravel_Half",
      "support": 15,
      "rotation": 5
    },
    {
      "x": -7,
      "y": 7,
      "z": -5,
      "name": "Rock_Stone_Brick"
    },
    {
      "x": -7,
      "y": 1,
      "z": -4,
      "name": "Rock_Stone_Brick",
      "rotation": 1
    },
    {
      "x": -7,
      "y": 2,
      "z": -4,
      "name": "Rock_Stone_Brick_Decorative",
      "rotation": 1
    },
    {
      "x": -7,
      "y": 3,
      "z": -4,
      "name": "Rock_Stone_Brick_Pillar_Base",
      "rotation": 1
    },
    {
      "x": -7,
      "y": 4,
      "z": -4,
      "name": "Rock_Stone_Brick_Pillar_Middle",
      "rotation": 1
    },
    {
      "x": -7,
      "y": 5,
      "z": -4,
      "name": "Rock_Stone_Brick_Pillar_Middle",
      "rotation": 1
    },
    {
      "x": -7,
      "y": 6,
      "z": -4,
      "name": "Rock_Stone_Brick_Pillar_Base",
      "rotation": 35
    },
    {
      "x": -7,
      "y": 7,
      "z": -4,
      "name": "Rock_Stone_Brick"
    },
    {
      "x": -7,
      "y": 1,
      "z": -3,
      "name": "Rock_Stone_Brick",
      "rotation": 1
    },
    {
      "x": -7,
      "y": 2,
      "z": -3,
      "name": "Rock_Stone_Brick_Decorative",
      "rotation": 1
    },
    {
      "x": -7,
      "y": 3,
      "z": -3,
      "name": "Soil_Gravel_Half",
      "support": 15,
      "rotation": 5
    },
    {
      "x": -7,
      "y": 4,
      "z": -3,
      "name": "Soil_Gravel_Half",
      "support": 15,
      "rotation": 5
    },
    {
      "x": -7,
      "y": 5,
      "z": -3,
      "name": "Soil_Gravel_Half",
      "support": 15,
      "rotation": 5
    },
    {
      "x": -7,
      "y": 6,
      "z": -3,
      "name": "Soil_Gravel_Half",
      "support": 15,
      "rotation": 5
    },
    {
      "x": -7,
      "y": 7,
      "z": -3,
      "name": "Rock_Stone_Brick"
    },
    {
      "x": -7,
      "y": 1,
      "z": -2,
      "name": "Rock_Stone_Brick",
      "rotation": 1
    },
    {
      "x": -7,
      "y": 2,
      "z": -2,
      "name": "Rock_Stone_Brick_Decorative",
      "rotation": 1
    },
    {
      "x": -7,
      "y": 3,
      "z": -2,
      "name": "Soil_Gravel_Half",
      "support": 15,
      "rotation": 5
    },
    {
      "x": -7,
      "y": 4,
      "z": -2,
      "name": "Soil_Gravel_Half",
      "support": 15,
      "rotation": 5
    },
    {
      "x": -7,
      "y": 5,
      "z": -2,
      "name": "Soil_Gravel_Half",
      "support": 15,
      "rotation": 5
    },
    {
      "x": -7,
      "y": 6,
      "z": -2,
      "name": "Soil_Gravel_Half",
      "support": 15,
      "rotation": 5
    },
    {
      "x": -7,
      "y": 7,
      "z": -2,
      "name": "Rock_Stone_Brick"
    },
    {
      "x": -7,
      "y": 1,
      "z": -1,
      "name": "Rock_Stone_Brick",
      "rotation": 1
    },
    {
      "x": -7,
      "y": 2,
      "z": -1,
      "name": "Rock_Stone_Brick_Decorative",
      "rotation": 1
    },
    {
      "x": -7,
      "y": 3,
      "z": -1,
      "name": "Soil_Gravel_Half",
      "support": 15,
      "rotation": 5
    },
    {
      "x": -7,
      "y": 4,
      "z": -1,
      "name": "Soil_Gravel_Half",
      "support": 15,
      "rotation": 5
    },
    {
      "x": -7,
      "y": 5,
      "z": -1,
      "name": "Soil_Gravel_Half",
      "support": 15,
      "rotation": 5
    },
    {
      "x": -7,
      "y": 6,
      "z": -1,
      "name": "Soil_Gravel_Half",
      "support": 15,
      "rotation": 5
    },
    {
      "x": -7,
      "y": 7,
      "z": -1,
      "name": "Rock_Stone_Brick"
    },
    {
      "x": -7,
      "y": 1,
      "z": 0,
      "name": "Rock_Stone_Brick"
    },
    {
      "x": -7,
      "y": 2,
      "z": 0,
      "name": "Rock_Stone_Brick_Decorative"
    },
    {
      "x": -7,
      "y": 3,
      "z": 0,
      "name": "Rock_Stone_Brick_Pillar_Base"
    },
    {
      "x": -7,
      "y": 4,
      "z": 0,
      "name": "Rock_Stone_Brick_Pillar_Middle"
    },
    {
      "x": -7,
      "y": 5,
      "z": 0,
      "name": "Rock_Stone_Brick_Pillar_Middle",
      "rotation": 8
    },
    {
      "x": -7,
      "y": 6,
      "z": 0,
      "name": "Rock_Stone_Brick_Pillar_Base",
      "rotation": 8
    },
    {
      "x": -7,
      "y": 7,
      "z": 0,
      "name": "Rock_Stone_Brick"
    },
    {
      "x": -7,
      "y": 1,
      "z": 1,
      "name": "Rock_Stone_Brick",
      "rotation": 2
    },
    {
      "x": -7,
      "y": 2,
      "z": 1,
      "name": "Rock_Stone_Brick_Decorative",
      "rotation": 2
    },
    {
      "x": -7,
      "y": 3,
      "z": 1,
      "name": "Soil_Gravel_Half",
      "support": 15,
      "rotation": 5
    },
    {
      "x": -7,
      "y": 4,
      "z": 1,
      "name": "Soil_Gravel_Half",
      "support": 15,
      "rotation": 5
    },
    {
      "x": -7,
      "y": 5,
      "z": 1,
      "name": "Soil_Gravel_Half",
      "support": 15,
      "rotation": 5
    },
    {
      "x": -7,
      "y": 6,
      "z": 1,
      "name": "Soil_Gravel_Half",
      "support": 15,
      "rotation": 5
    },
    {
      "x": -7,
      "y": 7,
      "z": 1,
      "name": "Rock_Stone_Brick",
      "rotation": 1
    },
    {
      "x": -7,
      "y": 1,
      "z": 2,
      "name": "Rock_Stone_Brick",
      "rotation": 2
    },
    {
      "x": -7,
      "y": 2,
      "z": 2,
      "name": "Rock_Stone_Brick_Decorative",
      "rotation": 2
    },
    {
      "x": -7,
      "y": 3,
      "z": 2,
      "name": "Soil_Gravel_Half",
      "support": 15,
      "rotation": 5
    },
    {
      "x": -7,
      "y": 4,
      "z": 2,
      "name": "Soil_Gravel_Half",
      "support": 15,
      "rotation": 5
    },
    {
      "x": -7,
      "y": 5,
      "z": 2,
      "name": "Soil_Gravel_Half",
      "support": 15,
      "rotation": 5
    },
    {
      "x": -7,
      "y": 6,
      "z": 2,
      "name": "Soil_Gravel_Half",
      "support": 15,
      "rotation": 5
    },
    {
      "x": -7,
      "y": 7,
      "z": 2,
      "name": "Rock_Stone_Brick",
      "rotation": 1
    },
    {
      "x": -7,
      "y": 1,
      "z": 3,
      "name": "Rock_Stone_Brick",
      "rotation": 2
    },
    {
      "x": -7,
      "y": 2,
      "z": 3,
      "name": "Rock_Stone_Brick_Decorative",
      "rotation": 2
    },
    {
      "x": -7,
      "y": 3,
      "z": 3,
      "name": "Soil_Gravel_Half",
      "support": 15,
      "rotation": 5
    },
    {
      "x": -7,
      "y": 4,
      "z": 3,
      "name": "Soil_Gravel_Half",
      "support": 15,
      "rotation": 5
    },
    {
      "x": -7,
      "y": 5,
      "z": 3,
      "name": "Soil_Gravel_Half",
      "support": 15,
      "rotation": 5
    },
    {
      "x": -7,
      "y": 6,
      "z": 3,
      "name": "Soil_Gravel_Half",
      "support": 15,
      "rotation": 5
    },
    {
      "x": -7,
      "y": 7,
      "z": 3,
      "name": "Rock_Stone_Brick",
      "rotation": 1
    },
    {
      "x": -7,
      "y": 1,
      "z": 4,
      "name": "Rock_Stone_Brick",
      "rotation": 2
    },
    {
      "x": -7,
      "y": 2,
      "z": 4,
      "name": "Rock_Stone_Brick_Decorative",
      "rotation": 2
    },
    {
      "x": -7,
      "y": 3,
      "z": 4,
      "name": "Rock_Stone_Brick_Pillar_Base",
      "rotation": 2
    },
    {
      "x": -7,
      "y": 4,
      "z": 4,
      "name": "Rock_Stone_Brick_Pillar_Middle",
      "rotation": 2
    },
    {
      "x": -7,
      "y": 5,
      "z": 4,
      "name": "Rock_Stone_Brick_Pillar_Middle",
      "rotation": 2
    },
    {
      "x": -7,
      "y": 6,
      "z": 4,
      "name": "Rock_Stone_Brick_Pillar_Base",
      "rotation": 32
    },
    {
      "x": -7,
      "y": 7,
      "z": 4,
      "name": "Rock_Stone_Brick",
      "rotation": 1
    },
    {
      "x": -7,
      "y": 1,
      "z": 5,
      "name": "Rock_Stone_Brick",
      "rotation": 2
    },
    {
      "x": -7,
      "y": 2,
      "z": 5,
      "name": "Rock_Stone_Brick_Decorative",
      "rotation": 2
    },
    {
      "x": -7,
      "y": 3,
      "z": 5,
      "name": "Soil_Gravel_Half",
      "support": 15,
      "rotation": 5
    },
    {
      "x": -7,
      "y": 4,
      "z": 5,
      "name": "Soil_Gravel_Half",
      "support": 15,
      "rotation": 5
    },
    {
      "x": -7,
      "y": 5,
      "z": 5,
      "name": "Soil_Gravel_Half",
      "support": 15,
      "rotation": 5
    },
    {
      "x": -7,
      "y": 6,
      "z": 5,
      "name": "Soil_Gravel_Half",
      "support": 15,
      "rotation": 5
    },
    {
      "x": -7,
      "y": 7,
      "z": 5,
      "name": "Rock_Stone_Brick",
      "rotation": 1
    },
    {
      "x": -7,
      "y": 1,
      "z": 6,
      "name": "Rock_Stone_Brick",
      "rotation": 1
    },
    {
      "x": -7,
      "y": 2,
      "z": 6,
      "name": "Rock_Stone_Brick_Decorative",
      "rotation": 2
    },
    {
      "x": -7,
      "y": 3,
      "z": 6,
      "name": "Soil_Gravel",
      "support": 15,
      "rotation": 2
    },
    {
      "x": -7,
      "y": 4,
      "z": 6,
      "name": "Soil_Gravel",
      "support": 15,
      "rotation": 2
    },
    {
      "x": -7,
      "y": 5,
      "z": 6,
      "name": "Soil_Gravel",
      "support": 15,
      "rotation": 2
    },
    {
      "x": -7,
      "y": 6,
      "z": 6,
      "name": "Soil_Gravel",
      "support": 15,
      "rotation": 2
    },
    {
      "x": -7,
      "y": 7,
      "z": 6,
      "name": "Rock_Stone_Brick_Smooth",
      "rotation": 2
    },
    {
      "x": -7,
      "y": 1,
      "z": 7,
      "name": "Rock_Stone_Brick",
      "rotation": 1
    },
    {
      "x": -7,
      "y": 2,
      "z": 7,
      "name": "Rock_Stone_Brick_Decorative",
      "rotation": 2
    },
    {
      "x": -7,
      "y": 3,
      "z": 7,
      "name": "Soil_Gravel",
      "support": 15,
      "rotation": 2
    },
    {
      "x": -7,
      "y": 4,
      "z": 7,
      "name": "Soil_Gravel",
      "support": 15,
      "rotation": 2
    },
    {
      "x": -7,
      "y": 5,
      "z": 7,
      "name": "Soil_Gravel",
      "support": 15,
      "rotation": 2
    },
    {
      "x": -7,
      "y": 6,
      "z": 7,
      "name": "Soil_Gravel",
      "support": 15,
      "rotation": 2
    },
    {
      "x": -7,
      "y": 7,
      "z": 7,
      "name": "Rock_Stone_Brick_Smooth",
      "rotation": 2
    },
    {
      "x": -6,
      "y": 1,
      "z": -9,
      "name": "Rock_Stone_Brick"
    },
    {
      "x": -6,
      "y": 2,
      "z": -9,
      "name": "Rock_Stone_Brick_Decorative",
      "rotation": 1
    },
    {
      "x": -6,
      "y": 3,
      "z": -9,
      "name": "Soil_Gravel",
      "support": 15,
      "rotation": 1
    },
    {
      "x": -6,
      "y": 4,
      "z": -9,
      "name": "Soil_Gravel",
      "support": 15,
      "rotation": 1
    },
    {
      "x": -6,
      "y": 5,
      "z": -9,
      "name": "Soil_Gravel",
      "support": 15,
      "rotation": 1
    },
    {
      "x": -6,
      "y": 6,
      "z": -9,
      "name": "Soil_Gravel",
      "support": 15,
      "rotation": 1
    },
    {
      "x": -6,
      "y": 7,
      "z": -9,
      "name": "Rock_Stone_Brick_Smooth",
      "rotation": 1
    },
    {
      "x": -6,
      "y": 1,
      "z": -8,
      "name": "Rock_Stone_Brick"
    },
    {
      "x": -6,
      "y": 2,
      "z": -8,
      "name": "Rock_Stone_Brick_Decorative",
      "rotation": 1
    },
    {
      "x": -6,
      "y": 3,
      "z": -8,
      "name": "Soil_Gravel",
      "support": 15,
      "rotation": 1
    },
    {
      "x": -6,
      "y": 4,
      "z": -8,
      "name": "Soil_Gravel",
      "support": 15,
      "rotation": 1
    },
    {
      "x": -6,
      "y": 5,
      "z": -8,
      "name": "Soil_Gravel",
      "support": 15,
      "rotation": 1
    },
    {
      "x": -6,
      "y": 6,
      "z": -8,
      "name": "Soil_Gravel",
      "support": 15,
      "rotation": 1
    },
    {
      "x": -6,
      "y": 7,
      "z": -8,
      "name": "Rock_Stone_Brick_Smooth"
    },
    {
      "x": -6,
      "y": 1,
      "z": -7,
      "name": "Rock_Stone_Brick",
      "rotation": 1
    },
    {
      "x": -6,
      "y": 2,
      "z": -7,
      "name": "Rock_Stone_Brick_Decorative",
      "rotation": 1
    },
    {
      "x": -6,
      "y": 3,
      "z": -7,
      "name": "Rock_Stone_Brick_Pillar_Base",
      "rotation": 1
    },
    {
      "x": -6,
      "y": 4,
      "z": -7,
      "name": "Rock_Stone_Brick_Pillar_Middle",
      "rotation": 1
    },
    {
      "x": -6,
      "y": 5,
      "z": -7,
      "name": "Rock_Stone_Brick_Pillar_Middle",
      "rotation": 1
    },
    {
      "x": -6,
      "y": 6,
      "z": -7,
      "name": "Rock_Stone_Brick_Pillar_Base",
      "rotation": 35
    },
    {
      "x": -6,
      "y": 7,
      "z": -7,
      "name": "Rock_Stone_Brick"
    },
    {
      "x": -6,
      "y": 1,
      "z": -6,
      "name": "Rock_Stone_Brick_Smooth",
      "rotation": 1
    },
    {
      "x": -6,
      "y": 2,
      "z": -6,
      "name": "Rock_Stone_Brick_Half",
      "rotation": 5
    },
    {
      "x": -6,
      "y": 7,
      "z": -6,
      "name": "Rock_Stone_Brick_Smooth",
      "rotation": 1
    },
    {
      "x": -6,
      "y": 1,
      "z": -5,
      "name": "Rock_Stone_Brick_Smooth",
      "rotation": 1
    },
    {
      "x": -6,
      "y": 7,
      "z": -5,
      "name": "Rock_Stone_Brick_Smooth",
      "rotation": 1
    },
    {
      "x": -6,
      "y": 1,
      "z": -4,
      "name": "Rock_Stone_Brick_Smooth",
      "rotation": 1
    },
    {
      "x": -6,
      "y": 7,
      "z": -4,
      "name": "Rock_Stone_Brick_Smooth",
      "rotation": 1
    },
    {
      "x": -6,
      "y": 1,
      "z": -3,
      "name": "Rock_Stone_Brick_Smooth",
      "rotation": 1
    },
    {
      "x": -6,
      "y": 7,
      "z": -3,
      "name": "Rock_Stone_Brick_Smooth",
      "rotation": 1
    },
    {
      "x": -6,
      "y": 1,
      "z": -2,
      "name": "Rock_Stone_Brick_Smooth",
      "rotation": 1
    },
    {
      "x": -6,
      "y": 7,
      "z": -2,
      "name": "Rock_Stone_Brick_Smooth",
      "rotation": 1
    },
    {
      "x": -6,
      "y": 1,
      "z": -1,
      "name": "Rock_Stone_Brick_Smooth",
      "rotation": 1
    },
    {
      "x": -6,
      "y": 7,
      "z": -1,
      "name": "Rock_Stone_Brick_Smooth",
      "rotation": 1
    },
    {
      "x": -6,
      "y": 1,
      "z": 0,
      "name": "Rock_Stone_Brick_Smooth"
    },
    {
      "x": -6,
      "y": 7,
      "z": 0,
      "name": "Rock_Stone_Brick_Smooth"
    },
    {
      "x": -6,
      "y": 1,
      "z": 1,
      "name": "Rock_Stone_Brick_Smooth",
      "rotation": 2
    },
    {
      "x": -6,
      "y": 7,
      "z": 1,
      "name": "Rock_Stone_Brick_Smooth",
      "rotation": 2
    },
    {
      "x": -6,
      "y": 1,
      "z": 2,
      "name": "Rock_Stone_Brick_Smooth",
      "rotation": 2
    },
    {
      "x": -6,
      "y": 7,
      "z": 2,
      "name": "Rock_Stone_Brick_Smooth",
      "rotation": 2
    },
    {
      "x": -6,
      "y": 1,
      "z": 3,
      "name": "Rock_Stone_Brick_Smooth",
      "rotation": 2
    },
    {
      "x": -6,
      "y": 7,
      "z": 3,
      "name": "Rock_Stone_Brick_Smooth",
      "rotation": 2
    },
    {
      "x": -6,
      "y": 1,
      "z": 4,
      "name": "Rock_Stone_Brick_Smooth",
      "rotation": 2
    },
    {
      "x": -6,
      "y": 7,
      "z": 4,
      "name": "Rock_Stone_Brick_Smooth",
      "rotation": 2
    },
    {
      "x": -6,
      "y": 1,
      "z": 5,
      "name": "Rock_Stone_Brick_Smooth",
      "rotation": 2
    },
    {
      "x": -6,
      "y": 7,
      "z": 5,
      "name": "Rock_Stone_Brick_Smooth",
      "rotation": 2
    },
    {
      "x": -6,
      "y": 1,
      "z": 6,
      "name": "Rock_Stone_Brick_Smooth",
      "rotation": 2
    },
    {
      "x": -6,
      "y": 2,
      "z": 6,
      "name": "Rock_Stone_Brick_Half",
      "rotation": 5
    },
    {
      "x": -6,
      "y": 7,
      "z": 6,
      "name": "Rock_Stone_Brick_Smooth",
      "rotation": 2
    },
    {
      "x": -6,
      "y": 1,
      "z": 7,
      "name": "Rock_Stone_Brick",
      "rotation": 2
    },
    {
      "x": -6,
      "y": 2,
      "z": 7,
      "name": "Rock_Stone_Brick_Decorative",
      "rotation": 2
    },
    {
      "x": -6,
      "y": 3,
      "z": 7,
      "name": "Rock_Stone_Brick_Pillar_Base",
      "rotation": 2
    },
    {
      "x": -6,
      "y": 4,
      "z": 7,
      "name": "Rock_Stone_Brick_Pillar_Middle",
      "rotation": 2
    },
    {
      "x": -6,
      "y": 5,
      "z": 7,
      "name": "Rock_Stone_Brick_Pillar_Middle",
      "rotation": 2
    },
    {
      "x": -6,
      "y": 6,
      "z": 7,
      "name": "Rock_Stone_Brick_Pillar_Base",
      "rotation": 32
    },
    {
      "x": -6,
      "y": 7,
      "z": 7,
      "name": "Rock_Stone_Brick",
      "rotation": 1
    },
    {
      "x": -6,
      "y": 1,
      "z": 8,
      "name": "Rock_Stone_Brick",
      "rotation": 1
    },
    {
      "x": -6,
      "y": 2,
      "z": 8,
      "name": "Rock_Stone_Brick_Decorative",
      "rotation": 2
    },
    {
      "x": -6,
      "y": 3,
      "z": 8,
      "name": "Soil_Gravel",
      "support": 15,
      "rotation": 2
    },
    {
      "x": -6,
      "y": 4,
      "z": 8,
      "name": "Soil_Gravel",
      "support": 15,
      "rotation": 2
    },
    {
      "x": -6,
      "y": 5,
      "z": 8,
      "name": "Soil_Gravel",
      "support": 15,
      "rotation": 2
    },
    {
      "x": -6,
      "y": 6,
      "z": 8,
      "name": "Soil_Gravel",
      "support": 15,
      "rotation": 2
    },
    {
      "x": -6,
      "y": 7,
      "z": 8,
      "name": "Rock_Stone_Brick_Smooth",
      "rotation": 2
    },
    {
      "x": -6,
      "y": 1,
      "z": 9,
      "name": "Rock_Stone_Brick",
      "rotation": 1
    },
    {
      "x": -6,
      "y": 2,
      "z": 9,
      "name": "Rock_Stone_Brick_Decorative",
      "rotation": 2
    },
    {
      "x": -6,
      "y": 3,
      "z": 9,
      "name": "Soil_Gravel",
      "support": 15,
      "rotation": 2
    },
    {
      "x": -6,
      "y": 4,
      "z": 9,
      "name": "Soil_Gravel",
      "support": 15,
      "rotation": 2
    },
    {
      "x": -6,
      "y": 5,
      "z": 9,
      "name": "Soil_Gravel",
      "support": 15,
      "rotation": 2
    },
    {
      "x": -6,
      "y": 6,
      "z": 9,
      "name": "Soil_Gravel",
      "support": 15,
      "rotation": 2
    },
    {
      "x": -6,
      "y": 7,
      "z": 9,
      "name": "Rock_Stone_Brick_Smooth",
      "rotation": 2
    },
    {
      "x": -5,
      "y": 1,
      "z": -10,
      "name": "Rock_Stone_Brick"
    },
    {
      "x": -5,
      "y": 2,
      "z": -10,
      "name": "Rock_Stone_Brick_Decorative",
      "rotation": 1
    },
    {
      "x": -5,
      "y": 3,
      "z": -10,
      "name": "Soil_Gravel",
      "support": 15,
      "rotation": 1
    },
    {
      "x": -5,
      "y": 4,
      "z": -10,
      "name": "Soil_Gravel",
      "support": 15,
      "rotation": 1
    },
    {
      "x": -5,
      "y": 5,
      "z": -10,
      "name": "Soil_Gravel",
      "support": 15,
      "rotation": 1
    },
    {
      "x": -5,
      "y": 6,
      "z": -10,
      "name": "Soil_Gravel",
      "support": 15,
      "rotation": 1
    },
    {
      "x": -5,
      "y": 7,
      "z": -10,
      "name": "Rock_Stone_Brick_Smooth",
      "rotation": 1
    },
    {
      "x": -5,
      "y": 1,
      "z": -9,
      "name": "Rock_Stone_Brick",
      "rotation": 1
    },
    {
      "x": -5,
      "y": 2,
      "z": -9,
      "name": "Rock_Stone_Brick_Decorative",
      "rotation": 1
    },
    {
      "x": -5,
      "y": 3,
      "z": -9,
      "name": "Soil_Gravel_Half",
      "support": 15,
      "rotation": 5
    },
    {
      "x": -5,
      "y": 4,
      "z": -9,
      "name": "Soil_Gravel_Half",
      "support": 15,
      "rotation": 5
    },
    {
      "x": -5,
      "y": 5,
      "z": -9,
      "name": "Soil_Gravel_Half",
      "support": 15,
      "rotation": 5
    },
    {
      "x": -5,
      "y": 6,
      "z": -9,
      "name": "Soil_Gravel_Half",
      "support": 15,
      "rotation": 5
    },
    {
      "x": -5,
      "y": 7,
      "z": -9,
      "name": "Rock_Stone_Brick"
    },
    {
      "x": -5,
      "y": 1,
      "z": -8,
      "name": "Rock_Stone_Brick_Smooth",
      "rotation": 1
    },
    {
      "x": -5,
      "y": 2,
      "z": -8,
      "name": "Rock_Stone_Brick_Half",
      "rotation": 5
    },
    {
      "x": -5,
      "y": 7,
      "z": -8,
      "name": "Rock_Stone_Brick_Smooth",
      "rotation": 1
    },
    {
      "x": -5,
      "y": 1,
      "z": -7,
      "name": "Rock_Stone_Brick_Smooth",
      "rotation": 1
    },
    {
      "x": -5,
      "y": 7,
      "z": -7,
      "name": "Rock_Stone_Brick_Smooth",
      "rotation": 1
    },
    {
      "x": -5,
      "y": 1,
      "z": -6,
      "name": "Rock_Stone_Brick_Smooth",
      "rotation": 1
    },
    {
      "x": -5,
      "y": 7,
      "z": -6,
      "name": "Rock_Stone_Brick_Smooth",
      "rotation": 1
    },
    {
      "x": -5,
      "y": 1,
      "z": -5,
      "name": "Rock_Stone_Brick_Smooth",
      "rotation": 1
    },
    {
      "x": -5,
      "y": 7,
      "z": -5,
      "name": "Rock_Stone_Brick_Smooth",
      "rotation": 1
    },
    {
      "x": -5,
      "y": 1,
      "z": -4,
      "name": "Rock_Stone_Brick_Smooth",
      "rotation": 1
    },
    {
      "x": -5,
      "y": 7,
      "z": -4,
      "name": "Rock_Stone_Brick_Smooth",
      "rotation": 1
    },
    {
      "x": -5,
      "y": 1,
      "z": -3,
      "name": "Rock_Stone_Brick_Smooth",
      "rotation": 1
    },
    {
      "x": -5,
      "y": 7,
      "z": -3,
      "name": "Rock_Stone_Brick_Smooth",
      "rotation": 1
    },
    {
      "x": -5,
      "y": 1,
      "z": -2,
      "name": "Rock_Stone_Brick_Smooth",
      "rotation": 1
    },
    {
      "x": -5,
      "y": 7,
      "z": -2,
      "name": "Rock_Stone_Brick_Smooth",
      "rotation": 1
    },
    {
      "x": -5,
      "y": 1,
      "z": -1,
      "name": "Rock_Stone_Brick_Smooth",
      "rotation": 1
    },
    {
      "x": -5,
      "y": 7,
      "z": -1,
      "name": "Rock_Stone_Brick_Smooth",
      "rotation": 1
    },
    {
      "x": -5,
      "y": 1,
      "z": 0,
      "name": "Rock_Stone_Brick_Smooth"
    },
    {
      "x": -5,
      "y": 7,
      "z": 0,
      "name": "Rock_Stone_Brick_Smooth"
    },
    {
      "x": -5,
      "y": 1,
      "z": 1,
      "name": "Rock_Stone_Brick_Smooth",
      "rotation": 2
    },
    {
      "x": -5,
      "y": 7,
      "z": 1,
      "name": "Rock_Stone_Brick_Smooth",
      "rotation": 2
    },
    {
      "x": -5,
      "y": 1,
      "z": 2,
      "name": "Rock_Stone_Brick_Smooth",
      "rotation": 2
    },
    {
      "x": -5,
      "y": 7,
      "z": 2,
      "name": "Rock_Stone_Brick_Smooth",
      "rotation": 2
    },
    {
      "x": -5,
      "y": 1,
      "z": 3,
      "name": "Rock_Stone_Brick_Smooth",
      "rotation": 2
    },
    {
      "x": -5,
      "y": 7,
      "z": 3,
      "name": "Rock_Stone_Brick_Smooth",
      "rotation": 2
    },
    {
      "x": -5,
      "y": 1,
      "z": 4,
      "name": "Rock_Stone_Brick_Smooth",
      "rotation": 2
    },
    {
      "x": -5,
      "y": 7,
      "z": 4,
      "name": "Rock_Stone_Brick_Smooth",
      "rotation": 2
    },
    {
      "x": -5,
      "y": 1,
      "z": 5,
      "name": "Rock_Stone_Brick_Smooth",
      "rotation": 2
    },
    {
      "x": -5,
      "y": 7,
      "z": 5,
      "name": "Rock_Stone_Brick_Smooth",
      "rotation": 2
    },
    {
      "x": -5,
      "y": 1,
      "z": 6,
      "name": "Rock_Stone_Brick_Smooth",
      "rotation": 2
    },
    {
      "x": -5,
      "y": 7,
      "z": 6,
      "name": "Rock_Stone_Brick_Smooth",
      "rotation": 2
    },
    {
      "x": -5,
      "y": 1,
      "z": 7,
      "name": "Rock_Stone_Brick_Smooth",
      "rotation": 2
    },
    {
      "x": -5,
      "y": 7,
      "z": 7,
      "name": "Rock_Stone_Brick_Smooth",
      "rotation": 2
    },
    {
      "x": -5,
      "y": 1,
      "z": 8,
      "name": "Rock_Stone_Brick_Smooth",
      "rotation": 2
    },
    {
      "x": -5,
      "y": 2,
      "z": 8,
      "name": "Rock_Stone_Brick_Half",
      "rotation": 5
    },
    {
      "x": -5,
      "y": 7,
      "z": 8,
      "name": "Rock_Stone_Brick_Smooth",
      "rotation": 2
    },
    {
      "x": -5,
      "y": 1,
      "z": 9,
      "name": "Rock_Stone_Brick",
      "rotation": 2
    },
    {
      "x": -5,
      "y": 2,
      "z": 9,
      "name": "Rock_Stone_Brick_Decorative",
      "rotation": 2
    },
    {
      "x": -5,
      "y": 3,
      "z": 9,
      "name": "Soil_Gravel_Half",
      "support": 15,
      "rotation": 5
    },
    {
      "x": -5,
      "y": 4,
      "z": 9,
      "name": "Soil_Gravel_Half",
      "support": 15,
      "rotation": 5
    },
    {
      "x": -5,
      "y": 5,
      "z": 9,
      "name": "Soil_Gravel_Half",
      "support": 15,
      "rotation": 5
    },
    {
      "x": -5,
      "y": 6,
      "z": 9,
      "name": "Soil_Gravel_Half",
      "support": 15,
      "rotation": 5
    },
    {
      "x": -5,
      "y": 7,
      "z": 9,
      "name": "Rock_Stone_Brick",
      "rotation": 1
    },
    {
      "x": -5,
      "y": 1,
      "z": 10,
      "name": "Rock_Stone_Brick",
      "rotation": 1
    },
    {
      "x": -5,
      "y": 2,
      "z": 10,
      "name": "Rock_Stone_Brick_Decorative",
      "rotation": 2
    },
    {
      "x": -5,
      "y": 3,
      "z": 10,
      "name": "Soil_Gravel",
      "support": 15,
      "rotation": 2
    },
    {
      "x": -5,
      "y": 4,
      "z": 10,
      "name": "Soil_Gravel",
      "support": 15,
      "rotation": 2
    },
    {
      "x": -5,
      "y": 5,
      "z": 10,
      "name": "Soil_Gravel",
      "support": 15,
      "rotation": 2
    },
    {
      "x": -5,
      "y": 6,
      "z": 10,
      "name": "Soil_Gravel",
      "support": 15,
      "rotation": 2
    },
    {
      "x": -5,
      "y": 7,
      "z": 10,
      "name": "Rock_Stone_Brick_Smooth",
      "rotation": 2
    },
    {
      "x": -4,
      "y": 1,
      "z": -11,
      "name": "Rock_Stone_Brick"
    },
    {
      "x": -4,
      "y": 2,
      "z": -11,
      "name": "Rock_Stone_Brick_Decorative",
      "rotation": 1
    },
    {
      "x": -4,
      "y": 3,
      "z": -11,
      "name": "Soil_Gravel",
      "support": 15,
      "rotation": 1
    },
    {
      "x": -4,
      "y": 4,
      "z": -11,
      "name": "Soil_Gravel",
      "support": 15,
      "rotation": 1
    },
    {
      "x": -4,
      "y": 5,
      "z": -11,
      "name": "Soil_Gravel",
      "support": 15,
      "rotation": 1
    },
    {
      "x": -4,
      "y": 6,
      "z": -11,
      "name": "Soil_Gravel",
      "support": 15,
      "rotation": 1
    },
    {
      "x": -4,
      "y": 7,
      "z": -11,
      "name": "Rock_Stone_Brick_Smooth",
      "rotation": 1
    },
    {
      "x": -4,
      "y": 1,
      "z": -10,
      "name": "Rock_Stone_Brick",
      "rotation": 1
    },
    {
      "x": -4,
      "y": 2,
      "z": -10,
      "name": "Rock_Stone_Brick_Decorative",
      "rotation": 1
    },
    {
      "x": -4,
      "y": 3,
      "z": -10,
      "name": "Rock_Stone_Brick_Pillar_Base",
      "rotation": 1
    },
    {
      "x": -4,
      "y": 4,
      "z": -10,
      "name": "Rock_Stone_Brick_Pillar_Middle",
      "rotation": 1
    },
    {
      "x": -4,
      "y": 5,
      "z": -10,
      "name": "Rock_Stone_Brick_Pillar_Middle",
      "rotation": 1
    },
    {
      "x": -4,
      "y": 6,
      "z": -10,
      "name": "Rock_Stone_Brick_Pillar_Base",
      "rotation": 35
    },
    {
      "x": -4,
      "y": 7,
      "z": -10,
      "name": "Rock_Stone_Brick"
    },
    {
      "x": -4,
      "y": 1,
      "z": -9,
      "name": "Rock_Stone_Brick_Smooth",
      "rotation": 1
    },
    {
      "x": -4,
      "y": 7,
      "z": -9,
      "name": "Rock_Stone_Brick_Smooth",
      "rotation": 1
    },
    {
      "x": -4,
      "y": 1,
      "z": -8,
      "name": "Rock_Stone_Brick_Smooth",
      "rotation": 1
    },
    {
      "x": -4,
      "y": 7,
      "z": -8,
      "name": "Rock_Stone_Brick_Smooth",
      "rotation": 1
    },
    {
      "x": -4,
      "y": 1,
      "z": -7,
      "name": "Rock_Stone_Brick_Smooth",
      "rotation": 1
    },
    {
      "x": -4,
      "y": 7,
      "z": -7,
      "name": "Rock_Stone_Brick_Smooth",
      "rotation": 1
    },
    {
      "x": -4,
      "y": 1,
      "z": -6,
      "name": "Rock_Stone_Brick_Smooth",
      "rotation": 1
    },
    {
      "x": -4,
      "y": 7,
      "z": -6,
      "name": "Rock_Stone_Brick_Smooth",
      "rotation": 1
    },
    {
      "x": -4,
      "y": 1,
      "z": -5,
      "name": "Rock_Stone_Brick_Smooth",
      "rotation": 1
    },
    {
      "x": -4,
      "y": 7,
      "z": -5,
      "name": "Rock_Stone_Brick_Smooth",
      "rotation": 1
    },
    {
      "x": -4,
      "y": 1,
      "z": -4,
      "name": "Rock_Stone_Brick_Smooth",
      "rotation": 1
    },
    {
      "x": -4,
      "y": 7,
      "z": -4,
      "name": "Rock_Stone_Brick_Smooth",
      "rotation": 1
    },
    {
      "x": -4,
      "y": 1,
      "z": -3,
      "name": "Rock_Stone_Brick_Smooth",
      "rotation": 1
    },
    {
      "x": -4,
      "y": 7,
      "z": -3,
      "name": "Rock_Stone_Brick_Smooth",
      "rotation": 1
    },
    {
      "x": -4,
      "y": 1,
      "z": -2,
      "name": "Rock_Stone_Brick_Smooth",
      "rotation": 1
    },
    {
      "x": -4,
      "y": 7,
      "z": -2,
      "name": "Rock_Stone_Brick_Smooth",
      "rotation": 1
    },
    {
      "x": -4,
      "y": 1,
      "z": -1,
      "name": "Rock_Stone_Brick_Smooth",
      "rotation": 1
    },
    {
      "x": -4,
      "y": 7,
      "z": -1,
      "name": "Rock_Stone_Brick_Smooth",
      "rotation": 1
    },
    {
      "x": -4,
      "y": 1,
      "z": 0,
      "name": "Rock_Stone_Brick_Smooth"
    },
    {
      "x": -4,
      "y": 7,
      "z": 0,
      "name": "Rock_Stone_Brick_Smooth"
    },
    {
      "x": -4,
      "y": 1,
      "z": 1,
      "name": "Rock_Stone_Brick_Smooth",
      "rotation": 2
    },
    {
      "x": -4,
      "y": 7,
      "z": 1,
      "name": "Rock_Stone_Brick_Smooth",
      "rotation": 2
    },
    {
      "x": -4,
      "y": 1,
      "z": 2,
      "name": "Rock_Stone_Brick_Smooth",
      "rotation": 2
    },
    {
      "x": -4,
      "y": 7,
      "z": 2,
      "name": "Rock_Stone_Brick_Smooth",
      "rotation": 2
    },
    {
      "x": -4,
      "y": 1,
      "z": 3,
      "name": "Rock_Stone_Brick_Smooth",
      "rotation": 2
    },
    {
      "x": -4,
      "y": 7,
      "z": 3,
      "name": "Rock_Stone_Brick_Smooth",
      "rotation": 2
    },
    {
      "x": -4,
      "y": 1,
      "z": 4,
      "name": "Rock_Stone_Brick_Smooth",
      "rotation": 2
    },
    {
      "x": -4,
      "y": 7,
      "z": 4,
      "name": "Rock_Stone_Brick_Smooth",
      "rotation": 2
    },
    {
      "x": -4,
      "y": 1,
      "z": 5,
      "name": "Rock_Stone_Brick_Smooth",
      "rotation": 2
    },
    {
      "x": -4,
      "y": 7,
      "z": 5,
      "name": "Rock_Stone_Brick_Smooth",
      "rotation": 2
    },
    {
      "x": -4,
      "y": 1,
      "z": 6,
      "name": "Rock_Stone_Brick_Smooth",
      "rotation": 2
    },
    {
      "x": -4,
      "y": 7,
      "z": 6,
      "name": "Rock_Stone_Brick_Smooth",
      "rotation": 2
    },
    {
      "x": -4,
      "y": 1,
      "z": 7,
      "name": "Rock_Stone_Brick_Smooth",
      "rotation": 2
    },
    {
      "x": -4,
      "y": 7,
      "z": 7,
      "name": "Rock_Stone_Brick_Smooth",
      "rotation": 2
    },
    {
      "x": -4,
      "y": 1,
      "z": 8,
      "name": "Rock_Stone_Brick_Smooth",
      "rotation": 2
    },
    {
      "x": -4,
      "y": 7,
      "z": 8,
      "name": "Rock_Stone_Brick_Smooth",
      "rotation": 2
    },
    {
      "x": -4,
      "y": 1,
      "z": 9,
      "name": "Rock_Stone_Brick_Smooth",
      "rotation": 2
    },
    {
      "x": -4,
      "y": 7,
      "z": 9,
      "name": "Rock_Stone_Brick_Smooth",
      "rotation": 2
    },
    {
      "x": -4,
      "y": 1,
      "z": 10,
      "name": "Rock_Stone_Brick",
      "rotation": 2
    },
    {
      "x": -4,
      "y": 2,
      "z": 10,
      "name": "Rock_Stone_Brick_Decorative",
      "rotation": 2
    },
    {
      "x": -4,
      "y": 3,
      "z": 10,
      "name": "Rock_Stone_Brick_Pillar_Base",
      "rotation": 2
    },
    {
      "x": -4,
      "y": 4,
      "z": 10,
      "name": "Rock_Stone_Brick_Pillar_Middle",
      "rotation": 2
    },
    {
      "x": -4,
      "y": 5,
      "z": 10,
      "name": "Rock_Stone_Brick_Pillar_Middle",
      "rotation": 2
    },
    {
      "x": -4,
      "y": 6,
      "z": 10,
      "name": "Rock_Stone_Brick_Pillar_Base",
      "rotation": 32
    },
    {
      "x": -4,
      "y": 7,
      "z": 10,
      "name": "Rock_Stone_Brick",
      "rotation": 1
    },
    {
      "x": -4,
      "y": 1,
      "z": 11,
      "name": "Rock_Stone_Brick",
      "rotation": 1
    },
    {
      "x": -4,
      "y": 2,
      "z": 11,
      "name": "Rock_Stone_Brick_Decorative",
      "rotation": 2
    },
    {
      "x": -4,
      "y": 3,
      "z": 11,
      "name": "Soil_Gravel",
      "support": 15,
      "rotation": 2
    },
    {
      "x": -4,
      "y": 4,
      "z": 11,
      "name": "Soil_Gravel",
      "support": 15,
      "rotation": 2
    },
    {
      "x": -4,
      "y": 5,
      "z": 11,
      "name": "Soil_Gravel",
      "support": 15,
      "rotation": 2
    },
    {
      "x": -4,
      "y": 6,
      "z": 11,
      "name": "Soil_Gravel",
      "support": 15,
      "rotation": 2
    },
    {
      "x": -4,
      "y": 7,
      "z": 11,
      "name": "Rock_Stone_Brick_Smooth",
      "rotation": 2
    },
    {
      "x": -3,
      "y": 1,
      "z": -12,
      "name": "Rock_Stone_Brick"
    },
    {
      "x": -3,
      "y": 2,
      "z": -12,
      "name": "Rock_Stone_Brick_Decorative",
      "rotation": 1
    },
    {
      "x": -3,
      "y": 3,
      "z": -12,
      "name": "Soil_Gravel",
      "support": 15,
      "rotation": 1
    },
    {
      "x": -3,
      "y": 4,
      "z": -12,
      "name": "Soil_Gravel",
      "support": 15,
      "rotation": 1
    },
    {
      "x": -3,
      "y": 5,
      "z": -12,
      "name": "Soil_Gravel",
      "support": 15,
      "rotation": 1
    },
    {
      "x": -3,
      "y": 6,
      "z": -12,
      "name": "Soil_Gravel",
      "support": 15,
      "rotation": 1
    },
    {
      "x": -3,
      "y": 7,
      "z": -12,
      "name": "Rock_Stone_Brick_Smooth",
      "rotation": 1
    },
    {
      "x": -3,
      "y": 1,
      "z": -11,
      "name": "Rock_Stone_Brick",
      "rotation": 1
    },
    {
      "x": -3,
      "y": 2,
      "z": -11,
      "name": "Rock_Stone_Brick_Decorative",
      "rotation": 1
    },
    {
      "x": -3,
      "y": 3,
      "z": -11,
      "name": "Soil_Gravel_Half",
      "support": 15,
      "rotation": 4
    },
    {
      "x": -3,
      "y": 4,
      "z": -11,
      "name": "Soil_Gravel_Half",
      "support": 15,
      "rotation": 4
    },
    {
      "x": -3,
      "y": 5,
      "z": -11,
      "name": "Soil_Gravel_Half",
      "support": 15,
      "rotation": 4
    },
    {
      "x": -3,
      "y": 6,
      "z": -11,
      "name": "Soil_Gravel_Half",
      "support": 15,
      "rotation": 4
    },
    {
      "x": -3,
      "y": 7,
      "z": -11,
      "name": "Rock_Stone_Brick"
    },
    {
      "x": -3,
      "y": 1,
      "z": -10,
      "name": "Rock_Stone_Brick_Smooth",
      "rotation": 1
    },
    {
      "x": -3,
      "y": 7,
      "z": -10,
      "name": "Rock_Stone_Brick_Smooth",
      "rotation": 1
    },
    {
      "x": -3,
      "y": 1,
      "z": -9,
      "name": "Rock_Stone_Brick_Smooth",
      "rotation": 1
    },
    {
      "x": -3,
      "y": 7,
      "z": -9,
      "name": "Rock_Stone_Brick_Smooth",
      "rotation": 1
    },
    {
      "x": -3,
      "y": 1,
      "z": -8,
      "name": "Rock_Stone_Brick_Smooth",
      "rotation": 1
    },
    {
      "x": -3,
      "y": 7,
      "z": -8,
      "name": "Rock_Stone_Brick_Smooth",
      "rotation": 1
    },
    {
      "x": -3,
      "y": 1,
      "z": -7,
      "name": "Rock_Stone_Brick_Smooth",
      "rotation": 1
    },
    {
      "x": -3,
      "y": 7,
      "z": -7,
      "name": "Rock_Stone_Brick_Smooth",
      "rotation": 1
    },
    {
      "x": -3,
      "y": 1,
      "z": -6,
      "name": "Rock_Stone_Brick_Smooth",
      "rotation": 1
    },
    {
      "x": -3,
      "y": 7,
      "z": -6,
      "name": "Rock_Stone_Brick_Smooth",
      "rotation": 1
    },
    {
      "x": -3,
      "y": 1,
      "z": -5,
      "name": "Rock_Stone_Brick_Smooth",
      "rotation": 1
    },
    {
      "x": -3,
      "y": 2,
      "z": -5,
      "name": "Rock_Stone_Brick_Half",
      "rotation": 7
    },
    {
      "x": -3,
      "y": 7,
      "z": -5,
      "name": "Rock_Stone_Brick_Smooth",
      "rotation": 1
    },
    {
      "x": -3,
      "y": 1,
      "z": -4,
      "name": "Rock_Stone_Brick",
      "rotation": 1
    },
    {
      "x": -3,
      "y": 2,
      "z": -4,
      "name": "Rock_Stone_Brick_Decorative",
      "rotation": 1
    },
    {
      "x": -3,
      "y": 3,
      "z": -4,
      "name": "Rock_Stone_Brick_Pillar_Base",
      "rotation": 1
    },
    {
      "x": -3,
      "y": 4,
      "z": -4,
      "name": "Rock_Stone_Brick_Pillar_Middle",
      "rotation": 1
    },
    {
      "x": -3,
      "y": 5,
      "z": -4,
      "name": "Rock_Stone_Brick_Pillar_Middle",
      "rotation": 1
    },
    {
      "x": -3,
      "y": 6,
      "z": -4,
      "name": "Rock_Stone_Brick_Pillar_Base",
      "rotation": 35
    },
    {
      "x": -3,
      "y": 7,
      "z": -4,
      "name": "Rock_Stone_Brick",
      "rotation": 1
    },
    {
      "x": -3,
      "y": 1,
      "z": -3,
      "name": "Rock_Stone_Brick_Smooth",
      "rotation": 1
    },
    {
      "x": -3,
      "y": 2,
      "z": -3,
      "name": "Rock_Stone_Brick_Decorative"
    },
    {
      "x": -3,
      "y": 3,
      "z": -3,
      "name": "Soil_Gravel_Half",
      "support": 15,
      "rotation": 7
    },
    {
      "x": -3,
      "y": 4,
      "z": -3,
      "name": "Soil_Gravel_Half",
      "support": 15,
      "rotation": 7
    },
    {
      "x": -3,
      "y": 5,
      "z": -3,
      "name": "Soil_Gravel_Half",
      "support": 15,
      "rotation": 7
    },
    {
      "x": -3,
      "y": 6,
      "z": -3,
      "name": "Soil_Gravel_Half",
      "support": 15,
      "rotation": 7
    },
    {
      "x": -3,
      "y": 7,
      "z": -3,
      "name": "Rock_Stone_Brick",
      "rotation": 1
    },
    {
      "x": -3,
      "y": 1,
      "z": -2,
      "name": "Rock_Stone_Brick_Smooth",
      "rotation": 1
    },
    {
      "x": -3,
      "y": 2,
      "z": -2,
      "name": "Rock_Stone_Brick_Decorative"
    },
    {
      "x": -3,
      "y": 3,
      "z": -2,
      "name": "Soil_Gravel_Half",
      "support": 15,
      "rotation": 7
    },
    {
      "x": -3,
      "y": 4,
      "z": -2,
      "name": "Soil_Gravel_Half",
      "support": 15,
      "rotation": 7
    },
    {
      "x": -3,
      "y": 5,
      "z": -2,
      "name": "Soil_Gravel_Half",
      "support": 15,
      "rotation": 7
    },
    {
      "x": -3,
      "y": 6,
      "z": -2,
      "name": "Soil_Gravel_Half",
      "support": 15,
      "rotation": 7
    },
    {
      "x": -3,
      "y": 7,
      "z": -2,
      "name": "Rock_Stone_Brick",
      "rotation": 1
    },
    {
      "x": -3,
      "y": 1,
      "z": -1,
      "name": "Rock_Stone_Brick_Smooth",
      "rotation": 1
    },
    {
      "x": -3,
      "y": 2,
      "z": -1,
      "name": "Rock_Stone_Brick_Decorative"
    },
    {
      "x": -3,
      "y": 3,
      "z": -1,
      "name": "Soil_Gravel_Half",
      "support": 15,
      "rotation": 7
    },
    {
      "x": -3,
      "y": 4,
      "z": -1,
      "name": "Soil_Gravel_Half",
      "support": 15,
      "rotation": 7
    },
    {
      "x": -3,
      "y": 5,
      "z": -1,
      "name": "Soil_Gravel_Half",
      "support": 15,
      "rotation": 7
    },
    {
      "x": -3,
      "y": 6,
      "z": -1,
      "name": "Soil_Gravel_Half",
      "support": 15,
      "rotation": 7
    },
    {
      "x": -3,
      "y": 7,
      "z": -1,
      "name": "Rock_Stone_Brick",
      "rotation": 1
    },
    {
      "x": -3,
      "y": 1,
      "z": 0,
      "name": "Rock_Stone_Brick"
    },
    {
      "x": -3,
      "y": 2,
      "z": 0,
      "name": "Rock_Stone_Brick_Decorative"
    },
    {
      "x": -3,
      "y": 3,
      "z": 0,
      "name": "Rock_Stone_Brick_Pillar_Base"
    },
    {
      "x": -3,
      "y": 4,
      "z": 0,
      "name": "Rock_Stone_Brick_Pillar_Middle"
    },
    {
      "x": -3,
      "y": 5,
      "z": 0,
      "name": "Rock_Stone_Brick_Pillar_Middle",
      "rotation": 8
    },
    {
      "x": -3,
      "y": 6,
      "z": 0,
      "name": "Rock_Stone_Brick_Pillar_Base",
      "rotation": 8
    },
    {
      "x": -3,
      "y": 7,
      "z": 0,
      "name": "Rock_Stone_Brick"
    },
    {
      "x": -3,
      "y": 1,
      "z": 1,
      "name": "Rock_Stone_Brick_Smooth",
      "rotation": 2
    },
    {
      "x": -3,
      "y": 2,
      "z": 1,
      "name": "Rock_Stone_Brick_Decorative",
      "rotation": 1
    },
    {
      "x": -3,
      "y": 3,
      "z": 1,
      "name": "Soil_Gravel_Half",
      "support": 15,
      "rotation": 7
    },
    {
      "x": -3,
      "y": 4,
      "z": 1,
      "name": "Soil_Gravel_Half",
      "support": 15,
      "rotation": 7
    },
    {
      "x": -3,
      "y": 5,
      "z": 1,
      "name": "Soil_Gravel_Half",
      "support": 15,
      "rotation": 7
    },
    {
      "x": -3,
      "y": 6,
      "z": 1,
      "name": "Soil_Gravel_Half",
      "support": 15,
      "rotation": 7
    },
    {
      "x": -3,
      "y": 7,
      "z": 1,
      "name": "Rock_Stone_Brick",
      "rotation": 2
    },
    {
      "x": -3,
      "y": 1,
      "z": 2,
      "name": "Rock_Stone_Brick_Smooth",
      "rotation": 2
    },
    {
      "x": -3,
      "y": 2,
      "z": 2,
      "name": "Rock_Stone_Brick_Decorative",
      "rotation": 1
    },
    {
      "x": -3,
      "y": 3,
      "z": 2,
      "name": "Soil_Gravel_Half",
      "support": 15,
      "rotation": 7
    },
    {
      "x": -3,
      "y": 4,
      "z": 2,
      "name": "Soil_Gravel_Half",
      "support": 15,
      "rotation": 7
    },
    {
      "x": -3,
      "y": 5,
      "z": 2,
      "name": "Soil_Gravel_Half",
      "support": 15,
      "rotation": 7
    },
    {
      "x": -3,
      "y": 6,
      "z": 2,
      "name": "Soil_Gravel_Half",
      "support": 15,
      "rotation": 7
    },
    {
      "x": -3,
      "y": 7,
      "z": 2,
      "name": "Rock_Stone_Brick",
      "rotation": 2
    },
    {
      "x": -3,
      "y": 1,
      "z": 3,
      "name": "Rock_Stone_Brick_Smooth",
      "rotation": 2
    },
    {
      "x": -3,
      "y": 2,
      "z": 3,
      "name": "Rock_Stone_Brick_Decorative",
      "rotation": 1
    },
    {
      "x": -3,
      "y": 3,
      "z": 3,
      "name": "Soil_Gravel_Half",
      "support": 15,
      "rotation": 7
    },
    {
      "x": -3,
      "y": 4,
      "z": 3,
      "name": "Soil_Gravel_Half",
      "support": 15,
      "rotation": 7
    },
    {
      "x": -3,
      "y": 5,
      "z": 3,
      "name": "Soil_Gravel_Half",
      "support": 15,
      "rotation": 7
    },
    {
      "x": -3,
      "y": 6,
      "z": 3,
      "name": "Soil_Gravel_Half",
      "support": 15,
      "rotation": 7
    },
    {
      "x": -3,
      "y": 7,
      "z": 3,
      "name": "Rock_Stone_Brick",
      "rotation": 2
    },
    {
      "x": -3,
      "y": 1,
      "z": 4,
      "name": "Rock_Stone_Brick",
      "rotation": 2
    },
    {
      "x": -3,
      "y": 2,
      "z": 4,
      "name": "Rock_Stone_Brick_Decorative",
      "rotation": 2
    },
    {
      "x": -3,
      "y": 3,
      "z": 4,
      "name": "Rock_Stone_Brick_Pillar_Base",
      "rotation": 2
    },
    {
      "x": -3,
      "y": 4,
      "z": 4,
      "name": "Rock_Stone_Brick_Pillar_Middle",
      "rotation": 2
    },
    {
      "x": -3,
      "y": 5,
      "z": 4,
      "name": "Rock_Stone_Brick_Pillar_Middle",
      "rotation": 2
    },
    {
      "x": -3,
      "y": 6,
      "z": 4,
      "name": "Rock_Stone_Brick_Pillar_Base",
      "rotation": 32
    },
    {
      "x": -3,
      "y": 7,
      "z": 4,
      "name": "Rock_Stone_Brick",
      "rotation": 2
    },
    {
      "x": -3,
      "y": 1,
      "z": 5,
      "name": "Rock_Stone_Brick_Smooth",
      "rotation": 2
    },
    {
      "x": -3,
      "y": 2,
      "z": 5,
      "name": "Rock_Stone_Brick_Half",
      "rotation": 7
    },
    {
      "x": -3,
      "y": 7,
      "z": 5,
      "name": "Rock_Stone_Brick_Smooth",
      "rotation": 2
    },
    {
      "x": -3,
      "y": 1,
      "z": 6,
      "name": "Rock_Stone_Brick_Smooth",
      "rotation": 2
    },
    {
      "x": -3,
      "y": 7,
      "z": 6,
      "name": "Rock_Stone_Brick_Smooth",
      "rotation": 2
    },
    {
      "x": -3,
      "y": 1,
      "z": 7,
      "name": "Rock_Stone_Brick_Smooth",
      "rotation": 2
    },
    {
      "x": -3,
      "y": 7,
      "z": 7,
      "name": "Rock_Stone_Brick_Smooth",
      "rotation": 2
    },
    {
      "x": -3,
      "y": 1,
      "z": 8,
      "name": "Rock_Stone_Brick_Smooth",
      "rotation": 2
    },
    {
      "x": -3,
      "y": 7,
      "z": 8,
      "name": "Rock_Stone_Brick_Smooth",
      "rotation": 2
    },
    {
      "x": -3,
      "y": 1,
      "z": 9,
      "name": "Rock_Stone_Brick_Smooth",
      "rotation": 2
    },
    {
      "x": -3,
      "y": 7,
      "z": 9,
      "name": "Rock_Stone_Brick_Smooth",
      "rotation": 2
    },
    {
      "x": -3,
      "y": 1,
      "z": 10,
      "name": "Rock_Stone_Brick_Smooth",
      "rotation": 2
    },
    {
      "x": -3,
      "y": 7,
      "z": 10,
      "name": "Rock_Stone_Brick_Smooth",
      "rotation": 2
    },
    {
      "x": -3,
      "y": 1,
      "z": 11,
      "name": "Rock_Stone_Brick",
      "rotation": 2
    },
    {
      "x": -3,
      "y": 2,
      "z": 11,
      "name": "Rock_Stone_Brick_Decorative",
      "rotation": 2
    },
    {
      "x": -3,
      "y": 3,
      "z": 11,
      "name": "Soil_Gravel_Half",
      "support": 15,
      "rotation": 6
    },
    {
      "x": -3,
      "y": 4,
      "z": 11,
      "name": "Soil_Gravel_Half",
      "support": 15,
      "rotation": 6
    },
    {
      "x": -3,
      "y": 5,
      "z": 11,
      "name": "Soil_Gravel_Half",
      "support": 15,
      "rotation": 6
    },
    {
      "x": -3,
      "y": 6,
      "z": 11,
      "name": "Soil_Gravel_Half",
      "support": 15,
      "rotation": 6
    },
    {
      "x": -3,
      "y": 7,
      "z": 11,
      "name": "Rock_Stone_Brick",
      "rotation": 1
    },
    {
      "x": -3,
      "y": 1,
      "z": 12,
      "name": "Rock_Stone_Brick",
      "rotation": 1
    },
    {
      "x": -3,
      "y": 2,
      "z": 12,
      "name": "Rock_Stone_Brick_Decorative",
      "rotation": 2
    },
    {
      "x": -3,
      "y": 3,
      "z": 12,
      "name": "Soil_Gravel",
      "support": 15,
      "rotation": 2
    },
    {
      "x": -3,
      "y": 4,
      "z": 12,
      "name": "Soil_Gravel",
      "support": 15,
      "rotation": 2
    },
    {
      "x": -3,
      "y": 5,
      "z": 12,
      "name": "Soil_Gravel",
      "support": 15,
      "rotation": 2
    },
    {
      "x": -3,
      "y": 6,
      "z": 12,
      "name": "Soil_Gravel",
      "support": 15,
      "rotation": 2
    },
    {
      "x": -3,
      "y": 7,
      "z": 12,
      "name": "Rock_Stone_Brick_Smooth",
      "rotation": 2
    },
    {
      "x": -2,
      "y": 1,
      "z": -12,
      "name": "Rock_Stone_Brick"
    },
    {
      "x": -2,
      "y": 2,
      "z": -12,
      "name": "Rock_Stone_Brick_Decorative",
      "rotation": 1
    },
    {
      "x": -2,
      "y": 3,
      "z": -12,
      "name": "Soil_Gravel",
      "support": 15,
      "rotation": 1
    },
    {
      "x": -2,
      "y": 4,
      "z": -12,
      "name": "Soil_Gravel",
      "support": 15,
      "rotation": 1
    },
    {
      "x": -2,
      "y": 5,
      "z": -12,
      "name": "Soil_Gravel",
      "support": 15,
      "rotation": 1
    },
    {
      "x": -2,
      "y": 6,
      "z": -12,
      "name": "Soil_Gravel",
      "support": 15,
      "rotation": 1
    },
    {
      "x": -2,
      "y": 7,
      "z": -12,
      "name": "Rock_Stone_Brick_Smooth",
      "rotation": 1
    },
    {
      "x": -2,
      "y": 1,
      "z": -11,
      "name": "Rock_Stone_Brick_Smooth",
      "rotation": 1
    },
    {
      "x": -2,
      "y": 2,
      "z": -11,
      "name": "Rock_Stone_Brick_Half",
      "rotation": 4
    },
    {
      "x": -2,
      "y": 7,
      "z": -11,
      "name": "Rock_Stone_Brick_Smooth",
      "rotation": 1
    },
    {
      "x": -2,
      "y": 1,
      "z": -10,
      "name": "Rock_Stone_Brick_Smooth",
      "rotation": 1
    },
    {
      "x": -2,
      "y": 7,
      "z": -10,
      "name": "Rock_Stone_Brick_Smooth",
      "rotation": 1
    },
    {
      "x": -2,
      "y": 1,
      "z": -9,
      "name": "Rock_Stone_Brick_Smooth",
      "rotation": 1
    },
    {
      "x": -2,
      "y": 7,
      "z": -9,
      "name": "Rock_Stone_Brick_Smooth",
      "rotation": 1
    },
    {
      "x": -2,
      "y": 1,
      "z": -8,
      "name": "Rock_Stone_Brick_Smooth",
      "rotation": 1
    },
    {
      "x": -2,
      "y": 7,
      "z": -8,
      "name": "Rock_Stone_Brick_Smooth",
      "rotation": 1
    },
    {
      "x": -2,
      "y": 1,
      "z": -7,
      "name": "Rock_Stone_Brick_Smooth",
      "rotation": 1
    },
    {
      "x": -2,
      "y": 7,
      "z": -7,
      "name": "Rock_Stone_Brick_Smooth",
      "rotation": 1
    },
    {
      "x": -2,
      "y": 1,
      "z": -6,
      "name": "Rock_Stone_Brick_Smooth",
      "rotation": 1
    },
    {
      "x": -2,
      "y": 2,
      "z": -6,
      "name": "Rock_Stone_Brick_Decorative"
    },
    {
      "x": -2,
      "y": 3,
      "z": -6,
      "name": "Soil_Gravel_Half",
      "support": 15,
      "rotation": 7
    },
    {
      "x": -2,
      "y": 4,
      "z": -6,
      "name": "Soil_Gravel_Half",
      "support": 15,
      "rotation": 7
    },
    {
      "x": -2,
      "y": 5,
      "z": -6,
      "name": "Soil_Gravel_Half",
      "support": 15,
      "rotation": 7
    },
    {
      "x": -2,
      "y": 6,
      "z": -6,
      "name": "Soil_Gravel_Half",
      "support": 15,
      "rotation": 7
    },
    {
      "x": -2,
      "y": 7,
      "z": -6,
      "name": "Rock_Stone_Brick"
    },
    {
      "x": -2,
      "y": 1,
      "z": -5,
      "name": "Rock_Stone_Brick"
    },
    {
      "x": -2,
      "y": 2,
      "z": -5,
      "name": "Rock_Stone_Brick_Decorative"
    },
    {
      "x": -2,
      "y": 3,
      "z": -5,
      "name": "*Soil_Gravel_Half_State_Definitions_Block",
      "rotation": 7
    },
    {
      "x": -2,
      "y": 4,
      "z": -5,
      "name": "*Soil_Gravel_Half_State_Definitions_Block",
      "rotation": 7
    },
    {
      "x": -2,
      "y": 5,
      "z": -5,
      "name": "*Soil_Gravel_Half_State_Definitions_Block",
      "rotation": 7
    },
    {
      "x": -2,
      "y": 6,
      "z": -5,
      "name": "*Soil_Gravel_Half_State_Definitions_Block",
      "rotation": 7
    },
    {
      "x": -2,
      "y": 7,
      "z": -5,
      "name": "Rock_Stone_Brick"
    },
    {
      "x": -2,
      "y": 1,
      "z": -4,
      "name": "Rock_Stone_Brick"
    },
    {
      "x": -2,
      "y": 2,
      "z": -4,
      "name": "Rock_Stone_Brick_Decorative"
    },
    {
      "x": -2,
      "y": 3,
      "z": -4,
      "name": "Soil_Gravel",
      "support": 15
    },
    {
      "x": -2,
      "y": 4,
      "z": -4,
      "name": "Soil_Gravel",
      "support": 15
    },
    {
      "x": -2,
      "y": 5,
      "z": -4,
      "name": "Soil_Gravel",
      "support": 15
    },
    {
      "x": -2,
      "y": 6,
      "z": -4,
      "name": "Soil_Gravel",
      "support": 15
    },
    {
      "x": -2,
      "y": 7,
      "z": -4,
      "name": "Rock_Stone_Brick_Smooth"
    },
    {
      "x": -2,
      "y": 1,
      "z": -3,
      "name": "Rock_Stone_Brick"
    },
    {
      "x": -2,
      "y": 2,
      "z": -3,
      "name": "Rock_Stone_Brick_Decorative"
    },
    {
      "x": -2,
      "y": 3,
      "z": -3,
      "name": "Soil_Gravel",
      "support": 15
    },
    {
      "x": -2,
      "y": 4,
      "z": -3,
      "name": "Soil_Gravel",
      "support": 15
    },
    {
      "x": -2,
      "y": 5,
      "z": -3,
      "name": "Soil_Gravel",
      "support": 15
    },
    {
      "x": -2,
      "y": 6,
      "z": -3,
      "name": "Soil_Gravel",
      "support": 15
    },
    {
      "x": -2,
      "y": 7,
      "z": -3,
      "name": "Rock_Stone_Brick_Smooth"
    },
    {
      "x": -2,
      "y": 1,
      "z": -2,
      "name": "Rock_Stone_Brick"
    },
    {
      "x": -2,
      "y": 2,
      "z": -2,
      "name": "Rock_Stone_Brick_Decorative"
    },
    {
      "x": -2,
      "y": 3,
      "z": -2,
      "name": "Soil_Gravel",
      "support": 15
    },
    {
      "x": -2,
      "y": 4,
      "z": -2,
      "name": "Soil_Gravel",
      "support": 15
    },
    {
      "x": -2,
      "y": 5,
      "z": -2,
      "name": "Soil_Gravel",
      "support": 15
    },
    {
      "x": -2,
      "y": 6,
      "z": -2,
      "name": "Soil_Gravel",
      "support": 15
    },
    {
      "x": -2,
      "y": 7,
      "z": -2,
      "name": "Rock_Stone_Brick_Smooth"
    },
    {
      "x": -2,
      "y": 1,
      "z": -1,
      "name": "Rock_Stone_Brick"
    },
    {
      "x": -2,
      "y": 2,
      "z": -1,
      "name": "Rock_Stone_Brick_Decorative"
    },
    {
      "x": -2,
      "y": 3,
      "z": -1,
      "name": "Soil_Gravel",
      "support": 15
    },
    {
      "x": -2,
      "y": 4,
      "z": -1,
      "name": "Soil_Gravel",
      "support": 15
    },
    {
      "x": -2,
      "y": 5,
      "z": -1,
      "name": "Soil_Gravel",
      "support": 15
    },
    {
      "x": -2,
      "y": 6,
      "z": -1,
      "name": "Soil_Gravel",
      "support": 15
    },
    {
      "x": -2,
      "y": 7,
      "z": -1,
      "name": "Rock_Stone_Brick_Smooth"
    },
    {
      "x": -2,
      "y": 1,
      "z": 0,
      "name": "Rock_Stone_Brick"
    },
    {
      "x": -2,
      "y": 2,
      "z": 0,
      "name": "Rock_Stone_Brick_Decorative"
    },
    {
      "x": -2,
      "y": 3,
      "z": 0,
      "name": "Soil_Gravel",
      "support": 15
    },
    {
      "x": -2,
      "y": 4,
      "z": 0,
      "name": "Soil_Gravel",
      "support": 15
    },
    {
      "x": -2,
      "y": 5,
      "z": 0,
      "name": "Soil_Gravel",
      "support": 15
    },
    {
      "x": -2,
      "y": 6,
      "z": 0,
      "name": "Soil_Gravel",
      "support": 15
    },
    {
      "x": -2,
      "y": 7,
      "z": 0,
      "name": "Rock_Stone_Brick_Smooth"
    },
    {
      "x": -2,
      "y": 1,
      "z": 1,
      "name": "Rock_Stone_Brick",
      "rotation": 1
    },
    {
      "x": -2,
      "y": 2,
      "z": 1,
      "name": "Rock_Stone_Brick_Decorative",
      "rotation": 1
    },
    {
      "x": -2,
      "y": 3,
      "z": 1,
      "name": "Soil_Gravel",
      "support": 15,
      "rotation": 1
    },
    {
      "x": -2,
      "y": 4,
      "z": 1,
      "name": "Soil_Gravel",
      "support": 15,
      "rotation": 1
    },
    {
      "x": -2,
      "y": 5,
      "z": 1,
      "name": "Soil_Gravel",
      "support": 15,
      "rotation": 1
    },
    {
      "x": -2,
      "y": 6,
      "z": 1,
      "name": "Soil_Gravel",
      "support": 15,
      "rotation": 1
    },
    {
      "x": -2,
      "y": 7,
      "z": 1,
      "name": "Rock_Stone_Brick_Smooth",
      "rotation": 1
    },
    {
      "x": -2,
      "y": 1,
      "z": 2,
      "name": "Rock_Stone_Brick",
      "rotation": 1
    },
    {
      "x": -2,
      "y": 2,
      "z": 2,
      "name": "Rock_Stone_Brick_Decorative",
      "rotation": 1
    },
    {
      "x": -2,
      "y": 3,
      "z": 2,
      "name": "Soil_Gravel",
      "support": 15,
      "rotation": 1
    },
    {
      "x": -2,
      "y": 4,
      "z": 2,
      "name": "Soil_Gravel",
      "support": 15,
      "rotation": 1
    },
    {
      "x": -2,
      "y": 5,
      "z": 2,
      "name": "Soil_Gravel",
      "support": 15,
      "rotation": 1
    },
    {
      "x": -2,
      "y": 6,
      "z": 2,
      "name": "Soil_Gravel",
      "support": 15,
      "rotation": 1
    },
    {
      "x": -2,
      "y": 7,
      "z": 2,
      "name": "Rock_Stone_Brick_Smooth",
      "rotation": 1
    },
    {
      "x": -2,
      "y": 1,
      "z": 3,
      "name": "Rock_Stone_Brick",
      "rotation": 1
    },
    {
      "x": -2,
      "y": 2,
      "z": 3,
      "name": "Rock_Stone_Brick_Decorative",
      "rotation": 1
    },
    {
      "x": -2,
      "y": 3,
      "z": 3,
      "name": "Soil_Gravel",
      "support": 15,
      "rotation": 1
    },
    {
      "x": -2,
      "y": 4,
      "z": 3,
      "name": "Soil_Gravel",
      "support": 15,
      "rotation": 1
    },
    {
      "x": -2,
      "y": 5,
      "z": 3,
      "name": "Soil_Gravel",
      "support": 15,
      "rotation": 1
    },
    {
      "x": -2,
      "y": 6,
      "z": 3,
      "name": "Soil_Gravel",
      "support": 15,
      "rotation": 1
    },
    {
      "x": -2,
      "y": 7,
      "z": 3,
      "name": "Rock_Stone_Brick_Smooth",
      "rotation": 1
    },
    {
      "x": -2,
      "y": 1,
      "z": 4,
      "name": "Rock_Stone_Brick",
      "rotation": 1
    },
    {
      "x": -2,
      "y": 2,
      "z": 4,
      "name": "Rock_Stone_Brick_Decorative",
      "rotation": 1
    },
    {
      "x": -2,
      "y": 3,
      "z": 4,
      "name": "Soil_Gravel",
      "support": 15,
      "rotation": 1
    },
    {
      "x": -2,
      "y": 4,
      "z": 4,
      "name": "Soil_Gravel",
      "support": 15,
      "rotation": 1
    },
    {
      "x": -2,
      "y": 5,
      "z": 4,
      "name": "Soil_Gravel",
      "support": 15,
      "rotation": 1
    },
    {
      "x": -2,
      "y": 6,
      "z": 4,
      "name": "Soil_Gravel",
      "support": 15,
      "rotation": 1
    },
    {
      "x": -2,
      "y": 7,
      "z": 4,
      "name": "Rock_Stone_Brick_Smooth",
      "rotation": 1
    },
    {
      "x": -2,
      "y": 1,
      "z": 5,
      "name": "Rock_Stone_Brick",
      "rotation": 1
    },
    {
      "x": -2,
      "y": 2,
      "z": 5,
      "name": "Rock_Stone_Brick_Decorative",
      "rotation": 1
    },
    {
      "x": -2,
      "y": 3,
      "z": 5,
      "name": "Soil_Gravel",
      "support": 15,
      "rotation": 1
    },
    {
      "x": -2,
      "y": 4,
      "z": 5,
      "name": "Soil_Gravel",
      "support": 15,
      "rotation": 1
    },
    {
      "x": -2,
      "y": 5,
      "z": 5,
      "name": "Soil_Gravel",
      "support": 15,
      "rotation": 1
    },
    {
      "x": -2,
      "y": 6,
      "z": 5,
      "name": "Soil_Gravel",
      "support": 15,
      "rotation": 1
    },
    {
      "x": -2,
      "y": 7,
      "z": 5,
      "name": "Rock_Stone_Brick",
      "rotation": 1
    },
    {
      "x": -2,
      "y": 1,
      "z": 6,
      "name": "Rock_Stone_Brick_Smooth",
      "rotation": 2
    },
    {
      "x": -2,
      "y": 2,
      "z": 6,
      "name": "Rock_Stone_Brick_Decorative",
      "rotation": 1
    },
    {
      "x": -2,
      "y": 3,
      "z": 6,
      "name": "Soil_Gravel_Half",
      "support": 15,
      "rotation": 7
    },
    {
      "x": -2,
      "y": 4,
      "z": 6,
      "name": "Soil_Gravel_Half",
      "support": 15,
      "rotation": 7
    },
    {
      "x": -2,
      "y": 5,
      "z": 6,
      "name": "Soil_Gravel_Half",
      "support": 15,
      "rotation": 7
    },
    {
      "x": -2,
      "y": 6,
      "z": 6,
      "name": "Soil_Gravel_Half",
      "support": 15,
      "rotation": 7
    },
    {
      "x": -2,
      "y": 7,
      "z": 6,
      "name": "Rock_Stone_Brick",
      "rotation": 1
    },
    {
      "x": -2,
      "y": 1,
      "z": 7,
      "name": "Rock_Stone_Brick_Smooth",
      "rotation": 2
    },
    {
      "x": -2,
      "y": 7,
      "z": 7,
      "name": "Rock_Stone_Brick_Smooth",
      "rotation": 2
    },
    {
      "x": -2,
      "y": 1,
      "z": 8,
      "name": "Rock_Stone_Brick_Smooth",
      "rotation": 2
    },
    {
      "x": -2,
      "y": 7,
      "z": 8,
      "name": "Rock_Stone_Brick_Smooth",
      "rotation": 2
    },
    {
      "x": -2,
      "y": 1,
      "z": 9,
      "name": "Rock_Stone_Brick_Smooth",
      "rotation": 2
    },
    {
      "x": -2,
      "y": 7,
      "z": 9,
      "name": "Rock_Stone_Brick_Smooth",
      "rotation": 2
    },
    {
      "x": -2,
      "y": 1,
      "z": 10,
      "name": "Rock_Stone_Brick_Smooth",
      "rotation": 2
    },
    {
      "x": -2,
      "y": 7,
      "z": 10,
      "name": "Rock_Stone_Brick_Smooth",
      "rotation": 2
    },
    {
      "x": -2,
      "y": 1,
      "z": 11,
      "name": "Rock_Stone_Brick_Smooth",
      "rotation": 2
    },
    {
      "x": -2,
      "y": 2,
      "z": 11,
      "name": "Rock_Stone_Brick_Half",
      "rotation": 6
    },
    {
      "x": -2,
      "y": 7,
      "z": 11,
      "name": "Rock_Stone_Brick_Smooth",
      "rotation": 2
    },
    {
      "x": -2,
      "y": 1,
      "z": 12,
      "name": "Rock_Stone_Brick",
      "rotation": 1
    },
    {
      "x": -2,
      "y": 2,
      "z": 12,
      "name": "Rock_Stone_Brick_Decorative",
      "rotation": 2
    },
    {
      "x": -2,
      "y": 3,
      "z": 12,
      "name": "Soil_Gravel",
      "support": 15,
      "rotation": 2
    },
    {
      "x": -2,
      "y": 4,
      "z": 12,
      "name": "Soil_Gravel",
      "support": 15,
      "rotation": 2
    },
    {
      "x": -2,
      "y": 5,
      "z": 12,
      "name": "Soil_Gravel",
      "support": 15,
      "rotation": 2
    },
    {
      "x": -2,
      "y": 6,
      "z": 12,
      "name": "Soil_Gravel",
      "support": 15,
      "rotation": 2
    },
    {
      "x": -2,
      "y": 7,
      "z": 12,
      "name": "Rock_Stone_Brick_Smooth",
      "rotation": 1
    },
    {
      "x": -1,
      "y": 1,
      "z": -13,
      "name": "Rock_Stone_Brick"
    },
    {
      "x": -1,
      "y": 2,
      "z": -13,
      "name": "Rock_Stone_Brick_Decorative",
      "rotation": 1
    },
    {
      "x": -1,
      "y": 3,
      "z": -13,
      "name": "Soil_Gravel",
      "support": 15,
      "rotation": 1
    },
    {
      "x": -1,
      "y": 4,
      "z": -13,
      "name": "Soil_Gravel",
      "support": 15,
      "rotation": 1
    },
    {
      "x": -1,
      "y": 5,
      "z": -13,
      "name": "Soil_Gravel",
      "support": 15,
      "rotation": 1
    },
    {
      "x": -1,
      "y": 6,
      "z": -13,
      "name": "Soil_Gravel",
      "support": 15,
      "rotation": 1
    },
    {
      "x": -1,
      "y": 7,
      "z": -13,
      "name": "Rock_Stone_Brick_Smooth",
      "rotation": 1
    },
    {
      "x": -1,
      "y": 1,
      "z": -12,
      "name": "Rock_Stone_Brick",
      "rotation": 1
    },
    {
      "x": -1,
      "y": 2,
      "z": -12,
      "name": "Rock_Stone_Brick_Decorative",
      "rotation": 1
    },
    {
      "x": -1,
      "y": 3,
      "z": -12,
      "name": "Rock_Stone_Brick_Pillar_Base",
      "rotation": 1
    },
    {
      "x": -1,
      "y": 4,
      "z": -12,
      "name": "Rock_Stone_Brick_Pillar_Middle",
      "rotation": 1
    },
    {
      "x": -1,
      "y": 5,
      "z": -12,
      "name": "Rock_Stone_Brick_Pillar_Middle",
      "rotation": 1
    },
    {
      "x": -1,
      "y": 6,
      "z": -12,
      "name": "Rock_Stone_Brick_Pillar_Base",
      "rotation": 35
    },
    {
      "x": -1,
      "y": 7,
      "z": -12,
      "name": "Rock_Stone_Brick"
    },
    {
      "x": -1,
      "y": 1,
      "z": -11,
      "name": "Rock_Stone_Brick_Smooth",
      "rotation": 1
    },
    {
      "x": -1,
      "y": 7,
      "z": -11,
      "name": "Rock_Stone_Brick_Smooth",
      "rotation": 1
    },
    {
      "x": -1,
      "y": 1,
      "z": -10,
      "name": "Rock_Stone_Brick_Smooth",
      "rotation": 1
    },
    {
      "x": -1,
      "y": 7,
      "z": -10,
      "name": "Rock_Stone_Brick_Smooth",
      "rotation": 1
    },
    {
      "x": -1,
      "y": 1,
      "z": -9,
      "name": "Rock_Stone_Brick_Smooth",
      "rotation": 1
    },
    {
      "x": -1,
      "y": 7,
      "z": -9,
      "name": "Rock_Stone_Brick_Smooth",
      "rotation": 1
    },
    {
      "x": -1,
      "y": 1,
      "z": -8,
      "name": "Rock_Stone_Brick_Smooth",
      "rotation": 1
    },
    {
      "x": -1,
      "y": 7,
      "z": -8,
      "name": "Rock_Stone_Brick_Smooth",
      "rotation": 1
    },
    {
      "x": -1,
      "y": 1,
      "z": -7,
      "name": "Rock_Stone_Brick",
      "rotation": 1
    },
    {
      "x": -1,
      "y": 2,
      "z": -7,
      "name": "Rock_Stone_Brick_Decorative",
      "rotation": 1
    },
    {
      "x": -1,
      "y": 3,
      "z": -7,
      "name": "Rock_Stone_Brick_Pillar_Base",
      "rotation": 1
    },
    {
      "x": -1,
      "y": 4,
      "z": -7,
      "name": "Rock_Stone_Brick_Pillar_Middle",
      "rotation": 1
    },
    {
      "x": -1,
      "y": 5,
      "z": -7,
      "name": "Rock_Stone_Brick_Pillar_Middle",
      "rotation": 1
    },
    {
      "x": -1,
      "y": 6,
      "z": -7,
      "name": "Rock_Stone_Brick_Pillar_Base",
      "rotation": 35
    },
    {
      "x": -1,
      "y": 7,
      "z": -7,
      "name": "Rock_Stone_Brick",
      "rotation": 1
    },
    {
      "x": -1,
      "y": 1,
      "z": -6,
      "name": "Rock_Stone_Brick"
    },
    {
      "x": -1,
      "y": 2,
      "z": -6,
      "name": "Rock_Stone_Brick_Decorative"
    },
    {
      "x": -1,
      "y": 3,
      "z": -6,
      "name": "Soil_Gravel",
      "support": 15
    },
    {
      "x": -1,
      "y": 4,
      "z": -6,
      "name": "Soil_Gravel",
      "support": 15
    },
    {
      "x": -1,
      "y": 5,
      "z": -6,
      "name": "Soil_Gravel",
      "support": 15
    },
    {
      "x": -1,
      "y": 6,
      "z": -6,
      "name": "Soil_Gravel",
      "support": 15
    },
    {
      "x": -1,
      "y": 7,
      "z": -6,
      "name": "Rock_Stone_Brick_Smooth"
    },
    {
      "x": -1,
      "y": 1,
      "z": -5,
      "name": "Rock_Stone_Brick"
    },
    {
      "x": -1,
      "y": 2,
      "z": -5,
      "name": "Rock_Stone_Brick_Decorative"
    },
    {
      "x": -1,
      "y": 3,
      "z": -5,
      "name": "Soil_Gravel",
      "support": 15
    },
    {
      "x": -1,
      "y": 4,
      "z": -5,
      "name": "Soil_Gravel",
      "support": 15
    },
    {
      "x": -1,
      "y": 5,
      "z": -5,
      "name": "Soil_Gravel",
      "support": 15
    },
    {
      "x": -1,
      "y": 6,
      "z": -5,
      "name": "Soil_Gravel",
      "support": 15
    },
    {
      "x": -1,
      "y": 7,
      "z": -5,
      "name": "Rock_Stone_Brick_Smooth"
    },
    {
      "x": -1,
      "y": 1,
      "z": 5,
      "name": "Rock_Stone_Brick",
      "rotation": 1
    },
    {
      "x": -1,
      "y": 2,
      "z": 5,
      "name": "Rock_Stone_Brick_Decorative",
      "rotation": 1
    },
    {
      "x": -1,
      "y": 3,
      "z": 5,
      "name": "Soil_Gravel",
      "support": 15,
      "rotation": 1
    },
    {
      "x": -1,
      "y": 4,
      "z": 5,
      "name": "Soil_Gravel",
      "support": 15,
      "rotation": 1
    },
    {
      "x": -1,
      "y": 5,
      "z": 5,
      "name": "Soil_Gravel",
      "support": 15,
      "rotation": 1
    },
    {
      "x": -1,
      "y": 6,
      "z": 5,
      "name": "Soil_Gravel",
      "support": 15,
      "rotation": 1
    },
    {
      "x": -1,
      "y": 7,
      "z": 5,
      "name": "Rock_Stone_Brick_Smooth",
      "rotation": 1
    },
    {
      "x": -1,
      "y": 1,
      "z": 6,
      "name": "Rock_Stone_Brick",
      "rotation": 1
    },
    {
      "x": -1,
      "y": 2,
      "z": 6,
      "name": "Rock_Stone_Brick_Decorative",
      "rotation": 1
    },
    {
      "x": -1,
      "y": 3,
      "z": 6,
      "name": "Soil_Gravel",
      "support": 15,
      "rotation": 1
    },
    {
      "x": -1,
      "y": 4,
      "z": 6,
      "name": "Soil_Gravel",
      "support": 15,
      "rotation": 1
    },
    {
      "x": -1,
      "y": 5,
      "z": 6,
      "name": "Soil_Gravel",
      "support": 15,
      "rotation": 1
    },
    {
      "x": -1,
      "y": 6,
      "z": 6,
      "name": "Soil_Gravel",
      "support": 15,
      "rotation": 1
    },
    {
      "x": -1,
      "y": 7,
      "z": 6,
      "name": "Rock_Stone_Brick_Smooth",
      "rotation": 1
    },
    {
      "x": -1,
      "y": 1,
      "z": 7,
      "name": "Rock_Stone_Brick",
      "rotation": 2
    },
    {
      "x": -1,
      "y": 2,
      "z": 7,
      "name": "Rock_Stone_Brick_Decorative",
      "rotation": 2
    },
    {
      "x": -1,
      "y": 3,
      "z": 7,
      "name": "Rock_Stone_Brick_Pillar_Base",
      "rotation": 2
    },
    {
      "x": -1,
      "y": 4,
      "z": 7,
      "name": "Rock_Stone_Brick_Pillar_Middle",
      "rotation": 2
    },
    {
      "x": -1,
      "y": 5,
      "z": 7,
      "name": "Rock_Stone_Brick_Pillar_Middle",
      "rotation": 2
    },
    {
      "x": -1,
      "y": 6,
      "z": 7,
      "name": "Rock_Stone_Brick_Pillar_Base",
      "rotation": 32
    },
    {
      "x": -1,
      "y": 7,
      "z": 7,
      "name": "Rock_Stone_Brick",
      "rotation": 2
    },
    {
      "x": -1,
      "y": 1,
      "z": 8,
      "name": "Rock_Stone_Brick_Smooth",
      "rotation": 2
    },
    {
      "x": -1,
      "y": 7,
      "z": 8,
      "name": "Rock_Stone_Brick_Smooth",
      "rotation": 2
    },
    {
      "x": -1,
      "y": 1,
      "z": 9,
      "name": "Rock_Stone_Brick_Smooth",
      "rotation": 2
    },
    {
      "x": -1,
      "y": 7,
      "z": 9,
      "name": "Rock_Stone_Brick_Smooth",
      "rotation": 2
    },
    {
      "x": -1,
      "y": 1,
      "z": 10,
      "name": "Rock_Stone_Brick_Smooth",
      "rotation": 2
    },
    {
      "x": -1,
      "y": 7,
      "z": 10,
      "name": "Rock_Stone_Brick_Smooth",
      "rotation": 2
    },
    {
      "x": -1,
      "y": 1,
      "z": 11,
      "name": "Rock_Stone_Brick_Smooth",
      "rotation": 2
    },
    {
      "x": -1,
      "y": 7,
      "z": 11,
      "name": "Rock_Stone_Brick_Smooth",
      "rotation": 2
    },
    {
      "x": -1,
      "y": 1,
      "z": 12,
      "name": "Rock_Stone_Brick",
      "rotation": 2
    },
    {
      "x": -1,
      "y": 2,
      "z": 12,
      "name": "Rock_Stone_Brick_Decorative",
      "rotation": 2
    },
    {
      "x": -1,
      "y": 3,
      "z": 12,
      "name": "Rock_Stone_Brick_Pillar_Base",
      "rotation": 2
    },
    {
      "x": -1,
      "y": 4,
      "z": 12,
      "name": "Rock_Stone_Brick_Pillar_Middle",
      "rotation": 2
    },
    {
      "x": -1,
      "y": 5,
      "z": 12,
      "name": "Rock_Stone_Brick_Pillar_Middle",
      "rotation": 2
    },
    {
      "x": -1,
      "y": 6,
      "z": 12,
      "name": "Rock_Stone_Brick_Pillar_Base",
      "rotation": 32
    },
    {
      "x": -1,
      "y": 7,
      "z": 12,
      "name": "Rock_Stone_Brick",
      "rotation": 1
    },
    {
      "x": -1,
      "y": 1,
      "z": 13,
      "name": "Rock_Stone_Brick",
      "rotation": 1
    },
    {
      "x": -1,
      "y": 2,
      "z": 13,
      "name": "Rock_Stone_Brick_Decorative",
      "rotation": 2
    },
    {
      "x": -1,
      "y": 3,
      "z": 13,
      "name": "Soil_Gravel",
      "support": 15,
      "rotation": 2
    },
    {
      "x": -1,
      "y": 4,
      "z": 13,
      "name": "Soil_Gravel",
      "support": 15,
      "rotation": 2
    },
    {
      "x": -1,
      "y": 5,
      "z": 13,
      "name": "Soil_Gravel",
      "support": 15,
      "rotation": 2
    },
    {
      "x": -1,
      "y": 6,
      "z": 13,
      "name": "Soil_Gravel",
      "support": 15,
      "rotation": 2
    },
    {
      "x": -1,
      "y": 7,
      "z": 13,
      "name": "Rock_Stone_Brick_Smooth",
      "rotation": 2
    },
    {
      "x": 0,
      "y": 1,
      "z": -13,
      "name": "Rock_Stone_Brick"
    },
    {
      "x": 0,
      "y": 2,
      "z": -13,
      "name": "Rock_Stone_Brick_Decorative",
      "rotation": 1
    },
    {
      "x": 0,
      "y": 3,
      "z": -13,
      "name": "Soil_Gravel",
      "support": 15,
      "rotation": 1
    },
    {
      "x": 0,
      "y": 4,
      "z": -13,
      "name": "Soil_Gravel",
      "support": 15,
      "rotation": 1
    },
    {
      "x": 0,
      "y": 5,
      "z": -13,
      "name": "Soil_Gravel",
      "support": 15,
      "rotation": 1
    },
    {
      "x": 0,
      "y": 6,
      "z": -13,
      "name": "Soil_Gravel",
      "support": 15,
      "rotation": 1
    },
    {
      "x": 0,
      "y": 7,
      "z": -13,
      "name": "Rock_Stone_Brick_Smooth",
      "rotation": 1
    },
    {
      "x": 0,
      "y": 1,
      "z": -12,
      "name": "Rock_Stone_Brick_Smooth",
      "rotation": 1
    },
    {
      "x": 0,
      "y": 2,
      "z": -12,
      "name": "Rock_Stone_Brick_Half",
      "rotation": 4
    },
    {
      "x": 0,
      "y": 7,
      "z": -12,
      "name": "Rock_Stone_Brick_Smooth",
      "rotation": 1
    },
    {
      "x": 0,
      "y": 1,
      "z": -11,
      "name": "Rock_Stone_Brick_Smooth",
      "rotation": 1
    },
    {
      "x": 0,
      "y": 7,
      "z": -11,
      "name": "Rock_Stone_Brick_Smooth",
      "rotation": 1
    },
    {
      "x": 0,
      "y": 1,
      "z": -10,
      "name": "Rock_Stone_Brick_Smooth",
      "rotation": 1
    },
    {
      "x": 0,
      "y": 7,
      "z": -10,
      "name": "Rock_Stone_Brick_Smooth",
      "rotation": 1
    },
    {
      "x": 0,
      "y": 1,
      "z": -9,
      "name": "Rock_Stone_Brick_Smooth",
      "rotation": 1
    },
    {
      "x": 0,
      "y": 7,
      "z": -9,
      "name": "Rock_Stone_Brick_Smooth",
      "rotation": 1
    },
    {
      "x": 0,
      "y": 1,
      "z": -8,
      "name": "Rock_Stone_Brick_Smooth",
      "rotation": 1
    },
    {
      "x": 0,
      "y": 2,
      "z": -8,
      "name": "Rock_Stone_Brick_Decorative"
    },
    {
      "x": 0,
      "y": 3,
      "z": -8,
      "name": "Soil_Gravel_Half",
      "support": 15,
      "rotation": 6
    },
    {
      "x": 0,
      "y": 4,
      "z": -8,
      "name": "Soil_Gravel_Half",
      "support": 15,
      "rotation": 6
    },
    {
      "x": 0,
      "y": 5,
      "z": -8,
      "name": "Soil_Gravel_Half",
      "support": 15,
      "rotation": 6
    },
    {
      "x": 0,
      "y": 6,
      "z": -8,
      "name": "Soil_Gravel_Half",
      "support": 15,
      "rotation": 6
    },
    {
      "x": 0,
      "y": 7,
      "z": -8,
      "name": "Rock_Stone_Brick"
    },
    {
      "x": 0,
      "y": 1,
      "z": -7,
      "name": "Rock_Stone_Brick"
    },
    {
      "x": 0,
      "y": 2,
      "z": -7,
      "name": "Rock_Stone_Brick_Decorative"
    },
    {
      "x": 0,
      "y": 3,
      "z": -7,
      "name": "Soil_Gravel",
      "support": 15
    },
    {
      "x": 0,
      "y": 4,
      "z": -7,
      "name": "Soil_Gravel",
      "support": 15
    },
    {
      "x": 0,
      "y": 5,
      "z": -7,
      "name": "Soil_Gravel",
      "support": 15
    },
    {
      "x": 0,
      "y": 6,
      "z": -7,
      "name": "Soil_Gravel",
      "support": 15
    },
    {
      "x": 0,
      "y": 7,
      "z": -7,
      "name": "Rock_Stone_Brick_Smooth"
    },
    {
      "x": 0,
      "y": 1,
      "z": -6,
      "name": "Rock_Stone_Brick"
    },
    {
      "x": 0,
      "y": 2,
      "z": -6,
      "name": "Rock_Stone_Brick_Decorative"
    },
    {
      "x": 0,
      "y": 3,
      "z": -6,
      "name": "Soil_Gravel",
      "support": 15
    },
    {
      "x": 0,
      "y": 4,
      "z": -6,
      "name": "Soil_Gravel",
      "support": 15
    },
    {
      "x": 0,
      "y": 5,
      "z": -6,
      "name": "Soil_Gravel",
      "support": 15
    },
    {
      "x": 0,
      "y": 6,
      "z": -6,
      "name": "Soil_Gravel",
      "support": 15
    },
    {
      "x": 0,
      "y": 7,
      "z": -6,
      "name": "Rock_Stone_Brick_Smooth"
    },
    {
      "x": 0,
      "y": 1,
      "z": 6,
      "name": "Rock_Stone_Brick",
      "rotation": 1
    },
    {
      "x": 0,
      "y": 2,
      "z": 6,
      "name": "Rock_Stone_Brick_Decorative",
      "rotation": 1
    },
    {
      "x": 0,
      "y": 3,
      "z": 6,
      "name": "Soil_Gravel",
      "support": 15,
      "rotation": 1
    },
    {
      "x": 0,
      "y": 4,
      "z": 6,
      "name": "Soil_Gravel",
      "support": 15,
      "rotation": 1
    },
    {
      "x": 0,
      "y": 5,
      "z": 6,
      "name": "Soil_Gravel",
      "support": 15,
      "rotation": 1
    },
    {
      "x": 0,
      "y": 6,
      "z": 6,
      "name": "Soil_Gravel",
      "support": 15,
      "rotation": 1
    },
    {
      "x": 0,
      "y": 7,
      "z": 6,
      "name": "Rock_Stone_Brick_Smooth",
      "rotation": 1
    },
    {
      "x": 0,
      "y": 1,
      "z": 7,
      "name": "Rock_Stone_Brick",
      "rotation": 1
    },
    {
      "x": 0,
      "y": 2,
      "z": 7,
      "name": "Rock_Stone_Brick_Decorative",
      "rotation": 1
    },
    {
      "x": 0,
      "y": 3,
      "z": 7,
      "name": "Soil_Gravel",
      "support": 15,
      "rotation": 1
    },
    {
      "x": 0,
      "y": 4,
      "z": 7,
      "name": "Soil_Gravel",
      "support": 15,
      "rotation": 1
    },
    {
      "x": 0,
      "y": 5,
      "z": 7,
      "name": "Soil_Gravel",
      "support": 15,
      "rotation": 1
    },
    {
      "x": 0,
      "y": 6,
      "z": 7,
      "name": "Soil_Gravel",
      "support": 15,
      "rotation": 1
    },
    {
      "x": 0,
      "y": 7,
      "z": 7,
      "name": "Rock_Stone_Brick_Smooth",
      "rotation": 1
    },
    {
      "x": 0,
      "y": 1,
      "z": 8,
      "name": "Rock_Stone_Brick_Smooth",
      "rotation": 2
    },
    {
      "x": 0,
      "y": 2,
      "z": 8,
      "name": "Rock_Stone_Brick_Decorative",
      "rotation": 1
    },
    {
      "x": 0,
      "y": 3,
      "z": 8,
      "name": "Soil_Gravel_Half",
      "support": 15,
      "rotation": 4
    },
    {
      "x": 0,
      "y": 4,
      "z": 8,
      "name": "Soil_Gravel_Half",
      "support": 15,
      "rotation": 4
    },
    {
      "x": 0,
      "y": 5,
      "z": 8,
      "name": "Soil_Gravel_Half",
      "support": 15,
      "rotation": 4
    },
    {
      "x": 0,
      "y": 6,
      "z": 8,
      "name": "Soil_Gravel_Half",
      "support": 15,
      "rotation": 4
    },
    {
      "x": 0,
      "y": 7,
      "z": 8,
      "name": "Rock_Stone_Brick",
      "rotation": 1
    },
    {
      "x": 0,
      "y": 1,
      "z": 9,
      "name": "Rock_Stone_Brick_Smooth",
      "rotation": 2
    },
    {
      "x": 0,
      "y": 7,
      "z": 9,
      "name": "Rock_Stone_Brick_Smooth",
      "rotation": 2
    },
    {
      "x": 0,
      "y": 1,
      "z": 10,
      "name": "Rock_Stone_Brick_Smooth",
      "rotation": 2
    },
    {
      "x": 0,
      "y": 7,
      "z": 10,
      "name": "Rock_Stone_Brick_Smooth",
      "rotation": 2
    },
    {
      "x": 0,
      "y": 1,
      "z": 11,
      "name": "Rock_Stone_Brick_Smooth",
      "rotation": 2
    },
    {
      "x": 0,
      "y": 7,
      "z": 11,
      "name": "Rock_Stone_Brick_Smooth",
      "rotation": 2
    },
    {
      "x": 0,
      "y": 1,
      "z": 12,
      "name": "Rock_Stone_Brick_Smooth",
      "rotation": 2
    },
    {
      "x": 0,
      "y": 2,
      "z": 12,
      "name": "Rock_Stone_Brick_Half",
      "rotation": 6
    },
    {
      "x": 0,
      "y": 7,
      "z": 12,
      "name": "Rock_Stone_Brick_Smooth",
      "rotation": 2
    },
    {
      "x": 0,
      "y": 1,
      "z": 13,
      "name": "Rock_Stone_Brick",
      "rotation": 1
    },
    {
      "x": 0,
      "y": 2,
      "z": 13,
      "name": "Rock_Stone_Brick_Decorative",
      "rotation": 2
    },
    {
      "x": 0,
      "y": 3,
      "z": 13,
      "name": "Soil_Gravel",
      "support": 15,
      "rotation": 2
    },
    {
      "x": 0,
      "y": 4,
      "z": 13,
      "name": "Soil_Gravel",
      "support": 15,
      "rotation": 2
    },
    {
      "x": 0,
      "y": 5,
      "z": 13,
      "name": "Soil_Gravel",
      "support": 15,
      "rotation": 2
    },
    {
      "x": 0,
      "y": 6,
      "z": 13,
      "name": "Soil_Gravel",
      "support": 15,
      "rotation": 2
    },
    {
      "x": 0,
      "y": 7,
      "z": 13,
      "name": "Rock_Stone_Brick_Smooth",
      "rotation": 2
    },
    {
      "x": 1,
      "y": 1,
      "z": -14,
      "name": "Rock_Stone_Brick"
    },
    {
      "x": 1,
      "y": 2,
      "z": -14,
      "name": "Rock_Stone_Brick_Decorative"
    },
    {
      "x": 1,
      "y": 3,
      "z": -14,
      "name": "*Soil_Gravel_Half_State_Definitions_Block",
      "rotation": 6
    },
    {
      "x": 1,
      "y": 4,
      "z": -14,
      "name": "*Soil_Gravel_Half_State_Definitions_Block",
      "rotation": 6
    },
    {
      "x": 1,
      "y": 5,
      "z": -14,
      "name": "*Soil_Gravel_Half_State_Definitions_Block",
      "rotation": 6
    },
    {
      "x": 1,
      "y": 6,
      "z": -14,
      "name": "*Soil_Gravel_Half_State_Definitions_Block",
      "rotation": 6
    },
    {
      "x": 1,
      "y": 7,
      "z": -14,
      "name": "Rock_Stone_Brick_Smooth"
    },
    {
      "x": 1,
      "y": 1,
      "z": -13,
      "name": "Rock_Stone_Brick",
      "rotation": 1
    },
    {
      "x": 1,
      "y": 2,
      "z": -13,
      "name": "Rock_Stone_Brick_Decorative",
      "rotation": 1
    },
    {
      "x": 1,
      "y": 3,
      "z": -13,
      "name": "Soil_Gravel_Half",
      "support": 15,
      "rotation": 4
    },
    {
      "x": 1,
      "y": 4,
      "z": -13,
      "name": "Soil_Gravel_Half",
      "support": 15,
      "rotation": 4
    },
    {
      "x": 1,
      "y": 5,
      "z": -13,
      "name": "Soil_Gravel_Half",
      "support": 15,
      "rotation": 4
    },
    {
      "x": 1,
      "y": 6,
      "z": -13,
      "name": "Soil_Gravel_Half",
      "support": 15,
      "rotation": 4
    },
    {
      "x": 1,
      "y": 7,
      "z": -13,
      "name": "Rock_Stone_Brick"
    },
    {
      "x": 1,
      "y": 1,
      "z": -12,
      "name": "Rock_Stone_Brick_Smooth",
      "rotation": 1
    },
    {
      "x": 1,
      "y": 7,
      "z": -12,
      "name": "Rock_Stone_Brick_Smooth",
      "rotation": 1
    },
    {
      "x": 1,
      "y": 1,
      "z": -11,
      "name": "Rock_Stone_Brick_Smooth",
      "rotation": 1
    },
    {
      "x": 1,
      "y": 7,
      "z": -11,
      "name": "Rock_Stone_Brick_Smooth",
      "rotation": 1
    },
    {
      "x": 1,
      "y": 1,
      "z": -10,
      "name": "Rock_Stone_Brick_Smooth",
      "rotation": 1
    },
    {
      "x": 1,
      "y": 7,
      "z": -10,
      "name": "Rock_Stone_Brick_Smooth",
      "rotation": 1
    },
    {
      "x": 1,
      "y": 1,
      "z": -9,
      "name": "Rock_Stone_Brick_Smooth",
      "rotation": 1
    },
    {
      "x": 1,
      "y": 2,
      "z": -9,
      "name": "Rock_Stone_Brick_Half",
      "rotation": 6
    },
    {
      "x": 1,
      "y": 7,
      "z": -9,
      "name": "Rock_Stone_Brick_Smooth",
      "rotation": 1
    },
    {
      "x": 1,
      "y": 1,
      "z": -8,
      "name": "Rock_Stone_Brick"
    },
    {
      "x": 1,
      "y": 2,
      "z": -8,
      "name": "Rock_Stone_Brick_Decorative"
    },
    {
      "x": 1,
      "y": 3,
      "z": -8,
      "name": "Soil_Gravel",
      "support": 15
    },
    {
      "x": 1,
      "y": 4,
      "z": -8,
      "name": "Soil_Gravel",
      "support": 15
    },
    {
      "x": 1,
      "y": 5,
      "z": -8,
      "name": "Soil_Gravel",
      "support": 15
    },
    {
      "x": 1,
      "y": 6,
      "z": -8,
      "name": "Soil_Gravel",
      "support": 15
    },
    {
      "x": 1,
      "y": 7,
      "z": -8,
      "name": "Rock_Stone_Brick"
    },
    {
      "x": 1,
      "y": 1,
      "z": -7,
      "name": "Rock_Stone_Brick"
    },
    {
      "x": 1,
      "y": 2,
      "z": -7,
      "name": "Rock_Stone_Brick_Decorative"
    },
    {
      "x": 1,
      "y": 3,
      "z": -7,
      "name": "Soil_Gravel",
      "support": 15
    },
    {
      "x": 1,
      "y": 4,
      "z": -7,
      "name": "Soil_Gravel",
      "support": 15
    },
    {
      "x": 1,
      "y": 5,
      "z": -7,
      "name": "Soil_Gravel",
      "support": 15
    },
    {
      "x": 1,
      "y": 6,
      "z": -7,
      "name": "Soil_Gravel",
      "support": 15
    },
    {
      "x": 1,
      "y": 7,
      "z": -7,
      "name": "Rock_Stone_Brick_Smooth"
    },
    {
      "x": 1,
      "y": 1,
      "z": 7,
      "name": "Rock_Stone_Brick",
      "rotation": 1
    },
    {
      "x": 1,
      "y": 2,
      "z": 7,
      "name": "Rock_Stone_Brick_Decorative",
      "rotation": 1
    },
    {
      "x": 1,
      "y": 3,
      "z": 7,
      "name": "Soil_Gravel",
      "support": 15,
      "rotation": 1
    },
    {
      "x": 1,
      "y": 4,
      "z": 7,
      "name": "Soil_Gravel",
      "support": 15,
      "rotation": 1
    },
    {
      "x": 1,
      "y": 5,
      "z": 7,
      "name": "Soil_Gravel",
      "support": 15,
      "rotation": 1
    },
    {
      "x": 1,
      "y": 6,
      "z": 7,
      "name": "Soil_Gravel",
      "support": 15,
      "rotation": 1
    },
    {
      "x": 1,
      "y": 7,
      "z": 7,
      "name": "Rock_Stone_Brick_Smooth",
      "rotation": 1
    },
    {
      "x": 1,
      "y": 1,
      "z": 8,
      "name": "Rock_Stone_Brick",
      "rotation": 1
    },
    {
      "x": 1,
      "y": 2,
      "z": 8,
      "name": "Rock_Stone_Brick_Decorative",
      "rotation": 1
    },
    {
      "x": 1,
      "y": 3,
      "z": 8,
      "name": "*Soil_Gravel_Half_State_Definitions_Block",
      "rotation": 4
    },
    {
      "x": 1,
      "y": 4,
      "z": 8,
      "name": "*Soil_Gravel_Half_State_Definitions_Block",
      "rotation": 4
    },
    {
      "x": 1,
      "y": 5,
      "z": 8,
      "name": "*Soil_Gravel_Half_State_Definitions_Block",
      "rotation": 4
    },
    {
      "x": 1,
      "y": 6,
      "z": 8,
      "name": "*Soil_Gravel_Half_State_Definitions_Block",
      "rotation": 4
    },
    {
      "x": 1,
      "y": 7,
      "z": 8,
      "name": "Rock_Stone_Brick",
      "rotation": 1
    },
    {
      "x": 1,
      "y": 1,
      "z": 9,
      "name": "Rock_Stone_Brick_Smooth",
      "rotation": 2
    },
    {
      "x": 1,
      "y": 2,
      "z": 9,
      "name": "Rock_Stone_Brick_Half",
      "rotation": 4
    },
    {
      "x": 1,
      "y": 7,
      "z": 9,
      "name": "Rock_Stone_Brick_Smooth",
      "rotation": 2
    },
    {
      "x": 1,
      "y": 1,
      "z": 10,
      "name": "Rock_Stone_Brick_Smooth",
      "rotation": 2
    },
    {
      "x": 1,
      "y": 7,
      "z": 10,
      "name": "Rock_Stone_Brick_Smooth",
      "rotation": 2
    },
    {
      "x": 1,
      "y": 1,
      "z": 11,
      "name": "Rock_Stone_Brick_Smooth",
      "rotation": 2
    },
    {
      "x": 1,
      "y": 7,
      "z": 11,
      "name": "Rock_Stone_Brick_Smooth",
      "rotation": 2
    },
    {
      "x": 1,
      "y": 1,
      "z": 12,
      "name": "Rock_Stone_Brick_Smooth",
      "rotation": 2
    },
    {
      "x": 1,
      "y": 7,
      "z": 12,
      "name": "Rock_Stone_Brick_Smooth",
      "rotation": 2
    },
    {
      "x": 1,
      "y": 1,
      "z": 13,
      "name": "Rock_Stone_Brick_Smooth",
      "rotation": 1
    },
    {
      "x": 1,
      "y": 2,
