{
  "version": 8,
  "blockIdVersion": 11,
  "anchorX": 0,
  "anchorY": 0,
  "anchorZ": 0,
  "blocks": [
    {
      "x": -7,
      "y": 0,
      "z": -7,
      "name": "Wood_Blackwood_Decorative"
    },
    {
      "x": -7,
      "y": 1,
      "z": -7,
      "name": "Rock_Stone_Brick"
    },
    {
      "x": -7,
      "y": 2,
      "z": -7,
      "name": "Rock_Stone_Brick"
    },
    {
      "x": -7,
      "y": 3,
      "z": -7,
      "name": "Rock_Stone_Brick"
    },
    {
      "x": -7,
      "y": 4,
      "z": -7,
      "name": "Rock_Stone_Brick"
    },
    {
      "x": -7,
      "y": 5,
      "z": -7,
      "name": "Rock_Stone_Brick"
    },
    {
      "x": -7,
      "y": 6,
      "z": -7,
      "name": "Rock_Stone_Brick"
    },
    {
      "x": -7,
      "y": 7,
      "z": -7,
      "name": "Rock_Stone_Brick"
    },
    {
      "x": -7,
      "y": 8,
      "z": -7,
      "name": "Rock_Stone_Brick"
    },
    {
      "x": -7,
      "y": 9,
      "z": -7,
      "name": "Rock_Stone_Brick"
    },
    {
      "x": -7,
      "y": 10,
      "z": -7,
      "name": "Rock_Stone_Brick"
    },
    {
      "x": -7,
      "y": 11,
      "z": -7,
      "name": "Rock_Stone_Brick"
    },
    {
      "x": -7,
      "y": 12,
      "z": -7,
      "name": "Rock_Stone_Brick"
    },
    {
      "x": -7,
      "y": 13,
      "z": -7,
      "name": "Rock_Stone_Brick"
    },
    {
      "x": -7,
      "y": 14,
      "z": -7,
      "name": "Rock_Stone_Brick"
    },
    {
      "x": -7,
      "y": 15,
      "z": -7,
      "name": "Rock_Stone_Brick"
    },
    {
      "x": -7,
      "y": 0,
      "z": -6,
      "name": "Rock_Stone_Brick"
    },
    {
      "x": -7,
      "y": 1,
      "z": -6,
      "name": "Rock_Stone_Brick"
    },
    {
      "x": -7,
      "y": 2,
      "z": -6,
      "name": "Rock_Stone_Brick"
    },
    {
      "x": -7,
      "y": 3,
      "z": -6,
      "name": "Rock_Stone_Brick"
    },
    {
      "x": -7,
      "y": 4,
      "z": -6,
      "name": "Rock_Stone_Brick"
    },
    {
      "x": -7,
      "y": 5,
      "z": -6,
      "name": "Rock_Stone_Brick"
    },
    {
      "x": -7,
      "y": 6,
      "z": -6,
      "name": "Rock_Stone_Brick"
    },
    {
      "x": -7,
      "y": 7,
      "z": -6,
      "name": "Rock_Stone_Brick"
    },
    {
      "x": -7,
      "y": 8,
      "z": -6,
      "name": "Rock_Stone_Brick"
    },
    {
      "x": -7,
      "y": 9,
      "z": -6,
      "name": "Rock_Stone_Brick"
    },
    {
      "x": -7,
      "y": 10,
      "z": -6,
      "name": "Rock_Stone_Brick"
    },
    {
      "x": -7,
      "y": 11,
      "z": -6,
      "name": "Rock_Stone_Brick"
    },
    {
      "x": -7,
      "y": 12,
      "z": -6,
      "name": "Rock_Stone_Brick"
    },
    {
      "x": -7,
      "y": 13,
      "z": -6,
      "name": "Rock_Stone_Brick"
    },
    {
      "x": -7,
      "y": 14,
      "z": -6,
      "name": "Rock_Stone_Brick"
    },
    {
      "x": -7,
      "y": 15,
      "z": -6,
      "name": "Rock_Stone_Brick"
    },
    {
      "x": -7,
      "y": 0,
      "z": -5,
      "name": "Rock_Stone_Brick"
    },
    {
      "x": -7,
      "y": 1,
      "z": -5,
      "name": "Rock_Stone_Brick"
    },
    {
      "x": -7,
      "y": 2,
      "z": -5,
      "name": "Rock_Stone_Brick"
    },
    {
      "x": -7,
      "y": 3,
      "z": -5,
      "name": "Rock_Stone_Brick"
    },
    {
      "x": -7,
      "y": 4,
      "z": -5,
      "name": "Rock_Stone_Brick"
    },
    {
      "x": -7,
      "y": 5,
      "z": -5,
      "name": "Rock_Stone_Brick"
    },
    {
      "x": -7,
      "y": 6,
      "z": -5,
      "name": "Rock_Stone_Brick"
    },
    {
      "x": -7,
      "y": 7,
      "z": -5,
      "name": "Rock_Stone_Brick"
    },
    {
      "x": -7,
      "y": 8,
      "z": -5,
      "name": "Rock_Stone_Brick"
    },
    {
      "x": -7,
      "y": 9,
      "z": -5,
      "name": "Rock_Stone_Brick"
    },
    {
      "x": -7,
      "y": 10,
      "z": -5,
      "name": "Rock_Stone_Brick"
    },
    {
      "x": -7,
      "y": 11,
      "z": -5,
      "name": "Rock_Stone_Brick"
    },
    {
      "x": -7,
      "y": 12,
      "z": -5,
      "name": "Rock_Stone_Brick"
    },
    {
      "x": -7,
      "y": 13,
      "z": -5,
      "name": "Rock_Stone_Brick"
    },
    {
      "x": -7,
      "y": 14,
      "z": -5,
      "name": "Rock_Stone_Brick"
    },
    {
      "x": -7,
      "y": 15,
      "z": -5,
      "name": "Rock_Stone_Brick"
    },
    {
      "x": -7,
      "y": 0,
      "z": -4,
      "name": "Rock_Stone_Brick"
    },
    {
      "x": -7,
      "y": 1,
      "z": -4,
      "name": "Rock_Stone_Brick"
    },
    {
      "x": -7,
      "y": 2,
      "z": -4,
      "name": "Rock_Stone_Brick"
    },
    {
      "x": -7,
      "y": 3,
      "z": -4,
      "name": "Rock_Stone_Brick"
    },
    {
      "x": -7,
      "y": 4,
      "z": -4,
      "name": "Rock_Stone_Brick"
    },
    {
      "x": -7,
      "y": 5,
      "z": -4,
      "name": "Rock_Stone_Brick"
    },
    {
      "x": -7,
      "y": 6,
      "z": -4,
      "name": "Rock_Stone_Brick"
    },
    {
      "x": -7,
      "y": 7,
      "z": -4,
      "name": "Rock_Stone_Brick"
    },
    {
      "x": -7,
      "y": 8,
      "z": -4,
      "name": "Rock_Stone_Brick"
    },
    {
      "x": -7,
      "y": 9,
      "z": -4,
      "name": "Rock_Stone_Brick"
    },
    {
      "x": -7,
      "y": 10,
      "z": -4,
      "name": "Rock_Stone_Brick"
    },
    {
      "x": -7,
      "y": 11,
      "z": -4,
      "name": "Rock_Stone_Brick"
    },
    {
      "x": -7,
      "y": 12,
      "z": -4,
      "name": "Rock_Stone_Brick"
    },
    {
      "x": -7,
      "y": 13,
      "z": -4,
      "name": "Rock_Stone_Brick"
    },
    {
      "x": -7,
      "y": 14,
      "z": -4,
      "name": "Rock_Stone_Brick"
    },
    {
      "x": -7,
      "y": 15,
      "z": -4,
      "name": "Rock_Stone_Brick"
    },
    {
      "x": -7,
      "y": 0,
      "z": -3,
      "name": "Rock_Stone_Brick"
    },
    {
      "x": -7,
      "y": 1,
      "z": -3,
      "name": "Rock_Stone_Brick"
    },
    {
      "x": -7,
      "y": 2,
      "z": -3,
      "name": "Rock_Stone_Brick"
    },
    {
      "x": -7,
      "y": 3,
      "z": -3,
      "name": "Rock_Stone_Brick"
    },
    {
      "x": -7,
      "y": 4,
      "z": -3,
      "name": "Rock_Stone_Brick"
    },
    {
      "x": -7,
      "y": 5,
      "z": -3,
      "name": "Rock_Stone_Brick"
    },
    {
      "x": -7,
      "y": 6,
      "z": -3,
      "name": "Rock_Stone_Brick"
    },
    {
      "x": -7,
      "y": 7,
      "z": -3,
      "name": "Rock_Stone_Brick"
    },
    {
      "x": -7,
      "y": 8,
      "z": -3,
      "name": "Rock_Stone_Brick"
    },
    {
      "x": -7,
      "y": 9,
      "z": -3,
      "name": "Rock_Stone_Brick"
    },
    {
      "x": -7,
      "y": 10,
      "z": -3,
      "name": "Rock_Stone_Brick"
    },
    {
      "x": -7,
      "y": 11,
      "z": -3,
      "name": "Rock_Stone_Brick"
    },
    {
      "x": -7,
      "y": 12,
      "z": -3,
      "name": "Rock_Stone_Brick"
    },
    {
      "x": -7,
      "y": 13,
      "z": -3,
      "name": "Rock_Stone_Brick"
    },
    {
      "x": -7,
      "y": 14,
      "z": -3,
      "name": "Rock_Stone_Brick"
    },
    {
      "x": -7,
      "y": 15,
      "z": -3,
      "name": "Rock_Stone_Brick"
    },
    {
      "x": -7,
      "y": 0,
      "z": -2,
      "name": "Rock_Stone_Brick"
    },
    {
      "x": -7,
      "y": 1,
      "z": -2,
      "name": "Rock_Stone_Brick"
    },
    {
      "x": -7,
      "y": 2,
      "z": -2,
      "name": "Rock_Stone_Brick"
    },
    {
      "x": -7,
      "y": 3,
      "z": -2,
      "name": "Rock_Stone_Brick"
    },
    {
      "x": -7,
      "y": 4,
      "z": -2,
      "name": "Rock_Stone_Brick"
    },
    {
      "x": -7,
      "y": 5,
      "z": -2,
      "name": "Rock_Stone_Brick"
    },
    {
      "x": -7,
      "y": 6,
      "z": -2,
      "name": "Rock_Stone_Brick"
    },
    {
      "x": -7,
      "y": 7,
      "z": -2,
      "name": "Rock_Stone_Brick"
    },
    {
      "x": -7,
      "y": 8,
      "z": -2,
      "name": "Rock_Stone_Brick"
    },
    {
      "x": -7,
      "y": 9,
      "z": -2,
      "name": "Rock_Stone_Brick"
    },
    {
      "x": -7,
      "y": 10,
      "z": -2,
      "name": "Rock_Stone_Brick"
    },
    {
      "x": -7,
      "y": 11,
      "z": -2,
      "name": "Rock_Stone_Brick"
    },
    {
      "x": -7,
      "y": 12,
      "z": -2,
      "name": "Rock_Stone_Brick"
    },
    {
      "x": -7,
      "y": 13,
      "z": -2,
      "name": "Rock_Stone_Brick"
    },
    {
      "x": -7,
      "y": 14,
      "z": -2,
      "name": "Rock_Stone_Brick"
    },
    {
      "x": -7,
      "y": 15,
      "z": -2,
      "name": "Rock_Stone_Brick"
    },
    {
      "x": -7,
      "y": 0,
      "z": -1,
      "name": "Rock_Stone_Brick"
    },
    {
      "x": -7,
      "y": 1,
      "z": -1,
      "name": "Rock_Stone_Brick"
    },
    {
      "x": -7,
      "y": 2,
      "z": -1,
      "name": "Rock_Stone_Brick"
    },
    {
      "x": -7,
      "y": 3,
      "z": -1,
      "name": "Rock_Stone_Brick"
    },
    {
      "x": -7,
      "y": 4,
      "z": -1,
      "name": "Rock_Stone_Brick"
    },
    {
      "x": -7,
      "y": 5,
      "z": -1,
      "name": "Rock_Stone_Brick"
    },
    {
      "x": -7,
      "y": 6,
      "z": -1,
      "name": "Rock_Stone_Brick"
    },
    {
      "x": -7,
      "y": 7,
      "z": -1,
      "name": "Rock_Stone_Brick"
    },
    {
      "x": -7,
      "y": 8,
      "z": -1,
      "name": "Rock_Stone_Brick"
    },
    {
      "x": -7,
      "y": 9,
      "z": -1,
      "name": "Rock_Stone_Brick"
    },
    {
      "x": -7,
      "y": 10,
      "z": -1,
      "name": "Rock_Stone_Brick"
    },
    {
      "x": -7,
      "y": 11,
      "z": -1,
      "name": "Rock_Stone_Brick"
    },
    {
      "x": -7,
      "y": 12,
      "z": -1,
      "name": "Rock_Stone_Brick"
    },
    {
      "x": -7,
      "y": 13,
      "z": -1,
      "name": "Rock_Stone_Brick"
    },
    {
      "x": -7,
      "y": 14,
      "z": -1,
      "name": "Rock_Stone_Brick"
    },
    {
      "x": -7,
      "y": 15,
      "z": -1,
      "name": "Rock_Stone_Brick"
    },
    {
      "x": -7,
      "y": 0,
      "z": 0,
      "name": "Rock_Stone_Brick"
    },
    {
      "x": -7,
      "y": 1,
      "z": 0,
      "name": "Rock_Stone_Brick"
    },
    {
      "x": -7,
      "y": 2,
      "z": 0,
      "name": "Rock_Stone_Brick"
    },
    {
      "x": -7,
      "y": 3,
      "z": 0,
      "name": "Rock_Stone_Brick"
    },
    {
      "x": -7,
      "y": 4,
      "z": 0,
      "name": "Rock_Stone_Brick"
    },
    {
      "x": -7,
      "y": 5,
      "z": 0,
      "name": "Rock_Stone_Brick"
    },
    {
      "x": -7,
      "y": 6,
      "z": 0,
      "name": "Rock_Stone_Brick"
    },
    {
      "x": -7,
      "y": 7,
      "z": 0,
      "name": "Rock_Stone_Brick"
    },
    {
      "x": -7,
      "y": 8,
      "z": 0,
      "name": "Rock_Stone_Brick"
    },
    {
      "x": -7,
      "y": 9,
      "z": 0,
      "name": "Rock_Stone_Brick"
    },
    {
      "x": -7,
      "y": 10,
      "z": 0,
      "name": "Rock_Stone_Brick"
    },
    {
      "x": -7,
      "y": 11,
      "z": 0,
      "name": "Rock_Stone_Brick"
    },
    {
      "x": -7,
      "y": 12,
      "z": 0,
      "name": "Rock_Stone_Brick"
    },
    {
      "x": -7,
      "y": 13,
      "z": 0,
      "name": "Rock_Stone_Brick"
    },
    {
      "x": -7,
      "y": 14,
      "z": 0,
      "name": "Rock_Stone_Brick"
    },
    {
      "x": -7,
      "y": 15,
      "z": 0,
      "name": "Rock_Stone_Brick"
    },
    {
      "x": -7,
      "y": 0,
      "z": 1,
      "name": "Rock_Stone_Brick"
    },
    {
      "x": -7,
      "y": 1,
      "z": 1,
      "name": "Rock_Stone_Brick"
    },
    {
      "x": -7,
      "y": 2,
      "z": 1,
      "name": "Rock_Stone_Brick"
    },
    {
      "x": -7,
      "y": 3,
      "z": 1,
      "name": "Rock_Stone_Mossy"
    },
    {
      "x": -7,
      "y": 4,
      "z": 1,
      "name": "Rock_Stone_Brick"
    },
    {
      "x": -7,
      "y": 5,
      "z": 1,
      "name": "Rock_Stone_Mossy"
    },
    {
      "x": -7,
      "y": 6,
      "z": 1,
      "name": "Rock_Stone_Brick"
    },
    {
      "x": -7,
      "y": 7,
      "z": 1,
      "name": "Rock_Stone_Brick"
    },
    {
      "x": -7,
      "y": 8,
      "z": 1,
      "name": "Rock_Stone_Brick"
    },
    {
      "x": -7,
      "y": 9,
      "z": 1,
      "name": "Rock_Stone_Brick"
    },
    {
      "x": -7,
      "y": 10,
      "z": 1,
      "name": "Rock_Stone_Brick"
    },
    {
      "x": -7,
      "y": 11,
      "z": 1,
      "name": "Rock_Stone_Brick"
    },
    {
      "x": -7,
      "y": 12,
      "z": 1,
      "name": "Rock_Stone_Brick"
    },
    {
      "x": -7,
      "y": 13,
      "z": 1,
      "name": "Rock_Stone_Brick"
    },
    {
      "x": -7,
      "y": 14,
      "z": 1,
      "name": "Rock_Stone_Brick"
    },
    {
      "x": -7,
      "y": 15,
      "z": 1,
      "name": "Rock_Stone_Brick"
    },
    {
      "x": -7,
      "y": 0,
      "z": 2,
      "name": "Rock_Stone_Brick"
    },
    {
      "x": -7,
      "y": 1,
      "z": 2,
      "name": "Rock_Stone_Brick"
    },
    {
      "x": -7,
      "y": 2,
      "z": 2,
      "name": "Rock_Stone_Mossy"
    },
    {
      "x": -7,
      "y": 3,
      "z": 2,
      "name": "Rock_Stone_Cobble_Mossy_Half"
    },
    {
      "x": -7,
      "y": 4,
      "z": 2,
      "name": "Rock_Stone_Brick_Mossy"
    },
    {
      "x": -7,
      "y": 5,
      "z": 2,
      "name": "Rock_Stone_Brick"
    },
    {
      "x": -7,
      "y": 6,
      "z": 2,
      "name": "Rock_Stone_Brick"
    },
    {
      "x": -7,
      "y": 7,
      "z": 2,
      "name": "Rock_Stone_Brick"
    },
    {
      "x": -7,
      "y": 8,
      "z": 2,
      "name": "Rock_Stone_Brick"
    },
    {
      "x": -7,
      "y": 9,
      "z": 2,
      "name": "Rock_Stone_Brick"
    },
    {
      "x": -7,
      "y": 10,
      "z": 2,
      "name": "Rock_Stone_Brick"
    },
    {
      "x": -7,
      "y": 11,
      "z": 2,
      "name": "Rock_Stone_Brick"
    },
    {
      "x": -7,
      "y": 12,
      "z": 2,
      "name": "Rock_Stone_Brick"
    },
    {
      "x": -7,
      "y": 13,
      "z": 2,
      "name": "Rock_Stone_Brick"
    },
    {
      "x": -7,
      "y": 14,
      "z": 2,
      "name": "Rock_Stone_Brick"
    },
    {
      "x": -7,
      "y": 15,
      "z": 2,
      "name": "Rock_Stone_Brick"
    },
    {
      "x": -7,
      "y": 0,
      "z": 3,
      "name": "Rock_Stone_Brick"
    },
    {
      "x": -7,
      "y": 1,
      "z": 3,
      "name": "Rock_Stone_Brick"
    },
    {
      "x": -7,
      "y": 2,
      "z": 3,
      "name": "Rock_Stone_Mossy"
    },
    {
      "x": -7,
      "y": 3,
      "z": 3,
      "name": "Rock_Stone_Brick"
    },
    {
      "x": -7,
      "y": 4,
      "z": 3,
      "name": "Rock_Stone_Brick"
    },
    {
      "x": -7,
      "y": 5,
      "z": 3,
      "name": "Rock_Stone_Brick"
    },
    {
      "x": -7,
      "y": 6,
      "z": 3,
      "name": "Rock_Stone_Brick"
    },
    {
      "x": -7,
      "y": 7,
      "z": 3,
      "name": "Rock_Stone_Brick"
    },
    {
      "x": -7,
      "y": 8,
      "z": 3,
      "name": "Rock_Stone_Brick"
    },
    {
      "x": -7,
      "y": 9,
      "z": 3,
      "name": "Rock_Stone_Brick"
    },
    {
      "x": -7,
      "y": 10,
      "z": 3,
      "name": "Rock_Stone_Brick"
    },
    {
      "x": -7,
      "y": 11,
      "z": 3,
      "name": "Rock_Stone_Brick"
    },
    {
      "x": -7,
      "y": 12,
      "z": 3,
      "name": "Rock_Stone_Brick"
    },
    {
      "x": -7,
      "y": 13,
      "z": 3,
      "name": "Rock_Stone_Brick"
    },
    {
      "x": -7,
      "y": 14,
      "z": 3,
      "name": "Rock_Stone_Brick"
    },
    {
      "x": -7,
      "y": 15,
      "z": 3,
      "name": "Rock_Stone_Brick"
    },
    {
      "x": -7,
      "y": 0,
      "z": 4,
      "name": "Rock_Stone_Brick"
    },
    {
      "x": -7,
      "y": 1,
      "z": 4,
      "name": "Rock_Stone_Brick"
    },
    {
      "x": -7,
      "y": 2,
      "z": 4,
      "name": "Rock_Stone_Cobble_Mossy_Half"
    },
    {
      "x": -7,
      "y": 3,
      "z": 4,
      "name": "Rock_Stone_Brick"
    },
    {
      "x": -7,
      "y": 4,
      "z": 4,
      "name": "Rock_Stone_Cobble_Mossy"
    },
    {
      "x": -7,
      "y": 5,
      "z": 4,
      "name": "Rock_Stone_Brick"
    },
    {
      "x": -7,
      "y": 6,
      "z": 4,
      "name": "Rock_Stone_Brick"
    },
    {
      "x": -7,
      "y": 7,
      "z": 4,
      "name": "Rock_Stone_Brick"
    },
    {
      "x": -7,
      "y": 8,
      "z": 4,
      "name": "Rock_Stone_Brick"
    },
    {
      "x": -7,
      "y": 9,
      "z": 4,
      "name": "Rock_Stone_Brick"
    },
    {
      "x": -7,
      "y": 10,
      "z": 4,
      "name": "Rock_Stone_Brick"
    },
    {
      "x": -7,
      "y": 11,
      "z": 4,
      "name": "Rock_Stone_Brick"
    },
    {
      "x": -7,
      "y": 12,
      "z": 4,
      "name": "Rock_Stone_Brick"
    },
    {
      "x": -7,
      "y": 13,
      "z": 4,
      "name": "Rock_Stone_Brick"
    },
    {
      "x": -7,
      "y": 14,
      "z": 4,
      "name": "Rock_Stone_Brick"
    },
    {
      "x": -7,
      "y": 15,
      "z": 4,
      "name": "Rock_Stone_Brick"
    },
    {
      "x": -7,
      "y": 0,
      "z": 5,
      "name": "Rock_Stone_Brick"
    },
    {
      "x": -7,
      "y": 1,
      "z": 5,
      "name": "Rock_Stone_Brick_Mossy"
    },
    {
      "x": -7,
      "y": 2,
      "z": 5,
      "name": "Rock_Stone_Mossy"
    },
    {
      "x": -7,
      "y": 3,
      "z": 5,
      "name": "Rock_Stone_Mossy"
    },
    {
      "x": -7,
      "y": 4,
      "z": 5,
      "name": "Rubble_Stone_Mossy"
    },
    {
      "x": -7,
      "y": 5,
      "z": 5,
      "name": "Rock_Stone_Brick"
    },
    {
      "x": -7,
      "y": 6,
      "z": 5,
      "name": "Rock_Stone_Brick"
    },
    {
      "x": -7,
      "y": 7,
      "z": 5,
      "name": "Rock_Stone_Brick"
    },
    {
      "x": -7,
      "y": 8,
      "z": 5,
      "name": "Rock_Stone_Brick"
    },
    {
      "x": -7,
      "y": 9,
      "z": 5,
      "name": "Rock_Stone_Brick"
    },
    {
      "x": -7,
      "y": 10,
      "z": 5,
      "name": "Rock_Stone_Brick"
    },
    {
      "x": -7,
      "y": 11,
      "z": 5,
      "name": "Rock_Stone_Brick"
    },
    {
      "x": -7,
      "y": 12,
      "z": 5,
      "name": "Rock_Stone_Brick"
    },
    {
      "x": -7,
      "y": 13,
      "z": 5,
      "name": "Rock_Stone_Brick"
    },
    {
      "x": -7,
      "y": 14,
      "z": 5,
      "name": "Rock_Stone_Brick"
    },
    {
      "x": -7,
      "y": 15,
      "z": 5,
      "name": "Rock_Stone_Brick"
    },
    {
      "x": -7,
      "y": 0,
      "z": 6,
      "name": "Rock_Stone_Brick"
    },
    {
      "x": -7,
      "y": 1,
      "z": 6,
      "name": "Rock_Stone_Brick"
    },
    {
      "x": -7,
      "y": 2,
      "z": 6,
      "name": "Rock_Stone_Brick"
    },
    {
      "x": -7,
      "y": 3,
      "z": 6,
      "name": "Rock_Stone_Cobble_Mossy_Half"
    },
    {
      "x": -7,
      "y": 4,
      "z": 6,
      "name": "Rock_Stone_Brick"
    },
    {
      "x": -7,
      "y": 5,
      "z": 6,
      "name": "Rock_Stone_Mossy"
    },
    {
      "x": -7,
      "y": 6,
      "z": 6,
      "name": "Rock_Stone_Brick"
    },
    {
      "x": -7,
      "y": 7,
      "z": 6,
      "name": "Rock_Stone_Brick"
    },
    {
      "x": -7,
      "y": 8,
      "z": 6,
      "name": "Rock_Stone_Brick"
    },
    {
      "x": -7,
      "y": 9,
      "z": 6,
      "name": "Rock_Stone_Brick"
    },
    {
      "x": -7,
      "y": 10,
      "z": 6,
      "name": "Rock_Stone_Brick"
    },
    {
      "x": -7,
      "y": 11,
      "z": 6,
      "name": "Rock_Stone_Brick"
    },
    {
      "x": -7,
      "y": 12,
      "z": 6,
      "name": "Rock_Stone_Brick"
    },
    {
      "x": -7,
      "y": 13,
      "z": 6,
      "name": "Rock_Stone_Brick"
    },
    {
      "x": -7,
      "y": 14,
      "z": 6,
      "name": "Rock_Stone_Brick"
    },
    {
      "x": -7,
      "y": 15,
      "z": 6,
      "name": "Rock_Stone_Brick"
    },
    {
      "x": -7,
      "y": 0,
      "z": 7,
      "name": "Rock_Stone_Brick"
    },
    {
      "x": -7,
      "y": 1,
      "z": 7,
      "name": "Rock_Stone_Brick"
    },
    {
      "x": -7,
      "y": 2,
      "z": 7,
      "name": "Rock_Stone_Brick"
    },
    {
      "x": -7,
      "y": 3,
      "z": 7,
      "name": "Rock_Stone_Mossy"
    },
    {
      "x": -7,
      "y": 4,
      "z": 7,
      "name": "Rock_Stone_Mossy"
    },
    {
      "x": -7,
      "y": 5,
      "z": 7,
      "name": "Rock_Stone_Brick"
    },
    {
      "x": -7,
      "y": 6,
      "z": 7,
      "name": "Rock_Stone_Brick"
    },
    {
      "x": -7,
      "y": 7,
      "z": 7,
      "name": "Rock_Stone_Brick"
    },
    {
      "x": -7,
      "y": 8,
      "z": 7,
      "name": "Rock_Stone_Brick"
    },
    {
      "x": -7,
      "y": 9,
      "z": 7,
      "name": "Rock_Stone_Brick"
    },
    {
      "x": -7,
      "y": 10,
      "z": 7,
      "name": "Rock_Stone_Brick"
    },
    {
      "x": -7,
      "y": 11,
      "z": 7,
      "name": "Rock_Stone_Brick"
    },
    {
      "x": -7,
      "y": 12,
      "z": 7,
      "name": "Rock_Stone_Brick"
    },
    {
      "x": -7,
      "y": 13,
      "z": 7,
      "name": "Rock_Stone_Brick"
    },
    {
      "x": -7,
      "y": 14,
      "z": 7,
      "name": "Rock_Stone_Brick"
    },
    {
      "x": -7,
      "y": 15,
      "z": 7,
      "name": "Rock_Stone_Brick"
    },
    {
      "x": -7,
      "y": 0,
      "z": 8,
      "name": "Rock_Stone_Brick"
    },
    {
      "x": -7,
      "y": 1,
      "z": 8,
      "name": "Rock_Stone_Brick"
    },
    {
      "x": -7,
      "y": 2,
      "z": 8,
      "name": "Rock_Stone_Brick"
    },
    {
      "x": -7,
      "y": 3,
      "z": 8,
      "name": "Rock_Stone_Brick"
    },
    {
      "x": -7,
      "y": 4,
      "z": 8,
      "name": "Rock_Stone_Brick"
    },
    {
      "x": -7,
      "y": 5,
      "z": 8,
      "name": "Rock_Stone_Brick"
    },
    {
      "x": -7,
      "y": 6,
      "z": 8,
      "name": "Rock_Stone_Brick"
    },
    {
      "x": -7,
      "y": 7,
      "z": 8,
      "name": "Rock_Stone_Brick"
    },
    {
      "x": -7,
      "y": 8,
      "z": 8,
      "name": "Rock_Stone_Brick"
    },
    {
      "x": -7,
      "y": 9,
      "z": 8,
      "name": "Rock_Stone_Brick"
    },
    {
      "x": -7,
      "y": 10,
      "z": 8,
      "name": "Rock_Stone_Brick"
    },
    {
      "x": -7,
      "y": 11,
      "z": 8,
      "name": "Rock_Stone_Brick"
    },
    {
      "x": -7,
      "y": 12,
      "z": 8,
      "name": "Rock_Stone_Brick"
    },
    {
      "x": -7,
      "y": 13,
      "z": 8,
      "name": "Rock_Stone_Brick"
    },
    {
      "x": -7,
      "y": 14,
      "z": 8,
      "name": "Rock_Stone_Brick"
    },
    {
      "x": -7,
      "y": 15,
      "z": 8,
      "name": "Rock_Stone_Brick"
    },
    {
      "x": -6,
      "y": 0,
      "z": -7,
      "name": "Rock_Stone_Brick"
    },
    {
      "x": -6,
      "y": 1,
      "z": -7,
      "name": "Rock_Stone_Brick"
    },
    {
      "x": -6,
      "y": 2,
      "z": -7,
      "name": "Rock_Stone_Brick"
    },
    {
      "x": -6,
      "y": 3,
      "z": -7,
      "name": "Rock_Stone_Brick"
    },
    {
      "x": -6,
      "y": 4,
      "z": -7,
      "name": "Rock_Stone_Brick"
    },
    {
      "x": -6,
      "y": 5,
      "z": -7,
      "name": "Rock_Stone_Brick"
    },
    {
      "x": -6,
      "y": 6,
      "z": -7,
      "name": "Rock_Stone_Brick"
    },
    {
      "x": -6,
      "y": 7,
      "z": -7,
      "name": "Rock_Stone_Brick"
    },
    {
      "x": -6,
      "y": 8,
      "z": -7,
      "name": "Rock_Stone_Brick"
    },
    {
      "x": -6,
      "y": 9,
      "z": -7,
      "name": "Rock_Stone_Brick"
    },
    {
      "x": -6,
      "y": 10,
      "z": -7,
      "name": "Rock_Stone_Brick"
    },
    {
      "x": -6,
      "y": 11,
      "z": -7,
      "name": "Rock_Stone_Brick"
    },
    {
      "x": -6,
      "y": 12,
      "z": -7,
      "name": "Rock_Stone_Brick"
    },
    {
      "x": -6,
      "y": 13,
      "z": -7,
      "name": "Rock_Stone_Brick"
    },
    {
      "x": -6,
      "y": 14,
      "z": -7,
      "name": "Rock_Stone_Brick"
    },
    {
      "x": -6,
      "y": 15,
      "z": -7,
      "name": "Rock_Stone_Brick"
    },
    {
      "x": -6,
      "y": 0,
      "z": -6,
      "name": "Rock_Stone_Brick"
    },
    {
      "x": -6,
      "y": 1,
      "z": -6,
      "name": "Rock_Stone_Brick"
    },
    {
      "x": -6,
      "y": 2,
      "z": -6,
      "name": "Rock_Stone_Brick"
    },
    {
      "x": -6,
      "y": 3,
      "z": -6,
      "name": "Rock_Stone_Brick"
    },
    {
      "x": -6,
      "y": 4,
      "z": -6,
      "name": "Rock_Stone_Brick"
    },
    {
      "x": -6,
      "y": 5,
      "z": -6,
      "name": "Rock_Stone_Brick"
    },
    {
      "x": -6,
      "y": 6,
      "z": -6,
      "name": "Rock_Stone_Brick"
    },
    {
      "x": -6,
      "y": 7,
      "z": -6,
      "name": "Rock_Stone_Brick"
    },
    {
      "x": -6,
      "y": 8,
      "z": -6,
      "name": "Rock_Stone_Brick"
    },
    {
      "x": -6,
      "y": 9,
      "z": -6,
      "name": "Rock_Stone_Brick"
    },
    {
      "x": -6,
      "y": 10,
      "z": -6,
      "name": "Rock_Stone_Brick"
    },
    {
      "x": -6,
      "y": 11,
      "z": -6,
      "name": "Rock_Stone_Brick"
    },
    {
      "x": -6,
      "y": 12,
      "z": -6,
      "name": "Rock_Stone_Brick"
    },
    {
      "x": -6,
      "y": 13,
      "z": -6,
      "name": "Rock_Stone_Brick"
    },
    {
      "x": -6,
      "y": 14,
      "z": -6,
      "name": "Rock_Stone_Brick"
    },
    {
      "x": -6,
      "y": 15,
      "z": -6,
      "name": "Rock_Stone_Brick"
    },
    {
      "x": -6,
      "y": 0,
      "z": -5,
      "name": "Rock_Stone_Brick"
    },
    {
      "x": -6,
      "y": 1,
      "z": -5,
      "name": "Rock_Stone_Brick"
    },
    {
      "x": -6,
      "y": 2,
      "z": -5,
      "name": "Rock_Stone_Brick"
    },
    {
      "x": -6,
      "y": 3,
      "z": -5,
      "name": "Rock_Stone_Brick"
    },
    {
      "x": -6,
      "y": 4,
      "z": -5,
      "name": "Rock_Stone_Brick"
    },
    {
      "x": -6,
      "y": 5,
      "z": -5,
      "name": "Rock_Stone_Brick"
    },
    {
      "x": -6,
      "y": 6,
      "z": -5,
      "name": "Rock_Stone_Brick"
    },
    {
      "x": -6,
      "y": 7,
      "z": -5,
      "name": "Rock_Stone_Brick"
    },
    {
      "x": -6,
      "y": 8,
      "z": -5,
      "name": "Rock_Stone_Brick"
    },
    {
      "x": -6,
      "y": 9,
      "z": -5,
      "name": "Rock_Stone_Brick"
    },
    {
      "x": -6,
      "y": 10,
      "z": -5,
      "name": "Rock_Stone_Brick"
    },
    {
      "x": -6,
      "y": 11,
      "z": -5,
      "name": "Rock_Stone_Brick"
    },
    {
      "x": -6,
      "y": 12,
      "z": -5,
      "name": "Rock_Stone_Brick"
    },
    {
      "x": -6,
      "y": 13,
      "z": -5,
      "name": "Rock_Stone_Brick"
    },
    {
      "x": -6,
      "y": 14,
      "z": -5,
      "name": "Rock_Stone_Brick"
    },
    {
      "x": -6,
      "y": 15,
      "z": -5,
      "name": "Rock_Stone_Brick"
    },
    {
      "x": -6,
      "y": 0,
      "z": -4,
      "name": "Rock_Stone_Brick"
    },
    {
      "x": -6,
      "y": 1,
      "z": -4,
      "name": "Rock_Stone_Brick"
    },
    {
      "x": -6,
      "y": 2,
      "z": -4,
      "name": "Rock_Stone_Brick"
    },
    {
      "x": -6,
      "y": 3,
      "z": -4,
      "name": "Rock_Stone_Brick"
    },
    {
      "x": -6,
      "y": 4,
      "z": -4,
      "name": "Rock_Stone_Brick_Stairs",
      "rotation": 1
    },
    {
      "x": -6,
      "y": 5,
      "z": -4,
      "name": "Rock_Stone_Brick"
    },
    {
      "x": -6,
      "y": 6,
      "z": -4,
      "name": "Rock_Stone_Brick"
    },
    {
      "x": -6,
      "y": 7,
      "z": -4,
      "name": "Rock_Stone_Brick"
    },
    {
      "x": -6,
      "y": 8,
      "z": -4,
      "name": "Rock_Stone_Brick"
    },
    {
      "x": -6,
      "y": 9,
      "z": -4,
      "name": "Rock_Stone_Brick"
    },
    {
      "x": -6,
      "y": 10,
      "z": -4,
      "name": "Rock_Stone_Brick"
    },
    {
      "x": -6,
      "y": 11,
      "z": -4,
      "name": "Rock_Stone_Brick"
    },
    {
      "x": -6,
      "y": 12,
      "z": -4,
      "name": "Rock_Stone_Brick"
    },
    {
      "x": -6,
      "y": 13,
      "z": -4,
      "name": "Rock_Stone_Brick"
    },
    {
      "x": -6,
      "y": 14,
      "z": -4,
      "name": "Rock_Stone_Brick"
    },
    {
      "x": -6,
      "y": 15,
      "z": -4,
      "name": "Rock_Stone_Brick"
    },
    {
      "x": -6,
      "y": 0,
      "z": -3,
      "name": "Rock_Stone_Brick"
    },
    {
      "x": -6,
      "y": 1,
      "z": -3,
      "name": "Rock_Stone_Brick"
    },
    {
      "x": -6,
      "y": 2,
      "z": -3,
      "name": "Rock_Stone_Brick"
    },
    {
      "x": -6,
      "y": 3,
      "z": -3,
      "name": "Rock_Stone_Brick"
    },
    {
      "x": -6,
      "y": 4,
      "z": -3,
      "name": "Rock_Stone_Brick"
    },
    {
      "x": -6,
      "y": 5,
      "z": -3,
      "name": "Rock_Stone_Brick"
    },
    {
      "x": -6,
      "y": 6,
      "z": -3,
      "name": "Rock_Stone_Brick"
    },
    {
      "x": -6,
      "y": 7,
      "z": -3,
      "name": "Rock_Stone_Brick"
    },
    {
      "x": -6,
      "y": 8,
      "z": -3,
      "name": "Rock_Stone_Brick"
    },
    {
      "x": -6,
      "y": 9,
      "z": -3,
      "name": "Rock_Stone_Brick"
    },
    {
      "x": -6,
      "y": 10,
      "z": -3,
      "name": "Rock_Stone_Brick"
    },
    {
      "x": -6,
      "y": 11,
      "z": -3,
      "name": "Rock_Stone_Brick"
    },
    {
      "x": -6,
      "y": 12,
      "z": -3,
      "name": "Rock_Stone_Brick"
    },
    {
      "x": -6,
      "y": 13,
      "z": -3,
      "name": "Rock_Stone_Brick"
    },
    {
      "x": -6,
      "y": 14,
      "z": -3,
      "name": "Rock_Stone_Brick"
    },
    {
      "x": -6,
      "y": 15,
      "z": -3,
      "name": "Rock_Stone_Brick"
    },
    {
      "x": -6,
      "y": 0,
      "z": -2,
      "name": "Rock_Stone_Brick"
    },
    {
      "x": -6,
      "y": 1,
      "z": -2,
      "name": "Rock_Stone_Brick"
    },
    {
      "x": -6,
      "y": 2,
      "z": -2,
      "name": "Rock_Stone_Brick"
    },
    {
      "x": -6,
      "y": 3,
      "z": -2,
      "name": "Rock_Stone_Brick"
    },
    {
      "x": -6,
      "y": 4,
      "z": -2,
      "name": "Rock_Stone_Brick"
    },
    {
      "x": -6,
      "y": 5,
      "z": -2,
      "name": "Rock_Stone_Brick"
    },
    {
      "x": -6,
      "y": 6,
      "z": -2,
      "name": "Rock_Stone_Brick"
    },
    {
      "x": -6,
      "y": 7,
      "z": -2,
      "name": "Rock_Stone_Brick_Stairs",
      "rotation": 11
    },
    {
      "x": -6,
      "y": 8,
      "z": -2,
      "name": "Rock_Stone_Brick"
    },
    {
      "x": -6,
      "y": 9,
      "z": -2,
      "name": "Rock_Stone_Brick"
    },
    {
      "x": -6,
      "y": 10,
      "z": -2,
      "name": "Rock_Stone_Brick"
    },
    {
      "x": -6,
      "y": 11,
      "z": -2,
      "name": "Rock_Stone_Brick"
    },
    {
      "x": -6,
      "y": 12,
      "z": -2,
      "name": "Rock_Stone_Brick"
    },
    {
      "x": -6,
      "y": 13,
      "z": -2,
      "name": "Rock_Stone_Brick"
    },
    {
      "x": -6,
      "y": 14,
      "z": -2,
      "name": "Rock_Stone_Brick"
    },
    {
      "x": -6,
      "y": 15,
      "z": -2,
      "name": "Rock_Stone_Brick"
    },
    {
      "x": -6,
      "y": 0,
      "z": -1,
      "name": "Rock_Stone_Brick"
    },
    {
      "x": -6,
      "y": 1,
      "z": -1,
      "name": "Rock_Stone_Brick"
    },
    {
      "x": -6,
      "y": 2,
      "z": -1,
      "name": "Rock_Stone_Brick"
    },
    {
      "x": -6,
      "y": 3,
      "z": -1,
      "name": "Rock_Stone_Brick"
    },
    {
      "x": -6,
      "y": 4,
      "z": -1,
      "name": "Rock_Stone_Brick"
    },
    {
      "x": -6,
      "y": 5,
      "z": -1,
      "name": "Rock_Stone_Brick"
    },
    {
      "x": -6,
      "y": 6,
      "z": -1,
      "name": "Rock_Stone_Brick"
    },
    {
      "x": -6,
      "y": 7,
      "z": -1,
      "name": "Rock_Stone_Brick"
    },
    {
      "x": -6,
      "y": 8,
      "z": -1,
      "name": "Rock_Stone_Brick"
    },
    {
      "x": -6,
      "y": 9,
      "z": -1,
      "name": "Rock_Stone_Brick"
    },
    {
      "x": -6,
      "y": 10,
      "z": -1,
      "name": "Rock_Stone_Brick"
    },
    {
      "x": -6,
      "y": 11,
      "z": -1,
      "name": "Rock_Stone_Brick"
    },
    {
      "x": -6,
      "y": 12,
      "z": -1,
      "name": "Rock_Stone_Brick"
    },
    {
      "x": -6,
      "y": 13,
      "z": -1,
      "name": "Rock_Stone_Brick"
    },
    {
      "x": -6,
      "y": 14,
      "z": -1,
      "name": "Rock_Stone_Brick"
    },
    {
      "x": -6,
      "y": 15,
      "z": -1,
      "name": "Rock_Stone_Brick"
    },
    {
      "x": -6,
      "y": 0,
      "z": 0,
      "name": "Rock_Stone_Brick"
    },
    {
      "x": -6,
      "y": 1,
      "z": 0,
      "name": "Rock_Stone_Brick"
    },
    {
      "x": -6,
      "y": 2,
      "z": 0,
      "name": "Rock_Stone_Mossy"
    },
    {
      "x": -6,
      "y": 3,
      "z": 0,
      "name": "Rock_Stone_Mossy"
    },
    {
      "x": -6,
      "y": 4,
      "z": 0,
      "name": "Rubble_Stone_Mossy"
    },
    {
      "x": -6,
      "y": 5,
      "z": 0,
      "name": "Rock_Stone_Mossy"
    },
    {
      "x": -6,
      "y": 6,
      "z": 0,
      "name": "Humans_Ruins_Torch_Echo",
      "rotation": 2
    },
    {
      "x": -6,
      "y": 7,
      "z": 0,
      "name": "Rock_Stone_Brick"
    },
    {
      "x": -6,
      "y": 8,
      "z": 0,
      "name": "Rock_Stone_Brick"
    },
    {
      "x": -6,
      "y": 9,
      "z": 0,
      "name": "Rock_Stone_Brick"
    },
    {
      "x": -6,
      "y": 10,
      "z": 0,
      "name": "Rock_Stone_Brick"
    },
    {
      "x": -6,
      "y": 11,
      "z": 0,
      "name": "Rock_Stone_Brick"
    },
    {
      "x": -6,
      "y": 12,
      "z": 0,
      "name": "Rock_Stone_Brick"
    },
    {
      "x": -6,
      "y": 13,
      "z": 0,
      "name": "Rock_Stone_Brick"
    },
    {
      "x": -6,
      "y": 14,
      "z": 0,
      "name": "Rock_Stone_Brick"
    },
    {
      "x": -6,
      "y": 15,
      "z": 0,
      "name": "Rock_Stone_Brick"
    },
    {
      "x": -6,
      "y": 0,
      "z": 1,
      "name": "Rock_Stone_Brick"
    },
    {
      "x": -6,
      "y": 1,
      "z": 1,
      "name": "Rock_Stone_Brick_Mossy"
    },
    {
      "x": -6,
      "y": 2,
      "z": 1,
      "name": "Rock_Stone_Mossy"
    },
    {
      "x": -6,
      "y": 3,
      "z": 1,
      "name": "Rubble_Stone_Mossy"
    },
    {
      "x": -6,
      "y": 4,
      "z": 1,
      "name": "Rock_Stone_Brick"
    },
    {
      "x": -6,
      "y": 5,
      "z": 1,
      "name": "Rock_Stone_Brick"
    },
    {
      "x": -6,
      "y": 6,
      "z": 1,
      "name": "Humans_Ruins_Torch_Echo",
      "rotation": 2
    },
    {
      "x": -6,
      "y": 7,
      "z": 1,
      "name": "Rock_Stone_Brick"
    },
    {
      "x": -6,
      "y": 8,
      "z": 1,
      "name": "Rock_Stone_Brick"
    },
    {
      "x": -6,
      "y": 9,
      "z": 1,
      "name": "Rock_Stone_Brick"
    },
    {
      "x": -6,
      "y": 10,
      "z": 1,
      "name": "Rock_Stone_Brick"
    },
    {
      "x": -6,
      "y": 11,
      "z": 1,
      "name": "Rock_Stone_Brick"
    },
    {
      "x": -6,
      "y": 12,
      "z": 1,
      "name": "Rock_Stone_Brick"
    },
    {
      "x": -6,
      "y": 13,
      "z": 1,
      "name": "Rock_Stone_Brick"
    },
    {
      "x": -6,
      "y": 14,
      "z": 1,
      "name": "Rock_Stone_Brick"
    },
    {
      "x": -6,
      "y": 15,
      "z": 1,
      "name": "Rock_Stone_Brick"
    },
    {
      "x": -6,
      "y": 0,
      "z": 2,
      "name": "Rock_Stone_Brick"
    },
    {
      "x": -6,
      "y": 1,
      "z": 2,
      "name": "Rock_Stone_Mossy"
    },
    {
      "x": -6,
      "y": 2,
      "z": 2,
      "name": "Rock_Stone_Mossy"
    },
    {
      "x": -6,
      "y": 3,
      "z": 2,
      "name": "Rock_Stone_Brick"
    },
    {
      "x": -6,
      "y": 4,
      "z": 2,
      "name": "Rock_Stone_Mossy"
    },
    {
      "x": -6,
      "y": 5,
      "z": 2,
      "name": "*Rock_Stone_Brick_Half_State_Definitions_Block",
      "rotation": 5
    },
    {
      "x": -6,
      "y": 6,
      "z": 2,
      "name": "Rock_Stone_Brick"
    },
    {
      "x": -6,
      "y": 7,
      "z": 2,
      "name": "Rock_Stone_Brick"
    },
    {
      "x": -6,
      "y": 8,
      "z": 2,
      "name": "Rock_Stone_Brick"
    },
    {
      "x": -6,
      "y": 9,
      "z": 2,
      "name": "Rock_Stone_Brick"
    },
    {
      "x": -6,
      "y": 10,
      "z": 2,
      "name": "Rock_Stone_Brick"
    },
    {
      "x": -6,
      "y": 11,
      "z": 2,
      "name": "Rock_Stone_Brick"
    },
    {
      "x": -6,
      "y": 12,
      "z": 2,
      "name": "Rock_Stone_Brick"
    },
    {
      "x": -6,
      "y": 13,
      "z": 2,
      "name": "Rock_Stone_Brick"
    },
    {
      "x": -6,
      "y": 14,
      "z": 2,
      "name": "Rock_Stone_Brick"
    },
    {
      "x": -6,
      "y": 15,
      "z": 2,
      "name": "Rock_Stone_Brick"
    },
    {
      "x": -6,
      "y": 0,
      "z": 3,
      "name": "Rock_Stone_Brick"
    },
    {
      "x": -6,
      "y": 1,
      "z": 3,
      "name": "Rock_Stone_Brick"
    },
    {
      "x": -6,
      "y": 2,
      "z": 3,
      "name": "Rock_Stone_Brick_Stairs"
    },
    {
      "x": -6,
      "y": 3,
      "z": 3,
      "name": "Rock_Stone_Brick_Half",
      "rotation": 4
    },
    {
      "x": -6,
      "y": 4,
      "z": 3,
      "name": "Rock_Stone_Brick_Half",
      "rotation": 4
    },
    {
      "x": -6,
      "y": 5,
      "z": 3,
      "name": "Rock_Stone_Brick_Stairs",
      "rotation": 11
    },
    {
      "x": -6,
      "y": 6,
      "z": 3,
      "name": "Rock_Stone_Brick"
    },
    {
      "x": -6,
      "y": 7,
      "z": 3,
      "name": "Rock_Stone_Brick"
    },
    {
      "x": -6,
      "y": 8,
      "z": 3,
      "name": "Rock_Stone_Brick"
    },
    {
      "x": -6,
      "y": 9,
      "z": 3,
      "name": "Rock_Stone_Brick"
    },
    {
      "x": -6,
      "y": 10,
      "z": 3,
      "name": "Rock_Stone_Brick"
    },
    {
      "x": -6,
      "y": 11,
      "z": 3,
      "name": "Rock_Stone_Brick"
    },
    {
      "x": -6,
      "y": 12,
      "z": 3,
      "name": "Rock_Stone_Brick"
    },
    {
      "x": -6,
      "y": 13,
      "z": 3,
      "name": "Rock_Stone_Brick"
    },
    {
      "x": -6,
      "y": 14,
      "z": 3,
      "name": "Rock_Stone_Brick"
    },
    {
      "x": -6,
      "y": 15,
      "z": 3,
      "name": "Rock_Stone_Brick"
    },
    {
      "x": -6,
      "y": 0,
      "z": 4,
      "name": "Rock_Stone_Brick"
    },
    {
      "x": -6,
      "y": 1,
      "z": 4,
      "name": "Rock_Stone_Brick_Half"
    },
    {
      "x": -6,
      "y": 3,
      "z": 4,
      "name": "Rock_Stone_Brick"
    },
    {
      "x": -6,
      "y": 4,
      "z": 4,
      "name": "Rock_Stone_Mossy"
    },
    {
      "x": -6,
      "y": 5,
      "z": 4,
      "name": "Rock_Stone_Brick"
    },
    {
      "x": -6,
      "y": 6,
      "z": 4,
      "name": "Rock_Stone_Brick"
    },
    {
      "x": -6,
      "y": 7,
      "z": 4,
      "name": "Rock_Stone_Brick"
    },
    {
      "x": -6,
      "y": 8,
      "z": 4,
      "name": "Rock_Stone_Brick"
    },
    {
      "x": -6,
      "y": 9,
      "z": 4,
      "name": "Rock_Stone_Brick"
    },
    {
      "x": -6,
      "y": 10,
      "z": 4,
      "name": "Rock_Stone_Brick"
    },
    {
      "x": -6,
      "y": 11,
      "z": 4,
      "name": "Rock_Stone_Brick"
    },
    {
      "x": -6,
      "y": 12,
      "z": 4,
      "name": "Rock_Stone_Brick"
    },
    {
      "x": -6,
      "y": 13,
      "z": 4,
      "name": "Rock_Stone_Brick"
    },
    {
      "x": -6,
      "y": 14,
      "z": 4,
      "name": "Rock_Stone_Brick"
    },
    {
      "x": -6,
      "y": 15,
      "z": 4,
      "name": "Rock_Stone_Brick"
    },
    {
      "x": -6,
      "y": 0,
      "z": 5,
      "name": "Rock_Stone_Brick"
    },
    {
      "x": -6,
      "y": 1,
      "z": 5,
      "name": "Rock_Stone_Brick"
    },
    {
      "x": -6,
      "y": 2,
      "z": 5,
      "name": "Rock_Stone_Cobble_Mossy"
    },
    {
      "x": -6,
      "y": 3,
      "z": 5,
      "name": "Rock_Stone_Brick_Stairs",
      "rotation": 1
    },
    {
      "x": -6,
      "y": 4,
      "z": 5,
      "name": "Rock_Stone_Mossy"
    },
    {
      "x": -6,
      "y": 5,
      "z": 5,
      "name": "Rock_Stone_Mossy"
    },
    {
      "x": -6,
      "y": 6,
      "z": 5,
      "name": "Rock_Stone_Brick_Stairs",
      "rotation": 1
    },
    {
      "x": -6,
      "y": 7,
      "z": 5,
      "name": "Rock_Stone_Brick"
    },
    {
      "x": -6,
      "y": 8,
      "z": 5,
      "name": "Rock_Stone_Brick"
    },
    {
      "x": -6,
      "y": 9,
      "z": 5,
      "name": "Rock_Stone_Brick"
    },
    {
      "x": -6,
      "y": 10,
      "z": 5,
      "name": "Rock_Stone_Brick"
    },
    {
      "x": -6,
      "y": 11,
      "z": 5,
      "name": "Rock_Stone_Brick"
    },
    {
      "x": -6,
      "y": 12,
      "z": 5,
      "name": "Rock_Stone_Brick"
    },
    {
      "x": -6,
      "y": 13,
      "z": 5,
      "name": "Rock_Stone_Brick"
    },
    {
      "x": -6,
      "y": 14,
      "z": 5,
      "name": "Rock_Stone_Brick"
    },
    {
      "x": -6,
      "y": 15,
      "z": 5,
      "name": "Rock_Stone_Brick"
    },
    {
      "x": -6,
      "y": 0,
      "z": 6,
      "name": "Rock_Stone_Brick"
    },
    {
      "x": -6,
      "y": 1,
      "z": 6,
      "name": "Rock_Stone_Cobble_Mossy"
    },
    {
      "x": -6,
      "y": 2,
      "z": 6,
      "name": "Rock_Stone_Brick"
    },
    {
      "x": -6,
      "y": 3,
      "z": 6,
      "name": "Rock_Stone_Brick"
    },
    {
      "x": -6,
      "y": 4,
      "z": 6,
      "name": "Rock_Stone_Mossy"
    },
    {
      "x": -6,
      "y": 5,
      "z": 6,
      "name": "Rock_Stone_Mossy"
    },
    {
      "x": -6,
      "y": 6,
      "z": 6,
      "name": "Rock_Stone_Brick"
    },
    {
      "x": -6,
      "y": 7,
      "z": 6,
      "name": "Rock_Stone_Brick"
    },
    {
      "x": -6,
      "y": 8,
      "z": 6,
      "name": "Rock_Stone_Brick"
    },
    {
      "x": -6,
      "y": 9,
      "z": 6,
      "name": "Rock_Stone_Brick"
    },
    {
      "x": -6,
      "y": 10,
      "z": 6,
      "name": "Rock_Stone_Brick"
    },
    {
      "x": -6,
      "y": 11,
      "z": 6,
      "name": "Rock_Stone_Brick"
    },
    {
      "x": -6,
      "y": 12,
      "z": 6,
      "name": "Rock_Stone_Brick"
    },
    {
      "x": -6,
      "y": 13,
      "z": 6,
      "name": "Rock_Stone_Brick"
    },
    {
      "x": -6,
      "y": 14,
      "z": 6,
      "name": "Rock_Stone_Brick"
    },
    {
      "x": -6,
      "y": 15,
      "z": 6,
      "name": "Rock_Stone_Brick"
    },
    {
      "x": -6,
      "y": 0,
      "z": 7,
      "name": "Rock_Stone_Brick"
    },
    {
      "x": -6,
      "y": 1,
      "z": 7,
      "name": "Rock_Stone_Brick"
    },
    {
      "x": -6,
      "y": 2,
      "z": 7,
      "name": "Rock_Stone_Brick"
    },
    {
      "x": -6,
      "y": 3,
      "z": 7,
      "name": "Rock_Stone_Brick"
    },
    {
      "x": -6,
      "y": 4,
      "z": 7,
      "name": "Rock_Stone_Brick"
    },
    {
      "x": -6,
      "y": 5,
      "z": 7,
      "name": "Rock_Stone_Brick"
    },
    {
      "x": -6,
      "y": 6,
      "z": 7,
      "name": "Rock_Stone_Brick"
    },
    {
      "x": -6,
      "y": 7,
      "z": 7,
      "name": "Rock_Stone_Brick"
    },
    {
      "x": -6,
      "y": 8,
      "z": 7,
      "name": "Rock_Stone_Brick"
    },
    {
      "x": -6,
      "y": 9,
      "z": 7,
      "name": "Rock_Stone_Brick"
    },
    {
      "x": -6,
      "y": 10,
      "z": 7,
      "name": "Rock_Stone_Brick"
    },
    {
      "x": -6,
      "y": 11,
      "z": 7,
      "name": "Rock_Stone_Brick"
    },
    {
      "x": -6,
      "y": 12,
      "z": 7,
      "name": "Rock_Stone_Brick"
    },
    {
      "x": -6,
      "y": 13,
      "z": 7,
      "name": "Rock_Stone_Brick"
    },
    {
      "x": -6,
      "y": 14,
      "z": 7,
      "name": "Rock_Stone_Brick"
    },
    {
      "x": -6,
      "y": 15,
      "z": 7,
      "name": "Rock_Stone_Brick"
    },
    {
      "x": -6,
      "y": 0,
      "z": 8,
      "name": "Rock_Stone_Brick"
    },
    {
      "x": -6,
      "y": 1,
      "z": 8,
      "name": "Rock_Stone_Brick"
    },
    {
      "x": -6,
      "y": 2,
      "z": 8,
      "name": "Rock_Stone_Brick"
    },
    {
      "x": -6,
      "y": 3,
      "z": 8,
      "name": "Rock_Stone_Brick"
    },
    {
      "x": -6,
      "y": 4,
      "z": 8,
      "name": "Rock_Stone_Brick"
    },
    {
      "x": -6,
      "y": 5,
      "z": 8,
      "name": "Rock_Stone_Brick"
    },
    {
      "x": -6,
      "y": 6,
      "z": 8,
      "name": "Rock_Stone_Brick"
    },
    {
      "x": -6,
      "y": 7,
      "z": 8,
      "name": "Rock_Stone_Brick"
    },
    {
      "x": -6,
      "y": 8,
      "z": 8,
      "name": "Rock_Stone_Brick"
    },
    {
      "x": -6,
      "y": 9,
      "z": 8,
      "name": "Rock_Stone_Brick"
    },
    {
      "x": -6,
      "y": 10,
      "z": 8,
      "name": "Rock_Stone_Brick"
    },
    {
      "x": -6,
      "y": 11,
      "z": 8,
      "name": "Rock_Stone_Brick"
    },
    {
      "x": -6,
      "y": 12,
      "z": 8,
      "name": "Rock_Stone_Brick"
    },
    {
      "x": -6,
      "y": 13,
      "z": 8,
      "name": "Rock_Stone_Brick"
    },
    {
      "x": -6,
      "y": 14,
      "z": 8,
      "name": "Rock_Stone_Brick"
    },
    {
      "x": -6,
      "y": 15,
      "z": 8,
      "name": "Rock_Stone_Brick"
    },
    {
      "x": -5,
      "y": 0,
      "z": -7,
      "name": "Rock_Stone_Brick"
    },
    {
      "x": -5,
      "y": 1,
      "z": -7,
      "name": "Rock_Stone_Brick"
    },
    {
      "x": -5,
      "y": 2,
      "z": -7,
      "name": "Rock_Stone_Brick"
    },
    {
      "x": -5,
      "y": 3,
      "z": -7,
      "name": "Rock_Stone_Brick_Beam"
    },
    {
      "x": -5,
      "y": 4,
      "z": -7,
      "name": "Rock_Stone_Brick_Beam"
    },
    {
      "x": -5,
      "y": 5,
      "z": -7,
      "name": "*Rock_Stone_Brick_Half_State_Definitions_Block"
    },
    {
      "x": -5,
      "y": 6,
      "z": -7,
      "name": "Rock_Stone_Brick_Beam"
    },
    {
      "x": -5,
      "y": 7,
      "z": -7,
      "name": "Rock_Stone_Brick_Beam"
    },
    {
      "x": -5,
      "y": 8,
      "z": -7,
      "name": "Rock_Stone_Brick"
    },
    {
      "x": -5,
      "y": 9,
      "z": -7,
      "name": "Humans_Ruins_Torch_Echo",
      "rotation": 1
    },
    {
      "x": -5,
      "y": 10,
      "z": -7,
      "name": "Rock_Stone_Brick"
    },
    {
      "x": -5,
      "y": 11,
      "z": -7,
      "name": "Rock_Stone_Brick_Half",
      "rotation": 5
    },
    {
      "x": -5,
      "y": 12,
      "z": -7,
      "name": "Rock_Stone_Brick_Stairs",
      "rotation": 11
    },
    {
      "x": -5,
      "y": 13,
      "z": -7,
      "name": "Rock_Stone_Brick"
    },
    {
      "x": -5,
      "y": 14,
      "z": -7,
      "name": "Rock_Stone_Brick"
    },
    {
      "x": -5,
      "y": 15,
      "z": -7,
      "name": "Rock_Stone_Brick"
    },
    {
      "x": -5,
      "y": 0,
      "z": -6,
      "name": "Rock_Stone_Brick"
    },
    {
      "x": -5,
      "y": 1,
      "z": -6,
      "name": "Rock_Stone_Brick"
    },
    {
      "x": -5,
      "y": 2,
      "z": -6,
      "name": "Rock_Stone_Brick_Stairs"
    },
    {
      "x": -5,
      "y": 5,
      "z": -6,
      "name": "Rock_Stone_Brick_Half",
      "rotation": 4
    },
    {
      "x": -5,
      "y": 8,
      "z": -6,
      "name": "*Rock_Stone_Brick_Stairs_State_Definitions_Inverted_Corner_Right",
      "rotation": 10
    },
    {
      "x": -5,
      "y": 10,
      "z": -6,
      "name": "Rock_Stone_Brick"
    },
    {
      "x": -5,
      "y": 11,
      "z": -6,
      "name": "Rock_Stone_Brick_Half",
      "rotation": 5
    },
    {
      "x": -5,
      "y": 12,
      "z": -6,
      "name": "Rock_Stone_Brick_Stairs",
      "rotation": 11
    },
    {
      "x": -5,
      "y": 13,
      "z": -6,
      "name": "Rock_Stone_Brick"
    },
    {
      "x": -5,
      "y": 14,
      "z": -6,
      "name": "Rock_Stone_Brick"
    },
    {
      "x": -5,
      "y": 15,
      "z": -6,
      "name": "Rock_Stone_Brick"
    },
    {
      "x": -5,
      "y": 0,
      "z": -5,
      "name": "Rock_Stone_Brick"
    },
    {
      "x": -5,
      "y": 1,
      "z": -5,
      "name": "Rock_Stone_Brick"
    },
    {
      "x": -5,
      "y": 8,
      "z": -5,
      "name": "Rock_Stone_Brick_Stairs",
      "rotation": 11
    },
    {
      "x": -5,
      "y": 10,
      "z": -5,
      "name": "Rock_Stone_Brick"
    },
    {
      "x": -5,
      "y": 11,
      "z": -5,
      "name": "Rock_Stone_Brick_Half",
      "rotation": 5
    },
    {
      "x": -5,
      "y": 12,
      "z": -5,
      "name": "Rock_Stone_Brick_Stairs",
      "rotation": 11
    },
    {
      "x": -5,
      "y": 13,
      "z": -5,
      "name": "Rock_Stone_Brick"
    },
    {
      "x": -5,
      "y": 14,
      "z": -5,
      "name": "Rock_Stone_Brick"
    },
    {
      "x": -5,
      "y": 15,
      "z": -5,
      "name": "Rock_Stone_Brick"
    },
    {
      "x": -5,
      "y": 0,
      "z": -4,
      "name": "Rock_Stone_Brick"
    },
    {
      "x": -5,
      "y": 1,
      "z": -4,
      "name": "Rock_Stone_Brick"
    },
    {
      "x": -5,
      "y": 8,
      "z": -4,
      "name": "Rock_Stone_Brick_Stairs",
      "rotation": 11
    },
    {
      "x": -5,
      "y": 10,
      "z": -4,
      "name": "Rock_Stone_Brick"
    },
    {
      "x": -5,
      "y": 11,
      "z": -4,
      "name": "Rock_Stone_Brick_Half",
      "rotation": 5
    },
    {
      "x": -5,
      "y": 12,
      "z": -4,
      "name": "Rock_Stone_Brick_Stairs",
      "rotation": 11
    },
    {
      "x": -5,
      "y": 13,
      "z": -4,
      "name": "Rock_Stone_Brick"
    },
    {
      "x": -5,
      "y": 14,
      "z": -4,
      "name": "Rock_Stone_Brick"
    },
    {
      "x": -5,
      "y": 15,
      "z": -4,
      "name": "Rock_Stone_Brick"
    },
    {
      "x": -5,
      "y": 0,
      "z": -3,
      "name": "Rock_Stone_Brick"
    },
    {
      "x": -5,
      "y": 1,
      "z": -3,
      "name": "Rock_Stone_Brick"
    },
    {
      "x": -5,
      "y": 8,
      "z": -3,
      "name": "Rock_Stone_Brick_Stairs",
      "rotation": 11
    },
    {
      "x": -5,
      "y": 10,
      "z": -3,
      "name": "Rock_Stone_Brick"
    },
    {
      "x": -5,
      "y": 11,
      "z": -3,
      "name": "Rock_Stone_Brick_Half",
      "rotation": 5
    },
    {
      "x": -5,
      "y": 12,
      "z": -3,
      "name": "Rock_Stone_Brick_Stairs",
      "rotation": 11
    },
    {
      "x": -5,
      "y": 13,
      "z": -3,
      "name": "Rock_Stone_Brick"
    },
    {
      "x": -5,
      "y": 14,
      "z": -3,
      "name": "Rock_Stone_Brick"
    },
    {
      "x": -5,
      "y": 15,
      "z": -3,
      "name": "Rock_Stone_Brick"
    },
    {
      "x": -5,
      "y": 0,
      "z": -2,
      "name": "Rock_Stone_Brick"
    },
    {
      "x": -5,
      "y": 1,
      "z": -2,
      "name": "Rock_Stone_Brick"
    },
    {
      "x": -5,
      "y": 8,
      "z": -2,
      "name": "Rock_Stone_Brick_Stairs",
      "rotation": 11
    },
    {
      "x": -5,
      "y": 10,
      "z": -2,
      "name": "Rock_Stone_Brick"
    },
    {
      "x": -5,
      "y": 11,
      "z": -2,
      "name": "Rock_Stone_Brick_Half",
      "rotation": 5
    },
    {
      "x": -5,
      "y": 12,
      "z": -2,
      "name": "Rock_Stone_Brick_Stairs",
      "rotation": 11
    },
    {
      "x": -5,
      "y": 13,
      "z": -2,
      "name": "Rock_Stone_Brick"
    },
    {
      "x": -5,
      "y": 14,
      "z": -2,
      "name": "Rock_Stone_Brick"
    },
    {
      "x": -5,
      "y": 15,
      "z": -2,
      "name": "Rock_Stone_Brick"
    },
    {
      "x": -5,
      "y": 0,
      "z": -1,
      "name": "Rock_Stone_Brick"
    },
    {
      "x": -5,
      "y": 1,
      "z": -1,
      "name": "Rock_Stone_Brick"
    },
    {
      "x": -5,
      "y": 2,
      "z": -1,
      "name": "Rock_Stone_Brick_Stairs",
      "rotation": 2
    },
    {
      "x": -5,
      "y": 8,
      "z": -1,
      "name": "Rock_Stone_Brick_Stairs",
      "rotation": 11
    },
    {
      "x": -5,
      "y": 10,
      "z": -1,
      "name": "Rock_Stone_Brick"
    },
    {
      "x": -5,
      "y": 11,
      "z": -1,
      "name": "Rock_Stone_Brick_Half",
      "rotation": 5
    },
    {
      "x": -5,
      "y": 12,
      "z": -1,
      "name": "Rock_Stone_Brick_Stairs",
      "rotation": 11
    },
    {
      "x": -5,
      "y": 13,
      "z": -1,
      "name": "Rock_Stone_Brick"
    },
    {
      "x": -5,
      "y": 14,
      "z": -1,
      "name": "Rock_Stone_Brick"
    },
    {
      "x": -5,
      "y": 15,
      "z": -1,
      "name": "Rock_Stone_Brick"
    },
    {
      "x": -5,
      "y": 0,
      "z": 0,
      "name": "Rock_Stone_Brick"
    },
    {
      "x": -5,
      "y": 1,
      "z": 0,
      "name": "Rock_Stone_Brick"
    },
    {
      "x": -5,
      "y": 2,
      "z": 0,
      "name": "Rock_Stone_Mossy"
    },
    {
      "x": -5,
      "y": 3,
      "z": 0,
      "name": "Rock_Stone_Brick_Half",
      "rotation": 5
    },
    {
      "x": -5,
      "y": 4,
      "z": 0,
      "name": "Rock_Stone_Brick_Half",
      "rotation": 5
    },
    {
      "x": -5,
      "y": 5,
      "z": 0,
      "name": "Rock_Stone_Brick_Stairs",
      "rotation": 11
    },
    {
      "x": -5,
      "y": 6,
      "z": 0,
      "name": "Rock_Stone_Brick_Wall",
      "rotation": 1
    },
    {
      "x": -5,
      "y": 7,
      "z": 0,
      "name": "Rock_Stone_Brick_Beam"
    },
    {
      "x": -5,
      "y": 8,
      "z": 0,
      "name": "Rock_Stone_Brick"
    },
    {
      "x": -5,
      "y": 10,
      "z": 0,
      "name": "Rock_Stone_Brick"
    },
    {
      "x": -5,
      "y": 11,
      "z": 0,
      "name": "Rock_Stone_Brick_Half",
      "rotation": 5
    },
    {
      "x": -5,
      "y": 12,
      "z": 0,
      "name": "Rock_Stone_Brick_Stairs",
      "rotation": 11
    },
    {
      "x": -5,
      "y": 13,
      "z": 0,
      "name": "Rock_Stone_Brick"
    },
    {
      "x": -5,
      "y": 14,
      "z": 0,
      "name": "Rock_Stone_Brick"
    },
    {
      "x": -5,
      "y": 15,
      "z": 0,
      "name": "Rock_Stone_Brick"
    },
    {
      "x": -5,
      "y": 0,
      "z": 1,
      "name": "Rock_Stone_Brick"
    },
    {
      "x": -5,
      "y": 1,
      "z": 1,
      "name": "Rock_Stone_Brick"
    },
    {
      "x": -5,
      "y": 2,
      "z": 1,
      "name": "Rock_Stone_Mossy"
    },
    {
      "x": -5,
      "y": 3,
      "z": 1,
      "name": "Rock_Stone_Brick_Half",
      "rotation": 5
    },
    {
      "x": -5,
      "y": 4,
      "z": 1,
      "name": "Rock_Stone_Brick_Half",
      "rotation": 5
    },
    {
      "x": -5,
      "y": 5,
      "z": 1,
      "name": "Rock_Stone_Brick_Stairs",
      "rotation": 11
    },
    {
      "x": -5,
      "y": 6,
      "z": 1,
      "name": "Rock_Stone_Brick_Wall",
      "rotation": 1
    },
    {
      "x": -5,
      "y": 7,
      "z": 1,
      "name": "Rock_Stone_Brick_Beam"
    },
    {
      "x": -5,
      "y": 8,
      "z": 1,
      "name": "Rock_Stone_Brick"
    },
    {
      "x": -5,
      "y": 10,
      "z": 1,
      "name": "Rock_Stone_Brick"
    },
    {
      "x": -5,
      "y": 11,
      "z": 1,
      "name": "Rock_Stone_Brick_Half",
      "rotation": 5
    },
    {
      "x": -5,
      "y": 12,
      "z": 1,
      "name": "Rock_Stone_Brick_Stairs",
      "rotation": 11
    },
    {
      "x": -5,
      "y": 13,
      "z": 1,
      "name": "Rock_Stone_Brick"
    },
    {
      "x": -5,
      "y": 14,
      "z": 1,
      "name": "Rock_Stone_Brick"
    },
    {
      "x": -5,
      "y": 15,
      "z": 1,
      "name": "Rock_Stone_Brick"
    },
    {
      "x": -5,
      "y": 0,
      "z": 2,
      "name": "Rock_Stone_Brick"
    },
    {
      "x": -5,
      "y": 1,
      "z": 2,
      "name": "Rock_Stone_Mossy"
    },
    {
      "x": -5,
      "y": 2,
      "z": 2,
      "name": "Rock_Stone_Brick_Stairs"
    },
    {
      "x": -5,
      "y": 8,
      "z": 2,
      "name": "Rock_Stone_Brick_Stairs",
      "rotation": 11
    },
    {
      "x": -5,
      "y": 10,
      "z": 2,
      "name": "Rock_Stone_Brick"
    },
    {
      "x": -5,
      "y": 11,
      "z": 2,
      "name": "Rock_Stone_Brick_Half",
      "rotation": 5
    },
    {
      "x": -5,
      "y": 12,
      "z": 2,
      "name": "Rock_Stone_Brick_Stairs",
      "rotation": 11
    },
    {
      "x": -5,
      "y": 13,
      "z": 2,
      "name": "Rock_Stone_Brick"
    },
    {
      "x": -5,
      "y": 14,
      "z": 2,
      "name": "Rock_Stone_Brick"
    },
    {
      "x": -5,
      "y": 15,
      "z": 2,
      "name": "Rock_Stone_Brick"
    },
    {
      "x": -5,
      "y": 0,
      "z": 3,
      "name": "Rock_Stone_Brick"
    },
    {
      "x": -5,
      "y": 1,
      "z": 3,
      "name": "*Rock_Stone_Brick_Half_State_Definitions_Block"
    },
    {
      "x": -5,
      "y": 2,
      "z": 3,
      "name": "Plant_Moss_Block_Yellow",
      "support": 15
    },
    {
      "x": -5,
      "y": 3,
      "z": 3,
      "name": "Plant_Moss_Yellow",
      "support": 15
    },
    {
      "x": -5,
      "y": 8,
      "z": 3,
      "name": "Rock_Stone_Brick_Stairs",
      "rotation": 11
    },
    {
      "x": -5,
      "y": 10,
      "z": 3,
      "name": "Rock_Stone_Brick"
    },
    {
      "x": -5,
      "y": 11,
      "z": 3,
      "name": "Rock_Stone_Brick_Half",
      "rotation": 5
    },
    {
      "x": -5,
      "y": 12,
      "z": 3,
      "name": "Rock_Stone_Brick_Stairs",
      "rotation": 11
    },
    {
      "x": -5,
      "y": 13,
      "z": 3,
      "name": "Rock_Stone_Brick"
    },
    {
      "x": -5,
      "y": 14,
      "z": 3,
      "name": "Rock_Stone_Brick"
    },
    {
      "x": -5,
      "y": 15,
      "z": 3,
      "name": "Rock_Stone_Brick"
    },
    {
      "x": -5,
      "y": 0,
      "z": 4,
      "name": "Rock_Stone_Brick"
    },
    {
      "x": -5,
      "y": 1,
      "z": 4,
      "name": "Rock_Stone_Brick_Half",
      "rotation": 4
    },
    {
      "x": -5,
      "y": 8,
      "z": 4,
      "name": "Rock_Stone_Brick_Stairs",
      "rotation": 11
    },
    {
      "x": -5,
      "y": 10,
      "z": 4,
      "name": "Rock_Stone_Brick"
    },
    {
      "x": -5,
      "y": 11,
      "z": 4,
      "name": "Rock_Stone_Brick_Half",
      "rotation": 5
    },
    {
      "x": -5,
      "y": 12,
      "z": 4,
      "name": "Rock_Stone_Brick_Stairs",
      "rotation": 11
    },
    {
      "x": -5,
      "y": 13,
      "z": 4,
      "name": "Rock_Stone_Brick"
    },
    {
      "x": -5,
      "y": 14,
      "z": 4,
      "name": "Rock_Stone_Brick"
    },
    {
      "x": -5,
      "y": 15,
      "z": 4,
      "name": "Rock_Stone_Brick"
    },
    {
      "x": -5,
      "y": 0,
      "z": 5,
      "name": "Rock_Stone_Brick"
    },
    {
      "x": -5,
      "y": 1,
      "z": 5,
      "name": "Rock_Stone_Mossy"
    },
    {
      "x": -5,
      "y": 8,
      "z": 5,
      "name": "Rock_Stone_Brick_Stairs",
      "rotation": 11
    },
    {
      "x": -5,
      "y": 10,
      "z": 5,
      "name": "Rock_Stone_Brick"
    },
    {
      "x": -5,
      "y": 11,
      "z": 5,
      "name": "Rock_Stone_Brick_Half",
      "rotation": 5
    },
    {
      "x": -5,
      "y": 12,
      "z": 5,
      "name": "Rock_Stone_Brick_Stairs",
      "rotation": 11
    },
    {
      "x": -5,
      "y": 13,
      "z": 5,
      "name": "Rock_Stone_Brick"
    },
    {
      "x": -5,
      "y": 14,
      "z": 5,
      "name": "Rock_Stone_Brick"
    },
    {
      "x": -5,
      "y": 15,
      "z": 5,
      "name": "Rock_Stone_Brick"
    },
    {
      "x": -5,
      "y": 0,
      "z": 6,
      "name": "Rock_Stone_Brick"
    },
    {
      "x": -5,
      "y": 1,
      "z": 6,
      "name": "Rock_Stone_Mossy"
    },
    {
      "x": -5,
      "y": 2,
      "z": 6,
      "name": "Rubble_Stone_Mossy"
    },
    {
      "x": -5,
      "y": 8,
      "z": 6,
      "name": "Rock_Stone_Brick_Stairs",
      "rotation": 11
    },
    {
      "x": -5,
      "y": 10,
      "z": 6,
      "name": "Rock_Stone_Brick"
    },
    {
      "x": -5,
      "y": 11,
      "z": 6,
      "name": "Rock_Stone_Brick_Half",
      "rotation": 5
    },
    {
      "x": -5,
      "y": 12,
      "z": 6,
      "name": "Rock_Stone_Brick_Stairs",
      "rotation": 11
    },
    {
      "x": -5,
      "y": 13,
      "z": 6,
      "name": "Rock_Stone_Brick"
    },
    {
      "x": -5,
      "y": 14,
      "z": 6,
      "name": "Rock_Stone_Brick"
    },
    {
      "x": -5,
      "y": 15,
      "z": 6,
      "name": "Rock_Stone_Brick"
    },
    {
      "x": -5,
      "y": 0,
      "z": 7,
      "name": "Rock_Stone_Brick"
    },
    {
      "x": -5,
      "y": 1,
      "z": 7,
      "name": "Rock_Stone_Brick"
    },
    {
      "x": -5,
      "y": 2,
      "z": 7,
      "name": "Rock_Stone_Brick_Stairs",
      "rotation": 2
    },
    {
      "x": -5,
      "y": 5,
      "z": 7,
      "name": "Rock_Stone_Brick_Half",
      "rotation": 6
    },
    {
      "x": -5,
      "y": 8,
      "z": 7,
      "name": "*Rock_Stone_Brick_Stairs_State_Definitions_Inverted_Corner_Left",
      "rotation": 8
    },
    {
      "x": -5,
      "y": 10,
      "z": 7,
      "name": "Rock_Stone_Brick"
    },
    {
      "x": -5,
      "y": 11,
      "z": 7,
      "name": "Rock_Stone_Brick_Half",
      "rotation": 5
    },
    {
      "x": -5,
      "y": 12,
      "z": 7,
      "name": "Rock_Stone_Brick_Stairs",
      "rotation": 11
    },
    {
      "x": -5,
      "y": 13,
      "z": 7,
      "name": "Rock_Stone_Brick"
    },
    {
      "x": -5,
      "y": 14,
      "z": 7,
      "name": "Rock_Stone_Brick"
    },
    {
      "x": -5,
      "y": 15,
      "z": 7,
      "name": "Rock_Stone_Brick"
    },
    {
      "x": -5,
      "y": 0,
      "z": 8,
      "name": "Rock_Stone_Brick"
    },
    {
      "x": -5,
      "y": 1,
      "z": 8,
      "name": "Rock_Stone_Brick"
    },
    {
      "x": -5,
      "y": 2,
      "z": 8,
      "name": "Rock_Stone_Brick",
      "rotation": 2
    },
    {
      "x": -5,
      "y": 3,
      "z": 8,
      "name": "Rock_Stone_Brick_Beam",
      "rotation": 2
    },
    {
      "x": -5,
      "y": 4,
      "z": 8,
      "name": "Rock_Stone_Brick_Beam",
      "rotation": 2
    },
    {
      "x": -5,
      "y": 5,
      "z": 8,
      "name": "*Rock_Stone_Brick_Half_State_Definitions_Block",
      "rotation": 2
    },
    {
      "x": -5,
      "y": 6,
      "z": 8,
      "name": "Rock_Stone_Brick_Beam",
      "rotation": 2
    },
    {
      "x": -5,
      "y": 7,
      "z": 8,
      "name": "Rock_Stone_Brick_Beam",
      "rotation": 2
    },
    {
      "x": -5,
      "y": 8,
      "z": 8,
      "name": "Rock_Stone_Brick",
      "rotation": 2
    },
    {
      "x": -5,
      "y": 9,
      "z": 8,
      "name": "Humans_Ruins_Torch_Echo"
    },
    {
      "x": -5,
      "y": 10,
      "z": 8,
      "name": "Rock_Stone_Brick"
    },
    {
      "x": -5,
      "y": 11,
      "z": 8,
      "name": "Rock_Stone_Brick_Half",
      "rotation": 5
    },
    {
      "x": -5,
      "y": 12,
      "z": 8,
      "name": "Rock_Stone_Brick_Stairs",
      "rotation": 11
    },
    {
      "x": -5,
      "y": 13,
      "z": 8,
      "name": "Rock_Stone_Brick"
    },
    {
      "x": -5,
      "y": 14,
      "z": 8,
      "name": "Rock_Stone_Brick"
    },
    {
      "x": -5,
      "y": 15,
      "z": 8,
      "name": "Rock_Stone_Brick"
    },
    {
      "x": -4,
      "y": 0,
      "z": -7,
      "name": "Rock_Stone_Brick"
    },
    {
      "x": -4,
      "y": 1,
      "z": -7,
      "name": "Humans_Ruins_Torch_Echo",
      "rotation": 2
    },
    {
      "x": -4,
      "y": 2,
      "z": -7,
      "name": "Rock_Stone_Brick_Stairs",
      "rotation": 1
    },
    {
      "x": -4,
      "y": 5,
      "z": -7,
      "name": "Rock_Stone_Brick_Half",
      "rotation": 5
    },
    {
      "x": -4,
      "y": 8,
      "z": -7,
      "name": "Rock_Stone_Brick_Stairs",
      "rotation": 11
    },
    {
      "x": -4,
      "y": 9,
      "z": -7,
      "name": "Rock_Stone_Brick_Wall",
      "rotation": 1
    },
    {
      "x": -4,
      "y": 10,
      "z": -7,
      "name": "Rock_Stone_Brick_Half"
    },
    {
      "x": -4,
      "y": 13,
      "z": -7,
      "name": "Rock_Stone_Brick_Stairs",
      "rotation": 11
    },
    {
      "x": -4,
      "y": 14,
      "z": -7,
      "name": "Rock_Stone_Brick"
    },
    {
      "x": -4,
      "y": 15,
      "z": -7,
      "name": "Rock_Stone_Brick"
    },
    {
      "x": -4,
      "y": 0,
      "z": -6,
      "name": "Rock_Stone_Brick"
    },
    {
      "x": -4,
      "y": 1,
      "z": -6,
      "name": "Rock_Stone_Brick"
    },
    {
      "x": -4,
      "y": 2,
      "z": -6,
      "name": "*Rock_Stone_Brick_Stairs_State_Definitions_Corner_Left"
    },
    {
      "x": -4,
      "y": 8,
      "z": -6,
      "name": "*Rock_Stone_Brick_Stairs_State_Definitions_Corner_Right",
      "rotation": 10
    },
    {
      "x": -4,
      "y": 9,
      "z": -6,
      "name": "Rock_Stone_Brick_Wall",
      "rotation": 1
    },
    {
      "x": -4,
      "y": 10,
      "z": -6,
      "name": "Rock_Stone_Brick_Half"
    },
    {
      "x": -4,
      "y": 13,
      "z": -6,
      "name": "Rock_Stone_Brick_Stairs",
      "rotation": 11
    },
    {
      "x": -4,
      "y": 14,
      "z": -6,
      "name": "Rock_Stone_Brick"
    },
    {
      "x": -4,
      "y": 15,
      "z": -6,
      "name": "Rock_Stone_Brick"
    },
    {
      "x": -4,
      "y": 0,
      "z": -5,
      "name": "Rock_Stone_Brick"
    },
    {
      "x": -4,
      "y": 1,
      "z": -5,
      "name": "Rock_Stone_Brick"
    },
    {
      "x": -4,
      "y": 8,
      "z": -5,
      "name": "Rock_Stone_Brick_Half",
      "rotation": 8
    },
    {
      "x": -4,
      "y": 9,
      "z": -5,
      "name": "Rock_Stone_Brick_Wall",
      "rotation": 1
    },
    {
      "x": -4,
      "y": 10,
      "z": -5,
      "name": "Rock_Stone_Brick_Half"
    },
    {
      "x": -4,
      "y": 13,
      "z": -5,
      "name": "Rock_Stone_Brick_Stairs",
      "rotation": 11
    },
    {
      "x": -4,
      "y": 14,
      "z": -5,
      "name": "Rock_Stone_Brick"
    },
    {
      "x": -4,
      "y": 15,
      "z": -5,
      "name": "Rock_Stone_Brick"
    },
    {
      "x": -4,
      "y": 0,
      "z": -4,
      "name": "Rock_Stone_Brick"
    },
    {
      "x": -4,
      "y": 1,
      "z": -4,
      "name": "Rock_Stone_Brick"
    },
    {
      "x": -4,
      "y": 8,
      "z": -4,
      "name": "Rock_Stone_Brick_Half",
      "rotation": 8
    },
    {
      "x": -4,
      "y": 9,
      "z": -4,
      "name": "Rock_Stone_Brick_Wall",
      "rotation": 1
    },
    {
      "x": -4,
      "y": 10,
      "z": -4,
      "name": "Rock_Stone_Brick_Half"
    },
    {
      "x": -4,
      "y": 13,
      "z": -4,
      "name": "Rock_Stone_Brick_Stairs",
      "rotation": 11
    },
    {
      "x": -4,
      "y": 14,
      "z": -4,
      "name": "Rock_Stone_Brick"
    },
    {
      "x": -4,
      "y": 15,
      "z": -4,
      "name": "Rock_Stone_Brick"
    },
    {
      "x": -4,
      "y": 0,
      "z": -3,
      "name": "Rock_Stone_Brick"
    },
    {
      "x": -4,
      "y": 1,
      "z": -3,
      "name": "Rock_Stone_Brick"
    },
    {
      "x": -4,
      "y": 8,
      "z": -3,
      "name": "Rock_Stone_Brick_Half",
      "rotation": 8
    },
    {
      "x": -4,
      "y": 9,
      "z": -3,
      "name": "Rock_Stone_Brick_Wall",
      "rotation": 1
    },
    {
      "x": -4,
      "y": 10,
      "z": -3,
      "name": "Rock_Stone_Brick_Half"
    },
    {
      "x": -4,
      "y": 13,
      "z": -3,
      "name": "Rock_Stone_Brick_Stairs",
      "rotation": 11
    },
    {
      "x": -4,
      "y": 14,
      "z": -3,
      "name": "Rock_Stone_Brick"
    },
    {
      "x": -4,
      "y": 15,
      "z": -3,
      "name": "Rock_Stone_Brick"
    },
    {
      "x": -4,
      "y": 0,
      "z": -2,
      "name": "Rock_Stone_Brick"
    },
    {
      "x": -4,
      "y": 1,
      "z": -2,
      "name": "Rock_Stone_Brick"
    },
    {
      "x": -4,
      "y": 8,
      "z": -2,
      "name": "Rock_Stone_Brick_Half",
      "rotation": 8
    },
    {
      "x": -4,
      "y": 9,
      "z": -2,
      "name": "Rock_Stone_Brick_Wall",
      "rotation": 1
    },
    {
      "x": -4,
      "y": 10,
      "z": -2,
      "name": "Rock_Stone_Brick_Half"
    },
    {
      "x": -4,
      "y": 13,
      "z": -2,
      "name": "Rock_Stone_Brick_Stairs",
      "rotation": 11
    },
    {
      "x": -4,
      "y": 14,
      "z": -2,
      "name": "Rock_Stone_Brick"
    },
    {
      "x": -4,
      "y": 15,
      "z": -2,
      "name": "Rock_Stone_Brick"
    },
    {
      "x": -4,
      "y": 0,
      "z": -1,
      "name": "Rock_Stone_Brick"
    },
    {
      "x": -4,
      "y": 1,
      "z": -1,
      "name": "Rock_Stone_Brick"
    },
    {
      "x": -4,
      "y": 2,
      "z": -1,
      "name": "*Rock_Stone_Brick_Stairs_State_Definitions_Corner_Right",
      "rotation": 2
    },
    {
      "x": -4,
      "y": 8,
      "z": -1,
      "name": "Rock_Stone_Brick_Half",
      "rotation": 8
    },
    {
      "x": -4,
      "y": 9,
      "z": -1,
      "name": "Rock_Stone_Brick_Wall",
      "rotation": 1
    },
    {
      "x": -4,
      "y": 10,
      "z": -1,
      "name": "Rock_Stone_Brick_Half"
    },
    {
      "x": -4,
      "y": 13,
      "z": -1,
      "name": "Rock_Stone_Brick_Stairs",
      "rotation": 11
    },
    {
      "x": -4,
      "y": 14,
      "z": -1,
      "name": "Rock_Stone_Brick"
    },
    {
      "x": -4,
      "y": 15,
      "z": -1,
      "name": "Rock_Stone_Brick"
    },
    {
      "x": -4,
      "y": 0,
      "z": 0,
      "name": "Rock_Stone_Brick"
    },
    {
      "x": -4,
      "y": 1,
      "z": 0,
      "name": "Humans_Ruins_Torch_Echo",
      "rotation": 1
    },
    {
      "x": -4,
      "y": 2,
      "z": 0,
      "name": "Rock_Stone_Brick_Stairs",
      "rotation": 1
    },
    {
      "x": -4,
      "y": 8,
      "z": 0,
      "name": "Rock_Stone_Brick_Half",
      "rotation": 8
    },
    {
      "x": -4,
      "y": 9,
      "z": 0,
      "name": "Rock_Stone_Brick_Wall",
      "rotation": 1
    },
    {
      "x": -4,
      "y": 10,
      "z": 0,
      "name": "Rock_Stone_Brick_Half"
    },
    {
      "x": -4,
      "y": 13,
      "z": 0,
      "name": "Rock_Stone_Brick_Stairs",
      "rotation": 11
    },
    {
      "x": -4,
      "y": 14,
      "z": 0,
      "name": "Rock_Stone_Brick"
    },
    {
      "x": -4,
      "y": 15,
      "z": 0,
      "name": "Rock_Stone_Brick"
    },
    {
      "x": -4,
      "y": 0,
      "z": 1,
      "name": "Rock_Stone_Brick"
    },
    {
      "x": -4,
      "y": 1,
      "z": 1,
      "name": "Humans_Ruins_Torch_Echo",
      "rotation": 1
    },
    {
      "x": -4,
      "y": 2,
      "z": 1,
      "name": "Rock_Stone_Brick_Stairs",
      "rotation": 1
    },
    {
      "x": -4,
      "y": 8,
      "z": 1,
      "name": "Rock_Stone_Brick_Half",
      "rotation": 8
    },
    {
      "x": -4,
      "y": 9,
      "z": 1,
      "name": "Rock_Stone_Brick_Wall",
      "rotation": 1
    },
    {
      "x": -4,
      "y": 10,
      "z": 1,
      "name": "Rock_Stone_Brick_Half"
    },
    {
      "x": -4,
      "y": 13,
      "z": 1,
      "name": "Rock_Stone_Brick_Stairs",
      "rotation": 11
    },
    {
      "x": -4,
      "y": 14,
      "z": 1,
      "name": "Rock_Stone_Brick"
    },
    {
      "x": -4,
      "y": 15,
      "z": 1,
      "name": "Rock_Stone_Brick"
    },
    {
      "x": -4,
      "y": 0,
      "z": 2,
      "name": "Rock_Stone_Brick"
    },
    {
      "x": -4,
      "y": 1,
      "z": 2,
      "name": "Rock_Stone_Brick"
    },
    {
      "x": -4,
      "y": 2,
      "z": 2,
      "name": "*Rock_Stone_Brick_Stairs_State_Definitions_Corner_Right",
      "rotation": 1
    },
    {
      "x": -4,
      "y": 8,
      "z": 2,
      "name": "Rock_Stone_Brick_Half",
      "rotation": 8
    },
    {
      "x": -4,
      "y": 9,
      "z": 2,
      "name": "Rock_Stone_Brick_Wall",
      "rotation": 1
    },
    {
      "x": -4,
      "y": 10,
      "z": 2,
      "name": "Rock_Stone_Brick_Half"
    },
    {
      "x": -4,
      "y": 13,
      "z": 2,
      "name": "Rock_Stone_Brick_Stairs",
      "rotation": 11
    },
    {
      "x": -4,
      "y": 14,
      "z": 2,
      "name": "Rock_Stone_Brick"
    },
    {
      "x": -4,
      "y": 15,
      "z": 2,
      "name": "Rock_Stone_Brick"
    },
    {
      "x": -4,
      "y": 0,
      "z": 3,
      "name": "Rock_Stone_Brick"
    },
    {
      "x": -4,
      "y": 1,
      "z": 3,
      "name": "Rock_Stone_Mossy"
    },
    {
      "x": -4,
      "y": 2,
      "z": 3,
      "name": "Plant_Moss_Rug_Blue",
      "support": 15
    },
    {
      "x": -4,
      "y": 8,
      "z": 3,
      "name": "Rock_Stone_Brick_Half",
      "rotation": 8
    },
    {
      "x": -4,
      "y": 9,
      "z": 3,
      "name": "Rock_Stone_Brick_Wall",
      "rotation": 1
    },
    {
      "x": -4,
      "y": 10,
      "z": 3,
      "name": "Rock_Stone_Brick_Half"
    },
    {
      "x": -4,
      "y": 13,
      "z": 3,
      "name": "Rock_Stone_Brick_Stairs",
      "rotation": 11
    },
    {
      "x": -4,
      "y": 14,
      "z": 3,
      "name": "Rock_Stone_Brick"
    },
    {
      "x": -4,
      "y": 15,
      "z": 3,
      "name": "Rock_Stone_Brick"
    },
    {
      "x": -4,
      "y": 0,
      "z": 4,
      "name": "Rock_Stone_Brick"
    },
    {
      "x": -4,
      "y": 1,
      "z": 4,
      "name": "Rock_Stone_Brick_Half",
      "rotation": 4
    },
    {
      "x": -4,
      "y": 8,
      "z": 4,
      "name": "Rock_Stone_Brick_Half",
      "rotation": 8
    },
    {
      "x": -4,
      "y": 9,
      "z": 4,
      "name": "Rock_Stone_Brick_Wall",
      "rotation": 1
    },
    {
      "x": -4,
      "y": 10,
      "z": 4,
      "name": "Rock_Stone_Brick_Half"
    },
    {
      "x": -4,
      "y": 13,
      "z": 4,
      "name": "Rock_Stone_Brick_Stairs",
      "rotation": 11
    },
    {
      "x": -4,
      "y": 14,
      "z": 4,
      "name": "Rock_Stone_Brick"
    },
    {
      "x": -4,
      "y": 15,
      "z": 4,
      "name": "Rock_Stone_Brick"
    },
    {
      "x": -4,
      "y": 0,
      "z": 5,
      "name": "Rock_Stone_Brick"
    },
    {
      "x": -4,
      "y": 1,
      "z": 5,
      "name": "Rock_Stone_Brick"
    },
    {
      "x": -4,
      "y": 8,
      "z": 5,
      "name": "Rock_Stone_Brick_Half",
      "rotation": 8
    },
    {
      "x": -4,
      "y": 9,
      "z": 5,
      "name": "Rock_Stone_Brick_Wall",
      "rotation": 1
    },
    {
      "x": -4,
      "y": 10,
      "z": 5,
      "name": "Rock_Stone_Brick_Half"
    },
    {
      "x": -4,
      "y": 13,
      "z": 5,
      "name": "Rock_Stone_Brick_Stairs",
      "rotation": 11
    },
    {
      "x": -4,
      "y": 14,
      "z": 5,
      "name": "Rock_Stone_Brick"
    },
    {
      "x": -4,
      "y": 15,
      "z": 5,
      "name": "Rock_Stone_Brick"
    },
    {
      "x": -4,
      "y": 0,
      "z": 6,
      "name": "Rock_Stone_Brick"
    },
    {
      "x": -4,
      "y": 1,
      "z": 6,
      "name": "Rock_Stone_Mossy"
    },
    {
      "x": -4,
      "y": 8,
      "z": 6,
      "name": "Rock_Stone_Brick_Half",
      "rotation": 8
    },
    {
      "x": -4,
      "y": 9,
      "z": 6,
      "name": "Rock_Stone_Brick_Wall",
      "rotation": 1
    },
    {
      "x": -4,
      "y": 10,
      "z": 6,
      "name": "Rock_Stone_Brick_Half"
    },
    {
      "x": -4,
      "y": 13,
      "z": 6,
      "name": "Rock_Stone_Brick_Stairs",
      "rotation": 11
    },
    {
      "x": -4,
      "y": 14,
      "z": 6,
      "name": "Rock_Stone_Brick"
    },
    {
      "x": -4,
      "y": 15,
      "z": 6,
      "name": "Rock_Stone_Brick"
    },
    {
      "x": -4,
      "y": 0,
      "z": 7,
      "name": "Rock_Stone_Brick"
    },
    {
      "x": -4,
      "y": 1,
      "z": 7,
      "name": "Rock_Stone_Mossy"
    },
    {
      "x": -4,
      "y": 2,
      "z": 7,
      "name": "*Rock_Stone_Brick_Stairs_State_Definitions_Corner_Right",
      "rotation": 2
    },
    {
      "x": -4,
      "y": 8,
      "z": 7,
      "name": "*Rock_Stone_Brick_Stairs_State_Definitions_Corner_Right",
      "rotation": 11
    },
    {
      "x": -4,
      "y": 9,
      "z": 7,
      "name": "Rock_Stone_Brick_Wall",
      "rotation": 1
    },
    {
      "x": -4,
      "y": 10,
      "z": 7,
      "name": "Rock_Stone_Brick_Half"
    },
    {
      "x": -4,
      "y": 13,
      "z": 7,
      "name": "Rock_Stone_Brick_Stairs",
      "rotation": 11
    },
    {
      "x": -4,
      "y": 14,
      "z": 7,
      "name": "Rock_Stone_Brick"
    },
    {
      "x": -4,
      "y": 15,
      "z": 7,
      "name": "Rock_Stone_Brick"
    },
    {
      "x": -4,
      "y": 0,
      "z": 8,
      "name": "Rock_Stone_Brick"
    },
    {
      "x": -4,
      "y": 1,
      "z": 8,
      "name": "Humans_Ruins_Torch_Echo"
    },
    {
      "x": -4,
      "y": 2,
      "z": 8,
      "name": "Rock_Stone_Brick_Stairs",
      "rotation": 1
    },
    {
      "x": -4,
      "y": 5,
      "z": 8,
      "name": "Rock_Stone_Brick_Half",
      "rotation": 5
    },
    {
      "x": -4,
      "y": 8,
      "z": 8,
      "name": "Rock_Stone_Brick_Stairs",
      "rotation": 11
    },
    {
      "x": -4,
      "y": 9,
      "z": 8,
      "name": "Rock_Stone_Brick_Wall",
      "rotation": 1
    },
    {
      "x": -4,
      "y": 10,
      "z": 8,
      "name": "Rock_Stone_Brick_Half"
    },
    {
      "x": -4,
      "y": 13,
      "z": 8,
      "name": "Rock_Stone_Brick_Stairs",
      "rotation": 11
    },
    {
      "x": -4,
      "y": 14,
      "z": 8,
      "name": "Rock_Stone_Brick"
    },
    {
      "x": -4,
      "y": 15,
      "z": 8,
      "name": "Rock_Stone_Brick"
    },
    {
      "x": -3,
      "y": 0,
      "z": -7,
      "name": "Rock_Stone_Brick"
    },
    {
      "x": -3,
      "y": 1,
      "z": -7,
      "name": "Rock_Stone_Brick"
    },
    {
      "x": -3,
      "y": 14,
      "z": -7,
      "name": "Rock_Stone_Brick"
    },
    {
      "x": -3,
      "y": 15,
      "z": -7,
      "name": "Rock_Stone_Brick"
    },
    {
      "x": -3,
      "y": 0,
      "z": -6,
      "name": "Rock_Stone_Brick"
    },
    {
      "x": -3,
      "y": 1,
      "z": -6,
      "name": "Rock_Stone_Brick"
    },
    {
      "x": -3,
      "y": 14,
      "z": -6,
      "name": "Rock_Stone_Brick_Stairs",
      "rotation": 11
    },
    {
      "x": -3,
      "y": 15,
      "z": -6,
      "name": "Rock_Stone_Brick"
    },
    {
      "x": -3,
      "y": 0,
      "z": -5,
      "name": "Rock_Stone_Brick"
    },
    {
      "x": -3,
      "y": 1,
      "z": -5,
      "name": "Rock_Stone_Brick"
    },
    {
      "x": -3,
      "y": 14,
      "z": -5,
      "name": "Rock_Stone_Brick"
    },
    {
      "x": -3,
      "y": 15,
      "z": -5,
      "name": "Rock_Stone_Brick"
    },
    {
      "x": -3,
      "y": 0,
      "z": -4,
      "name": "Rock_Stone_Brick"
    },
    {
      "x": -3,
      "y": 1,
      "z": -4,
      "name": "Rock_Stone_Brick"
    },
    {
      "x": -3,
      "y": 14,
      "z": -4,
      "name": "Rock_Stone_Brick"
    },
    {
      "x": -3,
      "y": 15,
      "z": -4,
      "name": "Rock_Stone_Brick"
    },
    {
      "x": -3,
      "y": 0,
      "z": -3,
      "name": "Rock_Stone_Brick"
    },
    {
      "x": -3,
      "y": 1,
      "z": -3,
      "name": "Rock_Stone_Brick"
    },
    {
      "x": -3,
      "y": 14,
      "z": -3,
      "name": "Rock_Stone_Brick"
    },
    {
      "x": -3,
      "y": 15,
      "z": -3,
      "name": "Rock_Stone_Brick"
    },
    {
      "x": -3,
      "y": 0,
      "z": -2,
      "name": "Rock_Stone_Brick"
    },
    {
      "x": -3,
      "y": 1,
      "z": -2,
      "name": "Rock_Stone_Brick"
    },
    {
      "x": -3,
      "y": 14,
      "z": -2,
      "name": "Rock_Stone_Brick"
    },
    {
      "x": -3,
      "y": 15,
      "z": -2,
      "name": "Rock_Stone_Brick"
    },
    {
      "x": -3,
      "y": 0,
      "z": -1,
      "name": "Rock_Stone_Brick"
    },
    {
      "x": -3,
      "y": 1,
      "z": -1,
      "name": "Rock_Stone_Brick"
    },
    {
      "x": -3,
      "y": 14,
      "z": -1,
      "name": "Rock_Stone_Brick"
    },
    {
      "x": -3,
      "y": 15,
      "z": -1,
      "name": "Rock_Stone_Brick"
    },
    {
      "x": -3,
      "y": 0,
      "z": 0,
      "name": "Rock_Stone_Brick"
    },
    {
      "x": -3,
      "y": 1,
      "z": 0,
      "name": "Rock_Stone_Brick"
    },
    {
      "x": -3,
      "y": 14,
      "z": 0,
      "name": "Rock_Stone_Brick"
    },
    {
      "x": -3,
      "y": 15,
      "z": 0,
      "name": "Rock_Stone_Brick"
    },
    {
      "x": -3,
      "y": 0,
      "z": 1,
      "name": "Rock_Stone_Brick"
    },
    {
      "x": -3,
      "y": 1,
      "z": 1,
      "name": "Rock_Stone_Brick"
    },
    {
      "x": -3,
      "y": 14,
      "z": 1,
      "name": "Rock_Stone_Brick"
    },
    {
      "x": -3,
      "y": 15,
      "z": 1,
      "name": "Rock_Stone_Brick"
    },
    {
      "x": -3,
      "y": 0,
      "z": 2,
      "name": "Rock_Stone_Brick"
    },
    {
      "x": -3,
      "y": 1,
      "z": 2,
      "name": "Rock_Stone_Brick"
    },
    {
      "x": -3,
      "y": 14,
      "z": 2,
      "name": "Rock_Stone_Brick"
    },
    {
      "x": -3,
      "y": 15,
      "z": 2,
      "name": "Rock_Stone_Brick"
    },
    {
      "x": -3,
      "y": 0,
      "z": 3,
      "name": "Rock_Stone_Brick"
    },
    {
      "x": -3,
      "y": 1,
      "z": 3,
      "name": "Rock_Stone_Brick"
    },
    {
      "x": -3,
      "y": 14,
      "z": 3,
      "name": "Rock_Stone_Brick"
    },
    {
      "x": -3,
      "y": 15,
      "z": 3,
      "name": "Rock_Stone_Brick"
    },
    {
      "x": -3,
      "y": 0,
      "z": 4,
      "name": "Rock_Stone_Brick"
    },
    {
      "x": -3,
      "y": 1,
      "z": 4,
      "name": "Rock_Stone_Brick_Half",
      "rotation": 7
    },
    {
      "x": -3,
      "y": 14,
      "z": 4,
      "name": "Rock_Stone_Brick"
    },
    {
      "x": -3,
      "y": 15,
      "z": 4,
      "name": "Rock_Stone_Brick"
    },
    {
      "x": -3,
      "y": 0,
      "z": 5,
      "name": "Rock_Stone_Brick"
    },
    {
      "x": -3,
      "y": 1,
      "z": 5,
      "name": "Rock_Stone_Brick_Half",
      "rotation": 6
    },
    {
      "x": -3,
      "y": 14,
      "z": 5,
      "name": "Rock_Stone_Brick"
    },
    {
      "x": -3,
      "y": 15,
      "z": 5,
      "name": "Rock_Stone_Brick"
    },
    {
      "x": -3,
      "y": 0,
      "z": 6,
      "name": "Rock_Stone_Brick"
    },
    {
      "x": -3,
      "y": 1,
      "z": 6,
      "name": "Rock_Stone_Mossy"
    },
    {
      "x": -3,
      "y": 2,
      "z": 6,
      "name": "Rubble_Stone_Mossy"
    },
    {
      "x": -3,
      "y": 14,
      "z": 6,
      "name": "Rock_Stone_Brick"
    },
    {
      "x": -3,
      "y": 15,
      "z": 6,
      "name": "Rock_Stone_Brick"
    },
    {
      "x": -3,
      "y": 0,
      "z": 7,
      "name": "Rock_Stone_Brick"
    },
    {
      "x": -3,
      "y": 1,
      "z": 7,
      "name": "Rock_Stone_Brick"
    },
    {
      "x": -3,
      "y": 14,
      "z": 7,
      "name": "Rock_Stone_Brick"
    },
    {
      "x": -3,
      "y": 15,
      "z": 7,
      "name": "Rock_Stone_Brick"
    },
    {
      "x": -3,
      "y": 0,
      "z": 8,
      "name": "Rock_Stone_Brick"
    },
    {
      "x": -3,
      "y": 1,
      "z": 8,
      "name": "Rock_Stone_Brick"
    },
    {
      "x": -3,
      "y": 14,
      "z": 8,
      "name": "Rock_Stone_Brick"
    },
    {
      "x": -3,
      "y": 15,
      "z": 8,
      "name": "Rock_Stone_Brick"
    },
    {
      "x": -2,
      "y": 0,
      "z": -7,
      "name": "Rock_Stone_Brick"
    },
    {
      "x": -2,
      "y": 1,
      "z": -7,
      "name": "Rock_Stone_Brick"
    },
    {
      "x": -2,
      "y": 13,
      "z": -7,
      "name": "Rock_Stone_Brick_Stairs",
      "rotation": 9
    },
    {
      "x": -2,
      "y": 14,
      "z": -7,
      "name": "Rock_Stone_Brick"
    },
    {
      "x": -2,
      "y": 15,
      "z": -7,
      "name": "Rock_Stone_Brick"
    },
    {
      "x": -2,
      "y": 0,
      "z": -6,
      "name": "Rock_Stone_Brick"
    },
    {
      "x": -2,
      "y": 1,
      "z": -6,
      "name": "Rock_Stone_Brick"
    },
    {
      "x": -2,
      "y": 13,
      "z": -6,
      "name": "Rock_Stone_Brick_Stairs",
      "rotation": 9
    },
    {
      "x": -2,
      "y": 14,
      "z": -6,
      "name": "Rock_Stone_Brick"
    },
    {
      "x": -2,
      "y": 15,
      "z": -6,
      "name": "Rock_Stone_Brick"
    },
    {
      "x": -2,
      "y": 0,
      "z": -5,
      "name": "Rock_Stone_Brick"
    },
    {
      "x": -2,
      "y": 1,
      "z": -5,
      "name": "Rock_Stone_Brick"
    },
    {
      "x": -2,
      "y": 13,
      "z": -5,
      "name": "Rock_Stone_Brick_Stairs",
      "rotation": 9
    },
    {
      "x": -2,
      "y": 14,
      "z": -5,
      "name": "Rock_Stone_Brick"
    },
    {
      "x": -2,
      "y": 15,
      "z": -5,
      "name": "Rock_Stone_Brick"
    },
    {
      "x": -2,
      "y": 0,
      "z": -4,
      "name": "Rock_Stone_Brick"
    },
    {
      "x": -2,
      "y": 1,
      "z": -4,
      "name": "Rock_Stone_Brick"
    },
    {
      "x": -2,
      "y": 13,
      "z": -4,
      "name": "Rock_Stone_Brick_Stairs",
      "rotation": 9
    },
    {
      "x": -2,
      "y": 14,
      "z": -4,
      "name": "Rock_Stone_Brick"
    },
    {
      "x": -2,
      "y": 15,
      "z": -4,
      "name": "Rock_Stone_Brick"
    },
    {
      "x": -2,
      "y": 0,
      "z": -3,
      "name": "Rock_Stone_Brick"
    },
    {
      "x": -2,
      "y": 1,
      "z": -3,
      "name": "Rock_Stone_Brick"
    },
    {
      "x": -2,
      "y": 13,
      "z": -3,
      "name": "Rock_Stone_Brick_Stairs",
      "rotation": 9
    },
    {
      "x": -2,
      "y": 14,
      "z": -3,
      "name": "Rock_Stone_Brick"
    },
    {
      "x": -2,
      "y": 15,
      "z": -3,
      "name": "Rock_Stone_Brick"
    },
    {
      "x": -2,
      "y": 0,
      "z": -2,
      "name": "Rock_Stone_Brick"
    },
    {
      "x": -2,
      "y": 1,
      "z": -2,
      "name": "Rock_Stone_Brick"
    },
    {
      "x": -2,
      "y": 13,
      "z": -2,
      "name": "Rock_Stone_Brick_Stairs",
      "rotation": 9
    },
    {
      "x": -2,
      "y": 14,
      "z": -2,
      "name": "Rock_Stone_Brick"
    },
    {
      "x": -2,
      "y": 15,
      "z": -2,
      "name": "Rock_Stone_Brick"
    },
    {
      "x": -2,
      "y": 0,
      "z": -1,
      "name": "Rock_Stone_Brick"
    },
    {
      "x": -2,
      "y": 1,
      "z": -1,
      "name": "Rock_Stone_Brick"
    },
    {
      "x": -2,
      "y": 13,
      "z": -1,
      "name": "Rock_Stone_Brick_Stairs",
      "rotation": 9
    },
    {
      "x": -2,
      "y": 14,
      "z": -1,
      "name": "Rock_Stone_Brick"
    },
    {
      "x": -2,
      "y": 15,
      "z": -1,
      "name": "Rock_Stone_Brick"
    },
    {
      "x": -2,
      "y": 0,
      "z": 0,
      "name": "Rock_Stone_Brick"
    },
    {
      "x": -2,
      "y": 1,
      "z": 0,
      "name": "Rock_Stone_Brick"
    },
    {
      "x": -2,
      "y": 13,
      "z": 0,
      "name": "Rock_Stone_Brick_Stairs",
      "rotation": 9
    },
    {
      "x": -2,
      "y": 14,
      "z": 0,
      "name": "Rock_Stone_Brick_Stairs",
      "rotation": 9
    },
    {
      "x": -2,
      "y": 15,
      "z": 0,
      "name": "Rock_Stone_Brick"
    },
    {
      "x": -2,
      "y": 0,
      "z": 1,
      "name": "Rock_Stone_Brick"
    },
    {
      "x": -2,
      "y": 1,
      "z": 1,
      "name": "Rock_Stone_Brick"
    },
    {
      "x": -2,
      "y": 13,
      "z": 1,
      "name": "Rock_Stone_Brick_Stairs",
      "rotation": 9
    },
    {
      "x": -2,
      "y": 14,
      "z": 1,
      "name": "Rock_Stone_Brick"
    },
    {
      "x": -2,
      "y": 15,
      "z": 1,
      "name": "Rock_Stone_Brick"
    },
    {
      "x": -2,
      "y": 0,
      "z": 2,
      "name": "Rock_Stone_Brick"
    },
    {
      "x": -2,
      "y": 1,
      "z": 2,
      "name": "Rock_Stone_Brick"
    },
    {
      "x": -2,
      "y": 13,
      "z": 2,
      "name": "Rock_Stone_Brick_Stairs",
      "rotation": 9
    },
    {
      "x": -2,
      "y": 14,
      "z": 2,
      "name": "Rock_Stone_Brick"
    },
    {
      "x": -2,
      "y": 15,
      "z": 2,
      "name": "Rock_Stone_Brick"
    },
    {
      "x": -2,
      "y": 0,
      "z": 3,
      "name": "Rock_Stone_Brick"
    },
    {
      "x": -2,
      "y": 1,
      "z": 3,
      "name": "Rock_Stone_Brick"
    },
    {
      "x": -2,
      "y": 13,
      "z": 3,
      "name": "Rock_Stone_Brick_Stairs",
      "rotation": 9
    },
    {
      "x": -2,
      "y": 14,
      "z": 3,
      "name": "Rock_Stone_Brick"
    },
    {
      "x": -2,
      "y": 15,
      "z": 3,
      "name": "Rock_Stone_Brick"
    },
    {
      "x": -2,
      "y": 0,
      "z": 4,
      "name": "Rock_Stone_Brick"
    },
    {
      "x": -2,
      "y": 1,
      "z": 4,
      "name": "Rock_Stone_Brick_Half",
      "rotation": 4
    },
    {
      "x": -2,
      "y": 13,
      "z": 4,
      "name": "Rock_Stone_Brick_Stairs",
      "rotation": 9
    },
    {
      "x": -2,
      "y": 14,
      "z": 4,
      "name": "Rock_Stone_Brick"
    },
    {
      "x": -2,
      "y": 15,
      "z": 4,
      "name": "Rock_Stone_Brick"
    },
    {
      "x": -2,
      "y": 0,
      "z": 5,
      "name": "Rock_Stone_Brick"
    },
    {
      "x": -2,
      "y": 1,
      "z": 5,
      "name": "Rock_Stone_Brick_Half",
      "rotation": 7
    },
    {
      "x": -2,
      "y": 13,
      "z": 5,
      "name": "Rock_Stone_Brick_Stairs",
      "rotation": 9
    },
    {
      "x": -2,
      "y": 14,
      "z": 5,
      "name": "Rock_Stone_Brick"
    },
    {
      "x": -2,
      "y": 15,
      "z": 5,
      "name": "Rock_Stone_Brick"
    },
    {
      "x": -2,
      "y": 0,
      "z": 6,
      "name": "Rock_Stone_Brick"
    },
    {
      "x": -2,
      "y": 1,
      "z": 6,
      "name": "Rock_Stone_Brick_Half",
      "rotation": 6
    },
    {
      "x": -2,
      "y": 13,
      "z": 6,
      "name": "Rock_Stone_Brick_Stairs",
      "rotation": 9
    },
    {
      "x": -2,
      "y": 14,
      "z": 6,
      "name": "Rock_Stone_Brick"
    },
    {
      "x": -2,
      "y": 15,
      "z": 6,
      "name": "Rock_Stone_Brick"
    },
    {
      "x": -2,
      "y": 0,
      "z": 7,
      "name": "Rock_Stone_Brick"
    },
    {
      "x": -2,
      "y": 1,
      "z": 7,
      "name": "Rock_Stone_Brick"
    },
    {
      "x": -2,
      "y": 13,
      "z": 7,
      "name": "Rock_Stone_Brick_Stairs",
      "rotation": 9
    },
    {
      "x": -2,
      "y": 14,
      "z": 7,
      "name": "Rock_Stone_Brick"
    },
    {
      "x": -2,
      "y": 15,
      "z": 7,
      "name": "Rock_Stone_Brick"
    },
    {
      "x": -2,
      "y": 0,
      "z": 8,
      "name": "Rock_Stone_Brick"
    },
    {
      "x": -2,
      "y": 1,
      "z": 8,
      "name": "Rock_Stone_Brick"
    },
    {
      "x": -2,
      "y": 13,
      "z": 8,
      "name": "Rock_Stone_Brick_Stairs",
      "rotation": 9
    },
    {
      "x": -2,
      "y": 14,
      "z": 8,
      "name": "Rock_Stone_Brick"
    },
    {
      "x": -2,
      "y": 15,
      "z": 8,
      "name": "Rock_Stone_Brick"
    },
    {
      "x": -1,
      "y": 0,
      "z": -7,
      "name": "Rock_Stone_Brick"
    },
    {
      "x": -1,
      "y": 1,
      "z": -7,
      "name": "Rock_Stone_Brick"
    },
    {
      "x": -1,
      "y": 13,
      "z": -7,
      "name": "Rock_Stone_Brick_Half",
      "rotation": 8
    },
    {
      "x": -1,
      "y": 14,
      "z": -7,
      "name": "Rock_Stone_Brick"
    },
    {
      "x": -1,
      "y": 15,
      "z": -7,
      "name": "Rock_Stone_Brick"
    },
    {
      "x": -1,
      "y": 0,
      "z": -6,
      "name": "Rock_Stone_Brick"
    },
    {
      "x": -1,
      "y": 1,
      "z": -6,
      "name": "Rock_Stone_Brick"
    },
    {
      "x": -1,
      "y": 13,
      "z": -6,
      "name": "Rock_Stone_Brick_Half",
      "rotation": 8
    },
    {
      "x": -1,
      "y": 14,
      "z": -6,
      "name": "Rock_Stone_Brick"
    },
    {
      "x": -1,
      "y": 15,
      "z": -6,
      "name": "Rock_Stone_Brick"
    },
    {
      "x": -1,
      "y": 0,
      "z": -5,
      "name": "Rock_Stone_Brick"
    },
    {
      "x": -1,
      "y": 1,
      "z": -5,
      "name": "Rock_Stone_Brick"
    },
    {
      "x": -1,
      "y": 13,
      "z": -5,
      "name": "Rock_Stone_Brick_Half",
      "rotation": 8
    },
    {
      "x": -1,
      "y": 14,
      "z": -5,
      "name": "Rock_Stone_Brick"
    },
    {
      "x": -1,
      "y": 15,
      "z": -5,
      "name": "Rock_Stone_Brick"
    },
    {
      "x": -1,
      "y": 0,
      "z": -4,
      "name": "Rock_Stone_Brick"
    },
    {
      "x": -1,
      "y": 1,
      "z": -4,
      "name": "Rock_Stone_Brick"
    },
    {
      "x": -1,
      "y": 13,
      "z": -4,
      "name": "Rock_Stone_Brick_Half",
      "rotation": 8
    },
    {
      "x": -1,
      "y": 14,
      "z": -4,
      "name": "Rock_Stone_Brick"
    },
    {
      "x": -1,
      "y": 15,
      "z": -4,
      "name": "Rock_Stone_Brick"
    },
    {
      "x": -1,
      "y": 0,
      "z": -3,
      "name": "Rock_Stone_Brick"
    },
    {
      "x": -1,
      "y": 1,
      "z": -3,
      "name": "Rock_Stone_Brick"
    },
    {
      "x": -1,
      "y": 13,
      "z": -3,
      "name": "Rock_Stone_Brick_Half",
      "rotation": 8
    },
    {
      "x": -1,
      "y": 14,
      "z": -3,
      "name": "Rock_Stone_Brick"
    },
    {
      "x": -1,
      "y": 15,
      "z": -3,
      "name": "Rock_Stone_Brick"
    },
    {
      "x": -1,
      "y": 0,
      "z": -2,
      "name": "Rock_Stone_Brick"
    },
    {
      "x": -1,
      "y": 1,
      "z": -2,
      "name": "Rock_Stone_Brick_Stairs",
      "rotation": 1
    },
    {
      "x": -1,
      "y": 13,
      "z": -2,
      "name": "Rock_Stone_Brick_Half",
      "rotation": 8
    },
    {
      "x": -1,
      "y": 14,
      "z": -2,
      "name": "Rock_Stone_Brick"
    },
    {
      "x": -1,
      "y": 15,
      "z": -2,
      "name": "Rock_Stone_Brick"
    },
    {
      "x": -1,
      "y": 0,
      "z": -1,
      "name": "Rock_Stone_Brick"
    },
    {
      "x": -1,
      "y": 1,
      "z": -1,
      "name": "Rock_Stone_Brick"
    },
    {
      "x": -1,
      "y": 13,
      "z": -1,
      "name": "Rock_Stone_Brick_Half",
      "rotation": 8
    },
    {
      "x": -1,
      "y": 14,
      "z": -1,
      "name": "Rock_Stone_Brick"
    },
    {
      "x": -1,
      "y": 15,
      "z": -1,
      "name": "Rock_Stone_Brick"
    },
    {
      "x": -1,
      "y": 0,
      "z": 0,
      "name": "Rock_Stone_Brick"
    },
    {
      "x": -1,
      "y": 1,
      "z": 0,
      "name": "Rock_Stone_Brick"
    },
    {
      "x": -1,
      "y": 13,
      "z": 0,
      "name": "Rock_Stone_Brick_Half",
      "rotation": 8
    },
    {
      "x": -1,
      "y": 14,
      "z": 0,
      "name": "Rock_Stone_Brick"
    },
    {
      "x": -1,
      "y": 15,
      "z": 0,
      "name": "Rock_Stone_Brick"
    },
    {
      "x": -1,
      "y": 0,
      "z": 1,
      "name": "Rock_Stone_Brick"
    },
    {
      "x": -1,
      "y": 1,
      "z": 1,
      "name": "Rock_Stone_Brick"
    },
    {
      "x": -1,
      "y": 13,
      "z": 1,
      "name": "Rock_Stone_Brick_Half",
      "rotation": 8
    },
    {
      "x": -1,
      "y": 14,
      "z": 1,
      "name": "Rock_Stone_Brick"
    },
    {
      "x": -1,
      "y": 15,
      "z": 1,
      "name": "Rock_Stone_Brick"
    },
    {
      "x": -1,
      "y": 0,
      "z": 2,
      "name": "Rock_Stone_Brick"
    },
    {
      "x": -1,
      "y": 1,
      "z": 2,
      "name": "Rock_Stone_Brick"
    },
    {
      "x": -1,
      "y": 13,
      "z": 2,
      "name": "Rock_Stone_Brick_Half",
      "rotation": 8
    },
    {
      "x": -1,
      "y": 14,
      "z": 2,
      "name": "Rock_Stone_Brick_Stairs",
      "rotation": 11
    },
    {
      "x": -1,
      "y": 15,
      "z": 2,
      "name": "Rock_Stone_Brick"
    },
    {
      "x": -1,
      "y": 0,
      "z": 3,
      "name": "Rock_Stone_Brick"
    },
    {
      "x": -1,
      "y": 1,
      "z": 3,
      "name": "Rock_Stone_Brick"
    },
    {
      "x": -1,
      "y": 13,
      "z": 3,
      "name": "Rock_Stone_Brick_Half",
      "rotation": 8
    },
    {
      "x": -1,
      "y": 14,
      "z": 3,
      "name": "Rock_Stone_Brick"
    },
    {
      "x": -1,
      "y": 15,
      "z": 3,
      "name": "Rock_Stone_Brick"
    },
    {
      "x": -1,
      "y": 0,
      "z": 4,
      "name": "Rock_Stone_Brick"
    },
    {
      "x": -1,
      "y": 1,
      "z": 4,
      "name": "Rock_Stone_Brick_Half",
      "rotation": 4
    },
    {
      "x": -1,
      "y": 13,
      "z": 4,
      "name": "Rock_Stone_Brick_Half",
      "rotation": 8
    },
    {
      "x": -1,
      "y": 14,
      "z": 4,
      "name": "Rock_Stone_Brick"
    },
    {
      "x": -1,
      "y": 15,
      "z": 4,
      "name": "Rock_Stone_Brick"
    },
    {
      "x": -1,
      "y": 0,
      "z": 5,
      "name": "Rock_Stone_Brick"
    },
    {
      "x": -1,
      "y": 1,
      "z": 5,
      "name": "Rock_Stone_Brick"
    },
    {
      "x": -1,
      "y": 13,
      "z": 5,
      "name": "Rock_Stone_Brick_Half",
      "rotation": 8
    },
    {
      "x": -1,
      "y": 14,
      "z": 5,
      "name": "Rock_Stone_Brick"
    },
    {
      "x": -1,
      "y": 15,
      "z": 5,
      "name": "Rock_Stone_Brick"
    },
    {
      "x": -1,
      "y": 0,
      "z": 6,
      "name": "Rock_Stone_Brick"
    },
    {
      "x": -1,
      "y": 1,
      "z": 6,
      "name": "Rock_Stone_Brick_Half",
      "rotation": 7
    },
    {
      "x": -1,
      "y": 13,
      "z": 6,
      "name": "Rock_Stone_Brick_Half",
      "rotation": 8
    },
    {
      "x": -1,
      "y": 14,
      "z": 6,
      "name": "Rock_Stone_Brick_Stairs",
      "rotation": 10
    },
    {
      "x": -1,
      "y": 15,
      "z": 6,
      "name": "Rock_Stone_Brick"
    },
    {
      "x": -1,
      "y": 0,
      "z": 7,
      "name": "Rock_Stone_Brick"
    },
    {
      "x": -1,
      "y": 1,
      "z": 7,
      "name": "Rock_Stone_Brick_Half",
      "rotation": 6
    },
    {
      "x": -1,
      "y": 13,
      "z": 7,
      "name": "Rock_Stone_Brick_Half",
      "rotation": 8
    },
    {
      "x": -1,
      "y": 14,
      "z": 7,
      "name": "Rock_Stone_Brick"
    },
    {
      "x": -1,
      "y": 15,
      "z": 7,
